Workbook

Sheet Sheet
A3: Номенклатура | B3: Ед. изм. | C3: Начальный остаток | D3: Приход | E3: Расход | F3: Конечный остаток | G3: Грация | H3: Остаток | I3: крат | J3: сроки | K3: метка | L3: метка2 | M3: заяв | N3: разн | O3: без опта | P3: опт | Q3: заказ в пути | R3: заказ в пути | S3: ср нов | T3: расчет | U3: заказ | V3: ТК | W3: кон ост | X3: факт | Y3: ср | Z3: ср | AA3: ср | AB3: ср | AC3: ср | AD3: ср | AE3: ср | AF3: ср | AG3: ср | AH3: ср | AI3: комментарии | AJ3: вес
G4: остатки | H4: без опта | Q4: 08,09, | R4: 08,09,доз | S4: 07,09, | U4: 15,09, | V4: Титенок | Y4: 31,08, | Z4: 24,08, | AA4: 17,08, | AB4: 10,08, | AC4: 03,08, | AD4: 27,07, | AE4: 20,07, | AF4: 13,07, | AG4: 06,07, | AH4: 29,06,
E5: =SUM(E6:E500) -> 21598.764 | F5: =SUM(F6:F500) -> 31559.457 | H5: =SUM(H6:H500) -> 26021.402 | M5: =SUM(M6:M500) -> 29605.034 | N5: =SUM(N6:N500) -> -8006.27 | O5: =SUM(O6:O500) -> 16998.858 | P5: =SUM(P6:P500) -> 4599.906 | Q5: =SUM(Q6:Q500) -> 14855 | R5: =SUM(R6:R500) -> 1000 | S5: =SUM(S6:S500) -> 3399.7716 | T5: =SUM(T6:T500) -> 13757.41 | U5: =SUM(U6:U500) -> 16977 | Y5: =SUM(Y6:Y500) -> 2006.4104 | Z5: =SUM(Z6:Z500) -> 3945.1628 | AA5: =SUM(AA6:AA500) -> 3703.6238 | AB5: =SUM(AB6:AB500) -> 2207.5886 | AC5: =SUM(AC6:AC500) -> 2571.0086 | AD5: =SUM(AD6:AD500) -> 3209.5596 | AE5: =SUM(AE6:AE500) -> 2940.3354 | AF5: =SUM(AF6:AF500) -> 2144.2982 | ... AH5: =SUM(AH6:AH500) -> 2158.793 | AJ5: =SUM(AJ6:AJ500) -> 7608.72
A6: 0614 ПРАЗДНИЧНАЯ с/к в/с дек.спец.мгс Останкино | B6: кг | C6: 26.505 | D6: 1.129 | E6: 3.986 | F6: 22.519 | G6: =VLOOKUP(A6,[1]Лист1!$A:$D,4,0) -> 0 | H6: =F6-G6 -> 22.519 | I6: 1 | J6: 120 | K6: матрица | M6: 4.5 | N6: =E6-M6 -> -0.514 | O6: =E6-P6 -> 3.986 | Q6: 0 | S6: =O6/5 -> 0.7972 | U6: =ROUND(T6,0) -> 0 | W6: =(H6+Q6+R6+U6)/S6 -> 28.247617 | X6: =(H6+Q6+R6)/S6 -> 28.247617 | Y6: 0.3392 | Z6: 3.1198 | AA6: 0 | AB6: 0 | AC6: 0 | AD6: 0 | AE6: 0 | AF6: 0 | AG6: 0 | AH6: 0 | AI6: новинка / нужно увеличить продажи!!! | AJ6: =I6*U6 -> 0
A7: 3215 ВЕТЧ.МЯСНАЯ Папа может п/о 0.4кг 8шт. ОСТАНКИНО | B7: шт | C7: 25 | D7: 963 | E7: 491 | F7: 469 | G7: =VLOOKUP(A7,[1]Лист1!$A:$D,4,0) -> 0 | H7: =F7-G7 -> 469 | I7: 0.4 | J7: 60 | K7: матрица | M7: 572 | N7: =E7-M7 -> -81 | O7: =E7-P7 -> 347 | P7: 144 | Q7: 70 | S7: =O7/5 -> 69.4 | T7: =14*S7-R7-Q7-H7 -> 432.6 | U7: =V7 -> 600 | V7: =VLOOKUP(A7,[2]Sheet!$A:$U,21,0) -> 600 | W7: =(H7+Q7+R7+U7)/S7 -> 16.412104 | X7: =(H7+Q7+R7)/S7 -> 7.7665706 | Y7: 26.6 | Z7: 68.8 | AA7: 75.6 | AB7: 35.4 | AC7: 54.2 | AD7: 62.6 | AE7: 55.6 | AF7: 41.2 | AG7: 33.6 | AH7: 46.6 | AJ7: =I7*U7 -> 240
A8: 3287 САЛЯМИ ИТАЛЬЯНСКАЯ с/к в/у ОСТАНКИНО | B8: кг | C8: 3.061 | D8: 243.643 | E8: 35.45 | F8: 211.254 | G8: =VLOOKUP(A8,[3]Лист1!$A:$D,4,0) -> 204.808 | H8: =F8-G8 -> 6.446 | I8: 1 | J8: 120 | K8: матрица | M8: 51.9 | N8: =E8-M8 -> -16.45 | O8: =E8-P8 -> 19.503 | P8: 15.947 | Q8: 30 | S8: =O8/5 -> 3.9006 | T8: =14*S8-H8-Q8-R8 -> 18.1624 | U8: =ROUND(T8+S8,0) -> 22 | W8: =(H8+Q8+R8+U8)/S8 -> 14.983849 | X8: =(H8+Q8+R8)/S8 -> 9.3436907 | Y8: 3.4222 | Z8: 5.2168 | AA8: 4.2012 | AB8: 3.2758 | AC8: 0.2996 | AD8: 0.9922 | AE8: 4.3466 | AF8: 1.4268 | AG8: 4.159 | AH8: 4.5156 | AI8: плюсом 5 дней | AJ8: =I8*U8 -> 22
A9: 3986 Ароматная с/к в/у 1/250 ОСТАНКИНО | B9: шт | C9: -6 | D9: 1086 | E9: 536 | F9: 506 | G9: =VLOOKUP(A9,[1]Лист1!$A:$D,4,0) -> 0 | H9: =F9-G9 -> 506 | I9: 0.25 | J9: 120 | K9: матрица | M9: 647 | N9: =E9-M9 -> -111 | O9: =E9-P9 -> 440 | P9: 96 | Q9: 70 | S9: =O9/5 -> 88 | T9: =14*S9-R9-Q9-H9 -> 656 | U9: =ROUND(T9+S9,0) -> 744 | W9: =(H9+Q9+R9+U9)/S9 -> 15 | X9: =(H9+Q9+R9)/S9 -> 6.5454545 | Y9: 23.2 | Z9: 97.8 | AA9: 70 | AB9: 29.8 | AC9: 37.4 | AD9: 61.4 | AE9: 31.4 | AF9: 25 | AG9: 35.8 | AH9: 25.4 | AI9: плюсом 5 дней | AJ9: =I9*U9 -> 186
A10: 4063 МЯСНАЯ Папа может вар п/о_Л ОСТАНКИНО | B10: кг | C10: 251.502 | D10: 641.564 | E10: 286.614 | F10: 586.11 | G10: =VLOOKUP(A10,[1]Лист1!$A:$D,4,0) -> 331.28 | H10: =F10-G10 -> 254.83 | I10: 1 | J10: 60 | K10: матрица | M10: 308.442 | N10: =E10-M10 -> -21.828 | O10: =E10-P10 -> 230.138 | P10: 56.476 | Q10: 650 | R10: 50 | S10: =O10/5 -> 46.0276 | U10: 100 | V10: =VLOOKUP(A10,[2]Sheet!$A:$U,21,0) -> 200 | W10: =(H10+Q10+R10+U10)/S10 -> 22.917337 | X10: =(H10+Q10+R10)/S10 -> 20.744727 | Y10: 57.7522 | Z10: 47.668 | AA10: 71.5244 | AB10: 59.9964 | AC10: 49.2606 | AD10: 56.2572 | AE10: 69.917 | AF10: 42.271 | AG10: 39.8542 | AH10: 46.8334 | AJ10: =I10*U10 -> 100
A11: 4117 ЭКСТРА Папа может с/к в/у_Л ОСТАНКИНО | B11: кг | C11: 100.353 | D11: 72.898 | E11: 49.861 | F11: 120.402 | G11: =VLOOKUP(A11,[1]Лист1!$A:$D,4,0) -> 0 | H11: =F11-G11 -> 120.402 | I11: 1 | J11: 120 | K11: матрица | M11: 55.2 | N11: =E11-M11 -> -5.339 | O11: =E11-P11 -> 21.725 | P11: 28.136 | Q11: 0 | S11: =O11/5 -> 4.345 | U11: =ROUND(T11,0) -> 0 | W11: =(H11+Q11+R11+U11)/S11 -> 27.710472 | X11: =(H11+Q11+R11)/S11 -> 27.710472 | Y11: 4.2176 | Z11: 10.532 | AA11: 6.9102 | AB11: 4.5746 | AC11: 8.6004 | AD11: 5.0928 | AE11: 2.7076 | AF11: 4.4042 | AG11: 2.8082 | AH11: 3.0776 | AI11: нужно увеличить продажи!!! / плюсом 5 дней | AJ11: =I11*U11 -> 0
A12: 4574 Мясная со шпиком Папа может вар п/о ОСТАНКИНО | B12: кг | C12: 27.39 | D12: 5.389 | E12: 31.04 | F12: 0.384 | G12: =VLOOKUP(A12,[1]Лист1!$A:$D,4,0) -> 0 | H12: =F12-G12 -> 0.384 | I12: 1 | J12: 60 | K12: матрица | M12: 51.9 | N12: =E12-M12 -> -20.86 | O12: =E12-P12 -> 31.04 | Q12: 120 | S12: =O12/5 -> 6.208 | U12: =ROUND(T12,0) -> 0 | W12: =(H12+Q12+R12+U12)/S12 -> 19.391753 | X12: =(H12+Q12+R12)/S12 -> 19.391753 | Y12: 8.6422 | Z12: 5.4014 | AA12: 2.4534 | AB12: 4.0156 | AC12: 8.7404 | AD12: 3.5336 | AE12: 3.8138 | AF12: 0.8198 | AG12: 1.0762 | AH12: 3.2698 | AJ12: =I12*U12 -> 0
A13: 4813 ФИЛЕЙНАЯ Папа может вар п/о_Л ОСТАНКИНО | B13: кг | C13: 101.26 | D13: 836.661 | E13: 322.046 | F13: 608.584 | G13: =VLOOKUP(A13,[1]Лист1!$A:$D,4,0) -> 301.424 | H13: =F13-G13 -> 307.16 | I13: 1 | J13: 60 | K13: матрица | M13: 304.365 | N13: =E13-M13 -> 17.681 | O13: =E13-P13 -> 232.085 | P13: 89.961 | Q13: 600 | S13: =O13/5 -> 46.417 | U13: 100 | V13: =VLOOKUP(A13,[2]Sheet!$A:$U,21,0) -> 200 | W13: =(H13+Q13+R13+U13)/S13 -> 21.698085 | X13: =(H13+Q13+R13)/S13 -> 19.543702 | Y13: 60.0048 | Z13: 59.6338 | AA13: 64.5988 | AB13: 47.5078 | AC13: 63.0726 | AD13: 49.1456 | AE13: 63.1104 | AF13: 35.6636 | AG13: 33.9338 | AH13: 49.6224 | AI13: нужно увеличить продажи | AJ13: =I13*U13 -> 100
A14: 4993 САЛЯМИ ИТАЛЬЯНСКАЯ с/к в/у 1/250*8_120c ОСТАНКИНО | B14: шт | C14: 38 | D14: 839 | E14: 319 | F14: 527 | G14: =VLOOKUP(A14,[1]Лист1!$A:$D,4,0) -> 0 | H14: =F14-G14 -> 527 | I14: 0.25 | J14: 120 | K14: матрица | M14: 404 | N14: =E14-M14 -> -85 | O14: =E14-P14 -> 223 | P14: 96 | Q14: 0 | S14: =O14/5 -> 44.6 | T14: =14*S14-R14-Q14-H14 -> 97.4 | U14: =ROUND(T14+S14,0) -> 142 | W14: =(H14+Q14+R14+U14)/S14 -> 15 | X14: =(H14+Q14+R14)/S14 -> 11.816143 | Y14: 30.6 | Z14: 70.4 | AA14: 62 | AB14: 37 | AC14: 33 | AD14: 47.4 | AE14: 53.6 | AF14: 24.2 | AG14: 21.4 | AH14: 43.8 | AI14: плюсом 5 дней | AJ14: =I14*U14 -> 35.5
A15: 5452 ВЕТЧ.МЯСНАЯ Папа может п/о ОСТАНКИНО | B15: кг | C15: 125.034 | D15: 331.761 | E15: 107.41 | F15: 342.517 | G15: =VLOOKUP(A15,[1]Лист1!$A:$D,4,0) -> 195.024 | H15: =F15-G15 -> 147.493 | I15: 1 | J15: 60 | K15: матрица | M15: 103.7 | N15: =E15-M15 -> 3.71 | O15: =E15-P15 -> 66.282 | P15: 41.128 | Q15: 50 | S15: =O15/5 -> 13.2564 | U15: =ROUND(T15,0) -> 0 | W15: =(H15+Q15+R15+U15)/S15 -> 14.897936 | X15: =(H15+Q15+R15)/S15 -> 14.897936 | Y15: 14.0612 | Z15: 19.493 | AA15: 0.472 | AB15: 8.4016 | AC15: 26.6348 | AD15: 14.544 | AE15: 9.7308 | AF15: 0.8118 | AG15: 3.512 | AH15: 11.567 | AJ15: =I15*U15 -> 0
A16: 5483 ЭКСТРА Папа может с/к в/у 1/250 8шт. ОСТАНКИНО | B16: шт | C16: 19 | D16: 1248 | E16: 557 | F16: 677 | G16: =VLOOKUP(A16,[1]Лист1!$A:$D,4,0) -> 0 | H16: =F16-G16 -> 677 | I16: 0.25 | J16: 120 | K16: матрица | M16: 637 | N16: =E16-M16 -> -80 | O16: =E16-P16 -> 413 | P16: 144 | Q16: 20 | S16: =O16/5 -> 82.6 | T16: =14*S16-R16-Q16-H16 -> 459.4 | U16: =ROUND(T16+S16,0) -> 542 | W16: =(H16+Q16+R16+U16)/S16 -> 15 | X16: =(H16+Q16+R16)/S16 -> 8.4382567 | Y16: 19.6 | Z16: 119.2 | AA16: 76 | AB16: 40.2 | AC16: 40.4 | AD16: 55.8 | AE16: 48.2 | AF16: 24.2 | AG16: 25.2 | AH16: 30.4 | AI16: плюсом 5 дней | AJ16: =I16*U16 -> 135.5
A17: 5495 ВЕТЧ.С ИНДЕЙКОЙ Папа может п/о 400*6 Останкино | B17: шт | C17: -3 | D17: 646 | E17: 236 | F17: 385 | G17: =VLOOKUP(A17,[1]Лист1!$A:$D,4,0) -> 0 | H17: =F17-G17 -> 385 | I17: 0.4 | J17: 60 | K17: матрица | M17: 335 | N17: =E17-M17 -> -99 | O17: =E17-P17 -> 188 | P17: 48 | Q17: 200 | S17: =O17/5 -> 37.6 | U17: =ROUND(T17,0) -> 0 | W17: =(H17+Q17+R17+U17)/S17 -> 15.558511 | X17: =(H17+Q17+R17)/S17 -> 15.558511 | Y17: 7.4 | Z17: 43.8 | AA17: 40 | AB17: 24.6 | AC17: 22.8 | AD17: 36.8 | AE17: 37 | AF17: 34.8 | AG17: 26.6 | AH17: 22.8 | AJ17: =I17*U17 -> 0
A18: 5544 Сервелат Финский в/к в/у_45с НОВАЯ ОСТАНКИНО | B18: кг | C18: 8.163 | D18: 547.732 | E18: 272.77 | F18: 246.823 | G18: =VLOOKUP(A18,[1]Лист1!$A:$D,4,0) -> 0 | H18: =F18-G18 -> 246.823 | I18: 1 | J18: 45 | K18: матрица | M18: 272.641 | N18: =E18-M18 -> 0.129 | O18: =E18-P18 -> 272.77 | Q18: 120 | S18: =O18/5 -> 54.554 | T18: =14*S18-R18-Q18-H18 -> 396.933 | U18: =V18 -> 500 | V18: =VLOOKUP(A18,[2]Sheet!$A:$U,21,0) -> 500 | W18: =(H18+Q18+R18+U18)/S18 -> 15.889266 | X18: =(H18+Q18+R18)/S18 -> 6.7240349 | Y18: 12.0352 | Z18: 43.8096 | AA18: 38.122 | AB18: 31.1738 | AC18: 36.7068 | AD18: 45.037 | AE18: 38.5836 | AF18: 38.1704 | AG18: 32.511 | AH18: 43.4754 | AJ18: =I18*U18 -> 500
A19: 5708 ПОСОЛЬСКАЯ Папа может с/к в/у ОСТАНКИНО | B19: кг | C19: 17.098 | D19: 61.862 | E19: 18.129 | F19: 60.831 | G19: =VLOOKUP(A19,[1]Лист1!$A:$D,4,0) -> 0 | H19: =F19-G19 -> 60.831 | I19: 1 | J19: 120 | K19: матрица | M19: 43.2 | N19: =E19-M19 -> -25.071 | O19: =E19-P19 -> 18.129 | Q19: 10 | S19: =O19/5 -> 3.6258 | U19: =ROUND(T19,0) -> 0 | W19: =(H19+Q19+R19+U19)/S19 -> 19.535275 | X19: =(H19+Q19+R19)/S19 -> 19.535275 | Y19: 4.1106 | Z19: 11.1694 | AA19: 5.2294 | AB19: 2.7152 | AC19: 5.2648 | AD19: 4.2116 | AE19: 3.5572 | AF19: 3.2544 | AG19: 1.6692 | AH19: 3.0582 | AI19: плюсом 5 дней | AJ19: =I19*U19 -> 0
A20: 5819 Сосиски Папа может 400г Мясные ОСТАНКИНО | B20: шт | C20: 32 | D20: 144 | F20: 176 | G20: =VLOOKUP(A20,[1]Лист1!$A:$D,4,0) -> 144 | H20: =F20-G20 -> 32 | I20: 0.4 | J20: 45 | K20: матрица | M20: 360 | N20: =E20-M20 -> -360 | O20: =E20-P20 -> 0 | Q20: 100 | S20: =O20/5 -> 0 | U20: =ROUND(T20,0) -> 0 | W20: =(H20+Q20+R20+U20)/S20 -> #DIV/0! | X20: =(H20+Q20+R20)/S20 -> #DIV/0! | Y20: 0 | Z20: 0 | AA20: -1.2 | AB20: -0.2 | AC20: -3.8 | AD20: -0.2 | AE20: 5 | AF20: 9.6 | AG20: 3.8 | AH20: 22.2 | AI20: нужно увеличить продажи / 192шт списано (11,08,26) | AJ20: =I20*U20 -> 0
A21: 5851 ЭКСТРА Папа может вар п/о ОСТАНКИНО | B21: кг | C21: -7.115 | D21: 419.729 | E21: 178.711 | F21: 226.472 | G21: =VLOOKUP(A21,[1]Лист1!$A:$D,4,0) -> 0 | H21: =F21-G21 -> 226.472 | I21: 1 | J21: 60 | K21: матрица | M21: 191.058 | N21: =E21-M21 -> -12.347 | O21: =E21-P21 -> 178.711 | Q21: 100 | S21: =O21/5 -> 35.7422 | T21: =14*S21-R21-Q21-H21 -> 173.9188 | U21: 300 | V21: =VLOOKUP(A21,[2]Sheet!$A:$U,21,0) -> 350 | W21: =(H21+Q21+R21+U21)/S21 -> 17.527516 | X21: =(H21+Q21+R21)/S21 -> 9.1340768 | Y21: 24.3264 | Z21: 38.0486 | AA21: 34.2052 | AB21: 22.6152 | AC21: 32.7796 | AD21: 30.8804 | AE21: 43.9718 | AF21: 24.5406 | AG21: 24.433 | AH21: 26.176 | AJ21: =I21*U21 -> 300
A22: 5931 ОХОТНИЧЬЯ Папа может с/к в/у 1/220 8шт. ОСТАНКИНО | B22: шт | C22: 20 | D22: 1089 | E22: 364 | F22: 734 | G22: =VLOOKUP(A22,[1]Лист1!$A:$D,4,0) -> 88 | H22: =F22-G22 -> 646 | I22: 0.22 | J22: 120 | K22: матрица | M22: 679 | N22: =E22-M22 -> -315 | O22: =E22-P22 -> 220 | P22: 144 | Q22: 250 | S22: =O22/5 -> 44 | U22: =ROUND(T22,0) -> 0 | W22: =(H22+Q22+R22+U22)/S22 -> 20.363636 | X22: =(H22+Q22+R22)/S22 -> 20.363636 | Y22: 71.6 | Z22: 133.6 | AA22: 105.8 | AB22: 63.4 | AC22: 72.2 | AD22: 83.4 | AE22: 44.2 | AF22: 39.6 | AG22: 29.2 | AH22: 39 | AI22: плюсом 5 дней | AJ22: =I22*U22 -> 0
A23: 6008 САЛО СОЛЕНОЕ С ЧЕРНЫМ ПЕРЦЕМ мл/к в/у ОСТАНКИНО | B23: кг | C23: 1.116 | D23: 38.06 | E23: 21.042 | F23: 9.022 | G23: =VLOOKUP(A23,[1]Лист1!$A:$D,4,0) -> 0 | H23: =F23-G23 -> 9.022 | I23: 1 | J23: 40 | K23: матрица | M23: 48.1 | N23: =E23-M23 -> -27.058 | O23: =E23-P23 -> 21.042 | Q23: 20 | S23: =O23/5 -> 4.2084 | T23: =14*S23-R23-Q23-H23 -> 29.8956 | U23: =ROUND(T23+S23,0) -> 34 | W23: =(H23+Q23+R23+U23)/S23 -> 14.975288 | X23: =(H23+Q23+R23)/S23 -> 6.8962076 | Y23: 0 | Z23: -0.176 | AA23: -0.27 | AB23: 1.016 | AC23: 0.6252 | AD23: 3.5936 | AE23: 9.972 | AF23: 8.8044 | AG23: 4.5224 | AH23: 2.25 | AI23: 58кг списано (11,08,26) | AJ23: =I23*U23 -> 34
A24: 6025 ВЕТЧ.ФИРМЕННАЯ С ИНДЕЙКОЙ п/о ОСТАНКИНО | B24: кг | C24: 39.21 | F24: 39.21 | G24: =VLOOKUP(A24,[1]Лист1!$A:$D,4,0) -> 0 | H24: =F24-G24 -> 39.21 | I24: 0 | K24: не в матрице | N24: =E24-M24 -> 0 | O24: =E24-P24 -> 0 | Q24: 0 | S24: =O24/5 -> 0 | U24: =ROUND(T24,0) -> 0 | W24: =(H24+Q24+R24+U24)/S24 -> #DIV/0! | X24: =(H24+Q24+R24)/S24 -> #DIV/0! | Y24: 0 | Z24: 2.414 | AA24: 3.625 | AB24: 0 | AC24: 5.444 | AD24: 0 | AE24: 0 | AF24: 0 | AG24: 0 | AH24: 0 | AI24: нужно увеличить продажи!!! / Грация | AJ24: =I24*U24 -> 0
A25: 6220 ГОВЯЖЬЯ папа может вар п/о Останкино | B25: кг | C25: 0.067 | D25: 139.816 | E25: 91.343 | F25: 41.794 | G25: =VLOOKUP(A25,[1]Лист1!$A:$D,4,0) -> 0 | H25: =F25-G25 -> 41.794 | I25: 1 | J25: 60 | K25: матрица | M25: 137.2 | N25: =E25-M25 -> -45.857 | O25: =E25-P25 -> 91.343 | Q25: 80 | S25: =O25/5 -> 18.2686 | T25: =14*S25-R25-Q25-H25 -> 133.9664 | U25: 170 | V25: =VLOOKUP(A25,[2]Sheet!$A:$U,21,0) -> 200 | W25: =(H25+Q25+R25+U25)/S25 -> 15.972434 | X25: =(H25+Q25+R25)/S25 -> 6.6668491 | Y25: 0.2426 | Z25: 10.1114 | AA25: 16.4042 | AB25: 2.424 | AC25: 13.7454 | AD25: 15.652 | AE25: 11.1342 | AF25: 14.0424 | AG25: 14.0364 | AH25: 10.058 | AJ25: =I25*U25 -> 170
A26: 6221 НЕОПОЛИТАНСКИЙ ДУЭТ с/к с/н мгс 1/90 Останкино | B26: шт | C26: 55 | D26: 377 | E26: 128 | F26: 287 | G26: =VLOOKUP(A26,[1]Лист1!$A:$D,4,0) -> 0 | H26: =F26-G26 -> 287 | I26: 0.09 | J26: 60 | K26: матрица | M26: 276 | N26: =E26-M26 -> -148 | O26: =E26-P26 -> 128 | Q26: 200 | S26: =O26/5 -> 25.6 | U26: =ROUND(T26,0) -> 0 | W26: =(H26+Q26+R26+U26)/S26 -> 19.023438 | X26: =(H26+Q26+R26)/S26 -> 19.023438 | Y26: 35.4 | Z26: 48.8 | AA26: 39.6 | AB26: 38.8 | AC26: 13.2 | AD26: 47.8 | AE26: 38.8 | AF26: 20 | AG26: 34.4 | AH26: 30.6 | AJ26: =I26*U26 -> 0
A27: 6222 ИТАЛЬЯНСКОЕ АССОРТИ с/в с/н мгс 1/90 ОСТАНКИНО | B27: шт | C27: 70 | F27: 70 | G27: =VLOOKUP(A27,[1]Лист1!$A:$D,4,0) -> 0 | H27: =F27-G27 -> 70 | I27: 0 | K27: не в матрице | N27: =E27-M27 -> 0 | O27: =E27-P27 -> 0 | Q27: 0 | S27: =O27/5 -> 0 | U27: =ROUND(T27,0) -> 0 | W27: =(H27+Q27+R27+U27)/S27 -> #DIV/0! | X27: =(H27+Q27+R27)/S27 -> #DIV/0! | Y27: 0 | Z27: 0 | AA27: 6 | AB27: 0 | AC27: 4.2 | AD27: 0 | AE27: 0 | AF27: 0 | AG27: 0 | AH27: 0 | AI27: нужно увеличить продажи!!! / Грация | AJ27: =I27*U27 -> 0
A28: 6228 МЯСНОЕ АССОРТИ к/з с/н мгс 1/90 10шт Останкино | B28: шт | C28: 3 | D28: 112 | E28: 61 | F28: 47 | G28: =VLOOKUP(A28,[1]Лист1!$A:$D,4,0) -> 0 | H28: =F28-G28 -> 47 | I28: 0.09 | J28: 45 | K28: матрица | M28: 78 | N28: =E28-M28 -> -17 | O28: =E28-P28 -> 61 | Q28: 80 | S28: =O28/5 -> 12.2 | T28: =14*S28-R28-Q28-H28 -> 43.8 | U28: =ROUND(T28+S28,0) -> 56 | W28: =(H28+Q28+R28+U28)/S28 -> 15 | X28: =(H28+Q28+R28)/S28 -> 10.409836 | Y28: 0.8 | Z28: 1.8 | AA28: 14.2 | AB28: 7.2 | AC28: 6.2 | AD28: 11 | AE28: 14.8 | AF28: 8.2 | AG28: 11 | AH28: 22 | AJ28: =I28*U28 -> 5.04
A29: 6279 КОРЕЙКА ПО-ОСТ.к/в в/с с/н в/у 1/150_45с Останкино | B29: шт | C29: 80 | D29: 32 | E29: 31 | F29: 81 | G29: =VLOOKUP(A29,[1]Лист1!$A:$D,4,0) -> 0 | H29: =F29-G29 -> 81 | I29: 0.15 | J29: 45 | K29: матрица | M29: 159 | N29: =E29-M29 -> -128 | O29: =E29-P29 -> 31 | Q29: 0 | S29: =O29/5 -> 6.2 | U29: =ROUND(T29,0) -> 0 | W29: =(H29+Q29+R29+U29)/S29 -> 13.064516 | X29: =(H29+Q29+R29)/S29 -> 13.064516 | Y29: 0 | Z29: 0 | AA29: 8 | AB29: 2 | AC29: 1.8 | AD29: 2.2 | AE29: 6 | AF29: 8.8 | AG29: 7 | AH29: 9.8 | AI29: нужно увеличить продажи!!! | AJ29: =I29*U29 -> 0
A30: 6303 Мясные Папа может сос п/о мгс 1,5*3 Останкино | B30: кг | C30: -107.374 | D30: 1733.694 | E30: 360.108 | F30: 1119.818 | G30: =VLOOKUP(A30,[1]Лист1!$A:$D,4,0) -> 109.3 | H30: =F30-G30 -> 1010.518 | I30: 1 | J30: 45 | K30: матрица | M30: 439.288 | N30: =E30-M30 -> -79.18 | O30: =E30-P30 -> 247.768 | P30: 112.34 | Q30: 450 | R30: 100 | S30: =O30/5 -> 49.5536 | U30: =ROUND(T30,0) -> 0 | W30: =(H30+Q30+R30+U30)/S30 -> 31.491516 | X30: =(H30+Q30+R30)/S30 -> 31.491516 | Y30: 55.7604 | Z30: 95.4908 | AA30: 113.2006 | AB30: 18.4908 | AC30: 75.1726 | AD30: 78.5144 | AE30: 67.3848 | AF30: 59.207 | AG30: 31.207 | AH30: 62.066 | AJ30: =I30*U30 -> 0
A31: 6325 ДОКТОРСКАЯ ПРЕМИУМ вар п/о 0.4кг 8шт. ОСТАНКИНО | B31: шт | D31: 384 | E31: 215 | F31: 161 | G31: =VLOOKUP(A31,[1]Лист1!$A:$D,4,0) -> 0 | H31: =F31-G31 -> 161 | I31: 0.4 | J31: 60 | K31: матрица | M31: 215 | N31: =E31-M31 -> 0 | O31: =E31-P31 -> 175 | P31: 40 | Q31: 20 | S31: =O31/5 -> 35 | T31: =13*S31-R31-Q31-H31 -> 274 | U31: =ROUND(T31,0) -> 274 | W31: =(H31+Q31+R31+U31)/S31 -> 13 | X31: =(H31+Q31+R31)/S31 -> 5.1714286 | Y31: 3.4 | Z31: 24 | AA31: 24 | AB31: 7.4 | AC31: 16 | AD31: 24.8 | AE31: 16.6 | AF31: 16.6 | AG31: 14.2 | AH31: 22.4 | AJ31: =I31*U31 -> 109.6
A32: 6333 МЯСНАЯ Папа может вар п/о 0.4кг 8шт. ОСТАНКИНО | B32: шт | C32: 25 | D32: 1689 | E32: 775 | F32: 881 | G32: =VLOOKUP(A32,[1]Лист1!$A:$D,4,0) -> 88 | H32: =F32-G32 -> 793 | I32: 0.4 | J32: 60 | K32: матрица | M32: 854 | N32: =E32-M32 -> -79 | O32: =E32-P32 -> 583 | P32: 192 | Q32: 350 | S32: =O32/5 -> 116.6 | T32: =14*S32-R32-Q32-H32 -> 489.4 | U32: =ROUND(T32+S32,0) -> 606 | W32: =(H32+Q32+R32+U32)/S32 -> 15 | X32: =(H32+Q32+R32)/S32 -> 9.8027444 | Y32: 78.6 | Z32: 127.2 | AA32: 120 | AB32: 82.4 | AC32: 83.8 | AD32: 120.6 | AE32: 106.6 | AF32: 74.8 | AG32: 84 | AH32: 80 | AJ32: =I32*U32 -> 242.4
A33: 6364 СЕРВЕЛАТ ЗЕРНИСТЫЙ ПМ в/к в/у 0.35кг ОСТАНКИНО | B33: шт | C33: -1 | F33: -1 | G33: =VLOOKUP(A33,[1]Лист1!$A:$D,4,0) -> 0 | H33: =F33-G33 -> -1 | I33: 0 | K33: не в матрице | L33: 7154 СЕРВЕЛАТ ЗЕРНИСТЫЙ ПМ в/к в/у 0,35кг_50с Останкино | N33: =E33-M33 -> 0 | O33: =E33-P33 -> 0 | Q33: 0 | S33: =O33/5 -> 0 | U33: =ROUND(T33,0) -> 0 | W33: =(H33+Q33+R33+U33)/S33 -> #DIV/0! | X33: =(H33+Q33+R33)/S33 -> #DIV/0! | Y33: 0 | Z33: 0 | AA33: 0 | AB33: 0 | AC33: 0 | AD33: 0 | AE33: 0 | AF33: 0 | AG33: 0 | AH33: 0 | AJ33: =I33*U33 -> 0
A34: 6392 ФИЛЕЙНАЯ Папа может вар п/о 0,4кг ОСТАНКИНО | B34: шт | C34: 9 | D34: 1446 | E34: 656 | F34: 729 | G34: =VLOOKUP(A34,[1]Лист1!$A:$D,4,0) -> 40 | H34: =F34-G34 -> 689 | I34: 0.4 | J34: 60 | K34: матрица | M34: 729 | N34: =E34-M34 -> -73 | O34: =E34-P34 -> 464 | P34: 192 | Q34: 250 | S34: =O34/5 -> 92.8 | T34: =14*S34-R34-Q34-H34 -> 360.2 | U34: =ROUND(T34+S34,0) -> 453 | W34: =(H34+Q34+R34+U34)/S34 -> 15 | X34: =(H34+Q34+R34)/S34 -> 10.118534 | Y34: 62 | Z34: 104.8 | AA34: 105.6 | AB34: 60 | AC34: 94.2 | AD34: 83.8 | AE34: 105 | AF34: 61.8 | AG34: 65.4 | AH34: 87.2 | AJ34: =I34*U34 -> 181.2
A35: 6411 ВЕТЧ.РУБЛЕНАЯ ПМ в/у срез 0.3кг 6шт. ОСТАНКИНО | B35: шт | C35: 148 | D35: 6 | E35: 30 | F35: 118 | G35: =VLOOKUP(A35,[1]Лист1!$A:$D,4,0) -> 0 | H35: =F35-G35 -> 118 | I35: 0 | J35: 45 | K35: вывод | M35: 37 | N35: =E35-M35 -> -7 | O35: =E35-P35 -> 30 | Q35: 0 | S35: =O35/5 -> 6 | U35: =ROUND(T35,0) -> 0 | W35: =(H35+Q35+R35+U35)/S35 -> 19.666667 | X35: =(H35+Q35+R35)/S35 -> 19.666667 | Y35: 5.8 | Z35: 3.8 | AA35: 0 | AB35: 0.4 | AC35: 0 | AD35: 0 | AE35: 0 | AF35: 0 | AG35: 0 | AH35: 0 | AI35: нужно увеличить продажи!!! / новинка | AJ35: =I35*U35 -> 0
A36: 6453 ЭКСТРА Папа может с/к с/н в/у 1/100 14шт. ОСТАНКИНО | B36: шт | C36: 2 | F36: 2 | G36: =VLOOKUP(A36,[1]Лист1!$A:$D,4,0) -> 0 | H36: =F36-G36 -> 2 | I36: 0 | J36: 60 | K36: не в матрице | L36: 7616 ЭКСТРА Папа может с/к с/н в/у 1/100_ ОСТАНКИНО | N36: =E36-M36 -> 0 | O36: =E36-P36 -> 0 | Q36: 0 | S36: =O36/5 -> 0 | U36: =ROUND(T36,0) -> 0 | W36: =(H36+Q36+R36+U36)/S36 -> #DIV/0! | X36: =(H36+Q36+R36)/S36 -> #DIV/0! | Y36: 0 | Z36: 0 | AA36: 0 | AB36: 0 | AC36: 0 | AD36: 0.2 | AE36: -0.4 | AF36: 20.6 | AG36: 34 | AH36: 49 | AI36: ротация на 7616 | AJ36: =I36*U36 -> 0
A37: 6454 АРОМАТНАЯ с/к с/н в/у 1/100 10шт. ОСТАНКИНО | B37: шт | C37: -15 | D37: 15 | G37: =VLOOKUP(A37,[1]Лист1!$A:$D,4,0) -> 0 | H37: =F37-G37 -> 0 | I37: 0 | J37: 60 | K37: не в матрице | L37: 7613 АРОМАТНАЯ с/к с/н в/у 1/100 10шт_Л10 ОСТАНКИНО | N37: =E37-M37 -> 0 | O37: =E37-P37 -> 0 | Q37: 0 | S37: =O37/5 -> 0 | U37: =ROUND(T37,0) -> 0 | W37: =(H37+Q37+R37+U37)/S37 -> #DIV/0! | X37: =(H37+Q37+R37)/S37 -> #DIV/0! | Y37: 0 | Z37: 0 | AA37: 3 | AB37: 0.2 | AC37: -0.2 | AD37: 17 | AE37: 24.6 | AF37: 36.6 | AG37: 34.4 | AH37: 33.8 | AI37: ротация на 7613 | AJ37: =I37*U37 -> 0
A38: 6470 ВЕТЧ.МРАМОРНАЯ в/у_45с ОСТАНКИНО | B38: кг | D38: 96.83 | E38: 82.275 | F38: 14.555 | G38: =VLOOKUP(A38,[1]Лист1!$A:$D,4,0) -> 13.13 | H38: =F38-G38 -> 1.425 | I38: 0 | J38: 45 | K38: не в матрице | M38: 105.9 | N38: =E38-M38 -> -23.625 | O38: =E38-P38 -> 9.695 | P38: 72.58 | Q38: 0 | S38: =O38/5 -> 1.939 | U38: =ROUND(T38,0) -> 0 | W38: =(H38+Q38+R38+U38)/S38 -> 0.7349149 | X38: =(H38+Q38+R38)/S38 -> 0.7349149 | Y38: 2.6938 | Z38: 9.0944 | AA38: 3.9172 | AB38: 0 | AC38: 11.114 | AD38: 13.551 | AE38: 8.172 | AF38: 2.647 | AG38: 0 | AH38: 1.433 | AJ38: =I38*U38 -> 0
A39: 6475 Сосиски Папа может 400г С сыром ОСТАНКИНО | B39: шт | D39: 198 | E39: 82 | F39: 114 | G39: 114 | H39: =F39-G39 -> 0 | I39: 0 | K39: не в матрице | M39: 283 | N39: =E39-M39 -> -201 | O39: =E39-P39 -> 10 | P39: 72 | S39: =O39/5 -> 2 | U39: =ROUND(T39,0) -> 0 | W39: =(H39+Q39+R39+U39)/S39 -> 0 | X39: =(H39+Q39+R39)/S39 -> 0 | Y39: 0 | Z39: 0 | AA39: 0 | AB39: 0 | AC39: 0 | AD39: 0 | AE39: 0 | AF39: 0 | AG39: 0 | AH39: 0 | AJ39: =I39*U39 -> 0
A40: 6495 ВЕТЧ.МРАМОРНАЯ в/у срез 0,3кг 6шт_45с Останкино | B40: шт | C40: 11 | D40: 258 | E40: 125 | F40: 126 | G40: =VLOOKUP(A40,[1]Лист1!$A:$D,4,0) -> 0 | H40: =F40-G40 -> 126 | I40: 0.3 | J40: 45 | K40: матрица | M40: 210 | N40: =E40-M40 -> -85 | O40: =E40-P40 -> 77 | P40: 48 | Q40: 100 | S40: =O40/5 -> 15.4 | U40: =ROUND(T40,0) -> 0 | W40: =(H40+Q40+R40+U40)/S40 -> 14.675325 | X40: =(H40+Q40+R40)/S40 -> 14.675325 | Y40: 16.4 | Z40: 26 | AA40: 22.4 | AB40: 25.8 | AC40: 11.4 | AD40: 21.2 | AE40: 45.2 | AF40: 22.6 | AG40: 12.4 | AH40: 1.4 | AJ40: =I40*U40 -> 0
A41: 6498 МОЛОЧНАЯ Папа может вар п/о ОСТАНКИНО | B41: кг | C41: 439.316 | D41: 514.812 | E41: 189.919 | F41: 754.81 | G41: =VLOOKUP(A41,[1]Лист1!$A:$D,4,0) -> 386.681 | H41: =F41-G41 -> 368.129 | I41: 1 | J41: 60 | K41: матрица | M41: 247.3 | N41: =E41-M41 -> -57.381 | O41: =E41-P41 -> 72.257 | P41: 117.662 | Q41: 302 | R41: 200 | S41: =O41/5 -> 14.4514 | U41: =ROUND(T41,0) -> 0 | W41: =(H41+Q41+R41+U41)/S41 -> 60.210706 | X41: =(H41+Q41+R41)/S41 -> 60.210706 | Y41: 46.3062 | Z41: 46.8828 | AA41: 45.8374 | AB41: 32.807 | AC41: 36.6816 | AD41: 46.652 | AE41: 53.2522 | AF41: 15.2168 | AG41: 15.7242 | AH41: 31.8386 | AI41: нужно увеличить продажи!!! | AJ41: =I41*U41 -> 0
A42: 6527 ШПИКАЧКИ СОЧНЫЕ ПМ сар б/о мгс 1*3 45с ОСТАНКИНО | B42: кг | C42: 1.811 | D42: 120.186 | E42: 92.328 | F42: 22.982 | G42: =VLOOKUP(A42,[1]Лист1!$A:$D,4,0) -> 0 | H42: =F42-G42 -> 22.982 | I42: 1 | J42: 45 | K42: матрица | M42: 97.531 | N42: =E42-M42 -> -5.203 | O42: =E42-P42 -> 92.328 | Q42: 135 | S42: =O42/5 -> 18.4656 | T42: =14*S42-R42-Q42-H42 -> 100.5364 | U42: 160 | V42: =VLOOKUP(A42,[2]Sheet!$A:$U,21,0) -> 200 | W42: =(H42+Q42+R42+U42)/S42 -> 17.220237 | X42: =(H42+Q42+R42)/S42 -> 8.5554761 | Y42: 17.5024 | Z42: 10.8488 | AA42: 17.9328 | AB42: 15.6494 | AC42: 12.671 | AD42: 16.6138 | AE42: 17.7024 | AF42: 10.3396 | AG42: 13.2452 | AH42: 13.0904 | AJ42: =I42*U42 -> 160
...
