Workbook
Name OLE_LINK1: Лист1!$A$516

Sheet Лист1
A1: 1С | B1: 1 | C1: 2 | D1: 3 | E1: 4 | F1: 5 | G1: сроки
A2: Вареники замороженные постные "Благолепные" с картофелем и луком ВЕС ПОКОМ | B2: SU002532 | C2: P002958 | D2: 4301080153 | E2: 4607111036827 | F2: Вареники Благолепные с картофелем и грибами No name Весовые Классическая форма No name 5 кг | G2: =VLOOKUP(E2,[1]Лист1!$D:$M,10,0) -> 90
A3: Вареники Благолепные с картофелем и грибами вес 5 кг МГ | B3: SU002532 | C3: P002958 | D3: 4301080153 | E3: 4607111036827 | F3: Вареники Благолепные с картофелем и грибами No name Весовые Классическая форма No name 5 кг | G3: =VLOOKUP(E3,[1]Лист1!$D:$M,10,0) -> 90
A4: Вареники Благолепные с картофелем и грибами No name Весовые Классическая форма No name 5 кг | B4: SU002532 | C4: P002958 | D4: 4301080153 | E4: 4607111036827 | F4: Вареники Благолепные с картофелем и грибами No name Весовые Классическая форма No name 5 кг | G4: =VLOOKUP(E4,[1]Лист1!$D:$M,10,0) -> 90
A5: Вареники замороженные постные Благолепные с картофелем и грибами классическая форма, ВЕС, ПОКОМ | B5: SU002532 | C5: P002958 | D5: 4301080153 | E5: 4607111036827 | F5: Вареники Благолепные с картофелем и грибами No name Весовые Классическая форма No name 5 кг | G5: =VLOOKUP(E5,[1]Лист1!$D:$M,10,0) -> 90
A6: Вареники замороженные "Благолепные" с картофелем и грибами. ВЕС ПОКОМ | B6: SU002532 | C6: P002958 | D6: 4301080153 | E6: 4607111036827 | F6: Вареники Благолепные с картофелем и грибами No name Весовые Классическая форма No name 5 кг | G6: =VLOOKUP(E6,[1]Лист1!$D:$M,10,0) -> 90
A7: Готовые бельмеши сочные с мясом ТМ Горячая штучка 0,3кг зам ПОКОМ | B7: SU003593 | C7: P004598 | D7: 4301135574 | E7: 4607111033659 | F7: Снеки «Бельмеши сочные с мясом» Фикс.вес 0,3 Пакет ТМ «Горячая штучка» | G7: =VLOOKUP(E7,[1]Лист1!$D:$M,10,0) -> 180
A8: Готовые бельмеши сочные с мясом ТМ Горячая штучка ТС Базовый ассортимент ф/в 0,3 кг НД1 МГ | B8: SU003593 | C8: P004598 | D8: 4301135574 | E8: 4607111033659 | F8: Снеки «Бельмеши сочные с мясом» Фикс.вес 0,3 Пакет ТМ «Горячая штучка» | G8: =VLOOKUP(E8,[1]Лист1!$D:$M,10,0) -> 180
A9: Бельмеши сочные с мясом Базовый ассортимент Фикс.вес 0,3 Лоток Горячая штучка | B9: SU003593 | C9: P004598 | D9: 4301135574 | E9: 4607111033659 | F9: Снеки «Бельмеши сочные с мясом» Фикс.вес 0,3 Пакет ТМ «Горячая штучка» | G9: =VLOOKUP(E9,[1]Лист1!$D:$M,10,0) -> 180
A10: Готовые бельмеши 0,3 кг Горячая штучка Тандер | B10: SU003593 | C10: P004598 | D10: 4301135574 | E10: 4607111033659 | F10: Снеки «Бельмеши сочные с мясом» Фикс.вес 0,3 Пакет ТМ «Горячая штучка» | G10: =VLOOKUP(E10,[1]Лист1!$D:$M,10,0) -> 180
A11: Готовые чебупели с ветчиной и сыром Горячая штучка 0,3кг зам ПОКОМ | B11: SU003889 | C11: P004971 | D11: 4301135793 | E11: 4620207491003 | F11: Снеки «Готовые чебупели с ветчиной и сыром» Фикс.вес 0,24 ТМ «Горячая штучка» | G11: =VLOOKUP(E11,[1]Лист1!$D:$M,10,0) -> #N/A | H11: ротация завода 0,3==0,24
A12: Чебупели с ветчиной и сыром Базовый ассортимент Фикс.вес 0,3 Лоток Горячая штучка | B12: SU003889 | C12: P004971 | D12: 4301135793 | E12: 4620207491003 | F12: Снеки «Готовые чебупели с ветчиной и сыром» Фикс.вес 0,24 ТМ «Горячая штучка» | G12: =VLOOKUP(E12,[1]Лист1!$D:$M,10,0) -> #N/A | H12: ротация завода 0,3==0,24
A13: Готовые чебупели 0,3 кг Горячая Штучка с ветчиной и сыром | B13: SU003889 | C13: P004971 | D13: 4301135793 | E13: 4620207491003 | F13: Снеки «Готовые чебупели с ветчиной и сыром» Фикс.вес 0,24 ТМ «Горячая штучка» | G13: =VLOOKUP(E13,[1]Лист1!$D:$M,10,0) -> #N/A | H13: ротация завода 0,3==0,24
A14: Снеки «Готовые чебупели с ветчиной и сыром» Фикс.вес 0,24 ТМ «Горячая штучка» | B14: SU003889 | C14: P004971 | D14: 4301135793 | E14: 4620207491003 | F14: Снеки «Готовые чебупели с ветчиной и сыром» Фикс.вес 0,24 ТМ «Горячая штучка»
A15: Готовые чебупели с ветчиной и сыром ТМ Горячая штучка флоу-пак 0,24 кг. ПОКОМ | B15: SU003889 | C15: P004971 | D15: 4301135793 | E15: 4620207491003 | F15: Снеки «Готовые чебупели с ветчиной и сыром» Фикс.вес 0,24 ТМ «Горячая штучка»
A16: Чебупели с мясом без свинины Базовый ассортимент Фикс.вес 0,3 Лоток Горячая штучка | B16: SU003892 | C16: P004974 | D16: 4301135768 | E16: 4620207491034 | F16: Снеки «Готовые чебупели с мясом» Фикс.вес 0,24 ТМ «Горячая штучка» | G16: =VLOOKUP(E16,[1]Лист1!$D:$M,10,0) -> #N/A | H16: ротация завода 0,3==0,24
A17: Готовые чебупели с мясом ТМ Горячая штучка Без свинины 0,3 кг ПОКОМ | B17: SU003892 | C17: P004974 | D17: 4301135768 | E17: 4620207491034 | F17: Снеки «Готовые чебупели с мясом» Фикс.вес 0,24 ТМ «Горячая штучка» | G17: =VLOOKUP(E17,[1]Лист1!$D:$M,10,0) -> #N/A | H17: ротация завода 0,3==0,24
A18: Готовые чебупели с мясом ТМ Горячая штучка Без свинины 0,3 кг ПОКОМ | B18: SU003892 | C18: P004974 | D18: 4301135768 | E18: 4620207491034 | F18: Снеки «Готовые чебупели с мясом» Фикс.вес 0,24 ТМ «Горячая штучка» | G18: =VLOOKUP(E18,[1]Лист1!$D:$M,10,0) -> #N/A | H18: ротация завода 0,3==0,24
A19: Готовые чебупели 0,3 кг Горячая штучка с мясом НТУ | B19: SU003892 | C19: P004974 | D19: 4301135768 | E19: 4620207491034 | F19: Снеки «Готовые чебупели с мясом» Фикс.вес 0,24 ТМ «Горячая штучка» | G19: =VLOOKUP(E19,[1]Лист1!$D:$M,10,0) -> #N/A | H19: ротация завода 0,3==0,24
A20: Готовые чебупели с мясом ТМ Горячая штучка флоу-пак 0,24 кг. ПОКОМ | B20: SU003892 | C20: P004974 | D20: 4301135768 | E20: 4620207491034 | F20: Снеки «Готовые чебупели с мясом» Фикс.вес 0,24 ТМ «Горячая штучка»
A21: Готовые чебупели с мясом ТМ Горячая штучка 0,24 кг ПОКОМ | B21: SU003892 | C21: P004974 | D21: 4301135768 | E21: 4620207491034 | F21: Снеки «Готовые чебупели с мясом» Фикс.вес 0,24 ТМ «Горячая штучка»
A22: Готовые чебупели сочные с мясом ТМ Горячая штучка 0,3кг зам ПОКОМ | B22: SU003884 | C22: P004966 | D22: 4301135760 | E22: 4620207491010 | F22: Снеки «Готовые чебупели сочные с мясом» Фикс.вес 0,24 ТМ «Горячая штучка» | G22: =VLOOKUP(E22,[1]Лист1!$D:$M,10,0) -> #N/A | H22: ротация завода 0,3==0,24
A23: Чебупели сочные с мясом Базовый ассортимент Фикс.вес 0,3 Лоток Горячая штучка | B23: SU003884 | C23: P004966 | D23: 4301135760 | E23: 4620207491010 | F23: Снеки «Готовые чебупели сочные с мясом» Фикс.вес 0,24 ТМ «Горячая штучка» | G23: =VLOOKUP(E23,[1]Лист1!$D:$M,10,0) -> #N/A | H23: ротация завода 0,3==0,24
A24: Готовые чебупели 0,3 кг Горячая Штучка сочные с мясом | B24: SU003884 | C24: P004966 | D24: 4301135760 | E24: 4620207491010 | F24: Снеки «Готовые чебупели сочные с мясом» Фикс.вес 0,24 ТМ «Горячая штучка» | G24: =VLOOKUP(E24,[1]Лист1!$D:$M,10,0) -> #N/A | H24: ротация завода 0,3==0,24
A25: Снеки «Готовые чебупели сочные с мясом» Фикс.вес 0,24 ТМ «Горячая штучка» | B25: SU003884 | C25: P004966 | D25: 4301135760 | E25: 4620207491010 | F25: Снеки «Готовые чебупели сочные с мясом» Фикс.вес 0,24 ТМ «Горячая штучка»
A26: Готовые чебупели сочные с мясом ТМ Горячая штучка флоу-пак 0,24 кг ПОКОМ | B26: SU003884 | C26: P004966 | D26: 4301135760 | E26: 4620207491010 | F26: Снеки «Готовые чебупели сочные с мясом» Фикс.вес 0,24 ТМ «Горячая штучка»
A27: Чебупели острые Базовый ассортимент Фикс.вес 0,3 Лоток Горячая штучка | B27: SU003887 | C27: P004969 | D27: 4301135763 | E27: 4620207491027 | F27: Снеки «Готовые чебупели острые с мясом» Фикс.вес 0,24 ТМ «Горячая штучка» | G27: =VLOOKUP(E27,[1]Лист1!$D:$M,10,0) -> #N/A | H27: ротация завода 0,3==0,24
A28: Готовые чебупели 0,3 кг Горячая Штучка острые с мясом | B28: SU003887 | C28: P004969 | D28: 4301135763 | E28: 4620207491027 | F28: Снеки «Готовые чебупели острые с мясом» Фикс.вес 0,24 ТМ «Горячая штучка» | G28: =VLOOKUP(E28,[1]Лист1!$D:$M,10,0) -> #N/A | H28: ротация завода 0,3==0,24
A29: Чебупели острые Базовый ассортимент Фикс.вес 0,3 Лоток Горячая штучка | B29: SU003887 | C29: P004969 | D29: 4301135763 | E29: 4620207491027 | F29: Снеки «Готовые чебупели острые с мясом» Фикс.вес 0,24 ТМ «Горячая штучка» | G29: =VLOOKUP(E29,[1]Лист1!$D:$M,10,0) -> #N/A | H29: ротация завода 0,3==0,24
A30: Готовые чебупели острые с мясом Горячая штучка 0,3 кг зам ПОКОМ | B30: SU003887 | C30: P004969 | D30: 4301135763 | E30: 4620207491027 | F30: Снеки «Готовые чебупели острые с мясом» Фикс.вес 0,24 ТМ «Горячая штучка» | G30: =VLOOKUP(E30,[1]Лист1!$D:$M,10,0) -> #N/A | H30: ротация завода 0,3==0,24
A31: Готовые чебуреки со свининой и говядиной ТМ Горячая штучка ТС Базовый ассортимент 0,36 кг ПОКОМ | B31: SU003613 | C31: P004583 | D31: 4301136079 | E31: 4607025784319 | F31: Чебуреки «Чебуреки со свининой и говядиной» Фикс.вес 0,36 Пакет ТМ «Горячая штучка» | G31: =VLOOKUP(E31,[1]Лист1!$D:$M,10,0) -> 180
A32: Чебуреки со свининой и говядиной 0,36 | B32: SU003613 | C32: P004583 | D32: 4301136079 | E32: 4607025784319 | F32: Чебуреки «Чебуреки со свининой и говядиной» Фикс.вес 0,36 Пакет ТМ «Горячая штучка» | G32: =VLOOKUP(E32,[1]Лист1!$D:$M,10,0) -> 180
A33: Готовые чебуреки со свининой и говядиной Гор.шт.0,36 кг зам. ПОКОМ | B33: SU003613 | C33: P004583 | D33: 4301136079 | E33: 4607025784319 | F33: Чебуреки «Чебуреки со свининой и говядиной» Фикс.вес 0,36 Пакет ТМ «Горячая штучка» | G33: =VLOOKUP(E33,[1]Лист1!$D:$M,10,0) -> 180
A34: Готовые чебуреки 1 уп Горячая Штучка New Box со свининой и говядиной | B34: SU003613 | C34: P004583 | D34: 4301136079 | E34: 4607025784319 | F34: Чебуреки «Чебуреки со свининой и говядиной» Фикс.вес 0,36 Пакет ТМ «Горячая штучка» | G34: =VLOOKUP(E34,[1]Лист1!$D:$M,10,0) -> 180
A35: Готовые чебуреки 0,09 кг Горячая Штучка Шоу-бокс с мясом тара 2 | B35: SU002573 | C35: P004138 | D35: 4301136070 | E35: 4607025784012 | F35: Чебуреки с мясом Базовый ассортимент Штучка 0,09 Пленка Горячая штучка | G35: =VLOOKUP(E35,[1]Лист1!$D:$M,10,0) -> 180
A36: Чебуреки с мясом Базовый ассортимент Штучка 0,09 Пленка Горячая штучка | B36: SU002573 | C36: P004138 | D36: 4301136070 | E36: 4607025784012 | F36: Чебуреки с мясом Базовый ассортимент Штучка 0,09 Пленка Горячая штучка | G36: =VLOOKUP(E36,[1]Лист1!$D:$M,10,0) -> 180
A37: Готовые чебуреки с мясом ТМ Горячая штучка 0,09 кг флоу-пак ПОКОМ | B37: SU002573 | C37: P004138 | D37: 4301136070 | E37: 4607025784012 | F37: Чебуреки с мясом Базовый ассортимент Штучка 0,09 Пленка Горячая штучка | G37: =VLOOKUP(E37,[1]Лист1!$D:$M,10,0) -> 180
A38: Чебуреки «Сочный мегачебурек» Весовой ТМ «No Name» | B38: SU003025 | C38: P003495 | D38: 4301136052 | E38: 4640242180410 | F38: Чебуреки «Сочный мегачебурек» Весовой ТМ «Зареченские» 2,24 кг | G38: =VLOOKUP(E38,[1]Лист1!$D:$M,10,0) -> 180
A39: Сочный мегачебурек ТМ Зареченские ВЕС ПОКОМ | B39: SU003025 | C39: P003495 | D39: 4301136052 | E39: 4640242180410 | F39: Чебуреки «Сочный мегачебурек» Весовой ТМ «Зареченские» 2,24 кг | G39: =VLOOKUP(E39,[1]Лист1!$D:$M,10,0) -> 180
A40: Готовые чебуреки Сочный мегачебурек.Готовые жареные.ВЕС ПОКОМ | B40: SU003025 | C40: P003495 | D40: 4301136052 | E40: 4640242180410 | F40: Чебуреки «Сочный мегачебурек» Весовой ТМ «Зареченские» 2,24 кг | G40: =VLOOKUP(E40,[1]Лист1!$D:$M,10,0) -> 180
...

Sheet Лист2
A1: 003 Колбаса Вязанка с индейкой, вектор ВЕС, ПОКОМ
A2: 009 Колбаса Классическая, Вязанка вектор, ВЕС., ВсхЗв. ПОКОМ
A3: 013 Сардельки Вязанка Стародворские NDX, ВЕС. ПОКОМ
A4: 016 Сосиски Вязанка Молочные, Вязанка вискофан ВЕС.ПОКОМ
A5: 017 Сосиски Вязанка Сливочные, Вязанка амицел ВЕС.ПОКОМ
A6: 018 Сосиски Рубленые, Вязанка вискофан ВЕС.ПОКОМ
A7: 312 Ветчина Филейская ТМ Вязанка ТС Столичная ВЕС ПОКОМ
A8: 313 Колбаса вареная Молокуша ТМ Вязанка в оболочке полиамид. ВЕС ПОКОМ
A9: 314 Колбаса вареная Филейская ТМ Вязанка ТС Классическая в оболочке полиамид. ПОКОМ
A10: 024 Колбаса Классическая, Вязанка вектор 0,5кг, ПОКОМ
A11: 029 Сосиски Венские, Вязанка NDX МГС, 0.5кг, ПОКОМ
A12: 030 Сосиски Вязанка Молочные, Вязанка вискофан МГС, 0.45кг, ПОКОМ
... A72: 323 Колбаса варенокопченая Балыкбургская рубленая ТМ Баварушка срез 0,35 кг ПОКОМ
