Workbook

Sheet 17.10 (3)
A1: МАРИУПОЛЬ | E1: ВСЕГО МАШИН | J1: 4
A2: 46312
A3: Выезд Машин
A4: ИСПРАВНЫЕ АВТО
A5: 1 | B5: 2 | C5: 3 | D5: 4 | E5: 5 | F5: 6 | G5: 7 | H5: 8 | I5: 9 | J5: 10 | K5: 10 | L5: 11
A6: № п/п | B6: Марка | C6: № авто | D6: ФИО водителя | E6: Заполняет механник перед выездом машин | F6: Выехал (время) | G6: количество ТГ (АКБ) | H6: кг | I6: вернулся (время) | J6: Время на маршруте | K6: Не вывезено
E7: Исправность холодильного оборудования | K7: количество ТГ (АКБ) | L7: кг
A8: 1 | B8: Спринтер | C8: Е792СР82 | D8: Дубинин Алексей | E8: Да | F8: 0.35416667 | G8: 29 | H8: 395.534 | I8: 0.58333333 | J8: =I8-F8 -> 0.22916667
A9: 2 | B9: Спринтер | C9: Е827УА82 | D9: Ковальский Дмитрий | E9: Нет | F9: 0.35416667 | G9: 29 | H9: 799.518 | I9: 0.59722222 | J9: =I9-F9 -> 0.24305556
A10: 3 | B10: Спринтер | C10: В952ХК82 | D10: Махонько Игорь | E10: Да | F10: 0.375 | G10: 27 | H10: 450.229 | I10: 0.57291667 | J10: =I10-F10 -> 0.19791667
A11: 4 | B11: Газель | C11: Е765МУ82 | D11: Приходько Виталий | E11: Нет | F11: 0.35069444 | G11: 24 | H11: 596.54 | I11: 0.5625 | J11: =I11-F11 -> 0.21180556
A12: 5 | E12: Нет | J12: =I12-F12 -> 0
A13: 6 | E13: Да
A14: 7
A15: 8
A16: 9
A17: 10
A18: 11
A19: 12
A20: 13
A21: ИТОГО | G21: =SUM(G8:G20) -> 109 | H21: =SUM(H8:H20) -> 2241.821 | K21: =SUM(K8:K20) -> 0 | L21: =SUM(L8:L20) -> 0
A24: НАЙМ АВТО
A25: 1 | B25: 2 | C25: 3 | D25: 4 | E25: 5 | F25: 6 | G25: 7 | H25: 8 | I25: 9
A26: № п/п | B26: Марка | C26: № авто | D26: Стоимость | E26: Выехал (время) | F26: кол-во тт (АКБ) | G26: кг | H26: Вернулся (время) | I26: Время на маршруте
A27: 14 | H27: 0.55208333 | I27: =H27-E27 -> 0.55208333
A28: 15
A29: 16
A31: ИТОГО | F31: =SUM(F30:F30) -> 0 | G31: =SUM(G30:G30) -> 0
A33: Неисправные
A34: 1 | B34: 2 | C34: 3 | D34: 4 | E34: 5 | F34: 6 | G34: 7 | H34: 8 | I34: 9 | J34: 10 | K34: 11 | L34: 12
A35: № п/п | B35: Марка | C35: № авто | D35: ФИО водителя | E35: Заполняет механник перед выездом машин | F35: Дата поломки | G35: сумма ремонта | H35: Ремонт одобрен +/- | I35: Дата постановки на ремонт | J35: Дата окончания ремонта | K35: Оплачено +/- | L35: Причина
E36: Исправность холодильного оборудования
A37: 17
A38: 18
A39: 19
A40: 20
A41: 21
A42: 22
A43: 23
A44: ИТОГО | G44: =SUM(G37:G43) -> 0
...

Sheet 20.10 (2)
A1: МАРИУПОЛЬ | E1: ВСЕГО МАШИН | J1: 5
A2: 46315
A3: Выезд Машин
A4: ИСПРАВНЫЕ АВТО
A5: 1 | B5: 2 | C5: 3 | D5: 4 | E5: 5 | F5: 6 | G5: 7 | H5: 8 | I5: 9 | J5: 10 | K5: 10 | L5: 11
A6: № п/п | B6: Марка | C6: № авто | D6: ФИО водителя | E6: Заполняет механник перед выездом машин | F6: Выехал (время) | G6: количество ТГ (АКБ) | H6: кг | I6: вернулся (время) | J6: Время на маршруте | K6: Не вывезено
E7: Исправность холодильного оборудования | K7: количество ТГ (АКБ) | L7: кг
A8: 1 | B8: Спринтер | C8: Е792СР82 | D8: Дубинин Алексей | E8: Да | F8: 0.32291667 | G8: 16 | H8: 826.281 | I8: 0.58333333 | J8: =I8-F8 -> 0.26041667
A9: 2 | B9: Спринтер | C9: Е827УА82 | D9: Ковальский Дмитрий | E9: Нет | F9: 0.32638889 | G9: 29 | H9: 645.281 | I9: 0.59722222 | J9: =I9-F9 -> 0.27083333
A10: 3 | B10: Спринтер | C10: В952ХК82 | D10: Махонько Игорь | E10: Да | F10: 0.3125 | G10: 29 | H10: 871.766 | I10: 0.57291667 | J10: =I10-F10 -> 0.26041667
A11: 4 | B11: Газель | C11: Е765МУ82 | D11: Приходько Виталий | E11: Нет | F11: 0.30902778 | G11: 12 | H11: 636.06 | I11: 0.5625 | J11: =I11-F11 -> 0.25347222
A21: ИТОГО | G21: =SUM(G8:G20) -> 86 | H21: =SUM(H8:H20) -> 2979.388 | K21: =SUM(K8:K20) -> 0 | L21: =SUM(L8:L20) -> 0
A24: НАЙМ АВТО
A25: 1 | B25: 2 | C25: 3 | D25: 4 | E25: 5 | F25: 6 | G25: 7 | H25: 8 | I25: 9
A26: № п/п | B26: Марка | C26: № авто | D26: Стоимость | E26: Выехал (время) | F26: кол-во тт (АКБ) | G26: кг | H26: Вернулся (время) | I26: Время на маршруте
A27: 5 | B27: Рено | C27: А341МХ | D27: 9000 | E27: 0.32291667 | F27: 7 | G27: 1159.99 | H27: 0.55208333 | I27: =H27-E27 -> 0.22916667
A31: ИТОГО | F31: =SUM(F30:F30) -> 0 | G31: =SUM(G30:G30) -> 0
A33: Неисправные
A34: 1 | B34: 2 | C34: 3 | D34: 4 | E34: 5 | F34: 6 | G34: 7 | H34: 8 | I34: 9 | J34: 10 | K34: 11 | L34: 12
A35: № п/п | B35: Марка | C35: № авто | D35: ФИО водителя | E35: Заполняет механник перед выездом машин | F35: Дата поломки | G35: сумма ремонта | H35: Ремонт одобрен +/- | I35: Дата постановки на ремонт | J35: Дата окончания ремонта | K35: Оплачено +/- | L35: Причина
E36: Исправность холодильного оборудования
A44: ИТОГО | G44: =SUM(G37:G43) -> 0
A46: Сборка
D47: Заказано (день заказа) | E47: Собрано (факт.день сборки) | G47: Выехало (факт день выезда) | I47: Вернулось (факт день выезда)
B48: Поком колбаса | C48: 1872.63 | E48: 1491.602 | G48: 1491.602 | I48: 76.409
B49: Поком заморозка | C49: 1098.25 | E49: 1064.67 | G49: 1064.67 | I49: 4.18
B50: Останкино | C50: 1665.02 | E50: 1509.12 | G50: 1509.12 | I50: 0
B51: Всего | C51: =SUM(C48:D50) -> 4635.9 | E51: =SUM(E48:E50) -> 4065.392 | G51: =G48+G49+G50 -> 4065.392 | I51: =SUM(I48:I50) -> 80.589
A54: Дефицит
A55: № | B55: Наименование позиций | J55: КГ
A56: 1 | B56: 5483 ЭКСТРА Папа может с/к в/у 1/250 8шт. ОСТАНКИНО | J56: 4
A57: 2 | B57: 5495 ВЕТЧ.С ИНДЕЙКОЙ Папа может п/о 400*6 Останкино | J57: 4.8
A58: 3 | B58: 6325 ДОКТОРСКАЯ ПРЕМИУМ вар п/о 0.4кг 8шт. ОСТАНКИНО | J58: 4.8
A59: 4 | B59: 6392 ФИЛЕЙНАЯ Папа может вар п/о 0,4кг ОСТАНКИНО | J59: 6.4
A60: 5 | B60: 6470 ВЕТЧ.МРАМОРНАЯ в/у_45с ОСТАНКИНО | J60: 16.321
A61: 6 | B61: 6475 Сосиски Папа может 400г С сыром ОСТАНКИНО | J61: 4.4
A62: 7 | B62: 6498 МОЛОЧНАЯ Папа может вар п/о ОСТАНКИНО | J62: 5.955
A63: 8 | B63: 6616 МОЛОЧНЫЕ КЛАССИЧЕСКИЕ сос п/о в/у 0,3 кг Останкино | J63: 18
A64: 9 | B64: 6787 СЕРВЕЛАТ КРЕМЛЕВСКИЙ в/к в/у 0,33кг 8шт Останкино | J64: 5.28
A65: 10 | B65: 6829 МОЛОЧНЫЕ КЛАССИЧЕСКИЕ сос п/о мгс 2*4 С Останккино | J65: 12
...

Sheet 21.10 (2)
A1: МАРИУПОЛЬ | E1: ВСЕГО МАШИН | J1: 5
A2: 46316
A3: Выезд Машин
A4: ИСПРАВНЫЕ АВТО
A5: 1 | B5: 2 | C5: 3 | D5: 4 | E5: 5 | F5: 6 | G5: 7 | H5: 8 | I5: 9 | J5: 10 | K5: 10 | L5: 11
A6: № п/п | B6: Марка | C6: № авто | D6: ФИО водителя | E6: Заполняет механник перед выездом машин | F6: Выехал (время) | G6: количество ТГ (АКБ) | H6: кг | I6: вернулся (время) | J6: Время на маршруте | K6: Не вывезено
E7: Исправность холодильного оборудования | K7: количество ТГ (АКБ) | L7: кг
A8: 1 | B8: Спринтер | C8: Е792СР82 | D8: Дубинин Алексей | E8: Да | F8: 0.3125 | G8: 20 | H8: 770.501 | I8: 0.61805556 | J8: =I8-F8 -> 0.30555556
A9: 2 | B9: Спринтер | C9: Е827УА82 | D9: Ковальский Дмитрий | E9: Нет | F9: 0.30208333 | G9: 28 | H9: 936.176 | I9: 0.625 | J9: =I9-F9 -> 0.32291667
A10: 3 | B10: Спринтер | C10: В952ХК82 | D10: Махонько Игорь | E10: Да | F10: 0.31944444 | G10: 32 | H10: 852.574 | I10: 0.66666667 | J10: =I10-F10 -> 0.34722222
A11: 4 | B11: Газель | C11: Е765МУ82 | D11: Приходько Виталий | E11: Нет | F11: 0.31597222 | G11: 16 | H11: 686.728 | I11: 0.67708333 | J11: =I11-F11 -> 0.36111111
A21: ИТОГО | G21: =SUM(G8:G20) -> 96 | H21: =SUM(H8:H20) -> 3245.979 | K21: =SUM(K8:K20) -> 0 | L21: =SUM(L8:L20) -> 0
N23: =SUM(N49) -> 0
A24: НАЙМ АВТО
A25: 1 | B25: 2 | C25: 3 | D25: 4 | E25: 5 | F25: 6 | G25: 7 | H25: 8 | I25: 9
A26: № п/п | B26: Марка | C26: № авто | D26: Стоимость | E26: Выехал (время) | F26: кол-во тт (АКБ) | G26: кг | H26: Вернулся (время) | I26: Время на маршруте
A27: 5 | B27: Фольцваген | C27: Р633ВК18 | D27: 9000 | E27: 0.30555556 | F27: 25 | G27: 918.001 | H27: 0.67361111 | I27: =H27-E27 -> 0.36805556
A31: ИТОГО | G31: 918
A33: Неисправные
A34: 1 | B34: 2 | C34: 3 | D34: 4 | E34: 5 | F34: 6 | G34: 7 | H34: 8 | I34: 9 | J34: 10 | K34: 11 | L34: 12
A35: № п/п | B35: Марка | C35: № авто | D35: ФИО водителя | E35: Заполняет механник перед выездом машин | F35: Дата поломки | G35: сумма ремонта | H35: Ремонт одобрен +/- | I35: Дата постановки на ремонт | J35: Дата окончания ремонта | K35: Оплачено +/- | L35: Причина
E36: Исправность холодильного оборудования
A44: ИТОГО | G44: =SUM(G37:G43) -> 0
A46: Сборка
D47: Заказано (день заказа) | E47: Собрано (факт.день сборки) | G47: Выехало (факт день выезда) | I47: Вернулось (факт день выезда)
B48: Поком колбаса | C48: 2087.02 | E48: 2031.65 | G48: 2031.65 | I48: 5.86
B49: Поком заморозка | C49: 1283.95 | E49: 1195.79 | G49: 1195.79 | I49: 0
B50: Останкино | C50: 1012.97 | E50: 936.54 | G50: 936.54 | I50: 0.41
B51: Всего | C51: =SUM(C48:D50) -> 4383.94 | E51: =SUM(E48:E50) -> 4163.98 | G51: =G48+G49+G50 -> 4163.98 | I51: =SUM(I48:I50) -> 6.27
A54: Дефицит
A55: № | B55: Наименование позиций | J55: КГ
A56: 1 | B56: 6470 ВЕТЧ.МРАМОРНАЯ в/у_45с ОСТАНКИНО | J56: 10
A57: 2 | B57: 6475 Сосиски Папа может 400г С сыром ОСТАНКИНО | J57: 6.4
A58: 3 | B58: 6498 МОЛОЧНАЯ Папа может вар п/о ОСТАНКИНО | J58: 10.977
A59: 4 | B59: 6616 МОЛОЧНЫЕ КЛАССИЧЕСКИЕ сос п/о в/у 0,3 кг Останкино | J59: 6.3
A60: 5 | B60: 6661 СОЧНЫЙ ГРИЛЬ ПМ сос п/о мгс 1,5*4_Маяк Останкино | J60: 7.5
A61: 6 | B61: 6787 СЕРВЕЛАТ КРЕМЛЕВСКИЙ в/к в/у 0,33кг 8шт Останкино | J61: 5.28
A62: 7 | B62: 7070 СОЧНЫЕ ПМ сос п/о 1,5*4_А_50с Останкино | J62: 7.322
A63: 8 | B63: 7489 СЫРРРВЕЛАТ Папа Может в/к в/у 0,28кг 8шт. ОСТАНКИНО | J63: 8.12
A64: 9 | B64: 030 Сосиски Вязанка Молочные, Вязанка вискофан МГС, 0.45кг, ПОКОМ | J64: 24.3
...

Sheet 22.10
A1: МАРИУПОЛЬ | E1: ВСЕГО МАШИН | J1: 4
A2: 46317
A3: Выезд Машин
A4: ИСПРАВНЫЕ АВТО
A5: 1 | B5: 2 | C5: 3 | D5: 4 | E5: 5 | F5: 6 | G5: 7 | H5: 8 | I5: 9 | J5: 10 | K5: 10 | L5: 11
A6: № п/п | B6: Марка | C6: № авто | D6: ФИО водителя | E6: Заполняет механник перед выездом машин | F6: Выехал (время) | G6: количество ТГ (АКБ) | H6: кг | I6: вернулся (время) | J6: Время на маршруте | K6: Не вывезено
E7: Исправность холодильного оборудования | K7: количество ТГ (АКБ) | L7: кг
A8: 1 | B8: Спринтер | C8: Е792СР82 | D8: Дубинин Алексей | E8: Да | F8: 0.30208333 | G8: 12 | H8: 998.059 | I8: 0.625 | J8: =I8-F8 -> 0.32291667
A9: 2 | B9: Спринтер | C9: Е827УА82 | D9: Ковальский Дмитрий | E9: Нет | F9: 0.29861111 | G9: 23 | H9: 657.12 | I9: 0.63194444 | J9: =I9-F9 -> 0.33333333
A10: 3 | B10: Спринтер | C10: В952ХК82 | D10: Махонько Игорь | E10: Да | F10: 0.32638889 | G10: 15 | H10: 841.389 | I10: 0.65277778 | J10: =I10-F10 -> 0.32638889
A11: 4 | B11: Газель | C11: Е765МУ82 | D11: Приходько Виталий | E11: Нет | F11: 0.31944444 | G11: 35 | H11: 816.761 | I11: 0.61805556 | J11: =I11-F11 -> 0.29861111
A21: ИТОГО | G21: =SUM(G8:G20) -> 85 | H21: =SUM(H8:H20) -> 3313.329 | K21: =SUM(K8:K20) -> 0 | L21: =SUM(L8:L20) -> 0
N23: =SUM(N49) -> 0
A24: НАЙМ АВТО
A25: 1 | B25: 2 | C25: 3 | D25: 4 | E25: 5 | F25: 6 | G25: 7 | H25: 8 | I25: 9
A26: № п/п | B26: Марка | C26: № авто | D26: Стоимость | E26: Выехал (время) | F26: кол-во тт (АКБ) | G26: кг | H26: Вернулся (время) | I26: Время на маршруте
A31: ИТОГО | F31: =SUM(F30:F30) -> 0 | G31: =SUM(G27:G30) -> 0
A33: Неисправные
A34: 1 | B34: 2 | C34: 3 | D34: 4 | E34: 5 | F34: 6 | G34: 7 | H34: 8 | I34: 9 | J34: 10 | K34: 11 | L34: 12
A35: № п/п | B35: Марка | C35: № авто | D35: ФИО водителя | E35: Заполняет механник перед выездом машин | F35: Дата поломки | G35: сумма ремонта | H35: Ремонт одобрен +/- | I35: Дата постановки на ремонт | J35: Дата окончания ремонта | K35: Оплачено +/- | L35: Причина
E36: Исправность холодильного оборудования
A44: ИТОГО | G44: =SUM(G37:G43) -> 0
A46: Сборка
D47: Заказано (день заказа) | E47: Собрано (факт.день сборки) | G47: Выехало (факт день выезда) | I47: Вернулось (факт день выезда)
B48: Поком колбаса | C48: 1917.5 | E48: 1669.075 | G48: 1669.075 | I48: 28.26
B49: Поком заморозка | C49: 1007.66 | E49: 873.78 | G49: 873.78 | I49: 50.61
B50: Останкино | C50: 884.88 | E50: 754.33 | G50: 754.33 | I50: 0
B51: Всего | C51: =SUM(C48:D50) -> 3810.04 | E51: =SUM(E48:E50) -> 3297.185 | G51: =G48+G49+G50 -> 3297.185 | I51: =SUM(I48:J50) -> 78.87
A54: Дефицит
A55: № | B55: Наименование позиций | J55: КГ
A56: 1 | B56: 005 Колбаса Докторская ГОСТ, Вязанка вектор,ВЕС. ПОКОМ | J56: 23.6
A57: 2 | B57: 032 Сосиски Вязанка Сливочные, Вязанка амицел МГС, 0.45кг, ПОКОМ | J57: 18.9
A58: 3 | B58: 225 Колбаса Дугушка со шпиком, ВЕС, ТМ Стародворье ПОКОМ | J58: 8.2
A59: 4 | B59: 239 Колбаса Салями запеч Дугушка, оболочка вектор, ВЕС, ТМ Стародворье ПОКОМ | J59: 22.28
A60: 5 | B60: 255 Сосиски Молочные для завтрака ТМ Особый рецепт, п/а МГС, ВЕС, ТМ Стародворье ПОКОМ | J60: 6.124
A61: 6 | B61: 301 Сосиски Сочинки по-баварски с сыром, 0.4кг, ТМ Стародворье ПОКОМ | J61: 10.8
A62: 7 | B62: 302 Сосиски Сочинки по-баварски, 0.4кг, ТМ Стародворье ПОКОМ | J62: 28.8
A63: 8 | B63: 305 Колбаса Сервелат Мясорубский с мелкорубленным окороком в/у ТМ Стародворье ВЕС ПОКОМ | J63: 2.177
A64: 9 | B64: 312 Ветчина Филейская ВЕС ТМ Вязанка ТС Столичная ПОКОМ | J64: 4.159
A65: 10 | B65: 344 Колбаса Сочинка по-европейски с сочной грудинкой ТМ Стародворье, ВЕС ПОКОМ | J65: 4
...

Sheet 23.10
A1: МАРИУПОЛЬ | E1: ВСЕГО МАШИН | J1: 3
A2: 46318
A3: Выезд Машин
A4: ИСПРАВНЫЕ АВТО
A5: 1 | B5: 2 | C5: 3 | D5: 4 | E5: 5 | F5: 6 | G5: 7 | H5: 8 | I5: 9 | J5: 10 | K5: 10 | L5: 11
A6: № п/п | B6: Марка | C6: № авто | D6: ФИО водителя | E6: Заполняет механник перед выездом машин | F6: Выехал (время) | G6: количество ТГ (АКБ) | H6: кг | I6: вернулся (время) | J6: Время на маршруте | K6: Не вывезено
E7: Исправность холодильного оборудования | K7: количество ТГ (АКБ) | L7: кг
A8: 1 | B8: Спринтер | C8: Е792СР82 | D8: Дубинин Алексей | E8: Да | J8: =I8-F8 -> 0
A9: 2 | B9: Спринтер | C9: Е827УА82 | D9: Ковальский Дмитрий | E9: Нет | F9: 0.31597222 | G9: 13 | H9: 509.411 | J9: =I9-F9 -> -0.31597222
A10: 3 | B10: Спринтер | C10: В952ХК82 | D10: Махонько Игорь | E10: Да | F10: 0.32291667 | G10: 22 | H10: 630.796 | J10: =I10-F10 -> -0.32291667
A11: 4 | B11: Газель | C11: Е765МУ82 | D11: Приходько Виталий | E11: Нет | F11: 0.32638889 | G11: 17 | H11: 421.645 | J11: =I11-F11 -> -0.32638889
A21: ИТОГО | G21: =SUM(G8:G20) -> 52 | H21: =SUM(H8:H20) -> 1561.852 | K21: =SUM(K8:K20) -> 0 | L21: =SUM(L8:L20) -> 0
N23: =SUM(N49) -> 0
A24: НАЙМ АВТО
A25: 1 | B25: 2 | C25: 3 | D25: 4 | E25: 5 | F25: 6 | G25: 7 | H25: 8 | I25: 9
A26: № п/п | B26: Марка | C26: № авто | D26: Стоимость | E26: Выехал (время) | F26: кол-во тт (АКБ) | G26: кг | H26: Вернулся (время) | I26: Время на маршруте
A31: ИТОГО | F31: =SUM(F30:F30) -> 0 | G31: =SUM(G27:G30) -> 0
A33: Неисправные
A34: 1 | B34: 2 | C34: 3 | D34: 4 | E34: 5 | F34: 6 | G34: 7 | H34: 8 | I34: 9 | J34: 10 | K34: 11 | L34: 12
A35: № п/п | B35: Марка | C35: № авто | D35: ФИО водителя | E35: Заполняет механник перед выездом машин | F35: Дата поломки | G35: сумма ремонта | H35: Ремонт одобрен +/- | I35: Дата постановки на ремонт | J35: Дата окончания ремонта | K35: Оплачено +/- | L35: Причина
E36: Исправность холодильного оборудования
A44: ИТОГО | G44: =SUM(G37:G43) -> 0
A46: Сборка
D47: Заказано (день заказа) | E47: Собрано (факт.день сборки) | G47: Выехало (факт день выезда) | I47: Вернулось (факт день выезда)
B48: Поком колбаса | C48: 964.58 | E48: 673.33 | G48: 673.33
B49: Поком заморозка | C49: 435.33 | E49: 410.26 | G49: 410.26
B50: Останкино | C50: 669.04 | E50: 479.017 | G50: 479.017
B51: Всего | C51: =SUM(C48:D50) -> 2068.95 | E51: =SUM(E48:E50) -> 1562.607 | G51: =G48+G49+G50 -> 1562.607 | I51: =SUM(I48:I50) -> 0
A54: Дефицит
A55: № | B55: Наименование позиций | J55: КГ
A56: 1 | B56: 5931 ОХОТНИЧЬЯ Папа может с/к в/у 1/220 8шт. ОСТАНКИНО | J56: 9.68
A57: 2 | B57: 6209 Блинчики с куриным мясом пл. 1/350 зам. ОСТАНКИНО | J57: 4.2
A58: 3 | B58: 6498 МОЛОЧНАЯ Папа может вар п/о ОСТАНКИНО | J58: 53
A59: 4 | B59: 6550 МЯСНЫЕ Папа может сар б/о мгс 1*3 О 45с Останкино | J59: 3.948
A60: 5 | B60: 6616 МОЛОЧНЫЕ КЛАССИЧЕСКИЕ сос п/о в/у 0,3 кг Останкино | J60: 11.7
A61: 6 | B61: 6620 РЕБРЫШКИ к/в в/у_30с Останкино | J61: 9
A62: 7 | B62: 6724 МОЛОЧНЫЕ ПМ сос п/о мгс 0,41кг 10шт Останкино | J62: 14.35
A63: 8 | B63: 6787 СЕРВЕЛАТ КРЕМЛЕВСКИЙ в/к в/у 0,33кг 8шт Останкино | J63: 3.63
A64: 9 | B64: 7066 СОЧНЫЕ ПМ сос п/о мгс 0,41кг 10шт 50с Останкино | J64: 13.94
A65: 10 | B65: 7070 СОЧНЫЕ ПМ сос п/о 1,5*4_А_50с Останкино | J65: 15
...

Sheet 24.10
A1: МАРИУПОЛЬ | E1: ВСЕГО МАШИН | J1: 3
A2: 46319
A3: Выезд Машин
A4: ИСПРАВНЫЕ АВТО
A5: 1 | B5: 2 | C5: 3 | D5: 4 | E5: 5 | F5: 6 | G5: 7 | H5: 8 | I5: 9 | J5: 10 | K5: 10 | L5: 11
A6: № п/п | B6: Марка | C6: № авто | D6: ФИО водителя | E6: Заполняет механник перед выездом машин | F6: Выехал (время) | G6: количество ТГ (АКБ) | H6: кг | I6: вернулся (время) | J6: Время на маршруте | K6: Не вывезено
E7: Исправность холодильного оборудования | K7: количество ТГ (АКБ) | L7: кг
A8: 1 | B8: Спринтер | C8: Е792СР82 | D8: Дубинин Алексей | E8: Да | F8: 0 | J8: =I8-F8 -> 0
A9: 2 | B9: Спринтер | C9: Е827УА82 | D9: Ковальский Дмитрий | E9: Нет | F9: 0.30555556 | G9: 30 | H9: 976.97 | I9: 0.70486111 | J9: =I9-F9 -> 0.39930556
A10: 3 | B10: Спринтер | C10: В952ХК82 | D10: Махонько Игорь | E10: Да | F10: 0.32638889 | G10: 33 | H10: 584.154 | I10: 0.69791667 | J10: =I10-F10 -> 0.37152778
A11: 4 | B11: Газель | C11: Е765МУ82 | D11: Приходько Виталий | E11: Нет | F11: 0.31597222 | G11: 18 | H11: 596.77 | I11: 0.71527778 | J11: =I11-F11 -> 0.39930556
A21: ИТОГО | G21: =SUM(G8:G20) -> 81 | H21: =SUM(H8:H20) -> 2157.894 | K21: =SUM(K8:K20) -> 0 | L21: =SUM(L8:L20) -> 0
N23: =SUM(N49) -> 0
A24: НАЙМ АВТО
A25: 1 | B25: 2 | C25: 3 | D25: 4 | E25: 5 | F25: 6 | G25: 7 | H25: 8 | I25: 9
A26: № п/п | B26: Марка | C26: № авто | D26: Стоимость | E26: Выехал (время) | F26: кол-во тт (АКБ) | G26: кг | H26: Вернулся (время) | I26: Время на маршруте
A31: ИТОГО | F31: =SUM(F30:F30) -> 0 | G31: =SUM(G27:G30) -> 0
A33: Неисправные
A34: 1 | B34: 2 | C34: 3 | D34: 4 | E34: 5 | F34: 6 | G34: 7 | H34: 8 | I34: 9 | J34: 10 | K34: 11 | L34: 12
A35: № п/п | B35: Марка | C35: № авто | D35: ФИО водителя | E35: Заполняет механник перед выездом машин | F35: Дата поломки | G35: сумма ремонта | H35: Ремонт одобрен +/- | I35: Дата постановки на ремонт | J35: Дата окончания ремонта | K35: Оплачено +/- | L35: Причина
E36: Исправность холодильного оборудования
A44: ИТОГО | G44: =SUM(G37:G43) -> 0
A46: Сборка
D47: Заказано (день заказа) | E47: Собрано (факт.день сборки) | G47: Выехало (факт день выезда) | I47: Вернулось (факт день выезда)
B48: Поком колбаса | C48: 1399.34 | E48: 1219.773 | G48: 1219.773
B49: Поком заморозка | C49: 342.98 | E49: 302.19 | G49: 302.19
B50: Останкино | C50: 1330.67 | E50: 635.93 | G50: 635.93
B51: Всего | I51: =SUM(I48:I50) -> 0
A54: Дефицит
A55: № | B55: Наименование позиций | J55: КГ
A56: 1 | B56: 005 Колбаса Докторская ГОСТ, Вязанка вектор,ВЕС. ПОКОМ | J56: 5.647
A57: 2 | B57: 016 Сосиски Вязанка Молочные, Вязанка вискофан ВЕС.ПОКОМ | J57: 29.064
A58: 3 | B58: 017 Сосиски Вязанка Сливочные, Вязанка амицел ВЕС.ПОКОМ | J58: 7.248
A59: 4 | B59: 200 Ветчина Дугушка ТМ Стародворье, вектор в/у ПОКОМ | J59: 7.675
A60: 5 | B60: 247 Сардельки Нежные, ВЕС. ПОКОМ | J60: 6.9
A61: 6 | B61: 255 Сосиски Молочные для завтрака ТМ Особый рецепт, п/а МГС, ВЕС, ТМ Стародворье ПОКОМ | J61: 6.5
A62: 7 | B62: 273 Сосиски Сочинки с сочной грудинкой, МГС 0.4кг, ПОКОМ | J62: 18.4
A63: 8 | B63: 312 Ветчина Филейская ВЕС ТМ Вязанка ТС Столичная ПОКОМ | J63: 7.8
A64: 9 | B64: 335 Колбаса Сливушка ТМ Вязанка. ВЕС. ПОКОМ | J64: 9.224
A65: 10 | B65: 364 Сардельки Филейские Вязанка ВЕС NDX ТМ Вязанка ПОКОМ | J65: 5.6
...

Sheet 27.10
A1: МАРИУПОЛЬ | E1: ВСЕГО МАШИН | J1: 4
A2: 46322
A3: Выезд Машин
A4: ИСПРАВНЫЕ АВТО
A5: 1 | B5: 2 | C5: 3 | D5: 4 | E5: 5 | F5: 6 | G5: 7 | H5: 8 | I5: 9 | J5: 10 | K5: 10 | L5: 11
A6: № п/п | B6: Марка | C6: № авто | D6: ФИО водителя | E6: Заполняет механник перед выездом машин | F6: Выехал (время) | G6: количество ТГ (АКБ) | H6: кг | I6: вернулся (время) | J6: Время на маршруте | K6: Не вывезено
E7: Исправность холодильного оборудования | K7: количество ТГ (АКБ) | L7: кг
A8: 1 | B8: Спринтер | C8: Е792СР82 | D8: Дубинин Алексей | E8: Да | F8: 0.3125 | G8: 27 | H8: 956.448 | I8: 0.67361111
A9: 2 | B9: Спринтер | C9: Е827УА82 | D9: Ковальский Дмитрий | E9: Нет | F9: 0.30555556 | G9: 23 | H9: 801.96 | I9: 0.68055556 | J9: 0.375
A10: 3 | B10: Спринтер | C10: В952ХК82 | D10: Махонько Игорь | E10: Да | F10: 0.29166667 | G10: 31 | H10: 918.882 | I10: 0.64583333 | J10: 0.35416667
A11: 4 | B11: Газель | C11: Е765МУ82 | D11: Приходько Виталий | E11: Нет | F11: 0.28472222 | G11: 13 | H11: 706.535 | I11: 0.55902778 | J11: =SUM(F11:I11) -> 720.37875
A21: ИТОГО | G21: =SUM(G8:G20) -> 94 | H21: =SUM(H8:H20) -> 3383.825 | K21: =SUM(K8:K20) -> 0 | L21: =SUM(L8:L20) -> 0
A24: НАЙМ АВТО
A25: 1 | B25: 2 | C25: 3 | D25: 4 | E25: 5 | F25: 6 | G25: 7 | H25: 8 | I25: 9
A26: № п/п | B26: Марка | C26: № авто | D26: Стоимость | E26: Выехал (время) | F26: кол-во тт (АКБ) | G26: кг | H26: Вернулся (время) | I26: Время на маршруте
A31: ИТОГО | F31: =SUM(F30:F30) -> 0 | G31: =SUM(G27:G30) -> 0
A33: Неисправные
A34: 1 | B34: 2 | C34: 3 | D34: 4 | E34: 5 | F34: 6 | G34: 7 | H34: 8 | I34: 9 | J34: 10 | K34: 11 | L34: 12
A35: № п/п | B35: Марка | C35: № авто | D35: ФИО водителя | E35: Заполняет механник перед выездом машин | F35: Дата поломки | G35: сумма ремонта | H35: Ремонт одобрен +/- | I35: Дата постановки на ремонт | J35: Дата окончания ремонта | K35: Оплачено +/- | L35: Причина
E36: Исправность холодильного оборудования
A44: ИТОГО | G44: =SUM(G37:G43) -> 0
A46: Сборка
D47: Заказано (день заказа) | E47: Собрано (факт.день сборки) | G47: Выехало (факт день выезда) | I47: Вернулось (факт день выезда)
B48: Поком колбаса | C48: 1417.52 | E48: 1348.602 | G48: 1348.602 | I48: 52.62
B49: Поком заморозка | C49: 1010.26 | E49: 915.19 | G49: 915.19 | I49: 0
B50: Останкино | C50: 1568.88 | E50: 1120.03 | G50: 1120.03 | I50: 29.682
B51: Всего | C51: =SUM(C48:D50) -> 3996.66 | E51: =SUM(E48:F50) -> 3383.822 | G51: =SUM(G48:H50) -> 3383.822 | I51: =SUM(I48:I50) -> 82.302
A54: Дефицит
A55: № | B55: Наименование позиций | J55: КГ
A56: 1 | B56: 201 Ветчина Нежная ТМ Особый рецепт, (2,5кг), ПОКОМ | J56: 7.2
A57: 2 | B57: 215 Колбаса Докторская ГОСТ Дугушка, ВЕС, ТМ Стародворье ПОКОМ | J57: 17.5
A58: 3 | B58: 225 Колбаса Дугушка со шпиком, ВЕС, ТМ Стародворье ПОКОМ | J58: 9.5
A59: 4 | B59: 273 Сосиски Сочинки с сочной грудинкой, МГС 0.4кг, ПОКОМ | J59: 5.4
A60: 5 | B60: 449 Колбаса Дугушка Стародворская ВЕС ТС Дугушка ПОКОМ | J60: 13.2
A61: 6 | B61: 452 Колбаса Со шпиком ВЕС большой батон ТМ Особый рецепт ПОКОМ | J61: 3.774
A62: 7 | B62: 456 Колбаса Филейная ТМ Особый рецепт ВЕС большой батон ПОКОМ | J62: 15
A63: 8 | B63: 457 Колбаса Молочная ТМ Особый рецепт ВЕС большой батон ПОКОМ | J63: 12.5
A64: 9 | B64: 556 Колбаса Сервелат Ореховый ТМ Вязанка в оболочке фиброуз в вакуумной упаковке, ВЕС ПОКОМ | J64: 14.894
A65: 10 | B65: 557 Колбаса Сервелат Финский ТМ Вязанка в оболочке фиброуз в вакуумной упаковке, ВЕС ПОКОМ | J65: 3.9
A66: 11 | B66: 4813 ФИЛЕЙНАЯ Папа может вар п/о_Л ОСТАНКИНО | J66: 4.386
...

Sheet 28.10
A1: МАРИУПОЛЬ | E1: ВСЕГО МАШИН | J1: 5
A2: 46323
A3: Выезд Машин
A4: ИСПРАВНЫЕ АВТО
A5: 1 | B5: 2 | C5: 3 | D5: 4 | E5: 5 | F5: 6 | G5: 7 | H5: 8 | I5: 9 | J5: 10 | K5: 10 | L5: 11
A6: № п/п | B6: Марка | C6: № авто | D6: ФИО водителя | E6: Заполняет механник перед выездом машин | F6: Выехал (время) | G6: количество ТГ (АКБ) | H6: кг | I6: вернулся (время) | J6: Время на маршруте | K6: Не вывезено
E7: Исправность холодильного оборудования | K7: количество ТГ (АКБ) | L7: кг
A8: 1 | B8: Спринтер | C8: Е792СР82 | D8: Дубинин Алексей | E8: Да | F8: 0.30208333 | G8: 30 | H8: 956.735 | I8: 0.75 | J8: =I8-F8 -> 0.44791667
A9: 2 | B9: Спринтер | C9: Е827УА82 | D9: Ковальский Дмитрий | E9: Нет | F9: 0.30555556 | G9: 32 | H9: 1086.252 | I9: 0.6875 | J9: =I9-F9 -> 0.38194444
A10: 3 | B10: Спринтер | C10: В952ХК82 | D10: Махонько Игорь | E10: Да | F10: 0.3125 | G10: 39 | H10: 1149.666 | I10: 0.71527778 | J10: =I10-F10 -> 0.40277778
A11: 4 | B11: Газель | C11: Е765МУ82 | D11: Приходько Виталий | E11: Нет | F11: 0.32291667 | G11: 19 | H11: 676.63 | I11: 0.73958333 | J11: =I11-F11 -> 0.41666667
A21: ИТОГО | G21: =SUM(G8:G20) -> 120 | H21: =SUM(H8:H20) -> 3869.283 | K21: =SUM(K8:K20) -> 0 | L21: =SUM(L8:L20) -> 0
A24: НАЙМ АВТО
A25: 1 | B25: 2 | C25: 3 | D25: 4 | E25: 5 | F25: 6 | G25: 7 | H25: 8 | I25: 9
A26: № п/п | B26: Марка | C26: № авто | D26: Стоимость | E26: Выехал (время) | F26: кол-во тт (АКБ) | G26: кг | H26: Вернулся (время) | I26: Время на маршруте
B27: Газель | C27: В558ВА86 | D27: 9000 | E27: 0.33333333 | F27: 21 | G27: 804.164 | H27: 0.70833333 | I27: =I8-F8 -> 0.44791667
A31: ИТОГО | F31: 21 | G31: =SUM(G27:G30) -> 804.164
A33: Неисправные
A34: 1 | B34: 2 | C34: 3 | D34: 4 | E34: 5 | F34: 6 | G34: 7 | H34: 8 | I34: 9 | J34: 10 | K34: 11 | L34: 12
A35: № п/п | B35: Марка | C35: № авто | D35: ФИО водителя | E35: Заполняет механник перед выездом машин | F35: Дата поломки | G35: сумма ремонта | H35: Ремонт одобрен +/- | I35: Дата постановки на ремонт | J35: Дата окончания ремонта | K35: Оплачено +/- | L35: Причина
E36: Исправность холодильного оборудования
A44: ИТОГО | G44: =SUM(G37:G43) -> 0
A46: Сборка
D47: Заказано (день заказа) | E47: Собрано (факт.день сборки) | G47: Выехало (факт день выезда) | I47: Вернулось (факт день выезда)
B48: Поком колбаса | C48: 2613.69 | E48: 2383.624 | G48: 2383.624 | I48: 43.831
B49: Поком заморозка | C49: 1032.08 | E49: 991.064 | G49: 991.064 | I49: 14.28
B50: Останкино | C50: 1027.68 | E50: 691.38 | G50: 691.38 | I50: 51.718
B51: Всего | C51: =SUM(C48:D50) -> 4673.45 | G51: =SUM(G48:H50) -> 4066.068 | I51: =SUM(I48:J50) -> 109.829
A53: Дефицит
A54: № | B54: Наименование позиций | J54: КГ
B55: 4813 ФИЛЕЙНАЯ Папа может вар п/о_Л ОСТАНКИНО | J55: 13.989
B56: 4993 САЛЯМИ ИТАЛЬЯНСКАЯ с/к в/у 1/250*8_120c ОСТАНКИНО | J56: 5.75
B57: 5483 ЭКСТРА Папа может с/к в/у 1/250 8шт. ОСТАНКИНО | J57: 11.75
B58: 5931 ОХОТНИЧЬЯ Папа может с/к в/у 1/220 8шт. ОСТАНКИНО | J58: 6.16
B59: 6333 МЯСНАЯ Папа может вар п/о 0.4кг 8шт. ОСТАНКИНО | J59: 23.2
B60: 6392 ФИЛЕЙНАЯ Папа может вар п/о 0,4кг ОСТАНКИНО | J60: 14.4
B61: 6470 ВЕТЧ.МРАМОРНАЯ в/у_45с ОСТАНКИНО | J61: 16.2
B62: 6498 МОЛОЧНАЯ Папа может вар п/о ОСТАНКИНО | J62: 22
B63: 6550 МЯСНЫЕ Папа может сар б/о мгс 1*3 О 45с Останкино | J63: 25
B64: 6697 СЕРВЕЛАТ ФИНСКИЙ ПМ в/к в/у 0,35кг 8шт ОСТАНКИНО | J64: 35
...

Sheet 29.10
A1: МАРИУПОЛЬ | E1: ВСЕГО МАШИН | J1: 3
A2: 46324
A3: Выезд Машин
A4: ИСПРАВНЫЕ АВТО
A5: 1 | B5: 2 | C5: 3 | D5: 4 | E5: 5 | F5: 6 | G5: 7 | H5: 8 | I5: 9 | J5: 10 | K5: 10 | L5: 11
A6: № п/п | B6: Марка | C6: № авто | D6: ФИО водителя | E6: Заполняет механник перед выездом машин | F6: Выехал (время) | G6: количество ТГ (АКБ) | H6: кг | I6: вернулся (время) | J6: Время на маршруте | K6: Не вывезено
E7: Исправность холодильного оборудования | K7: количество ТГ (АКБ) | L7: кг
A8: 1 | B8: Спринтер | C8: Е792СР82 | D8: Приходько Виталий | E8: Да | F8: 0.3125 | G8: 21 | H8: 1072.859 | I8: 0.6875 | J8: =I8-F8 -> 0.375
A9: 2 | B9: Спринтер | C9: Е827УА82 | D9: Ковальский Дмитрий | E9: Нет | F9: 0.31944444 | G9: 27 | H9: 569.68 | I9: 0.67361111 | J9: =I9-F9 -> 0.35416667
A10: 3 | B10: Спринтер | C10: В952ХК82 | D10: Махонько Игорь | E10: Да | F10: 0.30902778 | G10: 34 | H10: 892.377 | I10: 0.65625 | J10: =I10-F10 -> 0.34722222
A11: 4
A21: ИТОГО | G21: =SUM(G8:G20) -> 82 | H21: =SUM(H8:H20) -> 2534.916 | K21: =SUM(K8:K20) -> 0 | L21: =SUM(L8:L20) -> 0
A24: НАЙМ АВТО
A25: 1 | B25: 2 | C25: 3 | D25: 4 | E25: 5 | F25: 6 | G25: 7 | H25: 8 | I25: 9
A26: № п/п | B26: Марка | C26: № авто | D26: Стоимость | E26: Выехал (время) | F26: кол-во тт (АКБ) | G26: кг | H26: Вернулся (время) | I26: Время на маршруте
A31: ИТОГО | F31: =SUM(F30:F30) -> 0 | G31: =SUM(G27:G30) -> 0
A33: Неисправные
A34: 1 | B34: 2 | C34: 3 | D34: 4 | E34: 5 | F34: 6 | G34: 7 | H34: 8 | I34: 9 | J34: 10 | K34: 11 | L34: 12
A35: № п/п | B35: Марка | C35: № авто | D35: ФИО водителя | E35: Заполняет механник перед выездом машин | F35: Дата поломки | G35: сумма ремонта | H35: Ремонт одобрен +/- | I35: Дата постановки на ремонт | J35: Дата окончания ремонта | K35: Оплачено +/- | L35: Причина
E36: Исправность холодильного оборудования
B37: Газель | C37: Е765МУ82 | D37: Приходько Виталий | F37: 46323 | I37: 46323
A44: ИТОГО | G44: =SUM(G37:G43) -> 0
A46: Сборка
D47: Заказано (день заказа) | E47: Собрано (факт.день сборки) | G47: Выехало (факт день выезда) | I47: Вернулось (факт день выезда)
B48: Поком колбаса | C48: 1781.16 | E48: 1684.072 | G48: 1684.072 | I48: 20.555
B49: Поком заморозка | C49: 568.01 | E49: 531.436 | G49: 531.436 | I49: 6.6
B50: Останкино | C50: 704.04 | E50: 310.87 | G50: 310.87 | I50: 8.024
B51: Всего | C51: =SUM(C48:D50) -> 3053.21 | E51: =SUM(E48:F50) -> 2526.378 | G51: =SUM(G48:H50) -> 2526.378 | I51: =SUM(I48:J50) -> 35.179
A54: Дефицит
A55: № | B55: Наименование позиций | J55: КГ
B56: 4993 САЛЯМИ ИТАЛЬЯНСКАЯ с/к в/у 1/250*8_120c ОСТАНКИНО | J56: 5
B57: 5483 ЭКСТРА Папа может с/к в/у 1/250 8шт. ОСТАНКИНО | J57: 36.1
B58: 5544 Сервелат Финский в/к в/у_45с НОВАЯ ОСТАНКИНО | J58: 4.8
B59: 6325 ДОКТОРСКАЯ ПРЕМИУМ вар п/о 0.4кг 8шт. ОСТАНКИНО | J59: 32
B60: 6333 МЯСНАЯ Папа может вар п/о 0.4кг 8шт. ОСТАНКИНО | J60: 25.6
B61: 6392 ФИЛЕЙНАЯ Папа может вар п/о 0,4кг ОСТАНКИНО | J61: 4
B62: 6475 Сосиски Папа может 400г С сыром ОСТАНКИНО | J62: 31
B63: 6498 МОЛОЧНАЯ Папа может вар п/о ОСТАНКИНО | J63: 4
B64: 6550 МЯСНЫЕ Папа может сар б/о мгс 1*3 О 45с Останкино | J64: 42
B65: 6697 СЕРВЕЛАТ ФИНСКИЙ ПМ в/к в/у 0,35кг 8шт ОСТАНКИНО | J65: 4.51
...

Sheet 30.10
A1: МАРИУПОЛЬ | E1: ВСЕГО МАШИН | J1: 2
A2: 46325
A3: Выезд Машин
A4: ИСПРАВНЫЕ АВТО
A5: 1 | B5: 2 | C5: 3 | D5: 4 | E5: 5 | F5: 6 | G5: 7 | H5: 8 | I5: 9 | J5: 10 | K5: 10 | L5: 11
A6: № п/п | B6: Марка | C6: № авто | D6: ФИО водителя | E6: Заполняет механник перед выездом машин | F6: Выехал (время) | G6: количество ТГ (АКБ) | H6: кг | I6: вернулся (время) | J6: Время на маршруте | K6: Не вывезено
E7: Исправность холодильного оборудования | K7: количество ТГ (АКБ) | L7: кг | N7: м
A8: 1 | B8: Спринтер | C8: Е827УА82 | D8: Ковальский Дмитрий | E8: Да | F8: 0.28819444 | G8: 27 | H8: 656.412
A9: 2 | B9: Спринтер | C9: В952ХК82 | D9: Приходько Виталий | E9: Нет | F9: 0.29513889 | G9: 25 | H9: 410.373
A10: 3
A11: 4
A12: 5
A13: 6
A14: ИТОГО | G14: =SUM(G8:G13) -> 52 | H14: =SUM(H8:H13) -> 1066.785 | K14: =SUM(K8:K13) -> 0 | L14: =SUM(L8:L13) -> 0
A17: НАЙМ АВТО
A18: 1 | B18: 2 | C18: 3 | D18: 4 | E18: 5 | F18: 6 | G18: 7 | H18: 8 | I18: 9
A19: № п/п | B19: Марка | C19: № авто | D19: Стоимость | E19: Выехал (время) | F19: кол-во тт (АКБ) | G19: кг | H19: Вернулся (время) | I19: Время на маршруте
A24: ИТОГО | F24: =SUM(F23:F23) -> 0 | G24: =SUM(G20:G23) -> 0
A26: Неисправные
A27: 1 | B27: 2 | C27: 3 | D27: 4 | E27: 5 | F27: 6 | G27: 7 | H27: 8 | I27: 9 | J27: 10 | K27: 11 | L27: 12
A28: № п/п | B28: Марка | C28: № авто | D28: ФИО водителя | E28: Заполняет механник перед выездом машин | F28: Дата поломки | G28: сумма ремонта | H28: Ремонт одобрен +/- | I28: Дата постановки на ремонт | J28: Дата окончания ремонта | K28: Оплачено +/- | L28: Причина
E29: Исправность холодильного оборудования
B30: Газель | C30: Е765МУ82 | D30: Приходько Виталий | F30: 46323 | I30: 46323
A37: ИТОГО | G37: =SUM(G30:G36) -> 0
A39: Сборка
D40: Заказано (день заказа) | E40: Собрано (факт.день сборки) | G40: Выехало (факт день выезда) | I40: Вернулось (факт день выезда)
B41: Поком колбаса | C41: 503.37 | E41: 408.747 | G41: 408.747
B42: Поком заморозка | C42: 420.29 | E42: 445.65 | G42: 445.65
B43: Останкино | C43: 599.29 | E43: 212.39 | G43: 212.39
B44: Всего | C44: =SUM(C41:D43) -> 1522.95 | E44: =SUM(E41:F43) -> 1066.787 | G44: =SUM(G41:H43) -> 1066.787 | I44: =SUM(I41:I43) -> 0
A47: Дефицит
A48: № | B48: Наименование позиций | J48: КГ
B49: 201 Ветчина Нежная ТМ Особый рецепт, (2,5кг), ПОКОМ | J49: 10.507
B50: 4063 МЯСНАЯ Папа может вар п/о_Л ОСТАНКИНО | J50: 17.89
B51: 4993 САЛЯМИ ИТАЛЬЯНСКАЯ с/к в/у 1/250*8_120c ОСТАНКИНО | J51: 7.75
B52: 5483 ЭКСТРА Папа может с/к в/у 1/250 8шт. ОСТАНКИНО | J52: 7.75
B53: 5544 Сервелат Финский в/к в/у_45с НОВАЯ ОСТАНКИНО | J53: 4.2
B54: 6220 ГОВЯЖЬЯ папа может вар п/о Останкино | J54: 8
B55: 6303 Мясные Папа может сос п/о мгс 1,5*3 Останкино | J55: 12
B56: 6333 МЯСНАЯ Папа может вар п/о 0.4кг 8шт. ОСТАНКИНО | J56: 17.2
...

Sheet Лист1
A1: Наименование позиций | B1: КГ
A2: 201 Ветчина Нежная ТМ Особый рецепт, (2,5кг), ПОКОМ | B2: 10.507
A3: 4063 МЯСНАЯ Папа может вар п/о_Л ОСТАНКИНО | B3: 17.89
A4: 4993 САЛЯМИ ИТАЛЬЯНСКАЯ с/к в/у 1/250*8_120c ОСТАНКИНО | B4: 7.75
A5: 5483 ЭКСТРА Папа может с/к в/у 1/250 8шт. ОСТАНКИНО | B5: 7.75
A6: 5544 Сервелат Финский в/к в/у_45с НОВАЯ ОСТАНКИНО | B6: 4.2
A7: 6220 ГОВЯЖЬЯ папа может вар п/о Останкино | B7: 8
A8: 6303 Мясные Папа может сос п/о мгс 1,5*3 Останкино | B8: 12
A9: 6333 МЯСНАЯ Папа может вар п/о 0.4кг 8шт. ОСТАНКИНО | B9: 17.2
A10: 6392 ФИЛЕЙНАЯ Папа может вар п/о 0,4кг ОСТАНКИНО | B10: 8.8
A11: 6498 МОЛОЧНАЯ Папа может вар п/о ОСТАНКИНО | B11: 39
A12: 6550 МЯСНЫЕ Папа может сар б/о мгс 1*3 О 45с Останкино | B12: 12
A13: 6697 СЕРВЕЛАТ ФИНСКИЙ ПМ в/к в/у 0,35кг 8шт ОСТАНКИНО | B13: 28.35
... A56: 7632 ЭКСТРА Папа может вар п/о 0.4кг 8шт_195к ОСТАНКИНО | B56: 4.4

Sheet ПОКОМ
A1: Наименование позиций | B1: КГ | D1: остаток, кг
A2: 201 Ветчина Нежная ТМ Особый рецепт, (2,5кг), ПОКОМ | B2: 10.507 | C2: матрица | D2: 917

Sheet Останкино
A1: Наименование позиций | B1: КГ | D1: остаток, кг
A2: 4063 МЯСНАЯ Папа может вар п/о_Л ОСТАНКИНО | B2: 17.89 | C2: =VLOOKUP(A2,[2]Sheet!$A:$I,9,0) -> матрица | D2: =VLOOKUP(A2,[3]TDSheet!$A:$T,14,0) -> 329.168
A3: 4993 САЛЯМИ ИТАЛЬЯНСКАЯ с/к в/у 1/250*8_120c ОСТАНКИНО | B3: 7.75 | C3: =VLOOKUP(A3,[2]Sheet!$A:$I,9,0) -> матрица | D3: 0 | E3: =VLOOKUP(A3,[1]Останкино!$A:$E,5,0) -> списано 23кг (пересчет 28,10,26)
A4: 5483 ЭКСТРА Папа может с/к в/у 1/250 8шт. ОСТАНКИНО | B4: 7.75 | C4: =VLOOKUP(A4,[2]Sheet!$A:$I,9,0) -> матрица | D4: 0 | E4: =VLOOKUP(A4,[1]Останкино!$A:$E,5,0) -> списано 48кг (пересчет 28,10,26)
A5: 5544 Сервелат Финский в/к в/у_45с НОВАЯ ОСТАНКИНО | B5: 4.2 | C5: =VLOOKUP(A5,[2]Sheet!$A:$I,9,0) -> матрица | D5: =VLOOKUP(A5,[3]TDSheet!$A:$T,14,0) -> 0 | E5: =VLOOKUP(A5,[1]Останкино!$A:$E,5,0) -> списано 42кг (пересчет 28,10,26)
A6: 6220 ГОВЯЖЬЯ папа может вар п/о Останкино | B6: 8 | C6: =VLOOKUP(A6,[2]Sheet!$A:$I,9,0) -> матрица | D6: =VLOOKUP(A6,[3]TDSheet!$A:$T,14,0) -> 60.708
A7: 6303 Мясные Папа может сос п/о мгс 1,5*3 Останкино | B7: 12 | C7: =VLOOKUP(A7,[2]Sheet!$A:$I,9,0) -> матрица | D7: 0 | E7: списано 209кг (пересчет 28,10,26)
A8: 6333 МЯСНАЯ Папа может вар п/о 0.4кг 8шт. ОСТАНКИНО | B8: 17.2 | C8: =VLOOKUP(A8,[2]Sheet!$A:$I,9,0) -> матрица | D8: 0 | E8: =VLOOKUP(A8,[1]Останкино!$A:$E,5,0) -> списано 84кг (пересчет 28,10,26)
A9: 6392 ФИЛЕЙНАЯ Папа может вар п/о 0,4кг ОСТАНКИНО | B9: 8.8 | C9: =VLOOKUP(A9,[2]Sheet!$A:$I,9,0) -> матрица | D9: =VLOOKUP(A9,[3]TDSheet!$A:$T,14,0) -> 6.4 | E9: =VLOOKUP(A9,[1]Останкино!$A:$E,5,0) -> списано 100кг (пересчет 28,10,26)
A10: 6498 МОЛОЧНАЯ Папа может вар п/о ОСТАНКИНО | B10: 39 | C10: =VLOOKUP(A10,[2]Sheet!$A:$I,9,0) -> матрица | D10: =VLOOKUP(A10,[3]TDSheet!$A:$T,14,0) -> 235.131
A11: 6550 МЯСНЫЕ Папа может сар б/о мгс 1*3 О 45с Останкино | B11: 12 | C11: =VLOOKUP(A11,[2]Sheet!$A:$I,9,0) -> матрица | D11: 0 | E11: =VLOOKUP(A11,[1]Останкино!$A:$E,5,0) -> списание по срокам 68кг (27,10,26)
A12: 6697 СЕРВЕЛАТ ФИНСКИЙ ПМ в/к в/у 0,35кг 8шт ОСТАНКИНО | B12: 28.35 | C12: =VLOOKUP(A12,[2]Sheet!$A:$I,9,0) -> матрица | D12: 0 | E12: =VLOOKUP(A12,[1]Останкино!$A:$E,5,0) -> списано 90кг (пересчет 28,10,26)
A13: 6724 МОЛОЧНЫЕ ПМ сос п/о мгс 0,41кг 10шт Останкино | B13: 6.56 | C13: =VLOOKUP(A13,[2]Sheet!$A:$I,9,0) -> матрица | D13: =VLOOKUP(A13,[3]TDSheet!$A:$T,14,0) -> 2.05 | E13: =VLOOKUP(A13,[1]Останкино!$A:$E,5,0) -> списано 54кг (пересчет 28,10,26)
A14: 7066 СОЧНЫЕ ПМ сос п/о мгс 0,41кг 10шт 50с Останкино | B14: 24.6 | C14: =VLOOKUP(A14,[2]Sheet!$A:$I,9,0) -> матрица | D14: =VLOOKUP(A14,[3]TDSheet!$A:$T,14,0) -> 5.74 | E14: списано 114кг (27,10,26)
A15: 7070 СОЧНЫЕ ПМ сос п/о 1,5*4_А_50с Останкино | B15: 19.5 | C15: =VLOOKUP(A15,[2]Sheet!$A:$I,9,0) -> матрица | D15: =VLOOKUP(A15,[3]TDSheet!$A:$T,14,0) -> 10.847 | E15: списано 42кг (пересчет 28,10,26) + списано 9кг (27,10,26)
A16: 7103 БЕКОН Останкино с/к с/н в/у 1/180_50с Останкино | B16: 7.2 | C16: =VLOOKUP(A16,[2]Sheet!$A:$I,9,0) -> матрица | D16: 0 | E16: списано 5кг (пересчет 28,10,26)
A17: 7154 СЕРВЕЛАТ ЗЕРНИСТЫЙ ПМ в/к в/у 0,35кг_50с Останкино | B17: 10.15 | C17: =VLOOKUP(A17,[2]Sheet!$A:$I,9,0) -> матрица | D17: =VLOOKUP(A17,[3]TDSheet!$A:$T,14,0) -> 3.85 | E17: =VLOOKUP(A17,[1]Останкино!$A:$E,5,0) -> списано 86кг (пересчет 28,10,26)
A18: 7157 СЕРВЕЛАТ ЗЕРНИСТЫЙ ПМ в/к в/у_50с Останкино | B18: 31.8 | C18: =VLOOKUP(A18,[2]Sheet!$A:$I,9,0) -> матрица | D18: 0 | E18: =VLOOKUP(A18,[1]Останкино!$A:$E,5,0) -> списание по срокам 42кг (27,10,26)
A19: 7166 СЕРВЕЛАТ ОХОТНИЧИЙ ПМ в/к в/у_50с Останкино | B19: 15.5 | C19: =VLOOKUP(A19,[2]Sheet!$A:$I,9,0) -> матрица | D19: =VLOOKUP(A19,[3]TDSheet!$A:$T,14,0) -> 1.4 | E19: =VLOOKUP(A19,[1]Останкино!$A:$E,5,0) -> списание по срокам 53кг (27,10,26)
A20: 7169 СЕРВЕЛАТ ОХОТНИЧИЙ ПМ в/к в/у 0,35кг_50с Останкино | B20: 28.35 | C20: =VLOOKUP(A20,[2]Sheet!$A:$I,9,0) -> матрица | D20: 0 | E20: =VLOOKUP(A20,[1]Останкино!$A:$E,5,0) -> списано 47кг (пересчет 28,10,26)
A21: 7177 ЧЕСНОЧНАЯ ПМ п/к в/у 0,35кг 8шт_50с Останкино | B21: 8.75 | C21: не в матрице
A22: 7236 СЕРВЕЛАТ КАРЕЛЬСКИЙ в/к в/у 0,28кг_209к Останкино | B22: 14.28 | C22: =VLOOKUP(A22,[2]Sheet!$A:$I,9,0) -> матрица | D22: 0 | E22: =VLOOKUP(A22,[1]Останкино!$A:$E,5,0) -> списано 46кг (пересчет 28,10,26)
A23: 7255 МЯСНЫЕ С ГОВЯД.ПМ сос п/о мгс 0.4кг 6шт. ОСТАНКИНО | B23: 21.6 | C23: =VLOOKUP(A23,[2]Sheet!$A:$I,9,0) -> матрица | D23: 0 | E23: списано 63кг (пересчет 28,10,26) + списано 25кг (27,10,26)
A24: 7386 БАРСЕЛОНА ПМ с/к в/у 1/150 ОСТАНКИНО | B24: 5.4 | C24: =VLOOKUP(A24,[2]Sheet!$A:$I,9,0) -> матрица | D24: 0 | E24: списано 3кг (пересчет 28,10,26) + торгуем 2-ю неделю данным скю
A25: 7461 ДЛЯ ДЕТЕЙ Папа Может сос п/о мгс 0,33кг ОСТАНКИНО | B25: 4.29 | C25: =VLOOKUP(A25,[2]Sheet!$A:$I,9,0) -> матрица | D25: 0 | E25: списано 12кг (пересчет 28,10,26)
A26: 7632 ЭКСТРА Папа может вар п/о 0.4кг 8шт_195к ОСТАНКИНО | B26: 4.4 | C26: =VLOOKUP(A26,[2]Sheet!$A:$I,9,0) -> матрица | D26: =VLOOKUP(A26,[3]TDSheet!$A:$T,14,0) -> 108
B27: =SUM(B2:B26) -> 365.32

Sheet Заморозка
A1: Наименование позиций | B1: КГ | D1: остаток, кг
A2: Готовые чебупели с ветчиной и сыром 0,24 кг НОВАЯ ТМ Горячая штучка ПОКОМ | B2: 10.08 | C2: матрица | D2: =VLOOKUP(A2,[3]TDSheet!$A:$T,14,0) -> 4.08 | E2: =VLOOKUP(A2,[1]заморозка!$A:$E,5,0) -> рост продаж в 1,8 раза
A3: Пельмени Бульмени с говядиной и свининой Наваристые Горячая штучка ВЕС ПОКОМ | B3: 5 | C3: =VLOOKUP(A3,[4]Sheet!$A:$I,9,0) -> P003697 | D3: =VLOOKUP(A3,[3]TDSheet!$A:$T,14,0) -> 350
A4: Пельмени Медвежье ушко Премиум со сливочным маслом 0,4 кг ТМ Медвежье ушко ПОКОМ | B4: 12.8 | C4: =VLOOKUP(A4,[4]Sheet!$A:$I,9,0) -> P005439 | D4: =VLOOKUP(A4,[3]TDSheet!$A:$T,14,0) -> 57.2
A5: Чебупицца Пепперони ТМ Горячая штучка ТС Чебупицца 0.25кг зам ПОКОМ | B5: 21 | C5: =VLOOKUP(A5,[4]Sheet!$A:$I,9,0) -> P004486 | D5: =VLOOKUP(A5,[3]TDSheet!$A:$T,14,0) -> 1 | E5: рост продаж в 1,5 раза + машина выехала на день позже с завода
B6: =SUM(B2:B5) -> 48.88
