Workbook

Sheet Sheet
A3: Номенклатура | B3: Ед. изм. | C3: Начальный остаток | D3: Приход | E3: Расход | F3: Конечный остаток | G3: крат | H3: сроки | I3: метка | J3: метка2 | K3: заяв | L3: разн | M3: без опта | N3: опт | O3: заказ в пути | P3: ср нов | Q3: расчет | R3: итого | S3: заказ | T3: заказ филиала | U3: Комментарии филиала | V3: кон ост | W3: факт | X3: ср | Y3: ср | Z3: ср | AA3: ср | AB3: ср | AC3: ср | AD3: ср | AE3: ср | AF3: комментарии | AG3: вес
O4: 22,12, | P4: 23,12, | S4: 05,01, | X4: 16,12, | Y4: 08,12, | Z4: 01,12, | AA4: 24,11, | AB4: 17,11, | AC4: 10,11, | AD4: 03,11, | AE4: 27,10,
E5: =SUM(E6:E495) -> 6170.187 | F5: =SUM(F6:F495) -> 7069.803 | K5: =SUM(K6:K495) -> 6588.2 | L5: =SUM(L6:L495) -> -418.013 | M5: =SUM(M6:M495) -> 0 | N5: =SUM(N6:N495) -> 0 | O5: =SUM(O6:O495) -> 12090 | P5: =SUM(P6:P495) -> 1234.0374 | Q5: =SUM(Q6:Q495) -> 8241.313 | R5: =SUM(R6:R495) -> 7758.914 | ... T5: =SUM(T6:T495) -> 5594 | X5: =SUM(X6:X495) -> 1082.7646 | Y5: =SUM(Y6:Y495) -> 929.0648 | Z5: =SUM(Z6:Z495) -> 829.48 | AA5: =SUM(AA6:AA495) -> 843.9704 | AB5: =SUM(AB6:AB495) -> 973.037 | AC5: =SUM(AC6:AC495) -> 1035.436 | AD5: =SUM(AD6:AD495) -> 969.8966 | AE5: =SUM(AE6:AE495) -> 1166.6854 | AG5: =SUM(AG6:AG495) -> 2813.118
A6: 6948249 Майонезный соус провансаль 824,5гр деликатес.с массовой долей жирн.25% Коровино Останкино | B6: шт | D6: 48 | E6: 45 | F6: 3 | G6: =VLOOKUP(A6,[1]Sheet!$A:$I,7,0) -> 0.8245 | I6: =VLOOKUP(A6,[1]Sheet!$A:$I,9,0) -> 6948249 | K6: 45 | L6: =E6-K6 -> 0 | P6: =E6/5 -> 9 | Q6: =15*P6-O6-F6 -> 132 | R6: =T6 -> 96 | S6: =IFERROR(VLOOKUP(A6,заказ!A:B,2,0),0) -> 96 | T6: 96 | V6: =(F6+O6+R6)/P6 -> 11 | W6: =(F6+O6)/P6 -> 0.33333333 | X6: 0 | Y6: 0 | Z6: 0 | AA6: 0 | AB6: 0 | AC6: 0 | AD6: 0 | AE6: 0 | AG6: =G6*R6 -> 79.152
A7: 6948256 Майонез провансаль классич.оливковый Папа может 372гр с массовой долей жирн. 67% Останкино | B7: шт | D7: 600 | E7: 221 | F7: 379 | G7: =VLOOKUP(A7,[1]Sheet!$A:$I,7,0) -> 0.372 | I7: =VLOOKUP(A7,[1]Sheet!$A:$I,9,0) -> 6948256 | K7: 219 | L7: =E7-K7 -> 2 | P7: =E7/5 -> 44.2 | Q7: =20*P7-O7-F7 -> 505 | R7: =T7 -> 600 | S7: =IFERROR(VLOOKUP(A7,заказ!A:B,2,0),0) -> 600 | T7: 600 | V7: =(F7+O7+R7)/P7 -> 22.149321 | W7: =(F7+O7)/P7 -> 8.5746606 | X7: 0 | Y7: 0 | Z7: 0 | AA7: 0 | AB7: 0 | AC7: 0 | AD7: 0 | AE7: 0 | AG7: =G7*R7 -> 223.2
A8: 6948263 Майонез провансаль классич.оливковый Папа может 744гр с массовой долей жирн. 67% Останкино | B8: шт | D8: 408 | E8: 174 | F8: 234 | G8: =VLOOKUP(A8,[1]Sheet!$A:$I,7,0) -> 0.744 | I8: =VLOOKUP(A8,[1]Sheet!$A:$I,9,0) -> 6948263 | K8: 174 | L8: =E8-K8 -> 0 | P8: =E8/5 -> 34.8 | Q8: =20*P8-O8-F8 -> 462 | R8: =T8 -> 408 | S8: =IFERROR(VLOOKUP(A8,заказ!A:B,2,0),0) -> 408 | T8: 408 | V8: =(F8+O8+R8)/P8 -> 18.448276 | W8: =(F8+O8)/P8 -> 6.7241379 | X8: 0 | Y8: 0 | Z8: 0 | AA8: 0 | AB8: 0 | AC8: 0 | AD8: 0 | AE8: 0 | AG8: =G8*R8 -> 303.552
A9: 6948270 Майонез провансаль классич.Папа может 372гр с массовой долей жирн. 67% Останкино | B9: шт | D9: 600 | E9: 394 | F9: 206 | G9: =VLOOKUP(A9,[1]Sheet!$A:$I,7,0) -> 0.372 | I9: =VLOOKUP(A9,[1]Sheet!$A:$I,9,0) -> 6948270 | K9: 389 | L9: =E9-K9 -> 5 | P9: =E9/5 -> 78.8 | Q9: =18*P9-O9-F9 -> 1212.4 | R9: =T9 -> 1000 | S9: =IFERROR(VLOOKUP(A9,заказ!A:B,2,0),0) -> 996 | T9: 1000 | V9: =(F9+O9+R9)/P9 -> 15.304569 | W9: =(F9+O9)/P9 -> 2.6142132 | X9: 0 | Y9: 0 | Z9: 0 | AA9: 0 | AB9: 0 | AC9: 0 | AD9: 0 | AE9: 0 | AG9: =G9*R9 -> 372
A10: 6948287 Майонез провансаль классич.Папа может 744гр с массовой долей жирн. 67% Останкино | B10: шт | D10: 408 | E10: 291 | F10: 117 | G10: =VLOOKUP(A10,[1]Sheet!$A:$I,7,0) -> 0.744 | I10: =VLOOKUP(A10,[1]Sheet!$A:$I,9,0) -> 6948287 | K10: 289 | L10: =E10-K10 -> 2 | P10: =E10/5 -> 58.2 | Q10: =17*P10-O10-F10 -> 872.4 | R10: =T10 -> 600 | S10: =IFERROR(VLOOKUP(A10,заказ!A:B,2,0),0) -> 600 | T10: 600 | V10: =(F10+O10+R10)/P10 -> 12.319588 | W10: =(F10+O10)/P10 -> 2.0103093 | X10: 0 | Y10: 0 | Z10: 0 | AA10: 0 | AB10: 0 | AC10: 0 | AD10: 0 | AE10: 0 | AG10: =G10*R10 -> 446.4
A11: 9988421 Творожный Сыр 60 % С маринованными огурчиками и укропом Останкино | B11: шт | C11: 30 | D11: 16 | E11: 19 | F11: 18 | G11: 0.14 | H11: 180 | I11: 9988421 | K11: 20 | L11: =E11-K11 -> -1 | O11: 80 | P11: =E11/5 -> 3.8 | R11: =Q11 -> 0 | S11: =IFERROR(VLOOKUP(A11,заказ!A:B,2,0),0) -> 0 | V11: =(F11+O11+R11)/P11 -> 25.789474 | W11: =(F11+O11)/P11 -> 25.789474 | X11: 6 | Y11: 3.6 | Z11: 4.2 | AA11: 0 | AB11: 1 | AC11: 5 | AD11: 5.6 | AE11: 4 | AF11: 26,08,25 списание 140шт (недостача) | AG11: =G11*R11 -> 0
A12: 9988438 Плавленый Сыр 45% "С ветчиной" СТМ"ПапаМожет" 180гр Останкино | B12: шт | C12: 159 | D12: 48 | E12: 92 | F12: 94 | G12: 0.18 | H12: 270 | I12: 9988438 | K12: 92 | L12: =E12-K12 -> 0 | O12: 256 | P12: =E12/5 -> 18.4 | Q12: =20*P12-O12-F12 -> 18 | R12: =T12 -> 40 | S12: =IFERROR(VLOOKUP(A12,заказ!A:B,2,0),0) -> 32 | T12: 40 | V12: =(F12+O12+R12)/P12 -> 21.195652 | W12: =(F12+O12)/P12 -> 19.021739 | X12: 18.4 | Y12: 15.4 | Z12: 16 | AA12: 14.6 | AB12: 12.8 | AC12: 17.6 | AD12: 11.8 | AE12: 12.2 | AG12: =G12*R12 -> 7.2
A13: 9988445 Плавленый Сыр 45%"С грибами" СТМ"ПапаМожет" 180 гр Останкино | B13: шт | C13: 153 | D13: 96 | E13: 84 | F13: 160 | G13: 0.18 | H13: 270 | I13: 9988445 | K13: 84 | L13: =E13-K13 -> 0 | O13: 48 | P13: =E13/5 -> 16.8 | Q13: =20*P13-O13-F13 -> 128 | R13: =Q13 -> 128 | S13: =IFERROR(VLOOKUP(A13,заказ!A:B,2,0),0) -> 128 | V13: =(F13+O13+R13)/P13 -> 20 | W13: =(F13+O13)/P13 -> 12.380952 | X13: 12.6 | Y13: 15.4 | Z13: 15.4 | AA13: 13.2 | AB13: 10.4 | AC13: 14.6 | AD13: 12.8 | AE13: 13.2 | AG13: =G13*R13 -> 23.04
A14: Плавленый Сыр колбасный копченый 40% СТМ"ПапаМожет"400гр Останкино | B14: шт | C14: 135 | E14: 21 | F14: 102 | G14: 0.4 | H14: 270 | I14: 9988452 | K14: 21 | L14: =E14-K14 -> 0 | O14: 80 | P14: =E14/5 -> 4.2 | R14: =Q14 -> 0 | S14: =IFERROR(VLOOKUP(A14,заказ!A:B,2,0),0) -> 0 | V14: =(F14+O14+R14)/P14 -> 43.333333 | W14: =(F14+O14)/P14 -> 43.333333 | X14: 7.8 | Y14: 5.8 | Z14: 9.6 | AA14: 6.4 | AB14: 6.2 | AC14: 1.8 | AD14: 10.6 | AE14: 3.4 | AF14: нужно увеличить продажи!!! / 29,09,25 завод не отгрузил | AG14: =G14*R14 -> 0
A15: Плавленый продукт с Сыром колбасный копченый 40% СТМ "Коровино" 400гр Останкино | B15: шт | C15: 94 | E15: 19 | F15: 70 | G15: 0.4 | H15: 270 | I15: 9988476 | K15: 21 | L15: =E15-K15 -> -2 | O15: 0 | P15: =E15/5 -> 3.8 | Q15: =20*P15-O15-F15 -> 6 | R15: =Q15 -> 6 | S15: =IFERROR(VLOOKUP(A15,заказ!A:B,2,0),0) -> 28 | V15: =(F15+O15+R15)/P15 -> 20 | W15: =(F15+O15)/P15 -> 18.421053 | X15: 3.6 | Y15: 4.2 | Z15: 7.2 | AA15: 2.6 | AB15: 5 | AC15: 2.2 | AD15: 5.8 | AE15: 2.6 | AG15: =G15*R15 -> 2.4
A16: Сыр "Пармезан" 40% кусок 180 гр ОСТАНКИНО | B16: шт | C16: 256 | E16: 158 | F16: 1 | G16: 0.18 | H16: 150 | I16: 5034819 | K16: 170 | L16: =E16-K16 -> -12 | O16: 600 | P16: =E16/5 -> 31.6 | Q16: =20*P16-O16-F16 -> 31 | R16: =T16 -> 100 | S16: =IFERROR(VLOOKUP(A16,заказ!A:B,2,0),0) -> 102 | T16: 100 | V16: =(F16+O16+R16)/P16 -> 22.183544 | W16: =(F16+O16)/P16 -> 19.018987 | X16: 37 | Y16: 12.2 | Z16: 22.8 | AA16: 21.2 | AB16: 32.8 | AC16: 32 | AD16: 31.6 | AE16: 34.8 | AF16: 18,08,25 завод не отгрузил | AG16: =G16*R16 -> 18
A17: Сыр Боккончини копченый 40% 100 гр. ОСТАНКИНО | B17: шт | C17: 22 | D17: 96 | E17: 17 | F17: 100 | G17: 0.1 | H17: 90 | I17: 8444163 | K17: 23 | L17: =E17-K17 -> -6 | O17: 0 | P17: =E17/5 -> 3.4 | R17: =Q17 -> 0 | S17: =IFERROR(VLOOKUP(A17,заказ!A:B,2,0),0) -> 0 | V17: =(F17+O17+R17)/P17 -> 29.411765 | W17: =(F17+O17)/P17 -> 29.411765 | X17: 4.8 | Y17: 9.2 | Z17: 6.8 | AA17: 2.8 | AB17: 4.4 | AC17: 11 | AD17: 2.4 | AE17: 8.4 | AG17: =G17*R17 -> 0
A18: Сыр ПАПА МОЖЕТ "Гауда Голд" 45 % 180 гр (10шт) Останкино | B18: шт | C18: 382 | D18: 200 | E18: 310 | F18: 72 | G18: 0.18 | H18: 150 | I18: 5038411 | K18: 334 | L18: =E18-K18 -> -24 | O18: 1050 | P18: =E18/5 -> 62 | Q18: =20*P18-O18-F18 -> 118 | R18: =T18 -> 200 | S18: =IFERROR(VLOOKUP(A18,заказ!A:B,2,0),0) -> 200 | T18: 200 | V18: =(F18+O18+R18)/P18 -> 21.322581 | W18: =(F18+O18)/P18 -> 18.096774 | X18: 72.4 | Y18: 45.6 | Z18: 33.8 | AA18: 50.8 | AB18: 48.6 | AC18: 50.8 | AD18: 48 | AE18: 68.8 | AG18: =G18*R18 -> 36
A19: Сыр ПАПА МОЖЕТ "Голландский традиционный" 45% 180 гр (10шт) Останкино | B19: шт | C19: 538 | D19: 352 | E19: 448 | F19: 242 | G19: 0.18 | H19: 150 | I19: 5038459 | K19: 457 | L19: =E19-K19 -> -9 | O19: 1030 | P19: =E19/5 -> 89.6 | Q19: =20*P19-O19-F19 -> 520 | R19: =Q19 -> 520 | S19: =IFERROR(VLOOKUP(A19,заказ!A:B,2,0),0) -> 520 | V19: =(F19+O19+R19)/P19 -> 20 | W19: =(F19+O19)/P19 -> 14.196429 | X19: 86.4 | Y19: 63.6 | Z19: 61.6 | AA19: 63.8 | AB19: 51.6 | AC19: 76.8 | AD19: 55.6 | AE19: 93.8 | AG19: =G19*R19 -> 93.6
A20: Сыр ПАПА МОЖЕТ "Министерский" 180 г фасованный массовая Останкино | B20: шт | C20: 53 | D20: 350 | E20: 133 | F20: 211 | G20: 0.18 | H20: 150 | I20: 5038831 | K20: 254 | L20: =E20-K20 -> -121 | O20: 350 | P20: =E20/5 -> 26.6 | R20: =Q20 -> 0 | S20: =IFERROR(VLOOKUP(A20,заказ!A:B,2,0),0) -> 0 | V20: =(F20+O20+R20)/P20 -> 21.090226 | W20: =(F20+O20)/P20 -> 21.090226 | X20: 30 | Y20: 31 | Z20: 22.6 | AA20: 26.4 | AB20: 33.6 | AC20: 36.4 | AD20: 30.8 | AE20: 54.6 | AG20: =G20*R20 -> 0
A21: Сыр ПАПА МОЖЕТ "Папин завтрак" 45% 180 г Останкино | B21: шт | C21: 50 | D21: 400 | E21: 89 | F21: 327 | G21: 0.18 | H21: 120 | I21: 5038855 | K21: 89 | L21: =E21-K21 -> 0 | O21: 0 | P21: =E21/5 -> 17.8 | Q21: =20*P21-O21-F21 -> 29 | R21: =Q21 -> 29 | S21: =IFERROR(VLOOKUP(A21,заказ!A:B,2,0),0) -> 30 | V21: =(F21+O21+R21)/P21 -> 20 | W21: =(F21+O21)/P21 -> 18.370787 | X21: 6.6 | Y21: 32.4 | Z21: 7.2 | AA21: -0.8 | AB21: -0.2 | AC21: 0 | AD21: -1.2 | AE21: -2 | AF21: 17,11,25 завод не отгрузит / 10,11,25 завод не отгрузит / 03,11,25 завод не отгрузит / на заводе брак, следующие отгрузки не раньше ноября | AG21: =G21*R21 -> 5.22
A22: Сыр ПАПА МОЖЕТ "Российский традиционный"45 % 180 г Останкино | B22: шт | C22: 425 | D22: 750 | E22: 325 | F22: 560 | G22: 0.18 | H22: 150 | I22: 5038435 | K22: 417 | L22: =E22-K22 -> -92 | O22: 2000 | P22: =E22/5 -> 65 | R22: =Q22 -> 0 | S22: =IFERROR(VLOOKUP(A22,заказ!A:B,2,0),0) -> 0 | V22: =(F22+O22+R22)/P22 -> 39.384615 | W22: =(F22+O22)/P22 -> 39.384615 | X22: 136.8 | Y22: 94.2 | Z22: 76.4 | AA22: 94.6 | AB22: 112.4 | AC22: 95.2 | AD22: 89.4 | AE22: 121 | AG22: =G22*R22 -> 0
A23: Сыр ПАПА МОЖЕТ "Тильзитер" фасованный массовая доля жира в сухом веществе 45%, 180г Останкино | B23: шт | C23: 209 | D23: 250 | E23: 157 | F23: 129 | G23: 0.18 | H23: 120 | I23: 5038398 | K23: 273 | L23: =E23-K23 -> -116 | O23: 800 | P23: =E23/5 -> 31.4 | R23: =Q23 -> 0 | S23: =IFERROR(VLOOKUP(A23,заказ!A:B,2,0),0) -> 0 | V23: =(F23+O23+R23)/P23 -> 29.585987 | W23: =(F23+O23)/P23 -> 29.585987 | X23: 54.4 | Y23: 34.2 | Z23: 26.8 | AA23: 31 | AB23: 37 | AC23: 51.8 | AD23: 58.2 | AE23: 65.4 | AG23: =G23*R23 -> 0
A24: Сыр Папа Может "Гауда Голд" 45% (-2,5 кг брус) (6 шт) Останкино | B24: кг | G24: 1 | H24: 150 | I24: 8785242 | L24: =E24-K24 -> 0 | O24: 0 | P24: =E24/5 -> 0 | Q24: =20*(P24+P25)-O24-O25-F24-F25 -> 80.526 | R24: =T24 -> 100 | S24: =IFERROR(VLOOKUP(A24,заказ!A:B,2,0),0) -> 99 | T24: 100 | V24: =(F24+O24+R24)/P24 -> #DIV/0! | W24: =(F24+O24)/P24 -> #DIV/0! | X24: 0 | Y24: 0 | Z24: 0 | AA24: 0 | AB24: 0 | AC24: 0 | AD24: 0 | AE24: 0 | AG24: =G24*R24 -> 100
A25: Сыр полутвердый "Гауда" с массовой долей жира в пересчете на сухое вещество 45%, Останкино | B25: кг | C25: 104.344 | D25: 140.11 | E25: 64.056 | F25: 175.698 | G25: 0 | H25: #N/A | I25: дубль | J25: Сыр Папа Может "Гауда Голд" 45% (-2,5 кг брус) (6 шт) Останкино | K25: 67.4 | L25: =E25-K25 -> -3.344 | O25: 0 | P25: =E25/5 -> 12.8112 | R25: =Q25 -> 0 | S25: =IFERROR(VLOOKUP(A25,заказ!A:B,2,0),0) -> 0 | V25: =(F25+O25+R25)/P25 -> 13.714406 | W25: =(F25+O25)/P25 -> 13.714406 | X25: 3.19 | Y25: 14.999 | Z25: 8.9886 | AA25: 8.9422 | AB25: 10.83 | AC25: 9.6608 | AD25: 11.4234 | AE25: 14.6516 | AG25: =G25*R25 -> 0
A26: Сыр Папа Может "Голландский традиционный" 45% (2,5кг)(6шт) Останкино | B26: кг | G26: 0 | H26: 150 | I26: вывод | L26: =E26-K26 -> 0 | O26: 248 | P26: =E26/5 -> 0 | R26: =Q26 -> 0 | S26: =IFERROR(VLOOKUP(A26,заказ!A:B,2,0),0) -> 0 | V26: =(F26+O26+R26)/P26 -> #DIV/0! | W26: =(F26+O26)/P26 -> #DIV/0! | X26: 0 | Y26: 0 | Z26: 0 | AA26: 0 | AB26: 0 | AC26: 0 | AD26: 0 | AE26: 0 | AG26: =G26*R26 -> 0
A27: Сыр полутвердый "Голландский" с массовой долей жира в пересчете на сухое Останкино | B27: кг | C27: 69.9 | D27: 48.078 | E27: 53.022 | F27: 36.878 | G27: 0 | H27: #N/A | I27: дубль / вывод | J27: Сыр Папа Может "Голландский традиционный" 45% (2,5кг)(6шт) Останкино | K27: 45.4 | L27: =E27-K27 -> 7.622 | O27: 0 | P27: =E27/5 -> 10.6044 | R27: =Q27 -> 0 | S27: =IFERROR(VLOOKUP(A27,заказ!A:B,2,0),0) -> 0 | V27: =(F27+O27+R27)/P27 -> 3.4776131 | W27: =(F27+O27)/P27 -> 3.4776131 | X27: 13.2084 | Y27: 9.7916 | Z27: 3.3694 | AA27: 6.191 | AB27: 10.3796 | AC27: 4.7618 | AD27: 7.4278 | AE27: 4.8238 | AG27: =G27*R27 -> 0
A28: Сыр Папа Может "Российский традиционный" 50%, вакуум Останкино | B28: кг | G28: 1 | H28: 120 | I28: 8785204 | L28: =E28-K28 -> 0 | O28: 297 | P28: =E28/5 -> 0 | Q28: =20*(P28+P29)-O28-O29-F28-F29 -> 185.273 | R28: =T28 -> 200 | S28: =IFERROR(VLOOKUP(A28,заказ!A:B,2,0),0) -> 198 | T28: 200 | V28: =(F28+O28+R28)/P28 -> #DIV/0! | W28: =(F28+O28)/P28 -> #DIV/0! | X28: 0 | Y28: 0 | Z28: 0 | AA28: 0 | AB28: 0 | AC28: 0 | AD28: 0 | AE28: 0 | AG28: =G28*R28 -> 200
A29: Сыр полутвердый "Российский" с массовой долей жира 50% Останкино | B29: кг | C29: 209.334 | D29: 151.962 | E29: 164.114 | F29: 174.183 | G29: 0 | H29: #N/A | I29: дубль | J29: Сыр Папа Может "Российский традиционный" 50%, вакуум Останкино | K29: 155.9 | L29: =E29-K29 -> 8.214 | O29: 0 | P29: =E29/5 -> 32.8228 | R29: =Q29 -> 0 | S29: =IFERROR(VLOOKUP(A29,заказ!A:B,2,0),0) -> 0 | V29: =(F29+O29+R29)/P29 -> 5.3067685 | W29: =(F29+O29)/P29 -> 5.3067685 | X29: 30.1304 | Y29: 27.1464 | Z29: 24.0156 | AA29: 22.155 | AB29: 21.5882 | AC29: 28.4396 | AD29: 17.6074 | AE29: 28.2892 | AG29: =G29*R29 -> 0
A30: Сыр Творожный с зеленью 60% Папа может 140 гр. Останкино | B30: шт | C30: 73 | D30: 16 | E30: 33 | F30: 47 | G30: 0.14 | H30: 180 | I30: 9988391 | K30: 34 | L30: =E30-K30 -> -1 | O30: 144 | P30: =E30/5 -> 6.6 | R30: =Q30 -> 0 | S30: =IFERROR(VLOOKUP(A30,заказ!A:B,2,0),0) -> 0 | V30: =(F30+O30+R30)/P30 -> 28.939394 | W30: =(F30+O30)/P30 -> 28.939394 | X30: 7.4 | Y30: 5.8 | Z30: 8 | AA30: 4 | AB30: 4.6 | AC30: 5.6 | AD30: 6.8 | AE30: 7.2 | AG30: =G30*R30 -> 0
A31: Сыр плавленный Сливочный ж.45% 180г ТМ Папа может (16шт) Останкино | B31: шт | C31: 200 | D31: 448 | E31: 179 | F31: 418 | G31: 0.18 | H31: 270 | I31: 9988681 | K31: 182 | L31: =E31-K31 -> -3 | O31: 0 | P31: =E31/5 -> 35.8 | Q31: =20*P31-O31-F31 -> 298 | R31: =Q31 -> 298 | S31: =IFERROR(VLOOKUP(A31,заказ!A:B,2,0),0) -> 304 | V31: =(F31+O31+R31)/P31 -> 20 | W31: =(F31+O31)/P31 -> 11.675978 | X31: 29.4 | Y31: 34.6 | Z31: 24.2 | AA31: 28.2 | AB31: 26.4 | AC31: 35.2 | AD31: 22.4 | AE31: 46 | AG31: =G31*R31 -> 53.64
A32: Сыр полутвердый "Сметанковый", с масс долей жира в пересчете на сухое вещес50%, брус Останкино | B32: кг | C32: 195 | D32: 295.794 | E32: 148.07 | F32: 319.321 | G32: 1 | H32: 120 | I32: 8785198 | K32: 138.5 | L32: =E32-K32 -> 9.57 | O32: 297 | P32: =E32/5 -> 29.614 | R32: =Q32 -> 0 | S32: =IFERROR(VLOOKUP(A32,заказ!A:B,2,0),0) -> 0 | V32: =(F32+O32+R32)/P32 -> 20.811812 | W32: =(F32+O32)/P32 -> 20.811812 | X32: 36.3694 | Y32: 34.7294 | Z32: 25.0214 | AA32: 33.1196 | AB32: 32.2744 | AC32: 28.9396 | AD32: 23.6228 | AE32: 21.1998 | AG32: =G32*R32 -> 0
A33: Сыр рассольный жирный Чечил 45% 100 гр ОСТАНКИНО | B33: шт | C33: 110 | E33: 90 | G33: 0.1 | H33: 60 | I33: 8444187 | K33: 109 | L33: =E33-K33 -> -19 | O33: 120 | P33: =E33/5 -> 18 | Q33: =16*P33-O33-F33 -> 168 | R33: =Q33 -> 168 | S33: =IFERROR(VLOOKUP(A33,заказ!A:B,2,0),0) -> 168 | V33: =(F33+O33+R33)/P33 -> 16 | W33: =(F33+O33)/P33 -> 6.6666667 | X33: 13 | Y33: 7.2 | Z33: 13.8 | AA33: 17.4 | AB33: 7.2 | AC33: 10.2 | AD33: 6 | AE33: 15 | AG33: =G33*R33 -> 16.8
A34: Сыр рассольный жирный Чечил копченый 43% 100 гр Останкино | B34: шт | C34: 150 | E34: 118 | F34: 32 | G34: 0.1 | H34: 90 | I34: 8444194 | K34: 120 | L34: =E34-K34 -> -2 | O34: 0 | P34: =E34/5 -> 23.6 | Q34: =14*P34-O34-F34 -> 298.4 | R34: =T34 -> 350 | S34: =IFERROR(VLOOKUP(A34,заказ!A:B,2,0),0) -> 348 | T34: 350 | V34: =(F34+O34+R34)/P34 -> 16.186441 | W34: =(F34+O34)/P34 -> 1.3559322 | X34: 2.4 | Y34: 9.2 | Z34: 19 | AA34: 4.4 | AB34: 4 | AC34: 16.6 | AD34: 7 | AE34: 8.6 | AG34: =G34*R34 -> 35
A35: Сыр твердый "Пармезан", с масовой долей жира 35% Останкино | B35: кг | G35: 0 | H35: 150 | I35: 8786928 | L35: =E35-K35 -> 0 | O35: 0 | P35: =E35/5 -> 0 | R35: =Q35 -> 0 | S35: =IFERROR(VLOOKUP(A35,заказ!A:B,2,0),0) -> 0 | V35: =(F35+O35+R35)/P35 -> #DIV/0! | W35: =(F35+O35)/P35 -> #DIV/0! | X35: 0 | Y35: 0 | Z35: 0 | AA35: 0 | AB35: 0 | AC35: 0 | AD35: 0 | AE35: 0 | AF35: нет потребности | AG35: =G35*R35 -> 0
A36: Сыр творожный Сливочный 140 гр. Останкино | B36: шт | C36: 260 | D36: 96 | E36: 49 | F36: 293 | G36: 0.14 | H36: 180 | I36: 9988377 | K36: 49 | L36: =E36-K36 -> 0 | O36: 0 | P36: =E36/5 -> 9.8 | R36: =Q36 -> 0 | S36: =IFERROR(VLOOKUP(A36,заказ!A:B,2,0),0) -> 0 | V36: =(F36+O36+R36)/P36 -> 29.897959 | W36: =(F36+O36)/P36 -> 29.897959 | X36: 8.4 | Y36: 0 | Z36: 0 | AA36: 0 | AB36: 0 | AC36: 0 | AD36: 0 | AE36: 0 | AF36: нужно увеличить продажи!!! / новинка | AG36: =G36*R36 -> 0
A37: Сыч/Прод Коровино Российский 50% 200г СЗМЖ Останкино | B37: шт | G37: 0.2 | H37: 120 | I37: 783К798 | L37: =E37-K37 -> 0 | O37: 490 | P37: =E37/5 -> 0 | Q37: 300 | R37: =Q37 -> 300 | S37: =IFERROR(VLOOKUP(A37,заказ!A:B,2,0),0) -> 300 | V37: =(F37+O37+R37)/P37 -> #DIV/0! | W37: =(F37+O37)/P37 -> #DIV/0! | X37: 0 | Y37: 0 | Z37: 0 | AA37: 0 | AB37: 0 | AC37: 0 | AD37: 0 | AE37: 0 | AF37: 15,12,25 завод не отгрузил / 18,08,25 завод не отгрузил / 11,08,25 завод не отгрузил | AG37: =G37*R37 -> 60
A38: Сыч/Прод Коровино Российский 50% 200г НОВАЯ СЗМЖ ОСТАНКИНО | B38: шт | C38: 100 | E38: 83 | F38: -1 | G38: 0 | H38: #N/A | I38: дубль | J38: Сыч/Прод Коровино Российский 50% 200г СЗМЖ Останкино | K38: 91 | L38: =E38-K38 -> -8 | O38: 0 | P38: =E38/5 -> 16.6 | R38: =Q38 -> 0 | S38: =IFERROR(VLOOKUP(A38,заказ!A:B,2,0),0) -> 0 | V38: =(F38+O38+R38)/P38 -> -0.060240964 | W38: =(F38+O38)/P38 -> -0.060240964 | X38: 48.8 | Y38: 37.8 | Z38: 32 | AA38: 35.2 | AB38: 39.4 | AC38: 37.2 | AD38: 42.8 | AE38: 28.4 | AG38: =G38*R38 -> 0
A39: Сыч/Прод Коровино Российский Оригин 50% ВЕС (3,5 кг) Останкино | B39: кг | C39: 225.2 | D39: 3.01 | E39: 170.792 | F39: 22.254 | G39: 1 | H39: 120 | I39: 783К811 | K39: 177.5 | L39: =E39-K39 -> -6.708 | O39: 345 | P39: =E39/5 -> 34.1584 | Q39: =20*P39-O39-F39 -> 315.914 | R39: =Q39 -> 315.914 | S39: =IFERROR(VLOOKUP(A39,заказ!A:B,2,0),0) -> 315 | V39: =(F39+O39+R39)/P39 -> 20 | W39: =(F39+O39)/P39 -> 10.751499 | X39: 23.2106 | Y39: 10.4478 | Z39: 9.5518 | AA39: 7.8756 | AB39: 20.768 | AC39: 20.1858 | AD39: 16.9882 | AE39: 9.0054 | AG39: =G39*R39 -> 315.914
A40: Сыч/Прод Коровино Тильзитер 50% 200г СЗМЖ ОСТАНКИНО | B40: шт | G40: 0.2 | H40: 120 | I40: 783К801 | L40: =E40-K40 -> 0 | O40: 500 | P40: =E40/5 -> 0 | Q40: =20*(P40+P41)-O40-O41-F40-F41 -> 367 | R40: =T40 -> 400 | S40: =IFERROR(VLOOKUP(A40,заказ!A:B,2,0),0) -> 400 | T40: 400 | V40: =(F40+O40+R40)/P40 -> #DIV/0! | W40: =(F40+O40)/P40 -> #DIV/0! | X40: 0 | Y40: 0 | Z40: 0 | AA40: 0 | AB40: 0 | AC40: 0 | AD40: 0 | AE40: 0 | AG40: =G40*R40 -> 80
A41: Сыч/Прод Коровино Тильзитер 50% 200г НОВАЯ СЗМЖ ОСТАНКИНО | B41: шт | C41: 240 | D41: 100 | E41: 234 | F41: 69 | G41: 0 | H41: #N/A | I41: дубль | J41: Сыч/Прод Коровино Тильзитер 50% 200г СЗМЖ ОСТАНКИНО | K41: 236 | L41: =E41-K41 -> -2 | O41: 0 | P41: =E41/5 -> 46.8 | R41: =Q41 -> 0 | S41: =IFERROR(VLOOKUP(A41,заказ!A:B,2,0),0) -> 0 | V41: =(F41+O41+R41)/P41 -> 1.474359 | W41: =(F41+O41)/P41 -> 1.474359 | X41: 36.2 | Y41: 25.2 | Z41: 25.4 | AA41: 19.4 | AB41: 31 | AC41: 28.4 | AD41: 37 | AE41: 25 | AG41: =G41*R41 -> 0
A42: Сыч/Прод Коровино Тильзитер Оригин 50% ВЕС (3,5 кг брус) СЗМЖ Останкино | B42: кг | C42: 90 | D42: 701.65 | E42: 201.133 | F42: 525.469 | G42: 1 | H42: 120 | I42: 783К825 | K42: 206.5 | L42: =E42-K42 -> -5.367 | O42: 705 | P42: =E42/5 -> 40.2266 | R42: =Q42 -> 0 | S42: =IFERROR(VLOOKUP(A42,заказ!A:B,2,0),0) -> 0 | V42: =(F42+O42+R42)/P42 -> 30.588441 | W42: =(F42+O42)/P42 -> 30.588441 | X42: 68.2558 | Y42: 62.1506 | Z42: 58.9332 | AA42: 50.287 | AB42: 61.1968 | AC42: 49.6484 | AD42: 67.227 | AE42: 70.3156 | AF42: 01,09,25 завод не отгрузит (150кг) / 04,08,25 завод отгрузил 160кг из заказанных 500кг | AG42: =G42*R42 -> 0
...

Sheet заказ
A1: 6948249 Майонезный соус провансаль 824,5гр деликатес.с массовой долей жирн.25% Коровино Останкино | B1: 96
A2: 6948256 Майонез провансаль классич.оливковый Папа может 372гр с массовой долей жирн. 67% Останкино | B2: 600
A3: 6948263 Майонез провансаль классич.оливковый Папа может 744гр с массовой долей жирн. 67% Останкино | B3: 408
A4: 6948270 Майонез провансаль классич.Папа может 372гр с массовой долей жирн. 67% Останкино | B4: 996
A5: 6948287 Майонез провансаль классич.Папа может 744гр с массовой долей жирн. 67% Останкино | B5: 600
A6: 9988438 Плавленый Сыр 45% "С ветчиной" СТМ"ПапаМожет" 180гр Останкино | B6: 32
A7: 9988445 Плавленый Сыр 45%"С грибами" СТМ"ПапаМожет" 180 гр Останкино | B7: 128
A8: Плавленый продукт с Сыром колбасный копченый 40% СТМ "Коровино" 400гр Останкино | B8: 28
A9: Сыр "Пармезан" 40% кусок 180 гр ОСТАНКИНО | B9: 102
A10: Сыр ПАПА МОЖЕТ "Гауда Голд" 45 % 180 гр (10шт) Останкино | B10: 200
A11: Сыр ПАПА МОЖЕТ "Голландский традиционный" 45% 180 гр (10шт) Останкино | B11: 520
A12: Сыр ПАПА МОЖЕТ "Папин завтрак" 45% 180 г Останкино | B12: 30
... A20: Сыч/Прод Коровино Тильзитер 50% 200г СЗМЖ ОСТАНКИНО | B20: 400
