Workbook
Name кол_во_инд.__упак_к: Бланк!$AC$3:$AC$415
Name номин.вес_нетто__кг: Бланк!$W$3:$W$415

Sheet Бланк
C1: Грузополучатель: | D1: =K3 | E1: ООО "НОВОЕ ВРЕМЯ" | K1: 130438122 | L1: 130438122 ООО "НОВОЕ ВРЕМЯ" 272151 Бердянский р-н 90 Трояны
K2: 130438119 | L2: 130438119 ООО "НОВОЕ ВРЕМЯ" 90 Мелитопольский р-н с. Семеновка, Северный переезд, стр.3
C3: Дата отгрузки с ОМПК: | D3: 46299 | E3: Доставка: | F3: =D3+3 | G3: =VLOOKUP(D1,K:L,2,0) | K3: 130438120 | L3: 130438120 ООО "НОВОЕ ВРЕМЯ" 93 Донецк г Чаадаева ул.д.1
K4: 130439104 | L4: 130439104 ООО "НОВОЕ ВРЕМЯ" Мариуполь
C5: Ответственные:
D6: Москва : | K6: =LEFT(L6,9)
B7: ЗАКАЗ | D7: Тип заказа: | E7: ZOR | K7: =LEFT(L7,9)
A9: кратко | B9: Наименование материала | C9: ЕИ | D9: Код материала | E9: Заказ кг/шт | F9: Вес нетто, кг | G9: Вес нетто, кг | H9: Вес нетто короба, кг | I9: Срок реализации, суток | J9: Примечание
B10: Вареные колбасы
A11: =RIGHT(D11,4) | B11: ГОВЯЖЬЯ Папа может вар п/о 0.4кг 6шт. | C11: ШТ | D11: 1001012427523 | E11: 56 | F11: 0.4 | G11: =E11*F11 | H11: 2.4 | I11: 60
A12: =RIGHT(D12,4) | B12: ГОВЯЖЬЯ Папа может вар п/о | C12: КГ | D12: 1001012426220 | F12: 1.35 | G12: =E12 | H12: 4.05 | I12: 60
A13: =RIGHT(D13,4) | B13: ДОКТОРСКАЯ ГОСТ Останкино вар п/о 0.35кг | C13: ШТ | D13: 1001010017539 | F13: 0.35 | G13: =E13*F13 | H13: 2.8 | I13: 60
A14: =RIGHT(D14,4) | B14: ДОКТОРСКАЯ ГОСТ Останкино вар п/о | C14: КГ | D14: 1001010017536 | F14: 1.35 | G14: =E14 | H14: 4.05 | I14: 60
A15: =RIGHT(D15,4) | B15: ДОМАШНИЙ РЕЦЕПТ Коровино вар п/о | C15: КГ | D15: 1001015646861 | E15: 17 | F15: 1.95 | G15: =E15 | H15: 3.9 | I15: 60
A16: =RIGHT(D16,4) | B16: ДОМАШНИЙ РЕЦЕПТ СО ШПИК.Коровино вар п/о | C16: КГ | D16: 1001015706862 | F16: 1.95 | G16: =E16 | H16: 3.9 | I16: 60
A17: =RIGHT(D17,4) | B17: МОЛОЧНАЯ Папа может вар п/о | C17: КГ | D17: 1001012456498 | E17: 52 | F17: 1 | G17: =E17 | H17: 4 | I17: 60
A18: =RIGHT(D18,4) | B18: МЯСНАЯ Папа может вар п/о | C18: КГ | D18: 1001012484063 | E18: 460 | F18: 1.35 | G18: =E18 | H18: 4.05 | I18: 60
A19: =RIGHT(D19,4) | B19: МЯСНАЯ Папа может вар п/о 0.4кг 8шт. | C19: ШТ | D19: 1001012486333 | E19: 456 | F19: 0.4 | G19: =E19*F19 | H19: 3.2 | I19: 60
A20: =RIGHT(D20,4) | B20: МЯСНАЯ СО ШПИКОМ Папа может вар п/о | C20: КГ | D20: 1001012634574 | E20: 39 | F20: 1.35 | G20: =E20 | H20: 4.05 | I20: 60
A21: =RIGHT(D21,4) | B21: МЯСНАЯ СО ШПИКОМ ПМ вар п/о 0.4кг 8шт. | C21: ШТ | D21: 1001012637334 | F21: 0.4 | G21: =E21*F21 | H21: 3.2 | I21: 60
A22: =RIGHT(D22,4) | B22: ФИЛЕЙНАЯ Папа может вар п/о | C22: КГ | D22: 1001012564813 | E22: 256 | F22: 1.35 | G22: =E22 | H22: 4.05 | I22: 60
A23: =RIGHT(D23,4) | B23: ФИЛЕЙНАЯ Папа может вар п/о 0.4кг | C23: ШТ | D23: 1001012566392 | E23: 207 | F23: 0.4 | G23: =E23*F23 | H23: 3.2 | I23: 60
A24: =RIGHT(D24,4) | B24: ЭКСТРА Папа может вар п/о | C24: КГ | D24: 1001012505851 | E24: 137 | F24: 1.35 | G24: =E24 | H24: 4.05 | I24: 60
A25: =RIGHT(D25,4) | B25: ЭКСТРА Папа может вар п/о 0.4кг 8шт_195к | C25: ШТ | D25: 1001012507632 | F25: 0.4 | G25: =E25*F25 | H25: 3.2 | I25: 60
A26: =RIGHT(D26,4) | B26: ДОКТОРСКАЯ ГОСТ Папа может вар п/о | C26: КГ | D26: 1001010014561 | F26: 1.35 | G26: =E26 | H26: 4.05 | I26: 60
A27: =RIGHT(D27,4) | B27: ДОКТОРСКАЯ ПРЕМИУМ вар п/о 0.4кг 8шт. | C27: ШТ | D27: 1001010106325 | E27: 44 | F27: 0.4 | G27: =E27*F27 | H27: 3.2 | I27: 60
A28: =RIGHT(D28,4) | B28: ДОКТОРСКАЯ ПРЕМИУМ п/о(п) | C28: КГ | D28: 1001010108014 | E28: 5 | F28: 1.35 | G28: =E28 | H28: 5.4 | I28: 60
A29: =RIGHT(D29,4) | B29: ЛЮБИТЕЛЬСКАЯ ОСТАНКИНСКАЯ вар ц/о в/у | C29: КГ | D29: 1001017557514 | E29: 60 | G29: =E29 | J29: =VLOOKUP(D29,[1]Бланк!$D:$J,7,0)
A30: =RIGHT(D30,4) | B30: ТЕЛЯЧЬЯ ГОСТ Останкино вар н/о в/у | C30: КГ | D30: 1001017567518 | E30: 22 | G30: =E30 | J30: =VLOOKUP(D30,[1]Бланк!$D:$J,7,0)
A31: =RIGHT(D31,4) | B31: СЕЙЧАС СЕЗОН ПМ вар п/о 0.4кг | C31: ШТ | D31: 1001016747343 | F31: 0.4 | G31: =E31*F31 | H31: 3.2 | I31: 60
A32: =RIGHT(D32,4) | B32: С ИНДЕЙКОЙ Папа может вар п/о 0.4кг 8шт. | C32: ШТ | D32: 1001015026797 | F32: 0.4 | G32: =E32*F32 | H32: 3.2 | I32: 60
A33: =RIGHT(D33,4) | B33: КЛАССИЧЕСКАЯ ПМ вар п/о 0.3кг 8шт_209к | C33: ШТ | D33: 1001013957231 | E33: 6 | F33: 0.3 | G33: =E33*F33 | H33: 2.4 | I33: 60
B34: Сосиски
A35: =RIGHT(D35,4) | B35: БАВАРСКИЕ ПМ сос ц/о мгс 0.35кг 8шт. | C35: ШТ | D35: 1001021966602 | F35: 0.35 | G35: =E35*F35 | H35: 2.8 | I35: 45
A36: =RIGHT(D36,4) | B36: ДЛЯ ДЕТЕЙ Папа может сос п/о мгс 0.264кг | C36: ШТ | D36: 1001025767601 | F36: 0.264 | G36: =E36*F36 | H36: 1.58 | I36: 30
A37: =RIGHT(D37,4) | B37: ДЛЯ ДЕТЕЙ Папа может сос п/о мгс 0.33кг | C37: ШТ | D37: 1001025767461 | E37: 150 | F37: 0.33 | G37: =E37*F37 | H37: 1.98 | I37: 30
A38: =RIGHT(D38,4) | B38: С ИНДЕЙКОЙ ПМ сос ц/о в/у 1/270 8шт. | C38: ШТ | D38: 1001025027040 | F38: 0.27 | G38: =E38*F38
A39: =RIGHT(D39,4) | B39: МОЛОЧНЫЕ ГОСТ сос ц/о мгс 0.4кг 7шт. | C39: ШТ | D39: 1001020836759 | F39: 0.4 | G39: =E39*F39 | H39: 2.8 | I39: 30
A40: =RIGHT(D40,4) | B40: МОЛОЧНЫЕ ГОСТ сос ц/о мгс 1*4 | C40: КГ | D40: 1001020836761 | F40: 1 | G40: =E40 | H40: 4 | I40: 30
A41: =RIGHT(D41,4) | B41: МОЛОЧНЫЕ КЛАССИЧЕСКИЕ сос п/о мгс 2*4_С | C41: КГ | D41: 1001024976829 | F41: 2.1 | G41: =E41 | H41: 8.4 | I41: 45
...

Sheet Лист1
B2: 7523 | C2: 1001012427523 | D2: ГОВЯЖЬЯ Папа может вар п/о 0.4кг 6шт. | E2: Новинка, ротация | F2: ШТ | G2: 0.4
B3: 6220 | C3: 1001012426220 | D3: ГОВЯЖЬЯ Папа может вар п/о | F3: КГ | G3: 1
B4: 7539 | C4: 1001010017539 | D4: ДОКТОРСКАЯ ГОСТ Останкино вар п/о 0.35кг | E4: Новинка, ротация | F4: ШТ | G4: 0.35
B5: 7536 | C5: 1001010017536 | D5: ДОКТОРСКАЯ ГОСТ Останкино вар п/о | E5: Новинка, ротация | F5: КГ | G5: 1
B6: 6340 | C6: 1001012816340 | D6: ДОМАШНИЙ РЕЦЕПТ Коровино 0.5кг 8шт. | F6: ШТ | G6: 0.5
B7: 6861 | C7: 1001015646861 | D7: ДОМАШНИЙ РЕЦЕПТ Коровино вар п/о | F7: КГ | G7: 1
B8: 6862 | C8: 1001015706862 | D8: ДОМАШНИЙ РЕЦЕПТ СО ШПИК.Коровино вар п/о | F8: КГ | G8: 1
B9: 6341 | C9: 1001012816341 | D9: ДОМАШНИЙ РЕЦЕПТ СО ШПИКОМ Коровино 0.5кг | F9: ШТ | G9: 0.5
B10: 6498 | C10: 1001012456498 | D10: МОЛОЧНАЯ Папа может вар п/о | F10: КГ | G10: 1
B11: 4063 | C11: 1001012484063 | D11: МЯСНАЯ Папа может вар п/о | F11: КГ | G11: 1
B12: 6333 | C12: 1001012486333 | D12: МЯСНАЯ Папа может вар п/о 0.4кг 8шт. | F12: ШТ | G12: 0.4
B13: 4574 | C13: 1001012634574 | D13: МЯСНАЯ СО ШПИКОМ Папа может вар п/о | F13: КГ | G13: 1
B14: 7334 | C14: 1001012637334 | D14: МЯСНАЯ СО ШПИКОМ ПМ вар п/о 0.4кг 8шт. | F14: ШТ | G14: 0.4
B15: 4813 | C15: 1001012564813 | D15: ФИЛЕЙНАЯ Папа может вар п/о | F15: КГ | G15: 1
B16: 6392 | C16: 1001012566392 | D16: ФИЛЕЙНАЯ Папа может вар п/о 0.4кг | F16: ШТ | G16: 0.4
B17: 5851 | C17: 1001012505851 | D17: ЭКСТРА Папа может вар п/о | F17: КГ | G17: 1
B18: 6353 | C18: 1001012506353 | D18: ЭКСТРА Папа может вар п/о 0.4кг 8шт. | E18: Ротация на код 7632 | F18: ШТ | G18: 0.4
B19: 4561 | C19: 1001010014561 | D19: ДОКТОРСКАЯ ГОСТ Папа может вар п/о | F19: КГ | G19: 1
B20: 7555 | C20: 1001012497555 | D20: ДОКТОРСКАЯ ПО-ОСТАНКИНСКИ вар б/о в/у | E20: Новинка, ротация | F20: КГ | G20: 1
B21: 6325 | C21: 1001010106325 | D21: ДОКТОРСКАЯ ПРЕМИУМ вар п/о 0.4кг 8шт. | F21: ШТ | G21: 0.4
B22: 7556 | C22: 1001017597556 | D22: РУССКАЯ ПО-ОСТАНКИНСКИ вар б/о в/у | E22: Новинка, ротация | F22: КГ | G22: 1
B23: 7303 | C23: 1001010857303 | D23: РУССКАЯ ПРЕМИУМ ПМ вар п/о | F23: КГ | G23: 1
B24: 8014 | C24: 1001010108014 | D24: ДОКТОРСКАЯ ПРЕМИУМ вар п/о(п) | F24: КГ | G24: 1
B25: 7343 | C25: 1001016747343 | D25: СЕЙЧАС СЕЗОН ПМ вар п/о 0.4кг | F25: ШТ | G25: 0.4
B26: 6797 | C26: 1001015026797 | D26: С ИНДЕЙКОЙ Папа может вар п/о 0.4кг 8шт. | F26: ШТ | G26: 0.4
B27: 7231 | C27: 1001013957231 | D27: КЛАССИЧЕСКАЯ ПМ вар п/о 0.3кг 8шт_209к | F27: ШТ | G27: 0.3
D28: Ветчины
B29: 4584 | C29: 1001092674584 | D29: ВЕТЧ.ИЗ ЛОПАТКИ Папа может п/о_HRC | F29: КГ | G29: 1
B30: 6495 | C30: 1001092436495 | D30: ВЕТЧ.МРАМОРНАЯ в/у срез 0.3кг 6шт_45с | F30: ШТ | G30: 0.3
B31: 6470 | C31: 1001092436470 | D31: ВЕТЧ.МРАМОРНАЯ в/у_45с | F31: КГ | G31: 1
B32: 5452 | C32: 1001092485452 | D32: ВЕТЧ.МЯСНАЯ Папа может п/о | F32: КГ | G32: 1
B33: 3215 | C33: 1001094053215 | D33: ВЕТЧ.МЯСНАЯ Папа может п/о 0.4кг 8шт. | F33: ШТ | G33: 0.4
B34: 6866 | C34: 1001095716866 | D34: ВЕТЧ.НЕЖНАЯ Коровино п/о_Маяк | F34: КГ | G34: 1
B35: 5495 | C35: 1001093345495 | D35: ВЕТЧ.С ИНДЕЙКОЙ Папа может п/о 400*6 | F35: ШТ | G35: 0.4
B36: 7377 | C36: 1001095027377 | D36: ВЕТЧ.С ИНДЕЙКОЙ ПМ в/у срез 0.3кг 6шт. | F36: ШТ | G36: 0.3
B37: 6925 | C37: 1001095226925 | D37: ВЕТЧ.КЛАССИЧЕСКАЯ в/у 0.6кг 8шт. | F37: ШТ | G37: 0.6
B38: 6025 | C38: 1001094966025 | D38: ВЕТЧ.ФИРМЕННАЯ С ИНДЕЙКОЙ п/о | F38: КГ | G38: 1
D39: Копчености в/к
B40: 7090 | C40: 1001084217090 | D40: СВИНИНА ПО-ДОМ. к/в мл/к в/у 0.3кг_50с | F40: ШТ | G40: 0.3
B41: 7187 | C41: 1001085637187 | D41: ГРУДИНКА ПРЕМИУМ к/в мл/к в/у 0.3кг_50с | F41: ШТ | G41: 0.3
...
