Workbook

Sheet Sheet
A3: Номенклатура | B3: Ед. изм. | C3: Начальный остаток | D3: Приход | E3: Расход | F3: Конечный остаток | G3: крат | H3: сроки | I3: метка | J3: метка2 | K3: заяв | L3: разн | M3: без опта | N3: опт | O3: заказ в пути | P3: ср нов | Q3: расчет | R3: итого1 | S3: итого | T3: заказ | U3: заказ | V3: ТК | W3: ТК | X3: MAX | Y3: кон ост | Z3: факт | AA3: ср | AB3: ср | AC3: ср | AD3: ср | AE3: ср | AF3: ср | AG3: ср | AH3: ср | AI3: ср | AJ3: ср | AK3: комментарии | AL3: вес | AM3: вес
O4: 07,09, | P4: 08,09, | S4: сети | T4: 14,09, | U4: 14,09,сети | V4: Титенок | W4: Сети | X4: Титенок | AA4: 01,09, | AB4: 25,08, | AC4: 18,08, | AD4: 11,08, | AE4: 04,08, | AF4: 28,07, | AG4: 21,07, | AH4: 14,07, | AI4: 07,07, | AJ4: 29,06, | AM4: сети
E5: =SUM(E6:E499) -> 2799.93 | F5: =SUM(F6:F499) -> 3474.351 | K5: =SUM(K6:K499) -> 3478.238 | L5: =SUM(L6:L499) -> -678.308 | M5: =SUM(M6:M499) -> 0 | N5: =SUM(N6:N499) -> 0 | O5: =SUM(O6:O499) -> 1859 | P5: =SUM(P6:P499) -> 559.986 | Q5: =SUM(Q6:Q499) -> 3523.937 | R5: =SUM(R6:R499) -> 3924.537 | ... U5: =SUM(U6:U499) -> 160 | AA5: =SUM(AA6:AA499) -> 430.4206 | AB5: =SUM(AB6:AB499) -> 432.4984 | AC5: =SUM(AC6:AC499) -> 540.8796 | AD5: =SUM(AD6:AD499) -> 359.4726 | AE5: =SUM(AE6:AE499) -> 466.0342 | AF5: =SUM(AF6:AF499) -> 440.052 | AG5: =SUM(AG6:AG499) -> 293.5244 | AH5: =SUM(AH6:AH499) -> 493.168 | ... AJ5: =SUM(AJ6:AJ499) -> 562.3556 | AL5: =SUM(AL6:AL499) -> 963.157 | AM5: =SUM(AM6:AM499) -> 28.8
A6: 1103201 Сыр копченый "Косичка" мини ПАПА МОЖЕТ 55г лоток ОСТАНКИНО | B6: шт | C6: 70 | E6: 4 | F6: 66 | G6: 0.055 | H6: 120 | K6: 4 | L6: =E6-K6 -> 0 | P6: =E6/5 -> 0.8 | R6: =Q6 -> 0 | Y6: =(F6+O6+R6)/P6 -> 82.5 | Z6: =(F6+O6)/P6 -> 82.5 | AA6: 3.6 | AB6: 3.2 | AC6: 3.2 | AD6: 0 | AE6: 6.4 | AF6: 3.2 | AG6: 0 | AH6: 0 | AI6: 0 | AJ6: 0 | AK6: нужно увеличить продажи!!! / новинка | AL6: =G6*R6 -> 0 | AM6: =G6*S6 -> 0
A7: 2103201 БЖП, произведенный по технологии сыра копченый "Косичка" мини Ассорти ОСТАНКИНО | B7: шт | C7: 68 | D7: 24 | E7: 7 | F7: 85 | G7: 0.1 | H7: 120 | K7: 7 | L7: =E7-K7 -> 0 | P7: =E7/5 -> 1.4 | R7: =Q7 -> 0 | Y7: =(F7+O7+R7)/P7 -> 60.714286 | Z7: =(F7+O7)/P7 -> 60.714286 | AA7: 2 | AB7: 6 | AC7: 2.6 | AD7: 1 | AE7: 6 | AF7: 3 | AG7: 0 | AH7: 0 | AI7: 0 | AJ7: 0 | AK7: нужно увеличить продажи!!! / новинка | AL7: =G7*R7 -> 0 | AM7: =G7*S7 -> 0
A8: 2105201 БЖП, произведенный по технологии сыра копченый "Балык" резаный 4 вкуса ОСТАНКИНО | B8: шт | C8: 28 | D8: 24 | E8: 11 | F8: 36 | G8: 0.1 | H8: 120 | K8: 11 | L8: =E8-K8 -> 0 | P8: =E8/5 -> 2.2 | R8: =Q8 -> 0 | Y8: =(F8+O8+R8)/P8 -> 16.363636 | Z8: =(F8+O8)/P8 -> 16.363636 | AA8: 1.2 | AB8: 3.2 | AC8: 1.4 | AD8: 3 | AE8: 2.2 | AF8: 2.4 | AG8: 0 | AH8: 0 | AI8: 0 | AJ8: 0 | AK8: нужно увеличить продажи / новинка | AL8: =G8*R8 -> 0 | AM8: =G8*S8 -> 0
A9: 3323 Сыр Российский цилиндр 1/4 пленка ЮКМП м.д.ж. 50% ОСТАНКИНО | B9: кг | C9: 25.187 | D9: 30.862 | E9: 32.568 | F9: 15.555 | G9: 1 | H9: 120 | K9: 36.638 | L9: =E9-K9 -> -4.07 | O9: 75 | P9: =E9/5 -> 6.5136 | Q9: =15*P9-O9-F9 -> 7.149 | R9: =Q9 -> 7.149 | T9: =VLOOKUP(A9,заказ!A:B,2,0) -> 5 | Y9: =(F9+O9+R9)/P9 -> 15 | Z9: =(F9+O9)/P9 -> 13.90245 | AA9: 8.3614 | AB9: 5.9184 | AC9: 5.124 | AD9: 2.4896 | AE9: 4.2826 | AF9: 8.3128 | AG9: 1.8976 | AH9: 7.5636 | AI9: 6.4904 | AJ9: 13.1032 | AL9: =G9*R9 -> 7.149 | AM9: =G9*S9 -> 0
A10: 4421577 Спред растительно-сливочный "Сливочный вкус" 82,5% 180гр Останкино | B10: шт | E10: -2 | G10: 0.18 | H10: 180 | K10: 5 | L10: =E10-K10 -> -7 | O10: 0 | P10: =E10/5 -> -0.4 | Q10: 24 | R10: =Q10 -> 24 | T10: 0 | Y10: =(F10+O10+R10)/P10 -> -60 | Z10: =(F10+O10)/P10 -> 0 | AA10: 0 | AB10: 0 | AC10: 0 | AD10: 0 | AE10: 0 | AF10: 2 | AG10: 0 | AH10: 2 | AI10: 0.6 | AJ10: 1.8 | AK10: 10,09,26 - нет на заводе / 03,09,26 - нет на заводе / 27,08,26 - нет на заводе / 24,08,26 - нет на заводе / 13,08,26 - нет на заводе / 30,07,26 - нет на заводе / 62шт в уценку (28,07,26) | AL10: =G10*R10 -> 4.32 | AM10: =G10*S10 -> 0
A11: 4421584 Спред растительно-сливочный "Сливочный вкус" 72,5% 180гр Останкино | B11: шт | G11: 0.18 | H11: 180 | L11: =E11-K11 -> 0 | O11: 0 | P11: =E11/5 -> 0 | Q11: 24 | R11: =Q11 -> 24 | T11: 0 | Y11: =(F11+O11+R11)/P11 -> #DIV/0! | Z11: =(F11+O11)/P11 -> #DIV/0! | AA11: 0 | AB11: 0 | AC11: 0 | AD11: 0 | AE11: 0 | AF11: 3 | AG11: 0 | AH11: 1.2 | AI11: 0 | AJ11: 2 | AK11: 10,09,26 - нет на заводе / 03,09,26 - нет на заводе / 27,08,26 - нет на заводе / 24,08,26 - нет на заводе / 13,08,26 - нет на заводе / 30,07,26 - нет на заводе / 62шт в уценку (28,07,26) | AL11: =G11*R11 -> 4.32 | AM11: =G11*S11 -> 0
A12: 4931 Сыр полутвердый "Купеческий" с ароматом топленого молока, с м.д.ж. 50% ОСТАНКИНО | B12: кг | C12: 80.544 | E12: 19.496 | F12: 61.048 | G12: 1 | H12: 180 | K12: 20 | L12: =E12-K12 -> -0.504 | P12: =E12/5 -> 3.8992 | R12: =Q12 -> 0 | Y12: =(F12+O12+R12)/P12 -> 15.656545 | Z12: =(F12+O12)/P12 -> 15.656545 | AA12: 1.3052 | AB12: 0.6368 | AC12: 1.2988 | AD12: 1.2928 | AE12: 0.724 | AF12: 1.914 | AG12: 0.628 | AH12: 6.6284 | AI12: 1.3204 | AJ12: 5.8716 | AL12: =G12*R12 -> 0 | AM12: =G12*S12 -> 0
A13: 6948249 Майонезный соус провансаль 824,5гр деликатес.с массовой долей жирн.25% Коровино Останкино | B13: шт | C13: 140 | E13: 7 | F13: 133 | G13: 0.8245 | H13: 180 | K13: 9 | L13: =E13-K13 -> -2 | P13: =E13/5 -> 1.4 | R13: =Q13 -> 0 | Y13: =(F13+O13+R13)/P13 -> 95 | Z13: =(F13+O13)/P13 -> 95 | AA13: 0 | AB13: 0.4 | AC13: 0 | AD13: 0 | AE13: 0 | AF13: 0.6 | AG13: 0 | AH13: 0 | AI13: 0 | AJ13: 0 | AK13: нужно увеличить продажи!!! | AL13: =G13*R13 -> 0 | AM13: =G13*S13 -> 0
A14: 6948256 Майонез провансаль классич.оливковый Папа может 372гр с массовой долей жирн. 67% Останкино | B14: шт | C14: 272 | D14: 55 | E14: 93 | F14: 192 | G14: 0.372 | H14: 180 | K14: 102 | L14: =E14-K14 -> -9 | P14: =E14/5 -> 18.6 | Q14: =13*P14-O14-F14 -> 49.8 | R14: 120 | T14: =VLOOKUP(A14,заказ!A:B,2,0) -> 120 | V14: =VLOOKUP(A14,[1]Sheet!$A:$R,18,0) -> 120 | Y14: =(F14+O14+R14)/P14 -> 16.774194 | Z14: =(F14+O14)/P14 -> 10.322581 | AA14: 7.6 | AB14: 2.4 | AC14: 9.8 | AD14: 16.2 | AE14: 15.2 | AF14: 4.6 | AG14: 5 | AH14: 16 | AI14: 2.6 | AJ14: 29.8 | AL14: =G14*R14 -> 44.64 | AM14: =G14*S14 -> 0
A15: 6948263 Майонез провансаль классич.оливковый Папа может 744гр с массовой долей жирн. 67% Останкино | B15: шт | C15: -2 | F15: -2 | G15: 0.744 | H15: 180 | K15: 13 | L15: =E15-K15 -> -13 | O15: 24 | P15: =E15/5 -> 0 | R15: 190 | T15: =VLOOKUP(A15,заказ!A:B,2,0) -> 192 | V15: =VLOOKUP(A15,[1]Sheet!$A:$R,18,0) -> 120 | X15: 190 | Y15: =(F15+O15+R15)/P15 -> #DIV/0! | Z15: =(F15+O15)/P15 -> #DIV/0! | AA15: 1 | AB15: 6.6 | AC15: 6.4 | AD15: 2.8 | AE15: 2.6 | AF15: 4 | AG15: 2.6 | AH15: 4 | AI15: 2.4 | AJ15: 8.4 | AK15: 285шт в уценку (27,08,26) | AL15: =G15*R15 -> 141.36 | AM15: =G15*S15 -> 0
A16: 6948270 Майонез провансаль классич.Папа может 372гр с массовой долей жирн. 67% Останкино | B16: шт | C16: 357 | D16: 163 | E16: 176 | F16: 268 | G16: 0.372 | H16: 180 | K16: 198 | L16: =E16-K16 -> -22 | P16: =E16/5 -> 35.2 | Q16: =13*P16-O16-F16 -> 189.6 | R16: 240 | T16: =VLOOKUP(A16,заказ!A:B,2,0) -> 240 | V16: =VLOOKUP(A16,[1]Sheet!$A:$R,18,0) -> 240 | Y16: =(F16+O16+R16)/P16 -> 14.431818 | Z16: =(F16+O16)/P16 -> 7.6136364 | AA16: 11.6 | AB16: 10.2 | AC16: 16.2 | AD16: 7.8 | AE16: 15.4 | AF16: 15.8 | AG16: 10 | AH16: 20.4 | AI16: 8.8 | AJ16: 42.8 | AL16: =G16*R16 -> 89.28 | AM16: =G16*S16 -> 0
A17: 6948287 Майонез провансаль классич.Папа может 744гр с массовой долей жирн. 67% Останкино | B17: шт | C17: -4 | D17: 96 | E17: 59 | F17: 2 | G17: 0.744 | H17: 180 | K17: 101 | L17: =E17-K17 -> -42 | P17: =E17/5 -> 11.8 | Q17: =10*P17-O17-F17 -> 116 | R17: 180 | T17: =VLOOKUP(A17,заказ!A:B,2,0) -> 180 | V17: =VLOOKUP(A17,[1]Sheet!$A:$R,18,0) -> 120 | X17: 180 | Y17: =(F17+O17+R17)/P17 -> 15.423729 | Z17: =(F17+O17)/P17 -> 0.16949153 | AA17: 4 | AB17: 11 | AC17: 8.4 | AD17: 3.2 | AE17: 12.4 | AF17: 1.8 | AG17: 5.8 | AH17: 6.2 | AI17: 7 | AJ17: 15.8 | AK17: 24,08,26 - отсутствует на заводе | AL17: =G17*R17 -> 133.92 | AM17: =G17*S17 -> 0
A18: 9988438 Плавленый Сыр 45% "С ветчиной" СТМ"ПапаМожет" 180гр Останкино | B18: шт | C18: 62 | D18: 21 | E18: 29 | F18: 42 | G18: 0.18 | H18: 270 | K18: 37 | L18: =E18-K18 -> -8 | P18: =E18/5 -> 5.8 | Q18: =15*P18-O18-F18 -> 45 | R18: =Q18 -> 45 | T18: =VLOOKUP(A18,заказ!A:B,2,0) -> 48 | Y18: =(F18+O18+R18)/P18 -> 15 | Z18: =(F18+O18)/P18 -> 7.2413793 | AA18: 5 | AB18: 5.8 | AC18: 6.8 | AD18: 9 | AE18: 5.8 | AF18: 4.4 | AG18: 2 | AH18: 3.6 | AI18: 6.2 | AJ18: 9.2 | AL18: =G18*R18 -> 8.1 | AM18: =G18*S18 -> 0
A19: 9988445 Плавленый Сыр 45%"С грибами" СТМ"ПапаМожет" 180 гр Останкино | B19: шт | C19: 52 | D19: 16 | E19: 38 | F19: 21 | G19: 0.18 | H19: 270 | K19: 41 | L19: =E19-K19 -> -3 | O19: 16 | P19: =E19/5 -> 7.6 | Q19: =15*P19-O19-F19 -> 77 | R19: =Q19 -> 77 | T19: =VLOOKUP(A19,заказ!A:B,2,0) -> 80 | Y19: =(F19+O19+R19)/P19 -> 15 | Z19: =(F19+O19)/P19 -> 4.8684211 | AA19: 4.8 | AB19: 5.8 | AC19: 5.8 | AD19: 9.2 | AE19: 5.2 | AF19: 4.4 | AG19: 3.2 | AH19: 5.4 | AI19: 6.6 | AJ19: 9.6 | AL19: =G19*R19 -> 13.86 | AM19: =G19*S19 -> 0
A20: Масло "Папа может" 82,5% 180гр Останкино | B20: шт | C20: 359 | D20: 92 | E20: 196 | F20: 160 | G20: 0.18 | H20: 180 | K20: 268 | L20: =E20-K20 -> -72 | O20: 200 | P20: =E20/5 -> 39.2 | Q20: =15*P20-O20-F20 -> 228 | R20: =Q20 -> 228 | T20: =VLOOKUP(A20,заказ!A:B,2,0) -> 230 | Y20: =(F20+O20+R20)/P20 -> 15 | Z20: =(F20+O20)/P20 -> 9.1836735 | AA20: 38.6 | AB20: 36.6 | AC20: 46.2 | AD20: 38 | AE20: 34 | AF20: 30.0788 | AG20: 33.8 | AH20: 46 | AI20: 63 | AJ20: 56.6 | AL20: =G20*R20 -> 41.04 | AM20: =G20*S20 -> 0
A21: Масло сливочное 72,5 % 180 гр.(10 шт) СЛАВЯНА Останкино | B21: шт | C21: 251 | D21: 31 | E21: 103 | F21: 122 | G21: 0.18 | H21: 180 | K21: 156 | L21: =E21-K21 -> -53 | O21: 60 | P21: =E21/5 -> 20.6 | Q21: =15*P21-O21-F21 -> 127 | R21: =Q21 -> 127 | T21: =VLOOKUP(A21,заказ!A:B,2,0) -> 130 | Y21: =(F21+O21+R21)/P21 -> 15 | Z21: =(F21+O21)/P21 -> 8.8349515 | AA21: 19.2 | AB21: 15 | AC21: 26.6 | AD21: 30.6 | AE21: 17.6 | AF21: 16.2 | AG21: 9.2 | AH21: 27.6 | AI21: 28.4 | AJ21: 18.8 | AL21: =G21*R21 -> 22.86 | AM21: =G21*S21 -> 0
A22: Плавленый Сыр колбасный копченый 40% СТМ"ПапаМожет"400гр Останкино | B22: шт | C22: 31 | E22: -2 | F22: 31 | G22: 0.4 | H22: 270 | K22: 25 | L22: =E22-K22 -> -27 | P22: =E22/5 -> -0.4 | R22: =Q22 -> 0 | Y22: =(F22+O22+R22)/P22 -> -77.5 | Z22: =(F22+O22)/P22 -> -77.5 | AA22: -0.4 | AB22: 0 | AC22: 0 | AD22: 0 | AE22: -0.4 | AF22: 0 | AG22: 0.4 | AH22: 0.4 | AI22: 0.4 | AJ22: 0.8 | AK22: нужно увеличить продажи!!! | AL22: =G22*R22 -> 0 | AM22: =G22*S22 -> 0
A23: Плавленый продукт с Сыром колбасный копченый 40% СТМ "Коровино" 400гр Останкино | B23: шт | C23: 26 | E23: 6 | F23: 18 | G23: 0.4 | H23: 270 | K23: 6 | L23: =E23-K23 -> 0 | P23: =E23/5 -> 1.2 | R23: =Q23 -> 0 | Y23: =(F23+O23+R23)/P23 -> 15 | Z23: =(F23+O23)/P23 -> 15 | AA23: 0.4 | AB23: 2 | AC23: 0.6 | AD23: 0.4 | AE23: 0.4 | AF23: 0 | AG23: 0 | AH23: 1.6 | AI23: 0.8 | AJ23: 1 | AL23: =G23*R23 -> 0 | AM23: =G23*S23 -> 0
A24: Сыр "Пармезан" 40% кусок 180 гр ОСТАНКИНО | B24: шт | C24: 167 | D24: 137.23 | E24: 88 | F24: 200 | G24: 0.18 | H24: 150 | K24: 105 | L24: =E24-K24 -> -17 | P24: =E24/5 -> 17.6 | Q24: =15*P24-O24-F24 -> 64 | R24: 90 | T24: =VLOOKUP(A24,заказ!A:B,2,0) -> 90 | V24: =VLOOKUP(A24,[1]Sheet!$A:$R,18,0) -> 90 | Y24: =(F24+O24+R24)/P24 -> 16.477273 | Z24: =(F24+O24)/P24 -> 11.363636 | AA24: 1.6 | AB24: 1 | AC24: 11.8 | AD24: 2.6 | AE24: 6.8 | AF24: 13.2 | AG24: 10.6 | AH24: 12.2 | AI24: 8.8 | AJ24: 5.8 | AL24: =G24*R24 -> 16.2 | AM24: =G24*S24 -> 0
A25: Сыр Боккончини копченый 40% 100 гр. ОСТАНКИНО | B25: шт | C25: 337 | D25: 4 | E25: 125 | F25: 173 | G25: 0.1 | H25: 90 | K25: 131 | L25: =E25-K25 -> -6 | O25: 16 | P25: =E25/5 -> 25 | Q25: =15*P25-O25-F25 -> 186 | R25: =Q25 -> 186 | T25: =VLOOKUP(A25,заказ!A:B,2,0) -> 184 | Y25: =(F25+O25+R25)/P25 -> 15 | Z25: =(F25+O25)/P25 -> 7.56 | AA25: 22.4 | AB25: 14.6 | AC25: 17.4 | AD25: 11 | AE25: 36.4 | AF25: 20 | AG25: 16.2 | AH25: 20.8 | AI25: 14 | AJ25: 21.4 | AL25: =G25*R25 -> 18.6 | AM25: =G25*S25 -> 0
A26: Сыр Косичка сырная 45% 100г/8шт Папа Может Останкино | B26: шт | C26: 151 | D26: 192 | E26: 135 | F26: 190 | G26: 0.1 | H26: 60 | K26: 154 | L26: =E26-K26 -> -19 | P26: =E26/5 -> 27 | Q26: =15*P26-O26-F26 -> 215 | R26: =Q26 -> 215 | T26: =VLOOKUP(A26,заказ!A:B,2,0) -> 216 | Y26: =(F26+O26+R26)/P26 -> 15 | Z26: =(F26+O26)/P26 -> 7.037037 | AA26: 15.8 | AB26: 26.2 | AC26: 15 | AD26: 25.4 | AE26: 25.2 | AF26: 12.2 | AG26: 6.6 | AH26: 17.6 | AI26: 8 | AJ26: 5.2 | AL26: =G26*R26 -> 21.5 | AM26: =G26*S26 -> 0
A27: Сыр Косичка сырная копченая 43% 100г/8шт Папа Может Останкино | B27: шт | C27: 193 | D27: 8 | E27: 92 | F27: 86 | G27: 0.1 | H27: 90 | K27: 110 | L27: =E27-K27 -> -18 | O27: 72 | P27: =E27/5 -> 18.4 | Q27: =15*P27-O27-F27 -> 118 | R27: =Q27 -> 118 | T27: =VLOOKUP(A27,заказ!A:B,2,0) -> 120 | Y27: =(F27+O27+R27)/P27 -> 15 | Z27: =(F27+O27)/P27 -> 8.5869565 | AA27: 16.8 | AB27: 11.2 | AC27: 17.8 | AD27: 21 | AE27: 16.6 | AF27: 15 | AG27: 13.2 | AH27: 17.6 | AI27: 10 | AJ27: 18.2 | AL27: =G27*R27 -> 11.8 | AM27: =G27*S27 -> 0
A28: Сыр ПАПА МОЖЕТ "Гауда Голд" 45 % 180 гр (10шт) Останкино | B28: шт | C28: 59 | D28: 7 | E28: 62 | F28: -8 | G28: 0.18 | H28: 150 | K28: 91 | L28: =E28-K28 -> -29 | P28: =E28/5 -> 12.4 | Q28: =10*P28-O28-F28 -> 132 | R28: =Q28 -> 132 | T28: =VLOOKUP(A28,заказ!A:B,2,0) -> 130 | Y28: =(F28+O28+R28)/P28 -> 10 | Z28: =(F28+O28)/P28 -> -0.64516129 | AA28: 2 | AB28: 7 | AC28: 19 | AD28: 16.2 | AE28: 13.8 | AF28: 5.2 | AG28: 8.4 | AH28: 11.2 | AI28: 17.8 | AJ28: 14.6 | AK28: 187шт в уценку (27,08,26) | AL28: =G28*R28 -> 23.76 | AM28: =G28*S28 -> 0
A29: Сыр ПАПА МОЖЕТ "Голландский традиционный" 45% 180 гр (10шт) Останкино | B29: шт | C29: 402 | D29: 104 | E29: 358 | F29: 24 | G29: 0.18 | H29: 150 | K29: 378 | L29: =E29-K29 -> -20 | O29: 420 | P29: =E29/5 -> 71.6 | Q29: =14*P29-O29-F29 -> 558.4 | R29: =Q29 -> 558.4 | T29: =VLOOKUP(A29,заказ!A:B,2,0) -> 560 | Y29: =(F29+O29+R29)/P29 -> 14 | Z29: =(F29+O29)/P29 -> 6.2011173 | AA29: 57.6 | AB29: 47.8 | AC29: 68.6 | AD29: 30 | AE29: 58 | AF29: 69 | AG29: 36 | AH29: 58.4 | AI29: 37 | AJ29: 51.2 | AK29: 130шт в уценку (27,08,26) | AL29: =G29*R29 -> 100.512 | AM29: =G29*S29 -> 0
A30: Сыр ПАПА МОЖЕТ "Министерский" 180 г фасованный массовая Останкино | B30: шт | C30: 114 | D30: 2 | E30: 22 | F30: 91 | G30: 0.18 | H30: 150 | K30: 40 | L30: =E30-K30 -> -18 | P30: =E30/5 -> 4.4 | R30: =Q30 -> 0 | Y30: =(F30+O30+R30)/P30 -> 20.681818 | Z30: =(F30+O30)/P30 -> 20.681818 | AA30: 4.8 | AB30: 6 | AC30: 9 | AD30: 8.8 | AE30: 5.6 | AF30: 4.6 | AG30: 3.4 | AH30: 5.6 | AI30: 2.8 | AJ30: 6.2 | AK30: 93шт в уценку (27,08,26) | AL30: =G30*R30 -> 0 | AM30: =G30*S30 -> 0
A31: Сыр ПАПА МОЖЕТ "Папин завтрак" 45% 180 г Останкино | B31: шт | C31: -1 | D31: 1 | F31: -1 | G31: 0.18 | H31: 150 | K31: 16 | L31: =E31-K31 -> -16 | O31: 20 | P31: =E31/5 -> 0 | Q31: 20 | R31: =Q31 -> 20 | T31: =VLOOKUP(A31,заказ!A:B,2,0) -> 20 | Y31: =(F31+O31+R31)/P31 -> #DIV/0! | Z31: =(F31+O31)/P31 -> #DIV/0! | AA31: 0.8 | AB31: 2.6 | AC31: 4.4 | AD31: 4.4 | AE31: 2.8 | AF31: 2.6 | AG31: 2.6 | AH31: 3.2 | AI31: 0.8 | AJ31: 3.6 | AK31: 98шт в уценку (27,08,26) | AL31: =G31*R31 -> 3.6 | AM31: =G31*S31 -> 0
A32: Сыр ПАПА МОЖЕТ "Российский традиционный"45 % 180 г Останкино | B32: шт | C32: 696 | D32: 55 | E32: 377 | F32: 223 | G32: 0.18 | H32: 150 | K32: 438 | L32: =E32-K32 -> -61 | O32: 480 | P32: =E32/5 -> 75.4 | Q32: =15*P32-O32-F32 -> 428 | R32: =Q32 -> 428 | T32: =VLOOKUP(A32,заказ!A:B,2,0) -> 430 | Y32: =(F32+O32+R32)/P32 -> 15 | Z32: =(F32+O32)/P32 -> 9.3236074 | AA32: 73.2 | AB32: 55.8 | AC32: 91.6 | AD32: 30.8 | AE32: 47.2 | AF32: 91 | AG32: 44.8 | AH32: 74.6 | AI32: 64.4 | AJ32: 50.2 | AL32: =G32*R32 -> 77.04 | AM32: =G32*S32 -> 0
A33: Сыр ПАПА МОЖЕТ "Тильзитер" фасованный массовая доля жира в сухом веществе 45%, 180г Останкино | B33: шт | C33: 370 | D33: 162 | E33: 50 | F33: 382 | G33: 0.18 | H33: 150 | K33: 147 | L33: =E33-K33 -> -97 | P33: =E33/5 -> 10 | R33: =Q33 -> 0 | S33: 160 | U33: =VLOOKUP(A33,'заказ сети'!A:B,2,0) -> 160 | W33: 160 | Y33: =(F33+O33+R33)/P33 -> 38.2 | Z33: =(F33+O33)/P33 -> 38.2 | AA33: 14 | AB33: 34 | AC33: 14.2 | AD33: 8.4 | AE33: 6.4 | AF33: 5.4 | AG33: 17 | AH33: 11.8 | AI33: 27.6 | AJ33: 9 | AK33: нужно увеличить продажи!!! | AL33: =G33*R33 -> 0 | AM33: =G33*S33 -> 28.8
A34: Сыр Творожный с зеленью 60% Папа может 140 гр. Останкино | B34: шт | C34: 82 | D34: 3 | E34: 42 | F34: 31 | G34: 0.14 | H34: 180 | K34: 46 | L34: =E34-K34 -> -4 | P34: =E34/5 -> 8.4 | Q34: =14*P34-O34-F34 -> 86.6 | R34: =Q34 -> 86.6 | T34: =VLOOKUP(A34,заказ!A:B,2,0) -> 80 | Y34: =(F34+O34+R34)/P34 -> 14 | Z34: =(F34+O34)/P34 -> 3.6904762 | AA34: 5.2 | AB34: 3 | AC34: 7.6 | AD34: 9.2 | AE34: 6.8 | AF34: 6 | AG34: 1.6 | AH34: 5.4 | AI34: 8.6 | AJ34: 9 | AL34: =G34*R34 -> 12.124 | AM34: =G34*S34 -> 0
A35: Сыр плавленный Сливочный ж.45% 180г ТМ Папа может (16шт) Останкино | B35: шт | C35: 54 | D35: 40 | E35: 44 | F35: 29 | G35: 0.18 | H35: 270 | K35: 57 | L35: =E35-K35 -> -13 | O35: 16 | P35: =E35/5 -> 8.8 | Q35: =15*P35-O35-F35 -> 87 | R35: =Q35 -> 87 | T35: =VLOOKUP(A35,заказ!A:B,2,0) -> 80 | Y35: =(F35+O35+R35)/P35 -> 15 | Z35: =(F35+O35)/P35 -> 5.1136364 | AA35: 7 | AB35: 8 | AC35: 8 | AD35: 8.2 | AE35: 9 | AF35: 7 | AG35: 5.4 | AH35: 5.8 | AI35: 8.8 | AJ35: 9 | AL35: =G35*R35 -> 15.66 | AM35: =G35*S35 -> 0
A36: Сыр полутвердый "Гауда" с массовой долей жира в пересчете на сухое вещество 45%, Останкино | B36: кг | C36: 80.75 | E36: 13.746 | F36: 60.236 | G36: 1 | H36: 180 | K36: 25 | L36: =E36-K36 -> -11.254 | P36: =E36/5 -> 2.7492 | R36: =Q36 -> 0 | Y36: =(F36+O36+R36)/P36 -> 21.910374 | Z36: =(F36+O36)/P36 -> 21.910374 | AA36: 1.3732 | AB36: 2.7864 | AC36: 2.1148 | AD36: 0 | AE36: 0.7688 | AF36: 2.5832 | AG36: 0.6992 | AH36: 0.722 | AI36: 0.6772 | AJ36: 0.6712 | AK36: нужно увеличить продажи | AL36: =G36*R36 -> 0 | AM36: =G36*S36 -> 0
A37: Сыр полутвердый "Голландский" с массовой долей жира в пересчете на сухое Останкино | B37: кг | C37: 9.86 | E37: 6.686 | G37: 1 | H37: 180 | K37: 7 | L37: =E37-K37 -> -0.314 | O37: 16 | P37: =E37/5 -> 1.3372 | Q37: =15*P37-O37-F37 -> 4.058 | R37: =Q37 -> 4.058 | T37: =VLOOKUP(A37,заказ!A:B,2,0) -> 16 | Y37: =(F37+O37+R37)/P37 -> 15 | Z37: =(F37+O37)/P37 -> 11.965301 | AA37: 2.06 | AB37: 2.5316 | AC37: 0.674 | AD37: 1.9556 | AE37: 0.498 | AF37: 3.776 | AG37: 0 | AH37: 2.0184 | AI37: 0 | AJ37: 3.8392 | AK37: 16кг в уценку (27,08,26) | AL37: =G37*R37 -> 4.058 | AM37: =G37*S37 -> 0
A38: Сыр полутвердый "Сметанковый", с масс долей жира в пересчете на сухое вещес50%, брус Останкино | B38: кг | C38: 64.332 | D38: 5.686 | E38: 28.438 | F38: 32.918 | G38: 1 | H38: 180 | K38: 36.2 | L38: =E38-K38 -> -7.762 | P38: =E38/5 -> 5.6876 | Q38: =15*P38-O38-F38 -> 52.396 | R38: =Q38 -> 52.396 | T38: =VLOOKUP(A38,заказ!A:B,2,0) -> 50 | Y38: =(F38+O38+R38)/P38 -> 15 | Z38: =(F38+O38)/P38 -> 5.7876785 | AA38: 3.0772 | AB38: 4.3232 | AC38: 6.602 | AD38: 1.9152 | AE38: 3.442 | AF38: 4.5936 | AG38: 1.9608 | AH38: 3.072 | AI38: 3.2116 | AJ38: 9.9192 | AL38: =G38*R38 -> 52.396 | AM38: =G38*S38 -> 0
A39: Сыр полутвердый "Тильзитер" с массовой долей жира в пересчете на сухое вещество 45%. 1/5 Останкино | B39: кг | C39: 121.77 | E39: 5.78 | F39: 115.99 | G39: 1 | H39: 180 | K39: 5 | L39: =E39-K39 -> 0.78 | P39: =E39/5 -> 1.156 | R39: =Q39 -> 0 | Y39: =(F39+O39+R39)/P39 -> 100.33737 | Z39: =(F39+O39)/P39 -> 100.33737 | AA39: 0.6952 | AB39: 0.5996 | AC39: 1.1588 | AD39: 0 | AE39: 0.612 | AF39: 2.676 | AG39: 0.6388 | AH39: 0 | AI39: 0.6192 | AJ39: 4.4596 | AK39: нужно увеличить продажи!!! | AL39: =G39*R39 -> 0 | AM39: =G39*S39 -> 0
A40: Сыр рассольный жирный Чечил 45% 100 гр ОСТАНКИНО | B40: шт | C40: 429 | D40: 10 | E40: 235 | F40: 137 | G40: 0.1 | H40: 60 | K40: 249 | L40: =E40-K40 -> -14 | O40: 90 | P40: =E40/5 -> 47 | Q40: =14*P40-O40-F40 -> 431 | R40: =Q40 -> 431 | T40: =VLOOKUP(A40,заказ!A:B,2,0) -> 432 | Y40: =(F40+O40+R40)/P40 -> 14 | Z40: =(F40+O40)/P40 -> 4.8297872 | AA40: 30.2 | AB40: 36.6 | AC40: 49.2 | AD40: 0 | AE40: 0.8 | AF40: -0.4 | AG40: -0.4 | AH40: 26.8 | AI40: 38.6 | AJ40: 41.4 | AL40: =G40*R40 -> 43.1 | AM40: =G40*S40 -> 0
A41: Сыр рассольный жирный Чечил копченый 43% 100 гр Останкино | B41: шт | C41: 370 | D41: 39 | E41: 164 | F41: 161 | G41: 0.1 | H41: 90 | K41: 202 | L41: =E41-K41 -> -38 | O41: 348 | P41: =E41/5 -> 32.8 | R41: =Q41 -> 0 | Y41: =(F41+O41+R41)/P41 -> 15.518293 | Z41: =(F41+O41)/P41 -> 15.518293 | AA41: 44.8 | AB41: 33.8 | AC41: 31.4 | AD41: 33.4 | AE41: 67 | AF41: 49 | AG41: 35.4 | AH41: 47.8 | AI41: 31.6 | AJ41: 38.2 | AL41: =G41*R41 -> 0 | AM41: =G41*S41 -> 0
A42: Сыр твердый "Пармезан", с масовой долей жира 35% Останкино | B42: кг | C42: 6.378 | E42: 6.378 | G42: 1 | K42: 8.4 | L42: =E42-K42 -> -2.022 | O42: 6 | P42: =E42/5 -> 1.2756 | Q42: =15*P42-O42-F42 -> 13.134 | R42: =Q42 -> 13.134 | T42: =VLOOKUP(A42,заказ!A:B,2,0) -> 12 | Y42: =(F42+O42+R42)/P42 -> 15 | Z42: =(F42+O42)/P42 -> 4.7036689 | AA42: 0.7928 | AB42: 0 | AC42: 0 | AD42: 0.2494 | AE42: 0.5416 | AF42: 0 | AG42: 0 | AH42: 3.5344 | AI42: 0 | AJ42: 1.3344 | AK42: 32кг в уценку (06,08,26) | AL42: =G42*R42 -> 13.134 | AM42: =G42*S42 -> 0
...

Sheet заказ
A1: 3323 Сыр Российский цилиндр 1/4 пленка ЮКМП м.д.ж. 50% ОСТАНКИНО | B1: 5
A2: 4421577 Спред растительно-сливочный "Сливочный вкус" 82,5% 180гр Останкино | B2: 24
A3: 4421584 Спред растительно-сливочный "Сливочный вкус" 72,5% 180гр Останкино | B3: 24
A4: 6948256 Майонез провансаль классич.оливковый Папа может 372гр с массовой долей жирн. 67% Останкино | B4: 120
A5: 6948263 Майонез провансаль классич.оливковый Папа может 744гр с массовой долей жирн. 67% Останкино | B5: 192
A6: 6948270 Майонез провансаль классич.Папа может 372гр с массовой долей жирн. 67% Останкино | B6: 240
A7: 6948287 Майонез провансаль классич.Папа может 744гр с массовой долей жирн. 67% Останкино | B7: 180
A8: 9988438 Плавленый Сыр 45% "С ветчиной" СТМ"ПапаМожет" 180гр Останкино | B8: 48
A9: 9988445 Плавленый Сыр 45%"С грибами" СТМ"ПапаМожет" 180 гр Останкино | B9: 80
A10: Масло "Папа может" 82,5% 180гр Останкино | B10: 230
A11: Масло сливочное 72,5 % 180 гр.(10 шт) СЛАВЯНА Останкино | B11: 130
A12: Сыр "Пармезан" 40% кусок 180 гр ОСТАНКИНО | B12: 90
... A28: Сыч/Прод Коровино Тильзитер 50% 200г НОВАЯ СЗМЖ ОСТАНКИНО | B28: 20

Sheet заказ сети
A1: Сыр ПАПА МОЖЕТ "Тильзитер" фасованный массовая доля жира в сухом веществе 45%, 180г Останкино | B1: 160
