Workbook

Sheet Sheet
A3: Номенклатура | B3: Ед. изм. | C3: Начальный остаток | D3: Приход | E3: Расход | F3: Конечный остаток | G3: крат | H3: сроки | I3: метка | J3: метка2 | K3: заяв | L3: разн | M3: без опта | N3: опт | O3: заказ в пути | P3: заказ в пути | Q3: заказ в пути | R3: заказ в пути | S3: заказ в пути | T3: заказ в пути | U3: ср нов | V3: расчет | W3: заказ | X3: ТК | Y3: ТК ком | Z3: кон ост | AA3: факт | AB3: ср | AC3: ср | AD3: ср | AE3: ср | AF3: ср | AG3: ср | AH3: ср | AI3: ср | AJ3: комментарии | AK3: вес
O4: 26,09, | P4: 26,09,доз | Q4: 28,09, | R4: 28,09,доз | S4: 03,10, | T4: 04,10, | U4: 01,10, | W4: 05,10, | X4: Рекуто | AB4: 29,09, | AC4: 24,09, | AD4: 22,09, | AE4: 17,09, | AF4: 15,09, | AG4: 10,09, | AH4: 08,09, | AI4: 03,09,
E5: =SUM(E6:E500) -> 62830.964 | F5: =SUM(F6:F500) -> 58801.986 | K5: =SUM(K6:K500) -> 69234.633 | L5: =SUM(L6:L500) -> -6403.669 | M5: =SUM(M6:M500) -> 52423.765 | N5: =SUM(N6:N500) -> 10407.199 | O5: =SUM(O6:O500) -> 15056.355 | P5: =SUM(P6:P500) -> 810 | Q5: =SUM(Q6:Q500) -> 23324.569 | R5: =SUM(R6:R500) -> 510 | ... W5: =SUM(W6:W500) -> 14912.667 | AB5: =SUM(AB6:AB500) -> 12416.699 | AC5: =SUM(AC6:AC500) -> 11708.139 | AD5: =SUM(AD6:AD500) -> 12733.619 | AE5: =SUM(AE6:AE500) -> 12494.756 | AF5: =SUM(AF6:AF500) -> 12634.548 | AG5: =SUM(AG6:AG500) -> 13008.018 | AH5: =SUM(AH6:AH500) -> 13739.431 | AI5: =SUM(AI6:AI500) -> 10909.968 | AK5: =SUM(AK6:AK500) -> 12334
A6: 005 Колбаса Докторская ГОСТ, Вязанка вектор,ВЕС. ПОКОМ | B6: кг | C6: 1026.076 | D6: 3196.328 | E6: 1983.294 | F6: 996.695 | G6: 1 | H6: 50 | I6: матрица | K6: 2146.094 | L6: =E6-K6 -> -162.8 | M6: =E6-N6 -> 1265.04 | N6: 718.254 | O6: 120.53745 | Q6: 351.91382 | S6: 674.8 | T6: 725.2 | U6: =M6/5 -> 253.008 | V6: =12*U6-T6-S6-R6-Q6-P6-O6-F6 -> 166.94973 | Z6: =(F6+O6+P6+Q6+R6+S6+T6+W6)/U6 -> 11.34014 | AA6: =(F6+O6+P6+Q6+R6+S6+T6)/U6 -> 11.34014 | AB6: 347.271 | AC6: 256.8714 | AD6: 307.1072 | AE6: 314.5066 | AF6: 330.3754 | AG6: 323.599 | AH6: 328.35 | AI6: 238.0988 | AK6: =ROUND(G6*W6,0) -> 0
A7: 016 Сосиски Вязанка Молочные, Вязанка вискофан ВЕС.ПОКОМ | B7: кг | C7: 1739.19 | D7: 1823.405 | E7: 853.517 | F7: 2351.42 | G7: 1 | H7: 45 | I7: матрица | K7: 854.353 | L7: =E7-K7 -> -0.836 | M7: =E7-N7 -> 853.517 | Q7: 0 | S7: 0 | U7: =M7/5 -> 170.7034 | W7: =V7 -> 0 | Z7: =(F7+O7+P7+Q7+R7+S7+T7+W7)/U7 -> 13.774887 | AA7: =(F7+O7+P7+Q7+R7+S7+T7)/U7 -> 13.774887 | AB7: 199.7456 | AC7: 203.1606 | AD7: 215.5368 | AE7: 330.043 | AF7: 367.75 | AG7: 250.4322 | AH7: 253.253 | AI7: 222.0264 | AJ7: ПРОМО сентябрь | AK7: =ROUND(G7*W7,0) -> 0
A8: 017 Сосиски Вязанка Сливочные, Вязанка амицел ВЕС.ПОКОМ | B8: кг | C8: 3656.842 | D8: 5141.235 | E8: 2956.413 | F8: 3988.71 | G8: 1 | H8: 45 | I8: матрица | K8: 3022.401 | L8: =E8-K8 -> -65.988 | M8: =E8-N8 -> 2956.413 | Q8: 794.63644 | S8: 771.2 | T8: 828.8 | U8: =M8/5 -> 591.2826 | V8: =12*U8-T8-S8-R8-Q8-P8-O8-F8 -> 712.04476 | W8: 300 | Z8: =(F8+O8+P8+Q8+R8+S8+T8+W8)/U8 -> 11.303134 | AA8: =(F8+O8+P8+Q8+R8+S8+T8)/U8 -> 10.795762 | AB8: 723.934 | AC8: 580.0266 | AD8: 625.754 | AE8: 800.884 | AF8: 833.0154 | AG8: 751.5328 | AH8: 847.039 | AI8: 565.603 | AJ8: ПРОМО сентябрь | AK8: =ROUND(G8*W8,0) -> 300
A9: 023 Колбаса Докторская ГОСТ, Вязанка вектор, 0,4 кг, ПОКОМ | B9: шт | C9: 1 | E9: -1 | F9: 1 | G9: 0.4 | H9: 50 | I9: матрица | L9: =E9-K9 -> -1 | M9: =E9-N9 -> -1 | O9: 15 | Q9: 13.414 | S9: 0 | U9: =M9/5 -> -0.2 | W9: =V9 -> 0 | Z9: =(F9+O9+P9+Q9+R9+S9+T9+W9)/U9 -> -147.07 | AA9: =(F9+O9+P9+Q9+R9+S9+T9)/U9 -> -147.07 | AB9: 0.2 | AC9: 2.2 | AD9: 2 | AE9: 0 | AF9: 0.2 | AG9: 2.4 | AH9: 1.8 | AI9: -0.2 | AJ9: 18шт списано (19,09,26) / 19 шт списано (12,07,26) | AK9: =ROUND(G9*W9,0) -> 0
A10: 030 Сосиски Вязанка Молочные, Вязанка вискофан МГС, 0.45кг, ПОКОМ | B10: шт | C10: 619 | D10: 5522 | E10: 1372 | F10: 4135 | G10: 0.45 | H10: 45 | I10: матрица | K10: 1521 | L10: =E10-K10 -> -149 | M10: =E10-N10 -> 1222 | N10: 150 | O10: 400 | Q10: 2688.0284 | S10: 0 | U10: =M10/5 -> 244.4 | W10: =V10 -> 0 | Z10: =(F10+O10+P10+Q10+R10+S10+T10+W10)/U10 -> 29.554126 | AA10: =(F10+O10+P10+Q10+R10+S10+T10)/U10 -> 29.554126 | AB10: 326 | AC10: 640.6 | AD10: 845.8 | AE10: 569 | AF10: 530.8672 | AG10: 514.4672 | AH10: 409.866 | AI10: 437.2 | AJ10: нужно увеличить продажи | AK10: =ROUND(G10*W10,0) -> 0
A11: 032 Сосиски Вязанка Сливочные, Вязанка амицел МГС, 0.45кг, ПОКОМ | B11: шт | C11: 2040 | D11: 5970 | E11: 2429 | F11: 4504 | G11: 0.45 | H11: 45 | I11: матрица | K11: 2583 | L11: =E11-K11 -> -154 | M11: =E11-N11 -> 2069 | N11: 360 | O11: 226.032 | Q11: 0 | S11: 0 | U11: =M11/5 -> 413.8 | V11: =12*U11-T11-S11-R11-Q11-P11-O11-F11 -> 235.568 | W11: 100 | Z11: =(F11+O11+P11+Q11+R11+S11+T11+W11)/U11 -> 11.672383 | AA11: =(F11+O11+P11+Q11+R11+S11+T11)/U11 -> 11.43072 | AB11: 502.6 | AC11: 524 | AD11: 664.8 | AE11: 660.6 | AF11: 572.6762 | AG11: 553.8762 | AH11: 632.423 | AI11: 674.2 | AK11: =ROUND(G11*W11,0) -> 45
A12: 047 Кол Баварская, белков.обол. в термоусад. пакете 0.17 кг, ТМ Стародворье ПОКОМ | B12: шт | C12: -1 | D12: 153 | E12: 74 | F12: 56 | G12: 0.17 | H12: 180 | I12: матрица | K12: 81 | L12: =E12-K12 -> -7 | M12: =E12-N12 -> 74 | O12: 88.2 | Q12: 71.814 | S12: 0 | U12: =M12/5 -> 14.8 | W12: =V12 -> 0 | Z12: =(F12+O12+P12+Q12+R12+S12+T12+W12)/U12 -> 14.595541 | AA12: =(F12+O12+P12+Q12+R12+S12+T12)/U12 -> 14.595541 | AB12: 14.8 | AC12: 22.2 | AD12: 26 | AE12: 20.4 | AF12: 9.4 | AG12: 17.2 | AH12: 19.6 | AI12: 12.4 | AK12: =ROUND(G12*W12,0) -> 0
A13: 062 Колбаса Кракушка пряная с сальцем, 0.3кг в/у п/к, БАВАРУШКА ПОКОМ | B13: шт | C13: 57 | D13: 8 | E13: 35 | F13: 15 | G13: 0.3 | H13: 40 | I13: НЕДОГРУЗ / матрица | K13: 46 | L13: =E13-K13 -> -11 | M13: =E13-N13 -> 35 | O13: 13 | Q13: 72.54 | S13: 20 | U13: =M13/5 -> 7 | W13: =V13 -> 0 | Z13: =(F13+O13+P13+Q13+R13+S13+T13+W13)/U13 -> 17.22 | AA13: =(F13+O13+P13+Q13+R13+S13+T13)/U13 -> 17.22 | AB13: 7.6 | AC13: 9.4 | AD13: 6.8 | AE13: 5.8 | AF13: 9.2 | AG13: 8.6 | AH13: 7 | AI13: 4 | AK13: =ROUND(G13*W13,0) -> 0
A14: 083 Колбаса Швейцарская 0,17 кг., ШТ., сырокопченая ПОКОМ | B14: шт | C14: 118 | D14: 304 | E14: 243 | F14: 46 | G14: 0.17 | H14: 180 | I14: матрица | K14: 258 | L14: =E14-K14 -> -15 | M14: =E14-N14 -> 243 | O14: 66.4 | Q14: 68.998 | S14: 89.202 | U14: =M14/5 -> 48.6 | V14: =12*U14-T14-S14-R14-Q14-P14-O14-F14 -> 312.6 | W14: =V14 -> 312.6 | Z14: =(F14+O14+P14+Q14+R14+S14+T14+W14)/U14 -> 12 | AA14: =(F14+O14+P14+Q14+R14+S14+T14)/U14 -> 5.5679012 | AB14: 35.6 | AC14: 33.4 | AD14: 40.6 | AE14: 38.6 | AF14: 32.8 | AG14: 33.2 | AH14: 32.8 | AI14: 30.2 | AK14: =ROUND(G14*W14,0) -> 53
A15: 200 Ветчина Дугушка ТМ Стародворье, вектор в/у ПОКОМ | B15: кг | C15: 4598.493 | D15: 6961.01 | E15: 4316.642 | F15: 4382.471 | G15: 1 | H15: 70 | I15: НЕДОГРУЗ / матрица | K15: 4316.781 | L15: =E15-K15 -> -0.139 | M15: =E15-N15 -> 4316.642 | O15: 0 | Q15: 0 | S15: 1630.5771 | T15: 1752.3629 | U15: =M15/5 -> 863.3284 | V15: =12*U15-T15-S15-R15-Q15-P15-O15-F15 -> 2594.5298 | W15: =V15-U15 -> 1731.2014 | Z15: =(F15+O15+P15+Q15+R15+S15+T15+W15)/U15 -> 11 | AA15: =(F15+O15+P15+Q15+R15+S15+T15)/U15 -> 8.994736 | AB15: 914.482 | AC15: 675.8734 | AD15: 648.8124 | AE15: 873.2804 | AF15: 934.933 | AG15: 830.7464 | AH15: 811.177 | AI15: 526.5364 | AJ15: ПРОМО сентябрь | AK15: =ROUND(G15*W15,0) -> 1731
A16: 201 Ветчина Нежная ТМ Особый рецепт, (2,5кг), ПОКОМ | B16: кг | C16: 3487.511 | D16: 7226.151 | E16: 3755.235 | F16: 4389.914 | G16: 1 | H16: 50 | I16: матрица | K16: 4090.418 | L16: =E16-K16 -> -335.183 | M16: =E16-N16 -> 3755.235 | O16: 120 | Q16: 854.64765 | R16: 510 | S16: 223.36186 | T16: 240.04449 | U16: =M16/5 -> 751.047 | V16: =12*U16-T16-S16-R16-Q16-P16-O16-F16 -> 2674.596 | W16: =V16-U16 -> 1923.549 | Z16: =(F16+O16+P16+Q16+R16+S16+T16+W16)/U16 -> 11 | AA16: =(F16+O16+P16+Q16+R16+S16+T16)/U16 -> 8.4388434 | AB16: 753.8054 | AC16: 623.8304 | AD16: 608.6706 | AE16: 760.835 | AF16: 778.136 | AG16: 651.7174 | AH16: 634.6946 | AI16: 404.844 | AJ16: ПРОМО сентябрь | AK16: =ROUND(G16*W16,0) -> 1924
A17: 215 Колбаса Докторская ГОСТ Дугушка, ВЕС, ТМ Стародворье ПОКОМ | B17: кг | C17: 377.591 | D17: 244.899 | E17: 323.738 | F17: 53.903 | G17: 1 | H17: 60 | I17: матрица | K17: 345.147 | L17: =E17-K17 -> -21.409 | M17: =E17-N17 -> 323.738 | O17: 32.2362 | Q17: 230.51743 | S17: 248.33246 | T17: 266.88011 | U17: =M17/5 -> 64.7476 | W17: =V17 -> 0 | Z17: =(F17+O17+P17+Q17+R17+S17+T17+W17)/U17 -> 12.847877 | AA17: =(F17+O17+P17+Q17+R17+S17+T17)/U17 -> 12.847877 | AB17: 80.9772 | AC17: 49.1336 | AD17: 48.9528 | AE17: 44.7038 | AF17: 25.6744 | AG17: 21.1402 | AH17: 46.8898 | AI17: 48.1516 | AK17: =ROUND(G17*W17,0) -> 0
A18: 225 Колбаса Дугушка со шпиком, ВЕС, ТМ Стародворье ПОКОМ | B18: кг | G18: 0 | I18: матрица | L18: =E18-K18 -> 0 | M18: =E18-N18 -> 0 | Q18: 0 | S18: 0 | U18: =M18/5 -> 0 | W18: =V18 -> 0 | Z18: =(F18+O18+P18+Q18+R18+S18+T18+W18)/U18 -> #DIV/0! | AA18: =(F18+O18+P18+Q18+R18+S18+T18)/U18 -> #DIV/0! | AB18: 0 | AC18: 0 | AD18: 0 | AE18: 0 | AF18: 0 | AG18: 0 | AH18: 0 | AI18: 0 | AJ18: нет потребности | AK18: =ROUND(G18*W18,0) -> 0
A19: 226 Колбаса Княжеская, с/к белков.обол в термоусад. пакете, ВЕС, ТМ Стародворье ПОКОМ | B19: кг | C19: 13.374 | D19: 0.345 | E19: 2.098 | F19: 10.91 | G19: 1 | H19: 180 | I19: матрица | K19: 2.614 | L19: =E19-K19 -> -0.516 | M19: =E19-N19 -> 2.098 | Q19: 0 | S19: 0 | U19: =M19/5 -> 0.4196 | W19: =V19 -> 0 | Z19: =(F19+O19+P19+Q19+R19+S19+T19+W19)/U19 -> 26.000953 | AA19: =(F19+O19+P19+Q19+R19+S19+T19)/U19 -> 26.000953 | AB19: 0.6802 | AC19: 0.8224 | AD19: 0.69 | AE19: 0.419 | AF19: 0.9222 | AG19: 1.436 | AH19: 1.0902 | AI19: 0.649 | AK19: =ROUND(G19*W19,0) -> 0
A20: 229 Колбаса Молочная Дугушка, в/у, ВЕС, ТМ Стародворье ПОКОМ | B20: кг | C20: 3944.892 | D20: 6416.338 | E20: 5244.974 | F20: 2173.124 | G20: 1 | H20: 60 | I20: матрица | K20: 5280.364 | L20: =E20-K20 -> -35.39 | M20: =E20-N20 -> 3306.34 | N20: 1938.634 | O20: 383.42958 | Q20: 1732.5916 | S20: 1687 | T20: 1813 | U20: =M20/5 -> 661.268 | V20: =12*U20-T20-S20-R20-Q20-P20-O20-F20 -> 146.07083 | Z20: =(F20+O20+P20+Q20+R20+S20+T20+W20)/U20 -> 11.779105 | AA20: =(F20+O20+P20+Q20+R20+S20+T20)/U20 -> 11.779105 | AB20: 917.3738 | AC20: 723.8802 | AD20: 773.4884 | AE20: 732.9714 | AF20: 804.4324 | AG20: 875.0272 | AH20: 948.6904 | AI20: 609.1674 | AK20: =ROUND(G20*W20,0) -> 0
A21: 236 Колбаса Рубленая ЗАПЕЧ. Дугушка ТМ Стародворье, вектор, в/к ПОКОМ | B21: кг | C21: 238.636 | D21: 208.631 | E21: 239.968 | F21: 154.903 | G21: 1 | H21: 70 | I21: матрица | K21: 300.1 | L21: =E21-K21 -> -60.132 | M21: =E21-N21 -> 239.968 | O21: 50.01124 | Q21: 548.98065 | S21: 72.3 | T21: 77.7 | U21: =M21/5 -> 47.9936 | W21: =V21 -> 0 | Z21: =(F21+O21+P21+Q21+R21+S21+T21+W21)/U21 -> 18.833655 | AA21: =(F21+O21+P21+Q21+R21+S21+T21)/U21 -> 18.833655 | AB21: 75.931 | AC21: 74.3142 | AD21: 56.8262 | AE21: 33.1564 | AF21: 51.6118 | AG21: 86.9468 | AH21: 92.6002 | AI21: 51.8056 | AK21: =ROUND(G21*W21,0) -> 0
A22: 239 Колбаса Салями запеч Дугушка, оболочка вектор, ВЕС, ТМ Стародворье ПОКОМ | B22: кг | C22: 1203.835 | D22: 2583.889 | E22: 1918.937 | F22: 515.463 | G22: 1 | H22: 70 | I22: НЕДОГРУЗ / матрица | K22: 1934.788 | L22: =E22-K22 -> -15.851 | M22: =E22-N22 -> 1918.937 | O22: 0 | Q22: 808.92559 | S22: 723 | T22: 777 | U22: =M22/5 -> 383.7874 | V22: =12*U22-T22-S22-R22-Q22-P22-O22-F22 -> 1781.0602 | W22: 1500 | Z22: =(F22+O22+P22+Q22+R22+S22+T22+W22)/U22 -> 11.267667 | AA22: =(F22+O22+P22+Q22+R22+S22+T22)/U22 -> 7.359253 | AB22: 327.679 | AC22: 251.3426 | AD22: 229.2002 | AE22: 266.7368 | AF22: 285.9102 | AG22: 266.6316 | AH22: 281.76 | AI22: 176.7588 | AJ22: ПРОМО сентябрь | AK22: =ROUND(G22*W22,0) -> 1500
A23: 240 Колбаса Салями охотничья, ВЕС. ПОКОМ | B23: кг | G23: 0 | I23: матрица | L23: =E23-K23 -> 0 | M23: =E23-N23 -> 0 | Q23: 0 | S23: 0 | U23: =M23/5 -> 0 | W23: =V23 -> 0 | Z23: =(F23+O23+P23+Q23+R23+S23+T23+W23)/U23 -> #DIV/0! | AA23: =(F23+O23+P23+Q23+R23+S23+T23)/U23 -> #DIV/0! | AB23: 0 | AC23: 0 | AD23: 0 | AE23: 0 | AF23: 0 | AG23: 0 | AH23: 0 | AI23: 0 | AJ23: нет потребности | AK23: =ROUND(G23*W23,0) -> 0
A24: 242 Колбаса Сервелат ЗАПЕЧ.Дугушка ТМ Стародворье, вектор, в/к ПОКОМ | B24: кг | C24: 2313.854 | D24: 4351.27 | E24: 2638.069 | F24: 2633.806 | G24: 1 | H24: 70 | I24: НЕДОГРУЗ / матрица | K24: 2625.147 | L24: =E24-K24 -> 12.922 | M24: =E24-N24 -> 2638.069 | O24: 0 | Q24: 0 | S24: 819.4 | T24: 880.6 | U24: =M24/5 -> 527.6138 | V24: =12*U24-T24-S24-R24-Q24-P24-O24-F24 -> 1997.5596 | W24: 1800 | Z24: =(F24+O24+P24+Q24+R24+S24+T24+W24)/U24 -> 11.62556 | AA24: =(F24+O24+P24+Q24+R24+S24+T24)/U24 -> 8.2139739 | AB24: 509.9216 | AC24: 404.2436 | AD24: 396.5312 | AE24: 524.3068 | AF24: 537.1594 | AG24: 473.2216 | AH24: 516.0532 | AI24: 310.2648 | AJ24: ПРОМО сентябрь | AK24: =ROUND(G24*W24,0) -> 1800
A25: 244 Колбаса Сервелат Кремлевский, ВЕС. ПОКОМ | B25: кг | C25: 26.814 | E25: -0.744 | F25: -0.011 | G25: 1 | H25: 40 | I25: НЕДОГРУЗ / матрица | K25: 32.6 | L25: =E25-K25 -> -33.344 | M25: =E25-N25 -> -0.744 | O25: 18.30764 | Q25: 7.208188 | S25: 80 | U25: =M25/5 -> -0.1488 | V25: 20 | W25: =V25 -> 20 | Z25: =(F25+O25+P25+Q25+R25+S25+T25+W25)/U25 -> -843.44642 | AA25: =(F25+O25+P25+Q25+R25+S25+T25)/U25 -> -709.03782 | AB25: 0.2886 | AC25: 4.2222 | AD25: 3.7848 | AE25: -0.293 | AF25: 1.601 | AG25: 4.363 | AH25: 3.4886 | AI25: 2.0396 | AK25: =ROUND(G25*W25,0) -> 20
A26: 247 Сардельки Нежные, ВЕС. ПОКОМ | B26: кг | G26: 0 | I26: матрица | L26: =E26-K26 -> 0 | M26: =E26-N26 -> 0 | Q26: 0 | S26: 0 | U26: =M26/5 -> 0 | W26: =V26 -> 0 | Z26: =(F26+O26+P26+Q26+R26+S26+T26+W26)/U26 -> #DIV/0! | AA26: =(F26+O26+P26+Q26+R26+S26+T26)/U26 -> #DIV/0! | AB26: 0 | AC26: 0 | AD26: 0 | AE26: 0 | AF26: 0 | AG26: 0 | AH26: 0 | AI26: 0 | AJ26: нет потребности | AK26: =ROUND(G26*W26,0) -> 0
A27: 248 Сардельки Сочные ТМ Особый рецепт, ПОКОМ | B27: кг | G27: 0 | I27: матрица | L27: =E27-K27 -> 0 | M27: =E27-N27 -> 0 | Q27: 0 | S27: 0 | U27: =M27/5 -> 0 | W27: =V27 -> 0 | Z27: =(F27+O27+P27+Q27+R27+S27+T27+W27)/U27 -> #DIV/0! | AA27: =(F27+O27+P27+Q27+R27+S27+T27)/U27 -> #DIV/0! | AB27: 0 | AC27: 0 | AD27: 0 | AE27: 0 | AF27: 0 | AG27: 0 | AH27: 0 | AI27: 0 | AJ27: нет потребности | AK27: =ROUND(G27*W27,0) -> 0
A28: 250 Сардельки стародворские с говядиной в обол. NDX, ВЕС. ПОКОМ | B28: кг | C28: 1019.063 | D28: 1921.789 | E28: 1055.212 | F28: 1207.645 | G28: 1 | H28: 30 | I28: НЕДОГРУЗ / матрица | K28: 1188.696 | L28: =E28-K28 -> -133.484 | M28: =E28-N28 -> 933.816 | N28: 121.396 | O28: 0 | Q28: 0 | S28: 313.3 | T28: 336.7 | U28: =M28/5 -> 186.7632 | V28: =12*U28-T28-S28-R28-Q28-P28-O28-F28 -> 383.5134 | W28: 200 | Z28: =(F28+O28+P28+Q28+R28+S28+T28+W28)/U28 -> 11.017401 | AA28: =(F28+O28+P28+Q28+R28+S28+T28)/U28 -> 9.9465259 | AB28: 219.6258 | AC28: 196.6198 | AD28: 221.1712 | AE28: 225.0454 | AF28: 231.6586 | AG28: 235.7996 | AH28: 278.0154 | AI28: 227.6552 | AK28: =ROUND(G28*W28,0) -> 200
A29: 255 Сосиски Молочные для завтрака ТМ Особый рецепт, п/а МГС, ВЕС, ТМ Стародворье ПОКОМ | B29: кг | C29: 444.916 | D29: 7347.075 | E29: 2986.275 | F29: 2951.898 | G29: 1 | H29: 40 | I29: НЕДОГРУЗ / матрица | K29: 2952.042 | L29: =E29-K29 -> 34.233 | M29: =E29-N29 -> 2643.267 | N29: 343.008 | O29: 3710 | Q29: 0 | S29: 723 | T29: 777 | U29: =M29/5 -> 528.6534 | W29: =V29 -> 0 | Z29: =(F29+O29+P29+Q29+R29+S29+T29+W29)/U29 -> 15.439034 | AA29: =(F29+O29+P29+Q29+R29+S29+T29)/U29 -> 15.439034 | AB29: 571.5462 | AC29: 586.117 | AD29: 710.1294 | AE29: 412.9854 | AF29: 192.2834 | AG29: 374.2526 | AH29: 576.9176 | AI29: 427.835 | AK29: =ROUND(G29*W29,0) -> 0
A30: 257 Сосиски Молочные оригинальные ТМ Особый рецепт, ВЕС. ПОКОМ | B30: кг | G30: 0 | I30: матрица | L30: =E30-K30 -> 0 | M30: =E30-N30 -> 0 | Q30: 0 | S30: 0 | U30: =M30/5 -> 0 | W30: =V30 -> 0 | Z30: =(F30+O30+P30+Q30+R30+S30+T30+W30)/U30 -> #DIV/0! | AA30: =(F30+O30+P30+Q30+R30+S30+T30)/U30 -> #DIV/0! | AB30: 0 | AC30: 0 | AD30: 0 | AE30: 0 | AF30: 0 | AG30: 0 | AH30: 0 | AI30: 0 | AJ30: нет потребности | AK30: =ROUND(G30*W30,0) -> 0
A31: 263 Шпикачки Стародворские, ВЕС. ПОКОМ | B31: кг | G31: 0 | I31: матрица | L31: =E31-K31 -> 0 | M31: =E31-N31 -> 0 | Q31: 0 | S31: 0 | U31: =M31/5 -> 0 | W31: =V31 -> 0 | Z31: =(F31+O31+P31+Q31+R31+S31+T31+W31)/U31 -> #DIV/0! | AA31: =(F31+O31+P31+Q31+R31+S31+T31)/U31 -> #DIV/0! | AB31: 0 | AC31: 0 | AD31: 0 | AE31: 0 | AF31: 0 | AG31: 0 | AH31: 0 | AI31: 0 | AJ31: нет потребности | AK31: =ROUND(G31*W31,0) -> 0
A32: 265 Колбаса Балыкбургская, ВЕС, ТМ Баварушка ПОКОМ | B32: кг | G32: 0 | I32: матрица | L32: =E32-K32 -> 0 | M32: =E32-N32 -> 0 | Q32: 0 | S32: 0 | U32: =M32/5 -> 0 | W32: =V32 -> 0 | Z32: =(F32+O32+P32+Q32+R32+S32+T32+W32)/U32 -> #DIV/0! | AA32: =(F32+O32+P32+Q32+R32+S32+T32)/U32 -> #DIV/0! | AB32: 0 | AC32: 0 | AD32: 0 | AE32: 0 | AF32: 0 | AG32: 0 | AH32: 0 | AI32: 0 | AJ32: нет потребности | AK32: =ROUND(G32*W32,0) -> 0
A33: 267 Колбаса Салями Филейбургская зернистая, оболочка фиброуз, ВЕС, ТМ Баварушка ПОКОМ | B33: кг | G33: 0 | I33: матрица | L33: =E33-K33 -> 0 | M33: =E33-N33 -> 0 | Q33: 0 | S33: 0 | U33: =M33/5 -> 0 | W33: =V33 -> 0 | Z33: =(F33+O33+P33+Q33+R33+S33+T33+W33)/U33 -> #DIV/0! | AA33: =(F33+O33+P33+Q33+R33+S33+T33)/U33 -> #DIV/0! | AB33: 0 | AC33: 0 | AD33: 0 | AE33: 0 | AF33: 0 | AG33: 0 | AH33: 0 | AI33: 0 | AJ33: нет потребности | AK33: =ROUND(G33*W33,0) -> 0
A34: 273 Сосиски Сочинки с сочной грудинкой, МГС 0.4кг, ПОКОМ | B34: шт | C34: 1111 | D34: 4668 | E34: 3145 | F34: 1259 | G34: 0.4 | H34: 45 | I34: НЕДОГРУЗ / матрица | K34: 3618 | L34: =E34-K34 -> -473 | M34: =E34-N34 -> 2917 | N34: 228 | O34: 1600 | Q34: 2604.4512 | S34: 241 | T34: 259 | U34: =M34/5 -> 583.4 | V34: =12*U34-T34-S34-R34-Q34-P34-O34-F34 -> 1037.3488 | W34: 600 | Z34: =(F34+O34+P34+Q34+R34+S34+T34+W34)/U34 -> 11.250345 | AA34: =(F34+O34+P34+Q34+R34+S34+T34)/U34 -> 10.221891 | AB34: 686 | AC34: 679.4 | AD34: 754.6 | AE34: 654.8 | AF34: 869.4 | AG34: 631 | AH34: 648.4 | AI34: 1337.6 | AJ34: ПРОМО сентябрь | AK34: =ROUND(G34*W34,0) -> 240
A35: 276 Колбаса Сливушка ТМ Вязанка в оболочке полиамид 0,45 кг ПОКОМ | B35: шт | C35: -1 | D35: 1223 | E35: 541 | F35: 473 | G35: 0.45 | H35: 50 | I35: матрица | K35: 697 | L35: =E35-K35 -> -156 | M35: =E35-N35 -> 541 | O35: 71.218 | Q35: 372.408 | S35: 0 | U35: =M35/5 -> 108.2 | V35: =12*U35-T35-S35-R35-Q35-P35-O35-F35 -> 381.774 | W35: 300 | Z35: =(F35+O35+P35+Q35+R35+S35+T35+W35)/U35 -> 11.244233 | AA35: =(F35+O35+P35+Q35+R35+S35+T35)/U35 -> 8.4715896 | AB35: 107.4 | AC35: 120.4 | AD35: 124.2 | AE35: 129 | AF35: 84 | AG35: 83.2 | AH35: 183.328 | AI35: 310.8 | AK35: =ROUND(G35*W35,0) -> 135
A36: 278 Сосиски Сочинки с сочным окороком, МГС 0.4кг, ПОКОМ | B36: шт | C36: 112 | D36: 2336 | E36: 884 | F36: 1114 | G36: 0.4 | H36: 45 | I36: НЕДОГРУЗ / матрица | K36: 981 | L36: =E36-K36 -> -97 | M36: =E36-N36 -> 764 | N36: 120 | O36: 0 | Q36: 0 | S36: 120.5 | T36: 129.5 | U36: =M36/5 -> 152.8 | V36: =12*U36-T36-S36-R36-Q36-P36-O36-F36 -> 469.6 | W36: 350 | Z36: =(F36+O36+P36+Q36+R36+S36+T36+W36)/U36 -> 11.217277 | AA36: =(F36+O36+P36+Q36+R36+S36+T36)/U36 -> 8.9267016 | AB36: 173.4 | AC36: 179.2 | AD36: 210.4 | AE36: 192 | AF36: 152.4 | AG36: 151.6 | AH36: 137 | AI36: 55.2 | AK36: =ROUND(G36*W36,0) -> 140
A37: 281 Сосиски Молочные для завтрака ТМ Особый рецепт, 0,4кг ПОКОМ | B37: шт | D37: 162 | E37: 148 | F37: -11 | G37: 0.4 | H37: 40 | I37: !!! / НЕДОГРУЗ / матрица | K37: 572 | L37: =E37-K37 -> -424 | M37: =E37-N37 -> 148 | O37: 65 | Q37: 38.74 | S37: 120.5 | T37: 129.5 | U37: =M37/5 -> 29.6 | V37: =12*U37-T37-S37-R37-Q37-P37-O37-F37 -> 12.46 | W37: 400 | X37: 400 | Y37: =VLOOKUP(A37,[1]Лист1!$A:$B,2,0) -> до 400 шт (заказ сети) | Z37: =(F37+O37+P37+Q37+R37+S37+T37+W37)/U37 -> 25.092568 | AA37: =(F37+O37+P37+Q37+R37+S37+T37)/U37 -> 11.579054 | AB37: 30.4 | AC37: 20.4 | AD37: 0 | AE37: 1.8 | AF37: 13.6 | AG37: 18.8 | AH37: 7.4 | AI37: -0.2 | AK37: =ROUND(G37*W37,0) -> 160
A38: 283 Сосиски Сочинки, ВЕС, ТМ Стародворье ПОКОМ | B38: кг | C38: 162.95 | D38: 1.412 | E38: 11.436 | F38: 148.666 | G38: 1 | I38: НЕДОГРУЗ / матрица | K38: 11.5 | L38: =E38-K38 -> -0.064 | M38: =E38-N38 -> 11.436 | O38: 0 | Q38: 0 | S38: 0 | U38: =M38/5 -> 2.2872 | W38: =V38 -> 0 | Z38: =(F38+O38+P38+Q38+R38+S38+T38+W38)/U38 -> 64.999126 | AA38: =(F38+O38+P38+Q38+R38+S38+T38)/U38 -> 64.999126 | AB38: 2.8632 | AC38: 2.0016 | AD38: 2.2812 | AE38: 4.6482 | AF38: 6.3222 | AG38: 11.2442 | AH38: 18.956 | AI38: 4.8394 | AJ38: нужно увеличить продажи!!! | AK38: =ROUND(G38*W38,0) -> 0
A39: 285 Паштет печеночный со слив.маслом ТМ Стародворье ламистер 0,1 кг ПОКОМ | B39: шт | C39: 630 | D39: 8 | E39: 198 | F39: 374 | G39: 0.1 | H39: 731 | I39: матрица | K39: 229 | L39: =E39-K39 -> -31 | M39: =E39-N39 -> 198 | Q39: 177.046 | S39: 0 | U39: =M39/5 -> 39.6 | W39: =V39 -> 0 | Z39: =(F39+O39+P39+Q39+R39+S39+T39+W39)/U39 -> 13.915303 | AA39: =(F39+O39+P39+Q39+R39+S39+T39)/U39 -> 13.915303 | AB39: 47 | AC39: 55.8 | AD39: 66.2 | AE39: 60.8 | AF39: 56 | AG39: 60 | AH39: 69.4 | AI39: 43 | AK39: =ROUND(G39*W39,0) -> 0
A40: 296 Колбаса Мясорубская с рубленой грудинкой 0,35кг срез ТМ Стародворье ПОКОМ | B40: шт | C40: 7 | E40: 1.169 | F40: 1.831 | G40: 0.35 | H40: 40 | I40: НЕДОГРУЗ / матрица | K40: 31 | L40: =E40-K40 -> -29.831 | M40: =E40-N40 -> 1.169 | O40: 52 | Q40: 39 | S40: 0 | U40: =M40/5 -> 0.2338 | V40: 20 | W40: 60 | X40: 80 | Y40: =VLOOKUP(A40,[1]Лист1!$A:$B,2,0) -> до 80 шт | Z40: =(F40+O40+P40+Q40+R40+S40+T40+W40)/U40 -> 653.68263 | AA40: =(F40+O40+P40+Q40+R40+S40+T40)/U40 -> 397.05304 | AB40: 0.2338 | AC40: -0.2 | AD40: -0.4 | AE40: 17.4 | AF40: 18.2 | AG40: 0.4 | AH40: 0.6 | AI40: -0.8 | AK40: =ROUND(G40*W40,0) -> 21
A41: 297 Колбаса Мясорубская с рубленой грудинкой ВЕС ТМ Стародворье ПОКОМ | B41: кг | C41: 27.458 | D41: 28.981 | E41: 31.198 | F41: 21.586 | G41: 1 | H41: 40 | I41: НЕДОГРУЗ / матрица | K41: 41.82 | L41: =E41-K41 -> -10.622 | M41: =E41-N41 -> 31.198 | O41: 52 | Q41: 0 | S41: 0 | U41: =M41/5 -> 6.2396 | V41: 10 | W41: =V41 -> 10 | Z41: =(F41+O41+P41+Q41+R41+S41+T41+W41)/U41 -> 13.396051 | AA41: =(F41+O41+P41+Q41+R41+S41+T41)/U41 -> 11.793384 | AB41: 4.0526 | AC41: 0.8686 | AD41: 1.5376 | AE41: 4.7846 | AF41: 3.8284 | AG41: 1.671 | AH41: 2.0398 | AI41: 3.023 | AK41: =ROUND(G41*W41,0) -> 10
A42: 301 Сосиски Сочинки по-баварски с сыром, 0.4кг, ТМ Стародворье ПОКОМ | B42: шт | C42: 37 | D42: 166 | E42: 164 | F42: 4 | G42: 0.4 | H42: 40 | I42: НЕДОГРУЗ / матрица | K42: 365 | L42: =E42-K42 -> -201 | M42: =E42-N42 -> 164 | O42: 390 | Q42: 93.08 | S42: 86.76 | T42: 93.24 | U42: =M42/5 -> 32.8 | W42: =V42 -> 0 | Z42: =(F42+O42+P42+Q42+R42+S42+T42+W42)/U42 -> 20.337805 | AA42: =(F42+O42+P42+Q42+R42+S42+T42)/U42 -> 20.337805 | AB42: 53.2 | AC42: 65 | AD42: 73.2 | AE42: 57 | AF42: 51.2 | AG42: 38.4 | AH42: 34.6 | AI42: 39.4 | AK42: =ROUND(G42*W42,0) -> 0
...
