Workbook

Sheet Sheet
W1: 0.98
W2: дн | AL2: 17000
A3: Номенклатура | B3: Ед. изм. | C3: Начальный остаток | D3: Приход | E3: Расход | F3: Конечный остаток | G3: крат | H3: сроки | I3: метка | J3: метка2 | K3: заяв | L3: разн | M3: без опта | N3: опт | O3: заказ в пути | P3: заказ в пути | Q3: заказ в пути | R3: заказ в пути | S3: заказ в пути | T3: заказ в пути | U3: ср нов | V3: расчет | W3: итого | X3: заказ | Y3: заказ | Z3: ТК | AA3: кон ост | AB3: факт | AC3: ср | AD3: ср | AE3: ср | AF3: ср | AG3: ср | AH3: ср | AI3: ср | AJ3: ср | AK3: комментарии | AL3: вес | AM3: вес
O4: 18,08, | P4: 18,08,недогр | Q4: 22,08, | R4: 22,08,недогр | S4: 22,08,доз | T4: 23,08, | U4: 20,08, | X4: 25,08, | Y4: 24,08, | Z4: Хмель | AC4: 18,08, | AD4: 13,08, | AE4: 11,08, | AF4: 06,08, | AG4: 04,08, | AH4: 30,07, | AI4: 28,07, | AJ4: 23,07, | AL4: 25,08, | AM4: 24,08, | AO4: 1
E5: =SUM(E6:E500) -> 73581.433 | F5: =SUM(F6:F500) -> 46657.597 | K5: =SUM(K6:K500) -> 92199.358 | L5: =SUM(L6:L500) -> -18617.925 | M5: =SUM(M6:M500) -> 58637.696 | N5: =SUM(N6:N500) -> 14943.737 | O5: =SUM(O6:O500) -> 19603.011 | P5: =SUM(P6:P500) -> -1273.5 | Q5: =SUM(Q6:Q500) -> 22586.477 | R5: =SUM(R6:R500) -> -2032.9 | ... Y5: =SUM(Y6:Y500) -> 13146.432 | AC5: =SUM(AC6:AC500) -> 13329.493 | AD5: =SUM(AD6:AD500) -> 12669.462 | AE5: =SUM(AE6:AE500) -> 10646.114 | AF5: =SUM(AF6:AF500) -> 10433.826 | AG5: =SUM(AG6:AG500) -> 11173.737 | AH5: =SUM(AH6:AH500) -> 12763.75 | AI5: =SUM(AI6:AI500) -> 14118.473 | AJ5: =SUM(AJ6:AJ500) -> 10392.848 | AL5: =SUM(AL6:AL500) -> 16997 | AM5: =SUM(AM6:AM500) -> 7985 | AO5: 1
A6: 005 Колбаса Докторская ГОСТ, Вязанка вектор,ВЕС. ПОКОМ | B6: кг | C6: 2019.147 | D6: 3887.194 | E6: 2033.168 | F6: 2734.685 | G6: 1 | H6: 50 | I6: матрица | K6: 2268.741 | L6: =E6-K6 -> -235.573 | M6: =E6-N6 -> 1628.108 | N6: 405.06 | O6: 571.67825 | Q6: 215.47623 | T6: 267.65433 | U6: =M6/5 -> 325.6216 | V6: =12*U6-T6-Q6-P6-O6-F6 -> 117.96539 | W6: 0 | X6: =W6-Y6 -> 0 | AA6: =(F6+O6+P6+Q6+T6+X6+Y6+R6+S6)/U6 -> 11.637722 | AB6: =(F6+O6+P6+Q6+T6)/U6 -> 11.637722 | AC6: 402.6088 | AD6: 419.2068 | AE6: 402.0166 | AF6: 337.7342 | AG6: 348.7926 | AH6: 383.9166 | AI6: 414.5354 | AJ6: 309.1234 | AL6: =ROUND(G6*X6,0) -> 0 | AM6: =ROUND(G6*Y6,0) -> 0 | AN6: SU000722
A7: 016 Сосиски Вязанка Молочные, Вязанка вискофан ВЕС.ПОКОМ | B7: кг | C7: 473.784 | D7: 2893.569 | E7: 1688.492 | F7: 1204.04 | G7: 1 | H7: 45 | I7: матрица | K7: 1499.102 | L7: =E7-K7 -> 189.39 | M7: =E7-N7 -> 1081.529 | N7: 606.963 | O7: 753.70391 | Q7: 200.7 | T7: 249.3 | U7: =M7/5 -> 216.3058 | V7: =12*U7-T7-Q7-P7-O7-F7 -> 187.92569 | W7: =V7+$W$1*U7 -> 399.90537 | X7: =W7-Y7 -> 399.90537 | AA7: =(F7+O7+P7+Q7+T7+X7+Y7+R7+S7)/U7 -> 12.98 | AB7: =(F7+O7+P7+Q7+T7)/U7 -> 11.131204 | AC7: 223.072 | AD7: 285.975 | AE7: 246.8064 | AF7: 136.3926 | AG7: 175.6748 | AH7: 232.3934 | AI7: 194.2758 | AJ7: 139.5838 | AL7: =ROUND(G7*X7,0) -> 400 | AM7: =ROUND(G7*Y7,0) -> 0 | AN7: SU001523
A8: 017 Сосиски Вязанка Сливочные, Вязанка амицел ВЕС.ПОКОМ | B8: кг | C8: 2754.893 | D8: 6282.726 | E8: 4646.485 | F8: =2266.304+F86 -> 2260.863 | G8: 1 | H8: 45 | I8: матрица | K8: 4805.024 | L8: =E8-K8 -> -158.539 | M8: =E8-N8 -> 2732.122 | N8: 1914.363 | O8: 976.73631 | Q8: 1024.6154 | T8: 1272.7285 | U8: =M8/5 -> 546.4244 | V8: =12*U8-T8-Q8-P8-O8-F8 -> 1022.1495 | W8: =V8+$W$1*U8 -> 1557.6455 | X8: =W8-Y8 -> 857.64546 | Y8: 700 | AA8: =(F8+O8+P8+Q8+T8+X8+Y8+R8+S8)/U8 -> 12.98 | AB8: =(F8+O8+P8+Q8+T8)/U8 -> 10.129385 | AC8: 608.09 | AD8: 673.4266 | AE8: 716.373 | AF8: 543.649 | AG8: 613.5636 | AH8: 603.608 | AI8: 601.6022 | AJ8: 449.453 | AL8: =ROUND(G8*X8,0) -> 858 | AM8: =ROUND(G8*Y8,0) -> 700 | AN8: SU001721
A9: 023 Колбаса Докторская ГОСТ, Вязанка вектор, 0,4 кг, ПОКОМ | B9: шт | C9: 23 | D9: 10 | E9: 7 | F9: 18 | G9: 0.4 | H9: 50 | I9: матрица | K9: 14 | L9: =E9-K9 -> -7 | M9: =E9-N9 -> 7 | Q9: 0 | U9: =M9/5 -> 1.4 | W9: =V9 -> 0 | X9: =W9-Y9 -> 0 | AA9: =(F9+O9+P9+Q9+T9+X9+Y9+R9+S9)/U9 -> 12.857143 | AB9: =(F9+O9+P9+Q9+T9)/U9 -> 12.857143 | AC9: 1.4 | AD9: 1.8 | AE9: 2.4 | AF9: 1 | AG9: 1.2 | AH9: 2.6 | AI9: 2.2 | AJ9: 0 | AK9: 19 шт списано (12,07,26) | AL9: =ROUND(G9*X9,0) -> 0 | AM9: =ROUND(G9*Y9,0) -> 0 | AN9: SU001485
A10: 030 Сосиски Вязанка Молочные, Вязанка вискофан МГС, 0.45кг, ПОКОМ | B10: шт | C10: 1956.55 | D10: 2792 | E10: 2608.174 | F10: 615.376 | G10: 0.45 | H10: 45 | I10: ВНИМАНИЕ / матрица | K10: 3201 | L10: =E10-K10 -> -592.826 | M10: =E10-N10 -> 2464.174 | N10: 144 | O10: 907.608 | Q10: 535.2 | S10: 1000 | T10: 664.8 | U10: =M10/5 -> 492.8348 | V10: 2000 | W10: =V10 -> 2000 | X10: =W10-Y10 -> 700 | Y10: 1300 | AA10: =(F10+O10+P10+Q10+T10+X10+Y10+R10+S10)/U10 -> 11.612378 | AB10: =(F10+O10+P10+Q10+T10)/U10 -> 5.5251455 | AC10: 540.4348 | AD10: 426.419 | AE10: 373.019 | AF10: 298 | AG10: 339 | AH10: 705.871 | AI10: 624.671 | AJ10: 265.4 | AK10: 1000шт под ЮТЛ (Хмель 15,07,26) | AL10: =ROUND(G10*X10,0) -> 315 | AM10: =ROUND(G10*Y10,0) -> 585 | AN10: SU001718 | AO10: =VLOOKUP(AN10,[2]Лист1!$A:$A,1,0) -> SU001718
A11: 032 Сосиски Вязанка Сливочные, Вязанка амицел МГС, 0.45кг, ПОКОМ | B11: шт | C11: 5853.021 | D11: 2392 | E11: 4360.366 | F11: 1646.655 | G11: 0.45 | H11: 45 | I11: ВНИМАНИЕ / матрица | K11: 4886 | L11: =E11-K11 -> -525.634 | M11: =E11-N11 -> 3424.366 | N11: 936 | O11: 260 | Q11: 356.8 | T11: 443.2 | U11: =M11/5 -> 684.8732 | V11: =11*U11-T11-Q11-P11-O11-F11 -> 4826.9502 | W11: =V11 -> 4826.9502 | X11: =W11-Y11 -> 1826.9502 | Y11: 3000 | AA11: =(F11+O11+P11+Q11+T11+X11+Y11+R11+S11)/U11 -> 11 | AB11: =(F11+O11+P11+Q11+T11)/U11 -> 3.9520527 | AC11: 689.6732 | AD11: 718.03 | AE11: 763.0744 | AF11: 683.4 | AG11: 536.8 | AH11: 707.3658 | AI11: 771.7658 | AJ11: 431.2 | AK11: 1000 сеть МКД (05,08,26) | AL11: =ROUND(G11*X11,0) -> 822 | AM11: =ROUND(G11*Y11,0) -> 1350 | AN11: SU001720
A12: 047 Кол Баварская, белков.обол. в термоусад. пакете 0.17 кг, ТМ Стародворье ПОКОМ | B12: шт | C12: 282 | D12: 37 | E12: 119 | F12: 126 | G12: 0.17 | H12: 180 | I12: матрица | K12: 149 | L12: =E12-K12 -> -30 | M12: =E12-N12 -> 89 | N12: 30 | Q12: 0 | U12: =M12/5 -> 17.8 | V12: =12*U12-T12-Q12-P12-O12-F12 -> 87.6 | W12: =V12 -> 87.6 | X12: =W12-Y12 -> 87.6 | AA12: =(F12+O12+P12+Q12+T12+X12+Y12+R12+S12)/U12 -> 12 | AB12: =(F12+O12+P12+Q12+T12)/U12 -> 7.0786517 | AC12: 17.8 | AD12: 13.2 | AE12: 20 | AF12: 19.234 | AG12: 23.6 | AH12: 35 | AI12: 24.6 | AJ12: 9 | AL12: =ROUND(G12*X12,0) -> 15 | AM12: =ROUND(G12*Y12,0) -> 0 | AN12: SU002092
A13: 062 Колбаса Кракушка пряная с сальцем, 0.3кг в/у п/к, БАВАРУШКА ПОКОМ | B13: шт | C13: 96 | D13: 9 | E13: 60 | F13: 19 | G13: 0.3 | H13: 40 | I13: матрица | K13: 80 | L13: =E13-K13 -> -20 | M13: =E13-N13 -> 60 | Q13: 75 | R13: -78 | U13: =M13/5 -> 12 | V13: =12*U13-T13-Q13-P13-O13-F13 -> 50 | W13: =V13 -> 50 | X13: =W13-Y13 -> 50 | AA13: =(F13+O13+P13+Q13+T13+X13+Y13+R13+S13)/U13 -> 5.5 | AB13: =(F13+O13+P13+Q13+T13)/U13 -> 7.8333333 | AC13: 12.6 | AD13: 7.2 | AE13: 4.2 | AF13: 8.2 | AG13: 11.8 | AH13: 8.4 | AI13: 3.2 | AJ13: 1 | AL13: =ROUND(G13*X13,0) -> 15 | AM13: =ROUND(G13*Y13,0) -> 0 | AN13: SU002252
A14: 083 Колбаса Швейцарская 0,17 кг., ШТ., сырокопченая ПОКОМ | B14: шт | C14: 383 | D14: 103 | E14: 297 | F14: 6 | G14: 0.17 | H14: 180 | I14: матрица | K14: 397 | L14: =E14-K14 -> -100 | M14: =E14-N14 -> 87 | N14: 210 | Q14: 152 | U14: =M14/5 -> 17.4 | V14: =12*U14-T14-Q14-P14-O14-F14 -> 50.8 | W14: =V14 -> 50.8 | X14: =W14-Y14 -> 50.8 | AA14: =(F14+O14+P14+Q14+T14+X14+Y14+R14+S14)/U14 -> 12 | AB14: =(F14+O14+P14+Q14+T14)/U14 -> 9.0804598 | AC14: 35.4 | AD14: 34.2 | AE14: 26 | AF14: 27.634 | AG14: 36.8 | AH14: 60.2 | AI14: 65.2 | AJ14: 36.6 | AL14: =ROUND(G14*X14,0) -> 9 | AM14: =ROUND(G14*Y14,0) -> 0 | AN14: SU001869
A15: 103 Сосиски Классические, 0.42кг,ядрена копотьПОКОМ | B15: шт | C15: 336 | D15: 2 | E15: 5 | F15: 272 | G15: 0 | I15: не в матрице | K15: 53 | L15: =E15-K15 -> -48 | M15: =E15-N15 -> 5 | Q15: 0 | U15: =M15/5 -> 1 | W15: =V15 -> 0 | X15: =W15-Y15 -> 0 | AA15: =(F15+O15+P15+Q15+T15+X15+Y15+R15+S15)/U15 -> 272 | AB15: =(F15+O15+P15+Q15+T15)/U15 -> 272 | AC15: 1 | AD15: 5.2 | AE15: 4.4 | AF15: 0.2 | AG15: 4.4 | AH15: 4.2 | AI15: 0 | AJ15: 0 | AK15: Продукция для ПРС!!! | AL15: =ROUND(G15*X15,0) -> 0 | AM15: =ROUND(G15*Y15,0) -> 0 | AN15: SU000341
A16: 200 Ветчина Дугушка ТМ Стародворье, вектор в/у ПОКОМ | B16: кг | C16: 3949.242 | D16: 5740.334 | E16: 4270.796 | F16: 3018.523 | G16: 1 | H16: 70 | I16: матрица | K16: 4821.759 | L16: =E16-K16 -> -550.963 | M16: =E16-N16 -> 2883.302 | N16: 1387.494 | O16: 1598.8085 | Q16: 267.6 | T16: 332.4 | U16: =M16/5 -> 576.6604 | V16: =12*U16-T16-Q16-P16-O16-F16 -> 1702.5933 | W16: =V16+$W$1*U16 -> 2267.7205 | X16: =W16-Y16 -> 1402.7205 | Y16: 865 | AA16: =(F16+O16+P16+Q16+T16+X16+Y16+R16+S16)/U16 -> 12.98 | AB16: =(F16+O16+P16+Q16+T16)/U16 -> 9.047494 | AC16: 628.171 | AD16: 726.9406 | AE16: 643.966 | AF16: 609.9092 | AG16: 693.1158 | AH16: 746.7954 | AI16: 794.7714 | AJ16: 554.7976 | AL16: =ROUND(G16*X16,0) -> 1403 | AM16: =ROUND(G16*Y16,0) -> 865 | AN16: SU002035 | AO16: =VLOOKUP(AN16,[2]Лист1!$A:$A,1,0) -> SU002035
A17: 201 Ветчина Нежная ТМ Особый рецепт, (2,5кг), ПОКОМ | B17: кг | C17: 3045.259 | D17: 3464.733 | E17: 3118.307 | F17: 1311.933 | G17: 1 | H17: 50 | I17: матрица | K17: 4089.089 | L17: =E17-K17 -> -970.782 | M17: =E17-N17 -> 1418.037 | N17: 1700.27 | O17: 270.40264 | Q17: 888.46133 | T17: 1103.6044 | U17: =M17/5 -> 283.6074 | W17: =V17 -> 0 | X17: =W17-Y17 -> 0 | AA17: =(F17+O17+P17+Q17+T17+X17+Y17+R17+S17)/U17 -> 12.603343 | AB17: =(F17+O17+P17+Q17+T17)/U17 -> 12.603343 | AC17: 445.8572 | AD17: 436.475 | AE17: 435.7906 | AF17: 509.0408 | AG17: 530.1232 | AH17: 537.543 | AI17: 623.7324 | AJ17: 623.553 | AL17: =ROUND(G17*X17,0) -> 0 | AM17: =ROUND(G17*Y17,0) -> 0 | AN17: SU000126 | AO17: =VLOOKUP(AN17,[2]Лист1!$A:$A,1,0) -> SU000126
A18: 215 Колбаса Докторская ГОСТ Дугушка, ВЕС, ТМ Стародворье ПОКОМ | B18: кг | C18: 328.6 | D18: 310.218 | E18: 448.405 | F18: -10.764 | G18: 1 | H18: 60 | I18: матрица | K18: 523.844 | L18: =E18-K18 -> -75.439 | M18: =E18-N18 -> 146.161 | N18: 302.244 | Q18: 211.8584 | U18: =M18/5 -> 29.2322 | V18: =12*U18-T18-Q18-P18-O18-F18 -> 149.692 | W18: =V18 -> 149.692 | X18: =W18-Y18 -> 149.692 | AA18: =(F18+O18+P18+Q18+T18+X18+Y18+R18+S18)/U18 -> 12 | AB18: =(F18+O18+P18+Q18+T18)/U18 -> 6.8792085 | AC18: 29.2322 | AD18: 22.3572 | AE18: -0.251 | AF18: 23.0592 | AG18: 27.917 | AH18: 18.902 | AI18: 36.5078 | AJ18: 45.232 | AL18: =ROUND(G18*X18,0) -> 150 | AM18: =ROUND(G18*Y18,0) -> 0 | AN18: SU002011
A19: 219 Колбаса Докторская Особая ТМ Особый рецепт, ВЕС ПОКОМ | B19: кг | C19: -4.974 | E19: 1.755 | F19: -27.493 | G19: 0 | I19: не в матрице | J19: 597 Колбаса Классическая ТМ Особый рецепт в оболочке полиамид ВЕС. ПОКОМ | K19: 22.5 | L19: =E19-K19 -> -20.745 | M19: =E19-N19 -> 1.755 | Q19: 0 | U19: =M19/5 -> 0.351 | W19: =V19 -> 0 | X19: =W19-Y19 -> 0 | AA19: =(F19+O19+P19+Q19+T19+X19+Y19+R19+S19)/U19 -> -78.327635 | AB19: =(F19+O19+P19+Q19+T19)/U19 -> -78.327635 | AC19: 0.351 | AD19: -0.365 | AE19: -0.513 | AF19: -0.148 | AG19: 0 | AH19: 0.4948 | AI19: 0.4948 | AJ19: 0 | AL19: =ROUND(G19*X19,0) -> 0 | AM19: =ROUND(G19*Y19,0) -> 0 | AN19: SU004238 | AO19: =VLOOKUP(AN19,[2]Лист1!$A:$A,1,0) -> SU004238
A20: 225 Колбаса Дугушка со шпиком, ВЕС, ТМ Стародворье ПОКОМ | B20: кг | G20: 0 | I20: матрица | L20: =E20-K20 -> 0 | M20: =E20-N20 -> 0 | Q20: 0 | U20: =M20/5 -> 0 | W20: =V20 -> 0 | X20: =W20-Y20 -> 0 | AA20: =(F20+O20+P20+Q20+T20+X20+Y20+R20+S20)/U20 -> #DIV/0! | AB20: =(F20+O20+P20+Q20+T20)/U20 -> #DIV/0! | AC20: 0 | AD20: 0 | AE20: 0 | AF20: 0 | AG20: 0 | AH20: 0 | AI20: 0 | AJ20: 0 | AK20: нет потребности | AL20: =ROUND(G20*X20,0) -> 0 | AM20: =ROUND(G20*Y20,0) -> 0 | AN20: SU002182
A21: 226 Колбаса Княжеская, с/к белков.обол в термоусад. пакете, ВЕС, ТМ Стародворье ПОКОМ | B21: кг | C21: 4.074 | D21: 20.452 | E21: 4.417 | F21: 21.476 | G21: 1 | H21: 180 | I21: матрица | K21: 3.2 | L21: =E21-K21 -> 1.217 | M21: =E21-N21 -> 4.417 | Q21: 0 | U21: =M21/5 -> 0.8834 | W21: =V21 -> 0 | X21: =W21-Y21 -> 0 | AA21: =(F21+O21+P21+Q21+T21+X21+Y21+R21+S21)/U21 -> 24.310618 | AB21: =(F21+O21+P21+Q21+T21)/U21 -> 24.310618 | AC21: 0.8834 | AD21: 1.4618 | AE21: 1.1292 | AF21: 0.642 | AG21: 0.429 | AH21: 1.0448 | AI21: 1.1864 | AJ21: 0.4298 | AK21: нужно увеличить продажи | AL21: =ROUND(G21*X21,0) -> 0 | AM21: =ROUND(G21*Y21,0) -> 0 | AN21: SU001920
A22: 229 Колбаса Молочная Дугушка, в/у, ВЕС, ТМ Стародворье ПОКОМ | B22: кг | C22: 4132.444 | D22: 9744.665 | E22: 5972.888 | F22: 5774.89 | G22: 1 | H22: 60 | I22: матрица | K22: 5380.919 | L22: =E22-K22 -> 591.969 | M22: =E22-N22 -> 5972.888 | O22: 3489.2333 | Q22: 1826.1225 | T22: 2268.3225 | U22: =M22/5 -> 1194.5776 | V22: =12*U22-T22-Q22-P22-O22-F22 -> 976.36289 | W22: 0 | X22: =W22-Y22 -> 0 | AA22: =(F22+O22+P22+Q22+T22+X22+Y22+R22+S22)/U22 -> 11.182671 | AB22: =(F22+O22+P22+Q22+T22)/U22 -> 11.182671 | AC22: 1235.5082 | AD22: 1204.554 | AE22: 901.4088 | AF22: 763.3562 | AG22: 859.3734 | AH22: 796.5506 | AI22: 870.4836 | AJ22: 625.4246 | AL22: =ROUND(G22*X22,0) -> 0 | AM22: =ROUND(G22*Y22,0) -> 0 | AN22: SU002010
A23: 230 Колбаса Молочная Особая ТМ Особый рецепт, п/а, ВЕС. ПОКОМ | B23: кг | C23: -7.493 | E23: 4.97 | F23: -12.463 | G23: 0 | I23: не в матрице | J23: 457 Колбаса Молочная ТМ Особый рецепт ВЕС большой батон ПОКОМ | K23: 5 | L23: =E23-K23 -> -0.03 | M23: =E23-N23 -> 4.97 | Q23: 0 | U23: =M23/5 -> 0.994 | W23: =V23 -> 0 | X23: =W23-Y23 -> 0 | AA23: =(F23+O23+P23+Q23+T23+X23+Y23+R23+S23)/U23 -> -12.538229 | AB23: =(F23+O23+P23+Q23+T23)/U23 -> -12.538229 | AC23: 0.994 | AD23: 0 | AE23: 0 | AF23: 0 | AG23: 0 | AH23: 1.4986 | AI23: 1.4986 | AJ23: 0 | AL23: =ROUND(G23*X23,0) -> 0 | AM23: =ROUND(G23*Y23,0) -> 0 | AN23: SU003422 | AO23: =VLOOKUP(AN23,[2]Лист1!$A:$A,1,0) -> SU003422
A24: 236 Колбаса Рубленая ЗАПЕЧ. Дугушка ТМ Стародворье, вектор, в/к ПОКОМ | B24: кг | C24: 335.729 | D24: 1254.869 | E24: 209.511 | F24: 583.087 | G24: 1 | H24: 70 | I24: матрица | K24: 1037.545 | L24: =E24-K24 -> -828.034 | M24: =E24-N24 -> 108.401 | N24: 101.11 | Q24: 0 | U24: =M24/5 -> 21.6802 | W24: =V24 -> 0 | X24: =W24-Y24 -> 0 | AA24: =(F24+O24+P24+Q24+T24+X24+Y24+R24+S24)/U24 -> 26.894909 | AB24: =(F24+O24+P24+Q24+T24)/U24 -> 26.894909 | AC24: 72.8132 | AD24: 77.0706 | AE24: 121.8204 | AF24: 64.7166 | AG24: 29.2552 | AH24: 86.5184 | AI24: 112.269 | AJ24: 80.8328 | AK24: нужно увеличить продажи | AL24: =ROUND(G24*X24,0) -> 0 | AM24: =ROUND(G24*Y24,0) -> 0 | AN24: SU002150
A25: 239 Колбаса Салями запеч Дугушка, оболочка вектор, ВЕС, ТМ Стародворье ПОКОМ | B25: кг | C25: 1316.174 | D25: 1676.538 | E25: 1398.375 | F25: 990.209 | G25: 1 | H25: 70 | I25: матрица | K25: 1519.923 | L25: =E25-K25 -> -121.548 | M25: =E25-N25 -> 1063.414 | N25: 334.961 | O25: 457.30278 | Q25: 322.91478 | T25: 401.10939 | U25: =M25/5 -> 212.6828 | V25: =12*U25-T25-Q25-P25-O25-F25 -> 380.65764 | W25: =V25+$W$1*U25 -> 589.08679 | X25: =W25-Y25 -> 589.08679 | AA25: =(F25+O25+P25+Q25+T25+X25+Y25+R25+S25)/U25 -> 12.98 | AB25: =(F25+O25+P25+Q25+T25)/U25 -> 10.21021 | AC25: 230.368 | AD25: 244.7884 | AE25: 233.4784 | AF25: 197.4094 | AG25: 248.3712 | AH25: 254.2464 | AI25: 255.9778 | AJ25: 183.0002 | AL25: =ROUND(G25*X25,0) -> 589 | AM25: =ROUND(G25*Y25,0) -> 0 | AN25: SU002158
A26: 240 Колбаса Салями охотничья, ВЕС. ПОКОМ | B26: кг | G26: 0 | I26: матрица | L26: =E26-K26 -> 0 | M26: =E26-N26 -> 0 | Q26: 0 | U26: =M26/5 -> 0 | W26: =V26 -> 0 | X26: =W26-Y26 -> 0 | AA26: =(F26+O26+P26+Q26+T26+X26+Y26+R26+S26)/U26 -> #DIV/0! | AB26: =(F26+O26+P26+Q26+T26)/U26 -> #DIV/0! | AC26: 0 | AD26: 0 | AE26: 0 | AF26: 0 | AG26: 0 | AH26: 0 | AI26: 0 | AJ26: 0 | AK26: нет потребности | AL26: =ROUND(G26*X26,0) -> 0 | AM26: =ROUND(G26*Y26,0) -> 0 | AN26: SU001921
A27: 242 Колбаса Сервелат ЗАПЕЧ.Дугушка ТМ Стародворье, вектор, в/к ПОКОМ | B27: кг | C27: 2323.611 | D27: 2015.317 | E27: 2505.23 | F27: 633.433 | G27: 1 | H27: 70 | I27: матрица | K27: 2693.62 | L27: =E27-K27 -> -188.39 | M27: =E27-N27 -> 1782.234 | N27: 722.996 | O27: 416 | Q27: 1084.2377 | T27: 1346.7885 | U27: =M27/5 -> 356.4468 | V27: =12*U27-T27-Q27-P27-O27-F27 -> 796.90236 | W27: =V27+$W$1*U27 -> 1146.2202 | X27: =W27-Y27 -> 1146.2202 | AA27: =(F27+O27+P27+Q27+T27+X27+Y27+R27+S27)/U27 -> 12.98 | AB27: =(F27+O27+P27+Q27+T27)/U27 -> 9.7643161 | AC27: 377.3442 | AD27: 436.646 | AE27: 375.1652 | AF27: 497.5888 | AG27: 453.6796 | AH27: 417.4032 | AI27: 457.0628 | AJ27: 304.7148 | AL27: =ROUND(G27*X27,0) -> 1146 | AM27: =ROUND(G27*Y27,0) -> 0 | AN27: SU002151
A28: 244 Колбаса Сервелат Кремлевский, ВЕС. ПОКОМ | B28: кг | C28: 81.498 | E28: 6.511 | F28: 69.202 | G28: 1 | H28: 40 | I28: матрица | K28: 7.2 | L28: =E28-K28 -> -0.689 | M28: =E28-N28 -> 6.511 | Q28: 0 | U28: =M28/5 -> 1.3022 | W28: =V28 -> 0 | X28: =W28-Y28 -> 0 | AA28: =(F28+O28+P28+Q28+T28+X28+Y28+R28+S28)/U28 -> 53.142374 | AB28: =(F28+O28+P28+Q28+T28)/U28 -> 53.142374 | AC28: 1.3022 | AD28: 1.9806 | AE28: 1.2582 | AF28: 0.732 | AG28: 1.3146 | AH28: 7.8512 | AI28: 8.7356 | AJ28: 3.5048 | AK28: нужно увеличить продажи!!! | AL28: =ROUND(G28*X28,0) -> 0 | AM28: =ROUND(G28*Y28,0) -> 0 | AN28: SU001822
A29: 247 Сардельки Нежные, ВЕС. ПОКОМ | B29: кг | G29: 0 | I29: матрица | L29: =E29-K29 -> 0 | M29: =E29-N29 -> 0 | Q29: 0 | U29: =M29/5 -> 0 | W29: =V29 -> 0 | X29: =W29-Y29 -> 0 | AA29: =(F29+O29+P29+Q29+T29+X29+Y29+R29+S29)/U29 -> #DIV/0! | AB29: =(F29+O29+P29+Q29+T29)/U29 -> #DIV/0! | AC29: 0 | AD29: 0 | AE29: 0 | AF29: 0 | AG29: 0 | AH29: 0 | AI29: 0 | AJ29: 0 | AK29: нет потребности | AL29: =ROUND(G29*X29,0) -> 0 | AM29: =ROUND(G29*Y29,0) -> 0 | AN29: SU001051
A30: 248 Сардельки Сочные ТМ Особый рецепт, ПОКОМ | B30: кг | G30: 0 | I30: матрица | L30: =E30-K30 -> 0 | M30: =E30-N30 -> 0 | Q30: 0 | U30: =M30/5 -> 0 | W30: =V30 -> 0 | X30: =W30-Y30 -> 0 | AA30: =(F30+O30+P30+Q30+T30+X30+Y30+R30+S30)/U30 -> #DIV/0! | AB30: =(F30+O30+P30+Q30+T30)/U30 -> #DIV/0! | AC30: 0 | AD30: 0 | AE30: 0 | AF30: 0 | AG30: 0 | AH30: 0 | AI30: 0 | AJ30: 0 | AK30: нет потребности | AL30: =ROUND(G30*X30,0) -> 0 | AM30: =ROUND(G30*Y30,0) -> 0 | AN30: SU002287
A31: 250 Сардельки стародворские с говядиной в обол. NDX, ВЕС. ПОКОМ | B31: кг | C31: 1400.299 | D31: 2826.522 | E31: 3172.825 | F31: 187.902 | G31: 1 | H31: 30 | I31: НЕДОГРУЗ / матрица | K31: 2490.037 | L31: =E31-K31 -> 682.788 | M31: =E31-N31 -> 2203.238 | N31: 969.587 | O31: 416 | Q31: 669 | T31: 831 | U31: =M31/5 -> 440.6476 | V31: =11*U31-T31-Q31-P31-O31-F31 -> 2743.2216 | W31: =V31 -> 2743.2216 | X31: 2610 | Y31: =W31*0.5 -> 1371.6108 | AA31: =(F31+O31+P31+Q31+T31+X31+Y31+R31+S31)/U31 -> 13.810385 | AB31: =(F31+O31+P31+Q31+T31)/U31 -> 4.7745682 | AC31: 365.1898 | AD31: 310.8728 | AE31: 178.8978 | AF31: 437.4332 | AG31: 568.7244 | AH31: 251.4826 | AI31: 368.8554 | AJ31: 396.4942 | AL31: =ROUND(G31*X31,0) -> 2610 | AM31: =ROUND(G31*Y31,0) -> 1372 | AN31: SU000227
A32: 253 Сосиски Ганноверские ПОКОМ | B32: кг | C32: -0.23 | F32: -0.23 | G32: 0 | H32: 40 | I32: не в матрице | L32: =E32-K32 -> 0 | M32: =E32-N32 -> 0 | Q32: 0 | U32: =M32/5 -> 0 | W32: =V32 -> 0 | X32: =W32-Y32 -> 0 | AA32: =(F32+O32+P32+Q32+T32+X32+Y32+R32+S32)/U32 -> #DIV/0! | AB32: =(F32+O32+P32+Q32+T32)/U32 -> #DIV/0! | AC32: 0 | AD32: 0 | AE32: 0 | AF32: 0 | AG32: -0.098 | AH32: 12.5518 | AI32: 13.9894 | AJ32: 4.5704 | AL32: =ROUND(G32*X32,0) -> 0 | AM32: =ROUND(G32*Y32,0) -> 0 | AN32: SU001340
A33: 255 Сосиски Молочные для завтрака ТМ Особый рецепт, п/а МГС, ВЕС, ТМ Стародворье ПОКОМ | B33: кг | C33: 1148.73 | D33: 431.798 | E33: 3281.402 | F33: -114.405 | G33: 1 | H33: 40 | I33: НЕДОГРУЗ / матрица | K33: 3984.676 | L33: =E33-K33 -> -703.274 | M33: =E33-N33 -> 3281.402 | O33: 520 | P33: -522 | Q33: 892 | T33: 1208 | U33: =M33/5 -> 656.2804 | V33: 2200 | W33: =V33 -> 2200 | X33: =W33 -> 2200 | Y33: =W33*0.5 -> 1100 | AA33: =(F33+O33+P33+Q33+T33+X33+Y33+R33+S33)/U33 -> 8.0508194 | AB33: =(F33+O33+P33+Q33+T33)/U33 -> 3.0224809 | AC33: 656.844 | AD33: 328.153 | AE33: -0.8462 | AF33: 8.5924 | AG33: 9.8556 | AH33: 688.0432 | AI33: 1184.2532 | AJ33: 1031.4698 | AL33: =ROUND(G33*X33,0) -> 2200 | AM33: =ROUND(G33*Y33,0) -> 1100 | AN33: SU002074
A34: 257 Сосиски Молочные оригинальные ТМ Особый рецепт, ВЕС. ПОКОМ | B34: кг | G34: 0 | I34: матрица | L34: =E34-K34 -> 0 | M34: =E34-N34 -> 0 | Q34: 0 | U34: =M34/5 -> 0 | W34: =V34 -> 0 | X34: =W34-Y34 -> 0 | AA34: =(F34+O34+P34+Q34+T34+X34+Y34+R34+S34)/U34 -> #DIV/0! | AB34: =(F34+O34+P34+Q34+T34)/U34 -> #DIV/0! | AC34: 0 | AD34: 0 | AE34: 0 | AF34: 0 | AG34: 0 | AH34: 0 | AI34: 0 | AJ34: 0 | AK34: нет потребности | AL34: =ROUND(G34*X34,0) -> 0 | AM34: =ROUND(G34*Y34,0) -> 0 | AN34: SU000246
A35: 263 Шпикачки Стародворские, ВЕС. ПОКОМ | B35: кг | G35: 0 | I35: матрица | L35: =E35-K35 -> 0 | M35: =E35-N35 -> 0 | Q35: 0 | U35: =M35/5 -> 0 | W35: =V35 -> 0 | X35: =W35-Y35 -> 0 | AA35: =(F35+O35+P35+Q35+T35+X35+Y35+R35+S35)/U35 -> #DIV/0! | AB35: =(F35+O35+P35+Q35+T35)/U35 -> #DIV/0! | AC35: 0 | AD35: 0 | AE35: 0 | AF35: 0 | AG35: 0 | AH35: 0 | AI35: 0 | AJ35: 0 | AK35: нет потребности | AL35: =ROUND(G35*X35,0) -> 0 | AM35: =ROUND(G35*Y35,0) -> 0 | AN35: SU001430
A36: 265 Колбаса Балыкбургская, ВЕС, ТМ Баварушка ПОКОМ | B36: кг | G36: 0 | I36: матрица | L36: =E36-K36 -> 0 | M36: =E36-N36 -> 0 | Q36: 0 | U36: =M36/5 -> 0 | W36: =V36 -> 0 | X36: =W36-Y36 -> 0 | AA36: =(F36+O36+P36+Q36+T36+X36+Y36+R36+S36)/U36 -> #DIV/0! | AB36: =(F36+O36+P36+Q36+T36)/U36 -> #DIV/0! | AC36: 0 | AD36: 0 | AE36: 0 | AF36: 0 | AG36: 0 | AH36: 0 | AI36: 0 | AJ36: 0 | AK36: нет потребности | AL36: =ROUND(G36*X36,0) -> 0 | AM36: =ROUND(G36*Y36,0) -> 0 | AN36: SU002612
A37: 267 Колбаса Салями Филейбургская зернистая, оболочка фиброуз, ВЕС, ТМ Баварушка ПОКОМ | B37: кг | G37: 0 | I37: матрица | L37: =E37-K37 -> 0 | M37: =E37-N37 -> 0 | Q37: 0 | U37: =M37/5 -> 0 | W37: =V37 -> 0 | X37: =W37-Y37 -> 0 | AA37: =(F37+O37+P37+Q37+T37+X37+Y37+R37+S37)/U37 -> #DIV/0! | AB37: =(F37+O37+P37+Q37+T37)/U37 -> #DIV/0! | AC37: 0 | AD37: 0 | AE37: 0 | AF37: 0 | AG37: 0 | AH37: 0 | AI37: 0 | AJ37: 0 | AK37: нет потребности | AL37: =ROUND(G37*X37,0) -> 0 | AM37: =ROUND(G37*Y37,0) -> 0 | AN37: SU002614
A38: 273 Сосиски Сочинки с сочной грудинкой, МГС 0.4кг, ПОКОМ | B38: шт | C38: 1008 | D38: 4256 | E38: 5155 | F38: -322 | G38: 0.4 | H38: 45 | I38: НЕДОГРУЗ / матрица | K38: 4558 | L38: =E38-K38 -> 597 | M38: =E38-N38 -> 4075 | N38: 1080 | O38: 780 | Q38: 1767.944 | T38: 2196.056 | U38: =M38/5 -> 815 | V38: =11*U38-T38-Q38-P38-O38-F38 -> 4543 | W38: =V38 -> 4543 | X38: 3000 | Y38: 2220 | Z38: =VLOOKUP(A38,[1]Sheet!$A:$U,21,0) -> ОЧЕНЬ НУЖНА ЭТА ПОЗИЦИЯ !!! | AA38: =(F38+O38+P38+Q38+T38+X38+Y38+R38+S38)/U38 -> 11.830675 | AB38: =(F38+O38+P38+Q38+T38)/U38 -> 5.4257669 | AC38: 779 | AD38: 633.6 | AE38: 113.2 | AF38: 461.2 | AG38: 811.2 | AH38: 861.6 | AI38: 877.4 | AJ38: 623.4 | AL38: =ROUND(G38*X38,0) -> 1200 | AM38: =ROUND(G38*Y38,0) -> 888 | AN38: SU002618
A39: 276 Колбаса Сливушка ТМ Вязанка в оболочке полиамид 0,45 кг ПОКОМ | B39: шт | C39: 839.75 | D39: 263 | E39: 735 | F39: 253.75 | G39: 0.45 | H39: 50 | I39: ВНИМАНИЕ / матрица | K39: 1175 | L39: =E39-K39 -> -440 | M39: =E39-N39 -> 735 | Q39: 200 | U39: =M39/5 -> 147 | V39: =10*U39-T39-Q39-P39-O39-F39 -> 1016.25 | W39: =V39+500 -> 1516.25 | X39: =W39-Y39 -> 716.25 | Y39: 800 | Z39: =VLOOKUP(A39,[1]Sheet!$A:$U,21,0) -> еще плюс 500 сеть ютл | AA39: =(F39+O39+P39+Q39+T39+X39+Y39+R39+S39)/U39 -> 13.401361 | AB39: =(F39+O39+P39+Q39+T39)/U39 -> 3.0867347 | AC39: 147.6 | AD39: 112.6 | AE39: 71 | AF39: 70.4 | AG39: 98.4 | AH39: 126.8 | AI39: 127.8 | AJ39: 67.2 | AK39: 500шт под ЮТЛ (Хмель 21,08,26) | AL39: =ROUND(G39*X39,0) -> 322 | AM39: =ROUND(G39*Y39,0) -> 360 | AN39: SU002734
A40: 278 Сосиски Сочинки с сочным окороком, МГС 0.4кг, ПОКОМ | B40: шт | C40: -5 | D40: 832 | E40: 742 | F40: 43 | G40: 0.4 | H40: 45 | I40: НЕДОГРУЗ / матрица | K40: 2165 | L40: =E40-K40 -> -1423 | M40: =E40-N40 -> 742 | O40: 208 | Q40: 400 | R40: -402 | U40: =M40/5 -> 148.4 | V40: 500 | W40: =V40 -> 500 | X40: =W40 -> 500 | Y40: =W40*0.5 -> 250 | AA40: =(F40+O40+P40+Q40+T40+X40+Y40+R40+S40)/U40 -> 6.7318059 | AB40: =(F40+O40+P40+Q40+T40)/U40 -> 4.3867925 | AC40: 148.4 | AD40: 122.2 | AE40: 91.8 | AF40: 163.6 | AG40: 166.8 | AH40: 188.8 | AI40: 301.6 | AJ40: 192.2 | AL40: =ROUND(G40*X40,0) -> 200 | AM40: =ROUND(G40*Y40,0) -> 100 | AN40: SU002621
...

Sheet недогруз 22,08
A1: SU002205 | B1: Сосиски «Молочные для завтрака» Фикс.вес 0,4 П/а мгс ТМ «Особый рецепт» | C1: 81.6 | D1: -81.6
A2: SU002252 | B2: П/к колбасы Кракушка пряная с сальцем Бавария Фикс.вес 0,3 н/о в/у Стародворье | C2: 23.4 | D2: -23.4
A3: SU002621 | B3: Сосиски «Сочинки с сочным окороком» Фикс.вес 0,4 П/а мгс ТМ «Стародворье» | C3: 160.8 | D3: -160.8
A4: SU002660 | B4: Колбаса Мясорубская ТМ Стародворье с рубленой грудинкой в оболочке фиброуз в вакуумной упаковке 0,35 кг срез | C4: 18.9 | D4: -18.9
A5: SU002844 | B5: Сосиски «Сочинки Сливочные» Фикс.вес 0,4 п/а мгс ТМ «Стародворье» | C5: 76.8 | D5: -76.8
A6: SU002848 | B6: В/к колбасы Сервелат Мясорубский с мелкорубленным окороком срез Бордо Фикс.вес 0,35 фиброуз Стародворье | C6: 71.4 | D6: -71.4
A7: SU002942 | B7: В/к колбасы «Сочинка по-фински с сочным окороком» срез Фикс.вес 0,3 фиброуз ТМ «Стародворье» | C7: 16.2 | D7: -16.2
A8: SU002944 | B8: В/к колбасы «Сочинка по-европейски с сочной грудинкой» срез Фикс.вес 0,3 фиброуз ТМ «Стародворье» | C8: 30.6 | D8: -30.6
A9: SU002945 | B9: П/к колбасы «Сочинка зернистая с сочной грудинкой» Весовой фиброуз ТМ «Стародворье» | C9: 383.4 | D9: -383.4
A10: SU002948 | B10: П/к колбасы «Сочинка рубленая с сочным окороком» срез Фикс.вес 0,3 фиброуз ТМ «Стародворье» | C10: 16.2 | D10: -16.2
A11: SU004041 | B11: Копченые колбасы «Балыковая» Весовой фиброуз ТМ «Вязанка» | C11: 101.5 | D11: -101.5
A12: SU004045 | B12: Копченые колбасы «Сервелат Финский» Фикс.вес 0,28 фиброуз срез ТМ «Вязанка» | C12: 57.12 | D12: -57.12
