Workbook

Sheet Sheet
Y1: 0.98
Y2: дн | AO2: 17000
A3: Номенклатура | B3: Ед. изм. | C3: Начальный остаток | D3: Приход | E3: Расход | F3: Конечный остаток | G3: крат | H3: сроки | I3: метка | J3: метка2 | K3: заяв | L3: разн | M3: без опта | N3: опт | O3: заказ в пути | P3: заказ в пути | Q3: заказ в пути | R3: заказ в пути | S3: заказ в пути | T3: заказ в пути | U3: заказ в пути | V3: заказ в пути | W3: ср нов | X3: расчет | Y3: итого | Z3: заказ | AA3: заказ | AB3: заказ | AC3: ТК | AD3: кон ост | AE3: факт | AF3: ср | AG3: ср | AH3: ср | AI3: ср | AJ3: ср | AK3: ср | AL3: ср | AM3: ср | AN3: комментарии | AO3: вес | AP3: вес
O4: 18,08, | P4: 18,08,недогр | Q4: 22,08, | R4: 22,08,недогр | S4: 22,08,доз | T4: 23,08, | U4: 23,08,недогр | V4: 23,08,доз | W4: 20,08, | Z4: 25,08, | AA4: 24,08,недогр | AB4: 24,08, | AC4: Хмель | AF4: 18,08, | AG4: 13,08, | AH4: 11,08, | AI4: 06,08, | AJ4: 04,08, | AK4: 30,07, | AL4: 28,07, | AM4: 23,07, | AO4: 25,08, | AP4: 24,08, | AR4: 1
E5: =SUM(E6:E500) -> 73581.433 | F5: =SUM(F6:F500) -> 46657.597 | K5: =SUM(K6:K500) -> 92199.358 | L5: =SUM(L6:L500) -> -18617.925 | M5: =SUM(M6:M500) -> 58637.696 | N5: =SUM(N6:N500) -> 14943.737 | O5: =SUM(O6:O500) -> 19603.011 | P5: =SUM(P6:P500) -> -1273.5 | Q5: =SUM(Q6:Q500) -> 22586.477 | R5: =SUM(R6:R500) -> -2032.9 | ... AB5: =SUM(AB6:AB500) -> 13146.432 | AF5: =SUM(AF6:AF500) -> 13329.493 | AG5: =SUM(AG6:AG500) -> 12669.462 | AH5: =SUM(AH6:AH500) -> 10646.114 | AI5: =SUM(AI6:AI500) -> 10433.826 | AJ5: =SUM(AJ6:AJ500) -> 11173.737 | AK5: =SUM(AK6:AK500) -> 12763.75 | AL5: =SUM(AL6:AL500) -> 14118.473 | AM5: =SUM(AM6:AM500) -> 10392.848 | AO5: =SUM(AO6:AO500) -> 16997 | AP5: =SUM(AP6:AP500) -> 7985 | AR5: 1
A6: 005 Колбаса Докторская ГОСТ, Вязанка вектор,ВЕС. ПОКОМ | B6: кг | C6: 2019.147 | D6: 3887.194 | E6: 2033.168 | F6: 2734.685 | G6: 1 | H6: 50 | I6: матрица | K6: 2268.741 | L6: =E6-K6 -> -235.573 | M6: =E6-N6 -> 1628.108 | N6: 405.06 | O6: 571.67825 | Q6: 215.47623 | T6: 267.65433 | W6: =M6/5 -> 325.6216 | X6: =12*W6-T6-Q6-P6-O6-F6 -> 117.96539 | Y6: 0 | Z6: =Y6-AB6 -> 0 | AD6: =(F6+O6+P6+Q6+T6+Z6+AB6+R6+S6+U6+V6)/W6 -> 11.637722 | AE6: =(F6+O6+P6+Q6+T6)/W6 -> 11.637722 | AF6: 402.6088 | AG6: 419.2068 | AH6: 402.0166 | AI6: 337.7342 | AJ6: 348.7926 | AK6: 383.9166 | AL6: 414.5354 | AM6: 309.1234 | AO6: =ROUND(G6*Z6,0) -> 0 | AP6: =ROUND(G6*AB6,0) -> 0 | AQ6: SU000722
A7: 016 Сосиски Вязанка Молочные, Вязанка вискофан ВЕС.ПОКОМ | B7: кг | C7: 473.784 | D7: 2893.569 | E7: 1688.492 | F7: 1204.04 | G7: 1 | H7: 45 | I7: матрица | K7: 1499.102 | L7: =E7-K7 -> 189.39 | M7: =E7-N7 -> 1081.529 | N7: 606.963 | O7: 753.70391 | Q7: 200.7 | T7: 249.3 | W7: =M7/5 -> 216.3058 | X7: =12*W7-T7-Q7-P7-O7-F7 -> 187.92569 | Y7: =X7+$Y$1*W7 -> 399.90537 | Z7: =Y7-AB7 -> 399.90537 | AD7: =(F7+O7+P7+Q7+T7+Z7+AB7+R7+S7+U7+V7)/W7 -> 12.98 | AE7: =(F7+O7+P7+Q7+T7)/W7 -> 11.131204 | AF7: 223.072 | AG7: 285.975 | AH7: 246.8064 | AI7: 136.3926 | AJ7: 175.6748 | AK7: 232.3934 | AL7: 194.2758 | AM7: 139.5838 | AO7: =ROUND(G7*Z7,0) -> 400 | AP7: =ROUND(G7*AB7,0) -> 0 | AQ7: SU001523
A8: 017 Сосиски Вязанка Сливочные, Вязанка амицел ВЕС.ПОКОМ | B8: кг | C8: 2754.893 | D8: 6282.726 | E8: 4646.485 | F8: =2266.304+F86 -> 2260.863 | G8: 1 | H8: 45 | I8: матрица | K8: 4805.024 | L8: =E8-K8 -> -158.539 | M8: =E8-N8 -> 2732.122 | N8: 1914.363 | O8: 976.73631 | Q8: 1024.6154 | T8: 1272.7285 | W8: =M8/5 -> 546.4244 | X8: =12*W8-T8-Q8-P8-O8-F8 -> 1022.1495 | Y8: =X8+$Y$1*W8 -> 1557.6455 | Z8: =Y8-AB8 -> 857.64546 | AB8: 700 | AD8: =(F8+O8+P8+Q8+T8+Z8+AB8+R8+S8+U8+V8)/W8 -> 12.98 | AE8: =(F8+O8+P8+Q8+T8)/W8 -> 10.129385 | AF8: 608.09 | AG8: 673.4266 | AH8: 716.373 | AI8: 543.649 | AJ8: 613.5636 | AK8: 603.608 | AL8: 601.6022 | AM8: 449.453 | AO8: =ROUND(G8*Z8,0) -> 858 | AP8: =ROUND(G8*AB8,0) -> 700 | AQ8: SU001721
A9: 023 Колбаса Докторская ГОСТ, Вязанка вектор, 0,4 кг, ПОКОМ | B9: шт | C9: 23 | D9: 10 | E9: 7 | F9: 18 | G9: 0.4 | H9: 50 | I9: матрица | K9: 14 | L9: =E9-K9 -> -7 | M9: =E9-N9 -> 7 | Q9: 0 | W9: =M9/5 -> 1.4 | Y9: =X9 -> 0 | Z9: =Y9-AB9 -> 0 | AD9: =(F9+O9+P9+Q9+T9+Z9+AB9+R9+S9+U9+V9)/W9 -> 12.857143 | AE9: =(F9+O9+P9+Q9+T9)/W9 -> 12.857143 | AF9: 1.4 | AG9: 1.8 | AH9: 2.4 | AI9: 1 | AJ9: 1.2 | AK9: 2.6 | AL9: 2.2 | AM9: 0 | AN9: 19 шт списано (12,07,26) | AO9: =ROUND(G9*Z9,0) -> 0 | AP9: =ROUND(G9*AB9,0) -> 0 | AQ9: SU001485
A10: 030 Сосиски Вязанка Молочные, Вязанка вискофан МГС, 0.45кг, ПОКОМ | B10: шт | C10: 1956.55 | D10: 2792 | E10: 2608.174 | F10: 615.376 | G10: 0.45 | H10: 45 | I10: ВНИМАНИЕ / матрица | K10: 3201 | L10: =E10-K10 -> -592.826 | M10: =E10-N10 -> 2464.174 | N10: 144 | O10: 907.608 | Q10: 535.2 | S10: 1000 | T10: 664.8 | W10: =M10/5 -> 492.8348 | X10: 2000 | Y10: =X10 -> 2000 | Z10: =Y10-AB10 -> 700 | AB10: 1300 | AD10: =(F10+O10+P10+Q10+T10+Z10+AB10+R10+S10+U10+V10)/W10 -> 11.612378 | AE10: =(F10+O10+P10+Q10+T10)/W10 -> 5.5251455 | AF10: 540.4348 | AG10: 426.419 | AH10: 373.019 | AI10: 298 | AJ10: 339 | AK10: 705.871 | AL10: 624.671 | AM10: 265.4 | AN10: 1000шт под ЮТЛ (Хмель 15,07,26) | AO10: =ROUND(G10*Z10,0) -> 315 | AP10: =ROUND(G10*AB10,0) -> 585 | AQ10: SU001718 | AR10: =VLOOKUP(AQ10,[1]Лист1!$A:$A,1,0) -> SU001718
A11: 032 Сосиски Вязанка Сливочные, Вязанка амицел МГС, 0.45кг, ПОКОМ | B11: шт | C11: 5853.021 | D11: 2392 | E11: 4360.366 | F11: 1646.655 | G11: 0.45 | H11: 45 | I11: ВНИМАНИЕ / матрица | K11: 4886 | L11: =E11-K11 -> -525.634 | M11: =E11-N11 -> 3424.366 | N11: 936 | O11: 260 | Q11: 356.8 | T11: 443.2 | W11: =M11/5 -> 684.8732 | X11: =11*W11-T11-Q11-P11-O11-F11 -> 4826.9502 | Y11: =X11 -> 4826.9502 | Z11: =Y11-AB11 -> 1826.9502 | AB11: 3000 | AD11: =(F11+O11+P11+Q11+T11+Z11+AB11+R11+S11+U11+V11)/W11 -> 11 | AE11: =(F11+O11+P11+Q11+T11)/W11 -> 3.9520527 | AF11: 689.6732 | AG11: 718.03 | AH11: 763.0744 | AI11: 683.4 | AJ11: 536.8 | AK11: 707.3658 | AL11: 771.7658 | AM11: 431.2 | AN11: 1000 сеть МКД (05,08,26) | AO11: =ROUND(G11*Z11,0) -> 822 | AP11: =ROUND(G11*AB11,0) -> 1350 | AQ11: SU001720
A12: 047 Кол Баварская, белков.обол. в термоусад. пакете 0.17 кг, ТМ Стародворье ПОКОМ | B12: шт | C12: 282 | D12: 37 | E12: 119 | F12: 126 | G12: 0.17 | H12: 180 | I12: матрица | K12: 149 | L12: =E12-K12 -> -30 | M12: =E12-N12 -> 89 | N12: 30 | Q12: 0 | W12: =M12/5 -> 17.8 | X12: =12*W12-T12-Q12-P12-O12-F12 -> 87.6 | Y12: =X12 -> 87.6 | Z12: =Y12-AB12 -> 87.6 | AD12: =(F12+O12+P12+Q12+T12+Z12+AB12+R12+S12+U12+V12)/W12 -> 12 | AE12: =(F12+O12+P12+Q12+T12)/W12 -> 7.0786517 | AF12: 17.8 | AG12: 13.2 | AH12: 20 | AI12: 19.234 | AJ12: 23.6 | AK12: 35 | AL12: 24.6 | AM12: 9 | AO12: =ROUND(G12*Z12,0) -> 15 | AP12: =ROUND(G12*AB12,0) -> 0 | AQ12: SU002092
A13: 062 Колбаса Кракушка пряная с сальцем, 0.3кг в/у п/к, БАВАРУШКА ПОКОМ | B13: шт | C13: 96 | D13: 9 | E13: 60 | F13: 19 | G13: 0.3 | H13: 40 | I13: матрица | K13: 80 | L13: =E13-K13 -> -20 | M13: =E13-N13 -> 60 | Q13: 75 | R13: -78 | W13: =M13/5 -> 12 | X13: =12*W13-T13-Q13-P13-O13-F13 -> 50 | Y13: =X13 -> 50 | Z13: =Y13-AB13 -> 50 | AD13: =(F13+O13+P13+Q13+T13+Z13+AB13+R13+S13+U13+V13)/W13 -> 5.5 | AE13: =(F13+O13+P13+Q13+T13)/W13 -> 7.8333333 | AF13: 12.6 | AG13: 7.2 | AH13: 4.2 | AI13: 8.2 | AJ13: 11.8 | AK13: 8.4 | AL13: 3.2 | AM13: 1 | AO13: =ROUND(G13*Z13,0) -> 15 | AP13: =ROUND(G13*AB13,0) -> 0 | AQ13: SU002252
A14: 083 Колбаса Швейцарская 0,17 кг., ШТ., сырокопченая ПОКОМ | B14: шт | C14: 383 | D14: 103 | E14: 297 | F14: 6 | G14: 0.17 | H14: 180 | I14: матрица | K14: 397 | L14: =E14-K14 -> -100 | M14: =E14-N14 -> 87 | N14: 210 | Q14: 152 | W14: =M14/5 -> 17.4 | X14: =12*W14-T14-Q14-P14-O14-F14 -> 50.8 | Y14: =X14 -> 50.8 | Z14: =Y14-AB14 -> 50.8 | AD14: =(F14+O14+P14+Q14+T14+Z14+AB14+R14+S14+U14+V14)/W14 -> 12 | AE14: =(F14+O14+P14+Q14+T14)/W14 -> 9.0804598 | AF14: 35.4 | AG14: 34.2 | AH14: 26 | AI14: 27.634 | AJ14: 36.8 | AK14: 60.2 | AL14: 65.2 | AM14: 36.6 | AO14: =ROUND(G14*Z14,0) -> 9 | AP14: =ROUND(G14*AB14,0) -> 0 | AQ14: SU001869
A15: 103 Сосиски Классические, 0.42кг,ядрена копотьПОКОМ | B15: шт | C15: 336 | D15: 2 | E15: 5 | F15: 272 | G15: 0 | I15: не в матрице | K15: 53 | L15: =E15-K15 -> -48 | M15: =E15-N15 -> 5 | Q15: 0 | W15: =M15/5 -> 1 | Y15: =X15 -> 0 | Z15: =Y15-AB15 -> 0 | AD15: =(F15+O15+P15+Q15+T15+Z15+AB15+R15+S15+U15+V15)/W15 -> 272 | AE15: =(F15+O15+P15+Q15+T15)/W15 -> 272 | AF15: 1 | AG15: 5.2 | AH15: 4.4 | AI15: 0.2 | AJ15: 4.4 | AK15: 4.2 | AL15: 0 | AM15: 0 | AN15: Продукция для ПРС!!! | AO15: =ROUND(G15*Z15,0) -> 0 | AP15: =ROUND(G15*AB15,0) -> 0 | AQ15: SU000341
A16: 200 Ветчина Дугушка ТМ Стародворье, вектор в/у ПОКОМ | B16: кг | C16: 3949.242 | D16: 5740.334 | E16: 4270.796 | F16: 3018.523 | G16: 1 | H16: 70 | I16: матрица | K16: 4821.759 | L16: =E16-K16 -> -550.963 | M16: =E16-N16 -> 2883.302 | N16: 1387.494 | O16: 1598.8085 | Q16: 267.6 | T16: 332.4 | W16: =M16/5 -> 576.6604 | X16: =12*W16-T16-Q16-P16-O16-F16 -> 1702.5933 | Y16: =X16+$Y$1*W16 -> 2267.7205 | Z16: =Y16-AB16 -> 1402.7205 | AB16: 865 | AD16: =(F16+O16+P16+Q16+T16+Z16+AB16+R16+S16+U16+V16)/W16 -> 12.98 | AE16: =(F16+O16+P16+Q16+T16)/W16 -> 9.047494 | AF16: 628.171 | AG16: 726.9406 | AH16: 643.966 | AI16: 609.9092 | AJ16: 693.1158 | AK16: 746.7954 | AL16: 794.7714 | AM16: 554.7976 | AO16: =ROUND(G16*Z16,0) -> 1403 | AP16: =ROUND(G16*AB16,0) -> 865 | AQ16: SU002035 | AR16: =VLOOKUP(AQ16,[1]Лист1!$A:$A,1,0) -> SU002035
A17: 201 Ветчина Нежная ТМ Особый рецепт, (2,5кг), ПОКОМ | B17: кг | C17: 3045.259 | D17: 3464.733 | E17: 3118.307 | F17: 1311.933 | G17: 1 | H17: 50 | I17: матрица | K17: 4089.089 | L17: =E17-K17 -> -970.782 | M17: =E17-N17 -> 1418.037 | N17: 1700.27 | O17: 270.40264 | Q17: 888.46133 | T17: 1103.6044 | V17: 300 | W17: =M17/5 -> 283.6074 | Y17: =X17 -> 0 | Z17: =Y17-AB17 -> 0 | AD17: =(F17+O17+P17+Q17+T17+Z17+AB17+R17+S17+U17+V17)/W17 -> 13.661144 | AE17: =(F17+O17+P17+Q17+T17)/W17 -> 12.603343 | AF17: 445.8572 | AG17: 436.475 | AH17: 435.7906 | AI17: 509.0408 | AJ17: 530.1232 | AK17: 537.543 | AL17: 623.7324 | AM17: 623.553 | AO17: =ROUND(G17*Z17,0) -> 0 | AP17: =ROUND(G17*AB17,0) -> 0 | AQ17: SU000126 | AR17: =VLOOKUP(AQ17,[1]Лист1!$A:$A,1,0) -> SU000126
A18: 215 Колбаса Докторская ГОСТ Дугушка, ВЕС, ТМ Стародворье ПОКОМ | B18: кг | C18: 328.6 | D18: 310.218 | E18: 448.405 | F18: -10.764 | G18: 1 | H18: 60 | I18: матрица | K18: 523.844 | L18: =E18-K18 -> -75.439 | M18: =E18-N18 -> 146.161 | N18: 302.244 | Q18: 211.8584 | W18: =M18/5 -> 29.2322 | X18: =12*W18-T18-Q18-P18-O18-F18 -> 149.692 | Y18: =X18 -> 149.692 | Z18: =Y18-AB18 -> 149.692 | AD18: =(F18+O18+P18+Q18+T18+Z18+AB18+R18+S18+U18+V18)/W18 -> 12 | AE18: =(F18+O18+P18+Q18+T18)/W18 -> 6.8792085 | AF18: 29.2322 | AG18: 22.3572 | AH18: -0.251 | AI18: 23.0592 | AJ18: 27.917 | AK18: 18.902 | AL18: 36.5078 | AM18: 45.232 | AO18: =ROUND(G18*Z18,0) -> 150 | AP18: =ROUND(G18*AB18,0) -> 0 | AQ18: SU002011
A19: 219 Колбаса Докторская Особая ТМ Особый рецепт, ВЕС ПОКОМ | B19: кг | C19: -4.974 | E19: 1.755 | F19: -27.493 | G19: 0 | I19: не в матрице | J19: 597 Колбаса Классическая ТМ Особый рецепт в оболочке полиамид ВЕС. ПОКОМ | K19: 22.5 | L19: =E19-K19 -> -20.745 | M19: =E19-N19 -> 1.755 | Q19: 0 | W19: =M19/5 -> 0.351 | Y19: =X19 -> 0 | Z19: =Y19-AB19 -> 0 | AD19: =(F19+O19+P19+Q19+T19+Z19+AB19+R19+S19+U19+V19)/W19 -> -78.327635 | AE19: =(F19+O19+P19+Q19+T19)/W19 -> -78.327635 | AF19: 0.351 | AG19: -0.365 | AH19: -0.513 | AI19: -0.148 | AJ19: 0 | AK19: 0.4948 | AL19: 0.4948 | AM19: 0 | AO19: =ROUND(G19*Z19,0) -> 0 | AP19: =ROUND(G19*AB19,0) -> 0 | AQ19: SU004238 | AR19: =VLOOKUP(AQ19,[1]Лист1!$A:$A,1,0) -> SU004238
A20: 225 Колбаса Дугушка со шпиком, ВЕС, ТМ Стародворье ПОКОМ | B20: кг | G20: 0 | I20: матрица | L20: =E20-K20 -> 0 | M20: =E20-N20 -> 0 | Q20: 0 | W20: =M20/5 -> 0 | Y20: =X20 -> 0 | Z20: =Y20-AB20 -> 0 | AD20: =(F20+O20+P20+Q20+T20+Z20+AB20+R20+S20+U20+V20)/W20 -> #DIV/0! | AE20: =(F20+O20+P20+Q20+T20)/W20 -> #DIV/0! | AF20: 0 | AG20: 0 | AH20: 0 | AI20: 0 | AJ20: 0 | AK20: 0 | AL20: 0 | AM20: 0 | AN20: нет потребности | AO20: =ROUND(G20*Z20,0) -> 0 | AP20: =ROUND(G20*AB20,0) -> 0 | AQ20: SU002182
A21: 226 Колбаса Княжеская, с/к белков.обол в термоусад. пакете, ВЕС, ТМ Стародворье ПОКОМ | B21: кг | C21: 4.074 | D21: 20.452 | E21: 4.417 | F21: 21.476 | G21: 1 | H21: 180 | I21: матрица | K21: 3.2 | L21: =E21-K21 -> 1.217 | M21: =E21-N21 -> 4.417 | Q21: 0 | W21: =M21/5 -> 0.8834 | Y21: =X21 -> 0 | Z21: =Y21-AB21 -> 0 | AD21: =(F21+O21+P21+Q21+T21+Z21+AB21+R21+S21+U21+V21)/W21 -> 24.310618 | AE21: =(F21+O21+P21+Q21+T21)/W21 -> 24.310618 | AF21: 0.8834 | AG21: 1.4618 | AH21: 1.1292 | AI21: 0.642 | AJ21: 0.429 | AK21: 1.0448 | AL21: 1.1864 | AM21: 0.4298 | AN21: нужно увеличить продажи | AO21: =ROUND(G21*Z21,0) -> 0 | AP21: =ROUND(G21*AB21,0) -> 0 | AQ21: SU001920
A22: 229 Колбаса Молочная Дугушка, в/у, ВЕС, ТМ Стародворье ПОКОМ | B22: кг | C22: 4132.444 | D22: 9744.665 | E22: 5972.888 | F22: 5774.89 | G22: 1 | H22: 60 | I22: матрица | K22: 5380.919 | L22: =E22-K22 -> 591.969 | M22: =E22-N22 -> 5972.888 | O22: 3489.2333 | Q22: 1826.1225 | T22: 2268.3225 | W22: =M22/5 -> 1194.5776 | X22: =12*W22-T22-Q22-P22-O22-F22 -> 976.36289 | Y22: 0 | Z22: =Y22-AB22 -> 0 | AD22: =(F22+O22+P22+Q22+T22+Z22+AB22+R22+S22+U22+V22)/W22 -> 11.182671 | AE22: =(F22+O22+P22+Q22+T22)/W22 -> 11.182671 | AF22: 1235.5082 | AG22: 1204.554 | AH22: 901.4088 | AI22: 763.3562 | AJ22: 859.3734 | AK22: 796.5506 | AL22: 870.4836 | AM22: 625.4246 | AO22: =ROUND(G22*Z22,0) -> 0 | AP22: =ROUND(G22*AB22,0) -> 0 | AQ22: SU002010
A23: 230 Колбаса Молочная Особая ТМ Особый рецепт, п/а, ВЕС. ПОКОМ | B23: кг | C23: -7.493 | E23: 4.97 | F23: -12.463 | G23: 0 | I23: не в матрице | J23: 457 Колбаса Молочная ТМ Особый рецепт ВЕС большой батон ПОКОМ | K23: 5 | L23: =E23-K23 -> -0.03 | M23: =E23-N23 -> 4.97 | Q23: 0 | W23: =M23/5 -> 0.994 | Y23: =X23 -> 0 | Z23: =Y23-AB23 -> 0 | AD23: =(F23+O23+P23+Q23+T23+Z23+AB23+R23+S23+U23+V23)/W23 -> -12.538229 | AE23: =(F23+O23+P23+Q23+T23)/W23 -> -12.538229 | AF23: 0.994 | AG23: 0 | AH23: 0 | AI23: 0 | AJ23: 0 | AK23: 1.4986 | AL23: 1.4986 | AM23: 0 | AO23: =ROUND(G23*Z23,0) -> 0 | AP23: =ROUND(G23*AB23,0) -> 0 | AQ23: SU003422 | AR23: =VLOOKUP(AQ23,[1]Лист1!$A:$A,1,0) -> SU003422
A24: 236 Колбаса Рубленая ЗАПЕЧ. Дугушка ТМ Стародворье, вектор, в/к ПОКОМ | B24: кг | C24: 335.729 | D24: 1254.869 | E24: 209.511 | F24: 583.087 | G24: 1 | H24: 70 | I24: матрица | K24: 1037.545 | L24: =E24-K24 -> -828.034 | M24: =E24-N24 -> 108.401 | N24: 101.11 | Q24: 0 | W24: =M24/5 -> 21.6802 | Y24: =X24 -> 0 | Z24: =Y24-AB24 -> 0 | AD24: =(F24+O24+P24+Q24+T24+Z24+AB24+R24+S24+U24+V24)/W24 -> 26.894909 | AE24: =(F24+O24+P24+Q24+T24)/W24 -> 26.894909 | AF24: 72.8132 | AG24: 77.0706 | AH24: 121.8204 | AI24: 64.7166 | AJ24: 29.2552 | AK24: 86.5184 | AL24: 112.269 | AM24: 80.8328 | AN24: нужно увеличить продажи | AO24: =ROUND(G24*Z24,0) -> 0 | AP24: =ROUND(G24*AB24,0) -> 0 | AQ24: SU002150
A25: 239 Колбаса Салями запеч Дугушка, оболочка вектор, ВЕС, ТМ Стародворье ПОКОМ | B25: кг | C25: 1316.174 | D25: 1676.538 | E25: 1398.375 | F25: 990.209 | G25: 1 | H25: 70 | I25: матрица | K25: 1519.923 | L25: =E25-K25 -> -121.548 | M25: =E25-N25 -> 1063.414 | N25: 334.961 | O25: 457.30278 | Q25: 322.91478 | T25: 401.10939 | W25: =M25/5 -> 212.6828 | X25: =12*W25-T25-Q25-P25-O25-F25 -> 380.65764 | Y25: =X25+$Y$1*W25 -> 589.08679 | Z25: =Y25-AB25 -> 589.08679 | AD25: =(F25+O25+P25+Q25+T25+Z25+AB25+R25+S25+U25+V25)/W25 -> 12.98 | AE25: =(F25+O25+P25+Q25+T25)/W25 -> 10.21021 | AF25: 230.368 | AG25: 244.7884 | AH25: 233.4784 | AI25: 197.4094 | AJ25: 248.3712 | AK25: 254.2464 | AL25: 255.9778 | AM25: 183.0002 | AO25: =ROUND(G25*Z25,0) -> 589 | AP25: =ROUND(G25*AB25,0) -> 0 | AQ25: SU002158
A26: 240 Колбаса Салями охотничья, ВЕС. ПОКОМ | B26: кг | G26: 0 | I26: матрица | L26: =E26-K26 -> 0 | M26: =E26-N26 -> 0 | Q26: 0 | W26: =M26/5 -> 0 | Y26: =X26 -> 0 | Z26: =Y26-AB26 -> 0 | AD26: =(F26+O26+P26+Q26+T26+Z26+AB26+R26+S26+U26+V26)/W26 -> #DIV/0! | AE26: =(F26+O26+P26+Q26+T26)/W26 -> #DIV/0! | AF26: 0 | AG26: 0 | AH26: 0 | AI26: 0 | AJ26: 0 | AK26: 0 | AL26: 0 | AM26: 0 | AN26: нет потребности | AO26: =ROUND(G26*Z26,0) -> 0 | AP26: =ROUND(G26*AB26,0) -> 0 | AQ26: SU001921
A27: 242 Колбаса Сервелат ЗАПЕЧ.Дугушка ТМ Стародворье, вектор, в/к ПОКОМ | B27: кг | C27: 2323.611 | D27: 2015.317 | E27: 2505.23 | F27: 633.433 | G27: 1 | H27: 70 | I27: матрица | K27: 2693.62 | L27: =E27-K27 -> -188.39 | M27: =E27-N27 -> 1782.234 | N27: 722.996 | O27: 416 | Q27: 1084.2377 | T27: 1346.7885 | W27: =M27/5 -> 356.4468 | X27: =12*W27-T27-Q27-P27-O27-F27 -> 796.90236 | Y27: =X27+$Y$1*W27 -> 1146.2202 | Z27: =Y27-AB27 -> 1146.2202 | AD27: =(F27+O27+P27+Q27+T27+Z27+AB27+R27+S27+U27+V27)/W27 -> 12.98 | AE27: =(F27+O27+P27+Q27+T27)/W27 -> 9.7643161 | AF27: 377.3442 | AG27: 436.646 | AH27: 375.1652 | AI27: 497.5888 | AJ27: 453.6796 | AK27: 417.4032 | AL27: 457.0628 | AM27: 304.7148 | AO27: =ROUND(G27*Z27,0) -> 1146 | AP27: =ROUND(G27*AB27,0) -> 0 | AQ27: SU002151
A28: 244 Колбаса Сервелат Кремлевский, ВЕС. ПОКОМ | B28: кг | C28: 81.498 | E28: 6.511 | F28: 69.202 | G28: 1 | H28: 40 | I28: матрица | K28: 7.2 | L28: =E28-K28 -> -0.689 | M28: =E28-N28 -> 6.511 | Q28: 0 | W28: =M28/5 -> 1.3022 | Y28: =X28 -> 0 | Z28: =Y28-AB28 -> 0 | AD28: =(F28+O28+P28+Q28+T28+Z28+AB28+R28+S28+U28+V28)/W28 -> 53.142374 | AE28: =(F28+O28+P28+Q28+T28)/W28 -> 53.142374 | AF28: 1.3022 | AG28: 1.9806 | AH28: 1.2582 | AI28: 0.732 | AJ28: 1.3146 | AK28: 7.8512 | AL28: 8.7356 | AM28: 3.5048 | AN28: нужно увеличить продажи!!! | AO28: =ROUND(G28*Z28,0) -> 0 | AP28: =ROUND(G28*AB28,0) -> 0 | AQ28: SU001822
A29: 247 Сардельки Нежные, ВЕС. ПОКОМ | B29: кг | G29: 0 | I29: матрица | L29: =E29-K29 -> 0 | M29: =E29-N29 -> 0 | Q29: 0 | W29: =M29/5 -> 0 | Y29: =X29 -> 0 | Z29: =Y29-AB29 -> 0 | AD29: =(F29+O29+P29+Q29+T29+Z29+AB29+R29+S29+U29+V29)/W29 -> #DIV/0! | AE29: =(F29+O29+P29+Q29+T29)/W29 -> #DIV/0! | AF29: 0 | AG29: 0 | AH29: 0 | AI29: 0 | AJ29: 0 | AK29: 0 | AL29: 0 | AM29: 0 | AN29: нет потребности | AO29: =ROUND(G29*Z29,0) -> 0 | AP29: =ROUND(G29*AB29,0) -> 0 | AQ29: SU001051
A30: 248 Сардельки Сочные ТМ Особый рецепт, ПОКОМ | B30: кг | G30: 0 | I30: матрица | L30: =E30-K30 -> 0 | M30: =E30-N30 -> 0 | Q30: 0 | W30: =M30/5 -> 0 | Y30: =X30 -> 0 | Z30: =Y30-AB30 -> 0 | AD30: =(F30+O30+P30+Q30+T30+Z30+AB30+R30+S30+U30+V30)/W30 -> #DIV/0! | AE30: =(F30+O30+P30+Q30+T30)/W30 -> #DIV/0! | AF30: 0 | AG30: 0 | AH30: 0 | AI30: 0 | AJ30: 0 | AK30: 0 | AL30: 0 | AM30: 0 | AN30: нет потребности | AO30: =ROUND(G30*Z30,0) -> 0 | AP30: =ROUND(G30*AB30,0) -> 0 | AQ30: SU002287
A31: 250 Сардельки стародворские с говядиной в обол. NDX, ВЕС. ПОКОМ | B31: кг | C31: 1400.299 | D31: 2826.522 | E31: 3172.825 | F31: 187.902 | G31: 1 | H31: 30 | I31: НЕДОГРУЗ / матрица | K31: 2490.037 | L31: =E31-K31 -> 682.788 | M31: =E31-N31 -> 2203.238 | N31: 969.587 | O31: 416 | Q31: 669 | T31: 831 | W31: =M31/5 -> 440.6476 | X31: =11*W31-T31-Q31-P31-O31-F31 -> 2743.2216 | Y31: =X31 -> 2743.2216 | Z31: 2610 | AA31: -500.8 | AB31: =Y31*0.5 -> 1371.6108 | AD31: =(F31+O31+P31+Q31+T31+Z31+AB31+R31+S31+U31+V31)/W31 -> 13.810385 | AE31: =(F31+O31+P31+Q31+T31)/W31 -> 4.7745682 | AF31: 365.1898 | AG31: 310.8728 | AH31: 178.8978 | AI31: 437.4332 | AJ31: 568.7244 | AK31: 251.4826 | AL31: 368.8554 | AM31: 396.4942 | AO31: =ROUND(G31*Z31,0) -> 2610 | AP31: =ROUND(G31*AB31,0) -> 1372 | AQ31: SU000227
A32: 253 Сосиски Ганноверские ПОКОМ | B32: кг | C32: -0.23 | F32: -0.23 | G32: 0 | H32: 40 | I32: не в матрице | L32: =E32-K32 -> 0 | M32: =E32-N32 -> 0 | Q32: 0 | W32: =M32/5 -> 0 | Y32: =X32 -> 0 | Z32: =Y32-AB32 -> 0 | AD32: =(F32+O32+P32+Q32+T32+Z32+AB32+R32+S32+U32+V32)/W32 -> #DIV/0! | AE32: =(F32+O32+P32+Q32+T32)/W32 -> #DIV/0! | AF32: 0 | AG32: 0 | AH32: 0 | AI32: 0 | AJ32: -0.098 | AK32: 12.5518 | AL32: 13.9894 | AM32: 4.5704 | AO32: =ROUND(G32*Z32,0) -> 0 | AP32: =ROUND(G32*AB32,0) -> 0 | AQ32: SU001340
A33: 255 Сосиски Молочные для завтрака ТМ Особый рецепт, п/а МГС, ВЕС, ТМ Стародворье ПОКОМ | B33: кг | C33: 1148.73 | D33: 431.798 | E33: 3281.402 | F33: -114.405 | G33: 1 | H33: 40 | I33: НЕДОГРУЗ / матрица | K33: 3984.676 | L33: =E33-K33 -> -703.274 | M33: =E33-N33 -> 3281.402 | O33: 520 | P33: -522 | Q33: 892 | T33: 1208 | U33: -1208 | W33: =M33/5 -> 656.2804 | X33: 2200 | Y33: =X33 -> 2200 | Z33: =Y33 -> 2200 | AB33: =Y33*0.5 -> 1100 | AD33: =(F33+O33+P33+Q33+T33+Z33+AB33+R33+S33+U33+V33)/W33 -> 6.2101428 | AE33: =(F33+O33+P33+Q33+T33)/W33 -> 3.0224809 | AF33: 656.844 | AG33: 328.153 | AH33: -0.8462 | AI33: 8.5924 | AJ33: 9.8556 | AK33: 688.0432 | AL33: 1184.2532 | AM33: 1031.4698 | AO33: =ROUND(G33*Z33,0) -> 2200 | AP33: =ROUND(G33*AB33,0) -> 1100 | AQ33: SU002074
A34: 257 Сосиски Молочные оригинальные ТМ Особый рецепт, ВЕС. ПОКОМ | B34: кг | G34: 0 | I34: матрица | L34: =E34-K34 -> 0 | M34: =E34-N34 -> 0 | Q34: 0 | W34: =M34/5 -> 0 | Y34: =X34 -> 0 | Z34: =Y34-AB34 -> 0 | AD34: =(F34+O34+P34+Q34+T34+Z34+AB34+R34+S34+U34+V34)/W34 -> #DIV/0! | AE34: =(F34+O34+P34+Q34+T34)/W34 -> #DIV/0! | AF34: 0 | AG34: 0 | AH34: 0 | AI34: 0 | AJ34: 0 | AK34: 0 | AL34: 0 | AM34: 0 | AN34: нет потребности | AO34: =ROUND(G34*Z34,0) -> 0 | AP34: =ROUND(G34*AB34,0) -> 0 | AQ34: SU000246
A35: 263 Шпикачки Стародворские, ВЕС. ПОКОМ | B35: кг | G35: 0 | I35: матрица | L35: =E35-K35 -> 0 | M35: =E35-N35 -> 0 | Q35: 0 | W35: =M35/5 -> 0 | Y35: =X35 -> 0 | Z35: =Y35-AB35 -> 0 | AD35: =(F35+O35+P35+Q35+T35+Z35+AB35+R35+S35+U35+V35)/W35 -> #DIV/0! | AE35: =(F35+O35+P35+Q35+T35)/W35 -> #DIV/0! | AF35: 0 | AG35: 0 | AH35: 0 | AI35: 0 | AJ35: 0 | AK35: 0 | AL35: 0 | AM35: 0 | AN35: нет потребности | AO35: =ROUND(G35*Z35,0) -> 0 | AP35: =ROUND(G35*AB35,0) -> 0 | AQ35: SU001430
A36: 265 Колбаса Балыкбургская, ВЕС, ТМ Баварушка ПОКОМ | B36: кг | G36: 0 | I36: матрица | L36: =E36-K36 -> 0 | M36: =E36-N36 -> 0 | Q36: 0 | W36: =M36/5 -> 0 | Y36: =X36 -> 0 | Z36: =Y36-AB36 -> 0 | AD36: =(F36+O36+P36+Q36+T36+Z36+AB36+R36+S36+U36+V36)/W36 -> #DIV/0! | AE36: =(F36+O36+P36+Q36+T36)/W36 -> #DIV/0! | AF36: 0 | AG36: 0 | AH36: 0 | AI36: 0 | AJ36: 0 | AK36: 0 | AL36: 0 | AM36: 0 | AN36: нет потребности | AO36: =ROUND(G36*Z36,0) -> 0 | AP36: =ROUND(G36*AB36,0) -> 0 | AQ36: SU002612
A37: 267 Колбаса Салями Филейбургская зернистая, оболочка фиброуз, ВЕС, ТМ Баварушка ПОКОМ | B37: кг | G37: 0 | I37: матрица | L37: =E37-K37 -> 0 | M37: =E37-N37 -> 0 | Q37: 0 | W37: =M37/5 -> 0 | Y37: =X37 -> 0 | Z37: =Y37-AB37 -> 0 | AD37: =(F37+O37+P37+Q37+T37+Z37+AB37+R37+S37+U37+V37)/W37 -> #DIV/0! | AE37: =(F37+O37+P37+Q37+T37)/W37 -> #DIV/0! | AF37: 0 | AG37: 0 | AH37: 0 | AI37: 0 | AJ37: 0 | AK37: 0 | AL37: 0 | AM37: 0 | AN37: нет потребности | AO37: =ROUND(G37*Z37,0) -> 0 | AP37: =ROUND(G37*AB37,0) -> 0 | AQ37: SU002614
A38: 273 Сосиски Сочинки с сочной грудинкой, МГС 0.4кг, ПОКОМ | B38: шт | C38: 1008 | D38: 4256 | E38: 5155 | F38: -322 | G38: 0.4 | H38: 45 | I38: НЕДОГРУЗ / матрица | K38: 4558 | L38: =E38-K38 -> 597 | M38: =E38-N38 -> 4075 | N38: 1080 | O38: 780 | Q38: 1767.944 | T38: 2196.056 | W38: =M38/5 -> 815 | X38: =11*W38-T38-Q38-P38-O38-F38 -> 4543 | Y38: =X38 -> 4543 | Z38: 3000 | AB38: 2220 | AC38: =VLOOKUP(A38,[2]Sheet!$A:$U,21,0) -> ОЧЕНЬ НУЖНА ЭТА ПОЗИЦИЯ !!! | AD38: =(F38+O38+P38+Q38+T38+Z38+AB38+R38+S38+U38+V38)/W38 -> 11.830675 | AE38: =(F38+O38+P38+Q38+T38)/W38 -> 5.4257669 | AF38: 779 | AG38: 633.6 | AH38: 113.2 | AI38: 461.2 | AJ38: 811.2 | AK38: 861.6 | AL38: 877.4 | AM38: 623.4 | AO38: =ROUND(G38*Z38,0) -> 1200 | AP38: =ROUND(G38*AB38,0) -> 888 | AQ38: SU002618
A39: 276 Колбаса Сливушка ТМ Вязанка в оболочке полиамид 0,45 кг ПОКОМ | B39: шт | C39: 839.75 | D39: 263 | E39: 735 | F39: 253.75 | G39: 0.45 | H39: 50 | I39: ВНИМАНИЕ / матрица | K39: 1175 | L39: =E39-K39 -> -440 | M39: =E39-N39 -> 735 | Q39: 200 | W39: =M39/5 -> 147 | X39: =10*W39-T39-Q39-P39-O39-F39 -> 1016.25 | Y39: =X39+500 -> 1516.25 | Z39: =Y39-AB39 -> 716.25 | AB39: 800 | AC39: =VLOOKUP(A39,[2]Sheet!$A:$U,21,0) -> еще плюс 500 сеть ютл | AD39: =(F39+O39+P39+Q39+T39+Z39+AB39+R39+S39+U39+V39)/W39 -> 13.401361 | AE39: =(F39+O39+P39+Q39+T39)/W39 -> 3.0867347 | AF39: 147.6 | AG39: 112.6 | AH39: 71 | AI39: 70.4 | AJ39: 98.4 | AK39: 126.8 | AL39: 127.8 | AM39: 67.2 | AN39: 500шт под ЮТЛ (Хмель 21,08,26) | AO39: =ROUND(G39*Z39,0) -> 322 | AP39: =ROUND(G39*AB39,0) -> 360 | AQ39: SU002734
A40: 278 Сосиски Сочинки с сочным окороком, МГС 0.4кг, ПОКОМ | B40: шт | C40: -5 | D40: 832 | E40: 742 | F40: 43 | G40: 0.4 | H40: 45 | I40: НЕДОГРУЗ / матрица | K40: 2165 | L40: =E40-K40 -> -1423 | M40: =E40-N40 -> 742 | O40: 208 | Q40: 400 | R40: -402 | W40: =M40/5 -> 148.4 | X40: 500 | Y40: =X40 -> 500 | Z40: =Y40 -> 500 | AA40: -252 | AB40: =Y40*0.5 -> 250 | AD40: =(F40+O40+P40+Q40+T40+Z40+AB40+R40+S40+U40+V40)/W40 -> 6.7318059 | AE40: =(F40+O40+P40+Q40+T40)/W40 -> 4.3867925 | AF40: 148.4 | AG40: 122.2 | AH40: 91.8 | AI40: 163.6 | AJ40: 166.8 | AK40: 188.8 | AL40: 301.6 | AM40: 192.2 | AO40: =ROUND(G40*Z40,0) -> 200 | AP40: =ROUND(G40*AB40,0) -> 100 | AQ40: SU002621
...

Sheet недогруз 22,08
A1: SU002205 | B1: Сосиски «Молочные для завтрака» Фикс.вес 0,4 П/а мгс ТМ «Особый рецепт» | C1: 81.6 | D1: -81.6
A2: SU002252 | B2: П/к колбасы Кракушка пряная с сальцем Бавария Фикс.вес 0,3 н/о в/у Стародворье | C2: 23.4 | D2: -23.4
A3: SU002621 | B3: Сосиски «Сочинки с сочным окороком» Фикс.вес 0,4 П/а мгс ТМ «Стародворье» | C3: 160.8 | D3: -160.8
A4: SU002660 | B4: Колбаса Мясорубская ТМ Стародворье с рубленой грудинкой в оболочке фиброуз в вакуумной упаковке 0,35 кг срез | C4: 18.9 | D4: -18.9
A5: SU002844 | B5: Сосиски «Сочинки Сливочные» Фикс.вес 0,4 п/а мгс ТМ «Стародворье» | C5: 76.8 | D5: -76.8
A6: SU002848 | B6: В/к колбасы Сервелат Мясорубский с мелкорубленным окороком срез Бордо Фикс.вес 0,35 фиброуз Стародворье | C6: 71.4 | D6: -71.4
A7: SU002942 | B7: В/к колбасы «Сочинка по-фински с сочным окороком» срез Фикс.вес 0,3 фиброуз ТМ «Стародворье» | C7: 16.2 | D7: -16.2
A8: SU002944 | B8: В/к колбасы «Сочинка по-европейски с сочной грудинкой» срез Фикс.вес 0,3 фиброуз ТМ «Стародворье» | C8: 30.6 | D8: -30.6
A9: SU002945 | B9: П/к колбасы «Сочинка зернистая с сочной грудинкой» Весовой фиброуз ТМ «Стародворье» | C9: 383.4 | D9: -383.4
A10: SU002948 | B10: П/к колбасы «Сочинка рубленая с сочным окороком» срез Фикс.вес 0,3 фиброуз ТМ «Стародворье» | C10: 16.2 | D10: -16.2
A11: SU004041 | B11: Копченые колбасы «Балыковая» Весовой фиброуз ТМ «Вязанка» | C11: 101.5 | D11: -101.5
A12: SU004045 | B12: Копченые колбасы «Сервелат Финский» Фикс.вес 0,28 фиброуз срез ТМ «Вязанка» | C12: 57.12 | D12: -57.12

Sheet недогруз 24,08
A1: SU000227 | B1: Сардельки «Стародворские с говядиной» Весовые NDX ТМ «Стародворье» | C1: -500.8 | D1: 1372.8
A2: SU001718 | B2: Сосиски «Молокуши» ф/в 0,45 п/а мгс ТМ «Вязанка» | D2: 585.9
A3: SU001720 | B3: Сосиски «Сливочные» ф/в 0,45 п/а мгс ТМ «Вязанка» | D3: 1350
A4: SU001721 | B4: Сосиски «Сливочные Вязанка» Весовой п/а мгс ТМ «Вязанка» | D4: 704.7
A5: SU002035 | B5: Ветчины Дугушка Дугушка Вес б/о Дугушка | D5: 865.92
A6: SU002074 | B6: Сосиски «Молочные для завтрака» Весовой п/а ТМ «Особый рецепт» | D6: 1107
A7: SU002205 | B7: Сосиски «Молочные для завтрака» Фикс.вес 0,4 П/а мгс ТМ «Особый рецепт» | C7: -40.8 | D7: 40.8
A8: SU002618 | B8: Сосиски «Сочинки с сочной грудинкой» Фикс.вес 0,4 П/а мгс ТМ «Стародворье» | D8: 888
A9: SU002621 | B9: Сосиски «Сочинки с сочным окороком» Фикс.вес 0,4 П/а мгс ТМ «Стародворье» | C9: -100.8 | D9: 100.8
A10: SU002660 | B10: Колбаса Мясорубская ТМ Стародворье с рубленой грудинкой в оболочке фиброуз в вакуумной упаковке 0,35 кг срез | C10: -10.5 | D10: 10.5
A11: SU002686 | B11: Сосиски Сочинки с сыром Бордо ф/в 0,4 кг п/а Стародворье | D11: 12
A12: SU002734 | B12: Вареные колбасы Сливушка Вязанка Фикс.вес 0,45 П/а Вязанка | D12: 360
A13: SU002799 | B13: Сосиски Сочинки по-баварски Бавария Фикс.вес 0,4 П/а мгс Стародворье | D13: 21.6
A14: SU002801 | B14: Сосиски «Сочинки по-баварски с сыром» Фикс.вес 0,4 П/а мгс ТМ «Стародворье» | D14: 21.6
A15: SU002843 | B15: Сосиски «Сочинки Молочные» Весовой п/а мгс ТМ «Стародворье» | D15: 32.4
A16: SU002844 | B16: Сосиски «Сочинки Сливочные» Фикс.вес 0,4 п/а мгс ТМ «Стародворье» | D16: 40.8
A17: SU002845 | B17: Сосиски «Сочинки Сливочные» Весовые ТМ «Стародворье» 1,35 кг | D17: 32.4
A18: SU002848 | B18: В/к колбасы Сервелат Мясорубский с мелкорубленным окороком срез Бордо Фикс.вес 0,35 фиброуз Стародворье | C18: -159.6 | D18: 159.6
A19: SU002942 | B19: В/к колбасы «Сочинка по-фински с сочным окороком» срез Фикс.вес 0,3 фиброуз ТМ «Стародворье» | C19: -9 | D19: 9
A20: SU002944 | B20: В/к колбасы «Сочинка по-европейски с сочной грудинкой» срез Фикс.вес 0,3 фиброуз ТМ «Стародворье» | C20: -9 | D20: 9
A21: SU002948 | B21: П/к колбасы «Сочинка рубленая с сочным окороком» срез Фикс.вес 0,3 фиброуз ТМ «Стародворье» | C21: -9 | D21: 9
A22: SU003167 | B22: Сосиски «Баварские» Фикс.вес 0,35 П/а ТМ «Стародворье» | D22: 18.9
A23: SU003168 | B23: Сосиски «Баварские с сыром» Фикс.вес 0,35 п/а ТМ «Стародворье» | C23: -10.5 | D23: 10.5
A24: SU003829 | B24: Копченые колбасы «Сервелат Мясорубский Делюкс» Фикс.вес 0,3 фиброуз ТМ «Стародворье» | C24: -5.4 | D24: 5.4
A25: SU004039 | B25: Копченые колбасы «Балыковая» Фикс.вес 0,28 фиброуз срез ТМ «Вязанка» | C25: -43.68 | D25: 43.68
A26: SU004041 | B26: Копченые колбасы «Балыковая» Весовой фиброуз ТМ «Вязанка» | C26: -42 | D26: 42
A27: SU004042 | B27: Копченые колбасы «Сервелат Ореховый» Фикс.вес 0,28 фиброуз срез ТМ «Вязанка» | C27: -35.28 | D27: 35.28
A28: SU004044 | B28: Копченые колбасы «Сервелат Ореховый» Весовой фиброуз ТМ «Вязанка» | C28: -91 | D28: 91
A29: SU004045 | B29: Копченые колбасы «Сервелат Финский» Фикс.вес 0,28 фиброуз срез ТМ «Вязанка» | C29: -21.84 | D29: 21.84
A30: SU004047 | B30: Копченые колбасы «Сервелат Финский» Весовой фиброуз ТМ «Вязанка» | D30: 28
A31: SU004146 | B31: Консервы «Буженина в пряном маринаде» Фикс.вес 0,25 ТМ «Стародворье» | D31: 3
