Workbook

Sheet Лист1
B2: Заказ на 26.11 Стародв. Колбасы | E2: Нал | F2: Банк | G2: ИТОГО | H2: кооф | I2: ВЕС
E3: кг/шт | F3: кг/шт | G3: кг/шт | I3: кг
B4: Баварушка*****БАЛЫКБУРГСКАЯ с копч. Балыком 0.7кг | C4: 290 | D4: 308 | G4: =F4+E4 -> 0 | H4: 1 | I4: =H4*G4 -> 0 | J4: =E4*D4 -> 0 | K4: =D4*F4 -> 0
B5: Баварушка*****ФИЛЕЙБУРГСКАЯ Соч. окор. 0.7кг | C5: 290 | D5: 298 | E5: 30 | F5: 15 | G5: =F5+E5 -> 45 | H5: 1 | I5: =H5*G5 -> 45 | J5: =E5*D5 -> 8940 | K5: =D5*F5 -> 4470
B6: Ветчина*****ДУГУШКА Стародв колб 0,8кг / 5кг | C6: 240 | D6: 247 | G6: =F6+E6 -> 0 | H6: 1 | I6: =H6*G6 -> 0 | J6: =E6*D6 -> 0 | K6: =D6*F6 -> 0
B7: Ветчина*****Нежн Особ Славн бол батон 2,5кг /15кг | C7: 210 | D7: 218 | G7: =F7+E7 -> 0 | H7: 1 | I7: =H7*G7 -> 0 | J7: =E7*D7 -> 0 | K7: =D7*F7 -> 0
B8: Вязанка ветчина Филейская*****Стародв 1,3кг/10кг | C8: 255 | D8: 263 | G8: =F8+E8 -> 0 | H8: 1 | I8: =H8*G8 -> 0 | J8: =E8*D8 -> 0 | K8: =D8*F8 -> 0
B9: Вязанка Молокуша*****Стародв колб 1,3кг / 10кг | C9: 235 | D9: 240 | G9: =F9+E9 -> 0 | H9: 1 | I9: =H9*G9 -> 0 | J9: =E9*D9 -> 0 | K9: =D9*F9 -> 0
B10: Вязанка*****СО ШПИКОМ Стародвор. 1.3кг/10кг | C10: 252 | D10: 263 | G10: =F10+E10 -> 0 | H10: 1 | I10: =H10*G10 -> 0 | J10: =E10*D10 -> 0 | K10: =D10*F10 -> 0
B11: Вязанка*****Филейская Стародворье 1,3кг /11кг | C11: 235 | D11: 243 | G11: =F11+E11 -> 0 | H11: 1 | I11: =H11*G11 -> 0 | J11: =E11*D11 -> 0 | K11: =D11*F11 -> 0
B12: Докторская особ рецепт Филейная п/а*****2.5кг/16кг | C12: 150 | D12: 154 | E12: 100 | F12: 75 | G12: =F12+E12 -> 175 | H12: 1 | I12: =H12*G12 -> 175 | J12: =E12*D12 -> 15400 | K12: =D12*F12 -> 11550
B13: Докторская*****ГОСТ вяз п/о Стародворские Колбасы | C13: 270 | D13: 280 | G13: =F13+E13 -> 0 | H13: 1 | I13: =H13*G13 -> 0 | J13: =E13*D13 -> 0 | K13: =D13*F13 -> 0
B14: Докторская*****ДУГУШКА гост Стародв колб 0,8кг / 5кг | C14: 265 | D14: 276 | G14: =F14+E14 -> 0 | H14: 1 | I14: =H14*G14 -> 0 | J14: =E14*D14 -> 0 | K14: =D14*F14 -> 0
B15: Докторская*****Оригинальная Славница 1 кг/12кг | C15: 175 | D15: 175 | E15: 20 | F15: 20 | G15: =F15+E15 -> 40 | H15: 1 | I15: =H15*G15 -> 40 | J15: =E15*D15 -> 3500 | K15: =D15*F15 -> 3500
B16: Дугушка стародворская*****0,8кг / 5кг | C16: 205 | D16: 215 | E16: 40 | F16: 30 | G16: =F16+E16 -> 70 | H16: 1 | I16: =H16*G16 -> 70 | J16: =E16*D16 -> 8600 | K16: =D16*F16 -> 6450
B17: Дугушка стародворская со шпиком*****0,8кг / 5кг | C17: 235 | D17: 235 | E17: 5 | F17: 5 | G17: =F17+E17 -> 10 | H17: 1 | I17: =H17*G17 -> 10 | J17: =E17*D17 -> 1175 | K17: =D17*F17 -> 1175
B18: Молочная*****ДУГУШКА Стародв колб 0,8кг / 5кг | C18: 205 | D18: 214 | G18: =F18+E18 -> 0 | H18: 1 | I18: =H18*G18 -> 0 | J18: =E18*D18 -> 0 | K18: =D18*F18 -> 0
B19: Молочная*****Особая Славница бол бат 2,5кг /15кг | C19: 150 | D19: 154 | E19: 100 | F19: 75 | G19: =F19+E19 -> 175 | H19: 1 | I19: =H19*G19 -> 175 | J19: =E19*D19 -> 15400 | K19: =D19*F19 -> 11550
B20: МЯСОРУБСКАЯ*****рубл. груд вар. Бордо Стар 0,7 кг | G20: =F20+E20 -> 0 | H20: 1 | I20: =H20*G20 -> 0 | J20: =E20*D20 -> 0 | K20: =D20*F20 -> 0
B21: Нежная*****Славница вар Стародв 1,35кг / 10кг | C21: 150 | D21: 154 | G21: =F21+E21 -> 0 | H21: 1 | I21: =H21*G21 -> 0 | J21: =E21*D21 -> 0 | K21: =D21*F21 -> 0
B22: Особая*****со шпиком Славн бол.бат. 2,5кг / 16кг | C22: 150 | D22: 154 | G22: =F22+E22 -> 0 | H22: 1 | I22: =H22*G22 -> 0 | J22: =E22*D22 -> 0 | K22: =D22*F22 -> 0
B23: Рубленая*****ДУГУШКА запеч в/к Стародв 0,8кг/5кг | C23: 270 | D23: 271 | E23: 15 | F23: 10 | G23: =F23+E23 -> 25 | H23: 1 | I23: =H23*G23 -> 25 | J23: =E23*D23 -> 4065 | K23: =D23*F23 -> 2710
B24: Салями*****Запеч ДУГУШКА Стародвор 0,8кг / 5кг | C24: 265 | D24: 270 | E24: 10 | F24: 5 | G24: =F24+E24 -> 15 | H24: 1 | I24: =H24*G24 -> 15 | J24: =E24*D24 -> 2700 | K24: =D24*F24 -> 1350
B25: Салями*****Мясорубская с рурбл. шпик Старод 0,7 кг | D25: 280 | E25: 10 | F25: 10 | G25: =F25+E25 -> 20 | H25: 1 | I25: =H25*G25 -> 20 | J25: =E25*D25 -> 2800 | K25: =D25*F25 -> 2800
B26: Салями*****ФИЛЕЙБУРГСКАЯ Зер.вес. Стар.0.7кг/4,2кг | C26: 315 | D26: 315 | E26: 10 | F26: 5 | G26: =F26+E26 -> 15 | H26: 1 | I26: =H26*G26 -> 15 | J26: =E26*D26 -> 3150 | K26: =D26*F26 -> 1575
B27: Сардельки*****н/о Говяжьи Стародв 1,3кг /8кг | C27: 210 | D27: 219 | E27: 15 | F27: 15 | G27: =F27+E27 -> 30 | H27: 1 | I27: =H27*G27 -> 30 | J27: =E27*D27 -> 3285 | K27: =D27*F27 -> 3285
B28: Сервелат Зернистый в/к в/у | C28: 275 | D28: 275 | E28: 10 | F28: 10 | G28: =F28+E28 -> 20 | H28: 1 | I28: =H28*G28 -> 20 | J28: =E28*D28 -> 2750 | K28: =D28*F28 -> 2750
B29: Сервелат*****Запеченый Дугушка 0.8кг/5кг | C29: 255 | D29: 266 | E29: 35 | F29: 25 | G29: =F29+E29 -> 60 | H29: 1 | I29: =H29*G29 -> 60 | J29: =E29*D29 -> 9310 | K29: =D29*F29 -> 6650
B30: Сервелат*****МЯСОРУБСКИЙ с мелкоруб. окорок. Стар. | D30: 281 | E30: 15 | F30: 10 | G30: =F30+E30 -> 25 | H30: 1 | I30: =H30*G30 -> 25 | J30: =E30*D30 -> 4215 | K30: =D30*F30 -> 2810
B31: Сосис*****Сливушки Сливоч Вяз. мгу Стар.1,5 /9кг | C31: 260 | D31: 268 | E31: 70 | F31: 50 | G31: =F31+E31 -> 120 | H31: 1 | I31: =H31*G31 -> 120 | J31: =E31*D31 -> 18760 | K31: =D31*F31 -> 13400
B32: Сосиски*****Ганноверские Амилюкс Стародвор 1,3кг | D32: 200 | G32: =F32+E32 -> 0 | H32: 1 | I32: =H32*G32 -> 0 | J32: =E32*D32 -> 0 | K32: =D32*F32 -> 0
B33: Сосиски*****Датские мгу Стародворье 1,3кг / 9кг | C33: 150 | D33: 153 | G33: =F33+E33 -> 0 | H33: 1 | I33: =H33*G33 -> 0 | J33: =E33*D33 -> 0 | K33: =D33*F33 -> 0
B34: Сосиски*****Молочные Вязанка "Молокуши" 1.3кг/8кг | C34: 245 | D34: 254 | F34: 20 | G34: =F34+E34 -> 20 | H34: 1 | I34: =H34*G34 -> 20 | J34: =E34*D34 -> 0 | K34: =D34*F34 -> 5080
B35: Сосиски*****Молочные ДЛЯ ЗАВТРАКА 1.3кг/8кг | D35: 190 | E35: 10 | F35: 10 | G35: =F35+E35 -> 20 | H35: 1 | I35: =H35*G35 -> 20 | J35: =E35*D35 -> 1900 | K35: =D35*F35 -> 1900
B36: Сосиски*****Сливочные по Стародворски 1.3кг/8кг | G36: =F36+E36 -> 0 | H36: 1 | I36: =H36*G36 -> 0 | J36: =E36*D36 -> 0 | K36: =D36*F36 -> 0
B37: Сосиски*****Сочинки Молочные вес Стародворье 1 кг | C37: 210 | D37: 217 | G37: =F37+E37 -> 0 | H37: 1 | I37: =H37*G37 -> 0 | J37: =E37*D37 -> 0 | K37: =D37*F37 -> 0
B38: Сосиски*****Сочинки Сливочные вес Старовдорье 1кг | D38: 220 | G38: =F38+E38 -> 0 | H38: 1 | I38: =H38*G38 -> 0 | J38: =E38*D38 -> 0 | K38: =D38*F38 -> 0
B39: Сочинка*****Зернист с сочн. Грудинкой Стар 0,9/5.2 | D39: 240 | G39: =F39+E39 -> 0 | H39: 1 | I39: =H39*G39 -> 0 | J39: =E39*D39 -> 0 | K39: =D39*F39 -> 0
B40: Сочинка*****по-Европ. с соч грудинк Стар 0,9/5.2кг | C40: 240 | D40: 248 | E40: 40 | F40: 30 | G40: =F40+E40 -> 70 | H40: 1 | I40: =H40*G40 -> 70 | J40: =E40*D40 -> 9920 | K40: =D40*F40 -> 7440
B41: Сочинка*****по-фински с соч. окор. Стар. 0,9/5.2кг | C41: 255 | D41: 260 | E41: 30 | F41: 20 | G41: =F41+E41 -> 50 | H41: 1 | I41: =H41*G41 -> 50 | J41: =E41*D41 -> 7800 | K41: =D41*F41 -> 5200
...

Sheet Лист2

Sheet Лист3
