Workbook

Sheet Лист2
B1: № | C1: Наименование у Бычкова | D1: Наименование 1С ЛП | F1: Код УТ | G1: код завода | H1: ЗАКАЗ | I1: Вес, кг
B2: 1 | C2: Салями Охотничья б/о с/к Стародворские колбасы | D2: Колбаса Салями охотничья, ВЕС. ПОКОМ | E2: 1 | F2: 240 | G2: 1921 | H2: =VLOOKUP(C2,'Рабочий лист_Бычков'!B:J,9,0) -> 0 | I2: =H2*E2 -> 0
B3: 2 | C3: Сосиски БАВАРСКИЕ 0,35кг Стародворье | D3: Сосиски Баварские ТМ Стародворье 0,35 кг ПОКОМ | E3: 0.35 | F3: 412 | G3: 3167 | H3: =VLOOKUP(C3,'Рабочий лист_Бычков'!B:J,9,0) -> 12 | I3: =H3*E3 -> 4.2
B4: 3 | C4: Сосиски Баварские с сыром 0,35кг Стародворские колбасы | D4: Сосиски Баварские с сыром ТМ Стародворье 0,35 кг. ПОКОМ | E4: 0.35 | F4: 410 | G4: 3168 | H4: =VLOOKUP(C4,'Рабочий лист_Бычков'!B:J,9,0) -> 6 | I4: =H4*E4 -> 2.1
B5: 4 | C5: Сосиски Баварские Стародворские колбасы | D5: Сосиски Баварские Бавария Весовые п/а Стародворье | E5: 1 | F5: 251 | G5: 1835 | H5: =VLOOKUP(C5,'Рабочий лист_Бычков'!B:J,9,0) -> 25 | I5: =H5*E5 -> 25
B6: 5 | C6: Балыкбургская с копченым балыком 0,35кг | D6: Колбаса Балыкбурская с копченым балыком, в/у 0,35 кг срез, БАВАРУШКА ПОКОМ | E6: 0.35 | F6: 116 | G6: 2604 | H6: =VLOOKUP(C6,'Рабочий лист_Бычков'!B:J,9,0) -> 0 | I6: =H6*E6 -> 0
B7: 6 | C7: Балыковая в/к фиброуз в/у термо Стародворские колбасы | D7: Колбаса Балыковая НОВАЯ ВЕС Вязанка фиброуз в/у ПОКОМ | E7: 1 | F7: 558 | G7: 4041 | H7: =VLOOKUP(C7,'Рабочий лист_Бычков'!B:J,9,0) -> 0 | I7: =H7*E7 -> 0
B8: 7 | C8: Ветчина Нежная Особая 0,4кг Стародворские колбасы | D8: Ветчина Нежная ТМ Особый рецепт, п/а, 0,4кг ПОКОМ | E8: 0.4 | F8: 43 | G8: 2027 | H8: =VLOOKUP(C8,'Рабочий лист_Бычков'!B:J,9,0) -> 0 | I8: =H8*E8 -> 0
B9: 8 | C9: Ветчина нежная ОСОБАЯ Зареченские колбасы 2.6кг БАТОН | D9: Ветчина Нежная ТМ Особый рецепт, (2,5кг), ПОКОМ, кг | E9: 1 | F9: 201 | G9: 126 | H9: =VLOOKUP(C9,'Рабочий лист_Бычков'!B:J,9,0) -> 300 | I9: =H9*E9 -> 300
B10: 9 | C10: Ветчина Нежная Особая Зареченские колбасы малый батон | D10: Ветчина Нежная ВЕС ТМ Зареченские ПОКОМ | E10: 1 | F10: 510 | G10: 2806 | H10: =VLOOKUP(C10,'Рабочий лист_Бычков'!B:J,9,0) -> 0 | I10: =H10*E10 -> 0
B11: 10 | C11: Ветчина Столичная вязанка 0,45кг Стародворские колбасы | D11: Ветчина Филейская ТМ Вязанка Столичная 0,45 кг ПОКОМ | E11: 0.45 | F11: 324 | G11: 2814 | H11: =VLOOKUP(C11,'Рабочий лист_Бычков'!B:J,9,0) -> 0 | I11: =H11*E11 -> 0
B12: 11 | C12: Ветчина Филейская Столичная Стародворские колбасы | D12: Ветчина Филейская ВЕС ТМ Вязанка ТС Столичная ПОКОМ | E12: 1 | F12: 312 | G12: 2828 | H12: =VLOOKUP(C12,'Рабочий лист_Бычков'!B:J,9,0) -> 50 | I12: =H12*E12 -> 50
B13: 12 | C13: ГОСТ Докторская вязанка МИНИ 0,4кг Стародворские колбасы | D13: Колбаса Докторская ГОСТ, Вязанка вектор, 0,4 кг, ПОКОМ, шт | E13: 0.4 | F13: 23 | G13: 1485 | H13: =VLOOKUP(C13,'Рабочий лист_Бычков'!B:J,9,0) -> 0 | I13: =H13*E13 -> 0
... B79: 78 | C79: Шпикачки Стародворские н/о | D79: Шпикачки Стародворские, ВЕС. ПОКОМ | E79: 1 | F79: 263 | G79: 1430 | H79: =VLOOKUP(C79,'Рабочий лист_Бычков'!B:J,9,0) -> 15 | I79: =H79*E79 -> 15
D80: Сосиски Сочинки по-баварски ТМ Стародворье в оболочке полиамид в мод. газ. среде 0,3 кг ПОКОМ | E80: 0.3 | F80: 561 | G80: 3814 | I80: =H80*E80 -> 0
D81: Ассорти колбас Мясорубская коллекция: Сервелат Делюкс, С балыком 0,08 кг нарезка ПОКОМ | E81: 0.08 | F81: 553 | G81: 4026 | I81: =H81*E81 -> 0
D82: Колбаса Сервелат Мясорубский ТМ Стародворье в упаковке скин 0,08 кг нарезка ПОКОМ | E82: 0.08 | F82: 554 | G82: 3178 | I82: =H82*E82 -> 0
D83: Колбаса Сервелат Ореховый ТМ Вязанка в оболочке фиброуз в вакуумной упаковке, ВЕС ПОКОМ | E83: 1 | F83: 556 | G83: 4044 | I83: =H83*E83 -> 0
D84: Колбаса Сервелат Финский ТМ Вязанка в оболочке фиброуз в вакуумной упаковке, ВЕС ПОКОМ | E84: 1 | F84: 557 | G84: 4047 | I84: =H84*E84 -> 0
D85: Колбаса Сервелат Вяленый ТМ Стародворье в оболочке фиброуз в вакуумной упаковке 0,3 кг ПОКОМ | E85: 0.3 | F85: 559 | G85: 4086 | I85: =H85*E85 -> 0
D86: Колбаса Мясорубская с чесноком ТМ Стародворье в обол. фиброуз в вак. упак. 0,3 кг срез ПОКОМ | E86: 0.3 | F86: 550 | G86: 3997 | I86: =H86*E86 -> 0
D87: Колбаса Молокуша ТМ Вязанка в модифицированной газовой среде 0,17 кг нарезка ПОКОМ | E87: 0.17 | F87: 555 | G87: 2354 | I87: =H87*E87 -> 0
D88: Колбаса Молочная Дугушка ТМ Стародворье ТС Дугушка в оболочке полиамид 0,4 кг ПОКОМ | E88: 0.4 | F88: 538 | G88: 3786 | I88: =H88*E88 -> 0
D89: Колбаса Мясная Классическая ТМ Вязанка в оболочке полиамид. ВЕС ПОКОМ | E89: 1 | F89: 547 | G89: 4028 | I89: =H89*E89 -> 0
D90: Сосиски Классические ТМ Ядрена копоть 0,3кг ПОКОМ | E90: 0.3 | F90: 516 | G90: 3664 | I90: =H90*E90 -> 0
D91: Сосиски С сыром ТМ Ядрена копоть 0,3кг ПОКОМ | E91: 0.3 | F91: 517 | G91: 3665 | I91: =H91*E91 -> 0
... D158: Колбаса Балыкбургская рубленая, в/у 0,35 кг срез, БАВАРУШКА ПОКОМ | E158: 0.35 | F158: 282 | G158: 2545 | I158: =H158*E158 -> 0
B159: 79 | C159: Вязанка Молокуша 0,45кг Стародворские колбасы | D159: Колбаса вареная Молокуша 0,45кг ТМ Вязанка ПОКОМ | E159: 0.45 | F159: 322 | G159: 2816 | H159: =VLOOKUP(C159,'Рабочий лист_Бычков'!B:J,9,0) -> 30 | I159: =H159*E159 -> 13.5
D160: Колбаса вареная Сочинка ТМ Стародворье, 0,45 кг. ПОКОМ | E160: 0.45 | F160: 326 | G160: 2823 | I160: =H160*E160 -> 0
B161: 80 | C161: Дугушка со шпиком | D161: Колбаса Дугушка со шпиком, ВЕС, ТМ Стародворье ПОКОМ | E161: 1 | F161: 225 | G161: 2182 | H161: =VLOOKUP(C161,'Рабочий лист_Бычков'!B:J,9,0) -> 0 | I161: =H161*E161 -> 0
D162: Колбаса Княжеская, белковой обол в термоусад. пакете, ВЕС, ТМ Стародворье | E162: 1 | F162: 226 | G162: 1920 | I162: =H162*E162 -> 0
D163: Колбаса Кракушка пряная с сальцем, 0.3кг в/у п/к, БАВАРУШКА ПОКОМ | E163: 0.3 | F163: 62 | G163: 2252 | I163: =H163*E163 -> 0
D164: Колбаса Салями Мясорубская с рубленным шпиком ВЕС ТМ Стародворье ПОКОМ | E164: 1 | F164: 304 | G164: 2876 | I164: =H164*E164 -> 0
D165: Колбаса Салями Мясорубская с рубленым шпиком 0,35 кг срез ТМ Стародворье Поком | E165: 0.35 | F165: 306 | G165: 2877 | I165: =H165*E165 -> 0
D166: Колбаса Салями Финская, Вязанка фиброуз в/у, ПОКОМ | E166: 1 | F166: 11 | G166: 664 | I166: =H166*E166 -> 0
D167: Колбаса Сервелат Левантский ТМ Особый Рецепт, ВЕС. ПОКОМ | E167: 1 | F167: 271 | G167: 2360 | I167: =H167*E167 -> 0
D168: Колбаса Сервелат Мясорубский с мелкорубленным окороком 0,35 кг срез ТМ Стародворье Поком | E168: 0.35 | F168: 307 | G168: 2848 | I168: =H168*E168 -> 0
D169: Колбаса Сервелат Мясорубский с мелкорубленным окороком в/у ТМ Стародворье ВЕС ПОКОМ | E169: 1 | F169: 305 | G169: 2847 | I169: =H169*E169 -> 0
D170: Колбаса Сервелатная по-стародворски, Фирм. фиброуз в/у ВЕС, ТМ Стародворье | E170: 1 | F170: 245 | G170: 1801 | I170: =H170*E170 -> 0
D171: Колбаса Сливушка ТМ Вязанка в оболочке полиамид 0,45 кг ПОКОМ | E171: 0.45 | F171: 276 | G171: 2734 | I171: =H171*E171 -> 0
...

Sheet Рабочий лист_Бычков
A1: № | B1: Наименование у Бычкова | C1: Резерв 1 | D1: Резерв 2 | E1: Резерв 3 | F1: Резерв 4 | G1: Резерв 5 | H1: Резерв 6 | I1: Резерв 7 | J1: Итого заказ | K1: кооф | L1: ЗАКАЗ, кг
A2: 1 | B2: Салями Охотничья б/о с/к Стародворские колбасы | J2: =SUM(C2:I2) -> 0
A3: 2 | B3: Сосиски БАВАРСКИЕ 0,35кг Стародворье | C3: 12 | J3: =SUM(C3:I3) -> 12 | K3: 0.35 | L3: =K3*J3 -> 4.2
A4: 3 | B4: Сосиски Баварские с сыром 0,35кг Стародворские колбасы | C4: 6 | J4: =SUM(C4:I4) -> 6 | K4: 0.35 | L4: =K4*J4 -> 2.1
A5: 4 | B5: Сосиски Баварские Стародворские колбасы | C5: 25 | J5: =SUM(C5:I5) -> 25 | K5: 1 | L5: =K5*J5 -> 25
A6: 5 | B6: Балыкбургская с копченым балыком 0,35кг | J6: =SUM(C6:I6) -> 0
A7: 6 | B7: Балыковая в/к фиброуз в/у термо Стародворские колбасы | J7: =SUM(C7:I7) -> 0
A8: 7 | B8: Ветчина Нежная Особая 0,4кг Стародворские колбасы | J8: =SUM(C8:I8) -> 0
A9: 8 | B9: Ветчина нежная ОСОБАЯ Зареченские колбасы 2.6кг БАТОН | C9: 300 | J9: =SUM(C9:I9) -> 300 | K9: 1 | L9: =K9*J9 -> 300
A10: 9 | B10: Ветчина Нежная Особая Зареченские колбасы малый батон | J10: =SUM(C10:I10) -> 0
A11: 10 | B11: Ветчина Столичная вязанка 0,45кг Стародворские колбасы | J11: =SUM(C11:I11) -> 0
A12: 11 | B12: Ветчина Филейская Столичная Стародворские колбасы | C12: 50 | J12: =SUM(C12:I12) -> 50 | K12: 1 | L12: =K12*J12 -> 50
A13: 12 | B13: ГОСТ Докторская вязанка МИНИ 0,4кг Стародворские колбасы | J13: =SUM(C13:I13) -> 0
A14: 13 | B14: ГОСТ Докторская вязанка Стародворские колбасы | C14: 30 | J14: =SUM(C14:I14) -> 30 | K14: 1 | L14: =K14*J14 -> 30
A15: 14 | B15: Филейская Вязанка Классическая 0,45кг Стародворские колбасы | C15: 100 | J15: =SUM(C15:I15) -> 100 | K15: 0.45 | L15: =K15*J15 -> 45
A16: 15 | B16: ДУГУШКА Ветчина Стародворские колбасы | C16: 15 | J16: =SUM(C16:I16) -> 15 | K16: 1 | L16: =K16*J16 -> 15
A17: 16 | B17: ДУГУШКА Докторская вар. ГОСТ Стародворские колбасы | C17: 10 | J17: =SUM(C17:I17) -> 10 | K17: 1 | L17: =K17*J17 -> 10
A18: 17 | B18: ДУГУШКА Молочная вар. Стародворские колбасы | C18: 5 | J18: =SUM(C18:I18) -> 5 | K18: 1 | L18: =K18*J18 -> 5
A19: 18 | B19: ДУГУШКА Рубленная п/к. Стародворские колбасы | J19: =SUM(C19:I19) -> 0
A20: 19 | B20: ДУГУШКА Салями запеченная Стародворские колбасы | J20: =SUM(C20:I20) -> 0
A21: 20 | B21: ДУГУШКА Сервелат п/к Стародворские колбасы | C21: 5 | J21: =SUM(C21:I21) -> 5 | K21: 1 | L21: =K21*J21 -> 5
A22: 21 | B22: Дугушка Стародворская вар. ТУ Стародворские колбасы | J22: =SUM(C22:I22) -> 0
A23: 22 | B23: Колбаса вареная Вязанка Филейская Стародворские колбасы | J23: =SUM(C23:I23) -> 0
A24: 23 | B24: Колбаса вареная Мусульманская халяль 0,4 кг (СТМ Вязанка) KZ Стародворские колбасы | C24: 16 | J24: =SUM(C24:I24) -> 16 | K24: 0.4 | L24: =K24*J24 -> 6.4
A25: 24 | B25: Колбаса Вязанка со шпиком вар Стародворские колбасы | J25: =SUM(C25:I25) -> 0
A26: 25 | B26: Колбаса п/к Аль-Ислами халяль вак/уп 0,35 кг (СТМ Вязанка) К | J26: =SUM(C26:I26) -> 0
A27: 26 | B27: Колбаса Стародворская Традиционная п/а 400 г ТМ Стародворье | C27: 50 | J27: =SUM(C27:I27) -> 50 | K27: 0.4 | L27: =K27*J27 -> 20
A28: 27 | B28: Колбаса Стародворская Традиционная ТМ Стародворье | C28: 60 | J28: =SUM(C28:I28) -> 60 | K28: 1 | L28: =K28*J28 -> 60
A29: 28 | B29: Мини Сервелат Кремлевский 0,35 Стародворские колбасы | C29: 18 | J29: =SUM(C29:I29) -> 18 | K29: 0.35 | L29: =K29*J29 -> 6.3
A30: 29 | B30: Молочная по-стародворски вар п/а Стародворские колбасы | J30: =SUM(C30:I30) -> 0
A31: 30 | B31: Молочная по-стародворски вар. 0,4кг Стародворские колбасы | J31: =SUM(C31:I31) -> 0
A32: 31 | B32: Молочная ручная вязка Стародворские колбасы | C32: 20 | J32: =SUM(C32:I32) -> 20 | K32: 1 | L32: =K32*J32 -> 20
A33: 32 | B33: Молочная Традиционная Стародворские колбасы | C33: 30 | J33: =SUM(C33:I33) -> 30 | K33: 1 | L33: =K33*J33 -> 30
A34: 33 | B34: Молочная Традиционная п/а 400г Стародворские колбасы | J34: =SUM(C34:I34) -> 0
A35: 34 | B35: Мясорубская с рубленной грудинкой в/к 0,35кг Стародворские колбасы | J35: =SUM(C35:I35) -> 0
A36: 35 | B36: Мясорубская с рубленной грудинкой в/к Стародворские колбасы | J36: =SUM(C36:I36) -> 0
A37: 36 | B37: Нежная вар. Стародворские колбасы | C37: 60 | J37: =SUM(C37:I37) -> 60 | K37: 1 | L37: =K37*J37 -> 60
A38: 37 | B38: Особая вар сетка Зареченские колбасы | C38: 80 | J38: =SUM(C38:I38) -> 80 | K38: 1 | L38: =K38*J38 -> 80
A39: 38 | B39: ОСОБАЯ вар. 0,5кг Стародворские колбасы | J39: =SUM(C39:I39) -> 0
A40: 39 | B40: Особая Докторская 2,65кг сетка Зареченские колбасы Стародворские колбасы | C40: 100 | J40: =SUM(C40:I40) -> 100 | K40: 1 | L40: =K40*J40 -> 100
...
