Workbook

Sheet Sheet
AB1: -0.65
AB2: дн | AT2: 17200 | AU2: 4013 | AV2: 3380
A3: Номенклатура | B3: Ед. изм. | C3: Начальный остаток | D3: Приход | E3: Расход | F3: Конечный остаток | G3: крат | H3: сроки | I3: метка | J3: метка2 | K3: заяв | L3: разн | M3: без опта | N3: опт | O3: заказ в пути | P3: SU | Q3: заказ в пути | R3: заказ в пути | S3: заказ в пути | T3: заказ в пути | U3: заказ в пути | V3: заказ в пути | W3: заказ в пути | X3: заказ в пути | Y3: заказ в пути | Z3: заказ в пути | AA3: ср нов | AB3: расчет | AC3: заказ | AD3: заказ | AE3: заказ | AF3: ТК | AG3: кон ост | AH3: факт | AI3: ср | AJ3: ср | AK3: ср | AL3: ср | AM3: ср | AN3: ср | AO3: ср | AP3: ср | AQ3: ср | AR3: ср | AS3: комментарии | AT3: вес | AU3: вес | AV3: вес
O4: брак | Q4: 13,07, | R4: 13,07,(2) | S4: 14,07, | T4: 18,07, | U4: 18,07,(дозаказ) | V4: 19,07, | W4: 19,07,(недогруз) | X4: 19,07,(дозаказ) | Y4: 20,07,(дозаказ) | Z4: 20,07,(недогруз) | AA4: 16,07, | AC4: 20,07, | AD4: 21,07, | AE4: 21,07,(2) | AF4: Хмель | AI4: 14,07, | AJ4: 09,07, | AK4: 07,07, | AL4: 02,07, | AM4: 30,06, | AN4: 25,06, | AO4: 23,06, | AP4: 26,05, | AQ4: 02,06, | AR4: 09,06, | AT4: 20,07, | AU4: 21,07, | AV4: 21,07,(2)
E5: =SUM(E6:E496) -> 73628.852 | F5: =SUM(F6:F496) -> 53861.308 | K5: =SUM(K6:K496) -> 80313.207 | L5: =SUM(L6:L496) -> -6684.355 | M5: =SUM(M6:M496) -> 70696.337 | N5: =SUM(N6:N496) -> 2932.515 | O5: =SUM(O6:O496) -> -3500 | Q5: =SUM(Q6:Q496) -> 21569.382 | R5: =SUM(R6:R496) -> 13550 | S5: =SUM(S6:S496) -> 21100 | T5: =SUM(T6:T496) -> 21673.423 | U5: =SUM(U6:U496) -> 4000 | V5: =SUM(V6:V496) -> 15680.571 | W5: =SUM(W6:W496) -> -4381 | X5: =SUM(X6:X496) -> 4000 | ... AE5: =SUM(AE6:AE496) -> 4230 | AI5: =SUM(AI6:AI496) -> 14539.534 | AJ5: =SUM(AJ6:AJ496) -> 14055.493 | AK5: =SUM(AK6:AK496) -> 13132.787 | AL5: =SUM(AL6:AL496) -> 13790.886 | AM5: =SUM(AM6:AM496) -> 14807.387 | AN5: =SUM(AN6:AN496) -> 14449.542 | AO5: =SUM(AO6:AO496) -> 14334.903 | AP5: =SUM(AP6:AP496) -> 12027.39 | ... AR5: =SUM(AR6:AR496) -> 14678.959 | AT5: =SUM(AT6:AT496) -> 15812 | AU5: =SUM(AU6:AU496) -> 4013 | AV5: =SUM(AV6:AV496) -> 3380
A6: 005 Колбаса Докторская ГОСТ, Вязанка вектор,ВЕС. ПОКОМ | B6: кг | C6: 3397.371 | D6: 2919.476 | E6: 2893.803 | F6: 1018.439 | G6: 1 | H6: 50 | I6: P003011 | K6: 3012.177 | L6: =E6-K6 -> -118.374 | M6: =E6-N6 -> 2376.526 | N6: 517.277 | P6: SU000722 | Q6: 426.482 | R6: 400 | S6: 700 | T6: 1462.6172 | V6: 1486.2078 | AA6: =M6/5 -> 475.3052 | AB6: =12.5*AA6-V6-T6-S6-R6-Q6-O6-F6+$AB$1*AA6 -> 138.62063 | AC6: =AB6-AD6-AE6 -> 138.62063 | AG6: =(F6+O6+Q6+R6+S6+T6+U6+V6+W6+X6+Y6+AC6+AD6+AE6)/AA6 -> 11.85 | AH6: =(F6+O6+Q6+R6+S6+T6+U6+V6+W6+X6+Y6)/AA6 -> 11.558354 | AI6: 548.6424 | AJ6: 471.7946 | AK6: 438.9076 | AL6: 507.6376 | AM6: 550.456 | AN6: 574.1258 | AO6: 568.0958 | AP6: 541.7818 | AQ6: 554.7146 | AR6: 479.7918 | AT6: =ROUND(G6*AC6,0) -> 139 | AU6: =ROUND(G6*AD6,0) -> 0 | AV6: =ROUND(G6*AE6,0) -> 0
A7: 016 Сосиски Вязанка Молочные, Вязанка вискофан ВЕС.ПОКОМ | B7: кг | C7: 1119.769 | D7: 1157.342 | E7: 994.919 | F7: 693.67 | G7: 1 | H7: 45 | I7: P003986 | K7: 1035.197 | L7: =E7-K7 -> -40.278 | M7: =E7-N7 -> 994.919 | P7: SU001523 | Q7: 283.05579 | R7: 100 | S7: 300 | T7: 373.7359 | V7: 379.76389 | AA7: =M7/5 -> 198.9838 | AB7: =12.5*AA7-V7-T7-S7-R7-Q7-O7-F7+$AB$1*AA7 -> 227.73245 | AC7: =AB7-AD7-AE7 -> 227.73245 | AG7: =(F7+O7+Q7+R7+S7+T7+U7+V7+W7+X7+Y7+AC7+AD7+AE7)/AA7 -> 11.85 | AH7: =(F7+O7+Q7+R7+S7+T7+U7+V7+W7+X7+Y7)/AA7 -> 10.705523 | AI7: 211.201 | AJ7: 193.3256 | AK7: 182.8198 | AL7: 175.5036 | AM7: 191.0596 | AN7: 216.9326 | AO7: 206.4628 | AP7: 142.0986 | AQ7: 157.1064 | AR7: 162.0754 | AT7: =ROUND(G7*AC7,0) -> 228 | AU7: =ROUND(G7*AD7,0) -> 0 | AV7: =ROUND(G7*AE7,0) -> 0
A8: 017 Сосиски Вязанка Сливочные, Вязанка амицел ВЕС.ПОКОМ | B8: кг | C8: 2421.397 | D8: 4604.904 | E8: 3019.532 | F8: 2021.815 | G8: 1 | H8: 45 | I8: P003988 | K8: 3078.382 | L8: =E8-K8 -> -58.85 | M8: =E8-N8 -> 3019.532 | P8: SU001721 | Q8: 601.12828 | R8: 600 | S8: 800 | T8: 998.37706 | V8: 1014.4799 | AA8: =M8/5 -> 603.9064 | AB8: =12.5*AA8-V8-T8-S8-R8-Q8-O8-F8 -> 1513.0298 | AC8: =AB8-AD8-AE8 -> 1013.0298 | AE8: 500 | AG8: =(F8+O8+Q8+R8+S8+T8+U8+V8+W8+X8+Y8+AC8+AD8+AE8)/AA8 -> 12.5 | AH8: =(F8+O8+Q8+R8+S8+T8+U8+V8+W8+X8+Y8)/AA8 -> 9.9945956 | AI8: 611.2856 | AJ8: 564.6566 | AK8: 559.115 | AL8: 520.8624 | AM8: 595.9394 | AN8: 645.5598 | AO8: 584.8524 | AP8: 581.0992 | AQ8: 595.5908 | AR8: 611.736 | AT8: =ROUND(G8*AC8,0) -> 1013 | AU8: =ROUND(G8*AD8,0) -> 0 | AV8: =ROUND(G8*AE8,0) -> 500
A9: 023 Колбаса Докторская ГОСТ, Вязанка вектор, 0,4 кг, ПОКОМ | B9: шт | C9: 25 | D9: 2 | G9: 0.4 | H9: 50 | I9: P003008 | K9: 5 | L9: =E9-K9 -> -5 | M9: =E9-N9 -> 0 | P9: SU001485 | Q9: 0 | T9: 15 | AA9: =M9/5 -> 0 | AC9: =AB9-AD9-AE9 -> 0 | AG9: =(F9+O9+Q9+R9+S9+T9+U9+V9+W9+X9+Y9+AC9+AD9+AE9)/AA9 -> #DIV/0! | AH9: =(F9+O9+Q9+R9+S9+T9+U9+V9+W9+X9+Y9)/AA9 -> #DIV/0! | AI9: 0.6 | AJ9: 0.6 | AK9: 0 | AL9: 0 | AM9: 0.2 | AN9: 4.2 | AO9: 5.8 | AP9: 4.4 | AQ9: 4.4 | AR9: 2 | AS9: 19 шт списано (12,07,26) | AT9: =ROUND(G9*AC9,0) -> 0 | AU9: =ROUND(G9*AD9,0) -> 0 | AV9: =ROUND(G9*AE9,0) -> 0
A10: 030 Сосиски Вязанка Молочные, Вязанка вискофан МГС, 0.45кг, ПОКОМ | B10: шт | C10: 3252 | D10: 3927 | E10: 3368 | F10: 1112 | G10: 0.45 | H10: 45 | I10: ВНИМАНИЕ / P003985 | K10: 3603 | L10: =E10-K10 -> -235 | M10: =E10-N10 -> 3368 | P10: SU001718 | Q10: 124.0784 | R10: 100 | S10: 150 | T10: 1000 | AA10: =M10/5 -> 673.6 | AB10: 2500 | AC10: =AB10-AD10-AE10 -> 1000 | AD10: 500 | AE10: 1000 | AG10: =(F10+O10+Q10+R10+S10+T10+U10+V10+W10+X10+Y10+AC10+AD10+AE10)/AA10 -> 7.4021354 | AH10: =(F10+O10+Q10+R10+S10+T10+U10+V10+W10+X10+Y10)/AA10 -> 3.690734 | AI10: 380.8 | AJ10: 376.4 | AK10: 381.8 | AL10: 353.6 | AM10: 327.6 | AN10: 392 | AO10: 376.6 | AP10: 460 | AQ10: 328.2 | AR10: 407 | AS10: 1000шт под ЮТЛ (Хмель 15,07,26) | AT10: =ROUND(G10*AC10,0) -> 450 | AU10: =ROUND(G10*AD10,0) -> 225 | AV10: =ROUND(G10*AE10,0) -> 450
A11: 032 Сосиски Вязанка Сливочные, Вязанка амицел МГС, 0.45кг, ПОКОМ | B11: шт | C11: 2791 | D11: 4243 | E11: 3302.3 | F11: 1710 | G11: 0.45 | H11: 45 | I11: P003989 | K11: 3686 | L11: =E11-K11 -> -383.7 | M11: =E11-N11 -> 3302.3 | P11: SU001720 | Q11: 1113.8373 | R11: 1100 | S11: 1700 | T11: 649.09806 | V11: 659.56739 | AA11: =M11/5 -> 660.46 | AB11: =12.5*AA11-V11-T11-S11-R11-Q11-O11-F11 -> 1323.2472 | AC11: =AB11-AD11-AE11 -> 823.2472 | AD11: 500 | AG11: =(F11+O11+Q11+R11+S11+T11+U11+V11+W11+X11+Y11+AC11+AD11+AE11)/AA11 -> 12.5 | AH11: =(F11+O11+Q11+R11+S11+T11+U11+V11+W11+X11+Y11)/AA11 -> 10.496476 | AI11: 717.66 | AJ11: 698.8 | AK11: 602.2 | AL11: 550.4 | AM11: 621.8 | AN11: 638.6 | AO11: 583.8 | AP11: 603.6 | AQ11: 534.2492 | AR11: 630.2 | AT11: =ROUND(G11*AC11,0) -> 370 | AU11: =ROUND(G11*AD11,0) -> 225 | AV11: =ROUND(G11*AE11,0) -> 0
A12: 047 Кол Баварская, белков.обол. в термоусад. пакете 0.17 кг, ТМ Стародворье ПОКОМ | B12: шт | C12: 93 | D12: 102 | E12: 86 | F12: 36 | G12: 0.17 | H12: 180 | I12: P002290 | K12: 97 | L12: =E12-K12 -> -11 | M12: =E12-N12 -> 86 | P12: SU002092 | Q12: 64.2 | T12: 109.8 | AA12: =M12/5 -> 17.2 | AB12: 10 | AC12: =AB12-AD12-AE12 -> 10 | AG12: =(F12+O12+Q12+R12+S12+T12+U12+V12+W12+X12+Y12+AC12+AD12+AE12)/AA12 -> 12.790698 | AH12: =(F12+O12+Q12+R12+S12+T12+U12+V12+W12+X12+Y12)/AA12 -> 12.209302 | AI12: 21 | AJ12: 14.4 | AK12: 13.6 | AL12: 11.2 | AM12: 12.6 | AN12: 17 | AO12: 16.2 | AP12: 14.8 | AQ12: 14.8 | AR12: 35.4 | AT12: =ROUND(G12*AC12,0) -> 2 | AU12: =ROUND(G12*AD12,0) -> 0 | AV12: =ROUND(G12*AE12,0) -> 0
A13: 062 Колбаса Кракушка пряная с сальцем, 0.3кг в/у п/к, БАВАРУШКА ПОКОМ | B13: шт | C13: 54 | D13: 13 | E13: 47 | F13: 6 | G13: 0.3 | H13: 40 | I13: P002461 | K13: 60 | L13: =E13-K13 -> -13 | M13: =E13-N13 -> 47 | P13: SU002252 | Q13: 0 | T13: 84.8 | AA13: =M13/5 -> 9.4 | AB13: =12.5*AA13-V13-T13-S13-R13-Q13-O13-F13 -> 26.7 | AC13: =AB13-AD13-AE13 -> 26.7 | AG13: =(F13+O13+Q13+R13+S13+T13+U13+V13+W13+X13+Y13+AC13+AD13+AE13)/AA13 -> 12.5 | AH13: =(F13+O13+Q13+R13+S13+T13+U13+V13+W13+X13+Y13)/AA13 -> 9.6595745 | AI13: 13.4 | AJ13: 4.4 | AK13: 0.4 | AL13: 5.8 | AM13: 7 | AN13: 1.6 | AO13: -0.4 | AP13: 7 | AQ13: 6.2 | AR13: 7.4 | AT13: =ROUND(G13*AC13,0) -> 8 | AU13: =ROUND(G13*AD13,0) -> 0 | AV13: =ROUND(G13*AE13,0) -> 0
A14: 083 Колбаса Швейцарская 0,17 кг., ШТ., сырокопченая ПОКОМ | B14: шт | C14: 108 | D14: 269 | E14: 147 | F14: 16 | G14: 0.17 | H14: 180 | I14: P001909 | K14: 220 | L14: =E14-K14 -> -73 | M14: =E14-N14 -> 147 | P14: SU001869 | Q14: 220 | R14: 200 | S14: 300 | T14: 55.2 | AA14: =M14/5 -> 29.4 | AC14: =AB14-AD14-AE14 -> 0 | AG14: =(F14+O14+Q14+R14+S14+T14+U14+V14+W14+X14+Y14+AC14+AD14+AE14)/AA14 -> 26.911565 | AH14: =(F14+O14+Q14+R14+S14+T14+U14+V14+W14+X14+Y14)/AA14 -> 26.911565 | AI14: 74.2 | AJ14: 73.8 | AK14: 37.6 | AL14: 35.2 | AM14: 46.2 | AN14: 49.6 | AO14: 43.2 | AP14: 44 | AQ14: 46.6 | AR14: 48.4 | AT14: =ROUND(G14*AC14,0) -> 0 | AU14: =ROUND(G14*AD14,0) -> 0 | AV14: =ROUND(G14*AE14,0) -> 0
A15: 200 Ветчина Дугушка ТМ Стародворье, вектор в/у ПОКОМ | B15: кг | C15: 4219.967 | D15: 5059.901 | E15: 3589.93 | F15: 2650.539 | G15: 1 | H15: 70 | I15: P004460 | K15: 3595.25 | L15: =E15-K15 -> -5.32 | M15: =E15-N15 -> 3589.93 | P15: SU002035 | Q15: 1000.2384 | R15: 750 | S15: 1300 | T15: 650.32179 | V15: 660.81086 | AA15: =M15/5 -> 717.986 | AB15: =12.5*AA15-V15-T15-S15-R15-Q15-O15-F15 -> 1962.9149 | AC15: 800 | AD15: 500 | AE15: 500 | AG15: =(F15+O15+Q15+R15+S15+T15+U15+V15+W15+X15+Y15+AC15+AD15+AE15)/AA15 -> 12.273095 | AH15: =(F15+O15+Q15+R15+S15+T15+U15+V15+W15+X15+Y15)/AA15 -> 9.7660819 | AI15: 729.0608 | AJ15: 733.4764 | AK15: 698.6224 | AL15: 743.1684 | AM15: 777.89 | AN15: 793.4198 | AO15: 813.2912 | AP15: 705.1214 | AQ15: 789.393 | AR15: 802.2968 | AT15: =ROUND(G15*AC15,0) -> 800 | AU15: =ROUND(G15*AD15,0) -> 500 | AV15: =ROUND(G15*AE15,0) -> 500
A16: 201 Ветчина Нежная ТМ Особый рецепт, (2,5кг), ПОКОМ | B16: кг | C16: 5488.771 | D16: 1809.3 | E16: 3254.989 | F16: 2463.767 | G16: 1 | H16: 50 | I16: P002555 | K16: 3410.55 | L16: =E16-K16 -> -155.561 | M16: =E16-N16 -> 3254.989 | P16: SU000126 | Q16: 683.07408 | R16: 600 | S16: 800 | T16: 924.85034 | V16: 939.76729 | W16: -940 | AA16: =M16/5 -> 650.9978 | AB16: =12.5*AA16-V16-T16-S16-R16-Q16-O16-F16 -> 1726.0138 | AC16: =AB16-AD16-AE16 -> 1226.0138 | AD16: 500 | AG16: =(F16+O16+Q16+R16+S16+T16+U16+V16+W16+X16+Y16+AC16+AD16+AE16)/AA16 -> 11.056063 | AH16: =(F16+O16+Q16+R16+S16+T16+U16+V16+W16+X16+Y16)/AA16 -> 8.4047269 | AI16: 665.4226 | AJ16: 618.9746 | AK16: 533.1102 | AL16: 718.056 | AM16: 883.8804 | AN16: 762.7834 | AO16: 722.8462 | AP16: 706.8428 | AQ16: 748.3828 | AR16: 655.8824 | AT16: =ROUND(G16*AC16,0) -> 1226 | AU16: =ROUND(G16*AD16,0) -> 500 | AV16: =ROUND(G16*AE16,0) -> 0
A17: 215 Колбаса Докторская ГОСТ Дугушка, ВЕС, ТМ Стародворье ПОКОМ | B17: кг | C17: 602.357 | D17: 301.172 | E17: 263.431 | F17: 626.406 | G17: 1 | H17: 60 | I17: P004028 | K17: 269.65 | L17: =E17-K17 -> -6.219 | M17: =E17-N17 -> 263.431 | P17: SU002011 | Q17: 0 | T17: 0 | AA17: =M17/5 -> 52.6862 | AB17: =12.5*AA17-V17-T17-S17-R17-Q17-O17-F17 -> 32.1715 | AC17: =AB17-AD17-AE17 -> 32.1715 | AG17: =(F17+O17+Q17+R17+S17+T17+U17+V17+W17+X17+Y17+AC17+AD17+AE17)/AA17 -> 12.5 | AH17: =(F17+O17+Q17+R17+S17+T17+U17+V17+W17+X17+Y17)/AA17 -> 11.889375 | AI17: 53.1126 | AJ17: 49.3644 | AK17: 53.1448 | AL17: 67.8956 | AM17: 65.3426 | AN17: 56.4814 | AO17: 55.7172 | AP17: 68.611 | AQ17: 50.9578 | AR17: 50.5012 | AT17: =ROUND(G17*AC17,0) -> 32 | AU17: =ROUND(G17*AD17,0) -> 0 | AV17: =ROUND(G17*AE17,0) -> 0
A18: 226 Колбаса Княжеская, с/к белков.обол в термоусад. пакете, ВЕС, ТМ Стародворье ПОКОМ | B18: кг | C18: 14.237 | D18: 1.429 | E18: 5.267 | F18: 8.614 | G18: 1 | H18: 180 | I18: P001900 | K18: 6.18 | L18: =E18-K18 -> -0.913 | M18: =E18-N18 -> 5.267 | P18: SU001920 | Q18: 0 | T18: 4 | AA18: =M18/5 -> 1.0534 | AB18: 4 | AC18: =AB18-AD18-AE18 -> 4 | AG18: =(F18+O18+Q18+R18+S18+T18+U18+V18+W18+X18+Y18+AC18+AD18+AE18)/AA18 -> 15.771787 | AH18: =(F18+O18+Q18+R18+S18+T18+U18+V18+W18+X18+Y18)/AA18 -> 11.974559 | AI18: 1.054 | AJ18: 0.2838 | AK18: 0.07 | AL18: 0.4956 | AM18: 0.9974 | AN18: 1.117 | AO18: 0.6164 | AP18: 1.0632 | AQ18: 0.1398 | AR18: 0.5024 | AT18: =ROUND(G18*AC18,0) -> 4 | AU18: =ROUND(G18*AD18,0) -> 0 | AV18: =ROUND(G18*AE18,0) -> 0
A19: 229 Колбаса Молочная Дугушка, в/у, ВЕС, ТМ Стародворье ПОКОМ | B19: кг | C19: 5123.708 | D19: 4940.061 | E19: 4486.358 | F19: 3840.338 | G19: 1 | H19: 60 | I19: P004030 | K19: 4602.132 | L19: =E19-K19 -> -115.774 | M19: =E19-N19 -> 4385.126 | N19: 101.232 | P19: SU002010 | Q19: 1163.2069 | R19: 1000 | S19: 1500 | T19: 493.59248 | V19: 501.55365 | AA19: =M19/5 -> 877.0252 | AB19: =12.5*AA19-V19-T19-S19-R19-Q19-O19-F19 -> 2464.124 | AC19: =AB19-AD19-AE19 -> 1064.124 | AD19: 900 | AE19: 500 | AG19: =(F19+O19+Q19+R19+S19+T19+U19+V19+W19+X19+Y19+AC19+AD19+AE19)/AA19 -> 12.5 | AH19: =(F19+O19+Q19+R19+S19+T19+U19+V19+W19+X19+Y19)/AA19 -> 9.6903612 | AI19: 881.8386 | AJ19: 955.7506 | AK19: 939.1438 | AL19: 972.136 | AM19: 972.0944 | AN19: 939.8734 | AO19: 926.6484 | AP19: 875.1544 | AQ19: 870.9684 | AR19: 923.9608 | AT19: =ROUND(G19*AC19,0) -> 1064 | AU19: =ROUND(G19*AD19,0) -> 900 | AV19: =ROUND(G19*AE19,0) -> 500
A20: 230 Колбаса Молочная Особая ТМ Особый рецепт, п/а, ВЕС. ПОКОМ | B20: кг | D20: 4.995 | E20: 4.995 | G20: 0 | I20: дубль | J20: 457 Колбаса Молочная ТМ Особый рецепт ВЕС большой батон ПОКОМ | K20: 5 | L20: =E20-K20 -> -0.005 | M20: =E20-N20 -> 4.995 | P20: SU003422 | T20: 0 | AA20: =M20/5 -> 0.999 | AC20: =AB20-AD20-AE20 -> 0 | AG20: =(F20+O20+Q20+R20+S20+T20+U20+V20+W20+X20+Y20+AC20+AD20+AE20)/AA20 -> 0 | AH20: =(F20+O20+Q20+R20+S20+T20+U20+V20+W20+X20+Y20)/AA20 -> 0 | AI20: 0.999 | AJ20: 0 | AK20: 0 | AL20: 0 | AM20: 0 | AN20: 0 | AO20: 0 | AP20: 0 | AQ20: 0 | AR20: 0 | AT20: =ROUND(G20*AC20,0) -> 0 | AU20: =ROUND(G20*AD20,0) -> 0 | AV20: =ROUND(G20*AE20,0) -> 0
A21: 236 Колбаса Рубленая ЗАПЕЧ. Дугушка ТМ Стародворье, вектор, в/к ПОКОМ | B21: кг | C21: 577.778 | D21: 602.892 | E21: 438.835 | F21: 623.558 | G21: 1 | H21: 70 | I21: P004465 | K21: 457 | L21: =E21-K21 -> -18.165 | M21: =E21-N21 -> 438.835 | P21: SU002150 | Q21: 191.7284 | R21: 100 | S21: 200 | T21: 0 | AA21: =M21/5 -> 87.767 | AC21: =AB21-AD21-AE21 -> 0 | AG21: =(F21+O21+Q21+R21+S21+T21+U21+V21+W21+X21+Y21+AC21+AD21+AE21)/AA21 -> 12.707355 | AH21: =(F21+O21+Q21+R21+S21+T21+U21+V21+W21+X21+Y21)/AA21 -> 12.707355 | AI21: 81.9844 | AJ21: 105.7922 | AK21: 91.559 | AL21: 105.0118 | AM21: 101.4824 | AN21: 87.5822 | AO21: 89.2918 | AP21: 91.8488 | AQ21: 109.9436 | AR21: 85.9548 | AT21: =ROUND(G21*AC21,0) -> 0 | AU21: =ROUND(G21*AD21,0) -> 0 | AV21: =ROUND(G21*AE21,0) -> 0
A22: 239 Колбаса Салями запеч Дугушка, оболочка вектор, ВЕС, ТМ Стародворье ПОКОМ | B22: кг | C22: 2077.687 | D22: 1374.257 | E22: 1179.755 | F22: 1298.438 | G22: 1 | H22: 70 | I22: P004466 | K22: 1195.877 | L22: =E22-K22 -> -16.122 | M22: =E22-N22 -> 1179.755 | P22: SU002158 | Q22: 189.44697 | S22: 100 | T22: 259.85551 | V22: 264.04672 | AA22: =M22/5 -> 235.951 | AB22: =12.5*AA22-V22-T22-S22-R22-Q22-O22-F22 -> 837.6003 | AC22: =AB22-AD22-AE22 -> 437.6003 | AD22: 400 | AG22: =(F22+O22+Q22+R22+S22+T22+U22+V22+W22+X22+Y22+AC22+AD22+AE22)/AA22 -> 12.5 | AH22: =(F22+O22+Q22+R22+S22+T22+U22+V22+W22+X22+Y22)/AA22 -> 8.9501091 | AI22: 225.54 | AJ22: 220.3834 | AK22: 213.5002 | AL22: 289.4184 | AM22: 307.0924 | AN22: 271.9586 | AO22: 269.6736 | AP22: 231.0852 | AQ22: 233.071 | AR22: 257.7124 | AT22: =ROUND(G22*AC22,0) -> 438 | AU22: =ROUND(G22*AD22,0) -> 400 | AV22: =ROUND(G22*AE22,0) -> 0
A23: 242 Колбаса Сервелат ЗАПЕЧ.Дугушка ТМ Стародворье, вектор, в/к ПОКОМ | B23: кг | C23: 2139.249 | D23: 2797.232 | E23: 2145.882 | F23: 1423.508 | G23: 1 | H23: 70 | I23: P004470 | K23: 2130.2 | L23: =E23-K23 -> 15.682 | M23: =E23-N23 -> 2145.882 | P23: SU002151 | Q23: 528.78577 | R23: 500 | S23: 700 | T23: 434.92934 | V23: 441.94433 | AA23: =M23/5 -> 429.1764 | AB23: =12.5*AA23-V23-T23-S23-R23-Q23-O23-F23 -> 1335.5376 | AC23: =AB23-AD23-AE23 -> 705.53755 | AD23: 400 | AE23: 230 | AG23: =(F23+O23+Q23+R23+S23+T23+U23+V23+W23+X23+Y23+AC23+AD23+AE23)/AA23 -> 12.5 | AH23: =(F23+O23+Q23+R23+S23+T23+U23+V23+W23+X23+Y23)/AA23 -> 9.3881384 | AI23: 423.8756 | AJ23: 418.3464 | AK23: 400.0342 | AL23: 384.5324 | AM23: 404.6702 | AN23: 469.1594 | AO23: 501.861 | AP23: 425.3232 | AQ23: 412.9102 | AR23: 446.0642 | AT23: =ROUND(G23*AC23,0) -> 706 | AU23: =ROUND(G23*AD23,0) -> 400 | AV23: =ROUND(G23*AE23,0) -> 230
A24: 244 Колбаса Сервелат Кремлевский, ВЕС. ПОКОМ | B24: кг | C24: 49.999 | D24: 54.85 | E24: 37.012 | F24: 65.657 | G24: 1 | H24: 40 | I24: P003013 | K24: 39.2 | L24: =E24-K24 -> -2.188 | M24: =E24-N24 -> 37.012 | P24: SU001822 | Q24: 34.3356 | T24: 0 | AA24: =M24/5 -> 7.4024 | AC24: =AB24-AD24-AE24 -> 0 | AG24: =(F24+O24+Q24+R24+S24+T24+U24+V24+W24+X24+Y24+AC24+AD24+AE24)/AA24 -> 13.508132 | AH24: =(F24+O24+Q24+R24+S24+T24+U24+V24+W24+X24+Y24)/AA24 -> 13.508132 | AI24: 6.248 | AJ24: 11.03 | AK24: 9.5734 | AL24: 1.4524 | AM24: 1.8864 | AN24: 3.0478 | AO24: 2.6138 | AP24: 0.5814 | AQ24: 9.3972 | AR24: 6.6224 | AT24: =ROUND(G24*AC24,0) -> 0 | AU24: =ROUND(G24*AD24,0) -> 0 | AV24: =ROUND(G24*AE24,0) -> 0
A25: 250 Сардельки стародворские с говядиной в обол. NDX, ВЕС. ПОКОМ | B25: кг | C25: 3503.937 | D25: 2690.878 | E25: 1724.585 | F25: 4105.979 | G25: 1 | H25: 30 | I25: P002536 | K25: 2331.508 | L25: =E25-K25 -> -606.923 | M25: =E25-N25 -> 1724.585 | O25: -3500 | P25: SU000227 | Q25: 742.46054 | R25: 600 | S25: 900 | T25: 700 | V25: 700 | W25: -700 | Z25: =VLOOKUP(P25,[1]Лист1!$A:$E,5,0) -> -405.6 | AA25: =M25/5 -> 344.917 | AB25: 700 | AC25: =AB25-AD25-AE25 -> 400 | AD25: 300 | AG25: =(F25+O25+Q25+R25+S25+T25+U25+V25+W25+X25+Y25+AC25+AD25+AE25)/AA25 -> 12.317281 | AH25: =(F25+O25+Q25+R25+S25+T25+U25+V25+W25+X25+Y25)/AA25 -> 10.287807 | AI25: 256.0514 | AJ25: 349.7722 | AK25: 272.0672 | AL25: 228.8976 | AM25: 443.475 | AN25: 527.5074 | AO25: 438.756 | AP25: 67.3324 | AQ25: -3.8862 | AR25: 293.1708 | AS25: 2000кг плюсом (Рекуто 15,07,26) / 3500кг БРАК!!! | AT25: =ROUND(G25*AC25,0) -> 400 | AU25: =ROUND(G25*AD25,0) -> 300 | AV25: =ROUND(G25*AE25,0) -> 0
A26: 253 Сосиски Ганноверские ПОКОМ | B26: кг | C26: 42.805 | D26: 88.842 | E26: 44.279 | F26: 87.368 | G26: 1 | H26: 40 | I26: P002209 | K26: 61.9 | L26: =E26-K26 -> -17.621 | M26: =E26-N26 -> 44.279 | P26: SU001340 | Q26: 37.695 | T26: 0 | AA26: =M26/5 -> 8.8558 | AC26: =AB26-AD26-AE26 -> 0 | AG26: =(F26+O26+Q26+R26+S26+T26+U26+V26+W26+X26+Y26+AC26+AD26+AE26)/AA26 -> 14.122157 | AH26: =(F26+O26+Q26+R26+S26+T26+U26+V26+W26+X26+Y26)/AA26 -> 14.122157 | AI26: 9.4266 | AJ26: 13.422 | AK26: 12.8826 | AL26: 1.8428 | AM26: 1.2908 | AN26: 8.7688 | AO26: 8.7688 | AP26: 0.8072 | AQ26: 9.4638 | AR26: 4.793 | AT26: =ROUND(G26*AC26,0) -> 0 | AU26: =ROUND(G26*AD26,0) -> 0 | AV26: =ROUND(G26*AE26,0) -> 0
A27: 255 Сосиски Молочные для завтрака ТМ Особый рецепт, п/а МГС, ВЕС, ТМ Стародворье ПОКОМ | B27: кг | C27: 9816.232 | D27: 6885.539 | E27: 8319.279 | F27: 1565.151 | G27: 1 | H27: 40 | I27: P004844 | K27: 8323.194 | L27: =E27-K27 -> -3.915 | M27: =E27-N27 -> 6869.391 | N27: 1449.888 | P27: SU002074 | Q27: 2556.3827 | R27: 2500 | S27: 4000 | T27: 2697.2418 | V27: 2740.7457 | W27: -2741 | Z27: =VLOOKUP(P27,[1]Лист1!$A:$E,5,0) -> -621 | AA27: =M27/5 -> 1373.8782 | AB27: =12.5*AA27-V27-T27-S27-R27-Q27-O27-F27 -> 1113.9562 | AC27: =AB27-AD27-AE27 -> 613.95625 | AD27: 500 | AG27: =(F27+O27+Q27+R27+S27+T27+U27+V27+W27+X27+Y27+AC27+AD27+AE27)/AA27 -> 10.504918 | AH27: =(F27+O27+Q27+R27+S27+T27+U27+V27+W27+X27+Y27)/AA27 -> 9.6941063 | AI27: 1608.1394 | AJ27: 1503.0754 | AK27: 1112.3946 | AL27: 1252.3152 | AM27: 1806.3748 | AN27: 1535.5788 | AO27: 1474.7154 | AP27: 0 | AQ27: 1578.2022 | AR27: 1492.6122 | AT27: =ROUND(G27*AC27,0) -> 614 | AU27: =ROUND(G27*AD27,0) -> 500 | AV27: =ROUND(G27*AE27,0) -> 0
A28: 273 Сосиски Сочинки с сочной грудинкой, МГС 0.4кг, ПОКОМ | B28: шт | C28: 3878 | D28: 6198 | E28: 4080 | F28: 2693 | G28: 0.4 | H28: 45 | I28: P003957 | K28: 4412 | L28: =E28-K28 -> -332 | M28: =E28-N28 -> 4080 | P28: SU002618 | Q28: 1434.6087 | R28: 1000 | S28: 1700 | T28: 1015.897 | V28: 1032.2824 | AA28: =M28/5 -> 816 | AB28: =12.5*AA28-V28-T28-S28-R28-Q28-O28-F28 -> 1324.212 | AC28: =AB28-AD28-AE28 -> 824.212 | AE28: 500 | AG28: =(F28+O28+Q28+R28+S28+T28+U28+V28+W28+X28+Y28+AC28+AD28+AE28)/AA28 -> 12.5 | AH28: =(F28+O28+Q28+R28+S28+T28+U28+V28+W28+X28+Y28)/AA28 -> 10.877191 | AI28: 898.6 | AJ28: 865 | AK28: 794.6 | AL28: 770.4 | AM28: 777.8 | AN28: 836.4 | AO28: 934.6 | AP28: 824.4 | AQ28: 789 | AR28: 1397.2 | AT28: =ROUND(G28*AC28,0) -> 330 | AU28: =ROUND(G28*AD28,0) -> 0 | AV28: =ROUND(G28*AE28,0) -> 200
A29: 276 Колбаса Сливушка ТМ Вязанка в оболочке полиамид 0,45 кг ПОКОМ | B29: шт | C29: 49 | D29: 2673 | E29: 548 | F29: 204.75 | G29: 0.45 | H29: 50 | I29: ВНИМАНИЕ / P003103 | K29: 794 | L29: =E29-K29 -> -246 | M29: =E29-N29 -> 548 | P29: SU002734 | Q29: 839.0568 | R29: 800 | S29: 1100 | T29: 0 | AA29: =M29/5 -> 109.6 | AC29: =AB29-AD29-AE29 -> 0 | AG29: =(F29+O29+Q29+R29+S29+T29+U29+V29+W29+X29+Y29+AC29+AD29+AE29)/AA29 -> 26.859551 | AH29: =(F29+O29+Q29+R29+S29+T29+U29+V29+W29+X29+Y29)/AA29 -> 26.859551 | AI29: 174.8 | AJ29: 277.8 | AK29: 284.8 | AL29: 208.4 | AM29: 87.4 | AN29: 111.2 | AO29: 94.2 | AP29: 166 | AQ29: 120.8 | AR29: 153.6 | AS29: нужно увеличить продажи / 710шт под клиента отгрузили 02,07,26 | AT29: =ROUND(G29*AC29,0) -> 0 | AU29: =ROUND(G29*AD29,0) -> 0 | AV29: =ROUND(G29*AE29,0) -> 0
A30: 278 Сосиски Сочинки с сочным окороком, МГС 0.4кг, ПОКОМ | B30: шт | C30: 1095 | D30: 1838 | E30: 1021 | F30: 218 | G30: 0.4 | H30: 45 | I30: P003958 | K30: 1221 | L30: =E30-K30 -> -200 | M30: =E30-N30 -> 1021 | P30: SU002621 | Q30: 457.32849 | R30: 400 | S30: 600 | T30: 286.8306 | V30: 291.4569 | AA30: =M30/5 -> 204.2 | AB30: =12.5*AA30-V30-T30-S30-R30-Q30-O30-F30+$AB$1*AA30 -> 166.154 | AC30: =AB30-AD30-AE30 -> 166.154 | AG30: =(F30+O30+Q30+R30+S30+T30+U30+V30+W30+X30+Y30+AC30+AD30+AE30)/AA30 -> 11.85 | AH30: =(F30+O30+Q30+R30+S30+T30+U30+V30+W30+X30+Y30)/AA30 -> 11.036317 | AI30: 235.2 | AJ30: 211 | AK30: 165 | AL30: 174 | AM30: 215.2 | AN30: 201.2 | AO30: 198.2 | AP30: 204.4 | AQ30: 183.2 | AR30: 200.6 | AT30: =ROUND(G30*AC30,0) -> 66 | AU30: =ROUND(G30*AD30,0) -> 0 | AV30: =ROUND(G30*AE30,0) -> 0
A31: 281 Сосиски Молочные для завтрака ТМ Особый рецепт, 0,4кг ПОКОМ | B31: шт | C31: 373 | D31: 2006 | E31: 587 | F31: 874 | G31: 0.4 | H31: 40 | I31: P005198 | K31: 660 | L31: =E31-K31 -> -73 | M31: =E31-N31 -> 587 | P31: SU002205 | Q31: 0 | T31: 0 | Z31: =VLOOKUP(P31,[1]Лист1!$A:$E,5,0) -> -208.8 | AA31: =M31/5 -> 117.4 | AB31: =12.5*AA31-V31-T31-S31-R31-Q31-O31-F31+$AB$1*AA31 -> 517.19 | AC31: =AB31-AD31-AE31 -> 517.19 | AG31: =(F31+O31+Q31+R31+S31+T31+U31+V31+W31+X31+Y31+AC31+AD31+AE31)/AA31 -> 11.85 | AH31: =(F31+O31+Q31+R31+S31+T31+U31+V31+W31+X31+Y31)/AA31 -> 7.4446337 | AI31: 80.4 | AJ31: 83.2 | AK31: 136 | AL31: 101.6 | AM31: 63.2 | AN31: 73.2 | AO31: 81.8 | AP31: 99.389 | AQ31: 77.164 | AR31: 80.4 | AT31: =ROUND(G31*AC31,0) -> 207 | AU31: =ROUND(G31*AD31,0) -> 0 | AV31: =ROUND(G31*AE31,0) -> 0
A32: 285 Паштет печеночный со слив.маслом ТМ Стародворье ламистер 0,1 кг ПОКОМ | B32: шт | C32: 378 | D32: 14 | E32: 230 | F32: 151 | G32: 0.1 | H32: 731 | I32: P002648 | K32: 243 | L32: =E32-K32 -> -13 | M32: =E32-N32 -> 230 | P32: SU002368 | Q32: 174 | T32: 14 | AA32: =M32/5 -> 46 | AB32: =12.5*AA32-V32-T32-S32-R32-Q32-O32-F32 -> 236 | AC32: =AB32-AD32-AE32 -> 236 | AG32: =(F32+O32+Q32+R32+S32+T32+U32+V32+W32+X32+Y32+AC32+AD32+AE32)/AA32 -> 12.5 | AH32: =(F32+O32+Q32+R32+S32+T32+U32+V32+W32+X32+Y32)/AA32 -> 7.3695652 | AI32: 42 | AJ32: 46 | AK32: 39 | AL32: 48.2 | AM32: 46.8 | AN32: 41.2 | AO32: 42.4 | AP32: 33.2 | AQ32: 46.8 | AR32: 35.6 | AT32: =ROUND(G32*AC32,0) -> 24 | AU32: =ROUND(G32*AD32,0) -> 0 | AV32: =ROUND(G32*AE32,0) -> 0
A33: 296 Колбаса Мясорубская с рубленой грудинкой 0,35кг срез ТМ Стародворье ПОКОМ | B33: шт | C33: 97 | D33: 109 | E33: 65 | F33: 5 | G33: 0.35 | H33: 40 | I33: P003256 | K33: 111 | L33: =E33-K33 -> -46 | M33: =E33-N33 -> 65 | P33: SU002660 | Q33: 185.4 | T33: 118 | AA33: =M33/5 -> 13 | AC33: =AB33-AD33-AE33 -> 0 | AG33: =(F33+O33+Q33+R33+S33+T33+U33+V33+W33+X33+Y33+AC33+AD33+AE33)/AA33 -> 23.723077 | AH33: =(F33+O33+Q33+R33+S33+T33+U33+V33+W33+X33+Y33)/AA33 -> 23.723077 | AI33: 28.4 | AJ33: 24.2 | AK33: 16.4 | AL33: 18.4 | AM33: 15.6 | AN33: 17.2 | AO33: 15 | AP33: 18 | AQ33: 26 | AR33: 14.8 | AT33: =ROUND(G33*AC33,0) -> 0 | AU33: =ROUND(G33*AD33,0) -> 0 | AV33: =ROUND(G33*AE33,0) -> 0
A34: 297 Колбаса Мясорубская с рубленой грудинкой ВЕС ТМ Стародворье ПОКОМ | B34: кг | C34: 21.553 | D34: 5.793 | E34: 7.198 | F34: 19.129 | G34: 1 | H34: 40 | I34: P003179 | K34: 7.6 | L34: =E34-K34 -> -0.402 | M34: =E34-N34 -> 7.198 | P34: SU002756 | Q34: 16.9262 | T34: 0 | AA34: =M34/5 -> 1.4396 | AC34: =AB34-AD34-AE34 -> 0 | AG34: =(F34+O34+Q34+R34+S34+T34+U34+V34+W34+X34+Y34+AC34+AD34+AE34)/AA34 -> 25.04529 | AH34: =(F34+O34+Q34+R34+S34+T34+U34+V34+W34+X34+Y34)/AA34 -> 25.04529 | AI34: 2.4448 | AJ34: 3.2066 | AK34: 2.0582 | AL34: 2.5328 | AM34: 3.35 | AN34: 4.3372 | AO34: 4.6544 | AP34: 4.8608 | AQ34: 7.405 | AR34: 4.3842 | AS34: нужно увеличить продажи | AT34: =ROUND(G34*AC34,0) -> 0 | AU34: =ROUND(G34*AD34,0) -> 0 | AV34: =ROUND(G34*AE34,0) -> 0
A35: 301 Сосиски Сочинки по-баварски с сыром, 0.4кг, ТМ Стародворье ПОКОМ | B35: шт | C35: -2 | D35: 220 | E35: -5 | F35: -1 | G35: 0.4 | H35: 40 | I35: P003475 | K35: 285 | L35: =E35-K35 -> -290 | M35: =E35-N35 -> -5 | P35: SU002801 | Q35: 0 | T35: 300 | Z35: =VLOOKUP(P35,[1]Лист1!$A:$E,5,0) -> -81.6 | AA35: =M35/5 -> -1 | AB35: 200 | AC35: =AB35-AD35-AE35 -> 200 | AG35: =(F35+O35+Q35+R35+S35+T35+U35+V35+W35+X35+Y35+AC35+AD35+AE35)/AA35 -> -499 | AH35: =(F35+O35+Q35+R35+S35+T35+U35+V35+W35+X35+Y35)/AA35 -> -299 | AI35: -1 | AJ35: 12 | AK35: 65.4 | AL35: 80.2 | AM35: 44.4 | AN35: 31.2 | AO35: 40.4 | AP35: 42.6 | AQ35: 61.4 | AR35: 48 | AT35: =ROUND(G35*AC35,0) -> 80 | AU35: =ROUND(G35*AD35,0) -> 0 | AV35: =ROUND(G35*AE35,0) -> 0
A36: 302 Сосиски Сочинки по-баварски, 0.4кг, ТМ Стародворье ПОКОМ | B36: шт | C36: 253 | D36: 156 | E36: 261 | F36: 67 | G36: 0.4 | H36: 45 | I36: P003217 | K36: 287 | L36: =E36-K36 -> -26 | M36: =E36-N36 -> 261 | P36: SU002799 | Q36: 102.8 | R36: 100 | S36: 150 | T36: 0 | Z36: =VLOOKUP(P36,[1]Лист1!$A:$E,5,0) -> -93.6 | AA36: =M36/5 -> 52.2 | AB36: =12.5*AA36-V36-T36-S36-R36-Q36-O36-F36 -> 232.7 | AC36: =AB36-AD36-AE36 -> 232.7 | AG36: =(F36+O36+Q36+R36+S36+T36+U36+V36+W36+X36+Y36+AC36+AD36+AE36)/AA36 -> 12.5 | AH36: =(F36+O36+Q36+R36+S36+T36+U36+V36+W36+X36+Y36)/AA36 -> 8.0421456 | AI36: 48.4 | AJ36: 56.4 | AK36: 42 | AL36: 27.6 | AM36: 34.8 | AN36: 54.8 | AO36: 53.6 | AP36: 29.8 | AQ36: 41.8 | AR36: 40.2 | AT36: =ROUND(G36*AC36,0) -> 93 | AU36: =ROUND(G36*AD36,0) -> 0 | AV36: =ROUND(G36*AE36,0) -> 0
A37: 305 Колбаса Сервелат Мясорубский с мелкорубленным окороком в/у ТМ Стародворье ВЕС ПОКОМ | B37: кг | C37: 50.008 | D37: 45.617 | E37: 26.135 | F37: 33.619 | G37: 1 | H37: 40 | I37: P003259 | K37: 34.823 | L37: =E37-K37 -> -8.688 | M37: =E37-N37 -> 26.135 | P37: SU002847 | Q37: 0 | T37: 18.179 | AA37: =M37/5 -> 5.227 | AB37: =12.5*AA37-V37-T37-S37-R37-Q37-O37-F37 -> 13.5395 | AC37: =AB37-AD37-AE37 -> 13.5395 | AG37: =(F37+O37+Q37+R37+S37+T37+U37+V37+W37+X37+Y37+AC37+AD37+AE37)/AA37 -> 12.5 | AH37: =(F37+O37+Q37+R37+S37+T37+U37+V37+W37+X37+Y37)/AA37 -> 9.9096996 | AI37: 5.501 | AJ37: 4.4914 | AK37: 6.1064 | AL37: 6.388 | AM37: 3.4708 | AN37: 4.7606 | AO37: 6.7906 | AP37: 12.0244 | AQ37: 9.3468 | AR37: 10.9548 | AT37: =ROUND(G37*AC37,0) -> 14 | AU37: =ROUND(G37*AD37,0) -> 0 | AV37: =ROUND(G37*AE37,0) -> 0
A38: 307 Колбаса Сервелат Мясорубский с мелкорубленным окороком 0,35 кг срез ТМ Стародворье Поком | B38: шт | C38: 1154 | D38: 2979 | E38: 550 | F38: 613 | G38: 0.35 | H38: 40 | I38: ВНИМАНИЕ / P003260 | K38: 815 | L38: =E38-K38 -> -265 | M38: =E38-N38 -> 550 | P38: SU002848 | Q38: 0 | T38: 200 | AA38: =M38/5 -> 110 | AB38: =12.5*AA38-V38-T38-S38-R38-Q38-O38-F38+$AB$1*AA38 -> 490.5 | AC38: =AB38-AD38-AE38 -> 490.5 | AF38: 200 | AG38: =(F38+O38+Q38+R38+S38+T38+U38+V38+W38+X38+Y38+AC38+AD38+AE38)/AA38 -> 11.85 | AH38: =(F38+O38+Q38+R38+S38+T38+U38+V38+W38+X38+Y38)/AA38 -> 7.3909091 | AI38: 269.2 | AJ38: 266.4 | AK38: 466.2 | AL38: 465.2 | AM38: 121.2 | AN38: 128.6 | AO38: 118 | AP38: 217.4 | AQ38: 150.2 | AR38: 101.4 | AS38: 17,07,26 уменьшить до 200 шт (Хмель) / 15,07,26 уменьшить до 200 шт (Хмель) | AT38: =ROUND(G38*AC38,0) -> 172 | AU38: =ROUND(G38*AD38,0) -> 0 | AV38: =ROUND(G38*AE38,0) -> 0
A39: 309 Сосиски Сочинки с сыром 0,4 кг ТМ Стародворье ПОКОМ | B39: шт | C39: 266 | D39: 814 | E39: 380 | F39: 197 | G39: 0.4 | H39: 40 | I39: P004178 | K39: 551 | L39: =E39-K39 -> -171 | M39: =E39-N39 -> 380 | P39: SU002686 | Q39: 0 | T39: 251.6 | AA39: =M39/5 -> 76 | AB39: =12.5*AA39-V39-T39-S39-R39-Q39-O39-F39 -> 501.4 | AC39: =AB39-AD39-AE39 -> 501.4 | AG39: =(F39+O39+Q39+R39+S39+T39+U39+V39+W39+X39+Y39+AC39+AD39+AE39)/AA39 -> 12.5 | AH39: =(F39+O39+Q39+R39+S39+T39+U39+V39+W39+X39+Y39)/AA39 -> 5.9026316 | AI39: 54.6 | AJ39: 57.4 | AK39: 95.4 | AL39: 87.2 | AM39: 75.6 | AN39: 88.2 | AO39: 91.4 | AP39: 81.6 | AQ39: 86.4 | AR39: 80.2 | AT39: =ROUND(G39*AC39,0) -> 201 | AU39: =ROUND(G39*AD39,0) -> 0 | AV39: =ROUND(G39*AE39,0) -> 0
A40: 312 Ветчина Филейская ВЕС ТМ Вязанка ТС Столичная ПОКОМ | B40: кг | C40: 115.857 | D40: 212.744 | E40: 102.255 | F40: 160.014 | G40: 1 | H40: 50 | I40: P003234 | K40: 129.9 | L40: =E40-K40 -> -27.645 | M40: =E40-N40 -> 102.255 | P40: SU002828 | Q40: 0 | T40: 16.1672 | AA40: =M40/5 -> 20.451 | AB40: =12.5*AA40-V40-T40-S40-R40-Q40-O40-F40 -> 79.4563 | AC40: =AB40-AD40-AE40 -> 79.4563 | AG40: =(F40+O40+Q40+R40+S40+T40+U40+V40+W40+X40+Y40+AC40+AD40+AE40)/AA40 -> 12.5 | AH40: =(F40+O40+Q40+R40+S40+T40+U40+V40+W40+X40+Y40)/AA40 -> 8.6147963 | AI40: 20.7852 | AJ40: 18.3852 | AK40: 26.343 | AL40: 19.9468 | AM40: 21.798 | AN40: 22.8396 | AO40: 22.8786 | AP40: 16.0274 | AQ40: 26.9794 | AR40: 44.0774 | AT40: =ROUND(G40*AC40,0) -> 79 | AU40: =ROUND(G40*AD40,0) -> 0 | AV40: =ROUND(G40*AE40,0) -> 0
...
