Workbook

Sheet TDSheet
A2: Ведомость по товарам на складах
A4: Параметры: | C4: Период: 01.05.2026 - 25.08.2026
C5: Количество товаров: В единицах хранения
A6: Отбор: | C6: Склад В списке "АСП Донецк ПОКОМ" И Номенклатура Равно " 485 Колбаса Молочная по-стародворски ТМ Стародворье в оболочке полиамид. ВЕС ПОКОМ "
A8: Регистратор | F8: Количество | J8: Расход | L8: Вес (нетто), кг
F9: Начальный остаток | H9: Приход | J9: Расход | K9: Конечный остаток | L9: Начальный остаток | M9: Приход | N9: Расход | O9: Конечный остаток
A10: Приходный ордер на товары №00-00010789 от 05.06.2026 | D10: =RIGHT(A10,10) -> 05.06.2026 | E10: =LEFT(A10,9) -> Приходный | H10: 32.29 | K10: 32.29 | M10: 32.29 | O10: 32.29
A11: Приходный ордер на товары №00-00010910 от 09.06.2026 | D11: =RIGHT(A11,10) -> 09.06.2026 | E11: =LEFT(A11,9) -> Приходный | F11: 32.29 | H11: 150.58 | K11: 182.87 | L11: 32.29 | M11: 150.58 | O11: 182.87
A12: Приходный ордер на товары №00-00011290 от 16.06.2026 | D12: =RIGHT(A12,10) -> 16.06.2026 | E12: =LEFT(A12,9) -> Приходный | F12: 182.87 | H12: 205.14 | K12: 388.01 | L12: 182.87 | M12: 205.14 | O12: 388.01
A13: Приходный ордер на товары №00-00011399 от 18.06.2026 | D13: =RIGHT(A13,10) -> 18.06.2026 | E13: =LEFT(A13,9) -> Приходный | F13: 388.01 | H13: 305.995 | K13: 694.005 | L13: 388.01 | M13: 305.995 | O13: 694.005
A14: Расходный ордер на товары №00-00271269 от 24.06.2026 | D14: =RIGHT(A14,10) -> 24.06.2026 | E14: =LEFT(A14,9) -> Расходный | F14: 694.005 | J14: 1.35 | K14: 692.655 | L14: 694.005 | N14: 1.35 | O14: 692.655
A15: Приходный ордер на товары №00-00011634 от 24.06.2026 | D15: =RIGHT(A15,10) -> 24.06.2026 | E15: =LEFT(A15,9) -> Приходный | F15: 692.655 | H15: 410.134 | K15: 1102.789 | L15: 692.655 | M15: 410.134 | O15: 1102.789
A16: Расходный ордер на товары №00-00272479 от 25.06.2026 | D16: =RIGHT(A16,10) -> 25.06.2026 | E16: =LEFT(A16,9) -> Расходный | F16: 1102.789 | J16: 1.342 | K16: 1101.447 | L16: 1102.789 | N16: 1.342 | O16: 1101.447
A17: Расходный ордер на товары №00-00272480 от 25.06.2026 | D17: =RIGHT(A17,10) -> 25.06.2026 | E17: =LEFT(A17,9) -> Расходный | F17: 1101.447 | J17: 2.695 | K17: 1098.752 | L17: 1101.447 | N17: 2.695 | O17: 1098.752
A18: Расходный ордер на товары №00-00274230 от 26.06.2026 | D18: =RIGHT(A18,10) -> 26.06.2026 | E18: =LEFT(A18,9) -> Расходный | F18: 1098.752 | J18: 1.34 | K18: 1097.412 | L18: 1098.752 | N18: 1.34 | O18: 1097.412 | P18: 46201 | Q18: =SUM(J14:J18) -> 6.727
A19: Пересчет товаров №00-00001210 от 29.06.2026 | D19: =RIGHT(A19,10) -> 29.06.2026 | E19: =LEFT(A19,9) -> Пересчет | F19: 1097.412 | J19: 1.378 | K19: 1096.034 | L19: 1097.412 | N19: 1.378 | O19: 1096.034
A20: Расходный ордер на товары №00-00278375 от 30.06.2026 | D20: =RIGHT(A20,10) -> 30.06.2026 | E20: =LEFT(A20,9) -> Расходный | F20: 1096.034 | J20: 1.355 | K20: 1094.679 | L20: 1096.034 | N20: 1.355 | O20: 1094.679
A21: Расходный ордер на товары №00-00278140 от 30.06.2026 | D21: =RIGHT(A21,10) -> 30.06.2026 | E21: =LEFT(A21,9) -> Расходный | F21: 1094.679 | J21: 4 | K21: 1090.679 | L21: 1094.679 | N21: 4 | O21: 1090.679 | P21: 46208 | Q21: =SUM(J20:J21) -> 5.355
A22: Расходный ордер на товары №00-00289588 от 07.07.2026 | D22: =RIGHT(A22,10) -> 07.07.2026 | E22: =LEFT(A22,9) -> Расходный | F22: 1090.679 | J22: 2.686 | K22: 1087.993 | L22: 1090.679 | N22: 2.686 | O22: 1087.993
A23: Расходный ордер на товары №00-00292188 от 08.07.2026 | D23: =RIGHT(A23,10) -> 08.07.2026 | E23: =LEFT(A23,9) -> Расходный | F23: 1087.993 | J23: 1.33 | K23: 1086.663 | L23: 1087.993 | N23: 1.33 | O23: 1086.663
A24: Расходный ордер на товары №00-00292640 от 08.07.2026 | D24: =RIGHT(A24,10) -> 08.07.2026 | E24: =LEFT(A24,9) -> Расходный | F24: 1086.663 | J24: 1.34 | K24: 1085.323 | L24: 1086.663 | N24: 1.34 | O24: 1085.323
A25: Расходный ордер на товары №00-00293498 от 09.07.2026 | D25: =RIGHT(A25,10) -> 09.07.2026 | E25: =LEFT(A25,9) -> Расходный | F25: 1085.323 | J25: 1.355 | K25: 1083.968 | L25: 1085.323 | N25: 1.355 | O25: 1083.968
A26: Расходный ордер на товары №00-00293509 от 09.07.2026 | D26: =RIGHT(A26,10) -> 09.07.2026 | E26: =LEFT(A26,9) -> Расходный | F26: 1083.968 | J26: 1.34 | K26: 1082.628 | L26: 1083.968 | N26: 1.34 | O26: 1082.628
A27: Расходный ордер на товары №00-00292939 от 09.07.2026 | D27: =RIGHT(A27,10) -> 09.07.2026 | E27: =LEFT(A27,9) -> Расходный | F27: 1082.628 | J27: 1.33 | K27: 1081.298 | L27: 1082.628 | N27: 1.33 | O27: 1081.298
A28: Расходный ордер на товары №00-00292949 от 09.07.2026 | D28: =RIGHT(A28,10) -> 09.07.2026 | E28: =LEFT(A28,9) -> Расходный | F28: 1081.298 | J28: 2.69 | K28: 1078.608 | L28: 1081.298 | N28: 2.69 | O28: 1078.608
A29: Расходный ордер на товары №00-00292953 от 09.07.2026 | D29: =RIGHT(A29,10) -> 09.07.2026 | E29: =LEFT(A29,9) -> Расходный | F29: 1078.608 | J29: 1.41 | K29: 1077.198 | L29: 1078.608 | N29: 1.41 | O29: 1077.198
A30: Расходный ордер на товары №00-00292962 от 09.07.2026 | D30: =RIGHT(A30,10) -> 09.07.2026 | E30: =LEFT(A30,9) -> Расходный | F30: 1077.198 | J30: 1.405 | K30: 1075.793 | L30: 1077.198 | N30: 1.405 | O30: 1075.793
A31: Расходный ордер на товары №00-00292931 от 09.07.2026 | D31: =RIGHT(A31,10) -> 09.07.2026 | E31: =LEFT(A31,9) -> Расходный | F31: 1075.793 | J31: 1.343 | K31: 1074.45 | L31: 1075.793 | N31: 1.343 | O31: 1074.45
A32: Расходный ордер на товары №00-00292971 от 09.07.2026 | D32: =RIGHT(A32,10) -> 09.07.2026 | E32: =LEFT(A32,9) -> Расходный | F32: 1074.45 | J32: 1.33 | K32: 1073.12 | L32: 1074.45 | N32: 1.33 | O32: 1073.12
A33: Расходный ордер на товары №00-00293716 от 09.07.2026 | D33: =RIGHT(A33,10) -> 09.07.2026 | E33: =LEFT(A33,9) -> Расходный | F33: 1073.12 | J33: 1.34 | K33: 1071.78 | L33: 1073.12 | N33: 1.34 | O33: 1071.78
... A56: Расходный ордер на товары №00-00295105 от 10.07.2026 | D56: =RIGHT(A56,10) -> 10.07.2026 | E56: =LEFT(A56,9) -> Расходный | F56: 1042.168 | J56: 1.345 | K56: 1040.823 | L56: 1042.168 | N56: 1.345 | O56: 1040.823
A57: Расходный ордер на товары №00-00296232 от 09.07.2026 | D57: =RIGHT(A57,10) -> 09.07.2026 | E57: =LEFT(A57,9) -> Расходный | F57: 1040.823 | J57: 403.155 | K57: 637.668 | L57: 1040.823 | N57: 403.155 | O57: 637.668 | P57: перемещение
A58: Расходный ордер на товары №00-00296045 от 10.07.2026 | D58: =RIGHT(A58,10) -> 10.07.2026 | E58: =LEFT(A58,9) -> Расходный | F58: 637.668 | J58: 1.345 | K58: 636.323 | L58: 637.668 | N58: 1.345 | O58: 636.323
A59: Расходный ордер на товары №00-00295677 от 10.07.2026 | D59: =RIGHT(A59,10) -> 10.07.2026 | E59: =LEFT(A59,9) -> Расходный | F59: 636.323 | J59: 1.35 | K59: 634.973 | L59: 636.323 | N59: 1.35 | O59: 634.973
A60: Расходный ордер на товары №00-00295656 от 10.07.2026 | D60: =RIGHT(A60,10) -> 10.07.2026 | E60: =LEFT(A60,9) -> Расходный | F60: 634.973 | J60: 1.345 | K60: 633.628 | L60: 634.973 | N60: 1.345 | O60: 633.628
A61: Расходный ордер на товары №00-00295644 от 10.07.2026 | D61: =RIGHT(A61,10) -> 10.07.2026 | E61: =LEFT(A61,9) -> Расходный | F61: 633.628 | J61: 1.355 | K61: 632.273 | L61: 633.628 | N61: 1.355 | O61: 632.273
A62: Расходный ордер на товары №00-00295657 от 10.07.2026 | D62: =RIGHT(A62,10) -> 10.07.2026 | E62: =LEFT(A62,9) -> Расходный | F62: 632.273 | J62: 1.35 | K62: 630.923 | L62: 632.273 | N62: 1.35 | O62: 630.923
A63: Расходный ордер на товары №00-00295678 от 10.07.2026 | D63: =RIGHT(A63,10) -> 10.07.2026 | E63: =LEFT(A63,9) -> Расходный | F63: 630.923 | J63: 1.348 | K63: 629.575 | L63: 630.923 | N63: 1.348 | O63: 629.575
A64: Расходный ордер на товары №00-00296010 от 10.07.2026 | D64: =RIGHT(A64,10) -> 10.07.2026 | E64: =LEFT(A64,9) -> Расходный | F64: 629.575 | J64: 2.705 | K64: 626.87 | L64: 629.575 | N64: 2.705 | O64: 626.87
A65: Расходный ордер на товары №00-00295671 от 10.07.2026 | D65: =RIGHT(A65,10) -> 10.07.2026 | E65: =LEFT(A65,9) -> Расходный | F65: 626.87 | J65: 1.35 | K65: 625.52 | L65: 626.87 | N65: 1.35 | O65: 625.52
...

Sheet Лист1
B1: ПРОДАЖИ В РАЗРЕЗЕ НЕДЕЛЬ
A2: Номенклатура | B2: 46181 | C2: =B2+6 -> 46187 | D2: =C2+1 -> 46188 | E2: =D2+6 -> 46194 | F2: =E2+1 -> 46195 | G2: =F2+6 -> 46201 | H2: =G2+1 -> 46202 | I2: =H2+6 -> 46208 | J2: =I2+1 -> 46209 | K2: =J2+6 -> 46215 | L2: =K2+1 -> 46216 | M2: =L2+6 -> 46222 | N2: =M2+1 -> 46223 | O2: =N2+6 -> 46229 | P2: =O2+1 -> 46230 | Q2: =P2+6 -> 46236 | R2: =Q2+1 -> 46237 | S2: =R2+6 -> 46243 | T2: =S2+1 -> 46244 | U2: =T2+6 -> 46250 | V2: =U2+1 -> 46251 | W2: =V2+6 -> 46257
A3: 485 Колбаса Молочная по-стародворски ТМ Стародворье в оболочке полиамид. ВЕС ПОКОМ | B3: 0 | D3: 0 | F3: =VLOOKUP(G2,TDSheet!$P:$Q,2,0) -> 6.727 | H3: =VLOOKUP(I2,TDSheet!$P:$Q,2,0) -> 5.355 | J3: =VLOOKUP(K2,TDSheet!$P:$Q,2,0) -> 91.561 | L3: =VLOOKUP(M2,TDSheet!$P:$Q,2,0) -> 36.235 | N3: =VLOOKUP(O2,TDSheet!$P:$Q,2,0) -> 17.44 | P3: =VLOOKUP(Q2,TDSheet!$P:$Q,2,0) -> 29.573 | R3: =VLOOKUP(S2,TDSheet!$P:$Q,2,0) -> 29.839 | T3: 0 | V3: 0
