Workbook

Sheet Sheet
A3: Номенклатура | B3: Ед. изм. | C3: Начальный остаток | D3: Приход | E3: Расход | F3: Конечный остаток | G3: Остаток, кг | H3: крат | I3: сроки | J3: метка | K3: метка2 | L3: заяв | M3: разн | N3: без опта | O3: опт | P3: заказ в пути | Q3: заказ в пути | R3: ср нов | S3: расчет | T3: кон ост | U3: факт | V3: ср | W3: ср | X3: ср | Y3: ср | Z3: ср | AA3: ср | AB3: ср | AC3: ср | AD3: ср | AE3: ср | AF3: комментарии | AG3: вес
P4: 25,08, | Q4: 01,09, | R4: 31,08, | V4: 24,08, | W4: 17,08, | X4: 10,08, | Y4: 03,08, | Z4: 27,07, | AA4: 20,07, | AB4: 13,07, | AC4: 06,07, | AD4: 29,06, | AE4: 22,06, | AF4: ув
E5: =SUM(E6:E499) -> 9697.052 | F5: =SUM(F6:F499) -> 3749.911 | L5: =SUM(L6:L499) -> 25150.566 | M5: =SUM(M6:M499) -> -15453.514 | N5: =SUM(N6:N499) -> 0 | O5: =SUM(O6:O499) -> 0 | P5: =SUM(P6:P499) -> 18892 | Q5: =SUM(Q6:Q499) -> 20052 | R5: =SUM(R6:R499) -> 1939.4104 | S5: =SUM(S6:S499) -> 9829.9298 | V5: =SUM(V6:V499) -> 3945.1628 | W5: =SUM(W6:W499) -> 3703.6238 | X5: =SUM(X6:X499) -> 2207.5886 | Y5: =SUM(Y6:Y499) -> 2571.0086 | Z5: =SUM(Z6:Z499) -> 3209.5596 | AA5: =SUM(AA6:AA499) -> 2940.3354 | AB5: =SUM(AB6:AB499) -> 2144.2982 | AC5: =SUM(AC6:AC499) -> 2239.9688 | ... AE5: =SUM(AE6:AE499) -> 2298.7524 | AF5: ув | AG5: =SUM(AG6:AG499) -> 5181.8278
A6: 0614 ПРАЗДНИЧНАЯ с/к в/с дек.спец.мгс Останкино | B6: кг | C6: 28.201 | E6: 1.696 | F6: 26.505 | G6: =F6*H6 -> 26.505 | H6: 1 | I6: 120 | J6: матрица | L6: 1.5 | M6: =E6-L6 -> 0.196 | P6: 0 | Q6: 0 | R6: =E6/5 -> 0.3392 | T6: =(F6+P6+Q6+S6)/R6 -> 78.139741 | U6: =(F6+P6+Q6)/R6 -> 78.139741 | V6: 3.1198 | W6: 0 | X6: 0 | Y6: 0 | Z6: 0 | AA6: 0 | AB6: 0 | AC6: 0 | AD6: 0 | AE6: 0 | AF6: новинка / нужно увеличить продажи!!! / Грация | AG6: =H6*S6 -> 0
A7: 3215 ВЕТЧ.МЯСНАЯ Папа может п/о 0.4кг 8шт. ОСТАНКИНО | B7: шт | C7: 160 | D7: 1 | E7: 133 | F7: 25 | H7: 0.4 | I7: 60 | J7: матрица | L7: 383 | M7: =E7-L7 -> -250 | P7: 556 | Q7: 247 | R7: =E7/5 -> 26.6 | S7: 50 | T7: =(F7+P7+Q7+S7)/R7 -> 33.007519 | U7: =(F7+P7+Q7)/R7 -> 31.12782 | V7: 68.8 | W7: 75.6 | X7: 35.4 | Y7: 54.2 | Z7: 62.6 | AA7: 55.6 | AB7: 41.2 | AC7: 33.6 | AD7: 46.6 | AE7: 37.8 | AG7: =H7*S7 -> 20
A8: 3287 САЛЯМИ ИТАЛЬЯНСКАЯ с/к в/у ОСТАНКИНО | B8: кг | C8: 20.172 | D8: 2.996 | E8: 17.111 | F8: 3.061 | H8: 1 | I8: 120 | J8: матрица | L8: 44.086 | M8: =E8-L8 -> -26.975 | P8: 10 | Q8: 32 | R8: =E8/5 -> 3.4222 | S8: =16*R8-Q8-P8-F8 -> 9.6942 | T8: =(F8+P8+Q8+S8)/R8 -> 16 | U8: =(F8+P8+Q8)/R8 -> 13.167261 | V8: 5.2168 | W8: 4.2012 | X8: 3.2758 | Y8: 0.2996 | Z8: 0.9922 | AA8: 4.3466 | AB8: 1.4268 | AC8: 4.159 | AD8: 4.5156 | AE8: 3.8104 | AF8: плюсом 5 дней | AG8: =H8*S8 -> 9.6942
A9: 3986 Ароматная с/к в/у 1/250 ОСТАНКИНО | B9: шт | C9: 110 | D9: 1 | E9: 116 | F9: -6 | H9: 0.25 | I9: 120 | J9: матрица | L9: 496 | M9: =E9-L9 -> -380 | P9: 384 | Q9: 582 | R9: =E9/5 -> 23.2 | S9: 50 | T9: =(F9+P9+Q9+S9)/R9 -> 43.534483 | U9: =(F9+P9+Q9)/R9 -> 41.37931 | V9: 97.8 | W9: 70 | X9: 29.8 | Y9: 37.4 | Z9: 61.4 | AA9: 31.4 | AB9: 25 | AC9: 35.8 | AD9: 25.4 | AE9: 25 | AF9: плюсом 5 дней | AG9: =H9*S9 -> 12.5
A10: 4063 МЯСНАЯ Папа может вар п/о_Л ОСТАНКИНО | B10: кг | C10: 545.793 | D10: 13.599 | E10: 288.761 | F10: 251.502 | H10: 1 | I10: 60 | J10: матрица | L10: 358.225 | M10: =E10-L10 -> -69.464 | P10: 230 | Q10: 0 | R10: =E10/5 -> 57.7522 | S10: =16*R10-Q10-P10-F10 -> 442.5332 | T10: =(F10+P10+Q10+S10)/R10 -> 16 | U10: =(F10+P10+Q10)/R10 -> 8.3373794 | V10: 47.668 | W10: 71.5244 | X10: 59.9964 | Y10: 49.2606 | Z10: 56.2572 | AA10: 69.917 | AB10: 42.271 | AC10: 39.8542 | AD10: 46.8334 | AE10: 41.0588 | AG10: =H10*S10 -> 442.5332
A11: 4117 ЭКСТРА Папа может с/к в/у_Л ОСТАНКИНО | B11: кг | C11: 121.441 | E11: 21.088 | F11: 100.353 | G11: =F11*H11 -> 100.353 | H11: 1 | I11: 120 | J11: матрица | L11: 49.7 | M11: =E11-L11 -> -28.612 | P11: 0 | Q11: 26 | R11: =E11/5 -> 4.2176 | T11: =(F11+P11+Q11+S11)/R11 -> 29.958507 | U11: =(F11+P11+Q11)/R11 -> 29.958507 | V11: 10.532 | W11: 6.9102 | X11: 4.5746 | Y11: 8.6004 | Z11: 5.0928 | AA11: 2.7076 | AB11: 4.4042 | AC11: 2.8082 | AD11: 3.0776 | AE11: 3.7628 | AF11: нужно увеличить продажи / плюсом 5 дней | AG11: =H11*S11 -> 0
A12: 4574 Мясная со шпиком Папа может вар п/о ОСТАНКИНО | B12: кг | C12: 71.962 | D12: 10.816 | E12: 43.211 | F12: 27.39 | H12: 1 | I12: 60 | J12: матрица | L12: 54 | M12: =E12-L12 -> -10.789 | P12: 0 | Q12: 4 | R12: =E12/5 -> 8.6422 | S12: =12*R12-Q12-P12-F12 -> 72.3164 | T12: =(F12+P12+Q12+S12)/R12 -> 12 | U12: =(F12+P12+Q12)/R12 -> 3.632177 | V12: 5.4014 | W12: 2.4534 | X12: 4.0156 | Y12: 8.7404 | Z12: 3.5336 | AA12: 3.8138 | AB12: 0.8198 | AC12: 1.0762 | AD12: 3.2698 | AE12: 7.4386 | AG12: =H12*S12 -> 72.3164
A13: 4813 ФИЛЕЙНАЯ Папа может вар п/о_Л ОСТАНКИНО | B13: кг | C13: 407.057 | D13: 9.596 | E13: 300.024 | F13: 101.26 | H13: 1 | I13: 60 | J13: матрица | L13: 337.718 | M13: =E13-L13 -> -37.694 | P13: 197 | Q13: 231 | R13: =E13/5 -> 60.0048 | S13: =16*R13-Q13-P13-F13 -> 430.8168 | T13: =(F13+P13+Q13+S13)/R13 -> 16 | U13: =(F13+P13+Q13)/R13 -> 8.8202944 | V13: 59.6338 | W13: 64.5988 | X13: 47.5078 | Y13: 63.0726 | Z13: 49.1456 | AA13: 63.1104 | AB13: 35.6636 | AC13: 33.9338 | AD13: 49.6224 | AE13: 48.1694 | AG13: =H13*S13 -> 430.8168
A14: 4993 САЛЯМИ ИТАЛЬЯНСКАЯ с/к в/у 1/250*8_120c ОСТАНКИНО | B14: шт | C14: 191 | D14: 8 | E14: 153 | F14: 38 | H14: 0.25 | I14: 120 | J14: матрица | L14: 304 | M14: =E14-L14 -> -151 | P14: 326 | Q14: 398 | R14: =E14/5 -> 30.6 | T14: =(F14+P14+Q14+S14)/R14 -> 24.901961 | U14: =(F14+P14+Q14)/R14 -> 24.901961 | V14: 70.4 | W14: 62 | X14: 37 | Y14: 33 | Z14: 47.4 | AA14: 53.6 | AB14: 24.2 | AC14: 21.4 | AD14: 43.8 | AE14: 21.4 | AF14: плюсом 5 дней | AG14: =H14*S14 -> 0
A15: 5452 ВЕТЧ.МЯСНАЯ Папа может п/о ОСТАНКИНО | B15: кг | C15: 198.038 | D15: 1.35 | E15: 70.306 | F15: 125.034 | H15: 1 | I15: 60 | J15: матрица | L15: 148.8 | M15: =E15-L15 -> -78.494 | P15: 0 | Q15: 75 | R15: =E15/5 -> 14.0612 | S15: =16*R15-Q15-P15-F15 -> 24.9452 | T15: =(F15+P15+Q15+S15)/R15 -> 16 | U15: =(F15+P15+Q15)/R15 -> 14.225955 | V15: 19.493 | W15: 0.472 | X15: 8.4016 | Y15: 26.6348 | Z15: 14.544 | AA15: 9.7308 | AB15: 0.8118 | AC15: 3.512 | AD15: 11.567 | AE15: 18.5206 | AG15: =H15*S15 -> 24.9452
A16: 5483 ЭКСТРА Папа может с/к в/у 1/250 8шт. ОСТАНКИНО | B16: шт | C16: 114 | D16: 2 | E16: 98 | F16: 19 | H16: 0.25 | I16: 120 | J16: матрица | L16: 494 | M16: =E16-L16 -> -396 | P16: 380 | Q16: 698 | R16: =E16/5 -> 19.6 | T16: =(F16+P16+Q16+S16)/R16 -> 55.969388 | U16: =(F16+P16+Q16)/R16 -> 55.969388 | V16: 119.2 | W16: 76 | X16: 40.2 | Y16: 40.4 | Z16: 55.8 | AA16: 48.2 | AB16: 24.2 | AC16: 25.2 | AD16: 30.4 | AE16: 24.4 | AF16: плюсом 5 дней | AG16: =H16*S16 -> 0
A17: 5495 ВЕТЧ.С ИНДЕЙКОЙ Папа может п/о 400*6 Останкино | B17: шт | C17: 36 | E17: 37 | F17: -3 | H17: 0.4 | I17: 60 | J17: матрица | L17: 304 | M17: =E17-L17 -> -267 | P17: 318 | Q17: 259 | R17: =E17/5 -> 7.4 | S17: 100 | T17: =(F17+P17+Q17+S17)/R17 -> 91.081081 | U17: =(F17+P17+Q17)/R17 -> 77.567568 | V17: 43.8 | W17: 40 | X17: 24.6 | Y17: 22.8 | Z17: 36.8 | AA17: 37 | AB17: 34.8 | AC17: 26.6 | AD17: 22.8 | AE17: 21.8 | AG17: =H17*S17 -> 40
A18: 5544 Сервелат Финский в/к в/у_45с НОВАЯ ОСТАНКИНО | B18: кг | C18: 70.058 | D18: 4.249 | E18: 60.176 | F18: 8.163 | H18: 1 | I18: 45 | J18: матрица | L18: 183.352 | M18: =E18-L18 -> -123.176 | P18: 248 | Q18: 251 | R18: =E18/5 -> 12.0352 | S18: 50 | T18: =(F18+P18+Q18+S18)/R18 -> 46.294453 | U18: =(F18+P18+Q18)/R18 -> 42.139973 | V18: 43.8096 | W18: 38.122 | X18: 31.1738 | Y18: 36.7068 | Z18: 45.037 | AA18: 38.5836 | AB18: 38.1704 | AC18: 32.511 | AD18: 43.4754 | AE18: 43.322 | AG18: =H18*S18 -> 50
A19: 5708 ПОСОЛЬСКАЯ Папа может с/к в/у ОСТАНКИНО | B19: кг | C19: 38.15 | D19: 2.958 | E19: 20.553 | F19: 17.098 | H19: 1 | I19: 120 | J19: матрица | L19: 39 | M19: =E19-L19 -> -18.447 | P19: 0 | Q19: 62 | R19: =E19/5 -> 4.1106 | S19: 10 | T19: =(F19+P19+Q19+S19)/R19 -> 21.675181 | U19: =(F19+P19+Q19)/R19 -> 19.242446 | V19: 11.1694 | W19: 5.2294 | X19: 2.7152 | Y19: 5.2648 | Z19: 4.2116 | AA19: 3.5572 | AB19: 3.2544 | AC19: 1.6692 | AD19: 3.0582 | AE19: 1.0934 | AF19: плюсом 5 дней | AG19: =H19*S19 -> 10
A20: 5819 Сосиски Папа может 400г Мясные ОСТАНКИНО | B20: шт | C20: 32 | F20: 32 | G20: =F20*H20 -> 12.8 | H20: 0.4 | I20: 45 | J20: матрица | L20: 256 | M20: =E20-L20 -> -256 | P20: 0 | Q20: 0 | R20: =E20/5 -> 0 | T20: =(F20+P20+Q20+S20)/R20 -> #DIV/0! | U20: =(F20+P20+Q20)/R20 -> #DIV/0! | V20: 0 | W20: -1.2 | X20: -0.2 | Y20: -3.8 | Z20: -0.2 | AA20: 5 | AB20: 9.6 | AC20: 3.8 | AD20: 22.2 | AE20: 17.4 | AF20: нужно увеличить продажи!!! / 192шт списано (11,08,26) | AG20: =H20*S20 -> 0
A21: 5851 ЭКСТРА Папа может вар п/о ОСТАНКИНО | B21: кг | C21: 116.472 | D21: 13.55 | E21: 121.632 | F21: -7.115 | H21: 1 | I21: 60 | J21: матрица | L21: 181.804 | M21: =E21-L21 -> -60.172 | P21: 177 | Q21: 239 | R21: =E21/5 -> 24.3264 | S21: 50 | T21: =(F21+P21+Q21+S21)/R21 -> 18.863663 | U21: =(F21+P21+Q21)/R21 -> 16.808282 | V21: 38.0486 | W21: 34.2052 | X21: 22.6152 | Y21: 32.7796 | Z21: 30.8804 | AA21: 43.9718 | AB21: 24.5406 | AC21: 24.433 | AD21: 26.176 | AE21: 27.4224 | AG21: =H21*S21 -> 50
A22: 5931 ОХОТНИЧЬЯ Папа может с/к в/у 1/220 8шт. ОСТАНКИНО | B22: шт | C22: 376 | D22: 6 | E22: 358 | F22: 20 | H22: 0.22 | I22: 120 | J22: матрица | L22: 714 | M22: =E22-L22 -> -356 | P22: 439 | Q22: 788 | R22: =E22/5 -> 71.6 | S22: 200 | T22: =(F22+P22+Q22+S22)/R22 -> 20.209497 | U22: =(F22+P22+Q22)/R22 -> 17.416201 | V22: 133.6 | W22: 105.8 | X22: 63.4 | Y22: 72.2 | Z22: 83.4 | AA22: 44.2 | AB22: 39.6 | AC22: 29.2 | AD22: 39 | AE22: 36.2 | AF22: плюсом 5 дней | AG22: =H22*S22 -> 44
A23: 6008 САЛО СОЛЕНОЕ С ЧЕРНЫМ ПЕРЦЕМ мл/к в/у ОСТАНКИНО | B23: кг | C23: 1.116 | F23: 1.116 | H23: 1 | I23: 40 | J23: матрица | L23: 24 | M23: =E23-L23 -> -24 | P23: 20 | Q23: 10 | R23: =E23/5 -> 0 | S23: 10 | T23: =(F23+P23+Q23+S23)/R23 -> #DIV/0! | U23: =(F23+P23+Q23)/R23 -> #DIV/0! | V23: -0.176 | W23: -0.27 | X23: 1.016 | Y23: 0.6252 | Z23: 3.5936 | AA23: 9.972 | AB23: 8.8044 | AC23: 4.5224 | AD23: 2.25 | AE23: 2.5368 | AF23: 58кг списано (11,08,26) | AG23: =H23*S23 -> 10
A24: 6025 ВЕТЧ.ФИРМЕННАЯ С ИНДЕЙКОЙ п/о ОСТАНКИНО | B24: кг | C24: 39.21 | F24: 39.21 | G24: =F24*H24 -> 39.21 | H24: 1 | J24: не в матрице | M24: =E24-L24 -> 0 | P24: 0 | Q24: 0 | R24: =E24/5 -> 0 | T24: =(F24+P24+Q24+S24)/R24 -> #DIV/0! | U24: =(F24+P24+Q24)/R24 -> #DIV/0! | V24: 2.414 | W24: 3.625 | X24: 0 | Y24: 5.444 | Z24: 0 | AA24: 0 | AB24: 0 | AC24: 0 | AD24: 0 | AE24: 0 | AF24: нужно увеличить продажи!!! / Грация
A25: 6220 ГОВЯЖЬЯ папа может вар п/о Останкино | B25: кг | C25: 4.012 | D25: 1.336 | E25: 1.213 | F25: 0.067 | H25: 1 | I25: 60 | J25: матрица | L25: 105.4 | M25: =E25-L25 -> -104.187 | P25: 127 | Q25: 11 | R25: =E25/5 -> 0.2426 | S25: 60 | T25: =(F25+P25+Q25+S25)/R25 -> 816.43446 | U25: =(F25+P25+Q25)/R25 -> 569.11377 | V25: 10.1114 | W25: 16.4042 | X25: 2.424 | Y25: 13.7454 | Z25: 15.652 | AA25: 11.1342 | AB25: 14.0424 | AC25: 14.0364 | AD25: 10.058 | AE25: 11.2278 | AG25: =H25*S25 -> 60
A26: 6221 НЕОПОЛИТАНСКИЙ ДУЭТ с/к с/н мгс 1/90 Останкино | B26: шт | C26: 221 | D26: 12 | E26: 177 | F26: 55 | H26: 0.09 | I26: 60 | J26: матрица | L26: 270 | M26: =E26-L26 -> -93 | P26: 85 | Q26: 280 | R26: =E26/5 -> 35.4 | S26: =16*R26-Q26-P26-F26 -> 146.4 | T26: =(F26+P26+Q26+S26)/R26 -> 16 | U26: =(F26+P26+Q26)/R26 -> 11.864407 | V26: 48.8 | W26: 39.6 | X26: 38.8 | Y26: 13.2 | Z26: 47.8 | AA26: 38.8 | AB26: 20 | AC26: 34.4 | AD26: 30.6 | AE26: 34.4 | AG26: =H26*S26 -> 13.176
A27: 6222 ИТАЛЬЯНСКОЕ АССОРТИ с/в с/н мгс 1/90 ОСТАНКИНО | B27: шт | C27: 70 | F27: 70 | G27: =F27*H27 -> 6.3 | H27: 0.09 | J27: не в матрице | M27: =E27-L27 -> 0 | P27: 0 | Q27: 0 | R27: =E27/5 -> 0 | T27: =(F27+P27+Q27+S27)/R27 -> #DIV/0! | U27: =(F27+P27+Q27)/R27 -> #DIV/0! | V27: 0 | W27: 6 | X27: 0 | Y27: 4.2 | Z27: 0 | AA27: 0 | AB27: 0 | AC27: 0 | AD27: 0 | AE27: 0 | AF27: нужно увеличить продажи!!! / Грация
A28: 6228 МЯСНОЕ АССОРТИ к/з с/н мгс 1/90 10шт Останкино | B28: шт | C28: 12 | D28: 3 | E28: 4 | F28: 3 | H28: 0.09 | I28: 45 | J28: матрица | L28: 78 | M28: =E28-L28 -> -74 | P28: 118 | Q28: 0 | R28: =E28/5 -> 0.8 | S28: 60 | T28: =(F28+P28+Q28+S28)/R28 -> 226.25 | U28: =(F28+P28+Q28)/R28 -> 151.25 | V28: 1.8 | W28: 14.2 | X28: 7.2 | Y28: 6.2 | Z28: 11 | AA28: 14.8 | AB28: 8.2 | AC28: 11 | AD28: 22 | AE28: 18.8 | AG28: =H28*S28 -> 5.4
A29: 6279 КОРЕЙКА ПО-ОСТ.к/в в/с с/н в/у 1/150_45с Останкино | B29: шт | C29: 80 | F29: 80 | G29: =F29*H29 -> 12 | H29: 0.15 | I29: 45 | J29: матрица | L29: 101 | M29: =E29-L29 -> -101 | P29: 32 | Q29: 0 | R29: =E29/5 -> 0 | T29: =(F29+P29+Q29+S29)/R29 -> #DIV/0! | U29: =(F29+P29+Q29)/R29 -> #DIV/0! | V29: 0 | W29: 8 | X29: 2 | Y29: 1.8 | Z29: 2.2 | AA29: 6 | AB29: 8.8 | AC29: 7 | AD29: 9.8 | AE29: 17.4 | AF29: нужно увеличить продажи!!! | AG29: =H29*S29 -> 0
A30: 6303 Мясные Папа может сос п/о мгс 1,5*3 Останкино | B30: кг | C30: 193.652 | D30: 3.216 | E30: 278.802 | F30: -107.374 | H30: 1 | I30: 45 | J30: матрица | L30: 685.816 | M30: =E30-L30 -> -407.014 | P30: 836 | Q30: 307 | R30: =E30/5 -> 55.7604 | S30: 300 | T30: =(F30+P30+Q30+S30)/R30 -> 23.952949 | U30: =(F30+P30+Q30)/R30 -> 18.572786 | V30: 95.4908 | W30: 113.2006 | X30: 18.4908 | Y30: 75.1726 | Z30: 78.5144 | AA30: 67.3848 | AB30: 59.207 | AC30: 31.207 | AD30: 62.066 | AE30: 56.6302 | AG30: =H30*S30 -> 300
A31: 6325 ДОКТОРСКАЯ ПРЕМИУМ вар п/о 0.4кг 8шт. ОСТАНКИНО | B31: шт | C31: 17 | E31: 17 | H31: 0.4 | I31: 60 | J31: матрица | L31: 116 | M31: =E31-L31 -> -99 | P31: 202 | Q31: 117 | R31: =E31/5 -> 3.4 | T31: =(F31+P31+Q31+S31)/R31 -> 93.823529 | U31: =(F31+P31+Q31)/R31 -> 93.823529 | V31: 24 | W31: 24 | X31: 7.4 | Y31: 16 | Z31: 24.8 | AA31: 16.6 | AB31: 16.6 | AC31: 14.2 | AD31: 22.4 | AE31: 17.8 | AG31: =H31*S31 -> 0
A32: 6333 МЯСНАЯ Папа может вар п/о 0.4кг 8шт. ОСТАНКИНО | B32: шт | C32: 418 | D32: 17 | E32: 393 | F32: 25 | H32: 0.4 | I32: 60 | J32: матрица | L32: 659 | M32: =E32-L32 -> -266 | P32: 646 | Q32: 717 | R32: =E32/5 -> 78.6 | S32: 200 | T32: =(F32+P32+Q32+S32)/R32 -> 20.203562 | U32: =(F32+P32+Q32)/R32 -> 17.659033 | V32: 127.2 | W32: 120 | X32: 82.4 | Y32: 83.8 | Z32: 120.6 | AA32: 106.6 | AB32: 74.8 | AC32: 84 | AD32: 80 | AE32: 95.8 | AG32: =H32*S32 -> 80
A33: 6364 СЕРВЕЛАТ ЗЕРНИСТЫЙ ПМ в/к в/у 0.35кг ОСТАНКИНО | B33: шт | C33: -1 | F33: -1 | H33: 0 | J33: не в матрице | K33: 7154 СЕРВЕЛАТ ЗЕРНИСТЫЙ ПМ в/к в/у 0,35кг_50с Останкино | M33: =E33-L33 -> 0 | P33: 0 | Q33: 0 | R33: =E33/5 -> 0 | T33: =(F33+P33+Q33+S33)/R33 -> #DIV/0! | U33: =(F33+P33+Q33)/R33 -> #DIV/0! | V33: 0 | W33: 0 | X33: 0 | Y33: 0 | Z33: 0 | AA33: 0 | AB33: 0 | AC33: 0 | AD33: 0 | AE33: 0
A34: 6392 ФИЛЕЙНАЯ Папа может вар п/о 0,4кг ОСТАНКИНО | B34: шт | C34: 319 | D34: 7 | E34: 310 | F34: 9 | H34: 0.4 | I34: 60 | J34: матрица | L34: 662 | M34: =E34-L34 -> -352 | P34: 643 | Q34: 505 | R34: =E34/5 -> 62 | S34: 150 | T34: =(F34+P34+Q34+S34)/R34 -> 21.080645 | U34: =(F34+P34+Q34)/R34 -> 18.66129 | V34: 104.8 | W34: 105.6 | X34: 60 | Y34: 94.2 | Z34: 83.8 | AA34: 105 | AB34: 61.8 | AC34: 65.4 | AD34: 87.2 | AE34: 56.2 | AG34: =H34*S34 -> 60
A35: 6411 ВЕТЧ.РУБЛЕНАЯ ПМ в/у срез 0.3кг 6шт. ОСТАНКИНО | B35: шт | C35: 177 | D35: 1 | E35: 29 | F35: 148 | H35: 0 | I35: 45 | J35: вывод | L35: 34 | M35: =E35-L35 -> -5 | P35: 0 | Q35: 0 | R35: =E35/5 -> 5.8 | T35: =(F35+P35+Q35+S35)/R35 -> 25.517241 | U35: =(F35+P35+Q35)/R35 -> 25.517241 | V35: 3.8 | W35: 0 | X35: 0.4 | Y35: 0 | Z35: 0 | AA35: 0 | AB35: 0 | AC35: 0 | AD35: 0 | AE35: 0 | AF35: нужно увеличить продажи!!! / новинка
A36: 6453 ЭКСТРА Папа может с/к с/н в/у 1/100 14шт. ОСТАНКИНО | B36: шт | C36: 2 | F36: 2 | H36: 0 | I36: 60 | J36: не в матрице | K36: 7616 ЭКСТРА Папа может с/к с/н в/у 1/100_ ОСТАНКИНО | M36: =E36-L36 -> 0 | P36: 0 | Q36: 0 | R36: =E36/5 -> 0 | T36: =(F36+P36+Q36+S36)/R36 -> #DIV/0! | U36: =(F36+P36+Q36)/R36 -> #DIV/0! | V36: 0 | W36: 0 | X36: 0 | Y36: 0 | Z36: 0.2 | AA36: -0.4 | AB36: 20.6 | AC36: 34 | AD36: 49 | AE36: 32 | AF36: ротация на 7616
A37: 6454 АРОМАТНАЯ с/к с/н в/у 1/100 10шт. ОСТАНКИНО | B37: шт | C37: -15 | F37: -15 | H37: 0 | I37: 60 | J37: не в матрице | K37: 7613 АРОМАТНАЯ с/к с/н в/у 1/100 10шт_Л10 ОСТАНКИНО | M37: =E37-L37 -> 0 | P37: 0 | Q37: 0 | R37: =E37/5 -> 0 | T37: =(F37+P37+Q37+S37)/R37 -> #DIV/0! | U37: =(F37+P37+Q37)/R37 -> #DIV/0! | V37: 0 | W37: 3 | X37: 0.2 | Y37: -0.2 | Z37: 17 | AA37: 24.6 | AB37: 36.6 | AC37: 34.4 | AD37: 33.8 | AE37: 37.8 | AF37: ротация на 7613
A38: 6470 ВЕТЧ.МРАМОРНАЯ в/у_45с ОСТАНКИНО | B38: кг | C38: 13.469 | E38: 13.469 | H38: 0 | I38: 45 | J38: не в матрице | L38: 164.5 | M38: =E38-L38 -> -151.031 | P38: 0 | Q38: 0 | R38: =E38/5 -> 2.6938 | T38: =(F38+P38+Q38+S38)/R38 -> 0 | U38: =(F38+P38+Q38)/R38 -> 0 | V38: 9.0944 | W38: 3.9172 | X38: 0 | Y38: 11.114 | Z38: 13.551 | AA38: 8.172 | AB38: 2.647 | AC38: 0 | AD38: 1.433 | AE38: 7.953
A39: 6495 ВЕТЧ.МРАМОРНАЯ в/у срез 0,3кг 6шт_45с Останкино | B39: шт | C39: 103 | D39: 11 | E39: 82 | F39: 11 | H39: 0.3 | I39: 45 | J39: матрица | L39: 220 | M39: =E39-L39 -> -138 | P39: 63 | Q39: 144 | R39: =E39/5 -> 16.4 | S39: =16*R39-Q39-P39-F39 -> 44.4 | T39: =(F39+P39+Q39+S39)/R39 -> 16 | U39: =(F39+P39+Q39)/R39 -> 13.292683 | V39: 26 | W39: 22.4 | X39: 25.8 | Y39: 11.4 | Z39: 21.2 | AA39: 45.2 | AB39: 22.6 | AC39: 12.4 | AD39: 1.4 | AE39: 37.6 | AG39: =H39*S39 -> 13.32
A40: 6498 МОЛОЧНАЯ Папа может вар п/о ОСТАНКИНО | B40: кг | C40: 671.737 | D40: 7.758 | E40: 231.531 | F40: 439.316 | H40: 1 | I40: 60 | J40: матрица | L40: 267 | M40: =E40-L40 -> -35.469 | P40: 0 | Q40: 0 | R40: =E40/5 -> 46.3062 | S40: =16*R40-Q40-P40-F40 -> 301.5832 | T40: =(F40+P40+Q40+S40)/R40 -> 16 | U40: =(F40+P40+Q40)/R40 -> 9.4871961 | V40: 46.8828 | W40: 45.8374 | X40: 32.807 | Y40: 36.6816 | Z40: 46.652 | AA40: 53.2522 | AB40: 15.2168 | AC40: 15.7242 | AD40: 31.8386 | AE40: 20.4096 | AG40: =H40*S40 -> 301.5832
A41: 6527 ШПИКАЧКИ СОЧНЫЕ ПМ сар б/о мгс 1*3 45с ОСТАНКИНО | B41: кг | C41: 89.323 | D41: 4.143 | E41: 87.512 | F41: 1.811 | H41: 1 | I41: 45 | J41: матрица | L41: 101.158 | M41: =E41-L41 -> -13.646 | P41: 108 | Q41: 0 | R41: =E41/5 -> 17.5024 | S41: =14*R41-Q41-P41-F41 -> 135.2226 | T41: =(F41+P41+Q41+S41)/R41 -> 14 | U41: =(F41+P41+Q41)/R41 -> 6.2740538 | V41: 10.8488 | W41: 17.9328 | X41: 15.6494 | Y41: 12.671 | Z41: 16.6138 | AA41: 17.7024 | AB41: 10.3396 | AC41: 13.2452 | AD41: 13.0904 | AE41: 11.2984 | AG41: =H41*S41 -> 135.2226
A42: 6550 МЯСНЫЕ Папа может сар б/о мгс 1*3 О 45с Останкино | B42: кг | C42: 25.909 | D42: 4.707 | E42: 14.059 | F42: 8.146 | H42: 1 | I42: 45 | J42: матрица | L42: 130.2 | M42: =E42-L42 -> -116.141 | P42: 108 | Q42: 158 | R42: =E42/5 -> 2.8118 | S42: 40 | T42: =(F42+P42+Q42+S42)/R42 -> 111.72416 | U42: =(F42+P42+Q42)/R42 -> 97.4984 | V42: 24.3322 | W42: 18.1314 | X42: 12.0776 | Y42: 13.8966 | Z42: 19.7594 | AA42: 14.8596 | AB42: 11.2278 | AC42: 8.8872 | AD42: 4.9942 | AE42: 14.5874 | AG42: =H42*S42 -> 40
...

Sheet новинки
A1: 7514 | B1: 1001017557514 | C1: ЛЮБИТЕЛЬСКАЯ ОСТАНКИНСКАЯ вар ц/о в/у | D1: =A1&" "&C1 -> 7514 ЛЮБИТЕЛЬСКАЯ ОСТАНКИНСКАЯ вар ц/о в/у | E1: кг | F1: =VLOOKUP(B1,[1]КИ_ПФ!$B:$Q,16,0) -> 30 | G1: =VLOOKUP(B1,[1]КИ_ПФ!$B:$C,2,0) -> ЛЮБИТЕЛЬСКАЯ ОСТАНКИНСКАЯ вар ц/о в/у | H1: 1
A2: 7518 | B2: 1001017567518 | C2: ТЕЛЯЧЬЯ ГОСТ Останкино вар н/о в/у | D2: =A2&" "&C2 -> 7518 ТЕЛЯЧЬЯ ГОСТ Останкино вар н/о в/у | E2: кг | F2: =VLOOKUP(B2,[1]КИ_ПФ!$B:$Q,16,0) -> 30 | G2: =VLOOKUP(B2,[1]КИ_ПФ!$B:$C,2,0) -> ТЕЛЯЧЬЯ ГОСТ Останкино вар н/о в/у | H2: 1
A3: 6929 | B3: 1001085476929 | C3: КАРБОНAД ДОМАШНИЙ ПМ к/в кр/к в/у | D3: =A3&" "&C3 -> 6929 КАРБОНAД ДОМАШНИЙ ПМ к/в кр/к в/у | E3: кг | F3: =VLOOKUP(B3,[1]КИ_ПФ!$B:$Q,16,0) -> 45 | G3: =VLOOKUP(B3,[1]КИ_ПФ!$B:$C,2,0) -> КАРБОНAД ДОМАШНИЙ ПМ к/в кр/к в/у | H3: 1
A4: 614 | B4: 1001060720614 | C4: ПРАЗДНИЧНАЯ с/к в/с дек.спец.мгс | D4: 0614 ПРАЗДНИЧНАЯ с/к в/с дек.спец.мгс Останкино | E4: кг | F4: =VLOOKUP(B4,[1]КИ_ПФ!$B:$Q,16,0) -> 120 | G4: =VLOOKUP(B4,[1]КИ_ПФ!$B:$C,2,0) -> ПРАЗДНИЧНАЯ с/к в/с дек.спец.мгс | H4: 1
A5: 7143 | B5: 1001060717143 | C5: БРАУНШВЕЙГСКАЯ ГОСТ с/к в/у 1/220 8шт. | D5: =A5&" "&C5 -> 7143 БРАУНШВЕЙГСКАЯ ГОСТ с/к в/у 1/220 8шт. | E5: шт | F5: =VLOOKUP(B5,[1]КИ_ПФ!$B:$Q,16,0) -> 120 | G5: =VLOOKUP(B5,[1]КИ_ПФ!$B:$C,2,0) -> БРАУНШВЕЙГСКАЯ ГОСТ с/к в/у 1/220 8шт. | H5: 0.22
A6: 7710 | B6: 1001307587710 | C6: КРАКОВСКАЯ ГОСТ п/к н/о мгс 0.3кг | D6: =A6&" "&C6 -> 7710 КРАКОВСКАЯ ГОСТ п/к н/о мгс 0.3кг | E6: шт | F6: 45 | G6: КРАКОВСКАЯ ГОСТ п/к н/о мгс 0.3кг | H6: 0.3
A7: 7456 | B7: 1001063097456 | C7: САЛЯМИ ФИНСКАЯ Папа может с/к в/у 1/150 | D7: =A7&" "&C7 -> 7456 САЛЯМИ ФИНСКАЯ Папа может с/к в/у 1/150 | E7: шт | F7: =VLOOKUP(B7,[1]КИ_ПФ!$B:$Q,16,0) -> 90 | G7: =VLOOKUP(B7,[1]КИ_ПФ!$B:$C,2,0) -> САЛЯМИ ФИНСКАЯ Папа может с/к в/у 1/150 | H7: 0.15
A8: 7386 | B8: 1001067017386 | C8: БАРСЕЛОНА ПМ с/к в/у 1/150 | D8: 7386 БАРСЕЛОНА ПМ с/к в/у 1/150 ОСТАНКИНО | E8: шт | F8: =VLOOKUP(B8,[1]КИ_ПФ!$B:$Q,16,0) -> 90 | G8: =VLOOKUP(B8,[1]КИ_ПФ!$B:$C,2,0) -> БАРСЕЛОНА ПМ с/к в/у 1/150 | H8: 0.15
A9: 7344 | B9: 1001122287344 | C9: КОНСЕРВЫ МЯС.ГОВЯДИНА ТУШ. В/С 338г_ЧЗ | D9: =A9&" "&C9 -> 7344 КОНСЕРВЫ МЯС.ГОВЯДИНА ТУШ. В/С 338г_ЧЗ | E9: шт | F9: =VLOOKUP(B9,[1]КИ_ПФ!$B:$Q,16,0) -> 3 года | G9: =VLOOKUP(B9,[1]КИ_ПФ!$B:$C,2,0) -> КОНСЕРВЫ МЯС.ГОВЯДИНА ТУШ. В/С 338г_ЧЗ | H9: 0.338
A10: 7345 | B10: 1001123677345 | C10: КОНСЕРВЫ МЯС.СВИНИНА ТУШ. В/С 325г_ЧЗ | D10: =A10&" "&C10 -> 7345 КОНСЕРВЫ МЯС.СВИНИНА ТУШ. В/С 325г_ЧЗ | E10: шт | F10: =VLOOKUP(B10,[1]КИ_ПФ!$B:$Q,16,0) -> 3 года | G10: =VLOOKUP(B10,[1]КИ_ПФ!$B:$C,2,0) -> КОНСЕРВЫ МЯС.СВИНИНА ТУШ. В/С 325г_ЧЗ | H10: 0.325

Sheet вывод
A1: 6411 ВЕТЧ.РУБЛЕНАЯ ПМ в/у срез 0.3кг 6шт. ОСТАНКИНО | B1: вывод
A2: 6925 ВЕТЧ.КЛАССИЧЕСКАЯ в/у 0,6кг 8шт. ОСТАНКИНО | B2: вывод
A3: 7332 БОЯРСКАЯ ПМ п/к в/у 0,28кг ОСТАНКИНО | B3: вывод
A4: 7608 СЕРВЕЛАТ ШВЕЙЦАРСК.в/к с/н в/у 1/100_Л11 ОСТАНКИНО | B4: вывод
A5: 7612 БАЛЫК с/к с/н в/у 1/100 10шт_ ОСТАНКИНО | B5: вывод
