Workbook

Sheet Sheet
U1: 1450 | Y1: 1.56 | AC1: 0.615
Y2: дн | AC2: % | AQ2: 17100 | AR2: 17850 | AV2: 3500
A3: Номенклатура | B3: Ед. изм. | C3: Начальный остаток | D3: Приход | E3: Расход | F3: Конечный остаток | G3: крат | H3: сроки | I3: метка | J3: метка2 | K3: заяв | L3: разн | M3: без опта | N3: опт | O3: заказ в пути | P3: заказ в пути | Q3: заказ в пути | R3: заказ в пути | S3: заказ в пути | T3: заказ в пути | U3: заказ в пути | V3: заказ в пути | W3: ср нов | X3: расчет | Y3: итого | Z3: заказ | AA3: заказ | AB3: заказ | AC3: заказ | AD3: кон ост | AE3: факт | AF3: ср | AG3: ср | AH3: ср | AI3: ср | AJ3: ср | AK3: ср | AL3: ср | AM3: ср | AN3: ср | AO3: ср | AP3: комментарии | AQ3: вес | AR3: вес | AU3: 2600
O4: 22,08, | P4: 22,08,недогр | Q4: 22,08,доз | R4: 22,08,доз2 | S4: 23,08, | T4: 23,08,недогр | U4: 23,08,доз | V4: 23,08,доз2 | W4: 20,08, | Z4: 24,08, | AA4: 24,08,недогр | AB4: 24,08,доз | AC4: 25,08, | AF4: 18,08, | AG4: 13,08, | AH4: 11,08, | AI4: 06,08, | AJ4: 04,08, | AK4: 30,07, | AL4: 28,07, | AM4: 23,07, | AN4: 21,07, | AO4: 16,07, | AQ4: 24,08, | AR4: 25,08, | AT4: 1 | AU4: 22,08,доз | AV4: 24,08,доз
E5: =SUM(E6:E498) -> 51486.395 | F5: =SUM(F6:F498) -> 57483.743 | K5: =SUM(K6:K498) -> 55531.28 | L5: =SUM(L6:L498) -> -4044.885 | M5: =SUM(M6:M498) -> 0 | N5: =SUM(N6:N498) -> 0 | O5: =SUM(O6:O498) -> 23590.911 | P5: =SUM(P6:P498) -> -3692.6 | Q5: =SUM(Q6:Q498) -> 2600 | R5: =SUM(R6:R498) -> 600 | ... AC5: =SUM(AC6:AC498) -> 22089.981 | AF5: =SUM(AF6:AF498) -> 10547.458 | AG5: =SUM(AG6:AG498) -> 10043.437 | AH5: =SUM(AH6:AH498) -> 9948.0886 | AI5: =SUM(AI6:AI498) -> 10809.313 | AJ5: =SUM(AJ6:AJ498) -> 10812.657 | AK5: =SUM(AK6:AK498) -> 9813.4632 | AL5: =SUM(AL6:AL498) -> 10672.153 | AM5: =SUM(AM6:AM498) -> 11335.496 | ... AO5: =SUM(AO6:AO498) -> 10998.895 | AQ5: =SUM(AQ6:AQ498) -> 17093 | AR5: =SUM(AR6:AR498) -> 17848 | AT5: 1 | AU5: =SUM(AU6:AU498) -> 2600 | AV5: =SUM(AV6:AV498) -> 3495
A6: 005 Колбаса Докторская ГОСТ, Вязанка вектор,ВЕС. ПОКОМ | B6: кг | C6: 3735.695 | D6: 3940.618 | E6: 2734.288 | F6: 4731.657 | G6: 1 | H6: 50 | I6: матрица | K6: 2862.8 | L6: =E6-K6 -> -128.512 | O6: 271.20293 | S6: 296.16722 | W6: =E6/5 -> 546.8576 | X6: =12*W6-S6-O6-F6 -> 1263.2641 | Y6: =X6+$Y$1*W6 -> 2116.3619 | Z6: =Y6-AC6 -> 814.79934 | AC6: =Y6*$AC$1 -> 1301.5626 | AD6: =(F6+O6+S6+Z6+AC6)/W6 -> 13.56 | AE6: =(F6+O6+S6)/W6 -> 9.6899579 | AF6: 558.1642 | AG6: 472.441 | AH6: 450.1 | AI6: 477.9028 | AJ6: 497.2194 | AK6: 462.6874 | AL6: 504.1636 | AM6: 475.5916 | AN6: 485.4896 | AO6: 548.1358 | AQ6: =ROUND(G6*Z6,0) -> 815 | AR6: =ROUND(G6*AC6,0) -> 1302 | AS6: SU000722
A7: 016 Сосиски Вязанка Молочные, Вязанка вискофан ВЕС.ПОКОМ | B7: кг | C7: 1270.56 | D7: 2645.708 | E7: 1538.597 | F7: 2235.078 | G7: 1 | H7: 45 | I7: матрица | K7: 1535.45 | L7: =E7-K7 -> 3.147 | O7: 354.99048 | S7: 387.66743 | W7: =E7/5 -> 307.7194 | X7: =12*W7-S7-O7-F7 -> 714.89689 | Y7: =X7+$Y$1*W7 -> 1194.9392 | Z7: =Y7-AC7 -> 460.05157 | AC7: =Y7*$AC$1 -> 734.88758 | AD7: =(F7+O7+S7+Z7+AC7)/W7 -> 13.56 | AE7: =(F7+O7+S7)/W7 -> 9.6767897 | AF7: 321.2652 | AG7: 300.1066 | AH7: 262.3652 | AI7: 266.332 | AJ7: 285.4392 | AK7: 272.4182 | AL7: 253.4586 | AM7: 242.8768 | AN7: 235.5034 | AO7: 220.2848 | AQ7: =ROUND(G7*Z7,0) -> 460 | AR7: =ROUND(G7*AC7,0) -> 735 | AS7: SU001523
A8: 017 Сосиски Вязанка Сливочные, Вязанка амицел ВЕС.ПОКОМ | B8: кг | C8: 1317.427 | D8: 1889.173 | E8: 1286.434 | F8: 1816.946 | G8: 1 | H8: 45 | I8: матрица | K8: 1276.05 | L8: =E8-K8 -> 10.384 | O8: 385.51909 | S8: 421.0062 | W8: =E8/5 -> 257.2868 | X8: =12*W8-S8-O8-F8 -> 463.9703 | Y8: =X8+$Y$1*W8 -> 865.33771 | Z8: =Y8-AC8 -> 333.15502 | AC8: =Y8*$AC$1 -> 532.18269 | AD8: =(F8+O8+S8+Z8+AC8)/W8 -> 13.56 | AE8: =(F8+O8+S8)/W8 -> 10.196681 | AF8: 276.0038 | AG8: 247.2452 | AH8: 223.7616 | AI8: 249.8908 | AJ8: 251.5842 | AK8: 216.3372 | AL8: 214.1034 | AM8: 227.751 | AN8: 235.301 | AO8: 231.1304 | AQ8: =ROUND(G8*Z8,0) -> 333 | AR8: =ROUND(G8*AC8,0) -> 532 | AS8: SU001721
A9: 023 Колбаса Докторская ГОСТ, Вязанка вектор, 0,4 кг, ПОКОМ | B9: шт | G9: 0 | I9: матрица | L9: =E9-K9 -> 0 | O9: 0 | W9: =E9/5 -> 0 | Y9: =X9 -> 0 | Z9: =Y9-AC9 -> 0 | AD9: =(F9+O9+S9+Z9+AC9)/W9 -> #DIV/0! | AE9: =(F9+O9+S9)/W9 -> #DIV/0! | AF9: 0 | AG9: 0 | AH9: 0 | AI9: 0 | AJ9: 0 | AK9: 0 | AL9: 0 | AM9: 0 | AN9: 0 | AO9: 0 | AP9: нет потребности | AQ9: =ROUND(G9*Z9,0) -> 0 | AR9: =ROUND(G9*AC9,0) -> 0 | AS9: SU001485
A10: 030 Сосиски Вязанка Молочные, Вязанка вискофан МГС, 0.45кг, ПОКОМ | B10: шт | C10: 382 | D10: 1300 | E10: 551 | F10: 1020 | G10: 0.45 | H10: 45 | I10: матрица | K10: 587 | L10: =E10-K10 -> -36 | O10: 0 | W10: =E10/5 -> 110.2 | X10: =12*W10-S10-O10-F10 -> 302.4 | Y10: =X10+$Y$1*W10 -> 474.312 | Z10: =Y10-AC10 -> 182.61012 | AB10: 100 | AC10: =Y10*$AC$1 -> 291.70188 | AD10: =(F10+O10+S10+Z10+AC10+P10+Q10+T10+U10+R10+V10+AB10)/W10 -> 14.467441 | AE10: =(F10+O10+S10)/W10 -> 9.2558984 | AF10: 117.4 | AG10: 142.6 | AH10: 135.4 | AI10: 120.4 | AJ10: 117.2 | AK10: 118.2 | AL10: 139 | AM10: 136.8 | AN10: 124.8 | AO10: 110.6 | AQ10: =ROUND(G10*Z10,0) -> 82 | AR10: =ROUND(G10*AC10,0) -> 131 | AS10: SU001718 | AT10: =VLOOKUP(AS10,[1]Лист1!$A:$A,1,0) -> SU001718 | AU10: =Q10*G10 -> 0 | AV10: =ROUND(AB10*G10,0) -> 45
A11: 032 Сосиски Вязанка Сливочные, Вязанка амицел МГС, 0.45кг, ПОКОМ | B11: шт | C11: 964.76 | D11: 1855 | E11: 1226 | F11: 1403.76 | G11: 0.45 | H11: 45 | I11: матрица | K11: 1246 | L11: =E11-K11 -> -20 | O11: 352.18055 | S11: 384.59885 | W11: =E11/5 -> 245.2 | X11: =12*W11-S11-O11-F11 -> 801.8606 | Y11: =X11+$Y$1*W11 -> 1184.3726 | Z11: =Y11-AC11 -> 455.98345 | AC11: =Y11*$AC$1 -> 728.38915 | AD11: =(F11+O11+S11+Z11+AC11)/W11 -> 13.56 | AE11: =(F11+O11+S11)/W11 -> 8.7297692 | AF11: 245.4 | AG11: 235.2 | AH11: 216.8 | AI11: 224.448 | AJ11: 225.648 | AK11: 230.6 | AL11: 273.4 | AM11: 246.4 | AN11: 230.2 | AO11: 217 | AQ11: =ROUND(G11*Z11,0) -> 205 | AR11: =ROUND(G11*AC11,0) -> 328 | AS11: SU001720
A12: 047 Кол Баварская, белков.обол. в термоусад. пакете 0.17 кг, ТМ Стародворье ПОКОМ | B12: шт | C12: 83 | D12: 120 | E12: 83 | F12: 97 | G12: 0.17 | H12: 180 | I12: матрица | K12: 85 | L12: =E12-K12 -> -2 | O12: 79 | W12: =E12/5 -> 16.6 | X12: =12*W12-S12-O12-F12 -> 23.2 | Y12: =X12 -> 23.2 | Z12: =Y12-AC12 -> 23.2 | AD12: =(F12+O12+S12+Z12+AC12)/W12 -> 12 | AE12: =(F12+O12+S12)/W12 -> 10.60241 | AF12: 17.8 | AG12: 15.6 | AH12: 15 | AI12: 18.2 | AJ12: 17.2 | AK12: 10.2 | AL12: 14.6 | AM12: 20.2 | AN12: 15.2 | AO12: 11.8 | AQ12: =ROUND(G12*Z12,0) -> 4 | AR12: =ROUND(G12*AC12,0) -> 0 | AS12: SU002092
A13: 062 Колбаса Кракушка пряная с сальцем, 0.3кг в/у п/к, БАВАРУШКА ПОКОМ | B13: шт | C13: 154 | D13: 18 | E13: 105 | F13: 58 | G13: 0.3 | H13: 40 | I13: матрица | K13: 106 | L13: =E13-K13 -> -1 | O13: 97.8 | P13: -102 | W13: =E13/5 -> 21 | X13: =12*W13-S13-O13-F13 -> 96.2 | Y13: =X13 -> 96.2 | Z13: =Y13-AC13 -> 96.2 | AA13: -102 | AD13: =(F13+O13+S13+Z13+AC13)/W13 -> 12 | AE13: =(F13+O13+S13)/W13 -> 7.4190476 | AF13: 17.8 | AG13: 10.6 | AH13: 10 | AI13: 19 | AJ13: 21 | AK13: 22.2 | AL13: 22.8 | AM13: 17.6 | AN13: 17.8 | AO13: 9.2 | AQ13: =ROUND(G13*Z13,0) -> 29 | AR13: =ROUND(G13*AC13,0) -> 0 | AS13: SU002252
A14: 083 Колбаса Швейцарская 0,17 кг., ШТ., сырокопченая ПОКОМ | B14: шт | C14: 231 | D14: 375 | E14: 288 | F14: 293 | G14: 0.17 | H14: 180 | I14: матрица | K14: 288 | L14: =E14-K14 -> 0 | O14: 260.3402 | W14: =E14/5 -> 57.6 | X14: =12*W14-S14-O14-F14 -> 137.8598 | Y14: =X14 -> 137.8598 | Z14: =Y14-AC14 -> 137.8598 | AD14: =(F14+O14+S14+Z14+AC14)/W14 -> 12 | AE14: =(F14+O14+S14)/W14 -> 9.6066007 | AF14: 60.6 | AG14: 47.6 | AH14: 44.8 | AI14: 57.2 | AJ14: 52.8 | AK14: 33.6 | AL14: 38.4 | AM14: 56 | AN14: 56.2 | AO14: 45 | AQ14: =ROUND(G14*Z14,0) -> 23 | AR14: =ROUND(G14*AC14,0) -> 0 | AS14: SU001869
A15: 104 Сосиски Молочные по-стародворски, амицел МГС 0.45кг, ТМ Стародворье ПОКОМ | B15: шт | C15: -1 | F15: -1 | G15: 0 | I15: не в матрице | L15: =E15-K15 -> 0 | O15: 0 | W15: =E15/5 -> 0 | Y15: =X15 -> 0 | Z15: =Y15-AC15 -> 0 | AD15: =(F15+O15+S15+Z15+AC15)/W15 -> #DIV/0! | AE15: =(F15+O15+S15)/W15 -> #DIV/0! | AF15: 0 | AG15: 0 | AH15: 0 | AI15: 0 | AJ15: 0.2 | AK15: 0.2 | AL15: 0 | AM15: 0 | AN15: 0 | AO15: 0 | AQ15: =ROUND(G15*Z15,0) -> 0 | AR15: =ROUND(G15*AC15,0) -> 0 | AS15: SU001763
A16: 200 Ветчина Дугушка ТМ Стародворье, вектор в/у ПОКОМ | B16: кг | C16: 1742.112 | D16: 1772.821 | E16: 1143.703 | F16: 2269.288 | G16: 1 | H16: 70 | I16: матрица | K16: 1108.115 | L16: =E16-K16 -> 35.588 | O16: 0 | Q16: 400 | V16: 557 | W16: =E16/5 -> 228.7406 | X16: =12*W16-S16-O16-F16 -> 475.5992 | Y16: =X16 -> 475.5992 | Z16: =Y16-AC16 -> 183.10569 | AC16: =Y16*$AC$1 -> 292.49351 | AD16: =(F16+O16+S16+Z16+AC16+P16+Q16+T16+U16+R16+V16+AB16)/W16 -> 16.183778 | AE16: =(F16+O16+S16)/W16 -> 9.9207924 | AF16: 230.5266 | AG16: 233.1836 | AH16: 242.9832 | AI16: 239.7028 | AJ16: 236.7696 | AK16: 224.553 | AL16: 226.569 | AM16: 227.6094 | AN16: 217.932 | AO16: 228.4726 | AQ16: =ROUND(G16*Z16,0) -> 183 | AR16: =ROUND(G16*AC16,0) -> 292 | AS16: SU002035 | AT16: =VLOOKUP(AS16,[1]Лист1!$A:$A,1,0) -> SU002035 | AU16: =Q16*G16 -> 400 | AV16: =ROUND(AB16*G16,0) -> 0
A17: 201 Ветчина Нежная ТМ Особый рецепт, (2,5кг), ПОКОМ | B17: кг | C17: 5923.323 | D17: 2641.422 | E17: 3682.966 | F17: 4601.749 | G17: 1 | H17: 50 | I17: матрица | K17: 3701.751 | L17: =E17-K17 -> -18.785 | O17: 1090.019 | S17: 1190.3554 | U17: 450 | W17: =E17/5 -> 736.5932 | X17: =12*W17-S17-O17-F17 -> 1956.995 | Y17: =X17+$Y$1*W17 -> 3106.0804 | Z17: =Y17-AC17 -> 1195.841 | AB17: 700 | AC17: =Y17*$AC$1 -> 1910.2394 | AD17: =(F17+O17+S17+Z17+AC17+P17+Q17+T17+U17+R17+V17+AB17)/W17 -> 15.121242 | AE17: =(F17+O17+S17)/W17 -> 9.3431807 | AF17: 741.7268 | AG17: 660.6116 | AH17: 636.8632 | AI17: 674.4326 | AJ17: 703.1706 | AK17: 753.4372 | AL17: 789.1916 | AM17: 779.7954 | AN17: 746.6194 | AO17: 740.7606 | AQ17: =ROUND(G17*Z17,0) -> 1196 | AR17: =ROUND(G17*AC17,0) -> 1910 | AS17: SU000126 | AT17: =VLOOKUP(AS17,[1]Лист1!$A:$A,1,0) -> SU000126 | AU17: =Q17*G17 -> 0 | AV17: =ROUND(AB17*G17,0) -> 700
A18: 215 Колбаса Докторская ГОСТ Дугушка, ВЕС, ТМ Стародворье ПОКОМ | B18: кг | C18: 101.029 | D18: 217.462 | E18: 116.163 | F18: 191.749 | G18: 1 | H18: 60 | I18: матрица | K18: 113.29 | L18: =E18-K18 -> 2.873 | O18: 30.901 | W18: =E18/5 -> 23.2326 | X18: =12*W18-S18-O18-F18 -> 56.1412 | Y18: =X18 -> 56.1412 | Z18: =Y18-AC18 -> 56.1412 | AD18: =(F18+O18+S18+Z18+AC18)/W18 -> 12 | AE18: =(F18+O18+S18)/W18 -> 9.5835163 | AF18: 23.7644 | AG18: 25.4882 | AH18: 23.5362 | AI18: 24.8954 | AJ18: 24.5984 | AK18: 18.6858 | AL18: 21.4066 | AM18: 20.924 | AN18: 19.5894 | AO18: 22.2878 | AQ18: =ROUND(G18*Z18,0) -> 56 | AR18: =ROUND(G18*AC18,0) -> 0 | AS18: SU002011
A19: 225 Колбаса Дугушка со шпиком, ВЕС, ТМ Стародворье ПОКОМ | B19: кг | C19: 75.382 | D19: 139.154 | E19: 99.659 | F19: 111.399 | G19: 1 | H19: 60 | I19: матрица | K19: 97.22 | L19: =E19-K19 -> 2.439 | O19: 62.7086 | W19: =E19/5 -> 19.9318 | X19: =12*W19-S19-O19-F19 -> 65.074 | Y19: =X19 -> 65.074 | Z19: =Y19-AC19 -> 65.074 | AD19: =(F19+O19+S19+Z19+AC19)/W19 -> 12 | AE19: =(F19+O19+S19)/W19 -> 8.7351669 | AF19: 18.4558 | AG19: 16.8662 | AH19: 17.2274 | AI19: 14.8442 | AJ19: 17.3218 | AK19: 17.4784 | AL19: 13.7256 | AM19: 14.4166 | AN19: 16.773 | AO19: 16.836 | AQ19: =ROUND(G19*Z19,0) -> 65 | AR19: =ROUND(G19*AC19,0) -> 0 | AS19: SU002182
A20: 226 Колбаса Княжеская, с/к белков.обол в термоусад. пакете, ВЕС, ТМ Стародворье ПОКОМ | B20: кг | C20: 21.78 | D20: 5.768 | E20: 8.522 | F20: 15.788 | G20: 1 | H20: 180 | I20: матрица | K20: 8.35 | L20: =E20-K20 -> 0.172 | O20: 0 | W20: =E20/5 -> 1.7044 | X20: =12*W20-S20-O20-F20 -> 4.6648 | Y20: =X20 -> 4.6648 | Z20: =Y20-AC20 -> 4.6648 | AD20: =(F20+O20+S20+Z20+AC20)/W20 -> 12 | AE20: =(F20+O20+S20)/W20 -> 9.2630838 | AF20: 1.3306 | AG20: 0.6298 | AH20: 1.0428 | AI20: 2.0902 | AJ20: 2.1626 | AK20: 1.731 | AL20: 1.687 | AM20: 1.4314 | AN20: 1.4482 | AO20: 1.9716 | AQ20: =ROUND(G20*Z20,0) -> 5 | AR20: =ROUND(G20*AC20,0) -> 0 | AS20: SU001920
A21: 229 Колбаса Молочная Дугушка, в/у, ВЕС, ТМ Стародворье ПОКОМ | B21: кг | C21: 2270.755 | D21: 1127.692 | E21: 1364.653 | F21: 1909.526 | G21: 1 | H21: 60 | I21: матрица | K21: 1319.995 | L21: =E21-K21 -> 44.658 | O21: 303.49876 | S21: 331.43588 | W21: =E21/5 -> 272.9306 | X21: =12*W21-S21-O21-F21 -> 730.70656 | Y21: =X21+$Y$1*W21 -> 1156.4783 | Z21: =Y21-AC21 -> 445.24414 | AC21: =Y21*$AC$1 -> 711.23415 | AD21: =(F21+O21+S21+Z21+AC21)/W21 -> 13.56 | AE21: =(F21+O21+S21)/W21 -> 9.3227386 | AF21: 280.4986 | AG21: 283.1552 | AH21: 289.9638 | AI21: 276.8662 | AJ21: 268.4514 | AK21: 275.9112 | AL21: 284.7268 | AM21: 282.6728 | AN21: 268.6392 | AO21: 285.4614 | AQ21: =ROUND(G21*Z21,0) -> 445 | AR21: =ROUND(G21*AC21,0) -> 711 | AS21: SU002010
A22: 236 Колбаса Рубленая ЗАПЕЧ. Дугушка ТМ Стародворье, вектор, в/к ПОКОМ | B22: кг | C22: 156.485 | D22: 311.25 | E22: 249.477 | F22: 194.206 | G22: 1 | H22: 70 | I22: матрица | K22: 247.35 | L22: =E22-K22 -> 2.127 | O22: 271.41217 | W22: =E22/5 -> 49.8954 | X22: =12*W22-S22-O22-F22 -> 133.12663 | Y22: =X22 -> 133.12663 | Z22: =Y22-AC22 -> 133.12663 | AD22: =(F22+O22+S22+Z22+AC22)/W22 -> 12 | AE22: =(F22+O22+S22)/W22 -> 9.3318857 | AF22: 49.0822 | AG22: 37.724 | AH22: 35.753 | AI22: 35.9834 | AJ22: 37.6586 | AK22: 29.2252 | AL22: 30.3312 | AM22: 41.2404 | AN22: 40.3576 | AO22: 31.3566 | AQ22: =ROUND(G22*Z22,0) -> 133 | AR22: =ROUND(G22*AC22,0) -> 0 | AS22: SU002150
A23: 239 Колбаса Салями запеч Дугушка, оболочка вектор, ВЕС, ТМ Стародворье ПОКОМ | B23: кг | C23: 538.096 | D23: 441.946 | E23: 431.921 | F23: 517.871 | G23: 1 | H23: 70 | I23: матрица | K23: 418.35 | L23: =E23-K23 -> 13.571 | O23: 260.56065 | W23: =E23/5 -> 86.3842 | X23: =12*W23-S23-O23-F23 -> 258.17875 | Y23: =X23+$Y$1*W23 -> 392.9381 | Z23: =Y23-AC23 -> 151.28117 | AA23: -153.12 | AC23: =Y23*$AC$1 -> 241.65693 | AD23: =(F23+O23+S23+Z23+AC23)/W23 -> 13.56 | AE23: =(F23+O23+S23)/W23 -> 9.0112734 | AF23: 84.8442 | AG23: 79.9756 | AH23: 79.8802 | AI23: 85.5796 | AJ23: 89.1798 | AK23: 90.8622 | AL23: 89.5354 | AM23: 90.1674 | AN23: 90.7832 | AO23: 90.3426 | AQ23: =ROUND(G23*Z23,0) -> 151 | AR23: =ROUND(G23*AC23,0) -> 242 | AS23: SU002158
A24: 240 Колбаса Салями охотничья, ВЕС. ПОКОМ | B24: кг | G24: 0 | I24: матрица | L24: =E24-K24 -> 0 | O24: 0 | W24: =E24/5 -> 0 | Y24: =X24 -> 0 | Z24: =Y24-AC24 -> 0 | AD24: =(F24+O24+S24+Z24+AC24)/W24 -> #DIV/0! | AE24: =(F24+O24+S24)/W24 -> #DIV/0! | AF24: 0 | AG24: 0 | AH24: 0 | AI24: 0 | AJ24: 0 | AK24: 0 | AL24: 0 | AM24: 0 | AN24: 0 | AO24: 0 | AP24: нет потребности | AQ24: =ROUND(G24*Z24,0) -> 0 | AR24: =ROUND(G24*AC24,0) -> 0 | AS24: SU001921
A25: 242 Колбаса Сервелат ЗАПЕЧ.Дугушка ТМ Стародворье, вектор, в/к ПОКОМ | B25: кг | C25: 521.489 | D25: 1023.109 | E25: 679.241 | F25: 794.029 | G25: 1 | H25: 70 | I25: матрица | K25: 665.155 | L25: =E25-K25 -> 14.086 | O25: 448.44434 | W25: =E25/5 -> 135.8482 | X25: =12*W25-S25-O25-F25 -> 387.70506 | Y25: =X25+$Y$1*W25 -> 599.62826 | Z25: =Y25-AC25 -> 230.85688 | AA25: -232.32 | AC25: =Y25*$AC$1 -> 368.77138 | AD25: =(F25+O25+S25+Z25+AC25)/W25 -> 13.56 | AE25: =(F25+O25+S25)/W25 -> 9.1460419 | AF25: 138.0656 | AG25: 123.4304 | AH25: 120.0524 | AI25: 127.3804 | AJ25: 123.4118 | AK25: 117.6122 | AL25: 125.7372 | AM25: 138.39 | AN25: 139.7042 | AO25: 135.1922 | AQ25: =ROUND(G25*Z25,0) -> 231 | AR25: =ROUND(G25*AC25,0) -> 369 | AS25: SU002151
A26: 244 Колбаса Сервелат Кремлевский, ВЕС. ПОКОМ | B26: кг | C26: 195.62 | D26: 8.69 | E26: 157.724 | F26: 46.586 | G26: 1 | H26: 40 | I26: НЕДОГРУЗ / матрица | K26: 200.7 | L26: =E26-K26 -> -42.976 | O26: 50 | W26: =E26/5 -> 31.5448 | X26: 90 | Y26: =X26 -> 90 | Z26: =X26 -> 90 | AA26: -92.4 | AC26: =X26*0.5 -> 45 | AD26: =(F26+O26+S26+Z26+AC26)/W26 -> 7.3414953 | AE26: =(F26+O26+S26)/W26 -> 3.0618676 | AF26: 30.8242 | AG26: 25.3456 | AH26: 25.3456 | AI26: 29.3342 | AJ26: 30.3592 | AK26: 1.618 | AL26: 0.8882 | AM26: 28.8462 | AN26: 28.551 | AO26: 16.4596 | AQ26: =ROUND(G26*Z26,0) -> 90 | AR26: =ROUND(G26*AC26,0) -> 45 | AS26: SU001822
A27: 247 Сардельки Нежные, ВЕС. ПОКОМ | B27: кг | C27: 377.735 | D27: 268.71 | E27: 277.868 | F27: 339.792 | G27: 1 | H27: 30 | I27: матрица | K27: 289.2 | L27: =E27-K27 -> -11.332 | O27: 197.20011 | W27: =E27/5 -> 55.5736 | X27: =12*W27-S27-O27-F27 -> 129.89109 | Y27: =X27 -> 129.89109 | Z27: =Y27-AC27 -> 129.89109 | AD27: =(F27+O27+S27+Z27+AC27)/W27 -> 12 | AE27: =(F27+O27+S27)/W27 -> 9.6627196 | AF27: 57.696 | AG27: 53.5364 | AH27: 46.9894 | AI27: 50.7542 | AJ27: 52.6812 | AK27: 61.3154 | AL27: 65.9996 | AM27: 56.6406 | AN27: 57.6956 | AO27: 53.3138 | AQ27: =ROUND(G27*Z27,0) -> 130 | AR27: =ROUND(G27*AC27,0) -> 0 | AS27: SU001051
A28: 248 Сардельки Сочные ТМ Особый рецепт, ПОКОМ | B28: кг | C28: 0.235 | E28: -9.845 | F28: 0.235 | G28: 1 | H28: 40 | I28: НЕДОГРУЗ / матрица | K28: 79.7 | L28: =E28-K28 -> -89.545 | O28: 100 | P28: -108 | W28: =E28/5 -> -1.969 | X28: 100 | Y28: =X28 -> 100 | Z28: =X28 -> 100 | AA28: -108 | AC28: =X28*0.5 -> 50 | AD28: =(F28+O28+S28+Z28+AC28)/W28 -> -127.08735 | AE28: =(F28+O28+S28)/W28 -> -50.906552 | AF28: -1.5426 | AG28: 0.627 | AH28: 13.4148 | AI28: 42.743 | AJ28: 41.4948 | AK28: 42.4478 | AL28: 46.8592 | AM28: 44.1312 | AN28: 43.2066 | AO28: 39.3598 | AQ28: =ROUND(G28*Z28,0) -> 100 | AR28: =ROUND(G28*AC28,0) -> 50 | AS28: SU002287
A29: 250 Сардельки стародворские с говядиной в обол. NDX, ВЕС. ПОКОМ | B29: кг | C29: 247.591 | D29: 2594.23 | E29: 1878.28 | F29: 711.395 | G29: 1 | H29: 30 | I29: НЕДОГРУЗ / матрица | K29: 2030.781 | L29: =E29-K29 -> -152.501 | O29: 717 | S29: 783 | W29: =E29/5 -> 375.656 | X29: =11*W29-S29-O29-F29 -> 1920.821 | Y29: =X29 -> 1920.821 | Z29: =X29 -> 1920.821 | AA29: -500.6 | AC29: =X29*0.5 -> 960.4105 | AD29: =(F29+O29+S29+Z29+AC29)/W29 -> 13.556622 | AE29: =(F29+O29+S29)/W29 -> 5.8867554 | AF29: 362.0858 | AG29: 409.1834 | AH29: 406.6448 | AI29: 471.3384 | AJ29: 480.8798 | AK29: 213.437 | AL29: 215.164 | AM29: 450.7 | AN29: 450.2304 | AO29: 427.4828 | AQ29: =ROUND(G29*Z29,0) -> 1921 | AR29: =ROUND(G29*AC29,0) -> 960 | AS29: SU000227
A30: 251 Сосиски Баварские, ВЕС. ПОКОМ | B30: кг | C30: 0.437 | F30: 0.437 | G30: 0 | H30: 45 | I30: не в матрице | K30: 5.2 | L30: =E30-K30 -> -5.2 | O30: 0 | W30: =E30/5 -> 0 | Y30: =X30 -> 0 | Z30: =Y30-AC30 -> 0 | AD30: =(F30+O30+S30+Z30+AC30)/W30 -> #DIV/0! | AE30: =(F30+O30+S30)/W30 -> #DIV/0! | AF30: 0 | AG30: 0 | AH30: 0.26 | AI30: 1.5546 | AJ30: 4.6036 | AK30: 4.6284 | AL30: 3.6878 | AM30: 5.8214 | AN30: 3.9934 | AO30: 2.5616 | AQ30: =ROUND(G30*Z30,0) -> 0 | AR30: =ROUND(G30*AC30,0) -> 0 | AS30: SU001835
A31: 253 Сосиски Ганноверские ПОКОМ | B31: кг | C31: -0.257 | F31: -0.257 | G31: 0 | H31: 40 | I31: не в матрице | K31: 51.5 | L31: =E31-K31 -> -51.5 | O31: 0 | W31: =E31/5 -> 0 | Y31: =X31 -> 0 | Z31: =Y31-AC31 -> 0 | AD31: =(F31+O31+S31+Z31+AC31)/W31 -> #DIV/0! | AE31: =(F31+O31+S31)/W31 -> #DIV/0! | AF31: 0 | AG31: 0 | AH31: 0 | AI31: 0.7398 | AJ31: 1.2958 | AK31: 12.6168 | AL31: 11.9848 | AM31: 17.5422 | AN31: 20.3004 | AO31: 11.212 | AQ31: =ROUND(G31*Z31,0) -> 0 | AR31: =ROUND(G31*AC31,0) -> 0 | AS31: SU001340
A32: 255 Сосиски Молочные для завтрака ТМ Особый рецепт, п/а МГС, ВЕС, ТМ Стародворье ПОКОМ | B32: кг | C32: 3.748 | E32: -7.146 | F32: 3.748 | G32: 1 | H32: 40 | I32: НЕДОГРУЗ / матрица | K32: 321.4 | L32: =E32-K32 -> -328.546 | O32: 573.6 | S32: 626.4 | T32: -626 | W32: =E32/5 -> -1.4292 | X32: 1000 | Y32: =X32 -> 1000 | Z32: =X32 -> 1000 | AC32: 740 | AD32: =(F32+O32+S32+Z32+AC32)/W32 -> -2059.7173 | AE32: =(F32+O32+S32)/W32 -> -842.25301 | AF32: -0.5874 | AG32: -0.2024 | AH32: -0.2204 | AI32: 466.9548 | AJ32: 466.6568 | AK32: -1.0442 | AL32: 170.2936 | AM32: 540.2518 | AN32: 543.8248 | AO32: 632.0996 | AQ32: =ROUND(G32*Z32,0) -> 1000 | AR32: =ROUND(G32*AC32,0) -> 740 | AS32: SU002074
A33: 257 Сосиски Молочные оригинальные ТМ Особый рецепт, ВЕС. ПОКОМ | B33: кг | G33: 0 | I33: матрица | L33: =E33-K33 -> 0 | O33: 0 | W33: =E33/5 -> 0 | Y33: =X33 -> 0 | Z33: =Y33-AC33 -> 0 | AD33: =(F33+O33+S33+Z33+AC33)/W33 -> #DIV/0! | AE33: =(F33+O33+S33)/W33 -> #DIV/0! | AF33: 0 | AG33: 0 | AH33: 0 | AI33: 0 | AJ33: 0 | AK33: 0 | AL33: 0 | AM33: 0 | AN33: 0 | AO33: 0 | AP33: нет потребности | AQ33: =ROUND(G33*Z33,0) -> 0 | AR33: =ROUND(G33*AC33,0) -> 0 | AS33: SU000246
A34: 263 Шпикачки Стародворские, ВЕС. ПОКОМ | B34: кг | C34: 224.261 | D34: 105.424 | E34: 209.514 | F34: 73.827 | G34: 1 | H34: 30 | I34: НЕДОГРУЗ / матрица | K34: 227.7 | L34: =E34-K34 -> -18.186 | O34: 200 | W34: =E34/5 -> 41.9028 | X34: 150 | Y34: =X34 -> 150 | Z34: =X34 -> 150 | AC34: =X34*0.5 -> 75 | AD34: =(F34+O34+S34+Z34+AC34)/W34 -> 11.904383 | AE34: =(F34+O34+S34)/W34 -> 6.5348139 | AF34: 49.4908 | AG34: 47.4218 | AH34: 41.256 | AI34: 46.9576 | AJ34: 52.2822 | AK34: 40.8566 | AL34: 32.7374 | AM34: 46.5842 | AN34: 55.4348 | AO34: 52.496 | AQ34: =ROUND(G34*Z34,0) -> 150 | AR34: =ROUND(G34*AC34,0) -> 75 | AS34: SU001430
A35: 265 Колбаса Балыкбургская, ВЕС, ТМ Баварушка ПОКОМ | B35: кг | G35: 0 | I35: матрица | L35: =E35-K35 -> 0 | O35: 0 | W35: =E35/5 -> 0 | Y35: =X35 -> 0 | Z35: =Y35-AC35 -> 0 | AD35: =(F35+O35+S35+Z35+AC35)/W35 -> #DIV/0! | AE35: =(F35+O35+S35)/W35 -> #DIV/0! | AF35: 0 | AG35: 0 | AH35: 0 | AI35: 0 | AJ35: 0 | AK35: 0 | AL35: 0 | AM35: 0 | AN35: 0 | AO35: 0 | AP35: нет потребности | AQ35: =ROUND(G35*Z35,0) -> 0 | AR35: =ROUND(G35*AC35,0) -> 0 | AS35: SU002612
A36: 267 Колбаса Салями Филейбургская зернистая, оболочка фиброуз, ВЕС, ТМ Баварушка ПОКОМ | B36: кг | G36: 0 | I36: матрица | L36: =E36-K36 -> 0 | O36: 0 | W36: =E36/5 -> 0 | Y36: =X36 -> 0 | Z36: =Y36-AC36 -> 0 | AD36: =(F36+O36+S36+Z36+AC36)/W36 -> #DIV/0! | AE36: =(F36+O36+S36)/W36 -> #DIV/0! | AF36: 0 | AG36: 0 | AH36: 0 | AI36: 0 | AJ36: 0 | AK36: 0 | AL36: 0 | AM36: 0 | AN36: 0 | AO36: 0 | AP36: нет потребности | AQ36: =ROUND(G36*Z36,0) -> 0 | AR36: =ROUND(G36*AC36,0) -> 0 | AS36: SU002614
A37: 273 Сосиски Сочинки с сочной грудинкой, МГС 0.4кг, ПОКОМ | B37: шт | C37: -26.06 | D37: 4200 | E37: 1753 | F37: 1765.94 | G37: 0.4 | H37: 45 | I37: НЕДОГРУЗ / матрица | K37: 2927 | L37: =E37-K37 -> -1174 | O37: 1434 | S37: 1566 | W37: =E37/5 -> 350.6 | X37: 2000 | Y37: =X37 -> 2000 | Z37: =X37 -> 2000 | AC37: =X37*0.5 -> 1000 | AD37: =(F37+O37+S37+Z37+AC37)/W37 -> 22.150428 | AE37: =(F37+O37+S37)/W37 -> 13.593668 | AF37: 627.6 | AG37: 957.4 | AH37: 972 | AI37: 989.812 | AJ37: 974.612 | AK37: 922.4 | AL37: 935.8 | AM37: 879.4 | AN37: 846.3586 | AO37: 867.7586 | AQ37: =ROUND(G37*Z37,0) -> 800 | AR37: =ROUND(G37*AC37,0) -> 400 | AS37: SU002618 | AU37: =Q37*G37 -> 0
A38: 276 Колбаса Сливушка ТМ Вязанка в оболочке полиамид 0,45 кг ПОКОМ | B38: шт | C38: 191 | D38: 1050 | E38: 484 | F38: 658 | G38: 0.45 | H38: 50 | I38: матрица | K38: 486 | L38: =E38-K38 -> -2 | O38: 234.8454 | W38: =E38/5 -> 96.8 | X38: =12*W38-S38-O38-F38 -> 268.7546 | Y38: =X38+$Y$1*W38 -> 419.7626 | Z38: =Y38-AC38 -> 161.6086 | AC38: =Y38*$AC$1 -> 258.154 | AD38: =(F38+O38+S38+Z38+AC38)/W38 -> 13.56 | AE38: =(F38+O38+S38)/W38 -> 9.2236095 | AF38: 99.2 | AG38: 105.4 | AH38: 102.8 | AI38: 77.8 | AJ38: 75 | AK38: 65 | AL38: 95.6 | AM38: 101.8 | AN38: 92.4 | AO38: 96.2 | AQ38: =ROUND(G38*Z38,0) -> 73 | AR38: =ROUND(G38*AC38,0) -> 116 | AS38: SU002734
A39: 278 Сосиски Сочинки с сочным окороком, МГС 0.4кг, ПОКОМ | B39: шт | C39: -28 | D39: 300 | E39: 295 | F39: -30 | G39: 0.4 | H39: 45 | I39: НЕДОГРУЗ / матрица | K39: 814 | L39: =E39-K39 -> -519 | O39: 500 | W39: =E39/5 -> 59 | X39: 400 | Y39: =X39 -> 400 | Z39: =X39 -> 400 | AA39: -402 | AC39: =X39*0.5 -> 200 | AD39: =(F39+O39+S39+Z39+AC39)/W39 -> 18.135593 | AE39: =(F39+O39+S39)/W39 -> 7.9661017 | AF39: 102.6 | AG39: 216.8 | AH39: 259 | AI39: 245.2 | AJ39: 165.6 | AK39: 105.6 | AL39: 196.2 | AM39: 218.8 | AN39: 207.2 | AO39: 223 | AQ39: =ROUND(G39*Z39,0) -> 160 | AR39: =ROUND(G39*AC39,0) -> 80 | AS39: SU002621 | AU39: =Q39*G39 -> 0
A40: 281 Сосиски Молочные для завтрака ТМ Особый рецепт, 0,4кг ПОКОМ | B40: шт | C40: 22 | E40: 22 | G40: 0.4 | H40: 40 | I40: НЕДОГРУЗ / матрица | K40: 25 | L40: =E40-K40 -> -3 | O40: 30 | P40: -30 | W40: =E40/5 -> 4.4 | X40: 20 | Y40: =X40 -> 20 | Z40: =X40 -> 20 | AA40: -24 | AC40: =X40*0.5 -> 10 | AD40: =(F40+O40+S40+Z40+AC40)/W40 -> 13.636364 | AE40: =(F40+O40+S40)/W40 -> 6.8181818 | AF40: 7.2 | AG40: 3.8 | AH40: 2.6 | AI40: 3.6 | AJ40: 2.2 | AK40: 2.6 | AL40: 5.4 | AM40: 4 | AN40: 1.4 | AO40: 2.8 | AQ40: =ROUND(G40*Z40,0) -> 8 | AR40: =ROUND(G40*AC40,0) -> 4 | AS40: SU002205
...

Sheet недогруз 22,08
A1: SU002205 | B1: Сосиски «Молочные для завтрака» Фикс.вес 0,4 П/а мгс ТМ «Особый рецепт» | C1: 12 | D1: -12
A2: SU002252 | B2: П/к колбасы Кракушка пряная с сальцем Бавария Фикс.вес 0,3 н/о в/у Стародворье | C2: 30.6 | D2: -30.6
A3: SU002287 | B3: Сардельки «Сочные» Весовой п/а ТМ «Особый рецепт» | C3: 108 | D3: -108
A4: SU002621 | B4: Сосиски «Сочинки с сочным окороком» Фикс.вес 0,4 П/а мгс ТМ «Стародворье» | C4: 201.6 | D4: -201.6
A5: SU002655 | B5: Сосиски «Датские» Весовой п/а ТМ «Зареченские продукты» | C5: 54 | D5: -54
A6: SU002660 | B6: Колбаса Мясорубская ТМ Стародворье с рубленой грудинкой в оболочке фиброуз в вакуумной упаковке 0,35 кг срез | C6: 35.7 | D6: -35.7
A7: SU002725 | B7: Сосиски «Сочинки» Весовой п/а ТМ «Стародворье» | C7: 226.2 | D7: -226.2
A8: SU002758 | B8: Сардельки «Сочинки» Фикс.вес 0,4 п/а ТМ «Стародворье» | C8: 60 | D8: -60
A9: SU002844 | B9: Сосиски «Сочинки Сливочные» Фикс.вес 0,4 п/а мгс ТМ «Стародворье» | C9: 148.8 | D9: -148.8
A10: SU002848 | B10: В/к колбасы Сервелат Мясорубский с мелкорубленным окороком срез Бордо Фикс.вес 0,35 фиброуз Стародворье | C10: 100.8 | D10: -100.8
A11: SU002941 | B11: В/к колбасы «Сочинка по-европейски с сочной грудинкой» Весовой фиброуз ТМ «Стародворье» | C11: 345.6 | D11: -345.6
A12: SU002942 | B12: В/к колбасы «Сочинка по-фински с сочным окороком» срез Фикс.вес 0,3 фиброуз ТМ «Стародворье» | C12: 45 | D12: -45
... A19: SU004042 | B19: Копченые колбасы «Сервелат Ореховый» Фикс.вес 0,28 фиброуз срез ТМ «Вязанка» | C19: 57.12 | D19: -57.12

Sheet недогруз 24,08
A1: SU000126 | B1: Ветчины Нежная Особая Особая Весовые П/а Особый рецепт большой батон | D1: 1200
A2: SU000227 | B2: Сардельки «Стародворские с говядиной» Весовые NDX ТМ «Стародворье» | C2: -500.6 | D2: 1926.6
A3: SU000722 | B3: Вареные колбасы Докторская ГОСТ Вязанка Весовые Вектор Вязанка | D3: 820.8
A4: SU001051 | B4: Сардельки «Нежные» Весовые NDX мгс ТМ «Стародворье» | D4: 134.4
A5: SU001430 | B5: Сардельки «Шпикачки Стародворские» Весовой NDX ТМ «Стародворье» | D5: 151.2
A6: SU001523 | B6: Сосиски «Молокуши (Вязанка Молочные)» Весовой п/а мгс ТМ «Вязанка» | D6: 461.7
A7: SU001718 | B7: Сосиски «Молокуши» ф/в 0,45 п/а мгс ТМ «Вязанка» | D7: 83.7
A8: SU001720 | B8: Сосиски «Сливочные» ф/в 0,45 п/а мгс ТМ «Вязанка» | D8: 205.2
A9: SU001721 | B9: Сосиски «Сливочные Вязанка» Весовой п/а мгс ТМ «Вязанка» | D9: 340.2
A10: SU001822 | B10: В/к колбасы Кремлевский Бордо Весовые Фиброуз в/у Стародворье | C10: -92.4 | D10: 92.4
A11: SU001869 | B11: С/к колбасы Швейцарская Бордо Фикс.вес 0,17 Фиброуз терм/п Стародворье | D11: 25.5
A12: SU001920 | B12: С/к колбасы Княжеская Бордо Весовые б/о терм/п Стародворье | D12: 6.08
A13: SU002010 | B13: Вареные колбасы «Молочная Дугушка» Весовые Вектор ТМ «Дугушка» | D13: 448.8
A14: SU002011 | B14: Вареные колбасы Докторская ГОСТ Дугушка Весовые Вектор Дугушка | D14: 58.08
A15: SU002035 | B15: Ветчины Дугушка Дугушка Вес б/о Дугушка | D15: 184.8
A16: SU002074 | B16: Сосиски «Молочные для завтрака» Весовой п/а ТМ «Особый рецепт» | D16: 1008
A17: SU002092 | B17: С/к колбасы Баварская Бавария Фикс.вес 0,17 б/о терм/п Стародворье | D17: 5.1
A18: SU002150 | B18: В/к колбасы «Рубленая Запеченная» Весовые Вектор ТМ «Дугушка» | D18: 137.28
A19: SU002151 | B19: В/к колбасы «Сервелат Запеченный» Весовые Вектор ТМ «Дугушка» | C19: -232.32 | D19: 232.32
A20: SU002158 | B20: В/к колбасы «Салями Запеченая» Весовые ТМ «Дугушка» | C20: -153.12 | D20: 153.12
A21: SU002182 | B21: Вареные колбасы «Дугушка со шпиком» Весовой Вектор ТМ «Дугушка» | D21: 68.64
A22: SU002205 | B22: Сосиски «Молочные для завтрака» Фикс.вес 0,4 П/а мгс ТМ «Особый рецепт» | C22: -9.6 | D22: 9.6
A23: SU002252 | B23: П/к колбасы Кракушка пряная с сальцем Бавария Фикс.вес 0,3 н/о в/у Стародворье | C23: -30.6 | D23: 30.6
A24: SU002287 | B24: Сардельки «Сочные» Весовой п/а ТМ «Особый рецепт» | C24: -108 | D24: 108
A25: SU002354 | B25: Вареные колбасы «Молокуша» Фикс.вес 0,17 нарезка ТМ «Вязанка» | D25: 1.7
A26: SU002356 | B26: Ветчины «Сливушка с индейкой» Фикс.вес 0,1 нарезка ТМ «Вязанка» | C26: -3 | D26: 3
A27: SU002367 | B27: Сардельки «Сливушки» фикс.вес 0,33 п/а мгс ТМ «Вязанка» | D27: 31.68
A28: SU002368 | B28: Паштеты Со сливочным маслом ГОСТ Бордо фикс.вес 0,1 Стародворье | D28: 20
A29: SU002618 | B29: Сосиски «Сочинки с сочной грудинкой» Фикс.вес 0,4 П/а мгс ТМ «Стародворье» | D29: 801.6
A30: SU002621 | B30: Сосиски «Сочинки с сочным окороком» Фикс.вес 0,4 П/а мгс ТМ «Стародворье» | C30: -160.8 | D30: 160.8
A31: SU002631 | B31: Вареные колбасы «Молочная Дугушка» Фикс.вес 0,6 П/а ТМ «Дугушка» | D31: 9.6
A32: SU002632 | B32: Вареные колбасы «Докторская ГОСТ» Фикс.вес 0,6 п/а ТМ «Дугушка» | D32: 33.6
A33: SU002634 | B33: Вареные колбасы «Дугушка Стародворская» Вес п/а ТМ «Дугушка» | D33: 306.24
A34: SU002643 | B34: Ветчины «Дугушка» Фикс.вес 0,6 полиамид ТМ «Дугушка» | D34: 57.6
A35: SU002655 | B35: Сосиски «Датские» Весовой п/а ТМ «Зареченские продукты» | C35: -45 | D35: 45
A36: SU002660 | B36: Колбаса Мясорубская ТМ Стародворье с рубленой грудинкой в оболочке фиброуз в вакуумной упаковке 0,35 кг срез | C36: -35.7 | D36: 35.7
A37: SU002686 | B37: Сосиски Сочинки с сыром Бордо ф/в 0,4 кг п/а Стародворье | D37: 120
A38: SU002725 | B38: Сосиски «Сочинки» Весовой п/а ТМ «Стародворье» | D38: 165.3
A39: SU002734 | B39: Вареные колбасы Сливушка Вязанка Фикс.вес 0,45 П/а Вязанка | D39: 76.5
A40: SU002735 | B40: Ветчины «Сливушка с индейкой» Фикс.вес 0,4 п/а ТМ «Вязанка» | D40: 36
...
