Workbook

Sheet Sheet
A3: Номенклатура | B3: Ед. изм. | C3: Начальный остаток | D3: Приход | E3: Расход | F3: Конечный остаток | G3: крат | H3: сроки | I3: метка | J3: метка2 | K3: заяв | L3: разн | M3: без опта | N3: опт | O3: заказ в пути | P3: ср нов | Q3: расчет | R3: заказ | S3: ТК | T3: кон ост | U3: факт | V3: ср | W3: ср | X3: ср | Y3: ср | Z3: ср | AA3: ср | AB3: ср | AC3: ср | AD3: ср | AE3: ср | AF3: комментарии | AG3: вес
O4: 31,08, | P4: 31,08, | R4: 07,09, | S4: Чепрасова | V4: 24,08, | W4: 17,08, | X4: 10,08, | Y4: 03,08, | Z4: 27,07, | AA4: 20,07, | AB4: 13,07, | AC4: 06,07, | AD4: 29,06, | AE4: 22,06,
E5: =SUM(E6:E484) -> 13326.728 | F5: =SUM(F6:F484) -> 22297.967 | K5: =SUM(K6:K484) -> 14533.974 | L5: =SUM(L6:L484) -> -1207.246 | M5: =SUM(M6:M484) -> 0 | N5: =SUM(N6:N484) -> 0 | O5: =SUM(O6:O484) -> 9806 | P5: =SUM(P6:P484) -> 2665.3456 | Q5: =SUM(Q6:Q484) -> 10498.171 | R5: =SUM(R6:R484) -> 11061 | S5: =SUM(S6:S484) -> 1450 | V5: =SUM(V6:V484) -> 2675.4276 | W5: =SUM(W6:W484) -> 3087.9252 | X5: =SUM(X6:X484) -> 2393.9494 | Y5: =SUM(Y6:Y484) -> 2434.1146 | Z5: =SUM(Z6:Z484) -> 2654.1074 | AA5: =SUM(AA6:AA484) -> 2195.3986 | AB5: =SUM(AB6:AB484) -> 2190.4328 | AC5: =SUM(AC6:AC484) -> 2309.5252 | ... AE5: =SUM(AE6:AE484) -> 2228.9382 | AG5: =SUM(AG6:AG484) -> 5260.97
A6: 3215 ВЕТЧ.МЯСНАЯ Папа может п/о 0.4кг 8шт. ОСТАНКИНО | B6: шт | C6: 135 | D6: 181 | E6: 162 | F6: 106 | G6: 0.4 | H6: 60 | I6: матрица | K6: 162 | L6: =E6-K6 -> 0 | O6: 33 | P6: =E6/5 -> 32.4 | Q6: =12*P6-O6-F6 -> 249.8 | R6: =ROUND(Q6,0) -> 250 | T6: =(F6+O6+R6)/P6 -> 12.006173 | U6: =(F6+O6)/P6 -> 4.2901235 | V6: 20.2 | W6: 22.6 | X6: 23.2 | Y6: 21.8 | Z6: 34.4 | AA6: 33.4 | AB6: 17.2 | AC6: 43.6 | AD6: 24.8 | AE6: 43.4 | AG6: =G6*R6 -> 100
A7: 3287 САЛЯМИ ИТАЛЬЯНСКАЯ с/к в/у ОСТАНКИНО | B7: кг | C7: 14.849 | D7: 38.008 | E7: 4.97 | F7: 46.28 | G7: 1 | H7: 120 | I7: матрица | K7: 5 | L7: =E7-K7 -> -0.03 | O7: 30 | P7: =E7/5 -> 0.994 | R7: =ROUND(Q7,0) -> 0 | T7: =(F7+O7+R7)/P7 -> 76.740443 | U7: =(F7+O7)/P7 -> 76.740443 | V7: 2.5046 | W7: 4.4006 | X7: 1.4884 | Y7: 3.4176 | Z7: 1.4924 | AA7: 1.8888 | AB7: 1.8836 | AC7: 1.478 | AD7: 0.867 | AE7: 1.761 | AF7: нужно увеличить продажи / плюсом 5 дней | AG7: =G7*R7 -> 0
A8: 3986 Ароматная с/к в/у 1/250 ОСТАНКИНО | B8: шт | C8: 68 | D8: 78 | E8: 36 | F8: 99 | G8: 0.25 | H8: 120 | I8: матрица | K8: 36 | L8: =E8-K8 -> 0 | O8: 10 | P8: =E8/5 -> 7.2 | R8: 50 | S8: =VLOOKUP(A8,[1]Sheet!$A:$R,18,0) -> 300 | T8: =(F8+O8+R8)/P8 -> 22.083333 | U8: =(F8+O8)/P8 -> 15.138889 | V8: 10.4 | W8: 12.6 | X8: 8.4 | Y8: 11.4 | Z8: 13.6 | AA8: 8.2 | AB8: 10.2 | AC8: 7 | AD8: 11.4 | AE8: 10.2 | AF8: плюсом 5 дней | AG8: =G8*R8 -> 12.5
A9: 4063 МЯСНАЯ Папа может вар п/о_Л ОСТАНКИНО | B9: кг | C9: 638.965 | D9: 1974.305 | E9: 942.877 | F9: 1528.103 | G9: 1 | H9: 60 | I9: матрица | K9: 1052.1 | L9: =E9-K9 -> -109.223 | O9: 0 | P9: =E9/5 -> 188.5754 | Q9: =15*P9-O9-F9 -> 1300.528 | R9: =ROUND(Q9,0) -> 1301 | T9: =(F9+O9+R9)/P9 -> 15.002503 | U9: =(F9+O9)/P9 -> 8.1034059 | V9: 112.445 | W9: 197.815 | X9: 137.0042 | Y9: 134.9372 | Z9: 131.2398 | AA9: 130.735 | AB9: 106.291 | AC9: 127.9742 | AD9: 158.0384 | AE9: 114.2396 | AG9: =G9*R9 -> 1301
A10: 4117 ЭКСТРА Папа может с/к в/у_Л ОСТАНКИНО | B10: кг | C10: 38.613 | D10: 138.837 | E10: 21.442 | F10: 136.68 | G10: 1 | H10: 120 | I10: матрица | K10: 21.484 | L10: =E10-K10 -> -0.042 | O10: 0 | P10: =E10/5 -> 4.2884 | R10: =ROUND(Q10,0) -> 0 | T10: =(F10+O10+R10)/P10 -> 31.872027 | U10: =(F10+O10)/P10 -> 31.872027 | V10: 2.2122 | W10: 12.5686 | X10: 1.1908 | Y10: 6.0012 | Z10: 5.9808 | AA10: 1.9032 | AB10: 4.136 | AC10: 5.2066 | AD10: 5.0554 | AE10: 3.4814 | AF10: нужно увеличить продажи / плюсом 5 дней | AG10: =G10*R10 -> 0
A11: 4574 Мясная со шпиком Папа может вар п/о ОСТАНКИНО | B11: кг | C11: 143.947 | D11: 450.809 | E11: 145.267 | F11: 382.469 | G11: 1 | H11: 60 | I11: ВНИМАНИЕ / матрица | K11: 141.9 | L11: =E11-K11 -> 3.367 | O11: 182 | P11: =E11/5 -> 29.0534 | R11: =ROUND(Q11,0) -> 0 | T11: =(F11+O11+R11)/P11 -> 19.428673 | U11: =(F11+O11)/P11 -> 19.428673 | V11: 45.8638 | W11: 58.7442 | X11: 34.6208 | Y11: 39.8292 | Z11: 35.1408 | AA11: 33.5112 | AB11: 35.876 | AC11: 29.5872 | AD11: 41.2212 | AE11: 41.7146 | AF11: Главторг | AG11: =G11*R11 -> 0
A12: 4813 ФИЛЕЙНАЯ Папа может вар п/о_Л ОСТАНКИНО | B12: кг | C12: 298.732 | D12: 401.624 | E12: 249.659 | F12: 361.323 | G12: 1 | H12: 60 | I12: матрица | K12: 239.75 | L12: =E12-K12 -> 9.909 | O12: 307 | P12: =E12/5 -> 49.9318 | Q12: =15*P12-O12-F12 -> 80.654 | R12: =ROUND(Q12,0) -> 81 | T12: =(F12+O12+R12)/P12 -> 15.006929 | U12: =(F12+O12)/P12 -> 13.384717 | V12: 53.7774 | W12: 54.776 | X12: 52.1532 | Y12: 61.4394 | Z12: 52.1158 | AA12: 47.9068 | AB12: 52.5086 | AC12: 44.5054 | AD12: 67.461 | AE12: 68.8962 | AG12: =G12*R12 -> 81
A13: 4993 САЛЯМИ ИТАЛЬЯНСКАЯ с/к в/у 1/250*8_120c ОСТАНКИНО | B13: шт | C13: 69 | D13: 81 | E13: 46 | F13: 88 | G13: 0.25 | H13: 120 | I13: матрица | K13: 46 | L13: =E13-K13 -> 0 | O13: 0 | P13: =E13/5 -> 9.2 | Q13: =15*P13-O13-F13 -> 50 | R13: =ROUND(Q13,0) -> 50 | T13: =(F13+O13+R13)/P13 -> 15 | U13: =(F13+O13)/P13 -> 9.5652174 | V13: 7.2 | W13: 11.8 | X13: 8.6 | Y13: 10.6 | Z13: 12.4 | AA13: 14.4 | AB13: 15.4 | AC13: 17.4 | AD13: 15.8 | AE13: 8.8 | AF13: плюсом 5 дней | AG13: =G13*R13 -> 12.5
A14: 5452 ВЕТЧ.МЯСНАЯ Папа может п/о ОСТАНКИНО | B14: кг | C14: 85.708 | D14: 177.402 | E14: 80.61 | F14: 133.162 | G14: 1 | H14: 60 | I14: матрица | K14: 99.15 | L14: =E14-K14 -> -18.54 | O14: 50 | P14: =E14/5 -> 16.122 | Q14: =15*P14-O14-F14 -> 58.668 | R14: =ROUND(Q14,0) -> 59 | T14: =(F14+O14+R14)/P14 -> 15.020593 | U14: =(F14+O14)/P14 -> 11.360997 | V14: 7.6434 | W14: 14.446 | X14: 12.6616 | Y14: 8.7746 | Z14: 7.3464 | AA14: 9.1446 | AB14: 6.137 | AC14: 15.6576 | AD14: 16.7228 | AE14: 16.991 | AG14: =G14*R14 -> 59
A15: 5483 ЭКСТРА Папа может с/к в/у 1/250 8шт. ОСТАНКИНО | B15: шт | C15: 470 | D15: 35 | E15: 165 | F15: 287 | G15: 0.25 | H15: 120 | I15: ВНИМАНИЕ / матрица | K15: 160 | L15: =E15-K15 -> 5 | O15: 76 | P15: =E15/5 -> 33 | Q15: =15*P15-O15-F15 -> 132 | R15: 300 | S15: =VLOOKUP(A15,[1]Sheet!$A:$R,18,0) -> 300 | T15: =(F15+O15+R15)/P15 -> 20.090909 | U15: =(F15+O15)/P15 -> 11 | V15: 38.4 | W15: 24.2 | X15: 15.6 | Y15: 29.6 | Z15: 22.2 | AA15: 26.8 | AB15: 19.6 | AC15: 19.8 | AD15: 15.4 | AE15: 22.2 | AF15: плюсом 5 дней / Главторг | AG15: =G15*R15 -> 75
A16: 5495 ВЕТЧ.С ИНДЕЙКОЙ Папа может п/о 400*6 Останкино | B16: шт | C16: 193 | D16: 89 | E16: 98 | F16: 157 | G16: 0.4 | H16: 60 | I16: матрица | K16: 103 | L16: =E16-K16 -> -5 | O16: 27 | P16: =E16/5 -> 19.6 | Q16: =15*P16-O16-F16 -> 110 | R16: =ROUND(Q16,0) -> 110 | T16: =(F16+O16+R16)/P16 -> 15 | U16: =(F16+O16)/P16 -> 9.3877551 | V16: 18.6 | W16: 22.4 | X16: 16.4 | Y16: 31.4 | Z16: 28.8 | AA16: 21 | AB16: 22.2 | AC16: 24.8 | AD16: 28.4 | AE16: 25.2 | AG16: =G16*R16 -> 44
A17: 5544 Сервелат Финский в/к в/у_45с НОВАЯ ОСТАНКИНО | B17: кг | C17: 159.531 | D17: 856.964 | E17: 202.669 | F17: 677.176 | G17: 1 | H17: 45 | I17: матрица | K17: 196.4 | L17: =E17-K17 -> 6.269 | O17: 150 | P17: =E17/5 -> 40.5338 | R17: =ROUND(Q17,0) -> 0 | T17: =(F17+O17+R17)/P17 -> 20.407068 | U17: =(F17+O17)/P17 -> 20.407068 | V17: 50.5528 | W17: 79.149 | X17: 31.593 | Y17: 57.8962 | Z17: 45.7606 | AA17: 39.7852 | AB17: 38.8656 | AC17: 68.3928 | AD17: 51.934 | AE17: 60.9788 | AG17: =G17*R17 -> 0
A18: 5708 ПОСОЛЬСКАЯ Папа может с/к в/у ОСТАНКИНО | B18: кг | C18: 57.879 | D18: 116.028 | E18: 42.738 | F18: 103.31 | G18: 1 | H18: 120 | I18: матрица | K18: 58.4 | L18: =E18-K18 -> -15.662 | O18: 0 | P18: =E18/5 -> 8.5476 | Q18: =15*P18-O18-F18 -> 24.904 | R18: =ROUND(Q18,0) -> 25 | T18: =(F18+O18+R18)/P18 -> 15.011231 | U18: =(F18+O18)/P18 -> 12.086434 | V18: 6.8586 | W18: 10.388 | X18: 6.555 | Y18: 6.0966 | Z18: 6.272 | AA18: 2.3836 | AB18: 3.8856 | AC18: 5.706 | AD18: 6.0518 | AE18: 3.9136 | AF18: плюсом 5 дней | AG18: =G18*R18 -> 25
A19: 5819 Сосиски Папа может 400г Мясные ОСТАНКИНО | B19: шт | C19: 75 | D19: 141 | E19: 42 | F19: 139 | G19: 0.4 | H19: 45 | I19: матрица | K19: 44 | L19: =E19-K19 -> -2 | O19: 0 | P19: =E19/5 -> 8.4 | R19: =ROUND(Q19,0) -> 0 | T19: =(F19+O19+R19)/P19 -> 16.547619 | U19: =(F19+O19)/P19 -> 16.547619 | V19: 10.4 | W19: 12 | X19: 13.4 | Y19: 8.4 | Z19: 10.8 | AA19: 9.2 | AB19: 16.6 | AC19: 12.8 | AD19: 17.6 | AE19: 10.8 | AG19: =G19*R19 -> 0
A20: 5851 ЭКСТРА Папа может вар п/о ОСТАНКИНО | B20: кг | C20: 2.245 | D20: 533.266 | E20: 204.779 | F20: 255.152 | G20: 1 | H20: 60 | I20: матрица | K20: 399.4 | L20: =E20-K20 -> -194.621 | O20: 250 | P20: =E20/5 -> 40.9558 | Q20: =15*P20-O20-F20 -> 109.185 | R20: =ROUND(Q20,0) -> 109 | T20: =(F20+O20+R20)/P20 -> 14.995483 | U20: =(F20+O20)/P20 -> 12.334077 | V20: 44.3436 | W20: 53.4098 | X20: 29.6076 | Y20: 39.8716 | Z20: 43.7824 | AA20: 35.394 | AB20: 51.5266 | AC20: 31.5036 | AD20: 52.6226 | AE20: 44.6156 | AG20: =G20*R20 -> 109
A21: 5931 ОХОТНИЧЬЯ Папа может с/к в/у 1/220 8шт. ОСТАНКИНО | B21: шт | C21: 401 | D21: 689 | E21: 519 | F21: 451 | G21: 0.22 | H21: 120 | I21: матрица | K21: 536 | L21: =E21-K21 -> -17 | O21: 600 | P21: =E21/5 -> 103.8 | Q21: =15*P21-O21-F21 -> 506 | R21: =ROUND(Q21,0) -> 506 | T21: =(F21+O21+R21)/P21 -> 15 | U21: =(F21+O21)/P21 -> 10.125241 | V21: 95.4 | W21: 97.4 | X21: 81.8 | Y21: 78.4 | Z21: 92.2 | AA21: 66.2 | AB21: 109.8 | AC21: 89.8 | AD21: 30.6 | AE21: 80.6 | AF21: плюсом 5 дней | AG21: =G21*R21 -> 111.32
A22: 6008 САЛО СОЛЕНОЕ С ЧЕРНЫМ ПЕРЦЕМ мл/к в/у ОСТАНКИНО | B22: кг | C22: 8.75 | D22: 72.106 | E22: 34.172 | F22: 37.926 | G22: 1 | H22: 40 | I22: матрица | K22: 34.05 | L22: =E22-K22 -> 0.122 | O22: 40 | P22: =E22/5 -> 6.8344 | Q22: =15*P22-O22-F22 -> 24.59 | R22: =ROUND(Q22,0) -> 25 | T22: =(F22+O22+R22)/P22 -> 15.059991 | U22: =(F22+O22)/P22 -> 11.402025 | V22: 6.0042 | W22: 7.3088 | X22: 5.0584 | Y22: -0.3304 | Z22: 8.4344 | AA22: 6.0996 | AB22: 4.2108 | AC22: 8.4652 | AD22: 2.464 | AE22: 0 | AF22: 90кг в уценку (21,07,26) | AG22: =G22*R22 -> 25
A23: 6220 ГОВЯЖЬЯ папа может вар п/о Останкино | B23: кг | C23: 177.823 | D23: 197.069 | E23: 135.153 | F23: 229.426 | G23: 1 | H23: 60 | I23: матрица | K23: 131.2 | L23: =E23-K23 -> 3.953 | O23: 60 | P23: =E23/5 -> 27.0306 | Q23: =15*P23-O23-F23 -> 116.033 | R23: =ROUND(Q23,0) -> 116 | T23: =(F23+O23+R23)/P23 -> 14.998779 | U23: =(F23+O23)/P23 -> 10.707346 | V23: 24.7782 | W23: 30.3824 | X23: 12.0194 | Y23: 32.4158 | Z23: 26.7656 | AA23: 20.1238 | AB23: 23.694 | AC23: 38.83 | AD23: 48.1426 | AE23: 29.6064 | AG23: =G23*R23 -> 116
A24: 6221 НЕОПОЛИТАНСКИЙ ДУЭТ с/к с/н мгс 1/90 Останкино | B24: шт | C24: 517 | D24: 373 | E24: 234 | F24: 569 | G24: 0.09 | H24: 60 | I24: матрица | K24: 242 | L24: =E24-K24 -> -8 | O24: 0 | P24: =E24/5 -> 46.8 | Q24: =15*P24-O24-F24 -> 133 | R24: =ROUND(Q24,0) -> 133 | T24: =(F24+O24+R24)/P24 -> 15 | U24: =(F24+O24)/P24 -> 12.15812 | V24: 44.8 | W24: 65.6 | X24: 69 | Y24: 42.2 | Z24: 62 | AA24: 41.8 | AB24: 53.6 | AC24: 55.6 | AD24: 39.8 | AE24: 53.8 | AG24: =G24*R24 -> 11.97
A25: 6228 МЯСНОЕ АССОРТИ к/з с/н мгс 1/90 10шт Останкино | B25: шт | C25: 212 | D25: 235 | E25: 174 | F25: 198 | G25: 0.09 | H25: 45 | I25: ВНИМАНИЕ / матрица | K25: 180 | L25: =E25-K25 -> -6 | O25: 224 | P25: =E25/5 -> 34.8 | Q25: =15*P25-O25-F25 -> 100 | R25: =ROUND(Q25,0) -> 100 | T25: =(F25+O25+R25)/P25 -> 15 | U25: =(F25+O25)/P25 -> 12.126437 | V25: 39.2 | W25: 30.8 | X25: 20.6 | Y25: 27.4 | Z25: 31.8 | AA25: 26.2 | AB25: 23.6 | AC25: 24.4 | AD25: 24.8 | AE25: 20 | AF25: Главторг | AG25: =G25*R25 -> 9
A26: 6279 КОРЕЙКА ПО-ОСТ.к/в в/с с/н в/у 1/150_45с Останкино | B26: шт | C26: 111 | D26: 233 | E26: 177 | F26: 85 | G26: 0.15 | H26: 45 | I26: матрица | K26: 180 | L26: =E26-K26 -> -3 | O26: 207 | P26: =E26/5 -> 35.4 | Q26: =15*P26-O26-F26 -> 239 | R26: =ROUND(Q26,0) -> 239 | T26: =(F26+O26+R26)/P26 -> 15 | U26: =(F26+O26)/P26 -> 8.2485876 | V26: 32.2 | W26: 24.6 | X26: 26.2 | Y26: 19.6 | Z26: 27.4 | AA26: 33.6 | AB26: 20.4 | AC26: 21.2 | AD26: 31.4 | AE26: 18.6 | AG26: =G26*R26 -> 35.85
A27: 6303 Мясные Папа может сос п/о мгс 1,5*3 Останкино | B27: кг | C27: 327.558 | D27: 961.996 | E27: 425.486 | F27: 823.479 | G27: 1 | H27: 45 | I27: матрица | K27: 413.6 | L27: =E27-K27 -> 11.886 | O27: 232 | P27: =E27/5 -> 85.0972 | Q27: =15*P27-O27-F27 -> 220.979 | R27: =ROUND(Q27,0) -> 221 | T27: =(F27+O27+R27)/P27 -> 15.000247 | U27: =(F27+O27)/P27 -> 12.403217 | V27: 86.0894 | W27: 101.1476 | X27: 72.8874 | Y27: 74.641 | Z27: 69.1282 | AA27: 44.8872 | AB27: 61.0286 | AC27: 80.0628 | AD27: 71.7762 | AE27: 53.405 | AG27: =G27*R27 -> 221
A28: 6325 ДОКТОРСКАЯ ПРЕМИУМ вар п/о 0.4кг 8шт. ОСТАНКИНО | B28: шт | C28: 201 | D28: 474 | E28: 167 | F28: 471 | G28: 0.4 | H28: 60 | I28: матрица | K28: 167 | L28: =E28-K28 -> 0 | O28: 56 | P28: =E28/5 -> 33.4 | R28: =ROUND(Q28,0) -> 0 | T28: =(F28+O28+R28)/P28 -> 15.778443 | U28: =(F28+O28)/P28 -> 15.778443 | V28: 46.4 | W28: 43.2 | X28: 44.2 | Y28: 37.4 | Z28: 47.6 | AA28: 25.8 | AB28: 56.8 | AC28: 29.8 | AD28: 17.2 | AE28: 27 | AF28: Главторг | AG28: =G28*R28 -> 0
A29: 6333 МЯСНАЯ Папа может вар п/о 0.4кг 8шт. ОСТАНКИНО | B29: шт | C29: 583 | D29: 235 | E29: 244 | F29: 504 | G29: 0.4 | H29: 60 | I29: ВНИМАНИЕ / матрица | K29: 279 | L29: =E29-K29 -> -35 | O29: 0 | P29: =E29/5 -> 48.8 | Q29: =15*P29-O29-F29 -> 228 | R29: =ROUND(Q29,0) -> 228 | T29: =(F29+O29+R29)/P29 -> 15 | U29: =(F29+O29)/P29 -> 10.327869 | V29: 45 | W29: 32 | X29: 37.2 | Y29: 30.4 | Z29: 43 | AA29: 48 | AB29: 44.6 | AC29: 38.8 | AD29: 49.6 | AE29: 47.6 | AF29: Главторг | AG29: =G29*R29 -> 91.2
A30: 6392 ФИЛЕЙНАЯ Папа может вар п/о 0,4кг ОСТАНКИНО | B30: шт | C30: 138 | D30: 200 | E30: 189 | F30: 80 | G30: 0.4 | H30: 60 | I30: ВНИМАНИЕ / матрица | K30: 189 | L30: =E30-K30 -> 0 | O30: 321 | P30: =E30/5 -> 37.8 | Q30: =15*P30-O30-F30 -> 166 | R30: =ROUND(Q30,0) -> 166 | T30: =(F30+O30+R30)/P30 -> 15 | U30: =(F30+O30)/P30 -> 10.608466 | V30: 42.8 | W30: 27.4 | X30: 24.2 | Y30: 34.8 | Z30: 44.6 | AA30: 41.4 | AB30: 37.8 | AC30: 59.2 | AD30: 34.6 | AE30: 46.2 | AF30: Главторг | AG30: =G30*R30 -> 66.4
A31: 6495 ВЕТЧ.МРАМОРНАЯ в/у срез 0,3кг 6шт_45с Останкино | B31: шт | C31: 94 | D31: 346 | E31: 82 | F31: 323 | G31: 0.3 | H31: 45 | I31: матрица | K31: 95 | L31: =E31-K31 -> -13 | O31: 0 | P31: =E31/5 -> 16.4 | R31: =ROUND(Q31,0) -> 0 | T31: =(F31+O31+R31)/P31 -> 19.695122 | U31: =(F31+O31)/P31 -> 19.695122 | V31: 22.4 | W31: 36 | X31: 27.2 | Y31: 20.2 | Z31: 26.8 | AA31: 20.4 | AB31: 27 | AC31: 11.8 | AD31: 16 | AE31: 33.2 | AG31: =G31*R31 -> 0
A32: 6498 МОЛОЧНАЯ Папа может вар п/о ОСТАНКИНО | B32: кг | C32: 45.198 | D32: 204.266 | E32: 84.308 | F32: 140.406 | G32: 1 | H32: 60 | I32: матрица | K32: 84.4 | L32: =E32-K32 -> -0.092 | O32: 88 | P32: =E32/5 -> 16.8616 | Q32: =15*P32-O32-F32 -> 24.518 | R32: =ROUND(Q32,0) -> 25 | T32: =(F32+O32+R32)/P32 -> 15.028586 | U32: =(F32+O32)/P32 -> 13.545927 | V32: 19.8412 | W32: 21.4732 | X32: 16.6488 | Y32: 18.3598 | Z32: 19.6196 | AA32: 17.6358 | AB32: 18.295 | AC32: 17.577 | AD32: 25.6296 | AE32: 19.367 | AG32: =G32*R32 -> 25
A33: 6527 ШПИКАЧКИ СОЧНЫЕ ПМ сар б/о мгс 1*3 45с ОСТАНКИНО | B33: кг | C33: 60.017 | D33: 168.722 | E33: 48.082 | F33: 159.135 | G33: 1 | H33: 45 | I33: матрица | K33: 51.2 | L33: =E33-K33 -> -3.118 | O33: 33 | P33: =E33/5 -> 9.6164 | R33: =ROUND(Q33,0) -> 0 | T33: =(F33+O33+R33)/P33 -> 19.97993 | U33: =(F33+O33)/P33 -> 19.97993 | V33: 15.4948 | W33: 17.4918 | X33: 8.7322 | Y33: 19.0252 | Z33: 11.6818 | AA33: 9.6796 | AB33: 10.3604 | AC33: 23.97 | AD33: 23.714 | AE33: 19.5158 | AG33: =G33*R33 -> 0
A34: 6550 МЯСНЫЕ Папа может сар б/о мгс 1*3 О 45с Останкино | B34: кг | C34: 41.41 | D34: 261.245 | E34: 58.374 | F34: 222.923 | G34: 1 | H34: 45 | I34: матрица | K34: 62.5 | L34: =E34-K34 -> -4.126 | O34: 40 | P34: =E34/5 -> 11.6748 | R34: =ROUND(Q34,0) -> 0 | T34: =(F34+O34+R34)/P34 -> 22.520557 | U34: =(F34+O34)/P34 -> 22.520557 | V34: 20.364 | W34: 26.2212 | X34: 18.2844 | Y34: 23.6278 | Z34: 16.7678 | AA34: 13.0416 | AB34: 26.403 | AC34: 21.4896 | AD34: 29.6156 | AE34: 34.4256 | AG34: =G34*R34 -> 0
A35: 6602 БАВАРСКИЕ ПМ сос ц/о мгс 0.35кг 8шт. | B35: шт | G35: 0 | I35: РАЗОВО | L35: =E35-K35 -> 0 | O35: 300 | P35: =E35/5 -> 0 | R35: =ROUND(Q35,0) -> 0 | T35: =(F35+O35+R35)/P35 -> #DIV/0! | U35: =(F35+O35)/P35 -> #DIV/0! | V35: 0 | W35: 0 | X35: 0 | Y35: 0 | Z35: 0 | AA35: 0 | AB35: 0 | AC35: 0 | AD35: 0 | AE35: 0 | AF35: Главторг (1001021966602) | AG35: =G35*R35 -> 0
A36: 6608 С ГОВЯДИНОЙ ОРИГИН. сар б/о мгс 1*3_45с ОСТАНКИНО | B36: кг | C36: 134.159 | D36: 386.223 | E36: 127.359 | F36: 364.232 | G36: 1 | H36: 45 | I36: матрица | K36: 130.4 | L36: =E36-K36 -> -3.041 | O36: 0 | P36: =E36/5 -> 25.4718 | Q36: =15*P36-O36-F36 -> 17.845 | R36: =ROUND(Q36,0) -> 18 | T36: =(F36+O36+R36)/P36 -> 15.006085 | U36: =(F36+O36)/P36 -> 14.299421 | V36: 27.1644 | W36: 49.6982 | X36: 26.7538 | Y36: 42.906 | Z36: 40.4576 | AA36: 38.3834 | AB36: 37.245 | AC36: 34.217 | AD36: 44.958 | AE36: 38.3692 | AG36: =G36*R36 -> 18
A37: 6616 МОЛОЧНЫЕ КЛАССИЧЕСКИЕ сос п/о в/у 0,3 кг Останкино | B37: шт | C37: 466 | D37: 708 | E37: 178 | F37: 938 | G37: 0.3 | H37: 45 | I37: матрица | K37: 176 | L37: =E37-K37 -> 2 | O37: 0 | P37: =E37/5 -> 35.6 | R37: =ROUND(Q37,0) -> 0 | T37: =(F37+O37+R37)/P37 -> 26.348315 | U37: =(F37+O37)/P37 -> 26.348315 | V37: 48.4 | W37: 70.2 | X37: 69.8 | Y37: 41.6 | Z37: 43.2 | AA37: 18.8 | AB37: 58 | AC37: 42.8 | AD37: 21.2 | AE37: 22.8 | AF37: нужно увеличить продажи!!! | AG37: =G37*R37 -> 0
A38: 6620 РЕБРЫШКИ к/в в/у_30с Останкино | B38: кг | C38: -10.232 | D38: 390.5 | E38: 117.31 | F38: 160.54 | G38: 1 | H38: 30 | I38: матрица | K38: 124.7 | L38: =E38-K38 -> -7.39 | O38: 139 | P38: =E38/5 -> 23.462 | Q38: =15*P38-O38-F38 -> 52.39 | R38: =ROUND(Q38,0) -> 52 | T38: =(F38+O38+R38)/P38 -> 14.983377 | U38: =(F38+O38)/P38 -> 12.767028 | V38: 26.2592 | W38: 36.8956 | X38: 16.0452 | Y38: 14.3528 | Z38: 22.1236 | AA38: 20.264 | AB38: 18.5496 | AC38: 16.2388 | AD38: 13.0004 | AE38: 23.7596 | AG38: =G38*R38 -> 52
A39: 6661 СОЧНЫЙ ГРИЛЬ ПМ сос п/о мгс 1,5*4_Маяк Останкино | B39: кг | C39: 47.682 | D39: 565.17 | E39: 244.946 | F39: 285.118 | G39: 1 | H39: 45 | I39: матрица | K39: 309.7 | L39: =E39-K39 -> -64.754 | O39: 523 | P39: =E39/5 -> 48.9892 | R39: =ROUND(Q39,0) -> 0 | T39: =(F39+O39+R39)/P39 -> 16.49584 | U39: =(F39+O39)/P39 -> 16.49584 | V39: 66.378 | W39: 55.0392 | X39: 42.2362 | Y39: 44.667 | Z39: 51.4842 | AA39: 34.0432 | AB39: 46.1826 | AC39: 36.7466 | AD39: 52.7878 | AE39: 34.78 | AG39: =G39*R39 -> 0
A40: 6697 СЕРВЕЛАТ ФИНСКИЙ ПМ в/к в/у 0,35кг 8шт ОСТАНКИНО | B40: шт | C40: 7 | D40: 949 | E40: 231 | F40: 605 | G40: 0.35 | H40: 45 | I40: матрица | K40: 281 | L40: =E40-K40 -> -50 | O40: 78 | P40: =E40/5 -> 46.2 | Q40: =15*P40-O40-F40 -> 10 | R40: =ROUND(Q40,0) -> 10 | T40: =(F40+O40+R40)/P40 -> 15 | U40: =(F40+O40)/P40 -> 14.78355 | V40: 63 | W40: 93.8 | X40: 49.2 | Y40: 60.4 | Z40: 73 | AA40: 57.2 | AB40: 63.4 | AC40: 62.2 | AD40: 65.8 | AE40: 59.4 | AG40: =G40*R40 -> 3.5
A41: 6713 СОЧНЫЙ ГРИЛЬ ПМ сос п/о мгс 0,41кг 8 шт. ОСТАНКИНО | B41: шт | C41: 225 | D41: 361 | E41: 330 | F41: 196 | G41: 0.41 | H41: 45 | I41: матрица | K41: 352 | L41: =E41-K41 -> -22 | O41: 341 | P41: =E41/5 -> 66 | Q41: =15*P41-O41-F41 -> 453 | R41: =ROUND(Q41,0) -> 453 | T41: =(F41+O41+R41)/P41 -> 15 | U41: =(F41+O41)/P41 -> 8.1363636 | V41: 59.4 | W41: 44.8 | X41: 56 | Y41: 48.8 | Z41: 61 | AA41: 55.8 | AB41: 52.6 | AC41: 57.2 | AD41: 41.4 | AE41: 37.6 | AG41: =G41*R41 -> 185.73
A42: 6724 МОЛОЧНЫЕ ПМ сос п/о мгс 0,41кг 10шт Останкино | B42: шт | C42: 87 | D42: 389 | E42: 178 | F42: 249 | G42: 0.41 | H42: 45 | I42: матрица | K42: 181 | L42: =E42-K42 -> -3 | O42: 105 | P42: =E42/5 -> 35.6 | Q42: =15*P42-O42-F42 -> 180 | R42: =ROUND(Q42,0) -> 180 | T42: =(F42+O42+R42)/P42 -> 15 | U42: =(F42+O42)/P42 -> 9.9438202 | V42: 34.2 | W42: 40.6 | X42: 30.6 | Y42: 36.2 | Z42: 42.6 | AA42: 41.4 | AB42: 27.4 | AC42: 42.4 | AD42: 35.8 | AE42: 25.4 | AG42: =G42*R42 -> 73.8
...

Sheet новинки
A1: 7514 | B1: 1001017557514 | C1: ЛЮБИТЕЛЬСКАЯ ОСТАНКИНСКАЯ вар ц/о в/у | D1: 7514 ЛЮБИТЕЛЬСКАЯ ОСТАНКИНСКАЯ вар п/о в/у ОСТАНКИНО | E1: кг | F1: 30 | G1: ЛЮБИТЕЛЬСКАЯ ОСТАНКИНСКАЯ вар ц/о в/у | H1: 1 | J1: =VLOOKUP(D1,Sheet!A:I,9,0) -> матрица
A2: 7518 | B2: 1001017567518 | C2: ТЕЛЯЧЬЯ ГОСТ Останкино вар н/о в/у | D2: 7518 ТЕЛЯЧЬЯ ГОСТ Останкино вар п/о в/у ОСТАНКИНО | E2: кг | F2: 30 | G2: ТЕЛЯЧЬЯ ГОСТ Останкино вар н/о в/у | H2: 1 | J2: =VLOOKUP(D2,Sheet!A:I,9,0) -> матрица
A3: 6929 | B3: 1001085476929 | C3: КАРБОНAД ДОМАШНИЙ ПМ к/в кр/к в/у | D3: 6929 КАРБОНАД ДОМАШНИЙ ПМ к/в кр/к в/у ОСТАНКИНО | E3: кг | F3: 45 | G3: КАРБОНAД ДОМАШНИЙ ПМ к/в кр/к в/у | H3: 1 | J3: =VLOOKUP(D3,Sheet!A:I,9,0) -> матрица
A4: 614 | B4: 1001060720614 | C4: ПРАЗДНИЧНАЯ с/к в/с дек.спец.мгс | D4: 0614 ПРАЗДНИЧНАЯ с/к в/с дек.спец.мгс Останкино | E4: кг | F4: 120 | G4: ПРАЗДНИЧНАЯ с/к в/с дек.спец.мгс | H4: 1 | J4: =VLOOKUP(D4,Sheet!A:I,9,0) -> матрица
A5: 7143 | B5: 1001060717143 | C5: БРАУНШВЕЙГСКАЯ ГОСТ с/к в/у 1/220 8шт. | D5: 7143 БРАУНШВЕЙГСКАЯ ГОСТ с/к в/у 1/220 8шт. | E5: шт | F5: 120 | G5: БРАУНШВЕЙГСКАЯ ГОСТ с/к в/у 1/220 8шт. | H5: 0.22 | J5: =VLOOKUP(D5,Sheet!A:I,9,0) -> матрица
A6: 7710 | B6: 1001307587710 | C6: КРАКОВСКАЯ ГОСТ п/к н/о мгс 0.3кг | D6: 7710 КРАКОВСКАЯ ГОСТ п/к н/о мгс 0.3кг | E6: шт | F6: 45 | G6: КРАКОВСКАЯ ГОСТ п/к н/о мгс 0.3кг | H6: 0.3 | J6: =VLOOKUP(D6,Sheet!A:I,9,0) -> матрица
A7: 7456 | B7: 1001063097456 | C7: САЛЯМИ ФИНСКАЯ Папа может с/к в/у 1/150 | D7: 7456 САЛЯМИ ФИНСКАЯ Папа может с/к в/у 1/150 | E7: шт | F7: 90 | G7: САЛЯМИ ФИНСКАЯ Папа может с/к в/у 1/150 | H7: 0.15 | J7: =VLOOKUP(D7,Sheet!A:I,9,0) -> матрица
A8: 7386 | B8: 1001067017386 | C8: БАРСЕЛОНА ПМ с/к в/у 1/150 | D8: 7386 БАРСЕЛОНА ПМ с/к в/у 1/150 ОСТАНКИНО | E8: шт | F8: 90 | G8: БАРСЕЛОНА ПМ с/к в/у 1/150 | H8: 0.15 | J8: =VLOOKUP(D8,Sheet!A:I,9,0) -> матрица
A9: 7344 | B9: 1001122287344 | C9: КОНСЕРВЫ МЯС.ГОВЯДИНА ТУШ. В/С 338г_ЧЗ | D9: 7344 КОНСЕРВЫ МЯС.ГОВЯДИНА ТУШ. В/С 338г_ЧЗ | E9: шт | F9: 3 года | G9: КОНСЕРВЫ МЯС.ГОВЯДИНА ТУШ. В/С 338г_ЧЗ | H9: 0.338 | J9: =VLOOKUP(D9,Sheet!A:I,9,0) -> матрица
A10: 7345 | B10: 1001123677345 | C10: КОНСЕРВЫ МЯС.СВИНИНА ТУШ. В/С 325г_ЧЗ | D10: 7345 КОНСЕРВЫ МЯС.СВИНИНА ТУШ. В/С 325г_ЧЗ | E10: шт | F10: 3 года | G10: КОНСЕРВЫ МЯС.СВИНИНА ТУШ. В/С 325г_ЧЗ | H10: 0.325 | J10: =VLOOKUP(D10,Sheet!A:I,9,0) -> матрица

Sheet вывод
A1: 6411 ВЕТЧ.РУБЛЕНАЯ ПМ в/у срез 0.3кг 6шт. ОСТАНКИНО | B1: вывод
A2: 6925 ВЕТЧ.КЛАССИЧЕСКАЯ в/у 0,6кг 8шт. ОСТАНКИНО | B2: вывод
A3: 7332 БОЯРСКАЯ ПМ п/к в/у 0,28кг ОСТАНКИНО | B3: вывод
A4: 7608 СЕРВЕЛАТ ШВЕЙЦАРСК.в/к с/н в/у 1/100_Л11 ОСТАНКИНО | B4: вывод
A5: 7612 БАЛЫК с/к с/н в/у 1/100 10шт_ ОСТАНКИНО | B5: вывод
