Workbook

Sheet Sheet
A3: Номенклатура | B3: Ед. изм. | C3: Начальный остаток | D3: Приход | E3: Расход | F3: Конечный остаток | G3: крат | H3: сроки | I3: метка | J3: метка2 | K3: заяв | L3: разн | M3: без опта | N3: опт | O3: заказ в пути | P3: заказ в пути | Q3: заказ в пути | R3: заказ в пути | S3: ср нов | T3: расчет | U3: кон ост | V3: факт | W3: ср | X3: ср | Y3: ср | Z3: ср | AA3: ср | AB3: ср | AC3: ср | AD3: ср | AE3: ср | AF3: ср | AG3: ср | AH3: комментарии | AI3: вес
O4: 18,07, | P4: 18,07,(дозаказ) | Q4: 20,07,(дозаказ) | R4: 20,07, | S4: 21,07, | W4: 16,07, | X4: 14,07, | Y4: 09,07, | Z4: 07,07, | AA4: 02,07, | AB4: 30,06, | AC4: 25,06, | AD4: 23,06, | AE4: 16,06, | AF4: 09,06, | AG4: 02,06,
E5: =SUM(E6:E500) -> 26558.594 | F5: =SUM(F6:F500) -> 19313.231 | K5: =SUM(K6:K500) -> 27229.259 | L5: =SUM(L6:L500) -> -670.665 | M5: =SUM(M6:M500) -> 0 | N5: =SUM(N6:N500) -> 0 | O5: =SUM(O6:O500) -> 14044.125 | P5: =SUM(P6:P500) -> 1000 | Q5: =SUM(Q6:Q500) -> 1500 | R5: =SUM(R6:R500) -> 9305.5314 | ... T5: =SUM(T6:T500) -> 0 | W5: =SUM(W6:W500) -> 4949.0584 | X5: =SUM(X6:X500) -> 5681.1398 | Y5: =SUM(Y6:Y500) -> 4551.0276 | Z5: =SUM(Z6:Z500) -> 4055.5028 | AA5: =SUM(AA6:AA500) -> 4899.2522 | AB5: =SUM(AB6:AB500) -> 4551.2998 | AC5: =SUM(AC6:AC500) -> 4262.4296 | AD5: =SUM(AD6:AD500) -> 4449.9754 | ... AG5: =SUM(AG6:AG500) -> 4222.965 | AI5: =SUM(AI6:AI500) -> 0
A6: 005 Колбаса Докторская ГОСТ, Вязанка вектор,ВЕС. ПОКОМ | B6: кг | C6: 899.48 | D6: 5.408 | E6: 311.283 | F6: 569.574 | G6: 1 | H6: 50 | I6: P003011 | K6: 282.74 | L6: =E6-K6 -> 28.543 | O6: 0 | R6: 89.7795 | S6: =E6/5 -> 62.2566 | U6: =(F6+O6+P6+Q6+R6+T6)/S6 -> 10.590901 | V6: =(F6+O6+P6+Q6+R6)/S6 -> 10.590901 | W6: 66.8526 | X6: 82.294 | Y6: 60.082 | Z6: 55.817 | AA6: 53.8112 | AB6: 54.4542 | AC6: 78.6436 | AD6: 81.142 | AE6: 56.726 | AF6: 56.7282 | AG6: 58.5926 | AI6: =G6*T6 -> 0 | AJ6: =VLOOKUP(A6,[1]Лист1!$B:$O,14,0) -> матрица
A7: 016 Сосиски Вязанка Молочные, Вязанка вискофан ВЕС.ПОКОМ | B7: кг | C7: 1178.768 | D7: 347.246 | E7: 806.834 | F7: 579.577 | G7: 1 | H7: 45 | I7: P003986 | K7: 760.25 | L7: =E7-K7 -> 46.584 | O7: 332.08992 | R7: 276.6853 | S7: =E7/5 -> 161.3668 | U7: =(F7+O7+P7+Q7+R7+T7)/S7 -> 7.3642919 | V7: =(F7+O7+P7+Q7+R7)/S7 -> 7.3642919 | W7: 149.6454 | X7: 178.8482 | Y7: 149.6718 | Z7: 148.2108 | AA7: 187.2726 | AB7: 139.0446 | AC7: 77.6314 | AD7: 85.1312 | AE7: 120.8346 | AF7: 53.9194 | AG7: 103.5516 | AI7: =G7*T7 -> 0 | AJ7: =VLOOKUP(A7,[1]Лист1!$B:$O,14,0) -> матрица
A8: 017 Сосиски Вязанка Сливочные, Вязанка амицел ВЕС.ПОКОМ | B8: кг | C8: 1111.887 | D8: 485.18 | E8: 842.814 | F8: 621.62 | G8: 1 | H8: 45 | I8: P003988 | K8: 793.34 | L8: =E8-K8 -> 49.474 | O8: 362.17072 | R8: 185.82892 | S8: =E8/5 -> 168.5628 | U8: =(F8+O8+P8+Q8+R8+T8)/S8 -> 6.9387768 | V8: =(F8+O8+P8+Q8+R8)/S8 -> 6.9387768 | W8: 152.8908 | X8: 189.7098 | Y8: 156.5736 | Z8: 142.0624 | AA8: 183.8164 | AB8: 143.9012 | AC8: 28.5586 | AD8: 19.2348 | AE8: 136.8586 | AF8: 61.9152 | AG8: 120.945 | AI8: =G8*T8 -> 0 | AJ8: =VLOOKUP(A8,[1]Лист1!$B:$O,14,0) -> матрица
A9: 023 Колбаса Докторская ГОСТ, Вязанка вектор, 0,4 кг, ПОКОМ | B9: шт | D9: 20 | E9: 2 | F9: 17 | G9: 0.4 | H9: 50 | K9: 11 | L9: =E9-K9 -> -9 | O9: 0 | R9: 0 | S9: =E9/5 -> 0.4 | U9: =(F9+O9+P9+Q9+R9+T9)/S9 -> 42.5 | V9: =(F9+O9+P9+Q9+R9)/S9 -> 42.5 | W9: 0 | X9: 0 | Y9: 0 | Z9: 0.4 | AA9: 1.4 | AB9: 2 | AC9: 2.2 | AD9: 1.2 | AE9: 1 | AF9: 0 | AG9: 0 | AH9: 70 шт списаны (04,07,26 - недостача) | AI9: =G9*T9 -> 0 | AJ9: =VLOOKUP(A9,[1]Лист1!$B:$O,14,0) -> матрица
A10: 030 Сосиски Вязанка Молочные, Вязанка вискофан МГС, 0.45кг, ПОКОМ | B10: шт | C10: 455 | D10: 51 | E10: 343 | F10: 140 | G10: 0.45 | H10: 45 | I10: P003985 | K10: 348 | L10: =E10-K10 -> -5 | O10: 214 | R10: 62.3 | S10: =E10/5 -> 68.6 | U10: =(F10+O10+P10+Q10+R10+T10)/S10 -> 6.0685131 | V10: =(F10+O10+P10+Q10+R10)/S10 -> 6.0685131 | W10: 57 | X10: 64.4 | Y10: 51.8 | Z10: 54 | AA10: 66.6 | AB10: 69 | AC10: 72.6 | AD10: 51 | AE10: 59.6 | AF10: -0.4 | AG10: 12.8 | AI10: =G10*T10 -> 0 | AJ10: =VLOOKUP(A10,[1]Лист1!$B:$O,14,0) -> матрица
A11: 032 Сосиски Вязанка Сливочные, Вязанка амицел МГС, 0.45кг, ПОКОМ | B11: шт | C11: 435 | D11: 252 | E11: 443 | F11: 187 | G11: 0.45 | H11: 45 | I11: P003989 | K11: 467 | L11: =E11-K11 -> -24 | O11: 269.32 | R11: 225.54 | S11: =E11/5 -> 88.6 | U11: =(F11+O11+P11+Q11+R11+T11)/S11 -> 7.6959368 | V11: =(F11+O11+P11+Q11+R11)/S11 -> 7.6959368 | W11: 85.2 | X11: 90.6 | Y11: 71.4 | Z11: 71.8 | AA11: 78 | AB11: 73.2 | AC11: 69 | AD11: 81.8 | AE11: 64.8 | AF11: 39.8 | AG11: 75.6 | AI11: =G11*T11 -> 0 | AJ11: =VLOOKUP(A11,[1]Лист1!$B:$O,14,0) -> матрица
A12: 062 Колбаса Кракушка пряная с сальцем, 0.3кг в/у п/к, БАВАРУШКА ПОКОМ | B12: шт | C12: 114 | D12: 119 | E12: 99 | F12: 102 | G12: 0.3 | H12: 40 | I12: P002461 | K12: 97 | L12: =E12-K12 -> 2 | O12: 53.8 | R12: 0 | S12: =E12/5 -> 19.8 | U12: =(F12+O12+P12+Q12+R12+T12)/S12 -> 7.8686869 | V12: =(F12+O12+P12+Q12+R12)/S12 -> 7.8686869 | W12: 18 | X12: 25.6 | Y12: 22.4 | Z12: 14 | AA12: 18 | AB12: 14.4 | AC12: 9.4 | AD12: 11.6 | AE12: 16 | AF12: 8.6 | AG12: 17.2 | AI12: =G12*T12 -> 0 | AJ12: =VLOOKUP(A12,[1]Лист1!$B:$O,14,0) -> матрица
A13: 083 Колбаса Швейцарская 0,17 кг., ШТ., сырокопченая ПОКОМ | B13: шт | C13: 338 | D13: 3 | E13: 99 | F13: 231 | G13: 0.17 | H13: 180 | I13: P001909 | K13: 92 | L13: =E13-K13 -> 7 | O13: 0 | R13: 0 | S13: =E13/5 -> 19.8 | U13: =(F13+O13+P13+Q13+R13+T13)/S13 -> 11.666667 | V13: =(F13+O13+P13+Q13+R13)/S13 -> 11.666667 | W13: 14.8 | X13: 20.6 | Y13: 21.8 | Z13: 18.2 | AA13: 30.6 | AB13: 32.8 | AC13: 24.6 | AD13: 22.6 | AE13: 25 | AF13: 14.8 | AG13: 12 | AH13: нужно увеличить продажи | AI13: =G13*T13 -> 0 | AJ13: =VLOOKUP(A13,[1]Лист1!$B:$O,14,0) -> матрица
A14: 200 Ветчина Дугушка ТМ Стародворье, вектор в/у ПОКОМ | B14: кг | C14: 290.086 | D14: 711.014 | E14: 477.671 | F14: 465.919 | G14: 1 | H14: 70 | I14: P004460 | K14: 451.3 | L14: =E14-K14 -> 26.371 | O14: 0 | R14: 0 | S14: =E14/5 -> 95.5342 | U14: =(F14+O14+P14+Q14+R14+T14)/S14 -> 4.8769865 | V14: =(F14+O14+P14+Q14+R14)/S14 -> 4.8769865 | W14: 52.2468 | X14: 66.2222 | Y14: 84.409 | Z14: 85.928 | AA14: 52.178 | AB14: 15.4452 | AC14: 54.4834 | AD14: 91.6624 | AE14: 84.4096 | AF14: 76.5132 | AG14: 84.6612 | AI14: =G14*T14 -> 0 | AJ14: =VLOOKUP(A14,[1]Лист1!$B:$O,14,0) -> матрица
A15: 201 Ветчина Нежная ТМ Особый рецепт, (2,5кг), ПОКОМ | B15: кг | C15: 1714.635 | D15: 2238.902 | E15: 1844.558 | F15: 1549.371 | G15: 1 | H15: 50 | I15: P002555 | K15: 1870.017 | L15: =E15-K15 -> -25.459 | O15: 306.30568 | R15: 575.88682 | S15: =E15/5 -> 368.9116 | U15: =(F15+O15+P15+Q15+R15+T15)/S15 -> 6.591182 | V15: =(F15+O15+P15+Q15+R15)/S15 -> 6.591182 | W15: 333.2478 | X15: 396.964 | Y15: 364.6358 | Z15: 341.2748 | AA15: 267.3186 | AB15: 211.0538 | AC15: 419.6432 | AD15: 440.711 | AE15: 273.9434 | AF15: 349.3664 | AG15: 403.612 | AI15: =G15*T15 -> 0 | AJ15: =VLOOKUP(A15,[1]Лист1!$B:$O,14,0) -> матрица
A16: 215 Колбаса Докторская ГОСТ Дугушка, ВЕС, ТМ Стародворье ПОКОМ | B16: кг | C16: 150.711 | D16: 10.636 | E16: 83.011 | F16: 34.256 | G16: 1 | H16: 60 | I16: P004028 | K16: 86.1 | L16: =E16-K16 -> -3.089 | O16: 70.3826 | R16: 62.4539 | S16: =E16/5 -> 16.6022 | U16: =(F16+O16+P16+Q16+R16+T16)/S16 -> 10.064479 | V16: =(F16+O16+P16+Q16+R16)/S16 -> 10.064479 | W16: 18.7286 | X16: 18.4156 | Y16: 10.8032 | Z16: 8.297 | AA16: 16.9424 | AB16: 19.0762 | AC16: 18.81 | AD16: 20.7744 | AE16: 21.4712 | AF16: 20.5778 | AG16: 18.391 | AI16: =G16*T16 -> 0 | AJ16: =VLOOKUP(A16,[1]Лист1!$B:$O,14,0) -> матрица
A17: 225 Колбаса Дугушка со шпиком, ВЕС, ТМ Стародворье ПОКОМ | B17: кг | C17: 95.339 | D17: 33.526 | E17: 53.5 | F17: 56.085 | G17: 1 | H17: 60 | I17: P004406 | K17: 47.3 | L17: =E17-K17 -> 6.2 | O17: 0 | R17: 26.545 | S17: =E17/5 -> 10.7 | U17: =(F17+O17+P17+Q17+R17+T17)/S17 -> 7.7224299 | V17: =(F17+O17+P17+Q17+R17)/S17 -> 7.7224299 | W17: 9.692 | X17: 6.7256 | Y17: 4.0734 | Z17: 4.6054 | AA17: 12.0812 | AB17: 12.4332 | AC17: 2.8418 | AD17: 0 | AE17: 7.9376 | AF17: 1.604 | AG17: 3.9266 | AI17: =G17*T17 -> 0 | AJ17: =VLOOKUP(A17,[1]Лист1!$B:$O,14,0) -> матрица
A18: 226 Колбаса Княжеская, с/к белков.обол в термоусад. пакете, ВЕС, ТМ Стародворье ПОКОМ | B18: кг | C18: 54.755 | D18: 9.946 | E18: 13.398 | F18: 49.881 | G18: 1 | H18: 180 | I18: P001900 | K18: 14.85 | L18: =E18-K18 -> -1.452 | O18: 4 | R18: 7.2445 | S18: =E18/5 -> 2.6796 | U18: =(F18+O18+P18+Q18+R18+T18)/S18 -> 22.811427 | V18: =(F18+O18+P18+Q18+R18)/S18 -> 22.811427 | W18: 5.3262 | X18: 5.8662 | Y18: 3.2308 | Z18: 3.8264 | AA18: 6.4126 | AB18: 4.592 | AC18: 0.4318 | AD18: 1.2968 | AE18: 3.1156 | AF18: 1.7052 | AG18: 3.2548 | AI18: =G18*T18 -> 0 | AJ18: =VLOOKUP(A18,[1]Лист1!$B:$O,14,0) -> матрица
A19: 229 Колбаса Молочная Дугушка, в/у, ВЕС, ТМ Стародворье ПОКОМ | B19: кг | C19: 678.534 | D19: 200.948 | E19: 548.474 | F19: 259.672 | G19: 1 | H19: 60 | I19: P004030 | K19: 499.56 | L19: =E19-K19 -> 48.914 | O19: 475.11948 | R19: 136.29456 | S19: =E19/5 -> 109.6948 | U19: =(F19+O19+P19+Q19+R19+T19)/S19 -> 7.9409967 | V19: =(F19+O19+P19+Q19+R19)/S19 -> 7.9409967 | W19: 108.2616 | X19: 128.466 | Y19: 94.8788 | Z19: 92.3168 | AA19: 112.2612 | AB19: 109.2184 | AC19: 102.2408 | AD19: 114.7664 | AE19: 94.6184 | AF19: 100.6668 | AG19: 104.9052 | AI19: =G19*T19 -> 0 | AJ19: =VLOOKUP(A19,[1]Лист1!$B:$O,14,0) -> матрица
A20: 236 Колбаса Рубленая ЗАПЕЧ. Дугушка ТМ Стародворье, вектор, в/к ПОКОМ | B20: кг | C20: 73.486 | D20: 93.831 | E20: 82.912 | F20: 61.625 | G20: 1 | H20: 70 | I20: P004465 | K20: 117.2 | L20: =E20-K20 -> -34.288 | O20: 131.8778 | R20: 34.1021 | S20: =E20/5 -> 16.5824 | U20: =(F20+O20+P20+Q20+R20+T20)/S20 -> 13.725691 | V20: =(F20+O20+P20+Q20+R20)/S20 -> 13.725691 | W20: 21.9814 | X20: 25.2054 | Y20: 18.8088 | Z20: 8.6364 | AA20: 5.456 | AB20: 17.2584 | AC20: 23.96 | AD20: 16.3932 | AE20: 14.418 | AF20: 13.3426 | AG20: 12.1364 | AI20: =G20*T20 -> 0 | AJ20: =VLOOKUP(A20,[1]Лист1!$B:$O,14,0) -> матрица
A21: 239 Колбаса Салями запеч Дугушка, оболочка вектор, ВЕС, ТМ Стародворье ПОКОМ | B21: кг | C21: 416.741 | D21: 8.792 | E21: 305.261 | F21: 71.618 | G21: 1 | H21: 70 | I21: P004466 | K21: 295.38 | L21: =E21-K21 -> 9.881 | O21: 163.1102 | R21: 165.49278 | S21: =E21/5 -> 61.0522 | U21: =(F21+O21+P21+Q21+R21+T21)/S21 -> 6.55539 | V21: =(F21+O21+P21+Q21+R21)/S21 -> 6.55539 | W21: 53.9418 | X21: 51.1202 | Y21: 36.6006 | Z21: 37.3572 | AA21: 53.0854 | AB21: 53.4758 | AC21: 57.1746 | AD21: 54.5116 | AE21: 38.1788 | AF21: 33.2884 | AG21: 42.4342 | AI21: =G21*T21 -> 0 | AJ21: =VLOOKUP(A21,[1]Лист1!$B:$O,14,0) -> матрица
A22: 240 Колбаса Салями охотничья, ВЕС. ПОКОМ | B22: кг | C22: 23.865 | D22: 2.359 | E22: 8.439 | F22: 15.144 | G22: 1 | H22: 180 | I22: P001916 | K22: 10.74 | L22: =E22-K22 -> -2.301 | O22: 25.7494 | R22: 0 | S22: =E22/5 -> 1.6878 | U22: =(F22+O22+P22+Q22+R22+T22)/S22 -> 24.228819 | V22: =(F22+O22+P22+Q22+R22)/S22 -> 24.228819 | W22: 2.2938 | X22: 4.5104 | Y22: 4.2846 | Z22: 3.5438 | AA22: 6.9478 | AB22: 5.1382 | AC22: 0.4382 | AD22: 0.8734 | AE22: 3.0622 | AF22: 3.3464 | AG22: 1.7766 | AI22: =G22*T22 -> 0 | AJ22: =VLOOKUP(A22,[1]Лист1!$B:$O,14,0) -> матрица
A23: 242 Колбаса Сервелат ЗАПЕЧ.Дугушка ТМ Стародворье, вектор, в/к ПОКОМ | B23: кг | C23: 551.632 | D23: 5.251 | E23: 266.713 | F23: 240.993 | G23: 1 | H23: 70 | I23: P004470 | K23: 249.86 | L23: =E23-K23 -> 16.853 | O23: 114.918 | R23: 42.28838 | S23: =E23/5 -> 53.3426 | U23: =(F23+O23+P23+Q23+R23+T23)/S23 -> 7.4649413 | V23: =(F23+O23+P23+Q23+R23)/S23 -> 7.4649413 | W23: 51.2058 | X23: 58.68 | Y23: 46.4264 | Z23: 46.1366 | AA23: 69.9002 | AB23: 60.4416 | AC23: 43.51 | AD23: 49.8888 | AE23: 52.9904 | AF23: 39.3686 | AG23: 52.9868 | AI23: =G23*T23 -> 0 | AJ23: =VLOOKUP(A23,[1]Лист1!$B:$O,14,0) -> матрица
A24: 243 Колбаса Сервелат Зернистый, ВЕС. ПОКОМ | B24: кг | C24: 27.828 | D24: 25.16 | E24: 14.739 | F24: 34.732 | G24: 1 | H24: 35 | I24: P001820 | K24: 17.2 | L24: =E24-K24 -> -2.461 | O24: 25.40528 | R24: 0 | S24: =E24/5 -> 2.9478 | U24: =(F24+O24+P24+Q24+R24+T24)/S24 -> 20.400733 | V24: =(F24+O24+P24+Q24+R24)/S24 -> 20.400733 | W24: 4.7828 | X24: 7.0242 | Y24: 5.6068 | Z24: 2.6564 | AA24: 4.1876 | AB24: 4.7524 | AC24: 1.1226 | AD24: 4.208 | AE24: 8.168 | AF24: 2.45 | AG24: 3.4954 | AI24: =G24*T24 -> 0 | AJ24: =VLOOKUP(A24,[1]Лист1!$B:$O,14,0) -> не в матрице
A25: 247 Сардельки Нежные, ВЕС. ПОКОМ | B25: кг | C25: 236.143 | D25: 11.091 | E25: 198.553 | F25: 5.669 | G25: 1 | H25: 30 | I25: P003997 | K25: 195.1 | L25: =E25-K25 -> 3.453 | O25: 209.7144 | R25: 59.4791 | S25: =E25/5 -> 39.7106 | U25: =(F25+O25+P25+Q25+R25+T25)/S25 -> 6.9216406 | V25: =(F25+O25+P25+Q25+R25)/S25 -> 6.9216406 | W25: 34.5866 | X25: 40.6514 | Y25: 18.385 | Z25: 6.2452 | AA25: 23.9664 | AB25: 38.5518 | AC25: 15.3534 | AD25: 1.7964 | AE25: 17.0366 | AF25: 5.8122 | AG25: 19.6346 | AI25: =G25*T25 -> 0 | AJ25: =VLOOKUP(A25,[1]Лист1!$B:$O,14,0) -> матрица
... A37: 281 Сосиски Молочные для завтрака ТМ Особый рецепт, 0,4кг ПОКОМ | B37: шт | C37: 128 | D37: 1 | E37: 77 | F37: 46 | G37: 0.4 | H37: 40 | I37: P005198 | K37: 79 | L37: =E37-K37 -> -2 | O37: 0 | R37: 6 | S37: =E37/5 -> 15.4 | U37: =(F37+O37+P37+Q37+R37+T37)/S37 -> 3.3766234 | V37: =(F37+O37+P37+Q37+R37)/S37 -> 3.3766234 | W37: 8.2 | X37: 4.6 | Y37: 2.4 | Z37: 0.6 | AA37: 9.8 | AB37: 11.2 | AC37: 12.6 | AD37: 11.2 | AE37: 2.8 | AF37: 3.2 | AG37: 3 | AI37: =G37*T37 -> 0 | AJ37: =VLOOKUP(A37,[1]Лист1!$B:$O,14,0) -> матрица
A38: 283 Сосиски Сочинки, ВЕС, ТМ Стародворье ПОКОМ | B38: кг | C38: 59.265 | E38: 11.484 | F38: 40.569 | G38: 1 | H38: 45 | I38: P003959 | K38: 14.6 | L38: =E38-K38 -> -3.116 | O38: 0 | R38: 0 | S38: =E38/5 -> 2.2968 | U38: =(F38+O38+P38+Q38+R38+T38)/S38 -> 17.663271 | V38: =(F38+O38+P38+Q38+R38)/S38 -> 17.663271 | W38: 2.3052 | X38: 2.8776 | Y38: 1.722 | Z38: 0 | AA38: 1.1624 | AB38: 4.9402 | AC38: 3.7778 | AD38: 0 | AE38: 1.9924 | AF38: 5.518 | AG38: 3.1658 | AI38: =G38*T38 -> 0 | AJ38: =VLOOKUP(A38,[1]Лист1!$B:$O,14,0) -> матрица
A39: 285 Паштет печеночный со слив.маслом ТМ Стародворье ламистер 0,1 кг ПОКОМ | B39: шт | C39: 764 | D39: 52 | E39: 327 | F39: 432 | G39: 0.1 | H39: 731 | I39: P002648 | K39: 245 | L39: =E39-K39 -> 82 | O39: 0 | R39: 0 | S39: =E39/5 -> 65.4 | U39: =(F39+O39+P39+Q39+R39+T39)/S39 -> 6.6055046 | V39: =(F39+O39+P39+Q39+R39)/S39 -> 6.6055046 | W39: 37.6 | X39: 47 | Y39: 61 | Z39: 70.8 | AA39: 84.6 | AB39: 73.8 | AC39: 21.4 | AD39: 7.4 | AE39: 77.6 | AF39: 32.4 | AG39: 20.8 | AI39: =G39*T39 -> 0 | AJ39: =VLOOKUP(A39,[1]Лист1!$B:$O,14,0) -> матрица
A40: 296 Колбаса Мясорубская с рубленой грудинкой 0,35кг срез ТМ Стародворье ПОКОМ | B40: шт | C40: 220 | D40: 177 | E40: 240 | F40: 130 | G40: 0.35 | H40: 40 | I40: P003256 | K40: 270 | L40: =E40-K40 -> -30 | O40: 0 | R40: 80.6 | S40: =E40/5 -> 48 | U40: =(F40+O40+P40+Q40+R40+T40)/S40 -> 4.3875 | V40: =(F40+O40+P40+Q40+R40)/S40 -> 4.3875 | W40: 28 | X40: 33.8 | Y40: 35.2 | Z40: 30.4 | AA40: 34 | AB40: 27.4 | AC40: 7.6 | AD40: 13.6 | AE40: 27.2 | AF40: 18.2 | AG40: 25.4 | AI40: =G40*T40 -> 0 | AJ40: =VLOOKUP(A40,[1]Лист1!$B:$O,14,0) -> матрица
A41: 297 Колбаса Мясорубская с рубленой грудинкой ВЕС ТМ Стародворье ПОКОМ | B41: кг | C41: 153.325 | D41: 7.287 | E41: 106.548 | F41: 21.8 | G41: 1 | H41: 40 | I41: P003179 | K41: 108.8 | L41: =E41-K41 -> -2.252 | O41: 153.0966 | R41: 0 | S41: =E41/5 -> 21.3096 | U41: =(F41+O41+P41+Q41+R41+T41)/S41 -> 8.2074089 | V41: =(F41+O41+P41+Q41+R41)/S41 -> 8.2074089 | W41: 20.1924 | X41: 27.4656 | Y41: 16.9666 | Z41: 11.3088 | AA41: 21.4932 | AB41: 20.4976 | AC41: 6.564 | AD41: 8.259 | AE41: 17.3644 | AF41: 10.4474 | AG41: 16.3496 | AI41: =G41*T41 -> 0 | AJ41: =VLOOKUP(A41,[1]Лист1!$B:$O,14,0) -> матрица
A42: 301 Сосиски Сочинки по-баварски с сыром, 0.4кг, ТМ Стародворье ПОКОМ | B42: шт | C42: 82 | D42: 6 | E42: 77 | F42: 1 | G42: 0.4 | H42: 40 | I42: P003475 | K42: 157 | L42: =E42-K42 -> -80 | O42: 164.6 | R42: 120.88 | S42: =E42/5 -> 15.4 | U42: =(F42+O42+P42+Q42+R42+T42)/S42 -> 18.602597 | V42: =(F42+O42+P42+Q42+R42)/S42 -> 18.602597 | W42: 26.8 | X42: 22.6 | Y42: 12.6 | Z42: 16.8 | AA42: 27.2 | AB42: 28.8 | AC42: 33 | AD42: 28.78 | AE42: 18 | AF42: 15.6 | AG42: 21.8 | AI42: =G42*T42 -> 0 | AJ42: =VLOOKUP(A42,[1]Лист1!$B:$O,14,0) -> матрица
A43: 302 Сосиски Сочинки по-баварски, 0.4кг, ТМ Стародворье ПОКОМ | B43: шт | C43: 245 | D43: 16 | E43: 151 | F43: 102 | G43: 0.4 | H43: 45 | I43: P003217 | K43: 154 | L43: =E43-K43 -> -3 | O43: 0 | R43: 83 | S43: =E43/5 -> 30.2 | U43: =(F43+O43+P43+Q43+R43+T43)/S43 -> 6.1258278 | V43: =(F43+O43+P43+Q43+R43)/S43 -> 6.1258278 | W43: 22.4 | X43: 21.8 | Y43: 19.6 | Z43: 21.4 | AA43: 24.4 | AB43: 27.8 | AC43: 42 | AD43: 32 | AE43: 16.8 | AF43: 16 | AG43: 12.2 | AI43: =G43*T43 -> 0 | AJ43: =VLOOKUP(A43,[1]Лист1!$B:$O,14,0) -> матрица
A44: 304 Колбаса Салями Мясорубская с рубленным шпиком ВЕС ТМ Стародворье ПОКОМ | B44: кг | C44: 141.442 | D44: 1.423 | E44: 63.553 | F44: 67.688 | G44: 1 | H44: 40 | I44: P003276 | K44: 67.8 | L44: =E44-K44 -> -4.247 | O44: 0 | R44: 0 | S44: =E44/5 -> 12.7106 | U44: =(F44+O44+P44+Q44+R44+T44)/S44 -> 5.325319 | V44: =(F44+O44+P44+Q44+R44)/S44 -> 5.325319 | W44: 6.6038 | X44: 9.2596 | Y44: 9.5682 | Z44: 11.018 | AA44: 14.2368 | AB44: 11.3324 | AC44: 1.7376 | AD44: 1.3106 | AE44: 10.1592 | AF44: 6.616 | AG44: 7.5106 | AI44: =G44*T44 -> 0 | AJ44: =VLOOKUP(A44,[1]Лист1!$B:$O,14,0) -> не в матрице
A45: 305 Колбаса Сервелат Мясорубский с мелкорубленным окороком в/у ТМ Стародворье ВЕС ПОКОМ | B45: кг | C45: 185.246 | D45: 5.835 | E45: 127.553 | F45: 25.799 | G45: 1 | H45: 40 | I45: P003259 | K45: 124.3 | L45: =E45-K45 -> 3.253 | O45: 134.914 | R45: 0 | S45: =E45/5 -> 25.5106 | U45: =(F45+O45+P45+Q45+R45+T45)/S45 -> 6.2998518 | V45: =(F45+O45+P45+Q45+R45)/S45 -> 6.2998518 | W45: 21.3786 | X45: 28.646 | Y45: 20.7472 | Z45: 18.888 | AA45: 24.991 | AB45: 20.1832 | AC45: 12.0356 | AD45: 17.4416 | AE45: 20.315 | AF45: 4.5294 | AG45: 18.5532 | AI45: =G45*T45 -> 0 | AJ45: =VLOOKUP(A45,[1]Лист1!$B:$O,14,0) -> матрица
A46: 307 Колбаса Сервелат Мясорубский с мелкорубленным окороком 0,35 кг срез ТМ Стародворье Поком | B46: шт | C46: 421 | D46: 430 | E46: 444 | F46: 338 | G46: 0.35 | H46: 40 | I46: P003260 | K46: 444 | L46: =E46-K46 -> 0 | O46: 156.32 | R46: 2.28 | S46: =E46/5 -> 88.8 | U46: =(F46+O46+P46+Q46+R46+T46)/S46 -> 5.5923423 | V46: =(F46+O46+P46+Q46+R46)/S46 -> 5.5923423 | W46: 72.6 | X46: 95.6 | Y46: 83 | Z46: 71.8 | AA46: 77.2 | AB46: 67.98 | AC46: 25.58 | AD46: 37.4 | AE46: 78 | AF46: 40 | AG46: 84.2 | AI46: =G46*T46 -> 0 | AJ46: =VLOOKUP(A46,[1]Лист1!$B:$O,14,0) -> матрица
A47: 309 Сосиски Сочинки с сыром 0,4 кг ТМ Стародворье ПОКОМ | B47: шт | C47: 68 | D47: 409 | E47: 155 | F47: 298 | G47: 0.4 | H47: 40 | I47: P004178 | K47: 328 | L47: =E47-K47 -> -173 | O47: 319.6 | R47: 0 | S47: =E47/5 -> 31 | U47: =(F47+O47+P47+Q47+R47+T47)/S47 -> 19.922581 | V47: =(F47+O47+P47+Q47+R47)/S47 -> 19.922581 | W47: 47 | X47: 79.6 | Y47: 60 | Z47: 42 | AA47: 28.6 | AB47: 26.6 | AC47: 50.2 | AD47: 51.4 | AE47: 73.4 | AF47: 46.6 | AG47: 53 | AI47: =G47*T47 -> 0 | AJ47: =VLOOKUP(A47,[1]Лист1!$B:$O,14,0) -> матрица
A48: 312 Ветчина Филейская ВЕС ТМ Вязанка ТС Столичная ПОКОМ | B48: кг | C48: 63.414 | E48: 27.971 | F48: 35.057 | G48: 1 | H48: 50 | I48: P003234 | K48: 25.9 | L48: =E48-K48 -> 2.071 | O48: 62.085 | R48: 0 | S48: =E48/5 -> 5.5942 | U48: =(F48+O48+P48+Q48+R48+T48)/S48 -> 17.364771 | V48: =(F48+O48+P48+Q48+R48)/S48 -> 17.364771 | W48: 8.685 | X48: 11.409 | Y48: 5.1622 | Z48: 2.6922 | AA48: 6.464 | AB48: 7.74 | AC48: 4.5076 | AD48: 6.464 | AE48: 6.4568 | AF48: 6.7716 | AG48: 7.5808 | AI48: =G48*T48 -> 0 | AJ48: =VLOOKUP(A48,[1]Лист1!$B:$O,14,0) -> матрица
A49: 315 Колбаса вареная Молокуша ТМ Вязанка ВЕС, ПОКОМ | B49: кг | C49: 232.9 | D49: 4.082 | E49: 101.143 | F49: 121.388 | G49: 1 | H49: 50 | I49: P003239 | K49: 91.25 | L49: =E49-K49 -> 9.893 | O49: 124.3558 | Q49: 150 | R49: 90.4792 | S49: =E49/5 -> 20.2286 | U49: =(F49+O49+P49+Q49+R49+T49)/S49 -> 24.036414 | V49: =(F49+O49+P49+Q49+R49)/S49 -> 24.036414 | W49: 30.9044 | X49: 32.4778 | Y49: 18.959 | Z49: 17.485 | AA49: 29.4156 | AB49: 25.074 | AC49: 17.301 | AD49: 22.005 | AE49: 25.7574 | AF49: 6.9252 | AG49: 16.2096 | AI49: =G49*T49 -> 0 | AJ49: =VLOOKUP(A49,[1]Лист1!$B:$O,14,0) -> матрица
A50: 318 Сосиски Датские ТМ Зареченские, ВЕС ПОКОМ | B50: кг | C50: -0.171 | D50: 89.03 | E50: 1.53 | F50: -0.189 | G50: 1 | H50: 45 | I50: P004991 | K50: 54.9 | L50: =E50-K50 -> -53.37 | O50: 38.2808 | R50: 0 | S50: =E50/5 -> 0.306 | U50: =(F50+O50+P50+Q50+R50+T50)/S50 -> 124.48301 | V50: =(F50+O50+P50+Q50+R50)/S50 -> 124.48301 | W50: 1.5204 | X50: 10.6396 | Y50: 9.4252 | Z50: 0 | AA50: 0 | AB50: 0 | AC50: -0.3036 | AD50: 2.0486 | AE50: 29.5078 | AF50: 3.2396 | AG50: 14.2952 | AI50: =G50*T50 -> 0 | AJ50: =VLOOKUP(A50,[1]Лист1!$B:$O,14,0) -> матрица
A51: 319 Колбаса вареная Филейская ТМ Вязанка ТС Классическая, 0,45 кг. ПОКОМ | B51: шт | C51: 149 | D51: 71 | E51: 159 | F51: 59 | G51: 0.45 | H51: 50 | I51: P003227 | K51: 178 | L51: =E51-K51 -> -19 | O51: 25.2 | R51: 72.62 | S51: =E51/5 -> 31.8 | U51: =(F51+O51+P51+Q51+R51+T51)/S51 -> 4.9314465 | V51: =(F51+O51+P51+Q51+R51)/S51 -> 4.9314465 | W51: 22.2 | X51: 21.8 | Y51: 22.8 | Z51: 20.8 | AA51: 17.4 | AB51: 23 | AC51: 36 | AD51: 29 | AE51: 28 | AF51: 7.2 | AG51: 42.6 | AI51: =G51*T51 -> 0 | AJ51: =VLOOKUP(A51,[1]Лист1!$B:$O,14,0) -> матрица
A52: 322 Колбаса вареная Молокуша 0,45кг ТМ Вязанка ПОКОМ | B52: шт | C52: 251 | D52: 124 | E52: 133 | F52: 233 | G52: 0.45 | H52: 50 | I52: P003228 | K52: 132 | L52: =E52-K52 -> 1 | O52: 163.6 | R52: 0 | S52: =E52/5 -> 26.6 | U52: =(F52+O52+P52+Q52+R52+T52)/S52 -> 14.909774 | V52: =(F52+O52+P52+Q52+R52)/S52 -> 14.909774 | W52: 33.4 | X52: 48.6 | Y52: 40.6 | Z52: 35.6 | AA52: 40.6 | AB52: 40.4 | AC52: 42.6 | AD52: 49.2 | AE52: 37 | AF52: 23.4 | AG52: 35.2 | AI52: =G52*T52 -> 0 | AJ52: =VLOOKUP(A52,[1]Лист1!$B:$O,14,0) -> матрица
A53: 328 Сардельки Сочинки Стародворье ТМ 0,4 кг ПОКОМ | B53: шт | C53: 222 | D53: 4 | E53: 139 | F53: 75 | G53: 0.4 | H53: 40 | I53: P003960 | K53: 143 | L53: =E53-K53 -> -4 | O53: 0 | R53: 62.5 | S53: =E53/5 -> 27.8 | U53: =(F53+O53+P53+Q53+R53+T53)/S53 -> 4.9460432 | V53: =(F53+O53+P53+Q53+R53)/S53 -> 4.9460432 | W53: 19 | X53: 19 | Y53: 9.2 | Z53: 1.2 | AA53: 11.8 | AB53: 23 | AC53: 16.4 | AD53: 12.2 | AE53: 18.4 | AF53: 16.2 | AG53: 23.8 | AI53: =G53*T53 -> 0 | AJ53: =VLOOKUP(A53,[1]Лист1!$B:$O,14,0) -> матрица
...
