Workbook

Sheet Sheet
Z1: 0.71 | AB1: 0.682
R2: 1800 | T2: 4100 | W2: 1540 | Z2: дн | AB2: % | AO2: 12660 | AQ2: 16700
A3: Номенклатура | B3: Ед. изм. | C3: Начальный остаток | D3: Приход | E3: Расход | F3: Конечный остаток | G3: крат | H3: сроки | I3: метка | J3: метка2 | K3: заяв | L3: разн | M3: без опта | N3: опт | O3: заказ в пути | P3: заказ в пути | Q3: заказ в пути | R3: заказ в пути | S3: заказ в пути | T3: заказ в пути | U3: заказ в пути | V3: заказ в пути | W3: заказ в пути | X3: ср нов | Y3: расчет | Z3: итого | AA3: заказ | AB3: заказ | AC3: ТК | AD3: кон ост | AE3: факт | AF3: ср | AG3: ср | AH3: ср | AI3: ср | AJ3: ср | AK3: ср | AL3: ср | AM3: ср | AN3: комментарии | AO3: вес | AQ3: вес
O4: брак | P4: 01,09, | Q4: 01,09,предзаказ | R4: 01,09,доз | S4: 02,09, | T4: 02,09,доз | U4: 02,09,(2) | V4: 02,09,(2)недогр | W4: 02,09,(2)доз | X4: 30,07, | AA4: 03,08, | AB4: 04,08, | AC4: Боярко | AF4: 28,07, | AG4: 23,07, | AH4: 21,07, | AI4: 20,07, | AJ4: 16,07, | AK4: 14,07, | AL4: 09,07, | AM4: 07,07, | AO4: 03,08, | AQ4: 04,08,
E5: =SUM(E6:E492) -> 67932.835 | F5: =SUM(F6:F492) -> 50904.662 | K5: =SUM(K6:K492) -> 78555.285 | L5: =SUM(L6:L492) -> -10622.45 | M5: =SUM(M6:M492) -> 63818.748 | N5: =SUM(N6:N492) -> 4114.087 | O5: =SUM(O6:O492) -> -3500 | P5: =SUM(P6:P492) -> 25070.966 | Q5: =SUM(Q6:Q492) -> 15350 | R5: =SUM(R6:R492) -> 1800 | ... AB5: =SUM(AB6:AB492) -> 21727.185 | AF5: =SUM(AF6:AF492) -> 14118.473 | AG5: =SUM(AG6:AG492) -> 10392.848 | AH5: =SUM(AH6:AH492) -> 11560.837 | AI5: =SUM(AI6:AI492) -> 11734.199 | AJ5: =SUM(AJ6:AJ492) -> 14138.868 | AK5: =SUM(AK6:AK492) -> 14537.335 | AL5: =SUM(AL6:AL492) -> 14045.693 | AM5: =SUM(AM6:AM492) -> 13116.187 | AO5: =SUM(AO6:AO492) -> 12671 | AQ5: =SUM(AQ6:AQ492) -> 16729
A6: 005 Колбаса Докторская ГОСТ, Вязанка вектор,ВЕС. ПОКОМ | B6: кг | C6: 1920.41 | D6: 2613.872 | E6: 1919.583 | F6: 2027.259 | G6: 1 | H6: 50 | I6: ТОП / матрица | K6: 1966.02 | L6: =E6-K6 -> -46.437 | M6: =E6-N6 -> 1919.583 | P6: 725.08628 | S6: 800 | X6: =M6/5 -> 383.9166 | Y6: =11.5*X6-W6-U6-S6-P6-O6-F6 -> 862.69562 | Z6: =Y6+$Z$1*X6 -> 1135.2764 | AA6: =Z6-AB6 -> 361.0179 | AB6: =$AB$1*Z6 -> 774.25851 | AD6: =(F6+O6+P6+S6+U6+W6+Z6+Q6+T6+R6+V6)/X6 -> 12.21 | AE6: =(F6+O6+P6+S6+U6+W6)/X6 -> 9.2529088 | AF6: 414.5354 | AG6: 309.1234 | AH6: 397.2206 | AI6: 387.4498 | AJ6: 475.3052 | AK6: 548.6424 | AL6: 471.7946 | AM6: 438.9076 | AO6: =ROUND(G6*AA6,0) -> 361 | AP6: =VLOOKUP(A6,[1]Лист1!$A:$B,2,0) -> 361 | AQ6: =ROUND(G6*AB6,0) -> 774
A7: 016 Сосиски Вязанка Молочные, Вязанка вискофан ВЕС.ПОКОМ | B7: кг | C7: 598.005 | D7: 1030.546 | E7: 1194.783 | F7: 190.639 | G7: 1 | H7: 45 | I7: ТОП / матрица | K7: 1150.703 | L7: =E7-K7 -> 44.08 | M7: =E7-N7 -> 1161.967 | N7: 32.816 | P7: 284.72726 | Q7: 800 | X7: =M7/5 -> 232.3934 | Y7: =11.5*X7-W7-U7-S7-P7-O7-F7-Q7 -> 1397.1578 | Z7: =Y7+$Z$1*X7 -> 1562.1572 | AA7: =Z7-AB7 -> 496.76597 | AB7: =$AB$1*Z7 -> 1065.3912 | AD7: =(F7+O7+P7+S7+U7+W7+Z7+Q7+T7+R7+V7)/X7 -> 12.21 | AE7: =(F7+O7+P7+S7+U7+W7)/X7 -> 2.0455239 | AF7: 194.2758 | AG7: 139.5838 | AH7: 139.1384 | AI7: 153.544 | AJ7: 198.9838 | AK7: 211.201 | AL7: 193.3256 | AM7: 182.8198 | AO7: =ROUND(G7*AA7,0) -> 497 | AP7: =VLOOKUP(A7,[1]Лист1!$A:$B,2,0) -> 497 | AQ7: =ROUND(G7*AB7,0) -> 1065
A8: 017 Сосиски Вязанка Сливочные, Вязанка амицел ВЕС.ПОКОМ | B8: кг | C8: 2259.225 | D8: 3088.687 | E8: 3123.736 | F8: 801.897 | G8: 1 | H8: 45 | I8: ТОП / матрица | K8: 3159.01 | L8: =E8-K8 -> -35.274 | M8: =E8-N8 -> 3018.04 | N8: 105.696 | P8: 800 | Q8: 2300 | U8: 500 | X8: =M8/5 -> 603.608 | Y8: =11.5*X8-W8-U8-S8-P8-O8-F8-Q8 -> 2539.595 | Z8: =Y8+$Z$1*X8 -> 2968.1567 | AA8: =Z8-AB8 -> 943.87382 | AB8: =$AB$1*Z8 -> 2024.2829 | AD8: =(F8+O8+P8+S8+U8+W8+Z8+Q8+T8+R8+V8)/X8 -> 12.21 | AE8: =(F8+O8+P8+S8+U8+W8)/X8 -> 3.4822219 | AF8: 601.6022 | AG8: 449.453 | AH8: 483.4718 | AI8: 504.7164 | AJ8: 603.9064 | AK8: 611.2856 | AL8: 564.6566 | AM8: 559.115 | AO8: =ROUND(G8*AA8,0) -> 944 | AP8: =VLOOKUP(A8,[1]Лист1!$A:$B,2,0) -> 944 | AQ8: =ROUND(G8*AB8,0) -> 2024
A9: 023 Колбаса Докторская ГОСТ, Вязанка вектор, 0,4 кг, ПОКОМ | B9: шт | D9: 22 | E9: 13 | F9: 6 | G9: 0.4 | H9: 50 | I9: матрица | K9: 21 | L9: =E9-K9 -> -8 | M9: =E9-N9 -> 13 | P9: 13 | X9: =M9/5 -> 2.6 | Y9: =11.5*X9-W9-U9-S9-P9-O9-F9 -> 10.9 | Z9: =Y9 -> 10.9 | AA9: =Z9-AB9 -> 10.9 | AD9: =(F9+O9+P9+S9+U9+W9+Z9+Q9+T9+R9+V9)/X9 -> 11.5 | AE9: =(F9+O9+P9+S9+U9+W9)/X9 -> 7.3076923 | AF9: 2.2 | AG9: 0 | AH9: 0 | AI9: 0 | AJ9: 0 | AK9: 0.6 | AL9: 0.6 | AM9: 0 | AN9: 19 шт списано (12,07,26) | AO9: =ROUND(G9*AA9,0) -> 4 | AP9: =VLOOKUP(A9,[1]Лист1!$A:$B,2,0) -> 4 | AQ9: =ROUND(G9*AB9,0) -> 0
A10: 030 Сосиски Вязанка Молочные, Вязанка вискофан МГС, 0.45кг, ПОКОМ | B10: шт | C10: 292 | D10: 3888.201 | E10: 3529.355 | F10: 126.645 | G10: 0.45 | H10: 45 | I10: ВНИМАНИЕ / матрица | K10: 3764 | L10: =E10-K10 -> -234.645 | M10: =E10-N10 -> 3529.355 | P10: 1000 | U10: 1000 | X10: =M10/5 -> 705.871 | Y10: 3000 | Z10: =Y10 -> 3000 | AA10: =Z10-AB10 -> 954 | AB10: =$AB$1*Z10 -> 2046 | AD10: =(F10+O10+P10+S10+U10+W10+Z10+Q10+T10+R10+V10)/X10 -> 7.2628639 | AE10: =(F10+O10+P10+S10+U10+W10)/X10 -> 3.0127955 | AF10: 624.671 | AG10: 265.4 | AH10: 547.2 | AI10: 563.6 | AJ10: 673.6 | AK10: 380.8 | AL10: 376.4 | AM10: 381.8 | AN10: 1000шт под ЮТЛ (Хмель 15,07,26) | AO10: =ROUND(G10*AA10,0) -> 429 | AP10: =VLOOKUP(A10,[1]Лист1!$A:$B,2,0) -> 429 | AQ10: =ROUND(G10*AB10,0) -> 921
A11: 032 Сосиски Вязанка Сливочные, Вязанка амицел МГС, 0.45кг, ПОКОМ | B11: шт | C11: 3172 | D11: 2301 | E11: 3536.829 | F11: 1075.171 | G11: 0.45 | H11: 45 | I11: ТОП / матрица | K11: 3813 | L11: =E11-K11 -> -276.171 | M11: =E11-N11 -> 3536.829 | P11: 1989.487 | U11: 3000 | X11: =M11/5 -> 707.3658 | Y11: =11.5*X11-W11-U11-S11-P11-O11-F11 -> 2070.0487 | Z11: =Y11+$Z$1*X11 -> 2572.2784 | AA11: =Z11-AB11 -> 817.98454 | AB11: =$AB$1*Z11 -> 1754.2939 | AD11: =(F11+O11+P11+S11+U11+W11+Z11+Q11+T11+R11+V11)/X11 -> 12.21 | AE11: =(F11+O11+P11+S11+U11+W11)/X11 -> 8.573581 | AF11: 771.7658 | AG11: 431.2 | AH11: 445.4 | AI11: 495.2 | AJ11: 660.46 | AK11: 717.66 | AL11: 698.8 | AM11: 602.2 | AO11: =ROUND(G11*AA11,0) -> 368 | AP11: =VLOOKUP(A11,[1]Лист1!$A:$B,2,0) -> 368 | AQ11: =ROUND(G11*AB11,0) -> 789
A12: 047 Кол Баварская, белков.обол. в термоусад. пакете 0.17 кг, ТМ Стародворье ПОКОМ | B12: шт | C12: 66 | D12: 143 | E12: 175 | F12: 17 | G12: 0.17 | H12: 180 | I12: матрица | K12: 181 | L12: =E12-K12 -> -6 | M12: =E12-N12 -> 175 | P12: 150.6 | X12: =M12/5 -> 35 | Y12: =11.5*X12-W12-U12-S12-P12-O12-F12 -> 234.9 | Z12: =Y12 -> 234.9 | AA12: =Z12-AB12 -> 234.9 | AD12: =(F12+O12+P12+S12+U12+W12+Z12+Q12+T12+R12+V12)/X12 -> 11.5 | AE12: =(F12+O12+P12+S12+U12+W12)/X12 -> 4.7885714 | AF12: 24.6 | AG12: 9 | AH12: 5.4 | AI12: 12.6 | AJ12: 17.2 | AK12: 21 | AL12: 14.4 | AM12: 13.6 | AO12: =ROUND(G12*AA12,0) -> 40 | AP12: =VLOOKUP(A12,[1]Лист1!$A:$B,2,0) -> 40 | AQ12: =ROUND(G12*AB12,0) -> 0
A13: 062 Колбаса Кракушка пряная с сальцем, 0.3кг в/у п/к, БАВАРУШКА ПОКОМ | B13: шт | C13: 1 | D13: 122 | E13: 42 | F13: 53 | G13: 0.3 | H13: 40 | I13: матрица | K13: 50 | L13: =E13-K13 -> -8 | M13: =E13-N13 -> 42 | P13: 0 | X13: =M13/5 -> 8.4 | Y13: =11.5*X13-W13-U13-S13-P13-O13-F13 -> 43.6 | Z13: =Y13 -> 43.6 | AA13: =Z13-AB13 -> 43.6 | AD13: =(F13+O13+P13+S13+U13+W13+Z13+Q13+T13+R13+V13)/X13 -> 11.5 | AE13: =(F13+O13+P13+S13+U13+W13)/X13 -> 6.3095238 | AF13: 3.2 | AG13: 1 | AH13: 0.8 | AI13: 2.6 | AJ13: 9.4 | AK13: 13.4 | AL13: 4.4 | AM13: 0.4 | AO13: =ROUND(G13*AA13,0) -> 13 | AP13: =VLOOKUP(A13,[1]Лист1!$A:$B,2,0) -> 13 | AQ13: =ROUND(G13*AB13,0) -> 0
A14: 083 Колбаса Швейцарская 0,17 кг., ШТ., сырокопченая ПОКОМ | B14: шт | C14: 484 | D14: 80 | E14: 301 | F14: 230 | G14: 0.17 | H14: 180 | I14: матрица | K14: 307 | L14: =E14-K14 -> -6 | M14: =E14-N14 -> 301 | P14: 384.2 | X14: =M14/5 -> 60.2 | Y14: =11.5*X14-W14-U14-S14-P14-O14-F14 -> 78.1 | Z14: =Y14 -> 78.1 | AA14: =Z14-AB14 -> 78.1 | AD14: =(F14+O14+P14+S14+U14+W14+Z14+Q14+T14+R14+V14)/X14 -> 11.5 | AE14: =(F14+O14+P14+S14+U14+W14)/X14 -> 10.202658 | AF14: 65.2 | AG14: 36.6 | AH14: 21.4 | AI14: 16.2 | AJ14: 29.4 | AK14: 74.2 | AL14: 73.8 | AM14: 37.6 | AO14: =ROUND(G14*AA14,0) -> 13 | AP14: =VLOOKUP(A14,[1]Лист1!$A:$B,2,0) -> 13 | AQ14: =ROUND(G14*AB14,0) -> 0
A15: 103 Сосиски Классические, 0.42кг,ядрена копотьПОКОМ | B15: шт | D15: 384 | E15: 21 | F15: 363 | G15: 0 | I15: не в матрице | K15: 27 | L15: =E15-K15 -> -6 | M15: =E15-N15 -> 21 | P15: 0 | X15: =M15/5 -> 4.2 | Z15: =Y15 -> 0 | AA15: =Z15-AB15 -> 0 | AD15: =(F15+O15+P15+S15+U15+W15+Z15+Q15+T15+R15+V15)/X15 -> 86.428571 | AE15: =(F15+O15+P15+S15+U15+W15)/X15 -> 86.428571 | AF15: 0 | AG15: 0 | AH15: 0 | AI15: 0 | AJ15: 0 | AK15: 0 | AL15: 0 | AM15: 0 | AN15: перемещение ЛП???? | AO15: =ROUND(G15*AA15,0) -> 0 | AP15: =VLOOKUP(A15,[1]Лист1!$A:$B,2,0) -> 0 | AQ15: =ROUND(G15*AB15,0) -> 0
A16: 200 Ветчина Дугушка ТМ Стародворье, вектор в/у ПОКОМ | B16: кг | C16: 3574.535 | D16: 3026.318 | E16: 3733.977 | F16: 1545.165 | G16: 1 | H16: 70 | I16: ТОП / матрица | K16: 3676.315 | L16: =E16-K16 -> 57.662 | M16: =E16-N16 -> 3733.977 | P16: 1737 | S16: 800 | U16: 2000 | X16: =M16/5 -> 746.7954 | Y16: =11.5*X16-W16-U16-S16-P16-O16-F16 -> 2505.9821 | Z16: =Y16+$Z$1*X16 -> 3036.2068 | AA16: =Z16-AB16 -> 965.51377 | AB16: =$AB$1*Z16 -> 2070.6931 | AD16: =(F16+O16+P16+S16+U16+W16+Z16+Q16+T16+R16+V16)/X16 -> 12.21 | AE16: =(F16+O16+P16+S16+U16+W16)/X16 -> 8.1443525 | AF16: 794.7714 | AG16: 554.7976 | AH16: 546.9378 | AI16: 609.0922 | AJ16: 717.986 | AK16: 729.0608 | AL16: 733.4764 | AM16: 698.6224 | AO16: =ROUND(G16*AA16,0) -> 966 | AP16: =VLOOKUP(A16,[1]Лист1!$A:$B,2,0) -> 966 | AQ16: =ROUND(G16*AB16,0) -> 2071
A17: 201 Ветчина Нежная ТМ Особый рецепт, (2,5кг), ПОКОМ | B17: кг | C17: 1513.126 | D17: 6049.657 | E17: 2687.715 | F17: 4010.619 | G17: 1 | H17: 50 | I17: ТОП / матрица | K17: 2760.232 | L17: =E17-K17 -> -72.517 | M17: =E17-N17 -> 2687.715 | P17: 0 | Q17: 1400 | X17: =M17/5 -> 537.543 | Y17: =11.5*X17-W17-U17-S17-P17-O17-F17-Q17 -> 771.1255 | Z17: =Y17+$Z$1*X17 -> 1152.781 | AA17: =Z17-AB17 -> 366.58437 | AB17: =$AB$1*Z17 -> 786.19666 | AD17: =(F17+O17+P17+S17+U17+W17+Z17+Q17+T17+R17+V17)/X17 -> 12.21 | AE17: =(F17+O17+P17+S17+U17+W17)/X17 -> 7.4610199 | AF17: 623.7324 | AG17: 623.553 | AH17: 655.5956 | AI17: 514.5316 | AJ17: 650.9978 | AK17: 665.4226 | AL17: 618.9746 | AM17: 533.1102 | AO17: =ROUND(G17*AA17,0) -> 367 | AP17: =VLOOKUP(A17,[1]Лист1!$A:$B,2,0) -> 367 | AQ17: =ROUND(G17*AB17,0) -> 786
A18: 215 Колбаса Докторская ГОСТ Дугушка, ВЕС, ТМ Стародворье ПОКОМ | B18: кг | C18: 312.585 | D18: 200.646 | E18: 94.51 | F18: 327.364 | G18: 1 | H18: 60 | I18: матрица | K18: 324.4 | L18: =E18-K18 -> -229.89 | M18: =E18-N18 -> 94.51 | P18: 0 | X18: =M18/5 -> 18.902 | Z18: =Y18 -> 0 | AA18: =Z18-AB18 -> 0 | AD18: =(F18+O18+P18+S18+U18+W18+Z18+Q18+T18+R18+V18)/X18 -> 17.319014 | AE18: =(F18+O18+P18+S18+U18+W18)/X18 -> 17.319014 | AF18: 36.5078 | AG18: 45.232 | AH18: 39.9126 | AI18: 46.7558 | AJ18: 52.6862 | AK18: 53.1126 | AL18: 49.3644 | AM18: 53.1448 | AO18: =ROUND(G18*AA18,0) -> 0 | AP18: =VLOOKUP(A18,[1]Лист1!$A:$B,2,0) -> 0 | AQ18: =ROUND(G18*AB18,0) -> 0
A19: 219 Колбаса Докторская Особая ТМ Особый рецепт, ВЕС ПОКОМ | B19: кг | E19: 2.474 | F19: -4.974 | G19: 0 | I19: не в матрице | J19: 597 Колбаса Классическая ТМ Особый рецепт в оболочке полиамид ВЕС. ПОКОМ | K19: 5 | L19: =E19-K19 -> -2.526 | M19: =E19-N19 -> 2.474 | P19: 0 | X19: =M19/5 -> 0.4948 | Z19: =Y19 -> 0 | AA19: =Z19-AB19 -> 0 | AD19: =(F19+O19+P19+S19+U19+W19+Z19+Q19+T19+R19+V19)/X19 -> -10.052546 | AE19: =(F19+O19+P19+S19+U19+W19)/X19 -> -10.052546 | AF19: 0.4948 | AG19: 0 | AH19: 0 | AI19: 0 | AJ19: 0 | AK19: 0 | AL19: 0 | AM19: 0 | AO19: =ROUND(G19*AA19,0) -> 0 | AP19: =VLOOKUP(A19,[1]Лист1!$A:$B,2,0) -> 0 | AQ19: =ROUND(G19*AB19,0) -> 0
A20: 225 Колбаса Дугушка со шпиком, ВЕС, ТМ Стародворье ПОКОМ | B20: кг | G20: 0 | I20: матрица | L20: =E20-K20 -> 0 | M20: =E20-N20 -> 0 | P20: 0 | X20: =M20/5 -> 0 | Z20: =Y20 -> 0 | AA20: =Z20-AB20 -> 0 | AD20: =(F20+O20+P20+S20+U20+W20+Z20+Q20+T20+R20+V20)/X20 -> #DIV/0! | AE20: =(F20+O20+P20+S20+U20+W20)/X20 -> #DIV/0! | AF20: 0 | AG20: 0 | AH20: 0 | AI20: 0 | AJ20: 0 | AK20: 0 | AL20: 0 | AM20: 0 | AN20: нет потребности | AO20: =ROUND(G20*AA20,0) -> 0 | AP20: =VLOOKUP(A20,[1]Лист1!$A:$B,2,0) -> 0 | AQ20: =ROUND(G20*AB20,0) -> 0
A21: 226 Колбаса Княжеская, с/к белков.обол в термоусад. пакете, ВЕС, ТМ Стародворье ПОКОМ | B21: кг | C21: 6.465 | D21: 16.745 | E21: 5.224 | F21: 15.841 | G21: 1 | H21: 180 | I21: матрица | K21: 4.7 | L21: =E21-K21 -> 0.524 | M21: =E21-N21 -> 5.224 | P21: 0 | X21: =M21/5 -> 1.0448 | Z21: =Y21 -> 0 | AA21: =Z21-AB21 -> 0 | AD21: =(F21+O21+P21+S21+U21+W21+Z21+Q21+T21+R21+V21)/X21 -> 15.161753 | AE21: =(F21+O21+P21+S21+U21+W21)/X21 -> 15.161753 | AF21: 1.1864 | AG21: 0.4298 | AH21: 0.5714 | AI21: 0.6346 | AJ21: 1.0534 | AK21: 1.054 | AL21: 0.2838 | AM21: 0.07 | AO21: =ROUND(G21*AA21,0) -> 0 | AP21: =VLOOKUP(A21,[1]Лист1!$A:$B,2,0) -> 0 | AQ21: =ROUND(G21*AB21,0) -> 0
A22: 229 Колбаса Молочная Дугушка, в/у, ВЕС, ТМ Стародворье ПОКОМ | B22: кг | C22: 2521.835 | D22: 4798.296 | E22: 4162.983 | F22: 1694.723 | G22: 1 | H22: 60 | I22: ТОП / матрица | K22: 4092.73 | L22: =E22-K22 -> 70.253 | M22: =E22-N22 -> 3982.753 | N22: 180.23 | P22: 1901.5916 | U22: 3500 | X22: =M22/5 -> 796.5506 | Y22: =11.5*X22-W22-U22-S22-P22-O22-F22 -> 2064.0173 | Z22: =Y22+$Z$1*X22 -> 2629.5682 | AA22: =Z22-AB22 -> 836.2027 | AB22: =$AB$1*Z22 -> 1793.3655 | AD22: =(F22+O22+P22+S22+U22+W22+Z22+Q22+T22+R22+V22)/X22 -> 12.21 | AE22: =(F22+O22+P22+S22+U22+W22)/X22 -> 8.9088058 | AF22: 870.4836 | AG22: 625.4246 | AH22: 675.5632 | AI22: 724.8188 | AJ22: 877.0252 | AK22: 881.8386 | AL22: 955.7506 | AM22: 939.1438 | AO22: =ROUND(G22*AA22,0) -> 836 | AP22: =VLOOKUP(A22,[1]Лист1!$A:$B,2,0) -> 836 | AQ22: =ROUND(G22*AB22,0) -> 1793
A23: 230 Колбаса Молочная Особая ТМ Особый рецепт, п/а, ВЕС. ПОКОМ | B23: кг | E23: 7.493 | F23: -7.493 | G23: 0 | I23: не в матрице | J23: 457 Колбаса Молочная ТМ Особый рецепт ВЕС большой батон ПОКОМ | K23: 7.5 | L23: =E23-K23 -> -0.007 | M23: =E23-N23 -> 7.493 | P23: 0 | X23: =M23/5 -> 1.4986 | Z23: =Y23 -> 0 | AA23: =Z23-AB23 -> 0 | AD23: =(F23+O23+P23+S23+U23+W23+Z23+Q23+T23+R23+V23)/X23 -> -5 | AE23: =(F23+O23+P23+S23+U23+W23)/X23 -> -5 | AF23: 1.4986 | AG23: 0 | AH23: 0 | AI23: 0 | AJ23: 0 | AK23: 0 | AL23: 0 | AM23: 0 | AO23: =ROUND(G23*AA23,0) -> 0 | AP23: =VLOOKUP(A23,[1]Лист1!$A:$B,2,0) -> 0 | AQ23: =ROUND(G23*AB23,0) -> 0
A24: 236 Колбаса Рубленая ЗАПЕЧ. Дугушка ТМ Стародворье, вектор, в/к ПОКОМ | B24: кг | C24: 741.007 | D24: 184.474 | E24: 532.792 | F24: 301.059 | G24: 1 | H24: 70 | I24: матрица | K24: 561.19 | L24: =E24-K24 -> -28.398 | M24: =E24-N24 -> 432.592 | N24: 100.2 | P24: 343.26726 | U24: 300 | X24: =M24/5 -> 86.5184 | Y24: =11.5*X24-W24-U24-S24-P24-O24-F24 -> 50.63534 | Z24: =Y24 -> 50.63534 | AA24: =Z24-AB24 -> 50.63534 | AD24: =(F24+O24+P24+S24+U24+W24+Z24+Q24+T24+R24+V24)/X24 -> 11.5 | AE24: =(F24+O24+P24+S24+U24+W24)/X24 -> 10.914745 | AF24: 112.269 | AG24: 80.8328 | AH24: 82.7806 | AI24: 84.446 | AJ24: 87.767 | AK24: 81.9844 | AL24: 105.7922 | AM24: 91.559 | AO24: =ROUND(G24*AA24,0) -> 51 | AP24: =VLOOKUP(A24,[1]Лист1!$A:$B,2,0) -> 51 | AQ24: =ROUND(G24*AB24,0) -> 0
A25: 239 Колбаса Салями запеч Дугушка, оболочка вектор, ВЕС, ТМ Стародворье ПОКОМ | B25: кг | C25: 976.162 | D25: 1194.1 | E25: 1424.302 | F25: 547.821 | G25: 1 | H25: 70 | I25: ТОП / матрица | K25: 1400.889 | L25: =E25-K25 -> 23.413 | M25: =E25-N25 -> 1271.232 | N25: 153.07 | P25: 723.0628 | U25: 800 | X25: =M25/5 -> 254.2464 | Y25: =11.5*X25-W25-U25-S25-P25-O25-F25 -> 852.9498 | Z25: =Y25+$Z$1*X25 -> 1033.4647 | AA25: =Z25-AB25 -> 328.64179 | AB25: =$AB$1*Z25 -> 704.82296 | AD25: =(F25+O25+P25+S25+U25+W25+Z25+Q25+T25+R25+V25)/X25 -> 12.21 | AE25: =(F25+O25+P25+S25+U25+W25)/X25 -> 8.1451844 | AF25: 255.9778 | AG25: 183.0002 | AH25: 190.5056 | AI25: 210.4278 | AJ25: 235.951 | AK25: 225.54 | AL25: 220.3834 | AM25: 213.5002 | AO25: =ROUND(G25*AA25,0) -> 329 | AP25: =VLOOKUP(A25,[1]Лист1!$A:$B,2,0) -> 329 | AQ25: =ROUND(G25*AB25,0) -> 705
A26: 240 Колбаса Салями охотничья, ВЕС. ПОКОМ | B26: кг | G26: 0 | I26: матрица | L26: =E26-K26 -> 0 | M26: =E26-N26 -> 0 | P26: 0 | X26: =M26/5 -> 0 | Z26: =Y26 -> 0 | AA26: =Z26-AB26 -> 0 | AD26: =(F26+O26+P26+S26+U26+W26+Z26+Q26+T26+R26+V26)/X26 -> #DIV/0! | AE26: =(F26+O26+P26+S26+U26+W26)/X26 -> #DIV/0! | AF26: 0 | AG26: 0 | AH26: 0 | AI26: 0 | AJ26: 0 | AK26: 0 | AL26: 0 | AM26: 0 | AN26: нет потребности | AO26: =ROUND(G26*AA26,0) -> 0 | AP26: =VLOOKUP(A26,[1]Лист1!$A:$B,2,0) -> 0 | AQ26: =ROUND(G26*AB26,0) -> 0
A27: 242 Колбаса Сервелат ЗАПЕЧ.Дугушка ТМ Стародворье, вектор, в/к ПОКОМ | B27: кг | C27: 1747.523 | D27: 2040.44 | E27: 2087.016 | F27: 998.595 | G27: 1 | H27: 70 | I27: ТОП / матрица | K27: 2108.8 | L27: =E27-K27 -> -21.784 | M27: =E27-N27 -> 2087.016 | P27: 784.0868 | U27: 2000 | X27: =M27/5 -> 417.4032 | Y27: =11.5*X27-W27-U27-S27-P27-O27-F27 -> 1017.455 | Z27: =Y27+$Z$1*X27 -> 1313.8113 | AA27: =Z27-AB27 -> 417.79198 | AB27: =$AB$1*Z27 -> 896.01929 | AD27: =(F27+O27+P27+S27+U27+W27+Z27+Q27+T27+R27+V27)/X27 -> 12.21 | AE27: =(F27+O27+P27+S27+U27+W27)/X27 -> 9.0624169 | AF27: 457.0628 | AG27: 304.7148 | AH27: 332.0396 | AI27: 377.9864 | AJ27: 429.1764 | AK27: 423.8756 | AL27: 418.3464 | AM27: 400.0342 | AO27: =ROUND(G27*AA27,0) -> 418 | AP27: =VLOOKUP(A27,[1]Лист1!$A:$B,2,0) -> 418 | AQ27: =ROUND(G27*AB27,0) -> 896
A28: 244 Колбаса Сервелат Кремлевский, ВЕС. ПОКОМ | B28: кг | C28: 44.959 | D28: 2.925 | E28: 39.256 | F28: 4.281 | G28: 1 | H28: 40 | I28: матрица | K28: 39.3 | L28: =E28-K28 -> -0.044 | M28: =E28-N28 -> 39.256 | P28: 49.6042 | X28: =M28/5 -> 7.8512 | Y28: =11.5*X28-W28-U28-S28-P28-O28-F28 -> 36.4036 | Z28: =Y28 -> 36.4036 | AA28: =Z28-AB28 -> 36.4036 | AD28: =(F28+O28+P28+S28+U28+W28+Z28+Q28+T28+R28+V28)/X28 -> 11.5 | AE28: =(F28+O28+P28+S28+U28+W28)/X28 -> 6.8633075 | AF28: 8.7356 | AG28: 3.5048 | AH28: 4.648 | AI28: 5.948 | AJ28: 7.4024 | AK28: 6.248 | AL28: 11.03 | AM28: 9.5734 | AO28: =ROUND(G28*AA28,0) -> 36 | AP28: =VLOOKUP(A28,[1]Лист1!$A:$B,2,0) -> 36 | AQ28: =ROUND(G28*AB28,0) -> 0
A29: 247 Сардельки Нежные, ВЕС. ПОКОМ | B29: кг | G29: 0 | I29: матрица | L29: =E29-K29 -> 0 | M29: =E29-N29 -> 0 | P29: 0 | X29: =M29/5 -> 0 | Z29: =Y29 -> 0 | AA29: =Z29-AB29 -> 0 | AD29: =(F29+O29+P29+S29+U29+W29+Z29+Q29+T29+R29+V29)/X29 -> #DIV/0! | AE29: =(F29+O29+P29+S29+U29+W29)/X29 -> #DIV/0! | AF29: 0 | AG29: 0 | AH29: 0 | AI29: 0 | AJ29: 0 | AK29: 0 | AL29: 0 | AM29: 0 | AN29: нет потребности | AO29: =ROUND(G29*AA29,0) -> 0 | AP29: =VLOOKUP(A29,[1]Лист1!$A:$B,2,0) -> 0 | AQ29: =ROUND(G29*AB29,0) -> 0
A30: 248 Сардельки Сочные ТМ Особый рецепт, ПОКОМ | B30: кг | G30: 0 | I30: матрица | L30: =E30-K30 -> 0 | M30: =E30-N30 -> 0 | P30: 0 | X30: =M30/5 -> 0 | Z30: =Y30 -> 0 | AA30: =Z30-AB30 -> 0 | AD30: =(F30+O30+P30+S30+U30+W30+Z30+Q30+T30+R30+V30)/X30 -> #DIV/0! | AE30: =(F30+O30+P30+S30+U30+W30)/X30 -> #DIV/0! | AF30: 0 | AG30: 0 | AH30: 0 | AI30: 0 | AJ30: 0 | AK30: 0 | AL30: 0 | AM30: 0 | AN30: нет потребности | AO30: =ROUND(G30*AA30,0) -> 0 | AP30: =VLOOKUP(A30,[1]Лист1!$A:$B,2,0) -> 0 | AQ30: =ROUND(G30*AB30,0) -> 0
A31: 250 Сардельки стародворские с говядиной в обол. NDX, ВЕС. ПОКОМ | B31: кг | C31: 4422.644 | D31: 3561.144 | E31: 1963.7 | F31: 4970.949 | G31: 1 | H31: 30 | I31: ТОП / матрица | K31: 3116.16 | L31: =E31-K31 -> -1152.46 | M31: =E31-N31 -> 1257.413 | N31: 706.287 | O31: -3500 | P31: 316.48536 | U31: 400 | X31: =M31/5 -> 251.4826 | Y31: =11.5*X31-W31-U31-S31-P31-O31-F31 -> 704.61554 | Z31: =Y31+$Z$1*X31 -> 883.16819 | AA31: =Z31-AB31 -> 280.84748 | AB31: =$AB$1*Z31 -> 602.3207 | AD31: =(F31+O31+P31+S31+U31+W31+Z31+Q31+T31+R31+V31)/X31 -> 12.21 | AE31: =(F31+O31+P31+S31+U31+W31)/X31 -> 8.6981539 | AF31: 368.8554 | AG31: 396.4942 | AH31: 440.455 | AI31: 413.2102 | AJ31: 344.917 | AK31: 256.0514 | AL31: 349.7722 | AM31: 272.0672 | AN31: 3500кг БРАК!!! | AO31: =ROUND(G31*AA31,0) -> 281 | AP31: =VLOOKUP(A31,[1]Лист1!$A:$B,2,0) -> 281 | AQ31: =ROUND(G31*AB31,0) -> 602
A32: 253 Сосиски Ганноверские ПОКОМ | B32: кг | C32: 63.019 | E32: 62.759 | F32: -0.23 | G32: 0 | H32: 40 | I32: не в матрице | K32: 61.5 | L32: =E32-K32 -> 1.259 | M32: =E32-N32 -> 62.759 | P32: 0 | X32: =M32/5 -> 12.5518 | Z32: =Y32 -> 0 | AA32: =Z32-AB32 -> 0 | AD32: =(F32+O32+P32+S32+U32+W32+Z32+Q32+T32+R32+V32)/X32 -> -0.018324065 | AE32: =(F32+O32+P32+S32+U32+W32)/X32 -> -0.018324065 | AF32: 13.9894 | AG32: 4.5704 | AH32: 4.0182 | AI32: 1.0574 | AJ32: 8.8558 | AK32: 9.4266 | AL32: 13.422 | AM32: 12.8826 | AO32: =ROUND(G32*AA32,0) -> 0 | AP32: =VLOOKUP(A32,[1]Лист1!$A:$B,2,0) -> 0 | AQ32: =ROUND(G32*AB32,0) -> 0
A33: 255 Сосиски Молочные для завтрака ТМ Особый рецепт, п/а МГС, ВЕС, ТМ Стародворье ПОКОМ | B33: кг | C33: 3657.191 | D33: 1904.166 | E33: 4239.912 | F33: -103.289 | G33: 1 | H33: 40 | I33: ТОП / матрица | K33: 7840.504 | L33: =E33-K33 -> -3600.592 | M33: =E33-N33 -> 3440.216 | N33: 799.696 | P33: 1200 | Q33: 6000 | U33: 500 | V33: -504 | X33: =M33/5 -> 688.0432 | Y33: =11.5*X33-W33-U33-S33-P33-O33-F33-Q33 -> 315.7858 | Z33: =Y33+$Z$1*X33 -> 804.29647 | AA33: =Z33-AB33 -> 804.29647 | AD33: =(F33+O33+P33+S33+U33+W33+Z33+Q33+T33+R33+V33)/X33 -> 11.477488 | AE33: =(F33+O33+P33+S33+U33+W33)/X33 -> 2.3206552 | AF33: 1184.2532 | AG33: 1031.4698 | AH33: 1271.6156 | AI33: 1208.7454 | AJ33: 1373.8782 | AK33: 1608.1394 | AL33: 1503.0754 | AM33: 1112.3946 | AO33: =ROUND(G33*AA33,0) -> 804 | AP33: =VLOOKUP(A33,[1]Лист1!$A:$B,2,0) -> 804 | AQ33: =ROUND(G33*AB33,0) -> 0
A34: 257 Сосиски Молочные оригинальные ТМ Особый рецепт, ВЕС. ПОКОМ | B34: кг | G34: 0 | I34: матрица | L34: =E34-K34 -> 0 | M34: =E34-N34 -> 0 | P34: 0 | X34: =M34/5 -> 0 | Z34: =Y34 -> 0 | AA34: =Z34-AB34 -> 0 | AD34: =(F34+O34+P34+S34+U34+W34+Z34+Q34+T34+R34+V34)/X34 -> #DIV/0! | AE34: =(F34+O34+P34+S34+U34+W34)/X34 -> #DIV/0! | AF34: 0 | AG34: 0 | AH34: 0 | AI34: 0 | AJ34: 0 | AK34: 0 | AL34: 0 | AM34: 0 | AN34: нет потребности | AO34: =ROUND(G34*AA34,0) -> 0 | AP34: =VLOOKUP(A34,[1]Лист1!$A:$B,2,0) -> 0 | AQ34: =ROUND(G34*AB34,0) -> 0
A35: 263 Шпикачки Стародворские, ВЕС. ПОКОМ | B35: кг | G35: 0 | I35: матрица | L35: =E35-K35 -> 0 | M35: =E35-N35 -> 0 | P35: 0 | X35: =M35/5 -> 0 | Z35: =Y35 -> 0 | AA35: =Z35-AB35 -> 0 | AD35: =(F35+O35+P35+S35+U35+W35+Z35+Q35+T35+R35+V35)/X35 -> #DIV/0! | AE35: =(F35+O35+P35+S35+U35+W35)/X35 -> #DIV/0! | AF35: 0 | AG35: 0 | AH35: 0 | AI35: 0 | AJ35: 0 | AK35: 0 | AL35: 0 | AM35: 0 | AN35: нет потребности | AO35: =ROUND(G35*AA35,0) -> 0 | AP35: =VLOOKUP(A35,[1]Лист1!$A:$B,2,0) -> 0 | AQ35: =ROUND(G35*AB35,0) -> 0
A36: 265 Колбаса Балыкбургская, ВЕС, ТМ Баварушка ПОКОМ | B36: кг | G36: 0 | I36: матрица | L36: =E36-K36 -> 0 | M36: =E36-N36 -> 0 | P36: 0 | X36: =M36/5 -> 0 | Z36: =Y36 -> 0 | AA36: =Z36-AB36 -> 0 | AD36: =(F36+O36+P36+S36+U36+W36+Z36+Q36+T36+R36+V36)/X36 -> #DIV/0! | AE36: =(F36+O36+P36+S36+U36+W36)/X36 -> #DIV/0! | AF36: 0 | AG36: 0 | AH36: 0 | AI36: 0 | AJ36: 0 | AK36: 0 | AL36: 0 | AM36: 0 | AN36: нет потребности | AO36: =ROUND(G36*AA36,0) -> 0 | AP36: =VLOOKUP(A36,[1]Лист1!$A:$B,2,0) -> 0 | AQ36: =ROUND(G36*AB36,0) -> 0
A37: 267 Колбаса Салями Филейбургская зернистая, оболочка фиброуз, ВЕС, ТМ Баварушка ПОКОМ | B37: кг | G37: 0 | I37: матрица | L37: =E37-K37 -> 0 | M37: =E37-N37 -> 0 | P37: 0 | X37: =M37/5 -> 0 | Z37: =Y37 -> 0 | AA37: =Z37-AB37 -> 0 | AD37: =(F37+O37+P37+S37+U37+W37+Z37+Q37+T37+R37+V37)/X37 -> #DIV/0! | AE37: =(F37+O37+P37+S37+U37+W37)/X37 -> #DIV/0! | AF37: 0 | AG37: 0 | AH37: 0 | AI37: 0 | AJ37: 0 | AK37: 0 | AL37: 0 | AM37: 0 | AN37: нет потребности | AO37: =ROUND(G37*AA37,0) -> 0 | AP37: =VLOOKUP(A37,[1]Лист1!$A:$B,2,0) -> 0 | AQ37: =ROUND(G37*AB37,0) -> 0
A38: 273 Сосиски Сочинки с сочной грудинкой, МГС 0.4кг, ПОКОМ | B38: шт | C38: 3956 | D38: 2996 | E38: 4308 | F38: 1677 | G38: 0.4 | H38: 45 | I38: ТОП / матрица | K38: 4556 | L38: =E38-K38 -> -248 | M38: =E38-N38 -> 4308 | P38: 1200 | Q38: 3000 | U38: 1000 | V38: -1002 | X38: =M38/5 -> 861.6 | Y38: =11.5*X38-W38-U38-S38-P38-O38-F38-Q38 -> 3031.4 | Z38: =Y38+$Z$1*X38 -> 3643.136 | AA38: =Z38-AB38 -> 1158.5172 | AB38: =$AB$1*Z38 -> 2484.6188 | AD38: =(F38+O38+P38+S38+U38+W38+Z38+Q38+T38+R38+V38)/X38 -> 11.047047 | AE38: =(F38+O38+P38+S38+U38+W38)/X38 -> 4.4997679 | AF38: 877.4 | AG38: 623.4 | AH38: 584.8 | AI38: 637.6 | AJ38: 816 | AK38: 898.6 | AL38: 865 | AM38: 794.6 | AO38: =ROUND(G38*AA38,0) -> 463 | AP38: =VLOOKUP(A38,[1]Лист1!$A:$B,2,0) -> 463 | AQ38: =ROUND(G38*AB38,0) -> 994
A39: 276 Колбаса Сливушка ТМ Вязанка в оболочке полиамид 0,45 кг ПОКОМ | B39: шт | C39: 1900.75 | D39: 46 | E39: 634 | F39: 1076.75 | G39: 0.45 | H39: 50 | I39: матрица | K39: 779 | L39: =E39-K39 -> -145 | M39: =E39-N39 -> 634 | P39: 0 | X39: =M39/5 -> 126.8 | Y39: =11.5*X39-W39-U39-S39-P39-O39-F39 -> 381.45 | Z39: =Y39+$Z$1*X39 -> 471.478 | AA39: =Z39-AB39 -> 471.478 | AD39: =(F39+O39+P39+S39+U39+W39+Z39+Q39+T39+R39+V39)/X39 -> 12.21 | AE39: =(F39+O39+P39+S39+U39+W39)/X39 -> 8.4917192 | AF39: 127.8 | AG39: 67.2 | AH39: 118.2 | AI39: 109.4 | AJ39: 109.6 | AK39: 174.8 | AL39: 277.8 | AM39: 284.8 | AO39: =ROUND(G39*AA39,0) -> 212 | AP39: =VLOOKUP(A39,[1]Лист1!$A:$B,2,0) -> 212 | AQ39: =ROUND(G39*AB39,0) -> 0
A40: 278 Сосиски Сочинки с сочным окороком, МГС 0.4кг, ПОКОМ | B40: шт | C40: 763 | D40: 1419 | E40: 944 | F40: 762 | G40: 0.4 | H40: 45 | I40: матрица | K40: 1427 | L40: =E40-K40 -> -483 | M40: =E40-N40 -> 944 | P40: 763.978 | U40: 1000 | V40: -1002 | X40: =M40/5 -> 188.8 | Z40: =Y40 -> 0 | AA40: =Z40-AB40 -> 0 | AD40: =(F40+O40+P40+S40+U40+W40+Z40+Q40+T40+R40+V40)/X40 -> 8.0719174 | AE40: =(F40+O40+P40+S40+U40+W40)/X40 -> 13.379121 | AF40: 301.6 | AG40: 192.2 | AH40: 141.6 | AI40: 149 | AJ40: 204.2 | AK40: 235.2 | AL40: 211 | AM40: 165 | AO40: =ROUND(G40*AA40,0) -> 0 | AP40: =VLOOKUP(A40,[1]Лист1!$A:$B,2,0) -> 0 | AQ40: =ROUND(G40*AB40,0) -> 0
...

Sheet недогрузы
A1: SU002074 | B1: Сосиски «Молочные для завтрака» Весовой п/а ТМ «Особый рецепт» | C1: -504
A2: SU002205 | B2: Сосиски «Молочные для завтрака» Фикс.вес 0,4 П/а мгс ТМ «Особый рецепт» | C2: -160.8
A3: SU002367 | B3: Сардельки «Сливушки» фикс.вес 0,33 п/а мгс ТМ «Вязанка» | C3: -33.66
A4: SU002618 | B4: Сосиски «Сочинки с сочной грудинкой» Фикс.вес 0,4 П/а мгс ТМ «Стародворье» | C4: -400.8
A5: SU002621 | B5: Сосиски «Сочинки с сочным окороком» Фикс.вес 0,4 П/а мгс ТМ «Стародворье» | C5: -400.8
A6: SU003167 | B6: Сосиски «Баварские» Фикс.вес 0,35 П/а ТМ «Стародворье» | C6: -35.7
