Workbook

Sheet Sheet
S1: 3190 | AF1: 1043
S2: =S13+S24 -> 210 | AF2: =AF5-AF13-AF24 -> 1073
A3: Номенклатура | B3: Ед. изм. | C3: Начальный остаток | D3: Приход | E3: Расход | F3: Конечный остаток | G3: крат | H3: сроки | I3: метка | J3: метка2 | K3: заяв | L3: разн | M3: без опта | N3: опт | P3: заказ в пути | R3: расчет | S3: заказ филиала | T3: Комментарии филиала | U3: кон ост | V3: факт | W3: ср | X3: ср | Y3: ср | Z3: ср | AA3: ср | AB3: ср | AC3: ср | AD3: ср | AE3: комментарии | AF3: вес
P4: 46034 | W4: 18,12, | X4: 11,12, | Y4: 04,12, | Z4: 27,11, | AA4: 20,11, | AB4: 13,11, | AC4: 06,11, | AD4: 30,10,
E5: =SUM(E6:E498) -> 5659.268 | F5: =SUM(F6:F498) -> 2487.142 | K5: =SUM(K6:K498) -> 0 | L5: =SUM(L6:L498) -> 5659.268 | M5: =SUM(M6:M498) -> 0 | N5: =SUM(N6:N498) -> 0 | P5: =SUM(P6:P498) -> 11012.741 | R5: =SUM(R6:R498) -> 14294.671 | S5: =SUM(S6:S498) -> 3400 | W5: =SUM(W6:W498) -> 11373.745 | X5: =SUM(X6:X498) -> 5131.0362 | Y5: =SUM(Y6:Y498) -> 68112.64 | Z5: =SUM(Z6:Z498) -> 7984.952 | AA5: =SUM(AA6:AA498) -> 109.178 | AB5: =SUM(AB6:AB498) -> 430.9044 | AC5: =SUM(AC6:AC498) -> 413.264 | AD5: =SUM(AD6:AD498) -> 314.9992 | AF5: =SUM(AF6:AF498) -> 1247 | AG5: =SUM(AG6:AG498) -> 1043
A6: БОНУС_ВАР МОЛОЧНАЯ ПО-Ч НМО 1 КГ К3 ЧЕРКИЗОВО | B6: кг | C6: -3.083 | D6: 7.198 | E6: 23.776 | F6: -19.661 | G6: 0 | I6: бонус | J6: ВАР МОЛОЧНАЯ ПО-Ч НМО 1 КГ К3 ЧЕРКИЗОВО | L6: =E6-K6 -> 23.776 | P6: =E6/5 -> 4.7552 | U6: =(F6+O6+R6)/P6 -> -4.1346316 | V6: =(F6+O6)/P6 -> -4.1346316 | W6: =IFERROR(VLOOKUP(A6,[1]TDSheet!$A$1:$G$65536,3,0),0)/5 -> 3.0906 | X6: 5.0952 | Y6: 1.0324 | Z6: 2.366 | AA6: 2.6892 | AB6: 5.2024 | AC6: 0 | AD6: 0
A7: БОНУС_ВЕТЧ МРАМОРНАЯ ПО-ЧЕРКИЗОВСКИ ШТ 0,4 КГ ЧЕРКИЗОВО | B7: шт | C7: -2 | D7: 8 | E7: 6 | G7: 0 | I7: бонус | J7: ВЕТЧ МРАМОРНАЯ ПО-ЧЕРКИЗОВСКИ ШТ 0,4 КГ ЧЕРКИЗОВО | L7: =E7-K7 -> 6 | P7: =E7/5 -> 1.2 | U7: =(F7+O7+R7)/P7 -> 0 | V7: =(F7+O7)/P7 -> 0 | W7: =IFERROR(VLOOKUP(A7,[1]TDSheet!$A$1:$G$65536,3,0),0)/5 -> 2.4 | X7: 1.6 | Y7: 3.6 | Z7: 10.2 | AA7: 14.2 | AB7: 5.2 | AC7: 0 | AD7: 0
A8: БОНУС_КОПЧ БЕКОН НАР ВУ ШТ 0.18КГ К1.8 ЧЕРКИЗОВО | B8: шт | D8: 9 | E8: 31 | F8: -22 | G8: 0 | I8: бонус | J8: КОПЧ БЕКОН НАР ВУ ШТ 0.18КГ К1.8 ЧЕРКИЗОВО | L8: =E8-K8 -> 31 | P8: =E8/5 -> 6.2 | U8: =(F8+O8+R8)/P8 -> -3.5483871 | V8: =(F8+O8)/P8 -> -3.5483871 | W8: =IFERROR(VLOOKUP(A8,[1]TDSheet!$A$1:$G$65536,3,0),0)/5 -> 0 | X8: 0 | Y8: 1.4 | Z8: 0 | AA8: 0.8 | AB8: 1.6 | AC8: 0 | AD8: 2.8
A9: БОНУС_СК БОРОДИНСКАЯ СРЕЗ ФИБ ВУ 0.3КГ ШТ К3.6 ЧЕРКИЗОВО | C9: -3 | D9: 15 | E9: 12 | G9: 0 | I9: бонус | J9: СК БОРОДИНСКАЯ СРЕЗ ФИБ ВУ 0.3КГ ШТ К3.6 ЧЕРКИЗОВО | L9: =E9-K9 -> 12 | P9: =E9/5 -> 2.4 | U9: =(F9+O9+R9)/P9 -> 0 | V9: =(F9+O9)/P9 -> 0 | W9: =IFERROR(VLOOKUP(A9,[1]TDSheet!$A$1:$G$65536,3,0),0)/5 -> 7.6 | X9: 7.8 | Y9: 1 | Z9: 0 | AA9: 0 | AB9: 0 | AC9: 0 | AD9: 0
A10: БОНУС_СОС КОПЧ ПО-Ч ЛОТ ПМО ЗА ШТ 0.4КГ K1.6 ЧЕРКИЗОВО | B10: шт | D10: 11 | E10: 21 | F10: -10 | G10: 0 | I10: бонус | J10: СОС КОПЧ ПО-Ч ЛОТ ПМО ЗА ШТ 0.4КГ K1.6 ЧЕРКИЗОВО | L10: =E10-K10 -> 21 | P10: =E10/5 -> 4.2 | U10: =(F10+O10+R10)/P10 -> -2.3809524 | V10: =(F10+O10)/P10 -> -2.3809524 | W10: =IFERROR(VLOOKUP(A10,[1]TDSheet!$A$1:$G$65536,3,0),0)/5 -> 0 | X10: 5.8 | Y10: 0 | Z10: 0 | AA10: 16.8 | AB10: 14 | AC10: 0 | AD10: 5.8
A11: ВАР АРОМАТНАЯ ПО-Ч ЦО ЗА 1.6КГ K3.2 ЧЕРКИЗОВО | B11: кг | C11: -0.161 | D11: 100.942 | E11: 96.123 | F11: -0.191 | G11: 1 | H11: 30 | I11: 1030112235 | L11: =E11-K11 -> 96.123 | P11: 130 | Q11: =E11/5 -> 19.2246 | R11: =Q11*25-P11-F11 -> 350.806 | S11: 30 | U11: =(F11+O11+R11)/P11 -> 2.6970385 | V11: =(F11+O11)/P11 -> -0.0014692308 | W11: =IFERROR(VLOOKUP(A11,[1]TDSheet!$A$1:$G$65536,3,0),0)/5 -> 0 | X11: 10.3456 | Y11: -0.652 | Z11: 0.1742 | AA11: 3.3446 | AB11: 5.1424 | AC11: 14.7752 | AD11: -0.053 | AE11: 03,06,25 в уценку 119кг | AF11: =G11*S11 -> 30 | AG11: =VLOOKUP(I11,[2]Лист1!$B:$G,6,0) -> 30 | AI11: =VLOOKUP(I11,[2]Лист1!$B:$B,1,0) -> 1030112235
A12: ВАР КЛАССИЧЕСКАЯ ПО-Ч ЦО ЗА 1.6КГ K3.2 ЧЕРКИЗОВО | B12: кг | C12: 4.025 | D12: 163.43 | E12: 158.939 | G12: 1 | H12: 30 | I12: 1030112635 | L12: =E12-K12 -> 158.939 | P12: 160 | Q12: =E12/5 -> 31.7878 | R12: =Q12*25-P12-F12 -> 634.695 | S12: 60 | U12: =(F12+O12+R12)/P12 -> 3.9668437 | V12: =(F12+O12)/P12 -> 0 | W12: =IFERROR(VLOOKUP(A12,[1]TDSheet!$A$1:$G$65536,3,0),0)/5 -> 3.8632 | X12: 20.7238 | Y12: -0.324 | Z12: 7.817 | AA12: 4.5084 | AB12: 17.9106 | AC12: 17.3096 | AD12: 14.2786 | AE12: 03,06,25 в уценку 75кг | AF12: =G12*S12 -> 60 | AG12: =VLOOKUP(I12,[2]Лист1!$B:$G,6,0) -> 60 | AI12: =VLOOKUP(I12,[2]Лист1!$B:$B,1,0) -> 1030112635
A13: ВАР МОЛОЧНАЯ ПО-Ч НМО 1 КГ К3 ЧЕРКИЗОВО | B13: кг | C13: 18.446 | D13: 258.318 | E13: =218.757+E6 -> 242.533 | F13: 230 | G13: 1 | H13: 75 | I13: 1030115552 | L13: =E13-K13 -> 242.533 | P13: 250 | Q13: =E13/5 -> 48.5066 | R13: =Q13*25-P13-F13 -> 732.665 | S13: 150 | T13: нет в бланке | U13: =(F13+O13+R13)/P13 -> 3.85066 | V13: =(F13+O13)/P13 -> 0.92 | W13: =IFERROR(VLOOKUP(A13,[1]TDSheet!$A$1:$G$65536,3,0),0)/5 -> 6.9914 | X13: 29.0716 | Y13: 8.7838 | Z13: 14.3948 | AA13: 8.8358 | AB13: 23.1414 | AC13: 19.0918 | AD13: 6.5154 | AF13: =G13*S13 -> 150 | AI13: =VLOOKUP(I13,[2]Лист1!$B:$B,1,0) -> #N/A
A14: ВАР МОЛОЧНАЯ ПО-ЧЕ НМО ШТ 0.4КГ К2.4 ЧЕРКИЗОВО | B14: шт | C14: 84 | D14: 415 | E14: 496 | F14: 195 | G14: 0.4 | H14: 75 | I14: 1030115404 | L14: =E14-K14 -> 496 | P14: 600 | Q14: =E14/5 -> 99.2 | R14: =Q14*25-P14-F14 -> 1685 | S14: 300 | U14: =(F14+O14+R14)/P14 -> 3.1333333 | V14: =(F14+O14)/P14 -> 0.325 | W14: =IFERROR(VLOOKUP(A14,[1]TDSheet!$A$1:$G$65536,3,0),0)/5 -> 28.4 | X14: 57.2 | Y14: 33.6 | Z14: 31.8 | AA14: 53.8 | AB14: 48.4 | AC14: 49.8 | AD14: 40.6 | AF14: =G14*S14 -> 120 | AG14: =VLOOKUP(I14,[2]Лист1!$B:$G,6,0) -> 120 | AI14: =VLOOKUP(I14,[2]Лист1!$B:$B,1,0) -> 1030115404
A15: ВЕТЧ МРАМОРНАЯ ПО-ЧЕРКИЗОВСКИ ШТ 0,4 КГ ЧЕРКИЗОВО | B15: шт | C15: -6 | D15: 102 | E15: =49+E7 -> 55 | F15: 153 | G15: 0.4 | H15: 75 | I15: 1030804004 | L15: =E15-K15 -> 55 | P15: 300 | Q15: =E15/5 -> 11 | R15: =Q15*25-P15-F15 -> -178 | S15: 100 | U15: =(F15+O15+R15)/P15 -> -0.083333333 | V15: =(F15+O15)/P15 -> 0.51 | W15: =IFERROR(VLOOKUP(A15,[1]TDSheet!$A$1:$G$65536,3,0),0)/5 -> 2.4 | X15: 19.4 | Y15: 5.2 | Z15: 18.2 | AA15: 4.2 | AB15: 25.6 | AC15: 12 | AD15: 16.4 | AF15: =G15*S15 -> 40 | AG15: =VLOOKUP(I15,[2]Лист1!$B:$G,6,0) -> 40 | AI15: =VLOOKUP(I15,[2]Лист1!$B:$B,1,0) -> 1030804004
A16: ВК БАЛЫКОВАЯ ПО-ЧЕРКИЗ СРЕЗ ШТ0,3 К1,8 ЧЕРКИЗОВО | B16: шт | C16: 1 | D16: 120 | E16: 110 | F16: 1 | G16: 0 | H16: 45 | I16: 1030419235 | L16: =E16-K16 -> 110 | P16: 250 | Q16: =E16/5 -> 22 | R16: =Q16*25-P16-F16 -> 299 | T16: =VLOOKUP(A16,[3]Sheet!$A$1:$T$65536,20,0) -> заблокировано на 2026 | AB16: 7.4 | AC16: 2.2 | AD16: 8.2 | AE16: 11,08,25 завод не отгрузил / 28,07,25 завод не отгрузил | AF16: =G16*S16 -> 0
A17: ВК СЕРВ ГОСТ СРЕЗ ФИБ ВУ ШТ 0.5КГ К2 ЧЕРКИЗОВО | B17: шт | C17: 6 | D17: 256 | E17: 254 | F17: 96 | G17: 0.5 | H17: 45 | I17: 1030412236 | L17: =E17-K17 -> 254 | P17: 250 | Q17: =E17/5 -> 50.8 | R17: =Q17*25-P17-F17 -> 924 | S17: 150 | AB17: 17.4 | AC17: 22.8 | AD17: 13.2 | AF17: =G17*S17 -> 75 | AG17: =VLOOKUP(I17,[2]Лист1!$B:$G,6,0) -> 75 | AI17: =VLOOKUP(I17,[2]Лист1!$B:$B,1,0) -> 1030412236
A18: ВК СЕРВЕЛАТ ЗЕРНИСТЫЙ СРЕЗ ВУ ШТ К1.8 | B18: шт | F18: 57 | G18: 0.3 | H18: 45 | I18: 1030419435 | L18: =E18-K18 -> 0 | P18: 250 | Q18: =E18/5 -> 0 | R18: =Q18*25-P18-F18 -> -307 | S18: 120 | T18: нов | U18: Номенклатура | V18: Ед. изм. | W18: Расход | X18: Конечный остаток | Y18: заказ в пути | Z18: заказ филиала | AA18: Комментарии филиала | AB18: 0 | AC18: 0 | AD18: 0 | AE18: новинка | AF18: =G18*S18 -> 36 | AG18: =VLOOKUP(I18,[2]Лист1!$B:$G,6,0) -> 36 | AI18: =VLOOKUP(I18,[2]Лист1!$B:$B,1,0) -> 1030419435
A19: ВК Серв с говяд/ЛТФ/ох/шт 0.4кг/гк329/KZ | B19: шт | F19: 9 | G19: 0.4 | H19: 45 | I19: 1030503997 | L19: =E19-K19 -> 0 | P19: 202 | Q19: =E19/5 -> 0 | R19: =Q19*25-P19-F19 -> -211 | Y19: 46034 | AB19: 0 | AC19: 0 | AD19: 0 | AE19: новинка / нет в бланке | AF19: =G19*S19 -> 0
A20: КОПЧ БЕКОН НАР ВУ ШТ 0.18КГ К1.8 ЧЕРКИЗОВО | B20: шт | C20: 4 | D20: 800 | E20: =720+E8 -> 751 | F20: 242 | G20: 0.18 | H20: 90 | I20: 1030712385 | L20: =E20-K20 -> 751 | P20: 800 | Q20: =E20/5 -> 150.2 | R20: =Q20*25-P20-F20 -> 2713 | S20: 400 | W20: 5659 | X20: 2487 | Y20: 11013 | Z20: 3950 | AB20: 31 | AC20: 42.2 | AD20: 39.2 | AF20: =G20*S20 -> 72 | AG20: =VLOOKUP(I20,[2]Лист1!$B:$G,6,0) -> 72 | AI20: =VLOOKUP(I20,[2]Лист1!$B:$B,1,0) -> 1030712385
A21: КОПЧ ГРУДИНКА ПО-ЧЕРК ВУ ШТ 0.3КГ К1.8 ЧЕРКИЗОВО | B21: шт | G21: 0.3 | H21: 60 | I21: 1030709904 | L21: =E21-K21 -> 0 | Q21: =E21/5 -> 0 | R21: =Q21*25-P21-F21 -> 0 | T21: заблокировано на 2026 | U21: БОНУС_ВАР МОЛОЧНАЯ ПО-Ч НМО 1 КГ К3 ЧЕРКИЗОВО | V21: кг | W21: 24 | X21: -20 | Y21: 5 | AB21: 0 | AC21: 0 | AD21: 0 | AE21: 22,05,25 в уценку 234шт. | AF21: =G21*S21 -> 0
A22: Клб ПолуКпч С говяд/ЛТФ/ТУ/охл/-/гк329 | B22: шт | F22: 39 | G22: 0.4 | H22: 60 | I22: 1030518197 | L22: =E22-K22 -> 0 | P22: 200 | Q22: =E22/5 -> 0 | R22: =Q22*25-P22-F22 -> -239 | S22: 60 | T22: нов | U22: БОНУС_ВЕТЧ МРАМОРНАЯ ПО-ЧЕРКИЗОВСКИ ШТ 0,4 КГ ЧЕРКИЗОВО | V22: шт | W22: 6 | Y22: 1 | AB22: 0 | AC22: 0 | AD22: 0 | AE22: новинка / нет в бланке | AF22: =G22*S22 -> 24 | AG22: =VLOOKUP(I22,[2]Лист1!$B:$G,6,0) -> 24 | AI22: =VLOOKUP(I22,[2]Лист1!$B:$B,1,0) -> 1030518197
A23: Клб ПолуКпч Чесн/ТСБ/ТУ/охл/-/гк380т | B23: шт | G23: 0.4 | H23: 60 | I23: 1030517871 | L23: =E23-K23 -> 0 | Q23: =E23/5 -> 0 | R23: =Q23*25-P23-F23 -> 0 | T23: не отгрузил завод??? | U23: БОНУС_КОПЧ БЕКОН НАР ВУ ШТ 0.18КГ К1.8 ЧЕРКИЗОВО | V23: шт | W23: 31 | X23: -22 | Y23: 6 | AB23: 0 | AC23: 0 | AD23: 0 | AE23: новинка / нет в бланке | AF23: =G23*S23 -> 0
A24: Клб вар Мусул/ЛТФ/ТУ/охл/-/гк329 | B24: шт | F24: 38 | G24: 0.4 | H24: 65 | I24: 1030129697 | L24: =E24-K24 -> 0 | P24: 200 | Q24: =E24/5 -> 0 | R24: =Q24*25-P24-F24 -> -238 | S24: 60 | T24: нет в бланке | U24: БОНУС_СК БОРОДИНСКАЯ СРЕЗ ФИБ ВУ 0.3КГ ШТ К3.6 ЧЕРКИЗОВО | W24: 12 | Y24: 2 | AB24: 0 | AC24: 0 | AD24: 0 | AE24: новинка / нет в бланке | AF24: =G24*S24 -> 24 | AI24: =VLOOKUP(I24,[2]Лист1!$B:$B,1,0) -> #N/A
A25: СК АССОРТИ СЕРВ И ПРОШУТ 0.085КГ К 0,85 | B25: шт | F25: 40 | G25: 0.085 | H25: 90 | I25: 1030680328 | L25: =E25-K25 -> 0 | P25: 200 | Q25: =E25/5 -> 0 | R25: =Q25*25-P25-F25 -> -240 | S25: 100 | T25: нов | U25: БОНУС_СОС КОПЧ ПО-Ч ЛОТ ПМО ЗА ШТ 0.4КГ K1.6 ЧЕРКИЗОВО | V25: шт | W25: 21 | X25: -10 | Y25: 4 | AB25: 0 | AC25: 0 | AD25: 0 | AE25: новинка / нет в бланке | AF25: =G25*S25 -> 8.5 | AG25: =VLOOKUP(I25,[2]Лист1!$B:$G,6,0) -> 8.5 | AI25: =VLOOKUP(I25,[2]Лист1!$B:$B,1,0) -> 1030680328
A26: СК БОГОРОДСКАЯ ПРЕСС ФИБ ВУ ШТ0.3КГ К3.6 ЧЕРКИЗОВО | B26: шт | C26: 2 | D26: 606 | E26: 606 | F26: 319 | G26: 0.3 | H26: 150 | I26: 1030686740 | L26: =E26-K26 -> 606 | P26: 900 | Q26: =E26/5 -> 121.2 | R26: =Q26*25-P26-F26 -> 1811 | S26: 400 | U26: ВАР АРОМАТНАЯ ПО-Ч ЦО ЗА 1.6КГ K3.2 ЧЕРКИЗОВО | V26: кг | W26: 96 | X26: 0 | Y26: 130 | Z26: 30 | AB26: 46.4 | AC26: 45.4 | AD26: 32.6 | AF26: =G26*S26 -> 120 | AG26: =VLOOKUP(I26,[2]Лист1!$B:$G,6,0) -> 120 | AI26: =VLOOKUP(I26,[2]Лист1!$B:$B,1,0) -> 1030686740
A27: СК БОРОДИНСКАЯ СРЕЗ ФИБ ВУ 0.3КГ ШТ К3.6 ЧЕРКИЗОВО | B27: шт | C27: 16 | D27: 401 | E27: =415+E9 -> 427 | F27: 265 | G27: 0.3 | H27: 135 | I27: 1030686857 | L27: =E27-K27 -> 427 | P27: 800 | Q27: =E27/5 -> 85.4 | R27: =Q27*25-P27-F27 -> 1070 | S27: 300 | U27: ВАР КЛАССИЧЕСКАЯ ПО-Ч ЦО ЗА 1.6КГ K3.2 ЧЕРКИЗОВО | V27: кг | W27: 159 | Y27: 160 | Z27: 60 | AB27: 26.4 | AC27: 21.8 | AD27: 28.6 | AF27: =G27*S27 -> 90 | AG27: =VLOOKUP(I27,[2]Лист1!$B:$G,6,0) -> 90 | AI27: =VLOOKUP(I27,[2]Лист1!$B:$B,1,0) -> 1030686857
A28: СК БРАУНШВЕЙГСКАЯ ГОСТ БО СРЕЗ ШТ 0,2КГ ЧЕРКИЗОВО | B28: шт | C28: 3 | D28: 300 | E28: 272 | F28: 59 | G28: 0.2 | H28: 90 | I28: 1030654104 | L28: =E28-K28 -> 272 | P28: 600 | Q28: =E28/5 -> 54.4 | R28: =Q28*25-P28-F28 -> 701 | S28: 200 | U28: ВАР МОЛОЧНАЯ ПО-Ч НМО 1 КГ К3 ЧЕРКИЗОВО | V28: кг | W28: 243 | X28: 230 | Y28: 250 | Z28: 150 | AB28: 11.8 | AC28: 1 | AD28: 6 | AF28: =G28*S28 -> 40 | AG28: =VLOOKUP(I28,[2]Лист1!$B:$G,6,0) -> 40 | AI28: =VLOOKUP(I28,[2]Лист1!$B:$B,1,0) -> 1030654104
A29: СК КЛАССИКО ИТАЛИАНОНАР ЗА ШТ0.085 K0.85 | B29: шт | F29: 40 | G29: 0.085 | H29: 90 | I29: 1030683928 | L29: =E29-K29 -> 0 | P29: 200 | Q29: =E29/5 -> 0 | R29: =Q29*25-P29-F29 -> -240 | S29: 100 | T29: нов | U29: ВАР МОЛОЧНАЯ ПО-ЧЕ НМО ШТ 0.4КГ К2.4 ЧЕРКИЗОВО | V29: шт | W29: 496 | X29: 195 | Y29: 600 | Z29: 500 | AB29: 0 | AC29: 0 | AD29: 0 | AE29: новинка / нет в бланке | AF29: =G29*S29 -> 8.5 | AG29: =VLOOKUP(I29,[2]Лист1!$B:$G,6,0) -> 8.5 | AI29: =VLOOKUP(I29,[2]Лист1!$B:$B,1,0) -> 1030683928
A30: СК ОНЕЖСКАЯ СРЕЗ ФИБ ВУ ШТ 0.3КГ K1.8 ЧЕРКИЗОВО | B30: шт | C30: 83 | D30: 90 | E30: 171 | F30: -2 | G30: 0.3 | H30: 135 | I30: 1030686241 | L30: =E30-K30 -> 171 | P30: 300 | Q30: =E30/5 -> 34.2 | R30: =Q30*25-P30-F30 -> 557 | T30: заблокировано на 2026 | U30: ВЕТЧ МРАМОРНАЯ ПО-ЧЕРКИЗОВСКИ ШТ 0,4 КГ ЧЕРКИЗОВО | V30: шт | W30: 55 | X30: 153 | Y30: 300 | Z30: 100 | AB30: 8.2 | AC30: 6.4 | AD30: 6.2 | AF30: =G30*S30 -> 0
A31: СК САЛЬЧИЧОН НАРЕЗ ФИБ ЗА ШТ 0.1КГ К1.2 ЧЕРКИЗОВО | B31: шт | C31: -24 | D31: 204 | E31: 196 | F31: -16 | G31: 0.1 | H31: 90 | I31: 1030650028 | L31: =E31-K31 -> 196 | P31: 800 | Q31: =E31/5 -> 39.2 | R31: =Q31*25-P31-F31 -> 196 | T31: заблокировано на 2026 | U31: ВК БАЛЫКОВАЯ ПО-ЧЕРКИЗ СРЕЗ ШТ0,3 К1,8 ЧЕРКИЗОВО | V31: шт | W31: 110 | X31: 1 | Y31: 250 | AA31: заблокировано на 2026 | AB31: 0 | AC31: 12.4 | AD31: 6.2 | AE31: 03,06,25 в уценку 98 шт. | AF31: =G31*S31 -> 0
A32: СК САЛЬЧИЧОН С РОЗОВЫМ ПЕРЦ. СРЕЗ ШТ 0,3 ЧЕРКИЗОВО | B32: шт | C32: 83 | D32: 62 | E32: 139 | G32: 0 | H32: 135 | I32: 1030657419 | L32: =E32-K32 -> 139 | P32: 80 | Q32: =E32/5 -> 27.8 | R32: =Q32*25-P32-F32 -> 615 | T32: =VLOOKUP(A32,[3]Sheet!$A$1:$T$65536,20,0) -> заблокировано на 2026 | U32: ВК СЕРВ ГОСТ СРЕЗ ФИБ ВУ ШТ 0.5КГ К2 ЧЕРКИЗОВО | V32: шт | W32: 254 | X32: 96 | Y32: 250 | Z32: 200 | AB32: 5.6 | AC32: 10 | AD32: 8 | AE32: нужно увеличить продажи!!! | AF32: =G32*S32 -> 0
A33: СК САЛЬЧИЧОН С РОЗОВЫМ ПЕРЦЕМ НАР ШТ 85Г ЧЕРКИЗОВО | B33: шт | D33: 204 | E33: 181 | F33: 22 | G33: 0 | H33: 90 | I33: 1030657628 | L33: =E33-K33 -> 181 | P33: 500 | Q33: =E33/5 -> 36.2 | R33: =Q33*25-P33-F33 -> 383 | T33: =VLOOKUP(A33,[3]Sheet!$A$1:$T$65536,20,0) -> заблокировано на 2026 | U33: ВК СЕРВЕЛАТ ЗЕРНИСТЫЙ СРЕЗ ВУ ШТ К1.8 | V33: шт | X33: 57 | Y33: 250 | Z33: 120 | AA33: нов | AB33: 10.2 | AC33: -0.4 | AD33: 2.2 | AE33: 03,06,25 в уценку 240 шт. | AF33: =G33*S33 -> 0
A34: СК САЛЬЧИЧОН СРЕЗ ФИБ ВУ ШТ 0,3 КГ ЧЕРКИЗОВО (ПРЕМИУМ) | B34: шт | C34: 3 | D34: 52 | E34: 47 | F34: 452 | G34: 0.3 | H34: 135 | I34: 1030679319 | L34: =E34-K34 -> 47 | P34: 400 | Q34: =E34/5 -> 9.4 | R34: =Q34*25-P34-F34 -> -617 | U34: ВК Серв с говяд/ЛТФ/ох/шт 0.4кг/гк329/KZ | V34: шт | X34: 9 | Y34: 202 | AB34: 13.6 | AC34: 11.6 | AD34: 13.2 | AF34: =G34*S34 -> 0
A35: СК САЛЯМИ АСТОРИЯ СРЕЗ ФИБ ВУ ШТ 0.225КГ (ТМ ЧЕРКИЗОВО) K1.35 | B35: шт | F35: 116 | G35: 0.225 | H35: 135 | I35: 1030671534 | L35: =E35-K35 -> 0 | P35: 300 | Q35: =E35/5 -> 0 | R35: =Q35*25-P35-F35 -> -416 | S35: 200 | T35: нов | U35: КОПЧ БЕКОН НАР ВУ ШТ 0.18КГ К1.8 ЧЕРКИЗОВО | V35: шт | W35: 751 | X35: 242 | Y35: 800 | Z35: 400 | AB35: 0 | AC35: 0 | AD35: 0 | AE35: новинка | AF35: =G35*S35 -> 45 | AG35: =VLOOKUP(I35,[2]Лист1!$B:$G,6,0) -> 45 | AI35: =VLOOKUP(I35,[2]Лист1!$B:$B,1,0) -> 1030671534
A36: СК СВИНАЯ ПО-ЧЕРКИЗОВ СРЕЗ ШТ0,225 К1,35 | B36: шт | F36: 74 | G36: 0.225 | H36: 135 | I36: 1030688634 | L36: =E36-K36 -> 0 | P36: 300 | Q36: =E36/5 -> 0 | R36: =Q36*25-P36-F36 -> -374 | S36: 200 | T36: нов | U36: КОПЧ ГРУДИНКА ПО-ЧЕРК ВУ ШТ 0.3КГ К1.8 ЧЕРКИЗОВО | V36: шт | AA36: заблокировано на 2026 | AB36: 0 | AC36: 0 | AD36: 0 | AE36: новинка | AF36: =G36*S36 -> 45 | AG36: =VLOOKUP(I36,[2]Лист1!$B:$G,6,0) -> 45 | AI36: =VLOOKUP(I36,[2]Лист1!$B:$B,1,0) -> 1030688634
A37: СК СЕРВЕЛЕТТИ ПРЕСС СРЕЗ БО ВУ ШТ 0.25КГ ЧЕРКИЗОВО | B37: шт | C37: 3 | D37: 563 | E37: 555 | F37: 119 | G37: 0.25 | H37: 120 | I37: 1030670803 | L37: =E37-K37 -> 555 | P37: 800 | Q37: =E37/5 -> 111 | R37: =Q37*25-P37-F37 -> 1856 | S37: 200 | U37: Клб ПолуКпч С говяд/ЛТФ/ТУ/охл/-/гк329 | V37: шт | X37: 39 | Y37: 200 | Z37: 60 | AA37: нов | AB37: 0 | AC37: 0 | AD37: 0 | AE37: ИЗМЕНИЛСЯ АРТИКУЛ / нет в бланке | AF37: =G37*S37 -> 50 | AG37: =VLOOKUP(I37,[2]Лист1!$B:$G,6,0) -> 50 | AI37: =VLOOKUP(I37,[2]Лист1!$B:$B,1,0) -> 1030670803
A38: СОС ВЕНСКИЕ БО ЗА ПАК 1.25КГ K5 ЧЕРКИЗОВО | B38: кг | C38: -0.045 | D38: 78.372 | E38: 65.969 | G38: 1 | H38: 35 | I38: 1030228316 | L38: =E38-K38 -> 65.969 | P38: 80 | Q38: =E38/5 -> 13.1938 | R38: =Q38*25-P38-F38 -> 249.845 | S38: 50 | U38: Клб ПолуКпч Чесн/ТСБ/ТУ/охл/-/гк380т | V38: шт | AA38: не отгрузил завод??? | AB38: -5.3288 | AC38: 11.4874 | AD38: 18.2582 | AF38: =G38*S38 -> 50 | AG38: =VLOOKUP(I38,[2]Лист1!$B:$G,6,0) -> 50 | AI38: =VLOOKUP(I38,[2]Лист1!$B:$B,1,0) -> 1030228316
A39: СОС КОПЧ ПО-Ч ЛОТ ПМО ЗА ШТ 0.4КГ K1.6 ЧЕРКИЗОВО | B39: шт | C39: -6 | D39: 405 | E39: =341+E10 -> 362 | G39: 0.4 | H39: 41 | I39: 1030234120 | L39: =E39-K39 -> 362 | P39: 500 | Q39: =E39/5 -> 72.4 | R39: =Q39*25-P39-F39 -> 1310 | U39: Клб вар Мусул/ЛТФ/ТУ/охл/-/гк329 | V39: шт | X39: 38 | Y39: 200 | Z39: 60 | AA39: нов | AB39: 46.8 | AC39: 38.8 | AD39: 23.6 | AF39: =G39*S39 -> 0
A40: СОС МОЛОЧНЫЕ ПО-Ч ПМО ЗА ЛОТ ШТ 0.45КГ K1.8 ЧЕРКИЗОВО | B40: шт | C40: 4 | D40: 200 | E40: 172 | F40: 12 | G40: 0 | H40: 31 | I40: 1030228620 | L40: =E40-K40 -> 172 | P40: 105 | Q40: =E40/5 -> 34.4 | R40: =Q40*25-P40-F40 -> 743 | T40: =VLOOKUP(A40,[3]Sheet!$A$1:$T$65536,20,0) -> заблокировано на 2026 | U40: СК АССОРТИ СЕРВ И ПРОШУТ 0.085КГ К 0,85 | V40: шт | X40: 40 | Y40: 200 | Z40: 100 | AA40: нов | AB40: 25.8 | AC40: 26.6 | AD40: 10.8 | AF40: =G40*S40 -> 0
...
