Workbook
Name вес_короба__кг: КИ_ПФ!$AH$3:$AH$821
Name высота__мм: КИ_ПФ!$AE$3:$AE$821
Name высота_поддона__мм: КИ_ПФ!#REF!
Name ГОСТ_23670_2019: #REF!
Name ГОСТ_31785_2012: #REF!
Name ГОСТ_32125_2013: #REF!
Name ГОСТ_32244_2013: #REF!
Name ГОСТ_Р_55455_2013: #REF!
Name ГОСТ_Р_55456_2013: #REF!
Name итого_г_у: КИ_ПФ!$AM$3:$AM$821
Name кол_во_инд.__упак_к: КИ_ПФ!$AF$3:$AF$821
Name Кол_во_коробок_на_поддоне: кратность!$H$2:$H$341
Name кол_во_слоев_г_у: КИ_ПФ!$AL$3:$AL$821
Name Кол_во_штук_в_коробе: кратность!$G$2:$G$341
Name Новая_кратность_короба__кг: кратность!$E$2:$E$341
Name номин.вес_брутто__кг: КИ_ПФ!$AB$3:$AB$821
Name номин.вес_нетто__кг: КИ_ПФ!$Z$3:$Z$821
Name номин.вес_нетто_г_у__кг: КИ_ПФ!$AI$3:$AI$821
Name ТУ_10.13.14_130_00425283_2017: #REF!

Sheet КИ_ПФ
B1: Код | C1: Наименование | D1: БЕИ | E1: Вид | F1: Тип | G1: Торговая | H1: Производитель | I1: Номер | J1: Группа/категория | K1: Состав | L1: Пищевая ценность в 100 г: | P1: Условия | Q1: Срок | R1: Срок | S1: Штрих-код | T1: Штрих-код | U1: Штрих-код | V1: Штрих-код | Z1: Индивидуальная упаковка | AD1: Групповая упаковка (гофрокороб) | AM1: Паллета
B2: SAP | C2: Наименование продукции | D2: кг/шт | E2: Вид продукции | F2: Тип продукции | G2: марка | H2: Производитель | I2: ГОСТ/ТУ | J2: Группа/категория | K2: 3 | L2: белки (г) | M2: жиры (г) | N2: углеводы (г) | O2: ккал/кДж | P2: хранения,°С | Q2: годности, сут | R2: годности после вскрытия | S2: EAN-13 | T2: ITF-14 | U2: EAN-13 (GS1) | V2: ITF-14 (GS1) | W2: длина (мм) | X2: ширина (мм) | Y2: высота (мм) | Z2: номин.вес нетто (кг) | AA2: вес вспом. упаковки (кг) | AB2: номин.вес брутто (кг) | AC2: длина (мм) | AD2: ширина (мм) | AE2: высота (мм) | AF2: кол-во инд. упак-к | AG2: код короба | AH2: вес короба (кг) | AI2: номин.вес нетто г/у (кг) | AJ2: номин.вес брутто г/у (кг) | AK2: кол-во г/у в слое | AL2: кол-во слоев г/у | AM2: итого г/у | AN2: Кратность нетто (кг/шт) | AO2: Высота (мм)
A3: =VALUE(RIGHT(B3,4)) -> 6874 | B3: 1001012486874 | C3: БЕЗ ШПИКА ПМ вар п/о (катБ)_Kvalita | D3: КГ | E3: Колбасные изделия | F3: Вареные колбасы | G3: Папа может | H3: ОМПК(С) | I3: ТУ 10.13.14-180-00425283-2025 | J3: Мясной продукт. Изделие колбасное вареное категории Б. | K3: свинина, стабилизатор белковый (вода питьевая, шкурка свиная, кожа куриная), мясо куриное механической обвалки, вода питьевая, сыворотка молочная сухая, молоко сухое обезжиренное, крахмалы (кукурузный, картофельный), смесь посолочно-нитритная (соль, фиксатор окраски (нитрит натрия)), сахар, регуляторы кислотности (пирофосфаты, трифосфаты, цитраты натрия), загустители (каррагинан, гуаровая камедь, конжак, ксантановая камедь), специи, экстракты специй (в т.ч. горчица), антиокислитель (аскорбиновая кислота), усилитель вкуса и аромата (глутамат натрия), ароматизаторы, краситель (кармины) | L3: 9 | M3: 14 | N3: 5 | O3: 182/756 | P3: 0…+6 | Q3: 60 | R3: 72 часа | S3: 2800682000002 | T3: 12800682000009 | U3: 4630362180094 | V3: 14630362180091 | W3: 250 | X3: 90 | Y3: 90 | Z3: 1.35 | AA3: 0.002 | AB3: =Z3+AA3 -> 1.352 | AC3: 292 | AD3: 178 | AE3: 178 | AF3: 3 | AG3: 600000029 | AH3: =справочники!$C$21 -> 0.125 | AI3: =ROUNDDOWN(номин.вес_нетто__кг*кол_во_инд.__упак_к,2) -> 4.05 | AJ3: =(номин.вес_брутто__кг*кол_во_инд.__упак_к)+вес_короба__кг -> 4.181 | AK3: 16 | AL3: 8 | AM3: =AK3*AL3 -> 128 | AN3: =IF(D3="ШТ",кол_во_инд.__упак_к*итого_г_у,ROUNDDOWN(номин.вес_нетто_г_у__кг*итого_г_у,1)) -> 518.4 | AO3: =(высота__мм*кол_во_слоев_г_у)+145 -> 1569
A4: =VALUE(RIGHT(B4,4)) -> 7568 | B4: 1001012487568 | C4: БЕЗ ШПИКА вар п/о (катБ) 1.35*8_Kvalita | D4: КГ | E4: Колбасные изделия | F4: Вареные колбасы | G4: Папа может | H4: ОМПК(С) | I4: ТУ 10.13.14-180-00425283-2025 | J4: Мясной продукт. Изделие колбасное вареное категории Б. | K4: свинина, стабилизатор белковый (вода питьевая, шкурка свиная, кожа куриная), мясо куриное механической обвалки, вода питьевая, сыворотка молочная сухая, молоко сухое обезжиренное, крахмалы (кукурузный, картофельный), смесь посолочно-нитритная (соль, фиксатор окраски (нитрит натрия)), сахар, регуляторы кислотности (пирофосфаты, трифосфаты, цитраты натрия), загустители (каррагинан, гуаровая камедь, конжак, ксантановая камедь), специи, экстракты специй (в т.ч. горчица), антиокислитель (аскорбиновая кислота), усилитель вкуса и аромата (глутамат натрия), ароматизаторы, краситель (кармины) | L4: 9 | M4: 14 | N4: 5 | O4: 182/756 | P4: 0…+6 | Q4: 60 | R4: 72 часа | S4: 2800682000002 | T4: 12800682000009 | U4: 4630362180094 | V4: 24630362180098 | W4: 250 | X4: 90 | Y4: 90 | Z4: 1.35 | AA4: 0.002 | AB4: =Z4+AA4 -> 1.352 | AC4: 293 | AD4: 394 | AE4: 158 | AF4: 8 | AG4: 600000607 | AH4: =справочники!$C$195 -> 0.236 | AI4: =ROUNDDOWN(номин.вес_нетто__кг*кол_во_инд.__упак_к,2) -> 10.8 | AJ4: =(номин.вес_брутто__кг*кол_во_инд.__упак_к)+вес_короба__кг -> 11.052 | AK4: 8 | AL4: 9 | AM4: =AK4*AL4 -> 72 | AN4: =IF(D4="ШТ",кол_во_инд.__упак_к*итого_г_у,ROUNDDOWN(номин.вес_нетто_г_у__кг*итого_г_у,1)) -> 777.6 | AO4: =(высота__мм*кол_во_слоев_г_у)+145 -> 1567
A5: =VALUE(RIGHT(B5,4)) -> 6319 | B5: 1001013636319 | C5: БАЛЫКОВАЯ Папа может вар п/о 0.4кг 8шт. | D5: ШТ | E5: Колбасные изделия | F5: Вареные колбасы | G5: Папа может | H5: ОМПК(С) | I5: ТУ 10.13.14-130-00425283-2017 | J5: Мясной продукт. Изделие колбасное вареное категории Б. | K5: свинина, вода питьевая, стабилизатор белковый (вода питьевая, шкурка свиная, кожа куриная), мясо куриное механической обвалки, филе грудок куриных, крахмал картофельный, сыворотка молочная сухая, смесь посолочно-нитритная (соль, фиксатор окраски (нитрит натрия)), соль, регуляторы кислотности (пирофосфаты, трифосфаты, цитраты натрия), стабилизаторы (полифосфаты, альгинат натрия), загустители (тары камедь, камедь рожкового дерева, ксантановая камедь, каррагинан, гуаровая камедь, камедь целлюлозы, модифицированный крахмал), белок животный (говяжий), сахара, специи, пряности, экстракты пряностей, антиокислители (изоаскоробат натрия, аскорбат натрия), усилитель вкуса и аромата (глутамат натрия), ароматизаторы, краситель (кармины) | L5: 11 | M5: 15 | N5: 3 | O5: 191/793 | P5: 0…+6 | Q5: 60 | R5: 3 суток | S5: 4607958071111 | T5: 14607958071118 | U5: 4607958071111 | V5: 14607958071118 | W5: 160 | X5: 67 | Y5: 67 | Z5: 0.4 | AA5: 0.002 | AB5: =Z5+AA5 -> 0.402 | AC5: 318 | AD5: 143 | AE5: 138 | AF5: 8 | AG5: 600000407 | AH5: =справочники!$C$106 -> 0.094 | AI5: =ROUNDDOWN(номин.вес_нетто__кг*кол_во_инд.__упак_к,2) -> 3.2 | AJ5: =(номин.вес_брутто__кг*кол_во_инд.__упак_к)+вес_короба__кг -> 3.31 | AK5: 19 | AL5: 11 | AM5: =AK5*AL5 -> 209 | AN5: =IF(D5="ШТ",кол_во_инд.__упак_к*итого_г_у,ROUNDDOWN(номин.вес_нетто_г_у__кг*итого_г_у,1)) -> 1672 | AO5: =(высота__мм*кол_во_слоев_г_у)+145 -> 1663
A6: =VALUE(RIGHT(B6,4)) -> 7523 | B6: 1001012427523 | C6: ГОВЯЖЬЯ Папа может вар п/о 0.4кг 6шт. | D6: ШТ | E6: Колбасные изделия | F6: Вареные колбасы | G6: Папа может | H6: ОМПК(С) | I6: ТУ 10.13.14-180-00425283-2025 | J6: Мясосодержащий продукт. Изделие колбасное вареное категории В. | K6: говядина, стабилизатор белковый (кожа куриная, вода питьевая), мясо куриное механической обвалки, филе грудок куриных, вода питьевая, сыворотка молочная сухая, крахмал картофельный, смесь посолочно-нитритная (соль, фиксатор окраски (нитрит натрия)), регуляторы кислотности (трифосфаты, пирофосфаты, цитраты натрия), загустители (каррагинан, гуаровая камедь, ксантановая камедь, альгинат натрия), специи, экстракты пряностей, сахара, антиокислитель (аскорбиновая кислота), усилитель вкуса и аромата (глутамат натрия), ароматизатор, краситель (кармины) | L6: 9 | M6: 14 | N6: 4 | O6: 178/739 | P6: 0…+6 | Q6: 60 | R6: 72 часа | S6: 4607958076277 | T6: 24607958076271 | U6: 4607958076277 | V6: 24607958076271 | W6: 160 | X6: 67 | Y6: 67 | Z6: 0.4 | AA6: 0.002 | AB6: =Z6+AA6 -> 0.402 | AC6: 212 | AD6: 163 | AE6: 138 | AF6: 6 | AG6: 600000590 | AH6: =справочники!$C$189 -> 0.13 | AI6: =ROUNDDOWN(номин.вес_нетто__кг*кол_во_инд.__упак_к,2) -> 2.4 | AJ6: =(номин.вес_брутто__кг*кол_во_инд.__упак_к)+вес_короба__кг -> 2.542 | AK6: 26 | AL6: 9 | AM6: =AK6*AL6 -> 234 | AN6: =IF(D6="ШТ",кол_во_инд.__упак_к*итого_г_у,ROUNDDOWN(номин.вес_нетто_г_у__кг*итого_г_у,1)) -> 1404 | AO6: =(высота__мм*кол_во_слоев_г_у)+145 -> 1387
A7: =VALUE(RIGHT(B7,4)) -> 7025 | B7: 1001012427025 | C7: ГОВЯЖЬЯ ПМ вар п/о 0.85кг 4шт_Kvalita | D7: ШТ | E7: Колбасные изделия | F7: Вареные колбасы | G7: Папа может | H7: ОМПК(С) | I7: ТУ 10.13.14-180-00425283-2025 | J7: Мясосодержащий продукт. Изделие колбасное вареное категории В. | K7: говядина, стабилизатор белковый (кожа куриная, вода питьевая), мясо куриное механической обвалки, филе грудок куриных, вода питьевая, сыворотка молочная сухая, крахмал картофельный, смесь посолочно-нитритная (соль, фиксатор окраски (нитрит натрия)), регуляторы кислотности (трифосфаты, пирофосфаты, цитраты натрия), загустители (каррагинан, гуаровая камедь, ксантановая камедь, альгинат натрия), специи, экстракты пряностей, сахара, антиокислитель (аскорбиновая кислота), усилитель вкуса и аромата (глутамат натрия), ароматизатор, краситель (кармины) | L7: 9 | M7: 14 | N7: 4 | O7: 178/739 | P7: 0…+6 | Q7: 60 | R7: 72 часа | S7: 4607958078493 | T7: 14607958078490 | U7: 4607958078493 | V7: 14607958078490 | W7: 190 | X7: 70 | Y7: 70 | Z7: 0.85 | AA7: 0.002 | AB7: =Z7+AA7 -> 0.852 | AC7: 388 | AD7: 193 | AE7: 108 | AF7: 4 | AG7: 600000013 | AH7: =справочники!$C$5 -> 0.141 | AI7: =ROUNDDOWN(номин.вес_нетто__кг*кол_во_инд.__упак_к,2) -> 3.4 | AJ7: =(номин.вес_брутто__кг*кол_во_инд.__упак_к)+вес_короба__кг -> 3.549 | AK7: 12 | AL7: 14 | AM7: =AK7*AL7 -> 168 | AN7: =IF(D7="ШТ",кол_во_инд.__упак_к*итого_г_у,ROUNDDOWN(номин.вес_нетто_г_у__кг*итого_г_у,1)) -> 672 | AO7: =(высота__мм*кол_во_слоев_г_у)+145 -> 1657
A8: =VALUE(RIGHT(B8,4)) -> 6220 | B8: 1001012426220 | C8: ГОВЯЖЬЯ Папа может вар п/о | D8: КГ | E8: Колбасные изделия | F8: Вареные колбасы | G8: Папа может | H8: ОМПК(С) | I8: ТУ 10.13.14-180-00425283-2025 | J8: Мясосодержащий продукт. Изделие колбасное вареное категории В. | K8: говядина, мясо куриное механической обвалки, вода питьевая, филе грудок куриных, стабилизатор белковый (кожа куриная, вода питьевая), крахмал картофельный, сыворотка молочная сухая, смесь нитритно-посолочная (соль, фиксатор окраски (нитрит натрия)), соль, регуляторы кислотности (пирофосфаты, цитраты натрия), стабилизаторы (каррагинан, ксантановая камедь), пряности и экстракты пряностей, лук сушеный, сахара, усилитель вкуса и аромата (глутамат натрия), ароматизаторы, антиокислитель (аскорбиновая кислота), краситель (кармины) | L8: 9 | M8: 13 | N8: 2 | O8: 161/668 | P8: 0…+6 | Q8: 60 | R8: 72 часа | S8: 2800327000008 | T8: 12800327000005 | U8: 4630362181077 | V8: 14630362181074 | W8: 250 | X8: 90 | Y8: 90 | Z8: 1.35 | AA8: 0.002 | AB8: =Z8+AA8 -> 1.352 | AC8: 292 | AD8: 178 | AE8: 178 | AF8: 3 | AG8: 600000029 | AH8: =справочники!$C$21 -> 0.125 | AI8: =ROUNDDOWN(номин.вес_нетто__кг*кол_во_инд.__упак_к,2) -> 4.05 | AJ8: =(номин.вес_брутто__кг*кол_во_инд.__упак_к)+вес_короба__кг -> 4.181 | AK8: 14 | AL8: 8 | AM8: =AK8*AL8 -> 112 | AN8: =IF(D8="ШТ",кол_во_инд.__упак_к*итого_г_у,ROUNDDOWN(номин.вес_нетто_г_у__кг*итого_г_у,1)) -> 453.6 | AO8: =(высота__мм*кол_во_слоев_г_у)+145 -> 1569
A9: =VALUE(RIGHT(B9,4)) -> 3254 | B9: 1001012993254 | C9: ДОКТОР СКАЙ Папа может вар п/о | D9: КГ | E9: Колбасные изделия | F9: Вареные колбасы | G9: Папа может | H9: ОМПК(С) | I9: ТУ 10.13.14-180-00425283-2025 | J9: Мясной продукт. Изделие колбасное вареное категории В. | K9: свинина, филе грудок куриных, мясо цыпленка-бройлера механической обвалки, стабилизатор белковый (шкурка свиная, вода питьевая), вода питьевая, сыворотка молочная сухая, молоко сухое обезжиренное, крахмалы (кукурузный, картофельный), смесь посолочно-нитритная (соль, фиксатор окраски (нитрит натрия)), сахара, регуляторы кислотности (пирофосфаты, трифосфаты, цитраты натрия), загустители (каррагинан, гуаровая камедь, ксантановая камедь), пряности, чеснок сушеный молотый, перец черный молотый, имбирь, горчица, антиокислитель (аскорбиновая кислота), усилитель вкуса и аромата (глутамат натрия 1-замещенный), ароматизаторы, краситель (кармины) | L9: 9 | M9: 14 | N9: 5 | O9: 182/756 | P9: 0…+6 | Q9: 60 | R9: 72 часа | S9: 2100116000005 | T9: 12100116000002 | U9: 4630362181138 | V9: 14630362181135 | W9: 250 | X9: 90 | Y9: 90 | Z9: 1.35 | AA9: 0.002 | AB9: =Z9+AA9 -> 1.352 | AC9: 292 | AD9: 178 | AE9: 178 | AF9: 3 | AG9: 600000029 | AH9: =справочники!$C$21 -> 0.125 | AI9: =ROUNDDOWN(номин.вес_нетто__кг*кол_во_инд.__упак_к,2) -> 4.05 | AJ9: =(номин.вес_брутто__кг*кол_во_инд.__упак_к)+вес_короба__кг -> 4.181 | AK9: 16 | AL9: 8 | AM9: =AK9*AL9 -> 128 | AN9: =IF(D9="ШТ",кол_во_инд.__упак_к*итого_г_у,ROUNDDOWN(номин.вес_нетто_г_у__кг*итого_г_у,1)) -> 518.4 | AO9: =(высота__мм*кол_во_слоев_г_у)+145 -> 1569
A10: =VALUE(RIGHT(B10,4)) -> 7577 | B10: 1001012997577 | C10: ДОКТОР СКАЙ Папа может вар п/о 1.35*8 | D10: КГ | E10: Колбасные изделия | F10: Вареные колбасы | G10: Папа может | H10: ОМПК(С) | I10: ТУ 10.13.14-180-00425283-2025 | J10: Мясной продукт. Изделие колбасное вареное категории В. | K10: свинина, стабилизатор белковый (вода питьевая, шкурка свиная, кожа куриная), мясо куриное механической обвалки, вода питьевая, сыворотка молочная сухая, молоко сухое обезжиренное, крахмалы (кукурузный, картофельный), смесь посолочно-нитритная (соль, фиксатор окраски (нитрит натрия)), сахар, регуляторы кислотности (пирофосфаты, трифосфаты, цитраты натрия), загустители (каррагинан, гуаровая камедь, конжак, ксантановая камедь), специи, экстракты специй (в т.ч. горчица), антиокислитель (аскорбиновая кислота), усилитель вкуса и аромата (глутамат натрия), ароматизаторы, краситель (кармины) | L10: 9 | M10: 14 | N10: 5 | O10: 182/756 | P10: 0…+6 | Q10: 60 | R10: 72 часа | S10: 2100116000005 | T10: 12100116000002 | U10: 4630362181138 | V10: 24630362181132 | W10: 250 | X10: 90 | Y10: 90 | Z10: 1.35 | AA10: 0.002 | AB10: =Z10+AA10 -> 1.352 | AC10: 293 | AD10: 394 | AE10: 158 | AF10: 8 | AG10: 600000607 | AH10: =справочники!$C$195 -> 0.236 | AI10: =ROUNDDOWN(номин.вес_нетто__кг*кол_во_инд.__упак_к,2) -> 10.8 | AJ10: =(номин.вес_брутто__кг*кол_во_инд.__упак_к)+вес_короба__кг -> 11.052 | AK10: 8 | AL10: 9 | AM10: =AK10*AL10 -> 72 | AN10: =IF(D10="ШТ",кол_во_инд.__упак_к*итого_г_у,ROUNDDOWN(номин.вес_нетто_г_у__кг*итого_г_у,1)) -> 777.6 | AO10: =(высота__мм*кол_во_слоев_г_у)+145 -> 1567
A11: =VALUE(RIGHT(B11,4)) -> 1112 | B11: 1001010011112 | C11: ДОКТОРСКАЯ ГОСТ Останкино вар н/о в/у | D11: КГ | E11: Колбасные изделия | F11: Вареные колбасы | G11: Останкино | H11: ОМПК(Г) | I11: ГОСТ 23670-2019 | J11: Мясной продукт. Изделие колбасное вареное категории А. | K11: свинина, говядина, вода питьевая, сухой яичный меланж, молоко сухое обезжиренное, смесь посолочно-нитритная (соль, фиксатор окраски (нитрит натрия)), регуляторы кислотности (пирофосфаты, цитраты натрия), сахар, антиокислитель (аскорбиновая кислота), кардамон, усилитель вкуса и аромата (глутамат натрия) | L11: 12 | M11: 20 | N11: 0 | O11: 228/955 | P11: 0…+6 | Q11: 30 | R11: 48 часов | S11: 2326628000009 | T11: 12326628000006 | U11: 4630362182494 | V11: 14630362182491 | W11: 170-185 | X11: 115-125 | Y11: 115-125 | Z11: 1.325 | AA11: 0.008 | AB11: =Z11+AA11 -> 1.333 | AC11: 383 | AD11: 156 | AE11: 168 | AF11: 2 | AG11: 600000030 | AH11: =справочники!$C$22 -> 0.127 | AI11: =ROUNDDOWN(номин.вес_нетто__кг*кол_во_инд.__упак_к,2) -> 2.65 | AJ11: =(номин.вес_брутто__кг*кол_во_инд.__упак_к)+вес_короба__кг -> 2.793 | AK11: 15 | AL11: 9 | AM11: =AK11*AL11 -> 135 | AN11: =IF(D11="ШТ",кол_во_инд.__упак_к*итого_г_у,ROUNDDOWN(номин.вес_нетто_г_у__кг*итого_г_у,1)) -> 357.7 | AO11: =(высота__мм*кол_во_слоев_г_у)+145 -> 1657
A12: =VALUE(RIGHT(B12,4)) -> 4555 | B12: 1001010014555 | C12: ДОКТОРСКАЯ ГОСТ вар п/о | D12: КГ | E12: Колбасные изделия | F12: Вареные колбасы | G12: Останкино | H12: ОМПК(С) | I12: ГОСТ 23670-2019 | J12: Мясной продукт. Изделие колбасное вареное категории А. | K12: свинина, говядина, вода питьевая, сухой яичный меланж, молоко сухое обезжиренное, смесь посолочно-нитритная (соль, фиксатор окраски (нитрит натрия)), регуляторы кислотности (пирофосфаты, трифосфаты, цитраты натрия), стабилизатор (полифосфаты), пряности (орех мускатный молотый), сахар, антиокислитель (аскорбиновая кислота), усилитель вкуса и аромата (глутамат натрия) | L12: 12 | M12: 20 | N12: 0 | O12: 228/955 | P12: 0…+6 | Q12: 60 | R12: 3 суток | S12: 2722280000003 | T12: 12722280000000 | U12: 4630362181152 | V12: 14630362181159 | W12: 250 | X12: 90 | Y12: 90 | Z12: 1.35 | AA12: 0.002 | AB12: =Z12+AA12 -> 1.352 | AC12: 292 | AD12: 178 | AE12: 178 | AF12: 3 | AG12: 600000029 | AH12: =справочники!$C$21 -> 0.125 | AI12: =ROUNDDOWN(номин.вес_нетто__кг*кол_во_инд.__упак_к,2) -> 4.05 | AJ12: =(номин.вес_брутто__кг*кол_во_инд.__упак_к)+вес_короба__кг -> 4.181 | AK12: 16 | AL12: 8 | AM12: =AK12*AL12 -> 128 | AN12: =IF(D12="ШТ",кол_во_инд.__упак_к*итого_г_у,ROUNDDOWN(номин.вес_нетто_г_у__кг*итого_г_у,1)) -> 518.4 | AO12: =(высота__мм*кол_во_слоев_г_у)+145 -> 1569
A13: =VALUE(RIGHT(B13,4)) -> 7536 | B13: 1001010017536 | C13: ДОКТОРСКАЯ ГОСТ Останкино вар п/о | D13: КГ | E13: Колбасные изделия | F13: Вареные колбасы | G13: Останкино | H13: ОМПК(С) | I13: ГОСТ 23670-2019 | J13: Мясной продукт. Изделие колбасное вареное категории А. | K13: свинина, говядина, вода питьевая, сухой яичный меланж, молоко сухое обезжиренное, смесь посолочно-нитритная (соль, фиксатор окраски (нитрит натрия)), регуляторы кислотности (пирофосфаты, трифосфаты, цитраты натрия), стабилизатор (полифосфаты), пряности (орех мускатный молотый), сахар, антиокислитель (аскорбиновая кислота), усилитель вкуса и аромата (глутамат натрия) | L13: 12 | M13: 20 | N13: 0 | O13: 228/955 | P13: 0…+6 | Q13: 60 | R13: 3 суток | S13: 2800541000006 | T13: 12800541000003 | U13: 4630362181152 | V13: 14630362181159 | W13: 250 | X13: 90 | Y13: 90 | Z13: 1.35 | AA13: 0.002 | AB13: =Z13+AA13 -> 1.352 | AC13: 292 | AD13: 178 | AE13: 178 | AF13: 3 | AG13: 600000029 | AH13: =справочники!$C$21 -> 0.125 | AI13: =ROUNDDOWN(номин.вес_нетто__кг*кол_во_инд.__упак_к,2) -> 4.05 | AJ13: =(номин.вес_брутто__кг*кол_во_инд.__упак_к)+вес_короба__кг -> 4.181 | AK13: 16 | AL13: 8 | AM13: =AK13*AL13 -> 128 | AN13: =IF(D13="ШТ",кол_во_инд.__упак_к*итого_г_у,ROUNDDOWN(номин.вес_нетто_г_у__кг*итого_г_у,1)) -> 518.4 | AO13: =(высота__мм*кол_во_слоев_г_у)+145 -> 1569
A14: =VALUE(RIGHT(B14,4)) -> 7539 | B14: 1001010017539 | C14: ДОКТОРСКАЯ ГОСТ Останкино вар п/о 0.35кг | D14: ШТ | E14: Колбасные изделия | F14: Вареные колбасы | G14: Останкино | H14: ОМПК(С) | I14: ГОСТ 23670-2019 | J14: Мясной продукт. Изделие колбасное вареное категории А. | K14: свинина, говядина, вода питьевая, сухой яичный меланж, молоко сухое обезжиренное, смесь посолочно-нитритная (соль, фиксатор окраски (нитрит натрия)), регуляторы кислотности (пирофосфаты, трифосфаты, цитраты натрия), стабилизатор (полифосфаты), пряности (орех мускатный молотый), сахар, антиокислитель (аскорбиновая кислота), усилитель вкуса и аромата (глутамат натрия) | L14: 12 | M14: 20 | N14: 0 | O14: 228/955 | P14: 0…+6 | Q14: 60 | R14: 3 суток | S14: 4630362182227 | T14: 14630362182224 | U14: 4630362182227 | V14: 14630362182224 | W14: 180 | X14: 57 | Y14: 57 | Z14: 0.35 | AA14: 0.002 | AB14: =Z14+AA14 -> 0.352 | AC14: 258 | AD14: 193 | AE14: 123 | AF14: 8 | AG14: 600000403 | AH14: =справочники!$C$100 -> 0.104 | AI14: =ROUNDDOWN(номин.вес_нетто__кг*кол_во_инд.__упак_к,2) -> 2.8 | AJ14: =(номин.вес_брутто__кг*кол_во_инд.__упак_к)+вес_короба__кг -> 2.92 | AK14: 18 | AL14: 12 | AM14: =AK14*AL14 -> 216 | AN14: =IF(D14="ШТ",кол_во_инд.__упак_к*итого_г_у,ROUNDDOWN(номин.вес_нетто_г_у__кг*итого_г_у,1)) -> 1728 | AO14: =(высота__мм*кол_во_слоев_г_у)+145 -> 1621
A15: =VALUE(RIGHT(B15,4)) -> 7477 | B15: 1001016447477 | C15: ДОКТОРСКАЯ ГОСТ ПМ вар п/о 0.35кг 8шт. | D15: ШТ | E15: Колбасные изделия | F15: Вареные колбасы | G15: Папа может | H15: ОМПК(С) | I15: ГОСТ 23670-2019 | J15: Мясной продукт. Изделие колбасное вареное категории А. | K15: свинина, говядина, вода питьевая, сухой яичный меланж, молоко сухое обезжиренное, смесь посолочно-нитритная (соль, фиксатор окраски (нитрит натрия)), регуляторы кислотности (пирофосфаты, трифосфаты, цитраты натрия), стабилизатор (полифосфаты), пряности (орех мускатный молотый), сахар, антиокислитель (аскорбиновая кислота), усилитель вкуса и аромата (глутамат натрия) | L15: 12 | M15: 20 | N15: 0 | O15: 228/955 | P15: 0…+6 | Q15: 60 | R15: 3 суток | S15: 4630362181015 | T15: 14630362181012 | U15: 4630362181015 | V15: 14630362181012 | W15: 180 | X15: 57 | Y15: 57 | Z15: 0.35 | AA15: 0.002 | AB15: =Z15+AA15 -> 0.352 | AC15: 258 | AD15: 193 | AE15: 123 | AF15: 8 | AG15: 600000403 | AH15: =справочники!$C$100 -> 0.104 | AI15: =ROUNDDOWN(номин.вес_нетто__кг*кол_во_инд.__упак_к,2) -> 2.8 | AJ15: =(номин.вес_брутто__кг*кол_во_инд.__упак_к)+вес_короба__кг -> 2.92 | AK15: 18 | AL15: 12 | AM15: =AK15*AL15 -> 216 | AN15: =IF(D15="ШТ",кол_во_инд.__упак_к*итого_г_у,ROUNDDOWN(номин.вес_нетто_г_у__кг*итого_г_у,1)) -> 1728 | AO15: =(высота__мм*кол_во_слоев_г_у)+145 -> 1621
A16: =VALUE(RIGHT(B16,4)) -> 6324 | B16: 1001010016324 | C16: ДОКТОРСКАЯ ГОСТ вар п/о 0.4кг 8шт. | D16: ШТ | E16: Колбасные изделия | F16: Вареные колбасы | G16: Останкино | H16: ОМПК(С) | I16: ГОСТ 23670-2019 | J16: Мясной продукт. Изделие колбасное вареное категории А. | K16: свинина, говядина, вода питьевая, сухой яичный меланж, молоко сухое обезжиренное, смесь посолочно-нитритная (соль, фиксатор окраски (нитрит натрия)), регуляторы кислотности (пирофосфаты, трифосфаты, цитраты натрия), стабилизатор (полифосфаты), пряности (орех мускатный молотый), сахар, антиокислитель (аскорбиновая кислота), усилитель вкуса и аромата (глутамат натрия) | L16: 12 | M16: 20 | N16: 0 | O16: 228/955 | P16: 0…+6 | Q16: 60 | R16: 3 суток | S16: 4607958074334 | T16: 14607958074331 | U16: 4607958074334 | V16: 14607958074331 | W16: 160 | X16: 67 | Y16: 67 | Z16: 0.4 | AA16: 0.002 | AB16: =Z16+AA16 -> 0.402 | AC16: 318 | AD16: 143 | AE16: 138 | AF16: 8 | AG16: 600000407 | AH16: =справочники!$C$106 -> 0.094 | AI16: =ROUNDDOWN(номин.вес_нетто__кг*кол_во_инд.__упак_к,2) -> 3.2 | AJ16: =(номин.вес_брутто__кг*кол_во_инд.__упак_к)+вес_короба__кг -> 3.31 | AK16: 19 | AL16: 11 | AM16: =AK16*AL16 -> 209 | AN16: =IF(D16="ШТ",кол_во_инд.__упак_к*итого_г_у,ROUNDDOWN(номин.вес_нетто_г_у__кг*итого_г_у,1)) -> 1672 | AO16: =(высота__мм*кол_во_слоев_г_у)+145 -> 1663
A17: =VALUE(RIGHT(B17,4)) -> 7190 | B17: 1001016447190 | C17: ДОКТОРСКАЯ ГОСТ вар п/о 0.7кг 6шт. | D17: ШТ | E17: Колбасные изделия | F17: Вареные колбасы | G17: Останкино | H17: ОМПК(С) | I17: ГОСТ 23670-2019 | J17: Мясной продукт. Изделие колбасное вареное категории А. | K17: свинина, говядина, вода питьевая, сухой яичный меланж, молоко сухое обезжиренное, смесь посолочно-нитритная (соль, фиксатор окраски (нитрит натрия)), регуляторы кислотности (пирофосфаты, цитраты натрия), сахар, антиокислитель (аскорбиновая кислота), кардамон, усилитель вкуса и аромата (глутамат натрия) | L17: 12 | M17: 20 | O17: 228/955 | P17: 0…+6 | Q17: 60 | R17: 3 суток | S17: 4607958079230 | T17: 14607958079237 | U17: 4607958079230 | V17: 14607958079237 | W17: 245 | X17: 67 | Y17: 67 | Z17: 0.7 | AA17: 0.002 | AB17: =Z17+AA17 -> 0.702 | AC17: 293 | AD17: 153 | AE17: 224 | AF17: 6 | AG17: 600000400 | AH17: =справочники!$C$95 -> 0.135 | AI17: =ROUNDDOWN(номин.вес_нетто__кг*кол_во_инд.__упак_к,2) -> 4.2 | AJ17: =(номин.вес_брутто__кг*кол_во_инд.__упак_к)+вес_короба__кг -> 4.347 | AK17: 20 | AL17: 7 | AM17: =AK17*AL17 -> 140 | AN17: =IF(D17="ШТ",кол_во_инд.__упак_к*итого_г_у,ROUNDDOWN(номин.вес_нетто_г_у__кг*итого_г_у,1)) -> 840 | AO17: =(высота__мм*кол_во_слоев_г_у)+145 -> 1713
A18: =VALUE(RIGHT(B18,4)) -> 7557 | B18: 1001010017557 | C18: ДОКТОРСКАЯ ГОСТ Останкино вар ц/о в/у | D18: КГ | E18: Колбасные изделия | F18: Вареные колбасы | G18: Останкино | H18: ОМПК(С) | I18: ГОСТ 23670-2019 | J18: Мясной продукт. Изделие колбасное вареное категории А. | K18: свинина, говядина, вода питьевая, сухой яичный меланж, молоко сухое обезжиренное, смесь посолочно-нитритная (соль, фиксатор окраски (нитрит натрия)), регуляторы кислотности (пирофосфаты, трифосфаты, цитраты натрия), стабилизатор (полифосфаты), пряности (орех мускатный молотый), сахар, антиокислитель (аскорбиновая кислота), усилитель вкуса и аромата (глутамат натрия) | L18: 12 | M18: 20 | N18: 0 | O18: 228/955 | P18: 0…+6 | Q18: 30 | R18: 48 часов | S18: 2500317000000 | T18: 12500317000007 | U18: 4630362181169 | V18: 24630362181163 | W18: 330 | X18: 100 | Y18: 85 | Z18: 1.6 | AA18: 0.01 | AB18: =Z18+AA18 -> 1.61 | AC18: 338 | AD18: 188 | AE18: 178 | AF18: 4 | AG18: 600000260 | AH18: =справочники!$C$54 -> 0.177 | AI18: =ROUNDDOWN(номин.вес_нетто__кг*кол_во_инд.__упак_к,2) -> 6.4 | AJ18: =(номин.вес_брутто__кг*кол_во_инд.__упак_к)+вес_короба__кг -> 6.617 | AK18: 12 | AL18: 8 | AM18: =AK18*AL18 -> 96 | AN18: =IF(D18="ШТ",кол_во_инд.__упак_к*итого_г_у,ROUNDDOWN(номин.вес_нетто_г_у__кг*итого_г_у,1)) -> 614.4 | AO18: =(высота__мм*кол_во_слоев_г_у)+145 -> 1569
A19: =VALUE(RIGHT(B19,4)) -> 4561 | B19: 1001010014561 | C19: ДОКТОРСКАЯ ГОСТ Папа может вар п/о | D19: КГ | E19: Колбасные изделия | F19: Вареные колбасы | G19: Папа может | H19: ОМПК(С) | I19: ГОСТ 23670-2019 | J19: Мясной продукт. Изделие колбасное вареное категории А. | K19: свинина, говядина, вода, молоко коровье сухое обезжиренное, соль, смесь посолочно-нитритная (соль, фиксатор окраски нитрит натрия), сухой яичный меланж, регуляторы кислотности: пирофосфаты, ацетаты натрия; сахар, антиокислитель аскорбиновая кислота, кардамон, усилитель вкуса и аромата глутамат натрия | L19: 12 | M19: 20 | O19: 228/955 | P19: 0…+6 | Q19: 60 | R19: 3 суток | S19: 2800296000009 | T19: 12800296000006 | U19: 4630362180100 | V19: 14630362180107 | W19: 250 | X19: 90 | Y19: 90 | Z19: 1.35 | AA19: 0.002 | AB19: =Z19+AA19 -> 1.352 | AC19: 292 | AD19: 178 | AE19: 178 | AF19: 3 | AG19: 600000029 | AH19: =справочники!$C$21 -> 0.125 | AI19: =ROUNDDOWN(номин.вес_нетто__кг*кол_во_инд.__упак_к,2) -> 4.05 | AJ19: =(номин.вес_брутто__кг*кол_во_инд.__упак_к)+вес_короба__кг -> 4.181 | AK19: 16 | AL19: 8 | AM19: =AK19*AL19 -> 128 | AN19: =IF(D19="ШТ",кол_во_инд.__упак_к*итого_г_у,ROUNDDOWN(номин.вес_нетто_г_у__кг*итого_г_у,1)) -> 518.4 | AO19: =(высота__мм*кол_во_слоев_г_у)+145 -> 1569
A20: =VALUE(RIGHT(B20,4)) -> 7567 | B20: 1001010017567 | C20: ДОКТОРСКАЯ ГОСТ ПМ вар п/о 1.35*8 | D20: КГ | E20: Колбасные изделия | F20: Вареные колбасы | G20: Папа может | H20: ОМПК(С) | I20: ГОСТ 23670-2019 | J20: Мясной продукт. Изделие колбасное вареное категории А. | K20: свинина, говядина, вода, молоко коровье сухое обезжиренное, соль, смесь посолочно-нитритная (соль, фиксатор окраски нитрит натрия), сухой яичный меланж, регуляторы кислотности: пирофосфаты, ацетаты натрия; сахар, антиокислитель аскорбиновая кислота, кардамон, усилитель вкуса и аромата глутамат натрия | L20: 12 | M20: 20 | O20: 228/955 | P20: 0…+6 | Q20: 60 | R20: 3 суток | S20: 2800296000009 | T20: 12800296000006 | U20: 4630362180100 | V20: 24630362180104 | W20: 250 | X20: 90 | Y20: 90 | Z20: 1.35 | AA20: 0.002 | AB20: =Z20+AA20 -> 1.352 | AC20: 293 | AD20: 394 | AE20: 158 | AF20: 8 | AG20: 600000607 | AH20: =справочники!$C$195 -> 0.236 | AI20: =ROUNDDOWN(номин.вес_нетто__кг*кол_во_инд.__упак_к,2) -> 10.8 | AJ20: =(номин.вес_брутто__кг*кол_во_инд.__упак_к)+вес_короба__кг -> 11.052 | AK20: 8 | AL20: 9 | AM20: =AK20*AL20 -> 72 | AN20: =IF(D20="ШТ",кол_во_инд.__упак_к*итого_г_у,ROUNDDOWN(номин.вес_нетто_г_у__кг*итого_г_у,1)) -> 777.6 | AO20: =(высота__мм*кол_во_слоев_г_у)+145 -> 1567
A21: =VALUE(RIGHT(B21,4)) -> 7403 | B21: 1001010077403 | C21: ДОКТОРСКАЯ КЛАССИЧ. ASLAM вар п/о 0.5кг | D21: ШТ | E21: Колбасные изделия | F21: Вареные колбасы | G21: ASLAM | H21: ООО Казанские деликатесы | I21: ТУ 10.13.14-175-00425283-2025 | J21: Изделие колбасное вареное из мяса кур охлажденное. | K21: мясо куриное механической обвалки, филе грудок куриных, стабилизатор белковый (вода питьевая, кожа куриная, говядина), вода питьевая, молоко сухое обезжиренное, сыворотка молочная сухая, крахмал картофельный, смесь посолочно-нитритная (соль, фиксатор окраски (нитрит натрия)), регуляторы кислотности (пирофосфаты, трифосфаты, цитраты натрия), загустители (каррагинан, конжак, ксантановая камедь, гуаровая камедь), перец черный, экстракты пряностей, сахара, антиокислители (аскорбиновая кислота, лимонная кислота), усилитель вкуса и аромата (глутамат натрия), ароматизатор, экстракт гардении красной | L21: 10 | M21: 11 | N21: 3 | O21: 151/628 | P21: 0…+6 | Q21: 60 | R21: 72 часа | S21: 4630362180353 | T21: 14630362180350 | U21: 4630362180353 | V21: 14630362180350 | W21: 190 | X21: 67 | Y21: 67 | Z21: 0.5 | AA21: 0.006 | AB21: =Z21+AA21 -> 0.506 | AC21: 278 | AD21: 193 | AE21: 138 | AF21: 8 | AG21: 600000404 | AH21: =справочники!$C$179 -> 0.138 | AI21: =ROUNDDOWN(номин.вес_нетто__кг*кол_во_инд.__упак_к,2) -> 4 | AJ21: =(номин.вес_брутто__кг*кол_во_инд.__упак_к)+вес_короба__кг -> 4.186 | AK21: 16 | AL21: 9 | AM21: =AK21*AL21 -> 144 | AN21: =IF(D21="ШТ",кол_во_инд.__упак_к*итого_г_у,ROUNDDOWN(номин.вес_нетто_г_у__кг*итого_г_у,1)) -> 1152 | AO21: =(высота__мм*кол_во_слоев_г_у)+145 -> 1387
A22: =VALUE(RIGHT(B22,4)) -> 7406 | B22: 1001010077406 | C22: ДОКТОРСКАЯ КЛАССИЧ. ASLAM вар п/о 0.9кг | D22: ШТ | E22: Колбасные изделия | F22: Вареные колбасы | G22: ASLAM | H22: ООО Казанские деликатесы | I22: ТУ 10.13.14-175-00425283-2025 | J22: Изделие колбасное вареное из мяса кур охлажденное. | K22: мясо куриное механической обвалки, филе грудок куриных, стабилизатор белковый (вода питьевая, кожа куриная, говядина), вода питьевая, молоко сухое обезжиренное, сыворотка молочная сухая, крахмал картофельный, смесь посолочно-нитритная (соль, фиксатор окраски (нитрит натрия)), регуляторы кислотности (пирофосфаты, трифосфаты, цитраты натрия), загустители (каррагинан, конжак, ксантановая камедь, гуаровая камедь), перец черный, экстракты пряностей, сахара, антиокислители (аскорбиновая кислота, лимонная кислота), усилитель вкуса и аромата (глутамат натрия), ароматизатор, экстракт гардении красной | L22: 10 | M22: 11 | N22: 3 | O22: 151/628 | P22: 0…+6 | Q22: 60 | R22: 72 часа | S22: 4630362180360 | T22: 14630362180367 | U22: 4630362180360 | V22: 14630362180367 | W22: 250 | X22: 78 | Y22: 78 | Z22: 0.9 | AA22: 0.008 | AB22: =Z22+AA22 -> 0.908 | AC22: 292 | AD22: 178 | AE22: 178 | AF22: 4 | AG22: 600000573 | AH22: =справочники!$C$183 -> 0.15 | AI22: =ROUNDDOWN(номин.вес_нетто__кг*кол_во_инд.__упак_к,2) -> 3.6 | AJ22: =(номин.вес_брутто__кг*кол_во_инд.__упак_к)+вес_короба__кг -> 3.782 | AK22: 16 | AL22: 8 | AM22: =AK22*AL22 -> 128 | AN22: =IF(D22="ШТ",кол_во_инд.__упак_к*итого_г_у,ROUNDDOWN(номин.вес_нетто_г_у__кг*итого_г_у,1)) -> 512 | AO22: =(высота__мм*кол_во_слоев_г_у)+145 -> 1569
A23: =VALUE(RIGHT(B23,4)) -> 6988 | B23: 1001010096988 | C23: ДОКТОРСКАЯ ОРИГИНАЛЬНАЯ вар ц/о в/у_45с | D23: КГ | E23: Колбасные изделия | F23: Вареные колбасы | G23: Коровино | H23: ОМПК(С) | I23: ТУ 10.13.14-150-00425283-2018 | J23: Изделие колбасное вареное из мяса кур охлажденное. | K23: мясо куриное механической обвалки, вода, свинина, филе грудок куриных, белковый стабилизатор (вода, шкурка свиная, кожа куриная), крахмал картофельный, сыворотка молочная сухая, молоко сухое обезжиренное, смесь посолочно-нитритная (соль, фиксатор окраски нитрит натрия), регуляторы кислотности: пирофосфаты, цитраты натрия, глюконо-дельта-лактон; стабилизаторы: полифосфаты, альгинат натрия, камеди (гуаровая, конжаковая, ксантановая), специи и экстракты специй, сахара, соль, горчица, ароматизаторы, усилитель вкуса и аромата глутамат натрия, антиокислитель изоаскорбат натрия, краситель кармины | L23: 9 | M23: 14 | N23: 3 | O23: 174/722 | P23: 0…+6 | Q23: 45 | R23: 48 часов | S23: 2313712000007 | T23: 12313712000004 | U23: 4630362181176 | V23: 14630362181173 | W23: 330 | X23: 100 | Y23: 85 | Z23: 1.55 | AA23: 0.01 | AB23: =Z23+AA23 -> 1.56 | AC23: 338 | AD23: 188 | AE23: 178 | AF23: 4 | AG23: 600000260 | AH23: =справочники!$C$54 -> 0.177 | AI23: =ROUNDDOWN(номин.вес_нетто__кг*кол_во_инд.__упак_к,2) -> 6.2 | AJ23: =(номин.вес_брутто__кг*кол_во_инд.__упак_к)+вес_короба__кг -> 6.417 | AK23: 12 | AL23: 8 | AM23: =AK23*AL23 -> 96 | AN23: =IF(D23="ШТ",кол_во_инд.__упак_к*итого_г_у,ROUNDDOWN(номин.вес_нетто_г_у__кг*итого_г_у,1)) -> 595.2 | AO23: =(высота__мм*кол_во_слоев_г_у)+145 -> 1569
A24: =VALUE(RIGHT(B24,4)) -> 7515 | B24: 1001017437515 | C24: ДОКТОРСКАЯ ОСТАНКИНСКАЯ вар ц/о в/у | D24: КГ | E24: Колбасные изделия | F24: Вареные колбасы | G24: Останкино | H24: ОМПК(С) | I24: ТУ 10.13.14-180-00425283-2025 | J24: Мясной продукт. Изделие колбасное вареное категории В. | K24: свинина, вода питьевая, стабилизатор белковый (вода питьевая, шкурка свиная), шпик, говядина, сыворотка молочная сухая, смесь посолочно-нитритная (соль, фиксатор окраски (нитрит натрия)), соль, регуляторы кислотности (пирофосфаты, трифосфаты, цитраты натрия), стабилизатор (полифосфаты), загустители (альгинат натрия, каррагинан), крахмал картофельный, специи, экстракты специй и пряностей (в т.ч. горчица, сельдерей), сахара, антиокислители (изоаскорбат натрия, аскорбиновая кислота, лимонная кислота), усилитель вкуса и аромата (глутамат натрия), ароматизаторы, краситель (кармины) | L24: 10 | M24: 16 | N24: 4 | O24: 200/830 | P24: 0…+6 | Q24: 30 | R24: 72 часа | S24: 2800522000001 | T24: 12800522000008 | U24: 4630362182500 | V24: 14630362182507 | W24: 330 | X24: 100 | Y24: 85 | Z24: 1.6 | AA24: 0.01 | AB24: =Z24+AA24 -> 1.61 | AC24: 338 | AD24: 188 | AE24: 178 | AF24: 4 | AG24: 600000260 | AH24: =справочники!$C$54 -> 0.177 | AI24: =ROUNDDOWN(номин.вес_нетто__кг*кол_во_инд.__упак_к,2) -> 6.4 | AJ24: =(номин.вес_брутто__кг*кол_во_инд.__упак_к)+вес_короба__кг -> 6.617 | AK24: 12 | AL24: 8 | AM24: =AK24*AL24 -> 96 | AN24: =IF(D24="ШТ",кол_во_инд.__упак_к*итого_г_у,ROUNDDOWN(номин.вес_нетто_г_у__кг*итого_г_у,1)) -> 614.4 | AO24: =(высота__мм*кол_во_слоев_г_у)+145 -> 1569
A25: =VALUE(RIGHT(B25,4)) -> 7555 | B25: 1001012497555 | C25: ДОКТОРСКАЯ ПО-ОСТАНКИНСКИ вар б/о в/у | D25: КГ | E25: Колбасные изделия | F25: Вареные колбасы | G25: Останкино | H25: ОМПК(Г) | I25: ТУ 10.13.14-180-00425283-2025 | J25: Мясной продукт. Изделие колбасное вареное категории В. | K25: свинина, вода питьевая, стабилизатор белковый (вода питьевая, шкурка свиная, кожа куриная), мясо куриное механической обвалки, сыворотка молочная сухая, крахмал картофельный, смесь посолочно-нитритная (соль, фиксатор окраски (нитрит натрия)), соль, сахар, регуляторы кислотности (пирофосфаты, трифосфаты, цитраты натрия), стабилизатор (полифосфаты), загустители (альгинат натрия, каррагинан, гуаровая камедь, ксантановая камедь), специи, экстракты специй (в т.ч. горчица, сельдерей), антиокислители (аскорбиновая кислота, лимонная кислота, изоаскорбат натрия), усилитель вкуса и аромата (глутамат натрия), ароматизатор, краситель (кармины) | L25: 11 | M25: 16 | N25: 4 | O25: 204/847 | P25: 0…+6 | Q25: 30 | R25: 48 часов | S25: 2800243000007 | T25: 12800243000004 | U25: 4630362182531 | V25: 14630362182538 | W25: 365 | X25: 220 | Y25: 110 | Z25: 1.5 | AA25: 0.01 | AB25: =Z25+AA25 -> 1.51 | AC25: 292 | AD25: 178 | AE25: 178 | AF25: 2 | AG25: 600000029 | AH25: =справочники!$C$21 -> 0.125 | AI25: =ROUNDDOWN(номин.вес_нетто__кг*кол_во_инд.__упак_к,2) -> 3 | AJ25: =(номин.вес_брутто__кг*кол_во_инд.__упак_к)+вес_короба__кг -> 3.145 | AK25: 16 | AL25: 8 | AM25: =AK25*AL25 -> 128 | AN25: =IF(D25="ШТ",кол_во_инд.__упак_к*итого_г_у,ROUNDDOWN(номин.вес_нетто_г_у__кг*итого_г_у,1)) -> 384 | AO25: =(высота__мм*кол_во_слоев_г_у)+145 -> 1569
A26: =VALUE(RIGHT(B26,4)) -> 6325 | B26: 1001010106325 | C26: ДОКТОРСКАЯ ПРЕМИУМ вар п/о 0.4кг 8шт. | D26: ШТ | E26: Колбасные изделия | F26: Вареные колбасы | G26: Папа может | H26: ОМПК(С) | I26: ТУ 10.13.14-180-00425283-2025 | J26: Мясной продукт. Изделие колбасное вареное категории Б. | K26: свинина, вода питьевая, стабилизатор белковый (вода питьевая, шкурка свиная, кожа куриная), мясо куриное механической обвалки, филе грудок куриных, сыворотка молочная сухая, крахмал картофельный, смесь посолочно-нитритная (соль, фиксатор окраски (нитрит натрия)), соль, регуляторы кислотности (трифосфаты, пирофосфаты, цитраты натрия), загустители (альгинат натрия, каррагинан, гуаровая камедь, ксантановая камедь), специи, экстракты специй (в т.ч. горчица, сельдерей), сахара, антиокислитель (аскорбиновая кислота), усилитель вкуса и аромата (глутамат натрия), ароматизатор, краситель (кармины) | L26: 11 | M26: 16 | N26: 3 | O26: 200/830 | P26: 0…+6 | Q26: 60 | R26: 72 часа | S26: 4607958072682 | T26: 14607958072689 | U26: 4607958072682 | V26: 14607958072689 | W26: 160 | X26: 67 | Y26: 67 | Z26: 0.4 | AA26: 0.002 | AB26: =Z26+AA26 -> 0.402 | AC26: 318 | AD26: 143 | AE26: 138 | AF26: 8 | AG26: 600000407 | AH26: =справочники!$C$106 -> 0.094 | AI26: =ROUNDDOWN(номин.вес_нетто__кг*кол_во_инд.__упак_к,2) -> 3.2 | AJ26: =(номин.вес_брутто__кг*кол_во_инд.__упак_к)+вес_короба__кг -> 3.31 | AK26: 19 | AL26: 11 | AM26: =AK26*AL26 -> 209 | AN26: =IF(D26="ШТ",кол_во_инд.__упак_к*итого_г_у,ROUNDDOWN(номин.вес_нетто_г_у__кг*итого_г_у,1)) -> 1672 | AO26: =(высота__мм*кол_во_слоев_г_у)+145 -> 1663
A27: =VALUE(RIGHT(B27,4)) -> 8014 | B27: 1001010108014 | C27: ДОКТОРСКАЯ ПРЕМИУМ п/о(п) | D27: КГ | E27: Колбасные изделия | F27: Вареные колбасы | G27: Папа может | H27: ОМПК(С) | I27: ТУ 10.13.14-130-00425283-2017 | J27: Мясной продукт. Изделие колбасное вареное категории Б. | K27: свинина, вода питьевая, мясо куриное механической обвалки, филе грудок куриных, стабилизатор белковый (вода питьевая, кожа куриная, шкурка свиная), сыворотка молочная сухая, крахмал картофельный, смесь посолочно-нитритная (соль, фиксатор окраски (нитрит натрия)), регуляторы кислотности (трифосфаты, пирофосфаты, ацетаты натрия), стабилизатор (альгинат натрия), сахара, пряности и экстракты пряностей (в т.ч. сельдерей), белок животный (говяжий), антиокислитель (аскорбиновая кислота), усилитель вкуса и аромата (глутамат натрия), ароматизаторы (в т.ч. горчица), краситель (кармины) | L27: 10 | M27: 19 | N27: 1 | O27: 215/890 | P27: 0…+6 | Q27: 60 | R27: 3 суток | S27: 2727916000006 | T27: 12727916000003 | U27: 4630362181190 | V27: 14630362181197 | W27: 250 | X27: 88 | Y27: 88 | Z27: 1.35 | AA27: 0.002 | AB27: =Z27+AA27 -> 1.352 | AC27: 292 | AD27: 178 | AE27: 178 | AF27: 4 | AG27: 600000029 | AH27: =справочники!$C$21 -> 0.125 | AI27: =ROUNDDOWN(номин.вес_нетто__кг*кол_во_инд.__упак_к,2) -> 5.4 | AJ27: =(номин.вес_брутто__кг*кол_во_инд.__упак_к)+вес_короба__кг -> 5.533 | AK27: 16 | AL27: 8 | AM27: =AK27*AL27 -> 128 | AN27: =IF(D27="ШТ",кол_во_инд.__упак_к*итого_г_у,ROUNDDOWN(номин.вес_нетто_г_у__кг*итого_г_у,1)) -> 691.2 | AO27: =(высота__мм*кол_во_слоев_г_у)+145 -> 1569
A28: =VALUE(RIGHT(B28,4)) -> 7602 | B28: 1001010117602 | C28: ДОКТОРСКАЯ ТРАДИЦ.ПМ вар ц/о в/у 0.6кг | D28: ШТ | E28: Колбасные изделия | F28: Вареные колбасы | G28: Папа может | H28: ОМПК(О) | I28: ТУ 10.13.14-150-00425283-2026 | J28: Изделие колбасное вареное из мяса кур охлажденное. | K28: филе грудок куриных, мясо куриное механической обвалки, свинина, стабилизатор белковый (вода питьевая, кожа куриная, шкурка свиная), вода питьевая, сыворотка молочная сухая, молоко сухое обезжиренное, крахмал картофельный, смесь посолочно-нитритная (соль, фиксатор окраски (нитрит натрия)), регуляторы кислотности (пирофосфаты, трифосфаты, цитрат натрия), загуститель (альгинат натрия), сахара, соль, пряности и экстракты пряностей, белок животный (говяжий), антиокислитель (аскорбиновая кислота), усилитель вкуса и аромата (глутамат натрия), ароматизаторы, краситель (кармины) | L28: 10 | M28: 15 | N28: 2 | O28: 183/759 | P28: 0…+6 | Q28: 45 | R28: 48 часов | S28: 4630362182357 | T28: 14630362182354 | U28: 4630362182357 | V28: 14630362182354 | W28: 210 | X28: 100 | Y28: 60 | Z28: 0.6 | AA28: 0.007 | AB28: =Z28+AA28 -> 0.607 | AC28: 230 | AD28: 216 | AE28: 138 | AF28: 6 | AG28: 600000390 | AH28: =справочники!$C$90 -> 0.147 | AI28: =ROUNDDOWN(номин.вес_нетто__кг*кол_во_инд.__упак_к,2) -> 3.6 | AJ28: =(номин.вес_брутто__кг*кол_во_инд.__упак_к)+вес_короба__кг -> 3.789 | AK28: 15 | AL28: 11 | AM28: =AK28*AL28 -> 165 | AN28: =IF(D28="ШТ",кол_во_инд.__упак_к*итого_г_у,ROUNDDOWN(номин.вес_нетто_г_у__кг*итого_г_у,1)) -> 990 | AO28: =(высота__мм*кол_во_слоев_г_у)+145 -> 1663
A29: =VALUE(RIGHT(B29,4)) -> 6861 | B29: 1001015646861 | C29: ДОМАШНИЙ РЕЦЕПТ Коровино вар п/о | D29: КГ | E29: Колбасные изделия | F29: Вареные колбасы | G29: Коровино | H29: ОМПК(С) | I29: ТУ 10.13.14-150-00425283-2018 | J29: Изделие колбасное вареное из мяса кур охлажденное. | K29: мясо куриное механической обвалки, белковый стабилизатор (вода, шкурка свиная, кожа куриная), вода, свинина, крахмал картофельный, сыворотка молочная сухая, смесь посолочно-нитритная (соль, фиксатор окраски нитрит натрия), пищевые волокна, соль, регуляторы кислотности: пирофосфаты, ацетаты натрия, глюконо-дельта-лактон; стабилизаторы: альгинат натрия, гуаровая и ксантановая камеди; сахара, молоко сухое обезжиренное, экстракты пряностей (в т.ч. горчица), загуститель конжаковая камедь, усилитель вкуса и аромата глутамат натрия, антиокислитель изоаскорбат натрия, ароматизаторы, краситель кармины | L29: 7 | M29: 16 | O29: 172/711 | P29: 0…+6 | Q29: 60 | R29: 3 суток | S29: 2100653000001 | T29: 12100653000008 | U29: 4630362181213 | V29: 14630362181210 | W29: 350 | X29: 97 | Y29: 97 | Z29: 1.95 | AA29: 0.005 | AB29: =Z29+AA29 -> 1.955 | AC29: 368 | AD29: 238 | AE29: 128 | AF29: 2 | AG29: 600000025 | AH29: =справочники!$C$17 -> 0.175 | AI29: =ROUNDDOWN(номин.вес_нетто__кг*кол_во_инд.__упак_к,2) -> 3.9 | AJ29: =(номин.вес_брутто__кг*кол_во_инд.__упак_к)+вес_короба__кг -> 4.085 | AK29: 10 | AL29: 12 | AM29: =AK29*AL29 -> 120 | AN29: =IF(D29="ШТ",кол_во_инд.__упак_к*итого_г_у,ROUNDDOWN(номин.вес_нетто_г_у__кг*итого_г_у,1)) -> 468 | AO29: =(высота__мм*кол_во_слоев_г_у)+145 -> 1681
A30: =VALUE(RIGHT(B30,4)) -> 6340 | B30: 1001012816340 | C30: ДОМАШНИЙ РЕЦЕПТ Коровино 0.5кг 8шт. | D30: ШТ | E30: Колбасные изделия | F30: Вареные колбасы | G30: Коровино | H30: ОМПК(С) | I30: ТУ 10.13.14-150-00425283-2018 | J30: Изделие колбасное вареное из мяса кур охлажденное. | K30: мясо куриное механической обвалки, белковый стабилизатор (вода, шкурка свиная, кожа куриная), вода, свинина, крахмал картофельный, сыворотка молочная сухая, смесь посолочно-нитритная (соль, фиксатор окраски нитрит натрия), пищевые волокна, соль, регуляторы кислотности: пирофосфаты, ацетаты натрия, глюконо-дельта-лактон; стабилизаторы: альгинат натрия, гуаровая и ксантановая камеди; сахара, молоко сухое обезжиренное, экстракты пряностей (в т.ч. горчица), загуститель конжаковая камедь, усилитель вкуса и аромата глутамат натрия, антиокислитель изоаскорбат натрия, ароматизаторы, краситель кармины | L30: 7 | M30: 16 | N30: 4 | O30: 188/779 | P30: 0…+6 | Q30: 60 | R30: 3 суток | S30: 4607958077816 | T30: 14607958077813 | U30: 4607958077816 | V30: 14607958077813 | W30: 190 | X30: 67 | Y30: 67 | Z30: 0.5 | AA30: 0.003 | AB30: =Z30+AA30 -> 0.503 | AC30: 278 | AD30: 193 | AE30: 138 | AF30: 8 | AG30: 600000404 | AH30: =справочники!$C$101 -> 0.105 | AI30: =ROUNDDOWN(номин.вес_нетто__кг*кол_во_инд.__упак_к,2) -> 4 | AJ30: =(номин.вес_брутто__кг*кол_во_инд.__упак_к)+вес_короба__кг -> 4.129 | AK30: 16 | AL30: 9 | AM30: =AK30*AL30 -> 144 | AN30: =IF(D30="ШТ",кол_во_инд.__упак_к*итого_г_у,ROUNDDOWN(номин.вес_нетто_г_у__кг*итого_г_у,1)) -> 1152 | AO30: =(высота__мм*кол_во_слоев_г_у)+145 -> 1387
A31: =VALUE(RIGHT(B31,4)) -> 6862 | B31: 1001015706862 | C31: ДОМАШНИЙ РЕЦЕПТ СО ШПИК.Коровино вар п/о | D31: КГ | E31: Колбасные изделия | F31: Вареные колбасы | G31: Коровино | H31: ОМПК(С) | I31: ТУ 10.13.14-150-00425283-2018 | J31: Изделие колбасное вареное из мяса кур охлажденное. | K31: мясо куриное механической обвалки, белковый стабилизатор (вода, шкурка свиная, кожа куриная), вода, шпик, свинина, крахмал картофельный, сыворотка молочная сухая, смесь посолочно-нитритная (соль, фиксатор окраски нитрит натрия), регуляторы кислотности: пирофосфаты, трифосфаты, ацетаты натрия, цитраты натрия, глюконо-дельта-лактон; стабилизатор альгинат натрия, экстракты пряностей, ароматизаторы, антиокислитель изоаскорбат натрия, усилитель вкуса и аромата глутамат натрия, горчица, чеснок, соль, сахар, красители: кармины, диоксид титана | L31: 9 | M31: 14 | N31: 3 | O31: 149/617 | P31: 0…+6 | Q31: 60 | R31: 3 суток | S31: 2800746000009 | T31: 12800746000006 | U31: 4630362181220 | V31: 14630362181227 | W31: 350 | X31: 97 | Y31: 97 | Z31: 1.95 | AA31: 0.005 | AB31: =Z31+AA31 -> 1.955 | AC31: 368 | AD31: 238 | AE31: 128 | AF31: 2 | AG31: 600000025 | AH31: =справочники!$C$17 -> 0.175 | AI31: =ROUNDDOWN(номин.вес_нетто__кг*кол_во_инд.__упак_к,2) -> 3.9 | AJ31: =(номин.вес_брутто__кг*кол_во_инд.__упак_к)+вес_короба__кг -> 4.085 | AK31: 10 | AL31: 12 | AM31: =AK31*AL31 -> 120 | AN31: =IF(D31="ШТ",кол_во_инд.__упак_к*итого_г_у,ROUNDDOWN(номин.вес_нетто_г_у__кг*итого_г_у,1)) -> 468 | AO31: =(высота__мм*кол_во_слоев_г_у)+145 -> 1681
A32: =VALUE(RIGHT(B32,4)) -> 6341 | B32: 1001012816341 | C32: ДОМАШНИЙ РЕЦЕПТ СО ШПИКОМ Коровино 0.5кг | D32: ШТ | E32: Колбасные изделия | F32: Вареные колбасы | G32: Коровино | H32: ОМПК(С) | I32: ТУ 10.13.14-150-00425283-2018 | J32: Изделие колбасное вареное из мяса кур охлажденное. | K32: мясо куриное механической обвалки, белковый стабилизатор (вода, шкурка свиная, кожа куриная), вода, шпик, свинина, крахмал картофельный, сыворотка молочная сухая, смесь посолочно-нитритная (соль, фиксатор окраски нитрит натрия), регуляторы кислотности: пирофосфаты, трифосфаты, ацетаты натрия, цитраты натрия, глюконо-дельта-лактон; стабилизатор альгинат натрия, экстракты пряностей, ароматизаторы, антиокислитель изоаскорбат натрия, усилитель вкуса и аромата глутамат натрия, горчица, чеснок, соль, сахар, красители: кармины, диоксид титана | L32: 9 | M32: 14 | N32: 3 | O32: 149/617 | P32: 0…+6 | Q32: 60 | R32: 3 суток | S32: 4607958077823 | T32: 14607958077820 | U32: 4607958077823 | V32: 14607958077820 | W32: 190 | X32: 67 | Y32: 67 | Z32: 0.5 | AA32: 0.003 | AB32: =Z32+AA32 -> 0.503 | AC32: 278 | AD32: 193 | AE32: 138 | AF32: 8 | AG32: 600000404 | AH32: =справочники!$C$101 -> 0.105 | AI32: =ROUNDDOWN(номин.вес_нетто__кг*кол_во_инд.__упак_к,2) -> 4 | AJ32: =(номин.вес_брутто__кг*кол_во_инд.__упак_к)+вес_короба__кг -> 4.129 | AK32: 16 | AL32: 9 | AM32: =AK32*AL32 -> 144 | AN32: =IF(D32="ШТ",кол_во_инд.__упак_к*итого_г_у,ROUNDDOWN(номин.вес_нетто_г_у__кг*итого_г_у,1)) -> 1152 | AO32: =(высота__мм*кол_во_слоев_г_у)+145 -> 1387
A33: =VALUE(RIGHT(B33,4)) -> 6841 | B33: 1001011086841 | C33: ДОМАШНЯЯ Папа может вар н/о мгс 1*3 | D33: КГ | E33: Колбасные изделия | F33: Вареные колбасы | G33: Папа может | H33: ОМПК(О) | I33: ТУ 10.13.14-180-00425283-2025 | J33: Мясной продукт. Изделие колбасное вареное категории Б. | K33: свинина, вода питьевая, мясо куриное механической обвалки, шпик, стабилизатор белковый (вода питьевая, шкурка свиная), говядина, сыворотка молочная сухая, смесь посолочно-нитритная (соль, фиксатор окраски (нитрит натрия)), регуляторы кислотности (пирофосфаты, трифосфаты, цитраты натрия), загустители (каррагинан, гуаровая камедь, ксантановая камедь, камедь рожкового дерева, камедь тары), белок животный (говяжий), соль, сахара, специи, экстракты специй (в т.ч. горчица), антиокислители (аскорбиновая кислота), усилитель вкуса и аромата (глутамат натрия), краситель (кармины) | L33: 10 | M33: 26 | N33: 4 | O33: 290/1200 | P33: 0…+6 | Q33: 30 | R33: 72 часа | S33: 2100375000006 | T33: 12100375000003 | U33: 4630362181237 | V33: 14630362181234 | W33: 300 | X33: 190 | Y33: 80 | Z33: 1.05 | AA33: 0.014 | AB33: =Z33+AA33 -> 1.064 | AC33: 292 | AD33: 178 | AE33: 178 | AF33: 3 | AG33: 600000029 | AH33: =справочники!$C$21 -> 0.125 | AI33: =ROUNDDOWN(номин.вес_нетто__кг*кол_во_инд.__упак_к,2) -> 3.15 | AJ33: =(номин.вес_брутто__кг*кол_во_инд.__упак_к)+вес_короба__кг -> 3.317 | AK33: 16 | AL33: 8 | AM33: =AK33*AL33 -> 128 | AN33: =IF(D33="ШТ",кол_во_инд.__упак_к*итого_г_у,ROUNDDOWN(номин.вес_нетто_г_у__кг*итого_г_у,1)) -> 403.2 | AO33: =(высота__мм*кол_во_слоев_г_у)+145 -> 1569
A34: =VALUE(RIGHT(B34,4)) -> 7512 | B34: 1001016997512 | C34: ЧАЙНАЯ Останкино вар н/о мгс 1*3 | D34: КГ | E34: Колбасные изделия | F34: Вареные колбасы | G34: Останкино | H34: ОМПК(Г) | I34: ТУ 10.13.14-180-00425283-2025 | J34: Мясной продукт. Изделие колбасное вареное категории Б. | K34: свинина, вода питьевая, мясо куриное механической обвалки, шпик, стабилизатор белковый (вода питьевая, шкурка свиная), говядина, сыворотка молочная сухая, смесь посолочно-нитритная (соль, фиксатор окраски (нитрит натрия)), регуляторы кислотности (пирофосфаты, трифосфаты, цитраты натрия), загустители (каррагинан, гуаровая камедь, ксантановая камедь, камедь рожкового дерева, камедь тары), белок животный (говяжий), соль, сахара, специи, экстракты специй (в т.ч. горчица), антиокислители (аскорбиновая кислота), усилитель вкуса и аромата (глутамат натрия), краситель (кармины) | L34: 10 | M34: 26 | N34: 4 | O34: 290/1200 | P34: 0…+6 | Q34: 30 | R34: 72 часа | S34: 2800031000004 | T34: 12800031000001 | U34: 4630362182661 | V34: 14630362182668 | W34: 300 | X34: 190 | Y34: 80 | Z34: 1 | AA34: 0.014 | AB34: =Z34+AA34 -> 1.014 | AC34: 292 | AD34: 178 | AE34: 178 | AF34: 3 | AG34: 600000029 | AH34: =справочники!$C$21 -> 0.125 | AI34: =ROUNDDOWN(номин.вес_нетто__кг*кол_во_инд.__упак_к,2) -> 3 | AJ34: =(номин.вес_брутто__кг*кол_во_инд.__упак_к)+вес_короба__кг -> 3.167 | AK34: 16 | AL34: 8 | AM34: =AK34*AL34 -> 128 | AN34: =IF(D34="ШТ",кол_во_инд.__упак_к*итого_г_у,ROUNDDOWN(номин.вес_нетто_г_у__кг*итого_г_у,1)) -> 384 | AO34: =(высота__мм*кол_во_слоев_г_у)+145 -> 1569
A35: =VALUE(RIGHT(B35,4)) -> 3214 | B35: 1001013643214 | C35: К ЧАЮ вар н/о мгс 1*3 | D35: КГ | E35: Колбасные изделия | F35: Вареные колбасы | G35: Папа может | H35: ОМПК(Г) | I35: ТУ 10.13.14-180-00425283-2025 | J35: Мясной продукт. Изделие колбасное вареное категории Б. | K35: свинина, вода питьевая, мясо куриное механической обвалки, шпик, стабилизатор белковый (вода питьевая, шкурка свиная), говядина, сыворотка молочная сухая, смесь посолочно-нитритная (соль, фиксатор окраски (нитрит натрия)), регуляторы кислотности (пирофосфаты, трифосфаты, цитраты натрия), загустители (каррагинан, гуаровая камедь, ксантановая камедь, камедь рожкового дерева, камедь тары), белок животный (говяжий), соль, сахара, специи, экстракты специй (в т.ч. горчица), антиокислители (аскорбиновая кислота), усилитель вкуса и аромата (глутамат натрия), краситель (кармины) | L35: 10 | M35: 26 | N35: 4 | O35: 290/1200 | P35: 0…+6 | Q35: 30 | R35: 72 часа | S35: 2800845000009 | T35: 12800845000006 | W35: 300 | X35: 190 | Y35: 80 | Z35: 1 | AA35: 0.014 | AB35: =Z35+AA35 -> 1.014 | AC35: 292 | AD35: 178 | AE35: 178 | AF35: 3 | AG35: 600000029 | AH35: =справочники!$C$21 -> 0.125 | AI35: =ROUNDDOWN(номин.вес_нетто__кг*кол_во_инд.__упак_к,2) -> 3 | AJ35: =(номин.вес_брутто__кг*кол_во_инд.__упак_к)+вес_короба__кг -> 3.167 | AK35: 16 | AL35: 8 | AM35: =AK35*AL35 -> 128 | AN35: =IF(D35="ШТ",кол_во_инд.__упак_к*итого_г_у,ROUNDDOWN(номин.вес_нетто_г_у__кг*итого_г_у,1)) -> 384 | AO35: =(высота__мм*кол_во_слоев_г_у)+145 -> 1569
A36: =VALUE(RIGHT(B36,4)) -> 6247 | B36: 1001011086247 | C36: ДОМАШНЯЯ Папа может вар п/о 0.4кг 8шт. | D36: ШТ | E36: Колбасные изделия | F36: Вареные колбасы | G36: Папа может | H36: ОМПК(С) | I36: ТУ 10.13.14-180-00425283-2025 | J36: Мясной продукт. Изделие колбасное вареное категории В. | K36: свинина, стабилизатор белковый (кожа куриная, вода питьевая, шкурка свиная), вода питьевая, филе грудок куриных, сыворотка молочная сухая, крахмал картофельный, смесь посолочно-нитритная (соль, фиксатор окраски (нитрит натрия)), регуляторы кислотности (пирофосфаты, трифосфаты, цитраты натрия), загустители (каррагинан, гуаровая камедь, ксантановая камедь, альгинат натрия), специи (в т.ч. горчица, сельдерей), сахара, антиокислитель (аскорбиновая кислота), усилитель вкуса и аромата (глутамат натрия), краситель (кармины) | L36: 10 | M36: 11 | N36: 5 | O36: 159/662 | P36: 0…+6 | Q36: 60 | R36: 72 часа | S36: 4607958076321 | T36: 14607958076328 | U36: 4607958076321 | V36: 14607958076328 | W36: 160 | X36: 67 | Y36: 67 | Z36: 0.4 | AA36: 0.002 | AB36: =Z36+AA36 -> 0.402 | AC36: 318 | AD36: 143 | AE36: 138 | AF36: 8 | AG36: 600000407 | AH36: =справочники!$C$106 -> 0.094 | AI36: =ROUNDDOWN(номин.вес_нетто__кг*кол_во_инд.__упак_к,2) -> 3.2 | AJ36: =(номин.вес_брутто__кг*кол_во_инд.__упак_к)+вес_короба__кг -> 3.31 | AK36: 19 | AL36: 11 | AM36: =AK36*AL36 -> 209 | AN36: =IF(D36="ШТ",кол_во_инд.__упак_к*итого_г_у,ROUNDDOWN(номин.вес_нетто_г_у__кг*итого_г_у,1)) -> 1672 | AO36: =(высота__мм*кол_во_слоев_г_у)+145 -> 1663
A37: =VALUE(RIGHT(B37,4)) -> 6859 | B37: 1001013956859 | C37: КЛАССИЧЕСКАЯ Коровино вар п/о(обвязка) | D37: КГ | E37: Колбасные изделия | F37: Вареные колбасы | G37: Коровино | H37: ОМПК(С) | I37: ТУ 10.13.14-150-00425283-2018 | J37: Изделие колбасное вареное из мяса кур охлажденное высшего сорта. | K37: мясо куриное механической обвалки, белковый стабилизатор (свиная шкурка, вода), свинина, вода, крахмал картофельный, соль, посолочно-нитритная смесь (соль, фиксатор окраски нитрит натрия), стабилизаторы: альгинат натрия, каррагинан из водорослей EUCHEMA, камедь гуаровая, растительная клетчатка, регуляторы кислотности: пирофосфаты, ацетаты натрия; натуральные пряности, сахар, усилитель вкуса и аромата Е621, антиокислитель изоаскорбат натрия, ароматизаторы, краситель кармины | L37: 13 | M37: 15 | O37: 187/776 | P37: 0…+6 | Q37: 60 | R37: 3 суток | S37: 2100315000004 | T37: 12100315000001 | U37: 4630362181244 | V37: 14630362181241 | W37: 260 | X37: 90 | Y37: 90 | Z37: 1.35 | AA37: 0.005 | AB37: =Z37+AA37 -> 1.355 | AC37: 385 | AD37: 285 | AE37: 185 | AF37: 8 | AG37: 600000290 | AH37: =справочники!$C$59 -> 0.352 | AI37: =ROUNDDOWN(номин.вес_нетто__кг*кол_во_инд.__упак_к,2) -> 10.8 | AJ37: =(номин.вес_брутто__кг*кол_во_инд.__упак_к)+вес_короба__кг -> 11.192 | AK37: 8 | AL37: 8 | AM37: =AK37*AL37 -> 64 | AN37: =IF(D37="ШТ",кол_во_инд.__упак_к*итого_г_у,ROUNDDOWN(номин.вес_нетто_г_у__кг*итого_г_у,1)) -> 691.2 | AO37: =(высота__мм*кол_во_слоев_г_у)+145 -> 1625
A38: =VALUE(RIGHT(B38,4)) -> 7572 | B38: 1001013957572 | C38: КЛАССИЧЕСКАЯ Кор вар п/о(обвязка) 1.35*8 | D38: КГ | E38: Колбасные изделия | F38: Вареные колбасы | G38: Коровино | H38: ОМПК(С) | I38: ТУ 10.13.14-150-00425283-2018 | J38: Изделие колбасное вареное из мяса кур охлажденное высшего сорта. | K38: мясо куриное механической обвалки, белковый стабилизатор (свиная шкурка, вода), свинина, вода, крахмал картофельный, соль, посолочно-нитритная смесь (соль, фиксатор окраски нитрит натрия), стабилизаторы: альгинат натрия, каррагинан из водорослей EUCHEMA, камедь гуаровая, растительная клетчатка, регуляторы кислотности: пирофосфаты, ацетаты натрия; натуральные пряности, сахар, усилитель вкуса и аромата Е621, антиокислитель изоаскорбат натрия, ароматизаторы, краситель кармины | L38: 13 | M38: 15 | O38: 187/776 | P38: 0…+6 | Q38: 60 | R38: 3 суток | S38: 2100315000004 | T38: 12100315000001 | U38: 4630362181244 | V38: 14630362181241 | W38: 260 | X38: 90 | Y38: 90 | Z38: 1.35 | AA38: 0.005 | AB38: =Z38+AA38 -> 1.355 | AC38: 293 | AD38: 394 | AE38: 158 | AF38: 8 | AG38: 600000607 | AH38: =справочники!$C$195 -> 0.236 | AI38: =ROUNDDOWN(номин.вес_нетто__кг*кол_во_инд.__упак_к,2) -> 10.8 | AJ38: =(номин.вес_брутто__кг*кол_во_инд.__упак_к)+вес_короба__кг -> 11.076 | AK38: 8 | AL38: 9 | AM38: =AK38*AL38 -> 72 | AN38: =IF(D38="ШТ",кол_во_инд.__упак_к*итого_г_у,ROUNDDOWN(номин.вес_нетто_г_у__кг*итого_г_у,1)) -> 777.6 | AO38: =(высота__мм*кол_во_слоев_г_у)+145 -> 1567
A39: =VALUE(RIGHT(B39,4)) -> 6860 | B39: 1001013956860 | C39: КЛАССИЧЕСКАЯ Коровино вар п/о(обвязка)_М | D39: КГ | E39: Колбасные изделия | F39: Вареные колбасы | G39: Коровино | H39: ОМПК(С) | I39: ТУ 10.13.14-150-00425283-2018 | J39: Изделие колбасное вареное из мяса кур охлажденное высшего сорта. | K39: мясо куриное механической обвалки, белковый стабилизатор (свиная шкурка, вода), свинина, вода, крахмал картофельный, соль, посолочно-нитритная смесь (соль, фиксатор окраски нитрит натрия), стабилизаторы: альгинат натрия, каррагинан из водорослей EUCHEMA, камедь гуаровая, растительная клетчатка, регуляторы кислотности: пирофосфаты, ацетаты натрия; натуральные пряности, сахар, усилитель вкуса и аромата Е621, антиокислитель изоаскорбат натрия, ароматизаторы, краситель кармины | L39: 13 | M39: 15 | O39: 187/776 | P39: 0…+6 | Q39: 60 | R39: 3 суток | S39: 2101947000004 | T39: 12101947000001 | U39: 4630362181244 | V39: 14630362181241 | W39: 260 | X39: 90 | Y39: 90 | Z39: 1.35 | AA39: 0.005 | AB39: =Z39+AA39 -> 1.355 | AC39: 385 | AD39: 285 | AE39: 185 | AF39: 8 | AG39: 600000290 | AH39: =справочники!$C$59 -> 0.352 | AI39: =ROUNDDOWN(номин.вес_нетто__кг*кол_во_инд.__упак_к,2) -> 10.8 | AJ39: =(номин.вес_брутто__кг*кол_во_инд.__упак_к)+вес_короба__кг -> 11.192 | AK39: 8 | AL39: 8 | AM39: =AK39*AL39 -> 64 | AN39: =IF(D39="ШТ",кол_во_инд.__упак_к*итого_г_у,ROUNDDOWN(номин.вес_нетто_г_у__кг*итого_г_у,1)) -> 691.2 | AO39: =(высота__мм*кол_во_слоев_г_у)+145 -> 1625
A40: =VALUE(RIGHT(B40,4)) -> 7571 | B40: 1001013957571 | C40: КЛАССИЧЕСКАЯ Кор вар п/о(обвязка) 1.35_М | D40: КГ | E40: Колбасные изделия | F40: Вареные колбасы | G40: Коровино | H40: ОМПК(С) | I40: ТУ 10.13.14-150-00425283-2018 | J40: Изделие колбасное вареное из мяса кур охлажденное высшего сорта. | K40: мясо куриное механической обвалки, белковый стабилизатор (свиная шкурка, вода), свинина, вода, крахмал картофельный, соль, посолочно-нитритная смесь (соль, фиксатор окраски нитрит натрия), стабилизаторы: альгинат натрия, каррагинан из водорослей EUCHEMA, камедь гуаровая, растительная клетчатка, регуляторы кислотности: пирофосфаты, ацетаты натрия; натуральные пряности, сахар, усилитель вкуса и аромата Е621, антиокислитель изоаскорбат натрия, ароматизаторы, краситель кармины | L40: 13 | M40: 15 | O40: 187/776 | P40: 0…+6 | Q40: 60 | R40: 3 суток | S40: 2101947000004 | T40: 12101947000001 | U40: 4630362181244 | V40: 14630362181241 | W40: 260 | X40: 90 | Y40: 90 | Z40: 1.35 | AA40: 0.005 | AB40: =Z40+AA40 -> 1.355 | AC40: 293 | AD40: 394 | AE40: 158 | AF40: 8 | AG40: 600000607 | AH40: =справочники!$C$195 -> 0.236 | AI40: =ROUNDDOWN(номин.вес_нетто__кг*кол_во_инд.__упак_к,2) -> 10.8 | AJ40: =(номин.вес_брутто__кг*кол_во_инд.__упак_к)+вес_короба__кг -> 11.076 | AK40: 8 | AL40: 9 | AM40: =AK40*AL40 -> 72 | AN40: =IF(D40="ШТ",кол_во_инд.__упак_к*итого_г_у,ROUNDDOWN(номин.вес_нетто_г_у__кг*итого_г_у,1)) -> 777.6 | AO40: =(высота__мм*кол_во_слоев_г_у)+145 -> 1567
...

Sheet справочники
A1: Код короба SAP | B1: Наименование короба SAP | C1: Масса нетто короба SAP, кг | F1: Статус | K1: Номер ГОСТ/ТУ | N1: Номер ГОСТ/ТУ | O1: Группа / категория | Q1: Условия хранения | T1: EAN-13 | W1: ITF-14
A2: 600000010 | B2: Кор 380х250х180 П32СЕ Останкино №101 | C2: 0.339 | K2: ГОСТ 31785-2012 | N2: ГОСТ 31785-2012 | O2: Мясной продукт. Изделие колбасное полукопченое категории Б. | Q2: 0…+4 | S2: 1 | T2: 4630362183170 | U2: =CONCATENATE(S2,T2) -> 14630362183170 | V2: =LEFT(U2,13) -> 1463036218317 | W2: =V2*10+MOD(10-MOD(3*(MID(V2,1,1)+MID(V2,3,1)+MID(V2,5,1)+MID(V2,7,1)+MID(V2,9,1)+MID(V2,11,1)+MID(V2,13,1))+MID(V2,2,1)+MID(V2,4,1)+MID(V2,6,1)+MID(V2,8,1)+MID(V2,10,1)+MID(V2,12,1),10),10) -> 14630362183177
A3: 600000011 | B3: Кор N 103 (370х148х355)(0.225) бур.ОстN | F3: блок 24.01.24 | K3: ГОСТ 32125-2013 | N3: ГОСТ 31785-2012 | O3: Мясной продукт. Изделие колбасное полукопченое категории В. | Q3: 0…+6
A4: 600000012 | B4: Кор 380х282х232 П32СЕ Останкино №104 | F4: блок 24.01.24 | K4: ГОСТ 32244-2013 | N4: ГОСТ 32125-2013 | O4: Консервы мясные кусковые стерилизованные. | Q4: 0…+12
A5: 600000013 | B5: Кор 380х185х100 Т24С Останкино №106 | C5: 0.141 | K5: ГОСТ 23670-2019 | N5: ГОСТ 32244-2013 | O5: Субпродукт свиной замороженный мякотный. | Q5: 0…+20
