Workbook

Sheet Sheet
A3: Номенклатура | B3: Ед. изм. | C3: Начальный остаток | D3: Приход | E3: Расход | F3: Конечный остаток | G3: крат | H3: сроки | I3: метка | J3: метка2 | K3: заяв | L3: разн | M3: без опта | N3: опт | O3: заказ в пути | P3: ср нов | Q3: итого | R3: заказ | S3: кон ост | T3: факт | U3: ср | V3: ср | W3: ср | X3: ср | Y3: ср | Z3: ср | AA3: комментарии | AB3: вес
O4: 06,07, | P4: 07,07, | R4: 13,07, | U4: 26,01, | V4: 22,06, | W4: 15,06, | X4: 08,06, | Y4: 01,06, | Z4: 25,05,
E5: =SUM(E6:E500) -> 4216.796 | F5: =SUM(F6:F500) -> 11893.195 | K5: =SUM(K6:K500) -> 5048.136 | L5: =SUM(L6:L500) -> -831.34 | M5: =SUM(M6:M500) -> 0 | N5: =SUM(N6:N500) -> 0 | O5: =SUM(O6:O500) -> 4890 | P5: =SUM(P6:P500) -> 843.3592 | Q5: =SUM(Q6:Q500) -> 4175.2442 | R5: =SUM(R6:R500) -> 4177 | U5: =SUM(U6:U500) -> 765.104 | V5: =SUM(V6:V500) -> 655.5092 | W5: =SUM(W6:W500) -> 702.9154 | X5: =SUM(X6:X500) -> 878.7988 | Y5: =SUM(Y6:Y500) -> 528.0228 | Z5: =SUM(Z6:Z500) -> 881.3042 | AB5: =SUM(AB6:AB500) -> 1662.0442
A6: 3323 Сыр Российский цилиндр 1/4 пленка ЮКМП м.д.ж. 50% ОСТАНКИНО | B6: кг | C6: 241.624 | D6: 116.008 | E6: =66.038+E28+E48 -> 68.162 | F6: =278.288+F28+F48 -> 272.548 | G6: 1 | K6: 75.93 | L6: =E6-K6 -> -7.768 | P6: =E6/5 -> 13.6324 | S6: =(F6+O6+Q6)/P6 -> 19.992665 | T6: =(F6+O6)/P6 -> 19.992665 | U6: 9.0016 | V6: 20.4348 | W6: 20.4616 | X6: 14.24 | Y6: 16.4594 | Z6: 5.854 | AA6: нужно увеличить продажи | AB6: =G6*Q6 -> 0
A7: 4421577 Спред растительно-сливочный "Сливочный вкус" 82,5% 180гр Останкино | B7: шт | C7: 191 | D7: 168 | E7: 23 | F7: 324 | G7: 0.18 | K7: 33 | L7: =E7-K7 -> -10 | P7: =E7/5 -> 4.6 | S7: =(F7+O7+Q7)/P7 -> 70.434783 | T7: =(F7+O7)/P7 -> 70.434783 | U7: 6.8 | V7: 6.6 | W7: 7.4 | X7: 1 | Y7: 0 | Z7: 62 | AA7: нужно увеличить продажи!!! | AB7: =G7*Q7 -> 0
A8: 4421584 Спред растительно-сливочный "Сливочный вкус" 72,5% 180гр Останкино | B8: шт | C8: 228 | D8: 156 | E8: 36 | F8: 339 | G8: 0.18 | K8: 45 | L8: =E8-K8 -> -9 | P8: =E8/5 -> 7.2 | S8: =(F8+O8+Q8)/P8 -> 47.083333 | T8: =(F8+O8)/P8 -> 47.083333 | U8: 8 | V8: 4.4 | W8: 11.2 | X8: 9.2 | Y8: 5.6 | Z8: 81 | AA8: нужно увеличить продажи!!! | AB8: =G8*Q8 -> 0
A9: 4931 Сыр полутвердый "Купеческий" с ароматом топленого молока, с м.д.ж. 50% ОСТАНКИНО | B9: кг | C9: 50.47 | D9: 3.304 | E9: 30.588 | F9: 23.186 | G9: 1 | K9: 30 | L9: =E9-K9 -> 0.588 | O9: 66 | P9: =E9/5 -> 6.1176 | Q9: =20*P9-O9-F9 -> 33.166 | R9: =VLOOKUP(A9,заказ!A:B,2,0) -> 33 | S9: =(F9+O9+Q9)/P9 -> 20 | T9: =(F9+O9)/P9 -> 14.578593 | U9: 5.7628 | V9: 5.9208 | W9: 6.5168 | X9: 0.6144 | Y9: 0 | Z9: 0 | AB9: =G9*Q9 -> 33.166
A10: 6948249 Майонезный соус провансаль 824,5гр деликатес.с массовой долей жирн.25% Коровино Останкино | B10: шт | C10: 160 | E10: 14 | F10: 146 | G10: 0.8245 | H10: 180 | K10: 12 | L10: =E10-K10 -> 2 | P10: =E10/5 -> 2.8 | S10: =(F10+O10+Q10)/P10 -> 52.142857 | T10: =(F10+O10)/P10 -> 52.142857 | U10: 3.8 | V10: 1.6 | W10: 3.8 | X10: 2.2 | Y10: 1 | Z10: 7.6 | AA10: нужно увеличить продажи!!! | AB10: =G10*Q10 -> 0
A11: 6948256 Майонез провансаль классич.оливковый Папа может 372гр с массовой долей жирн. 67% Останкино | B11: шт | C11: 516 | D11: 9 | E11: 203 | F11: 315 | G11: 0.372 | H11: 180 | K11: 209 | L11: =E11-K11 -> -6 | O11: 72 | P11: =E11/5 -> 40.6 | Q11: =20*P11-O11-F11 -> 425 | R11: =VLOOKUP(A11,заказ!A:B,2,0) -> 420 | S11: =(F11+O11+Q11)/P11 -> 20 | T11: =(F11+O11)/P11 -> 9.5320197 | U11: 29.2 | V11: 21 | W11: 20.6 | X11: 44.4 | Y11: 21.8 | Z11: 32.2 | AB11: =G11*Q11 -> 158.1
A12: 6948263 Майонез провансаль классич.оливковый Папа может 744гр с массовой долей жирн. 67% Останкино | B12: шт | C12: 180 | D12: 105 | E12: 151 | F12: 127 | G12: 0.744 | H12: 180 | K12: 158 | L12: =E12-K12 -> -7 | O12: 204 | P12: =E12/5 -> 30.2 | Q12: =20*P12-O12-F12 -> 273 | R12: =VLOOKUP(A12,заказ!A:B,2,0) -> 276 | S12: =(F12+O12+Q12)/P12 -> 20 | T12: =(F12+O12)/P12 -> 10.960265 | U12: 24 | V12: 20 | W12: 19 | X12: 23.4 | Y12: 21.2 | Z12: 6.2 | AB12: =G12*Q12 -> 203.112
A13: 6948270 Майонез провансаль классич.Папа может 372гр с массовой долей жирн. 67% Останкино | B13: шт | C13: 596 | D13: 45 | E13: 419 | F13: 204 | G13: 0.372 | H13: 180 | K13: 422 | L13: =E13-K13 -> -3 | O13: 804 | P13: =E13/5 -> 83.8 | Q13: =20*P13-O13-F13 -> 668 | R13: =VLOOKUP(A13,заказ!A:B,2,0) -> 672 | S13: =(F13+O13+Q13)/P13 -> 20 | T13: =(F13+O13)/P13 -> 12.02864 | U13: 64.8 | V13: 50 | W13: 61.2 | X13: 70.8 | Y13: 48 | Z13: 54.4 | AB13: =G13*Q13 -> 248.496
A14: 6948287 Майонез провансаль классич.Папа может 744гр с массовой долей жирн. 67% Останкино | B14: шт | C14: 602 | D14: 21 | E14: 353 | F14: 241 | G14: 0.744 | H14: 180 | K14: 374 | L14: =E14-K14 -> -21 | O14: 348 | P14: =E14/5 -> 70.6 | Q14: =20*P14-O14-F14 -> 823 | R14: =VLOOKUP(A14,заказ!A:B,2,0) -> 828 | S14: =(F14+O14+Q14)/P14 -> 20 | T14: =(F14+O14)/P14 -> 8.3427762 | U14: 39.8 | V14: 36.4 | W14: 48.8 | X14: 39 | Y14: 32.2 | Z14: 31 | AB14: =G14*Q14 -> 612.312
A15: 9988421 Творожный Сыр 60 % С маринованными огурчиками и укропом Останкино | B15: шт | C15: 119 | D15: 6 | E15: 17 | F15: 102 | G15: 0.14 | K15: 23 | L15: =E15-K15 -> -6 | P15: =E15/5 -> 3.4 | S15: =(F15+O15+Q15)/P15 -> 30 | T15: =(F15+O15)/P15 -> 30 | U15: 1.6 | V15: 3.8 | W15: 0.4 | X15: 2.2 | Y15: 3.4 | Z15: 1.4 | AA15: нужно увеличить продажи!!! | AB15: =G15*Q15 -> 0
A16: 9988438 Плавленый Сыр 45% "С ветчиной" СТМ"ПапаМожет" 180гр Останкино | B16: шт | C16: -1 | D16: 1 | G16: 0.18 | K16: 16 | L16: =E16-K16 -> -16 | O16: 32 | P16: =E16/5 -> 0 | S16: =(F16+O16+Q16)/P16 -> #DIV/0! | T16: =(F16+O16)/P16 -> #DIV/0! | U16: -0.4 | V16: 0 | W16: 0 | X16: 0 | Y16: 0 | Z16: 0 | AB16: =G16*Q16 -> 0
A17: 9988445 Плавленый Сыр 45%"С грибами" СТМ"ПапаМожет" 180 гр Останкино | B17: шт | C17: 127 | D17: 6 | E17: 37 | F17: 92 | G17: 0.18 | H17: 270 | K17: 41 | L17: =E17-K17 -> -4 | O17: 16 | P17: =E17/5 -> 7.4 | Q17: =20*P17-O17-F17 -> 40 | R17: =VLOOKUP(A17,заказ!A:B,2,0) -> 32 | S17: =(F17+O17+Q17)/P17 -> 20 | T17: =(F17+O17)/P17 -> 14.594595 | U17: 7.2 | V17: 8.4 | W17: 8.8 | X17: 12 | Y17: 11 | Z17: 10.8 | AB17: =G17*Q17 -> 7.2
A18: Cыр Перлини со вкусом Васаби 40% 100гр (8шт) Останкино | B18: шт | C18: 109 | D18: 17 | E18: 32 | F18: 75 | G18: 0.1 | K18: 47 | L18: =E18-K18 -> -15 | P18: =E18/5 -> 6.4 | Q18: =20*P18-O18-F18 -> 53 | R18: =VLOOKUP(A18,заказ!A:B,2,0) -> 56 | S18: =(F18+O18+Q18)/P18 -> 20 | T18: =(F18+O18)/P18 -> 11.71875 | U18: 2.8 | V18: 5.4 | W18: 8.6 | X18: 9 | Y18: 5.2 | Z18: 11.6 | AB18: =G18*Q18 -> 5.3
A19: А_Сыр Боккончини копченый 40% 100 гр. ОСТАНКИНО | B19: шт | C19: 10 | F19: 10 | G19: 0 | I19: акция | L19: =E19-K19 -> 0 | P19: =E19/5 -> 0 | S19: =(F19+O19+Q19)/P19 -> #DIV/0! | T19: =(F19+O19)/P19 -> #DIV/0! | U19: 0 | V19: 2 | W19: 0 | X19: 0 | Y19: 0 | Z19: 0
A20: Масло "Папа может" 82,5% 180гр Останкино | B20: шт | C20: -7 | D20: 1525 | E20: 187 | F20: 1324 | G20: 0.18 | H20: 120 | K20: 307 | L20: =E20-K20 -> -120 | P20: =E20/5 -> 37.4 | S20: =(F20+O20+Q20)/P20 -> 35.40107 | T20: =(F20+O20)/P20 -> 35.40107 | U20: 18.4 | V20: 80.8 | W20: 1.4 | X20: 32 | Y20: 35.2 | Z20: 41 | AB20: =G20*Q20 -> 0
A21: Масло сливочное 72,5 % 180 гр.(10 шт) СЛАВЯНА Останкино | B21: шт | C21: 2629 | D21: 25 | E21: 633 | F21: 1983 | G21: 0.18 | H21: 120 | K21: 654 | L21: =E21-K21 -> -21 | O21: 150 | P21: =E21/5 -> 126.6 | Q21: =20*P21-O21-F21 -> 399 | R21: =VLOOKUP(A21,заказ!A:B,2,0) -> 400 | S21: =(F21+O21+Q21)/P21 -> 20 | T21: =(F21+O21)/P21 -> 16.848341 | U21: 138.8 | V21: 42 | W21: 156 | X21: 193.8 | Y21: 94.6 | Z21: 137.6 | AB21: =G21*Q21 -> 71.82
A22: Плавленый Сыр колбасный копченый 40% СТМ"ПапаМожет"400гр Останкино | B22: шт | C22: 45 | F22: 45 | G22: 0.4 | H22: 270 | L22: =E22-K22 -> 0 | P22: =E22/5 -> 0 | S22: =(F22+O22+Q22)/P22 -> #DIV/0! | T22: =(F22+O22)/P22 -> #DIV/0! | U22: 2.2 | V22: 0.8 | W22: 2.8 | X22: 0.6 | Y22: 0.6 | Z22: 0.4 | AA22: нужно увеличить продажи!!! | AB22: =G22*Q22 -> 0
A23: Плавленый продукт с Сыром колбасный копченый 40% СТМ "Коровино" 400гр Останкино | B23: шт | C23: 89 | D23: 2 | F23: 91 | G23: 0.4 | H23: 270 | L23: =E23-K23 -> 0 | P23: =E23/5 -> 0 | S23: =(F23+O23+Q23)/P23 -> #DIV/0! | T23: =(F23+O23)/P23 -> #DIV/0! | U23: 0 | V23: 0.2 | W23: 0.2 | X23: 0.2 | Y23: 0 | Z23: 1 | AA23: нужно увеличить продажи!!! | AB23: =G23*Q23 -> 0
A24: Плавленый сыр "Шоколадный" 30% 180гр Папа Может Останкино | B24: шт | C24: 215 | D24: 1 | E24: 9 | F24: 207 | G24: 0.18 | K24: 9 | L24: =E24-K24 -> 0 | P24: =E24/5 -> 1.8 | S24: =(F24+O24+Q24)/P24 -> 115 | T24: =(F24+O24)/P24 -> 115 | U24: 1 | V24: 1 | W24: 1.4 | X24: 0.6 | Y24: 3.2 | Z24: 3.6 | AA24: нужно увеличить продажи!!! | AB24: =G24*Q24 -> 0
A25: Продукт По-Росийски Классический с ЗМЖ 50% 200г Коровино Останкино | B25: шт | C25: 27 | F25: 27 | G25: 0.2 | L25: =E25-K25 -> 0 | P25: =E25/5 -> 0 | S25: =(F25+O25+Q25)/P25 -> #DIV/0! | T25: =(F25+O25)/P25 -> #DIV/0! | U25: 0 | V25: 0 | W25: 0 | X25: 0 | Y25: 1 | Z25: 0 | AA25: нужно увеличить продажи!!! | AB25: =G25*Q25 -> 0
A26: Продукт По-Росийски Классический с ЗМЖ 50% ВЕС Коровино Останкино | B26: кг | C26: 67.125 | E26: 2.815 | F26: 64.31 | G26: 1 | K26: 2 | L26: =E26-K26 -> 0.815 | P26: =E26/5 -> 0.563 | S26: =(F26+O26+Q26)/P26 -> 114.22735 | T26: =(F26+O26)/P26 -> 114.22735 | U26: 0 | V26: 0 | W26: 0 | X26: 0 | Y26: 0 | Z26: 0 | AA26: нужно увеличить продажи!!! | AB26: =G26*Q26 -> 0
A27: Продукт белково-жировой Сметанковый 50% ВЕС Коровино Останкино | B27: кг | C27: 51.577 | D27: 3.318 | F27: 54.895 | G27: 1 | L27: =E27-K27 -> 0 | P27: =E27/5 -> 0 | S27: =(F27+O27+Q27)/P27 -> #DIV/0! | T27: =(F27+O27)/P27 -> #DIV/0! | U27: 0 | V27: 0 | W27: 1.767 | X27: 0 | Y27: 0.975 | Z27: 0.445 | AA27: нужно увеличить продажи!!! | AB27: =G27*Q27 -> 0
A28: Российский сливочный 45% ТМ Папа Может, брус (2шт) Останкино | B28: кг | C28: -2.402 | D28: 1.214 | E28: -1.188 | F28: -1.188 | G28: 0 | I28: дубль | J28: 3323 Сыр Российский цилиндр 1/4 пленка ЮКМП м.д.ж. 50% ОСТАНКИНО | L28: =E28-K28 -> -1.188 | P28: =E28/5 -> -0.2376 | S28: =(F28+O28+Q28)/P28 -> 5 | T28: =(F28+O28)/P28 -> 5 | U28: 0.2376 | V28: 0 | W28: 0 | X28: 0 | Y28: 0 | Z28: 0
A29: Сыр "Пармезан" 40% кусок 180 гр ОСТАНКИНО | B29: шт | C29: 117 | D29: 204 | E29: 27 | F29: 294 | G29: 0.18 | H29: 150 | K29: 108 | L29: =E29-K29 -> -81 | P29: =E29/5 -> 5.4 | S29: =(F29+O29+Q29)/P29 -> 54.444444 | T29: =(F29+O29)/P29 -> 54.444444 | U29: 0 | V29: 0 | W29: -0.2 | X29: -0.6 | Y29: -0.6 | Z29: 0 | AA29: нужно увеличить продажи!!! | AB29: =G29*Q29 -> 0
A30: Сыр Боккончини копченый 40% 100 гр. ОСТАНКИНО | B30: шт | C30: 15 | D30: 195 | E30: 1 | F30: 206 | G30: 0.1 | H30: 90 | K30: 21 | L30: =E30-K30 -> -20 | P30: =E30/5 -> 0.2 | S30: =(F30+O30+Q30)/P30 -> 1030 | T30: =(F30+O30)/P30 -> 1030 | U30: 7.4 | V30: 12.2 | W30: -0.6 | X30: 0 | Y30: 0 | Z30: 0 | AA30: нужно увеличить продажи!!! | AB30: =G30*Q30 -> 0
A31: Сыр Косичка сырная 45% 100г/8шт Папа Может Останкино | B31: шт | C31: 447 | D31: 17 | E31: 152 | F31: 296 | G31: 0.1 | K31: 169 | L31: =E31-K31 -> -17 | O31: 304 | P31: =E31/5 -> 30.4 | S31: =(F31+O31+Q31)/P31 -> 19.736842 | T31: =(F31+O31)/P31 -> 19.736842 | U31: 37.4 | V31: 2 | W31: 24.8 | X31: 44.2 | Y31: 5.2 | Z31: 14 | AB31: =G31*Q31 -> 0
A32: Сыр Косичка сырная копченая 43% 100г/8шт Папа Может Останкино | B32: шт | C32: 191 | D32: 103 | E32: 105 | F32: 181 | G32: 0.1 | K32: 121 | L32: =E32-K32 -> -16 | O32: 248 | P32: =E32/5 -> 21 | S32: =(F32+O32+Q32)/P32 -> 20.428571 | T32: =(F32+O32)/P32 -> 20.428571 | U32: 26.6 | V32: 20.6 | W32: 21.4 | X32: 28 | Y32: 2.2 | Z32: 16.2 | AB32: =G32*Q32 -> 0
A33: Сыр ПАПА МОЖЕТ "Гауда Голд" 45 % 180 гр (10шт) Останкино | B33: шт | C33: 214 | D33: 174 | E33: 174 | F33: 188 | G33: 0.18 | H33: 150 | K33: 197 | L33: =E33-K33 -> -23 | O33: 280 | P33: =E33/5 -> 34.8 | Q33: =20*P33-O33-F33 -> 228 | R33: =VLOOKUP(A33,заказ!A:B,2,0) -> 230 | S33: =(F33+O33+Q33)/P33 -> 20 | T33: =(F33+O33)/P33 -> 13.448276 | U33: 33.2 | V33: 23.2 | W33: 15 | X33: 35 | Y33: 37.8 | Z33: 39.4 | AB33: =G33*Q33 -> 41.04
A34: Сыр ПАПА МОЖЕТ "Голландский традиционный" 45% 180 гр (10шт) Останкино | B34: шт | C34: 551 | D34: 354 | E34: 301 | F34: 601 | G34: 0.18 | H34: 150 | K34: 303 | L34: =E34-K34 -> -2 | O34: 750 | P34: =E34/5 -> 60.2 | S34: =(F34+O34+Q34)/P34 -> 22.44186 | T34: =(F34+O34)/P34 -> 22.44186 | U34: 84.2 | V34: 19.8 | W34: 15.8 | X34: 83.6 | Y34: 2 | Z34: 26.4 | AB34: =G34*Q34 -> 0
A35: Сыр ПАПА МОЖЕТ "Министерский" 180 г фасованный массовая Останкино | B35: шт | C35: 126 | F35: 126 | G35: 0.18 | H35: 150 | K35: 142 | L35: =E35-K35 -> -142 | P35: =E35/5 -> 0 | S35: =(F35+O35+Q35)/P35 -> #DIV/0! | T35: =(F35+O35)/P35 -> #DIV/0! | U35: -0.2 | V35: 0 | W35: -0.4 | X35: -0.4 | Y35: 0 | Z35: 0.2 | AA35: нужно увеличить продажи!!! | AB35: =G35*Q35 -> 0
A36: Сыр ПАПА МОЖЕТ "Папин завтрак" 45% 180 г Останкино | B36: шт | C36: 230 | D36: 230 | E36: =70+E39 -> 72 | F36: =370+F39 -> 366 | G36: 0.18 | H36: 120 | K36: 90 | L36: =E36-K36 -> -18 | P36: =E36/5 -> 14.4 | S36: =(F36+O36+Q36)/P36 -> 25.416667 | T36: =(F36+O36)/P36 -> 25.416667 | U36: 14.6 | V36: 27 | W36: 22.4 | X36: 19.2 | Y36: 19.2 | Z36: 17.4 | AB36: =G36*Q36 -> 0
A37: Сыр ПАПА МОЖЕТ "Российский традиционный"45 % 180 г Останкино | B37: шт | C37: 470 | D37: 9 | E37: =311+E40 -> 313 | F37: =159+F40 -> 155 | G37: 0.18 | H37: 150 | K37: 320 | L37: =E37-K37 -> -7 | O37: 750 | P37: =E37/5 -> 62.6 | Q37: =20*P37-O37-F37 -> 347 | R37: =VLOOKUP(A37,заказ!A:B,2,0) -> 350 | S37: =(F37+O37+Q37)/P37 -> 20 | T37: =(F37+O37)/P37 -> 14.456869 | U37: 65 | V37: 24.4 | W37: 46 | X37: 78 | Y37: 1.2 | Z37: 47.8 | AB37: =G37*Q37 -> 62.46
A38: Сыр ПАПА МОЖЕТ "Тильзитер" фасованный массовая доля жира в сухом веществе 45%, 180г Останкино | B38: шт | C38: 152 | D38: 1044 | E38: =118+E41 -> 119 | F38: =1074+F41 -> 1073 | G38: 0.18 | H38: 120 | K38: 170 | L38: =E38-K38 -> -51 | P38: =E38/5 -> 23.8 | S38: =(F38+O38+Q38)/P38 -> 45.084034 | T38: =(F38+O38)/P38 -> 45.084034 | U38: 17 | V38: 36.8 | W38: 22.6 | X38: 22 | Y38: 28.4 | Z38: 31.4 | AA38: нужно увеличить продажи!!! | AB38: =G38*Q38 -> 0
A39: Сыр Папа Может Папин Завтрак 50% 200г Останкино | B39: шт | C39: -2 | E39: 2 | F39: -4 | G39: 0 | I39: дубль | J39: Сыр ПАПА МОЖЕТ "Папин завтрак" 45% 180 г Останкино | K39: 2 | L39: =E39-K39 -> 0 | P39: =E39/5 -> 0.4 | S39: =(F39+O39+Q39)/P39 -> -10 | T39: =(F39+O39)/P39 -> -10 | U39: 0 | V39: 0.4 | W39: 0 | X39: 0 | Y39: 0 | Z39: 0
A40: Сыр Папа Может Российский 50% 200гр Останкино | B40: шт | C40: -2 | E40: 2 | F40: -4 | G40: 0 | I40: дубль | J40: Сыр ПАПА МОЖЕТ "Российский традиционный"45 % 180 г Останкино | K40: 2 | L40: =E40-K40 -> 0 | P40: =E40/5 -> 0.4 | S40: =(F40+O40+Q40)/P40 -> -10 | T40: =(F40+O40)/P40 -> -10 | U40: 0 | V40: 0.4 | W40: 0 | X40: 0 | Y40: 0 | Z40: 0
A41: Сыр Папа Может Тильзитер 45% 200гр Останкино | B41: шт | E41: 1 | F41: -1 | G41: 0 | I41: дубль | J41: Сыр ПАПА МОЖЕТ "Тильзитер" фасованный массовая доля жира в сухом веществе 45%, 180г Останкино | K41: 1 | L41: =E41-K41 -> 0 | P41: =E41/5 -> 0.2 | S41: =(F41+O41+Q41)/P41 -> -5 | T41: =(F41+O41)/P41 -> -5 | U41: 0 | V41: 0 | W41: 0 | X41: 0 | Y41: 0 | Z41: 0
A42: Сыр Плавленый Сливочный Папа Может 55% 190гр Останкино | B42: шт | C42: -3 | E42: 1 | F42: -4 | G42: 0 | I42: дубль | J42: Сыр плавленный Сливочный ж.45% 180г ТМ Папа может (16шт) Останкино | K42: 7 | L42: =E42-K42 -> -6 | P42: =E42/5 -> 0.2 | S42: =(F42+O42+Q42)/P42 -> -20 | T42: =(F42+O42)/P42 -> -20 | U42: 0.6 | V42: 0 | W42: 0 | X42: 0 | Y42: 0 | Z42: 0
...

Sheet заказ
A1: 4931 Сыр полутвердый "Купеческий" с ароматом топленого молока, с м.д.ж. 50% ОСТАНКИНО | B1: 33
A2: 6948256 Майонез провансаль классич.оливковый Папа может 372гр с массовой долей жирн. 67% Останкино | B2: 420
A3: 6948263 Майонез провансаль классич.оливковый Папа может 744гр с массовой долей жирн. 67% Останкино | B3: 276
A4: 6948270 Майонез провансаль классич.Папа может 372гр с массовой долей жирн. 67% Останкино | B4: 672
A5: 6948287 Майонез провансаль классич.Папа может 744гр с массовой долей жирн. 67% Останкино | B5: 828
A6: 9988445 Плавленый Сыр 45%"С грибами" СТМ"ПапаМожет" 180 гр Останкино | B6: 32
A7: Cыр Перлини со вкусом Васаби 40% 100гр (8шт) Останкино | B7: 56
A8: Масло сливочное 72,5 % 180 гр.(10 шт) СЛАВЯНА Останкино | B8: 400
A9: Сыр ПАПА МОЖЕТ "Гауда Голд" 45 % 180 гр (10шт) Останкино | B9: 230
A10: Сыр ПАПА МОЖЕТ "Российский традиционный"45 % 180 г Останкино | B10: 350
A11: Сыр Творожный с зеленью 60% Папа может 140 гр. Останкино | B11: 32
A12: Сыр полутвердый "Сметанковый", с масс долей жира в пересчете на сухое вещес50%, брус Останкино | B12: 116
... A15: Сыч/Прод Коровино Тильзитер Оригин 50% ВЕС НОВАЯ (5 кг брус) СЗМЖ ОСТАНКИНО | B15: 30
