Workbook

Sheet Sheet
A3: Номенклатура | B3: Ед. изм. | C3: Начальный остаток | D3: Приход | E3: Расход | F3: Конечный остаток | G3: крат | H3: сроки | I3: метка | J3: метка2 | K3: заяв | L3: разн | M3: без опта | N3: опт | O3: заказ в пути | P3: заказ в пути | Q3: ср нов | R3: расчет | S3: итого1 | T3: заказ | U3: итого | V3: заказ | W3: ТК | X3: ТК | Y3: кон ост | Z3: факт | AA3: ср | AB3: ср | AC3: ср | AD3: ср | AE3: ср | AF3: ср | AG3: ср | AH3: ср | AI3: ср | AJ3: ср | AK3: комментарии | AL3: вес | AM3: вес
O4: 28,09, | P4: 28,09,сети | Q4: 30,09, | S4: филиал | T4: 05,10, | U4: сети | V4: 05,10,сети | W4: Титенко | X4: сети | AA4: 23,09, | AB4: 16,09, | AC4: 08,09, | AD4: 01,09, | AE4: 25,08, | AF4: 18,08, | AG4: 11,08, | AH4: 04,08, | AI4: 28,07, | AJ4: 21,07, | AL4: филиал | AM4: сети
E5: =SUM(E6:E500) -> 2415.982 | F5: =SUM(F6:F500) -> 4132.216 | K5: =SUM(K6:K500) -> 3446.742 | L5: =SUM(L6:L500) -> -1030.76 | M5: =SUM(M6:M500) -> 0 | N5: =SUM(N6:N500) -> 0 | O5: =SUM(O6:O500) -> 3100 | P5: =SUM(P6:P500) -> 656 | Q5: =SUM(Q6:Q500) -> 483.1964 | R5: =SUM(R6:R500) -> 2839.3896 | ... X5: =SUM(X6:X500) -> 0 | AA5: =SUM(AA6:AA500) -> 491.886 | AB5: =SUM(AB6:AB500) -> 558.02 | AC5: =SUM(AC6:AC500) -> 559.986 | AD5: =SUM(AD6:AD500) -> 430.4206 | AE5: =SUM(AE6:AE500) -> 432.4984 | AF5: =SUM(AF6:AF500) -> 540.8796 | AG5: =SUM(AG6:AG500) -> 359.4726 | AH5: =SUM(AH6:AH500) -> 466.0342 | ... AJ5: =SUM(AJ6:AJ500) -> 293.5244 | AL5: =SUM(AL6:AL500) -> 838.3716 | AM5: =SUM(AM6:AM500) -> 141.4
A6: 1103201 Сыр копченый "Косичка" мини ПАПА МОЖЕТ 55г лоток ОСТАНКИНО | B6: шт | C6: 58 | E6: 3 | F6: 55 | G6: 0.055 | H6: 120 | K6: 3 | L6: =E6-K6 -> 0 | Q6: =E6/5 -> 0.6 | S6: =R6 -> 0 | Y6: =(F6+O6+S6)/Q6 -> 91.666667 | Z6: =(F6+O6)/Q6 -> 91.666667 | AA6: 1.4 | AB6: 1 | AC6: 0.8 | AD6: 3.6 | AE6: 3.2 | AF6: 3.2 | AG6: 0 | AH6: 6.4 | AI6: 3.2 | AJ6: 0 | AK6: нужно увеличить продажи!!! | AL6: =G6*S6 -> 0 | AM6: =G6*U6 -> 0
A7: 2103201 БЖП, произведенный по технологии сыра копченый "Косичка" мини Ассорти ОСТАНКИНО | B7: шт | C7: 59 | E7: 2 | F7: 57 | G7: 0.1 | H7: 120 | K7: 2 | L7: =E7-K7 -> 0 | Q7: =E7/5 -> 0.4 | S7: =R7 -> 0 | Y7: =(F7+O7+S7)/Q7 -> 142.5 | Z7: =(F7+O7)/Q7 -> 142.5 | AA7: 2 | AB7: 3.2 | AC7: 1.4 | AD7: 2 | AE7: 6 | AF7: 2.6 | AG7: 1 | AH7: 6 | AI7: 3 | AJ7: 0 | AK7: нужно увеличить продажи!!! | AL7: =G7*S7 -> 0 | AM7: =G7*U7 -> 0
A8: 2105201 БЖП, произведенный по технологии сыра копченый "Балык" резаный 4 вкуса ОСТАНКИНО | B8: шт | C8: 9 | D8: 24 | E8: 9 | F8: 24 | G8: 0.1 | H8: 120 | K8: 14 | L8: =E8-K8 -> -5 | O8: 24 | Q8: =E8/5 -> 1.8 | S8: =R8 -> 0 | Y8: =(F8+O8+S8)/Q8 -> 26.666667 | Z8: =(F8+O8)/Q8 -> 26.666667 | AA8: 3 | AB8: 2.4 | AC8: 2.2 | AD8: 1.2 | AE8: 3.2 | AF8: 1.4 | AG8: 3 | AH8: 2.2 | AI8: 2.4 | AJ8: 0 | AL8: =G8*S8 -> 0 | AM8: =G8*U8 -> 0
A9: 3323 Сыр Российский цилиндр 1/4 пленка ЮКМП м.д.ж. 50% ОСТАНКИНО | B9: кг | C9: 33.554 | D9: 53.302 | E9: 33.198 | F9: 46.034 | G9: 1 | H9: 120 | K9: 41.292 | L9: =E9-K9 -> -8.094 | O9: 60 | Q9: =E9/5 -> 6.6396 | R9: =18*Q9-O9-F9 -> 13.4788 | S9: =W9 -> 40 | T9: =VLOOKUP(A9,филиал!A:B,2,0) -> 40 | W9: =VLOOKUP(A9,[1]Sheet!$A:$S,19,0) -> 40 | Y9: =(F9+O9+S9)/Q9 -> 21.994397 | Z9: =(F9+O9)/Q9 -> 15.969938 | AA9: 8.668 | AB9: 7.408 | AC9: 6.5136 | AD9: 8.3614 | AE9: 5.9184 | AF9: 5.124 | AG9: 2.4896 | AH9: 4.2826 | AI9: 8.3128 | AJ9: 1.8976 | AL9: =G9*S9 -> 40 | AM9: =G9*U9 -> 0
A10: 4421577 Спред растительно-сливочный "Сливочный вкус" 82,5% 180гр Останкино | B10: шт | G10: 0.18 | H10: 180 | K10: 5 | L10: =E10-K10 -> -5 | O10: 0 | Q10: =E10/5 -> 0 | R10: 12 | S10: =R10 -> 12 | T10: 0 | Y10: =(F10+O10+S10)/Q10 -> #DIV/0! | Z10: =(F10+O10)/Q10 -> #DIV/0! | AA10: -0.2 | AB10: 0 | AC10: -0.4 | AD10: 0 | AE10: 0 | AF10: 0 | AG10: 0 | AH10: 0 | AI10: 2 | AJ10: 0 | AK10: нет на заводе | AL10: =G10*S10 -> 2.16 | AM10: =G10*U10 -> 0
A11: 4421584 Спред растительно-сливочный "Сливочный вкус" 72,5% 180гр Останкино | B11: шт | G11: 0.18 | H11: 180 | K11: 2 | L11: =E11-K11 -> -2 | O11: 0 | Q11: =E11/5 -> 0 | R11: 12 | S11: =R11 -> 12 | T11: 0 | Y11: =(F11+O11+S11)/Q11 -> #DIV/0! | Z11: =(F11+O11)/Q11 -> #DIV/0! | AA11: 0 | AB11: 0 | AC11: 0 | AD11: 0 | AE11: 0 | AF11: 0 | AG11: 0 | AH11: 0 | AI11: 3 | AJ11: 0 | AK11: нет на заводе | AL11: =G11*S11 -> 2.16 | AM11: =G11*U11 -> 0
A12: 4931 Сыр полутвердый "Купеческий" с ароматом топленого молока, с м.д.ж. 50% ОСТАНКИНО | B12: кг | C12: 38.614 | E12: 6.262 | F12: 29.026 | G12: 1 | H12: 180 | K12: 6.65 | L12: =E12-K12 -> -0.388 | Q12: =E12/5 -> 1.2524 | S12: =W12 -> 8 | T12: =VLOOKUP(A12,филиал!A:B,2,0) -> 16 | W12: =VLOOKUP(A12,[1]Sheet!$A:$S,19,0) -> 8 | Y12: =(F12+O12+S12)/Q12 -> 29.564037 | Z12: =(F12+O12)/Q12 -> 23.176302 | AA12: 2.61 | AB12: 2.4996 | AC12: 3.8992 | AD12: 1.3052 | AE12: 0.6368 | AF12: 1.2988 | AG12: 1.2928 | AH12: 0.724 | AI12: 1.914 | AJ12: 0.628 | AL12: =G12*S12 -> 8 | AM12: =G12*U12 -> 0
A13: 6948249 Майонезный соус провансаль 824,5гр деликатес.с массовой долей жирн.25% Коровино Останкино | B13: шт | C13: 96 | F13: 88 | G13: 0.8245 | H13: 180 | L13: =E13-K13 -> 0 | Q13: =E13/5 -> 0 | S13: =R13 -> 0 | Y13: =(F13+O13+S13)/Q13 -> #DIV/0! | Z13: =(F13+O13)/Q13 -> #DIV/0! | AA13: 0 | AB13: 0.8 | AC13: 1.4 | AD13: 0 | AE13: 0.4 | AF13: 0 | AG13: 0 | AH13: 0 | AI13: 0.6 | AJ13: 0 | AK13: нужно увеличить продажи!!! | AL13: =G13*S13 -> 0 | AM13: =G13*U13 -> 0
A14: 6948256 Майонез провансаль классич.оливковый Папа может 372гр с массовой долей жирн. 67% Останкино | B14: шт | C14: 52 | D14: 300 | E14: 53 | F14: 182 | G14: 0.372 | H14: 180 | I14: сети | K14: 193 | L14: =E14-K14 -> -140 | P14: 252 | Q14: =E14/5 -> 10.6 | S14: =W14 -> 90 | T14: =VLOOKUP(A14,филиал!A:B,2,0) -> 96 | W14: =VLOOKUP(A14,[1]Sheet!$A:$S,19,0) -> 90 | Y14: =(F14+O14+S14)/Q14 -> 25.660377 | Z14: =(F14+O14)/Q14 -> 17.169811 | AA14: 17.6 | AB14: 32.4 | AC14: 18.6 | AD14: 7.6 | AE14: 2.4 | AF14: 9.8 | AG14: 16.2 | AH14: 15.2 | AI14: 4.6 | AJ14: 5 | AL14: =G14*S14 -> 33.48 | AM14: =G14*U14 -> 0
A15: 6948263 Майонез провансаль классич.оливковый Папа может 744гр с массовой долей жирн. 67% Останкино | B15: шт | C15: 187 | D15: 48 | E15: 27 | F15: 196 | G15: 0.744 | H15: 180 | K15: 27 | L15: =E15-K15 -> 0 | O15: 36 | Q15: =E15/5 -> 5.4 | S15: 30 | T15: =VLOOKUP(A15,филиал!A:B,2,0) -> 24 | W15: =VLOOKUP(A15,[1]Sheet!$A:$S,19,0) -> 70 | Y15: =(F15+O15+S15)/Q15 -> 48.518519 | Z15: =(F15+O15)/Q15 -> 42.962963 | AA15: 2.4 | AB15: 4.2 | AC15: 0 | AD15: 1 | AE15: 6.6 | AF15: 6.4 | AG15: 2.8 | AH15: 2.6 | AI15: 4 | AJ15: 2.6 | AK15: нужно увеличить продажи / 285шт в уценку (27,08,26) | AL15: =G15*S15 -> 22.32 | AM15: =G15*U15 -> 0
A16: 6948270 Майонез провансаль классич.Папа может 372гр с массовой долей жирн. 67% Останкино | B16: шт | C16: 177 | D16: 456 | E16: 262 | F16: 336 | G16: 0.372 | H16: 180 | I16: сети | K16: 267 | L16: =E16-K16 -> -5 | P16: 204 | Q16: =E16/5 -> 52.4 | R16: =15*Q16-O16-F16 -> 450 | S16: =R16 -> 450 | T16: =VLOOKUP(A16,филиал!A:B,2,0) -> 456 | Y16: =(F16+O16+S16)/Q16 -> 15 | Z16: =(F16+O16)/Q16 -> 6.4122137 | AA16: 13 | AB16: 56.6 | AC16: 35.2 | AD16: 11.6 | AE16: 10.2 | AF16: 16.2 | AG16: 7.8 | AH16: 15.4 | AI16: 15.8 | AJ16: 10 | AL16: =G16*S16 -> 167.4 | AM16: =G16*U16 -> 0
A17: 6948287 Майонез провансаль классич.Папа может 744гр с массовой долей жирн. 67% Останкино | B17: шт | C17: 148 | D17: 48 | E17: 87 | F17: 90 | G17: 0.744 | H17: 180 | K17: 97 | L17: =E17-K17 -> -10 | O17: 48 | Q17: =E17/5 -> 17.4 | R17: =18*Q17-O17-F17 -> 175.2 | S17: =R17 -> 175.2 | T17: =VLOOKUP(A17,филиал!A:B,2,0) -> 180 | Y17: =(F17+O17+S17)/Q17 -> 18 | Z17: =(F17+O17)/Q17 -> 7.9310345 | AA17: 6.4 | AB17: 1.6 | AC17: 11.8 | AD17: 4 | AE17: 11 | AF17: 8.4 | AG17: 3.2 | AH17: 12.4 | AI17: 1.8 | AJ17: 5.8 | AK17: 24,08,26 - отсутствует на заводе | AL17: =G17*S17 -> 130.3488 | AM17: =G17*U17 -> 0
A18: 9988438 Плавленый Сыр 45% "С ветчиной" СТМ"ПапаМожет" 180гр Останкино | B18: шт | C18: 39 | D18: 48 | E18: 33 | F18: 42 | G18: 0.18 | H18: 270 | K18: 35 | L18: =E18-K18 -> -2 | O18: 16 | Q18: =E18/5 -> 6.6 | R18: =18*Q18-O18-F18 -> 60.8 | S18: =W18 -> 80 | T18: =VLOOKUP(A18,филиал!A:B,2,0) -> 80 | W18: =VLOOKUP(A18,[1]Sheet!$A:$S,19,0) -> 80 | Y18: =(F18+O18+S18)/Q18 -> 20.909091 | Z18: =(F18+O18)/Q18 -> 8.7878788 | AA18: 5.2 | AB18: 7.2 | AC18: 5.8 | AD18: 5 | AE18: 5.8 | AF18: 6.8 | AG18: 9 | AH18: 5.8 | AI18: 4.4 | AJ18: 2 | AL18: =G18*S18 -> 14.4 | AM18: =G18*U18 -> 0
A19: 9988445 Плавленый Сыр 45%"С грибами" СТМ"ПапаМожет" 180 гр Останкино | B19: шт | C19: 73 | D19: 16 | E19: 32 | F19: 39 | G19: 0.18 | H19: 270 | K19: 34 | L19: =E19-K19 -> -2 | O19: 16 | Q19: =E19/5 -> 6.4 | R19: =18*Q19-O19-F19 -> 60.2 | S19: =W19 -> 80 | T19: =VLOOKUP(A19,филиал!A:B,2,0) -> 80 | W19: =VLOOKUP(A19,[1]Sheet!$A:$S,19,0) -> 80 | Y19: =(F19+O19+S19)/Q19 -> 21.09375 | Z19: =(F19+O19)/Q19 -> 8.59375 | AA19: 3.2 | AB19: 6.8 | AC19: 7.6 | AD19: 4.8 | AE19: 5.8 | AF19: 5.8 | AG19: 9.2 | AH19: 5.2 | AI19: 4.4 | AJ19: 3.2 | AL19: =G19*S19 -> 14.4 | AM19: =G19*U19 -> 0
A20: Масло "Папа может" 82,5% 180гр Останкино | B20: шт | C20: 160 | D20: 355 | E20: 237 | F20: 176 | G20: 0.18 | H20: 180 | K20: 264 | L20: =E20-K20 -> -27 | O20: 270 | Q20: =E20/5 -> 47.4 | R20: =18*Q20-O20-F20 -> 407.2 | S20: =R20 -> 407.2 | T20: =VLOOKUP(A20,филиал!A:B,2,0) -> 410 | Y20: =(F20+O20+S20)/Q20 -> 18 | Z20: =(F20+O20)/Q20 -> 9.4092827 | AA20: 48.4 | AB20: 49 | AC20: 39.2 | AD20: 38.6 | AE20: 36.6 | AF20: 46.2 | AG20: 38 | AH20: 34 | AI20: 30.0788 | AJ20: 33.8 | AL20: =G20*S20 -> 73.296 | AM20: =G20*U20 -> 0
A21: Масло сливочное 72,5 % 180 гр.(10 шт) СЛАВЯНА Останкино | B21: шт | C21: 95 | D21: 93 | E21: 114 | F21: 37 | G21: 0.18 | H21: 180 | K21: 134 | L21: =E21-K21 -> -20 | O21: 200 | Q21: =E21/5 -> 22.8 | R21: =18*Q21-O21-F21 -> 173.4 | S21: =R21 -> 173.4 | T21: =VLOOKUP(A21,филиал!A:B,2,0) -> 170 | Y21: =(F21+O21+S21)/Q21 -> 18 | Z21: =(F21+O21)/Q21 -> 10.394737 | AA21: 25 | AB21: 21.2 | AC21: 20.6 | AD21: 19.2 | AE21: 15 | AF21: 26.6 | AG21: 30.6 | AH21: 17.6 | AI21: 16.2 | AJ21: 9.2 | AL21: =G21*S21 -> 31.212 | AM21: =G21*U21 -> 0
A22: Плавленый Сыр колбасный копченый 40% СТМ"ПапаМожет"400гр Останкино | B22: шт | G22: 0.4 | H22: 270 | K22: 11 | L22: =E22-K22 -> -11 | O22: 16 | Q22: =E22/5 -> 0 | R22: 16 | S22: =R22 -> 16 | T22: =VLOOKUP(A22,филиал!A:B,2,0) -> 16 | Y22: =(F22+O22+S22)/Q22 -> #DIV/0! | Z22: =(F22+O22)/Q22 -> #DIV/0! | AA22: -0.8 | AB22: 0 | AC22: -0.4 | AD22: -0.4 | AE22: 0 | AF22: 0 | AG22: 0 | AH22: -0.4 | AI22: 0 | AJ22: 0.4 | AK22: 31шт списано (19,09,26) | AL22: =G22*S22 -> 6.4 | AM22: =G22*U22 -> 0
A23: Плавленый продукт с Сыром колбасный копченый 40% СТМ "Коровино" 400гр Останкино | B23: шт | C23: 33 | D23: 31 | E23: 7 | F23: 53 | G23: 0.4 | H23: 270 | K23: 10 | L23: =E23-K23 -> -3 | Q23: =E23/5 -> 1.4 | S23: =R23 -> 0 | Y23: =(F23+O23+S23)/Q23 -> 37.857143 | Z23: =(F23+O23)/Q23 -> 37.857143 | AA23: 1.6 | AB23: 1.8 | AC23: 1.2 | AD23: 0.4 | AE23: 2 | AF23: 0.6 | AG23: 0.4 | AH23: 0.4 | AI23: 0 | AJ23: 0 | AK23: нужно увеличить продажи | AL23: =G23*S23 -> 0 | AM23: =G23*U23 -> 0
A24: Сыр "Пармезан" 40% кусок 180 гр ОСТАНКИНО | B24: шт | C24: 87 | D24: 210 | E24: 79 | F24: 211 | G24: 0.18 | H24: 150 | K24: 83 | L24: =E24-K24 -> -4 | Q24: =E24/5 -> 15.8 | R24: =18*Q24-O24-F24 -> 73.4 | S24: =W24 -> 100 | T24: =VLOOKUP(A24,филиал!A:B,2,0) -> 102 | W24: =VLOOKUP(A24,[1]Sheet!$A:$S,19,0) -> 100 | Y24: =(F24+O24+S24)/Q24 -> 19.683544 | Z24: =(F24+O24)/Q24 -> 13.35443 | AA24: 14.2 | AB24: 26.4 | AC24: 17.6 | AD24: 1.6 | AE24: 1 | AF24: 11.8 | AG24: 2.6 | AH24: 6.8 | AI24: 13.2 | AJ24: 10.6 | AL24: =G24*S24 -> 18 | AM24: =G24*U24 -> 0
A25: Сыр Боккончини копченый 40% 100 гр. ОСТАНКИНО | B25: шт | C25: 296 | D25: 2 | E25: 131 | F25: 152 | G25: 0.1 | H25: 90 | K25: 138 | L25: =E25-K25 -> -7 | O25: 40 | Q25: =E25/5 -> 26.2 | R25: =15*Q25-O25-F25 -> 201 | S25: =R25 -> 201 | T25: =VLOOKUP(A25,филиал!A:B,2,0) -> 200 | U25: 260 | V25: =VLOOKUP(A25,сети!A:B,2,0) -> 256 | X25: 260 со свежим ОСГ под сети | Y25: =(F25+O25+S25)/Q25 -> 15 | Z25: =(F25+O25)/Q25 -> 7.3282443 | AA25: 9.2 | AB25: 12 | AC25: 25 | AD25: 22.4 | AE25: 14.6 | AF25: 17.4 | AG25: 11 | AH25: 36.4 | AI25: 20 | AJ25: 16.2 | AL25: =G25*S25 -> 20.1 | AM25: =G25*U25 -> 26
A26: Сыр Косичка сырная 45% 100г/8шт Папа Может Останкино | B26: шт | C26: 227 | D26: 6 | E26: 84 | F26: 137 | G26: 0.1 | H26: 60 | K26: 109 | L26: =E26-K26 -> -25 | O26: 168 | Q26: =E26/5 -> 16.8 | S26: =R26 -> 0 | Y26: =(F26+O26+S26)/Q26 -> 18.154762 | Z26: =(F26+O26)/Q26 -> 18.154762 | AA26: 24.2 | AB26: 16 | AC26: 27 | AD26: 15.8 | AE26: 26.2 | AF26: 15 | AG26: 25.4 | AH26: 25.2 | AI26: 12.2 | AJ26: 6.6 | AL26: =G26*S26 -> 0 | AM26: =G26*U26 -> 0
A27: Сыр Косичка сырная копченая 43% 100г/8шт Папа Может Останкино | B27: шт | C27: 153 | D27: 3 | E27: 71 | F27: 73 | G27: 0.1 | H27: 90 | K27: 90 | L27: =E27-K27 -> -19 | O27: 152 | Q27: =E27/5 -> 14.2 | R27: =18*Q27-O27-F27 -> 30.6 | S27: =R27 -> 30.6 | T27: =VLOOKUP(A27,филиал!A:B,2,0) -> 32 | Y27: =(F27+O27+S27)/Q27 -> 18 | Z27: =(F27+O27)/Q27 -> 15.84507 | AA27: 17.8 | AB27: 13.4 | AC27: 18.4 | AD27: 16.8 | AE27: 11.2 | AF27: 17.8 | AG27: 21 | AH27: 16.6 | AI27: 15 | AJ27: 13.2 | AL27: =G27*S27 -> 3.06 | AM27: =G27*U27 -> 0
A28: Сыр ПАПА МОЖЕТ "Гауда Голд" 45 % 180 гр (10шт) Останкино | B28: шт | C28: 106 | D28: 20 | E28: 53 | F28: 63 | G28: 0.18 | H28: 150 | K28: 54 | L28: =E28-K28 -> -1 | Q28: =E28/5 -> 10.6 | R28: =18*Q28-O28-F28 -> 127.8 | S28: =R28 -> 127.8 | T28: =VLOOKUP(A28,филиал!A:B,2,0) -> 130 | Y28: =(F28+O28+S28)/Q28 -> 18 | Z28: =(F28+O28)/Q28 -> 5.9433962 | AA28: 4.8 | AB28: 0.2 | AC28: 12.4 | AD28: 2 | AE28: 7 | AF28: 19 | AG28: 16.2 | AH28: 13.8 | AI28: 5.2 | AJ28: 8.4 | AK28: 187шт в уценку (27,08,26) | AL28: =G28*S28 -> 23.004 | AM28: =G28*U28 -> 0
A29: Сыр ПАПА МОЖЕТ "Голландский традиционный" 45% 180 гр (10шт) Останкино | B29: шт | C29: 475 | D29: 50 | E29: 270 | F29: 178 | G29: 0.18 | H29: 150 | K29: 270 | L29: =E29-K29 -> 0 | O29: 450 | Q29: =E29/5 -> 54 | R29: =18*Q29-O29-F29 -> 344 | S29: =R29 -> 344 | T29: =VLOOKUP(A29,филиал!A:B,2,0) -> 340 | U29: 380 | V29: =VLOOKUP(A29,сети!A:B,2,0) -> 380 | X29: 380 со свежим ОСГ под сети | Y29: =(F29+O29+S29)/Q29 -> 18 | Z29: =(F29+O29)/Q29 -> 11.62963 | AA29: 65.2 | AB29: 54.8 | AC29: 71.6 | AD29: 57.6 | AE29: 47.8 | AF29: 68.6 | AG29: 30 | AH29: 58 | AI29: 69 | AJ29: 36 | AK29: 130шт в уценку (27,08,26) | AL29: =G29*S29 -> 61.92 | AM29: =G29*U29 -> 68.4
A30: Сыр ПАПА МОЖЕТ "Министерский" 180 г фасованный массовая Останкино | B30: шт | G30: 0.18 | H30: 150 | K30: 27 | L30: =E30-K30 -> -27 | O30: 40 | Q30: =E30/5 -> 0 | R30: 30 | S30: =R30 -> 30 | T30: =VLOOKUP(A30,филиал!A:B,2,0) -> 30 | Y30: =(F30+O30+S30)/Q30 -> #DIV/0! | Z30: =(F30+O30)/Q30 -> #DIV/0! | AA30: 0.4 | AB30: 3.4 | AC30: 4.4 | AD30: 4.8 | AE30: 6 | AF30: 9 | AG30: 8.8 | AH30: 5.6 | AI30: 4.6 | AJ30: 3.4 | AK30: 80шт в уценку (17,09,26) / 93шт в уценку (27,08,26) | AL30: =G30*S30 -> 5.4 | AM30: =G30*U30 -> 0
A31: Сыр ПАПА МОЖЕТ "Папин завтрак" 45% 180 г Останкино | B31: шт | C31: 13 | E31: 12 | G31: 0.18 | H31: 150 | K31: 12 | L31: =E31-K31 -> 0 | O31: 30 | Q31: =E31/5 -> 2.4 | R31: =18*Q31-O31-F31 -> 13.2 | S31: =R31 -> 13.2 | T31: =VLOOKUP(A31,филиал!A:B,2,0) -> 10 | Y31: =(F31+O31+S31)/Q31 -> 18 | Z31: =(F31+O31)/Q31 -> 12.5 | AA31: 3.8 | AB31: 1.8 | AC31: 0 | AD31: 0.8 | AE31: 2.6 | AF31: 4.4 | AG31: 4.4 | AH31: 2.8 | AI31: 2.6 | AJ31: 2.6 | AK31: 98шт в уценку (27,08,26) | AL31: =G31*S31 -> 2.376 | AM31: =G31*U31 -> 0
A32: Сыр ПАПА МОЖЕТ "Российский традиционный"45 % 180 г Останкино | B32: шт | C32: 316 | D32: 592 | E32: 224 | F32: 412 | G32: 0.18 | H32: 150 | K32: 492 | L32: =E32-K32 -> -268 | O32: 870 | Q32: =E32/5 -> 44.8 | S32: =R32 -> 0 | Y32: =(F32+O32+S32)/Q32 -> 28.616071 | Z32: =(F32+O32)/Q32 -> 28.616071 | AA32: 95.6 | AB32: 75.8 | AC32: 75.4 | AD32: 73.2 | AE32: 55.8 | AF32: 91.6 | AG32: 30.8 | AH32: 47.2 | AI32: 91 | AJ32: 44.8 | AL32: =G32*S32 -> 0 | AM32: =G32*U32 -> 0
A33: Сыр ПАПА МОЖЕТ "Тильзитер" фасованный массовая доля жира в сухом веществе 45%, 180г Останкино | B33: шт | C33: 317 | D33: 144 | E33: 49 | F33: 255 | G33: 0.18 | H33: 150 | I33: сети | K33: 314 | L33: =E33-K33 -> -265 | P33: 200 | Q33: =E33/5 -> 9.8 | S33: =R33 -> 0 | U33: 150 | V33: =VLOOKUP(A33,сети!A:B,2,0) -> 150 | X33: 150 со свежим ОСГ под сети | Y33: =(F33+O33+S33)/Q33 -> 26.020408 | Z33: =(F33+O33)/Q33 -> 26.020408 | AA33: 11 | AB33: 9.4 | AC33: 10 | AD33: 14 | AE33: 34 | AF33: 14.2 | AG33: 8.4 | AH33: 6.4 | AI33: 5.4 | AJ33: 17 | AK33: нужно увеличить продажи | AL33: =G33*S33 -> 0 | AM33: =G33*U33 -> 27
A34: Сыр Творожный с зеленью 60% Папа может 140 гр. Останкино | B34: шт | C34: 69 | D34: 16 | E34: 35 | F34: 35 | G34: 0.14 | H34: 180 | K34: 37 | L34: =E34-K34 -> -2 | Q34: =E34/5 -> 7 | R34: =18*Q34-O34-F34 -> 91 | S34: =R34 -> 91 | T34: =VLOOKUP(A34,филиал!A:B,2,0) -> 96 | Y34: =(F34+O34+S34)/Q34 -> 18 | Z34: =(F34+O34)/Q34 -> 5 | AA34: 2.2 | AB34: 6.2 | AC34: 8.4 | AD34: 5.2 | AE34: 3 | AF34: 7.6 | AG34: 9.2 | AH34: 6.8 | AI34: 6 | AJ34: 1.6 | AL34: =G34*S34 -> 12.74 | AM34: =G34*U34 -> 0
A35: Сыр плавленный Сливочный ж.45% 180г ТМ Папа может (16шт) Останкино | B35: шт | C35: 68 | D35: 64 | E35: 42 | F35: 72 | G35: 0.18 | H35: 270 | K35: 50 | L35: =E35-K35 -> -8 | Q35: =E35/5 -> 8.4 | R35: =18*Q35-O35-F35 -> 79.2 | S35: =R35 -> 79.2 | T35: =VLOOKUP(A35,филиал!A:B,2,0) -> 80 | Y35: =(F35+O35+S35)/Q35 -> 18 | Z35: =(F35+O35)/Q35 -> 8.5714286 | AA35: 5.4 | AB35: 10 | AC35: 8.8 | AD35: 7 | AE35: 8 | AF35: 8 | AG35: 8.2 | AH35: 9 | AI35: 7 | AJ35: 5.4 | AL35: =G35*S35 -> 14.256 | AM35: =G35*U35 -> 0
A36: Сыр полутвердый "Гауда" с массовой долей жира в пересчете на сухое вещество 45%, Останкино | B36: кг | C36: 33.45 | D36: 15.93 | E36: 26.826 | F36: 22.554 | G36: 1 | H36: 180 | K36: 29 | L36: =E36-K36 -> -2.174 | O36: 16 | Q36: =E36/5 -> 5.3652 | R36: =18*Q36-O36-F36 -> 58.0196 | S36: =R36 -> 58.0196 | T36: =VLOOKUP(A36,филиал!A:B,2,0) -> 66 | Y36: =(F36+O36+S36)/Q36 -> 18 | Z36: =(F36+O36)/Q36 -> 7.185939 | AA36: 3.3832 | AB36: 4.6584 | AC36: 2.7492 | AD36: 1.3732 | AE36: 2.7864 | AF36: 2.1148 | AG36: 0 | AH36: 0.7688 | AI36: 2.5832 | AJ36: 0.6992 | AL36: =G36*S36 -> 58.0196 | AM36: =G36*U36 -> 0
A37: Сыр полутвердый "Голландский" с массовой долей жира в пересчете на сухое Останкино | B37: кг | C37: 16.61 | D37: 3.578 | E37: 3.04 | F37: 9.992 | G37: 1 | H37: 180 | K37: 10 | L37: =E37-K37 -> -6.96 | O37: 33 | Q37: =E37/5 -> 0.608 | S37: =R37 -> 0 | Y37: =(F37+O37+S37)/Q37 -> 70.710526 | Z37: =(F37+O37)/Q37 -> 70.710526 | AA37: 3.1824 | AB37: 0.6596 | AC37: 1.3372 | AD37: 2.06 | AE37: 2.5316 | AF37: 0.674 | AG37: 1.9556 | AH37: 0.498 | AI37: 3.776 | AJ37: 0 | AK37: 16кг в уценку (27,08,26) | AL37: =G37*S37 -> 0 | AM37: =G37*U37 -> 0
A38: Сыр полутвердый "Сметанковый", с масс долей жира в пересчете на сухое вещес50%, брус Останкино | B38: кг | C38: 48.998 | E38: 18.802 | F38: 30.196 | G38: 1 | H38: 180 | K38: 20.9 | L38: =E38-K38 -> -2.098 | O38: 16 | Q38: =E38/5 -> 3.7604 | R38: =18*Q38-O38-F38 -> 21.4912 | S38: =R38 -> 21.4912 | T38: =VLOOKUP(A38,филиал!A:B,2,0) -> 16 | Y38: =(F38+O38+S38)/Q38 -> 18 | Z38: =(F38+O38)/Q38 -> 12.284863 | AA38: 1.1832 | AB38: 6.6988 | AC38: 5.6876 | AD38: 3.0772 | AE38: 4.3232 | AF38: 6.602 | AG38: 1.9152 | AH38: 3.442 | AI38: 4.5936 | AJ38: 1.9608 | AL38: =G38*S38 -> 21.4912 | AM38: =G38*U38 -> 0
A39: Сыр полутвердый "Тильзитер" с массовой долей жира в пересчете на сухое вещество 45%. 1/5 Останкино | B39: кг | C39: 98.448 | E39: 6.346 | F39: 86.374 | G39: 1 | H39: 180 | K39: 6 | L39: =E39-K39 -> 0.346 | Q39: =E39/5 -> 1.2692 | S39: =R39 -> 0 | Y39: =(F39+O39+S39)/Q39 -> 68.053892 | Z39: =(F39+O39)/Q39 -> 68.053892 | AA39: 1.836 | AB39: 2.9596 | AC39: 1.156 | AD39: 0.6952 | AE39: 0.5996 | AF39: 1.1588 | AG39: 0 | AH39: 0.612 | AI39: 2.676 | AJ39: 0.6388 | AK39: нужно увеличить продажи!!! | AL39: =G39*S39 -> 0 | AM39: =G39*U39 -> 0
A40: Сыр рассольный жирный Чечил 45% 100 гр ОСТАНКИНО | B40: шт | C40: 372 | D40: 250 | E40: 192 | F40: 377 | G40: 0.1 | H40: 60 | K40: 226 | L40: =E40-K40 -> -34 | O40: 12 | Q40: =E40/5 -> 38.4 | R40: =18*Q40-O40-F40 -> 302.2 | S40: =R40 -> 302.2 | T40: =VLOOKUP(A40,филиал!A:B,2,0) -> 300 | Y40: =(F40+O40+S40)/Q40 -> 18 | Z40: =(F40+O40)/Q40 -> 10.130208 | AA40: 19.4 | AB40: 44.4 | AC40: 47 | AD40: 30.2 | AE40: 36.6 | AF40: 49.2 | AG40: 0 | AH40: 0.8 | AI40: -0.4 | AJ40: -0.4 | AL40: =G40*S40 -> 30.22 | AM40: =G40*U40 -> 0
A41: Сыр рассольный жирный Чечил копченый 43% 100 гр Останкино | B41: шт | C41: 123 | D41: 330 | E41: 115 | F41: 258 | G41: 0.1 | H41: 90 | K41: 228 | L41: =E41-K41 -> -113 | O41: 450 | Q41: =E41/5 -> 23 | S41: =R41 -> 0 | U41: 200 | V41: =VLOOKUP(A41,сети!A:B,2,0) -> 198 | X41: 200 со свежим ОСГ под сети | Y41: =(F41+O41+S41)/Q41 -> 30.782609 | Z41: =(F41+O41)/Q41 -> 30.782609 | AA41: 48.2 | AB41: 33.8 | AC41: 32.8 | AD41: 44.8 | AE41: 33.8 | AF41: 31.4 | AG41: 33.4 | AH41: 67 | AI41: 49 | AJ41: 35.4 | AL41: =G41*S41 -> 0 | AM41: =G41*U41 -> 20
A42: Сыр твердый "Пармезан", с масовой долей жира 35% Останкино | B42: кг | C42: 8.156 | E42: 2.312 | F42: 5.844 | G42: 1 | K42: 2.9 | L42: =E42-K42 -> -0.588 | O42: 12 | Q42: =E42/5 -> 0.4624 | S42: =R42 -> 0 | Y42: =(F42+O42+S42)/Q42 -> 38.589965 | Z42: =(F42+O42)/Q42 -> 38.589965 | AA42: 1.0916 | AB42: 0.566 | AC42: 1.2756 | AD42: 0.7928 | AE42: 0 | AF42: 0 | AG42: 0.2494 | AH42: 0.5416 | AI42: 0 | AJ42: 0 | AK42: 32кг в уценку (06,08,26) | AL42: =G42*S42 -> 0 | AM42: =G42*U42 -> 0
...

Sheet филиал
A1: 3323 Сыр Российский цилиндр 1/4 пленка ЮКМП м.д.ж. 50% ОСТАНКИНО | B1: 40
A2: 4421577 Спред растительно-сливочный "Сливочный вкус" 82,5% 180гр Останкино | B2: 12
A3: 4421584 Спред растительно-сливочный "Сливочный вкус" 72,5% 180гр Останкино | B3: 12
A4: 4931 Сыр полутвердый "Купеческий" с ароматом топленого молока, с м.д.ж. 50% ОСТАНКИНО | B4: 16
A5: 6948256 Майонез провансаль классич.оливковый Папа может 372гр с массовой долей жирн. 67% Останкино | B5: 96
A6: 6948263 Майонез провансаль классич.оливковый Папа может 744гр с массовой долей жирн. 67% Останкино | B6: 24
A7: 6948270 Майонез провансаль классич.Папа может 372гр с массовой долей жирн. 67% Останкино | B7: 456
A8: 6948287 Майонез провансаль классич.Папа может 744гр с массовой долей жирн. 67% Останкино | B8: 180
A9: 9988438 Плавленый Сыр 45% "С ветчиной" СТМ"ПапаМожет" 180гр Останкино | B9: 80
A10: 9988445 Плавленый Сыр 45%"С грибами" СТМ"ПапаМожет" 180 гр Останкино | B10: 80
A11: Масло "Папа может" 82,5% 180гр Останкино | B11: 410
A12: Масло сливочное 72,5 % 180 гр.(10 шт) СЛАВЯНА Останкино | B12: 170
... A27: Сыч/Прод Коровино Тильзитер Оригин 50% ВЕС НОВАЯ (5 кг брус) СЗМЖ ОСТАНКИНО | B27: 15

Sheet сети
A1: Сыр Боккончини копченый 40% 100 гр. ОСТАНКИНО | B1: 256
A2: Сыр ПАПА МОЖЕТ "Голландский традиционный" 45% 180 гр (10шт) Останкино | B2: 380
A3: Сыр ПАПА МОЖЕТ "Тильзитер" фасованный массовая доля жира в сухом веществе 45%, 180г Останкино | B3: 150
A4: Сыр рассольный жирный Чечил копченый 43% 100 гр Останкино | B4: 198
