Workbook
Name CodeProxySet: Setting!$E$24:$E$25
Name Comment: 'Бланк заказа'!$H$5
Name ContactInformation: 'Бланк заказа'!$A$12
Name CustAccount: 'Бланк заказа'!$V$10
Name CustName: 'Бланк заказа'!$V$6
Name DateFrom: 'Бланк заказа'!$R$1
Name DeliveryAddress: 'Бланк заказа'!$D$6
Name DeliveryAdressList: Setting!$B$6:$B$11
Name DeliveryCodeAdressList: Setting!$C$6:$C$11
Name DeliveryConditions: 'Бланк заказа'!$V$12
Name DeliveryConditionsList: Setting!$B$25:$B$35
Name DeliveryDate: 'Бланк заказа'!$Q$9
Name DeliveryMethodList: Setting!$B$3:$B$4
Name DeliveryNumAdressList: Setting!$D$6:$D$11
Name DeliveryTime: 'Бланк заказа'!$Q$10
Name DeliveryTime2: 'Бланк заказа'!$Q$11
Name DeliveryTime3: 'Бланк заказа'!$Q$12
Name DeliveryTime4: 'Бланк заказа'!$Q$13
Name DlvMode: 'Бланк заказа'!$V$5
Name FileCodeCheck: Setting!$G$1
Name FIOProxy: 'Бланк заказа'!$H$9:$I$9
Name FIOProxySet: Setting!$C$24:$C$25
Name GrossWeightTotal: 'Бланк заказа'!$X$489:$X$489
Name GrossWeightTotalR: 'Бланк заказа'!$Y$489:$Y$489
Name LoadDate: 'Бланк заказа'!$Q$5
Name LoadTime: 'Бланк заказа'!$Q$8
Name NumProxy: 'Бланк заказа'!$D$10
Name NumProxySet: Setting!$B$24:$B$25
Name PalletQtyTotal: 'Бланк заказа'!$X$490:$X$490
Name PalletQtyTotalR: 'Бланк заказа'!$Y$490:$Y$490
Name PassportProxy: 'Бланк заказа'!$J$9:$M$9
Name PassportProxySet: Setting!$D$24:$D$25
Name ProductId1: 'Бланк заказа'!$B$22:$B$22
Name ProductId10: 'Бланк заказа'!$B$42:$B$42
Name ProductId100: 'Бланк заказа'!$B$218:$B$218
Name ProductId101: 'Бланк заказа'!$B$219:$B$219
Name ProductId102: 'Бланк заказа'!$B$220:$B$220
Name ProductId103: 'Бланк заказа'!$B$221:$B$221
Name ProductId104: 'Бланк заказа'!$B$222:$B$222
Name ProductId105: 'Бланк заказа'!$B$223:$B$223
Name ProductId106: 'Бланк заказа'!$B$224:$B$224
Name ProductId107: 'Бланк заказа'!$B$225:$B$225
Name ProductId108: 'Бланк заказа'!$B$229:$B$229
Name ProductId109: 'Бланк заказа'!$B$230:$B$230
Name ProductId11: 'Бланк заказа'!$B$43:$B$43
Name ProductId110: 'Бланк заказа'!$B$235:$B$235
Name ProductId111: 'Бланк заказа'!$B$236:$B$236
Name ProductId112: 'Бланк заказа'!$B$237:$B$237
Name ProductId113: 'Бланк заказа'!$B$238:$B$238
Name ProductId114: 'Бланк заказа'!$B$239:$B$239
Name ProductId115: 'Бланк заказа'!$B$240:$B$240
Name ProductId116: 'Бланк заказа'!$B$241:$B$241
Name ProductId117: 'Бланк заказа'!$B$245:$B$245
Name ProductId118: 'Бланк заказа'!$B$249:$B$249
Name ProductId119: 'Бланк заказа'!$B$253:$B$253
Name ProductId12: 'Бланк заказа'!$B$44:$B$44
Name ProductId120: 'Бланк заказа'!$B$254:$B$254
Name ProductId121: 'Бланк заказа'!$B$255:$B$255
Name ProductId122: 'Бланк заказа'!$B$256:$B$256
Name ProductId123: 'Бланк заказа'!$B$257:$B$257

Sheet Бланк заказа
D1: БЛАНК ЗАКАЗА | G1: КИ | H1: на отгрузку продукции с ООО Трейд-Сервис с | R1: 02.03.2026
A2: бланк создан | B2: 25.02.2026 | P2: =IF(ISNA(VLOOKUP(DeliveryAddress,Setting!B:C,2,FALSE)),"",IF(ISNA(VLOOKUP(UnloadAddress,Setting!B:C,2,FALSE)),"",IF(VLOOKUP(DeliveryAddress,Setting!B:C,2,FALSE)=VLOOKUP(UnloadAddress,Setting!B:C,2,FALSE),"","Укажите, кто получит груз в поле Тип доверенности.")))
B3: -поле, обязательное к заполнению | F3: -поля, не обязательные к заполнению
A5: Ваш контактный телефон и имя: | F5: Комментарий к заказу: | H5: загрузить отдельно, подписать №3, машина 4 | P5: Дата загрузки | Q5: 46222 | T5: Способ доставки (доставка/самовывоз) | V5: Самовывоз
A6: Адрес доставки: | D6: НВ, ООО 9001015535, Луганская Народная Респ, Рабочая ул, д. 10А, | P6: День недели | Q6: =IF(Q5=0," ",CHOOSE(WEEKDAY(Q5,2),"Понедельник","Вторник","Среда","Четверг","Пятница","Суббота","Воскресенье")) -> Воскресенье | T6: Наименование клиента | V6: ОБЩЕСТВО С ОГРАНИЧЕННОЙ ОТВЕТСТВЕННОСТЬЮ "НОВОЕ ВРЕМЯ"
D7: =IFERROR(VLOOKUP(DeliveryAddress,Table,3,0),1) -> 6
A8: Адрес сдачи груза: | P8: Время загрузки | Q8: 0.5
A9: =IF(ISNA(VLOOKUP(DeliveryAddress,Setting!B:C,2,FALSE)),"",IF(ISNA(VLOOKUP(UnloadAddress,Setting!B:C,2,FALSE)),"",IF(VLOOKUP(DeliveryAddress,Setting!B:C,2,FALSE)=VLOOKUP(UnloadAddress,Setting!B:C,2,FALSE),"","Тип доверенности/получателя при получении в адресе перегруза:"))) | F9: =IF(AND($A$9="Тип доверенности/получателя при получении в адресе перегруза:",$D$9="Разовая доверенность"),"Паспортные данные получателя заказа:","") | H9: =IF(AND($A$9="Тип доверенности/получателя при получении в адресе перегруза:",$D$9="Разовая доверенность"),"Введите ФИО","") | J9: =IF(AND($A$9="Тип доверенности/получателя при получении в адресе перегруза:",$D$9="Разовая доверенность"),"Введите паспортные данные","") | P9: Дата доставки | Q9: 46224
A10: =IF(AND($A$9="Тип доверенности/получателя при получении в адресе перегруза:",$D$9="Уполномоченное лицо"),"Постоянная доверенность (название, номер):","") | F10: =IF(AND($A$9="Тип доверенности/получателя при получении в адресе перегруза:",$D$9="Уполномоченное лицо"),"Уполномоченное лицо при получении груза в адресе перегруза:","") | H10: =IFERROR(VLOOKUP($D$10,Proxy,2,FALSE),"") | P10: Время доставки | Q10: 0.54166667 | U10: КОД Аксапты Клиента | V10: 596383
A11: Справочная информация: | P11: Время доставки 2 машины | U11: Тип заказа | V11: Основной заказ
A12: Телефоны для заказов: 8(919)002-63-01 E-mail: kolbasa@abi.ru Телефон сотрудников склада: 8 (910) 775-52-91 | P12: Время доставки 3 машины
A13: График приема заказов: Заказы принимаются за ДВА дня до отгрузки Пн-Пт: с 9:00 до 14:00, Суб., Вс. - до 12:00 | P13: Время доставки 4 машины
A14: Телефон менеджера по логистике: 8 (919) 012-30-55 - по вопросам доставки продукции
A15: Телефон по работе с претензиями/жалобами (WhatSapp): 8 (980) 757-69-93 E-mail: Claims@abiproduct.ru | P15: Кликните на продукт, чтобы просмотреть изображение
A17: Код единицы продаж | B17: Код продукта | C17: Номер варианта | D17: Штрих-код | F17: Вес нетто штуки, кг | G17: Кол-во штук в коробе, шт | H17: Вес нетто короба, кг | I17: Вес брутто короба, кг | J17: Кол-во кор. на паллте, шт | K17: Коробов в слое | L17: Квант заказа | M17: Завод | N17: Внешний код номенклатуры | O17: Срок годности, сут. | P17: Наименование | U17: Доступно к отгрузке | W17: Ед. изм. | X17: Заказ | Y17: Заказ с округлением до короба | Z17: Объём заказа, м3 | AA17: Примечание по продуктку | AB17: Признак "НОВИНКА" | AC17: Декларация/Сертификат | AD17: Для формул | BD17: Вид продукции
U18: начиная с | V18: до
A19: Ядрена копоть
A20: Ядрена копоть
A21: Копченые колбасы
A22: SU004004 | B22: P005154 | C22: 4301031446 | D22: 4680115887510 | F22: 0.2 | G22: 6 | H22: 1.2 | I22: 1.38 | J22: 182 | K22: 14 | M22: СК2 | O22: 40 | P22: =HYPERLINK("https://abi.ru/products/Охлажденные/Ядрена копоть/Ядрена копоть/Копченые колбасы/P005154/","Копченые колбасы «Колбаски Мини-колбаски со вкусом Мясо на углях» Фикс.вес 0,2 б/о ТМ «Ядрена копоть»") -> Копченые колбасы «Колбаски Мини-колбаски со вкусом Мясо на углях» Фикс.вес 0,2 б/о ТМ «Ядрена копоть» | W22: кг | X22: 0 | Y22: =IFERROR(IF(X22="",0,CEILING((X22/$H22),1)*$H22),"") -> 0 | Z22: =IFERROR(IF(Y22=0,"",ROUNDUP(Y22/H22,0)*0.00651),"") | AC22: ЕАЭС N RU Д-RU.РА09.В.81943/25 | AK22: 0 | BB22: КИ | BM22: =IFERROR(X22*I22/H22,"0") -> 0 | BN22: =IFERROR(Y22*I22/H22,"0") -> 0 | BO22: =IFERROR(1/J22*(X22/H22),"0") -> 0 | BP22: =IFERROR(1/J22*(Y22/H22),"0") -> 0
A23: SU003188 | B23: P003827 | C23: 4301031278 | D23: 4680115886643 | F23: 0.19 | G23: 10 | H23: 1.9 | I23: 2 | J23: 234 | K23: 18 | M23: СК2 | O23: 40 | P23: =HYPERLINK("https://abi.ru/products/Охлажденные/Ядрена копоть/Ядрена копоть/Копченые колбасы/P003827/","Копченые колбасы «Рубленая» Фикс.вес 0,19 целлофан ТМ «Ядрена копоть»") -> Копченые колбасы «Рубленая» Фикс.вес 0,19 целлофан ТМ «Ядрена копоть» | W23: кг | X23: 0 | Y23: =IFERROR(IF(X23="",0,CEILING((X23/$H23),1)*$H23),"") -> 0 | Z23: =IFERROR(IF(Y23=0,"",ROUNDUP(Y23/H23,0)*0.00502),"") | AC23: ЕАЭС N RU Д-RU.РА10.В.06818/24 | AK23: 0 | BB23: КИ | BM23: =IFERROR(X23*I23/H23,"0") -> 0 | BN23: =IFERROR(Y23*I23/H23,"0") -> 0 | BO23: =IFERROR(1/J23*(X23/H23),"0") -> 0 | BP23: =IFERROR(1/J23*(Y23/H23),"0") -> 0
P24: Итого | W24: кор | X24: =IFERROR(X22/H22,"0")+IFERROR(X23/H23,"0") -> 0 | Y24: =IFERROR(Y22/H22,"0")+IFERROR(Y23/H23,"0") -> 0 | Z24: =IFERROR(IF(Z22="",0,Z22),"0")+IFERROR(IF(Z23="",0,Z23),"0") -> 0
P25: Итого | W25: кг | X25: =IFERROR(SUM(X22:X23),"0") -> 0 | Y25: =IFERROR(SUM(Y22:Y23),"0") -> 0
A26: Сосиски
A27: SU003664 | B27: P004653 | C27: 4301051866 | D27: 4680115885912 | F27: 0.3 | G27: 6 | H27: 1.8 | I27: 3.18 | J27: 182 | K27: 14 | M27: СК3 | O27: 40 | P27: =HYPERLINK("https://abi.ru/products/Охлажденные/Ядрена копоть/Ядрена копоть/Сосиски/P004653/","Сосиски «Классические» Фикс.вес 0,3 ц/о мгс ТМ «Ядрена копоть»") -> Сосиски «Классические» Фикс.вес 0,3 ц/о мгс ТМ «Ядрена копоть» | W27: кг | X27: 0 | Y27: =IFERROR(IF(X27="",0,CEILING((X27/$H27),1)*$H27),"") -> 0 | Z27: =IFERROR(IF(Y27=0,"",ROUNDUP(Y27/H27,0)*0.00651),"") | AC27: ЕАЭС N RU Д-RU.РА10.В.84355/25, ЕАЭС N RU Д-RU.РА11.В.72353/25 | AK27: 0 | BB27: КИ | BM27: =IFERROR(X27*I27/H27,"0") -> 0 | BN27: =IFERROR(Y27*I27/H27,"0") -> 0 | BO27: =IFERROR(1/J27*(X27/H27),"0") -> 0 | BP27: =IFERROR(1/J27*(Y27/H27),"0") -> 0
A28: SU000341 | B28: P003752 | C28: 4301051776 | D28: 4607091388237 | F28: 0.42 | G28: 6 | H28: 2.52 | I28: 2.766 | J28: 182 | K28: 14 | M28: СК3 | O28: 40 | P28: =HYPERLINK("https://abi.ru/products/Охлажденные/Ядрена копоть/Ядрена копоть/Сосиски/P003752/","Сосиски Классические Ядрена копоть Фикс.вес 0,42 ц/о мгс Ядрена копоть") -> Сосиски Классические Ядрена копоть Фикс.вес 0,42 ц/о мгс Ядрена копоть | W28: кг | X28: 0 | Y28: =IFERROR(IF(X28="",0,CEILING((X28/$H28),1)*$H28),"") -> 0 | Z28: =IFERROR(IF(Y28=0,"",ROUNDUP(Y28/H28,0)*0.00651),"") | AC28: ЕАЭС N RU Д-RU.РА10.В.84355/25, ЕАЭС N RU Д-RU.РА11.В.72353/25 | AK28: 0 | BB28: КИ | BM28: =IFERROR(X28*I28/H28,"0") -> 0 | BN28: =IFERROR(Y28*I28/H28,"0") -> 0 | BO28: =IFERROR(1/J28*(X28/H28),"0") -> 0 | BP28: =IFERROR(1/J28*(Y28/H28),"0") -> 0
A29: SU004016 | B29: P005150 | C29: 4301052063 | D29: 4680115887350 | F29: 0.3 | G29: 6 | H29: 1.8 | I29: 3.18 | J29: 182 | K29: 14 | M29: СК4 | O29: 40 | P29: =HYPERLINK("https://abi.ru/products/Охлажденные/Ядрена копоть/Ядрена копоть/Сосиски/P005150/","Сосиски «Мясные для гриля» Фикс.вес 0,3 целлофан ТМ «Ядрена копоть»") -> Сосиски «Мясные для гриля» Фикс.вес 0,3 целлофан ТМ «Ядрена копоть» | W29: кг | X29: 0 | Y29: =IFERROR(IF(X29="",0,CEILING((X29/$H29),1)*$H29),"") -> 0 | Z29: =IFERROR(IF(Y29=0,"",ROUNDUP(Y29/H29,0)*0.00651),"") | AC29: ЕАЭС N RU Д-RU.РА07.В.65552/25, ЕАЭС N RU Д-RU.РА07.В.66509/25 | AK29: 0 | BB29: КИ | BM29: =IFERROR(X29*I29/H29,"0") -> 0 | BN29: =IFERROR(Y29*I29/H29,"0") -> 0 | BO29: =IFERROR(1/J29*(X29/H29),"0") -> 0 | BP29: =IFERROR(1/J29*(Y29/H29),"0") -> 0
A30: SU003665 | B30: P004642 | C30: 4301051863 | D30: 4680115885905 | F30: 0.3 | G30: 6 | H30: 1.8 | I30: 3.18 | J30: 182 | K30: 14 | M30: СК4 | O30: 40 | P30: =HYPERLINK("https://abi.ru/products/Охлажденные/Ядрена копоть/Ядрена копоть/Сосиски/P004642/","Сосиски «Сосиски с сыром» Фикс.вес 0,3 вискофан ТМ «Ядрена копоть»") -> Сосиски «Сосиски с сыром» Фикс.вес 0,3 вискофан ТМ «Ядрена копоть» | W30: кг | X30: 0 | Y30: =IFERROR(IF(X30="",0,CEILING((X30/$H30),1)*$H30),"") -> 0 | Z30: =IFERROR(IF(Y30=0,"",ROUNDUP(Y30/H30,0)*0.00651),"") | AC30: ЕАЭС N RU Д-RU.РА06.В.92094/23 | AK30: 0 | BB30: КИ | BM30: =IFERROR(X30*I30/H30,"0") -> 0 | BN30: =IFERROR(Y30*I30/H30,"0") -> 0 | BO30: =IFERROR(1/J30*(X30/H30),"0") -> 0 | BP30: =IFERROR(1/J30*(Y30/H30),"0") -> 0
A31: SU004080 | B31: P005211 | C31: 4301052078 | D31: 4680115887657 | F31: 0.33 | G31: 6 | H31: 1.98 | I31: 2.16 | J31: 182 | K31: 14 | M31: СК4 | O31: 40 | P31: =HYPERLINK("https://abi.ru/products/Охлажденные/Ядрена копоть/Ядрена копоть/Сосиски/P005211/","Сосиски «со вкусом Дикий васаби» Фикс.вес 0,33 целлофан ТМ «Ядрена копоть»") -> Сосиски «со вкусом Дикий васаби» Фикс.вес 0,33 целлофан ТМ «Ядрена копоть» | W31: кг | X31: 0 | Y31: =IFERROR(IF(X31="",0,CEILING((X31/$H31),1)*$H31),"") -> 0 | Z31: =IFERROR(IF(Y31=0,"",ROUNDUP(Y31/H31,0)*0.00651),"") | AC31: ЕАЭС N RU Д-RU.РА11.В.17157/25, ЕАЭС N RU Д-RU.РА11.В.18056/25 | AK31: 0 | BB31: КИ | BM31: =IFERROR(X31*I31/H31,"0") -> 0 | BN31: =IFERROR(Y31*I31/H31,"0") -> 0 | BO31: =IFERROR(1/J31*(X31/H31),"0") -> 0 | BP31: =IFERROR(1/J31*(Y31/H31),"0") -> 0
A32: SU004073 | B32: P005210 | C32: 4301052071 | D32: 4680115887619 | F32: 0.33 | G32: 6 | H32: 1.98 | I32: 2.16 | J32: 182 | K32: 14 | M32: СК3 | O32: 40 | P32: =HYPERLINK("https://abi.ru/products/Охлажденные/Ядрена копоть/Ядрена копоть/Сосиски/P005210/","Сосиски «со вкусом Перечный стейк» Фикс.вес 0,33 целлофан ТМ «Ядрена копоть»") -> Сосиски «со вкусом Перечный стейк» Фикс.вес 0,33 целлофан ТМ «Ядрена копоть» | W32: кг | X32: 0 | Y32: =IFERROR(IF(X32="",0,CEILING((X32/$H32),1)*$H32),"") -> 0 | Z32: =IFERROR(IF(Y32=0,"",ROUNDUP(Y32/H32,0)*0.00651),"") | AC32: ЕАЭС N RU Д-RU.РА09.В.48525/25 | AK32: 0 | BB32: КИ | BM32: =IFERROR(X32*I32/H32,"0") -> 0 | BN32: =IFERROR(Y32*I32/H32,"0") -> 0 | BO32: =IFERROR(1/J32*(X32/H32),"0") -> 0 | BP32: =IFERROR(1/J32*(Y32/H32),"0") -> 0
P33: Итого | W33: кор | X33: =IFERROR(X27/H27,"0")+IFERROR(X28/H28,"0")+IFERROR(X29/H29,"0")+IFERROR(X30/H30,"0")+IFERROR(X31/H31,"0")+IFERROR(X32/H32,"0") -> 0 | Y33: =IFERROR(Y27/H27,"0")+IFERROR(Y28/H28,"0")+IFERROR(Y29/H29,"0")+IFERROR(Y30/H30,"0")+IFERROR(Y31/H31,"0")+IFERROR(Y32/H32,"0") -> 0 | Z33: =IFERROR(IF(Z27="",0,Z27),"0")+IFERROR(IF(Z28="",0,Z28),"0")+IFERROR(IF(Z29="",0,Z29),"0")+IFERROR(IF(Z30="",0,Z30),"0")+IFERROR(IF(Z31="",0,Z31),"0")+IFERROR(IF(Z32="",0,Z32),"0") -> 0
P34: Итого | W34: кг | X34: =IFERROR(SUM(X27:X32),"0") -> 0 | Y34: =IFERROR(SUM(Y27:Y32),"0") -> 0
A35: Сырокопченые колбасы
A36: SU002050 | B36: P002188 | C36: 4301032013 | D36: 4607091388503 | F36: 0.05 | G36: 12 | H36: 0.6 | I36: 0.822 | J36: 182 | K36: 14 | M36: АК | O36: 120 | P36: =HYPERLINK("https://abi.ru/products/Охлажденные/Ядрена копоть/Ядрена копоть/Сырокопченые колбасы/P002188/","С/к колбасы Мини-салями во вкусом бекона Ядрена копоть Фикс.вес 0,05 б/о Ядрена копоть") -> С/к колбасы Мини-салями во вкусом бекона Ядрена копоть Фикс.вес 0,05 б/о Ядрена копоть | W36: кг | X36: 0 | Y36: =IFERROR(IF(X36="",0,CEILING((X36/$H36),1)*$H36),"") -> 0 | Z36: =IFERROR(IF(Y36=0,"",ROUNDUP(Y36/H36,0)*0.00651),"") | AC36: ЕАЭС N RU Д-RU.РА01.В.14797/20 | AK36: 0 | BB36: СНК | BM36: =IFERROR(X36*I36/H36,"0") -> 0 | BN36: =IFERROR(Y36*I36/H36,"0") -> 0 | BO36: =IFERROR(1/J36*(X36/H36),"0") -> 0 | BP36: =IFERROR(1/J36*(Y36/H36),"0") -> 0
P37: Итого | W37: кор | X37: =IFERROR(X36/H36,"0") -> 0 | Y37: =IFERROR(Y36/H36,"0") -> 0 | Z37: =IFERROR(IF(Z36="",0,Z36),"0") -> 0
P38: Итого | W38: кг | X38: =IFERROR(SUM(X36:X36),"0") -> 0 | Y38: =IFERROR(SUM(Y36:Y36),"0") -> 0
A39: Вязанка
A40: ГОСТ
A41: Вареные колбасы
A42: SU000722 | B42: P003011 | C42: 4301011380 | D42: 4607091385670 | F42: 1.35 | G42: 8 | H42: 10.8 | I42: 11.21 | J42: 64 | K42: 8 | M42: СК1 | O42: 50 | P42: =HYPERLINK("https://abi.ru/products/Охлажденные/Вязанка/ГОСТ/Вареные колбасы/P003011/","Вареные колбасы Докторская ГОСТ Вязанка Весовые Вектор Вязанка") -> Вареные колбасы Докторская ГОСТ Вязанка Весовые Вектор Вязанка | W42: кг | X42: 604.8 | Y42: =IFERROR(IF(X42="",0,CEILING((X42/$H42),1)*$H42),"") -> 604.8 | Z42: =IFERROR(IF(Y42=0,"",ROUNDUP(Y42/H42,0)*0.01898),"") -> 1.06288 | AC42: ЕАЭС N RU Д-RU.РА08.В.45907/25 | AK42: 0 | BB42: КИ | BM42: =IFERROR(X42*I42/H42,"0") -> 627.76 | BN42: =IFERROR(Y42*I42/H42,"0") -> 627.76 | BO42: =IFERROR(1/J42*(X42/H42),"0") -> 0.875 | BP42: =IFERROR(1/J42*(Y42/H42),"0") -> 0.875
...

Sheet Setting
G1: MSDAX_КИ
B3: Доставка
B4: Самовывоз
B6: НВ, ООО 9001015535, Запорожская обл, Трояны с., | C6: 596383_4 | D6: 1
B7: НВ, ООО 9001015535, Луганская Народная Респ, Комиссара Санюка (Каменнобродский р-н) ул, д. 50, | C7: 596383_5 | D7: 2
B8: НВ, ООО 9001015535, Донецкая Народная Респ, Охотская ул, д. 79А, | C8: 596383_6 | D8: 3
B9: НВ, ООО 9001015535, Запорожская обл, Мелитополь г, Полевая ул, д. 3, стр А, | C9: 596383_7 | D9: 4
B10: НВ, ООО 9001015535, Донецкая Народная Респ, Чаадаева ул, д. 1, | C10: 596383_8 | D10: 5
B11: НВ, ООО 9001015535, Луганская Народная Респ, Рабочая ул, д. 10А, | C11: 596383_9 | D11: 6
B13: 272151Российская Федерация, Запорожская обл, Бердянский р-н, Трояны с., | C13: 596383_4
B15: 291019Российская Федерация, Луганская Народная Респ, Луганск г, Комиссара Санюка (Каменнобродский р-н) ул, д. 50, | C15: 596383_5
B17: 283092Российская Федерация, Донецкая Народная Респ, Донецк г, Охотская ул, д. 79А, | C17: 596383_6
B19: 272302Российская Федерация, Запорожская обл, Мелитополь г, Полевая ул, д. 3, стр А, | C19: 596383_7
B21: 283032Российская Федерация, Донецкая Народная Респ, Донецк г, Чаадаева ул, д. 1, | C21: 596383_8
B23: 291002Российская Федерация, Луганская Народная Респ, Луганск г, Рабочая ул, д. 10А, | C23: 596383_9
B25: CFR
B26: CIF
B27: CIP
B28: CPT
B29: DAP
B30: DAT
B31: DDP
B32: EXW
B33: FAS
B34: FCA
B35: FOB
